20260109-09:17:19.323181000 : 8=FIX.4.49=10735=A34=149=SIRIUS_500007460_MD52=20260109-09:17:19.31556=NTPRO_IDBA_UAT98=0108=30141=Y554=Df2Hy8nM10=014
20260109-09:17:19.426713000 : 8=FIX.4.49=009435=A49=NTPRO_IDBA_UAT56=SIRIUS_500007460_MD34=152=20260109-09:17:18.32698=0108=30141=Y10=216
20260109-09:17:19.427395000 : 8=FIX.4.49=011135=h49=NTPRO_IDBA_UAT56=SIRIUS_500007460_MD34=252=20260109-09:17:18.326336=Market Data340=258=version 510=149
20260109-09:17:21.492885000 : 8=FIX.4.49=15035=V34=249=SIRIUS_500007460_MD52=20260109-09:17:21.49056=NTPRO_IDBA_UAT146=155=EUR/USD262=MD_EURUSD_091721263=1264=1265=1267=2269=0269=110=168
20260109-09:17:21.600185000 : 8=FIX.4.49=038235=W49=NTPRO_IDBA_UAT56=SIRIUS_500007460_MD34=352=20260109-09:17:20.359262=MD_EURUSD_09172155=EUR/USD268=6269=0270=1.13969271=100000299=1110=0269=0270=1.13969271=500000299=2110=100000269=0270=1.13969271=1000000299=3110=500000269=1270=1.18993271=100000299=4110=0269=1270=1.18993271=500000299=5110=100000269=1270=1.18993271=1000000299=6110=50000010=025
20260109-09:17:22.494121000 : 8=FIX.4.49=15035=V34=349=SIRIUS_500007460_MD52=20260109-09:17:22.49256=NTPRO_IDBA_UAT146=155=GBP/USD262=MD_GBPUSD_091722263=1264=1265=1267=2269=0269=110=135
20260109-09:17:22.616603000 : 8=FIX.4.49=057635=W49=NTPRO_IDBA_UAT56=SIRIUS_500007460_MD34=452=20260109-09:17:21.297262=MD_GBPUSD_09172255=GBP/USD268=10269=0270=1.25159271=100000299=1110=0269=0270=1.25159271=500000299=2110=100000269=0270=1.25159271=1000000299=3110=500000269=0270=1.25159271=3000000299=4110=1000000269=0270=1.25159271=5000000299=5110=3000000269=1270=1.43191271=100000299=6110=0269=1270=1.43191271=500000299=7110=100000269=1270=1.43191271=1000000299=8110=500000269=1270=1.43191271=3000000299=9110=1000000269=1270=1.43191271=5000000299=10110=300000010=224
20260109-09:17:23.527940000 : 8=FIX.4.49=038835=X49=NTPRO_IDBA_UAT56=SIRIUS_500007460_MD34=552=20260109-09:17:22.163262=MD_GBPUSD_091722268=5279=1269=1270=1.43192271=10000055=GBP/USD110=0279=1269=1270=1.43192271=50000055=GBP/USD110=100000279=1269=1270=1.43192271=100000055=GBP/USD110=500000279=1269=1270=1.43192271=300000055=GBP/USD110=1000000279=1269=1270=1.43192271=500000055=GBP/USD110=300000010=080
20260109-09:17:23.556200000 : 8=FIX.4.49=15035=V34=449=SIRIUS_500007460_MD52=20260109-09:17:23.55556=NTPRO_IDBA_UAT146=155=USD/JPY262=MD_USDJPY_091723263=1264=1265=1267=2269=0269=110=190
20260109-09:17:23.669330000 : 8=FIX.4.49=011435=W49=NTPRO_IDBA_UAT56=SIRIUS_500007460_MD34=652=20260109-09:17:22.294262=MD_USDJPY_09172355=USD/JPY268=010=165
20260109-09:17:24.443426000 : 8=FIX.4.49=038835=X49=NTPRO_IDBA_UAT56=SIRIUS_500007460_MD34=752=20260109-09:17:23.020262=MD_GBPUSD_091722268=5279=1269=0270=1.25158271=10000055=GBP/USD110=0279=1269=0270=1.25158271=50000055=GBP/USD110=100000279=1269=0270=1.25158271=100000055=GBP/USD110=500000279=1269=0270=1.25158271=300000055=GBP/USD110=1000000279=1269=0270=1.25158271=500000055=GBP/USD110=300000010=080
20260109-09:17:24.463992000 : 8=FIX.4.49=038835=X49=NTPRO_IDBA_UAT56=SIRIUS_500007460_MD34=852=20260109-09:17:23.039262=MD_GBPUSD_091722268=5279=1269=1270=1.43191271=10000055=GBP/USD110=0279=1269=1270=1.43191271=50000055=GBP/USD110=100000279=1269=1270=1.43191271=100000055=GBP/USD110=500000279=1269=1270=1.43191271=300000055=GBP/USD110=1000000279=1269=1270=1.43191271=500000055=GBP/USD110=300000010=081
20260109-09:17:24.590989000 : 8=FIX.4.49=15035=V34=549=SIRIUS_500007460_MD52=20260109-09:17:24.58856=NTPRO_IDBA_UAT146=155=EUR/GBP262=MD_EURGBP_091724263=1264=1265=1267=2269=0269=110=147
20260109-09:17:24.696115000 : 8=FIX.4.49=011435=W49=NTPRO_IDBA_UAT56=SIRIUS_500007460_MD34=952=20260109-09:17:23.257262=MD_EURGBP_09172455=EUR/GBP268=010=117
20260109-09:17:25.550358000 : 8=FIX.4.49=038435=X49=NTPRO_IDBA_UAT56=SIRIUS_500007460_MD34=1052=20260109-09:17:24.054262=MD_GBPUSD_091722268=5279=1269=1270=1.4319271=10000055=GBP/USD110=0279=1269=1270=1.4319271=50000055=GBP/USD110=100000279=1269=1270=1.4319271=100000055=GBP/USD110=500000279=1269=1270=1.4319271=300000055=GBP/USD110=1000000279=1269=1270=1.4319271=500000055=GBP/USD110=300000010=127
20260109-09:17:26.728967000 : 8=FIX.4.49=038935=X49=NTPRO_IDBA_UAT56=SIRIUS_500007460_MD34=1152=20260109-09:17:25.159262=MD_GBPUSD_091722268=5279=1269=0270=1.25157271=10000055=GBP/USD110=0279=1269=0270=1.25157271=50000055=GBP/USD110=100000279=1269=0270=1.25157271=100000055=GBP/USD110=500000279=1269=0270=1.25157271=300000055=GBP/USD110=1000000279=1269=0270=1.25157271=500000055=GBP/USD110=300000010=134
20260109-09:17:27.434743000 : 8=FIX.4.49=038935=X49=NTPRO_IDBA_UAT56=SIRIUS_500007460_MD34=1252=20260109-09:17:25.819262=MD_GBPUSD_091722268=5279=1269=1270=1.43189271=10000055=GBP/USD110=0279=1269=1270=1.43189271=50000055=GBP/USD110=100000279=1269=1270=1.43189271=100000055=GBP/USD110=500000279=1269=1270=1.43189271=300000055=GBP/USD110=1000000279=1269=1270=1.43189271=500000055=GBP/USD110=300000010=168
20260109-09:17:27.649202000 : 8=FIX.4.49=038935=X49=NTPRO_IDBA_UAT56=SIRIUS_500007460_MD34=1352=20260109-09:17:26.020262=MD_GBPUSD_091722268=5279=1269=0270=1.25156271=10000055=GBP/USD110=0279=1269=0270=1.25156271=50000055=GBP/USD110=100000279=1269=0270=1.25156271=100000055=GBP/USD110=500000279=1269=0270=1.25156271=300000055=GBP/USD110=1000000279=1269=0270=1.25156271=500000055=GBP/USD110=300000010=119
20260109-09:17:27.674275000 : 8=FIX.4.49=043835=X49=NTPRO_IDBA_UAT56=SIRIUS_500007460_MD34=1452=20260109-09:17:26.043262=MD_EURUSD_091721268=6279=1269=0270=1.13968271=10000055=EUR/USD110=0279=1269=0270=1.13968271=50000055=EUR/USD110=100000279=1269=0270=1.13968271=100000055=EUR/USD110=500000279=1269=1270=1.18992271=10000055=EUR/USD110=0279=1269=1270=1.18992271=50000055=EUR/USD110=100000279=1269=1270=1.18992271=100000055=EUR/USD110=50000010=148
20260109-09:17:27.694122000 : 8=FIX.4.49=043835=X49=NTPRO_IDBA_UAT56=SIRIUS_500007460_MD34=1552=20260109-09:17:26.062262=MD_EURUSD_091721268=6279=1269=0270=1.13966271=10000055=EUR/USD110=0279=1269=0270=1.13966271=50000055=EUR/USD110=100000279=1269=0270=1.13966271=100000055=EUR/USD110=500000279=1269=1270=1.18991271=10000055=EUR/USD110=0279=1269=1270=1.18991271=50000055=EUR/USD110=100000279=1269=1270=1.18991271=100000055=EUR/USD110=50000010=141
20260109-09:17:27.709544000 : 8=FIX.4.49=038935=X49=NTPRO_IDBA_UAT56=SIRIUS_500007460_MD34=1652=20260109-09:17:26.077262=MD_GBPUSD_091722268=5279=1269=1270=1.43186271=10000055=GBP/USD110=0279=1269=1270=1.43186271=50000055=GBP/USD110=100000279=1269=1270=1.43186271=100000055=GBP/USD110=500000279=1269=1270=1.43186271=300000055=GBP/USD110=1000000279=1269=1270=1.43186271=500000055=GBP/USD110=300000010=154
20260109-09:17:27.770367000 : 8=FIX.4.49=043535=X49=NTPRO_IDBA_UAT56=SIRIUS_500007460_MD34=1752=20260109-09:17:26.134262=MD_EURUSD_091721268=6279=1269=0270=1.13965271=10000055=EUR/USD110=0279=1269=0270=1.13965271=50000055=EUR/USD110=100000279=1269=0270=1.13965271=100000055=EUR/USD110=500000279=1269=1270=1.1899271=10000055=EUR/USD110=0279=1269=1270=1.1899271=50000055=EUR/USD110=100000279=1269=1270=1.1899271=100000055=EUR/USD110=50000010=246
20260109-09:17:27.785545000 : 8=FIX.4.49=067535=X49=NTPRO_IDBA_UAT56=SIRIUS_500007460_MD34=1852=20260109-09:17:26.148262=MD_GBPUSD_091722268=10279=2269=0270=1.25156271=10000055=GBP/USD110=0279=2269=0270=1.25156271=50000055=GBP/USD110=100000279=2269=0270=1.25156271=100000055=GBP/USD110=500000279=2269=0270=1.25156271=300000055=GBP/USD110=1000000279=2269=0270=1.25156271=500000055=GBP/USD110=3000000279=2269=1270=1.43186271=10000055=GBP/USD110=0279=2269=1270=1.43186271=50000055=GBP/USD110=100000279=2269=1270=1.43186271=100000055=GBP/USD110=500000279=2269=1270=1.43186271=300000055=GBP/USD110=1000000279=2269=1270=1.43186271=500000055=GBP/USD110=300000010=057
20260109-09:17:27.813472000 : 8=FIX.4.49=043835=X49=NTPRO_IDBA_UAT56=SIRIUS_500007460_MD34=1952=20260109-09:17:26.173262=MD_EURUSD_091721268=6279=1269=0270=1.13964271=10000055=EUR/USD110=0279=1269=0270=1.13964271=50000055=EUR/USD110=100000279=1269=0270=1.13964271=100000055=EUR/USD110=500000279=1269=1270=1.18989271=10000055=EUR/USD110=0279=1269=1270=1.18989271=50000055=EUR/USD110=100000279=1269=1270=1.18989271=100000055=EUR/USD110=50000010=163
20260109-09:17:27.833167000 : 8=FIX.4.49=067535=X49=NTPRO_IDBA_UAT56=SIRIUS_500007460_MD34=2052=20260109-09:17:26.192262=MD_GBPUSD_091722268=10279=0269=0270=1.25148271=10000055=GBP/USD110=0279=0269=0270=1.25148271=50000055=GBP/USD110=100000279=0269=0270=1.25148271=100000055=GBP/USD110=500000279=0269=0270=1.25148271=300000055=GBP/USD110=1000000279=0269=0270=1.25148271=500000055=GBP/USD110=3000000279=0269=1270=1.43181271=10000055=GBP/USD110=0279=0269=1270=1.43181271=50000055=GBP/USD110=100000279=0269=1270=1.43181271=100000055=GBP/USD110=500000279=0269=1270=1.43181271=300000055=GBP/USD110=1000000279=0269=1270=1.43181271=500000055=GBP/USD110=300000010=009
20260109-09:17:27.886494000 : 8=FIX.4.49=038435=X49=NTPRO_IDBA_UAT56=SIRIUS_500007460_MD34=2152=20260109-09:17:26.241262=MD_GBPUSD_091722268=5279=1269=0270=1.2515271=10000055=GBP/USD110=0279=1269=0270=1.2515271=50000055=GBP/USD110=100000279=1269=0270=1.2515271=100000055=GBP/USD110=500000279=1269=0270=1.2515271=300000055=GBP/USD110=1000000279=1269=0270=1.2515271=500000055=GBP/USD110=300000010=104
20260109-09:17:27.951447000 : 8=FIX.4.49=067535=X49=NTPRO_IDBA_UAT56=SIRIUS_500007460_MD34=2252=20260109-09:17:26.302262=MD_GBPUSD_091722268=10279=1269=0270=1.25151271=10000055=GBP/USD110=0279=1269=0270=1.25151271=50000055=GBP/USD110=100000279=1269=0270=1.25151271=100000055=GBP/USD110=500000279=1269=0270=1.25151271=300000055=GBP/USD110=1000000279=1269=0270=1.25151271=500000055=GBP/USD110=3000000279=1269=1270=1.43184271=10000055=GBP/USD110=0279=1269=1270=1.43184271=50000055=GBP/USD110=100000279=1269=1270=1.43184271=100000055=GBP/USD110=500000279=1269=1270=1.43184271=300000055=GBP/USD110=1000000279=1269=1270=1.43184271=500000055=GBP/USD110=300000010=255
20260109-09:17:28.007203000 : 8=FIX.4.49=027135=X49=NTPRO_IDBA_UAT56=SIRIUS_500007460_MD34=2352=20260109-09:17:26.355262=MD_EURUSD_091721268=3279=1269=0270=1.13965271=10000055=EUR/USD110=0279=1269=0270=1.13965271=50000055=EUR/USD110=100000279=1269=0270=1.13965271=100000055=EUR/USD110=50000010=075
20260109-09:17:28.060769000 : 8=FIX.4.49=038935=X49=NTPRO_IDBA_UAT56=SIRIUS_500007460_MD34=2452=20260109-09:17:26.405262=MD_GBPUSD_091722268=5279=1269=0270=1.25152271=10000055=GBP/USD110=0279=1269=0270=1.25152271=50000055=GBP/USD110=100000279=1269=0270=1.25152271=100000055=GBP/USD110=500000279=1269=0270=1.25152271=300000055=GBP/USD110=1000000279=1269=0270=1.25152271=500000055=GBP/USD110=300000010=108
20260109-09:17:28.320790000 : 8=FIX.4.49=038935=X49=NTPRO_IDBA_UAT56=SIRIUS_500007460_MD34=2552=20260109-09:17:26.648262=MD_GBPUSD_091722268=5279=1269=1270=1.43185271=10000055=GBP/USD110=0279=1269=1270=1.43185271=50000055=GBP/USD110=100000279=1269=1270=1.43185271=100000055=GBP/USD110=500000279=1269=1270=1.43185271=300000055=GBP/USD110=1000000279=1269=1270=1.43185271=500000055=GBP/USD110=300000010=153
20260109-09:17:28.578466000 : 8=FIX.4.49=027135=X49=NTPRO_IDBA_UAT56=SIRIUS_500007460_MD34=2652=20260109-09:17:26.889262=MD_EURUSD_091721268=3279=1269=0270=1.13964271=10000055=EUR/USD110=0279=1269=0270=1.13964271=50000055=EUR/USD110=100000279=1269=0270=1.13964271=100000055=EUR/USD110=50000010=087
20260109-09:17:30.127145000 : 8=FIX.4.49=027135=X49=NTPRO_IDBA_UAT56=SIRIUS_500007460_MD34=2752=20260109-09:17:28.339262=MD_EURUSD_091721268=3279=1269=0270=1.13965271=10000055=EUR/USD110=0279=1269=0270=1.13965271=50000055=EUR/USD110=100000279=1269=0270=1.13965271=100000055=EUR/USD110=50000010=083
20260109-09:17:30.305657000 : 8=FIX.4.49=038935=X49=NTPRO_IDBA_UAT56=SIRIUS_500007460_MD34=2852=20260109-09:17:28.503262=MD_GBPUSD_091722268=5279=1269=0270=1.25153271=10000055=GBP/USD110=0279=1269=0270=1.25153271=50000055=GBP/USD110=100000279=1269=0270=1.25153271=100000055=GBP/USD110=500000279=1269=0270=1.25153271=300000055=GBP/USD110=1000000279=1269=0270=1.25153271=500000055=GBP/USD110=300000010=118
20260109-09:17:30.612547000 : 8=FIX.4.49=027135=X49=NTPRO_IDBA_UAT56=SIRIUS_500007460_MD34=2952=20260109-09:17:28.792262=MD_EURUSD_091721268=3279=1269=0270=1.13964271=10000055=EUR/USD110=0279=1269=0270=1.13964271=50000055=EUR/USD110=100000279=1269=0270=1.13964271=100000055=EUR/USD110=50000010=085
20260109-09:17:30.958783000 : 8=FIX.4.49=038935=X49=NTPRO_IDBA_UAT56=SIRIUS_500007460_MD34=3052=20260109-09:17:29.117262=MD_GBPUSD_091722268=5279=1269=0270=1.25152271=10000055=GBP/USD110=0279=1269=0270=1.25152271=50000055=GBP/USD110=100000279=1269=0270=1.25152271=100000055=GBP/USD110=500000279=1269=0270=1.25152271=300000055=GBP/USD110=1000000279=1269=0270=1.25152271=500000055=GBP/USD110=300000010=108
20260109-09:17:31.377053000 : 8=FIX.4.49=038935=X49=NTPRO_IDBA_UAT56=SIRIUS_500007460_MD34=3152=20260109-09:17:29.506262=MD_GBPUSD_091722268=5279=1269=0270=1.25153271=10000055=GBP/USD110=0279=1269=0270=1.25153271=50000055=GBP/USD110=100000279=1269=0270=1.25153271=100000055=GBP/USD110=500000279=1269=0270=1.25153271=300000055=GBP/USD110=1000000279=1269=0270=1.25153271=500000055=GBP/USD110=300000010=116
20260109-09:17:31.499717000 : 8=FIX.4.49=038935=X49=NTPRO_IDBA_UAT56=SIRIUS_500007460_MD34=3252=20260109-09:17:29.623262=MD_GBPUSD_091722268=5279=1269=0270=1.25152271=10000055=GBP/USD110=0279=1269=0270=1.25152271=50000055=GBP/USD110=100000279=1269=0270=1.25152271=100000055=GBP/USD110=500000279=1269=0270=1.25152271=300000055=GBP/USD110=1000000279=1269=0270=1.25152271=500000055=GBP/USD110=300000010=112
20260109-09:17:32.080384000 : 8=FIX.4.49=038935=X49=NTPRO_IDBA_UAT56=SIRIUS_500007460_MD34=3352=20260109-09:17:30.163262=MD_GBPUSD_091722268=5279=1269=1270=1.43184271=10000055=GBP/USD110=0279=1269=1270=1.43184271=50000055=GBP/USD110=100000279=1269=1270=1.43184271=100000055=GBP/USD110=500000279=1269=1270=1.43184271=300000055=GBP/USD110=1000000279=1269=1270=1.43184271=500000055=GBP/USD110=300000010=134
20260109-09:17:31.104037000 : 8=FIX.4.49=067535=X49=NTPRO_IDBA_UAT56=SIRIUS_500007460_MD34=3452=20260109-09:17:30.944262=MD_GBPUSD_091722268=10279=1269=0270=1.25151271=10000055=GBP/USD110=0279=1269=0270=1.25151271=50000055=GBP/USD110=100000279=1269=0270=1.25151271=100000055=GBP/USD110=500000279=1269=0270=1.25151271=300000055=GBP/USD110=1000000279=1269=0270=1.25151271=500000055=GBP/USD110=3000000279=1269=1270=1.43183271=10000055=GBP/USD110=0279=1269=1270=1.43183271=50000055=GBP/USD110=100000279=1269=1270=1.43183271=100000055=GBP/USD110=500000279=1269=1270=1.43183271=300000055=GBP/USD110=1000000279=1269=1270=1.43183271=500000055=GBP/USD110=300000010=004
20260109-09:17:31.167206000 : 8=FIX.4.49=067035=X49=NTPRO_IDBA_UAT56=SIRIUS_500007460_MD34=3552=20260109-09:17:30.995262=MD_GBPUSD_091722268=10279=1269=0270=1.2515271=10000055=GBP/USD110=0279=1269=0270=1.2515271=50000055=GBP/USD110=100000279=1269=0270=1.2515271=100000055=GBP/USD110=500000279=1269=0270=1.2515271=300000055=GBP/USD110=1000000279=1269=0270=1.2515271=500000055=GBP/USD110=3000000279=1269=1270=1.43182271=10000055=GBP/USD110=0279=1269=1270=1.43182271=50000055=GBP/USD110=100000279=1269=1270=1.43182271=100000055=GBP/USD110=500000279=1269=1270=1.43182271=300000055=GBP/USD110=1000000279=1269=1270=1.43182271=500000055=GBP/USD110=300000010=012
20260109-09:17:32.176043000 : 8=FIX.4.49=027135=X49=NTPRO_IDBA_UAT56=SIRIUS_500007460_MD34=3652=20260109-09:17:31.941262=MD_EURUSD_091721268=3279=1269=1270=1.18988271=10000055=EUR/USD110=0279=1269=1270=1.18988271=50000055=EUR/USD110=100000279=1269=1270=1.18988271=100000055=EUR/USD110=50000010=109
20260109-09:17:36.187277000 : 8=FIX.4.49=038935=X49=NTPRO_IDBA_UAT56=SIRIUS_500007460_MD34=3752=20260109-09:17:35.702262=MD_GBPUSD_091722268=5279=1269=1270=1.43183271=10000055=GBP/USD110=0279=1269=1270=1.43183271=50000055=GBP/USD110=100000279=1269=1270=1.43183271=100000055=GBP/USD110=500000279=1269=1270=1.43183271=300000055=GBP/USD110=1000000279=1269=1270=1.43183271=500000055=GBP/USD110=300000010=137
20260109-09:17:36.712856000 : 8=FIX.4.49=038935=X49=NTPRO_IDBA_UAT56=SIRIUS_500007460_MD34=3852=20260109-09:17:36.192262=MD_GBPUSD_091722268=5279=1269=0270=1.25151271=10000055=GBP/USD110=0279=1269=0270=1.25151271=50000055=GBP/USD110=100000279=1269=0270=1.25151271=100000055=GBP/USD110=500000279=1269=0270=1.25151271=300000055=GBP/USD110=1000000279=1269=0270=1.25151271=500000055=GBP/USD110=300000010=112
20260109-09:17:36.872551000 : 8=FIX.4.49=038435=X49=NTPRO_IDBA_UAT56=SIRIUS_500007460_MD34=3952=20260109-09:17:36.343262=MD_GBPUSD_091722268=5279=1269=0270=1.2515271=10000055=GBP/USD110=0279=1269=0270=1.2515271=50000055=GBP/USD110=100000279=1269=0270=1.2515271=100000055=GBP/USD110=500000279=1269=0270=1.2515271=300000055=GBP/USD110=1000000279=1269=0270=1.2515271=500000055=GBP/USD110=300000010=117
20260109-09:17:41.226280000 : 8=FIX.4.49=038935=X49=NTPRO_IDBA_UAT56=SIRIUS_500007460_MD34=4052=20260109-09:17:40.417262=MD_GBPUSD_091722268=5279=1269=0270=1.25151271=10000055=GBP/USD110=0279=1269=0270=1.25151271=50000055=GBP/USD110=100000279=1269=0270=1.25151271=100000055=GBP/USD110=500000279=1269=0270=1.25151271=300000055=GBP/USD110=1000000279=1269=0270=1.25151271=500000055=GBP/USD110=300000010=100
20260109-09:17:41.502038000 : 8=FIX.4.49=038435=X49=NTPRO_IDBA_UAT56=SIRIUS_500007460_MD34=4152=20260109-09:17:40.675262=MD_GBPUSD_091722268=5279=1269=0270=1.2515271=10000055=GBP/USD110=0279=1269=0270=1.2515271=50000055=GBP/USD110=100000279=1269=0270=1.2515271=100000055=GBP/USD110=500000279=1269=0270=1.2515271=300000055=GBP/USD110=1000000279=1269=0270=1.2515271=500000055=GBP/USD110=300000010=113
20260109-09:17:42.344551000 : 8=FIX.4.49=038935=X49=NTPRO_IDBA_UAT56=SIRIUS_500007460_MD34=4252=20260109-09:17:41.360262=MD_GBPUSD_091722268=5279=1269=1270=1.43181271=10000055=GBP/USD110=0279=1269=1270=1.43181271=50000055=GBP/USD110=100000279=1269=1270=1.43181271=100000055=GBP/USD110=500000279=1269=1270=1.43181271=300000055=GBP/USD110=1000000279=1269=1270=1.43181271=500000055=GBP/USD110=300000010=120
20260109-09:17:42.345707000 : 8=FIX.4.49=043835=X49=NTPRO_IDBA_UAT56=SIRIUS_500007460_MD34=4352=20260109-09:17:41.381262=MD_EURUSD_091721268=6279=1269=0270=1.13961271=10000055=EUR/USD110=0279=1269=0270=1.13961271=50000055=EUR/USD110=100000279=1269=0270=1.13961271=100000055=EUR/USD110=500000279=1269=1270=1.18986271=10000055=EUR/USD110=0279=1269=1270=1.18986271=50000055=EUR/USD110=100000279=1269=1270=1.18986271=100000055=EUR/USD110=50000010=140
20260109-09:17:42.346665000 : 8=FIX.4.49=067535=X49=NTPRO_IDBA_UAT56=SIRIUS_500007460_MD34=4452=20260109-09:17:41.393262=MD_GBPUSD_091722268=10279=1269=0270=1.25149271=10000055=GBP/USD110=0279=1269=0270=1.25149271=50000055=GBP/USD110=100000279=1269=0270=1.25149271=100000055=GBP/USD110=500000279=1269=0270=1.25149271=300000055=GBP/USD110=1000000279=1269=0270=1.25149271=500000055=GBP/USD110=3000000279=1269=1270=1.43182271=10000055=GBP/USD110=0279=1269=1270=1.43182271=50000055=GBP/USD110=100000279=1269=1270=1.43182271=100000055=GBP/USD110=500000279=1269=1270=1.43182271=300000055=GBP/USD110=1000000279=1269=1270=1.43182271=500000055=GBP/USD110=300000010=035
20260109-09:17:42.347699000 : 8=FIX.4.49=067535=X49=NTPRO_IDBA_UAT56=SIRIUS_500007460_MD34=4552=20260109-09:17:41.435262=MD_GBPUSD_091722268=10279=1269=0270=1.25147271=10000055=GBP/USD110=0279=1269=0270=1.25147271=50000055=GBP/USD110=100000279=1269=0270=1.25147271=100000055=GBP/USD110=500000279=1269=0270=1.25147271=300000055=GBP/USD110=1000000279=1269=0270=1.25147271=500000055=GBP/USD110=3000000279=1269=1270=1.43179271=10000055=GBP/USD110=0279=1269=1270=1.43179271=50000055=GBP/USD110=100000279=1269=1270=1.43179271=100000055=GBP/USD110=500000279=1269=1270=1.43179271=300000055=GBP/USD110=1000000279=1269=1270=1.43179271=500000055=GBP/USD110=300000010=053
20260109-09:17:42.348335000 : 8=FIX.4.49=043835=X49=NTPRO_IDBA_UAT56=SIRIUS_500007460_MD34=4652=20260109-09:17:41.436262=MD_EURUSD_091721268=6279=2269=0270=1.13961271=10000055=EUR/USD110=0279=2269=0270=1.13961271=50000055=EUR/USD110=100000279=2269=0270=1.13961271=100000055=EUR/USD110=500000279=2269=1270=1.18986271=10000055=EUR/USD110=0279=2269=1270=1.18986271=50000055=EUR/USD110=100000279=2269=1270=1.18986271=100000055=EUR/USD110=50000010=150
20260109-09:17:42.407792000 : 8=FIX.4.49=043535=X49=NTPRO_IDBA_UAT56=SIRIUS_500007460_MD34=4752=20260109-09:17:41.501262=MD_EURUSD_091721268=6279=0269=0270=1.1396271=10000055=EUR/USD110=0279=0269=0270=1.1396271=50000055=EUR/USD110=100000279=0269=0270=1.1396271=100000055=EUR/USD110=500000279=0269=1270=1.18984271=10000055=EUR/USD110=0279=0269=1270=1.18984271=50000055=EUR/USD110=100000279=0269=1270=1.18984271=100000055=EUR/USD110=50000010=232
20260109-09:17:42.409276000 : 8=FIX.4.49=067535=X49=NTPRO_IDBA_UAT56=SIRIUS_500007460_MD34=4852=20260109-09:17:41.512262=MD_GBPUSD_091722268=10279=1269=0270=1.25146271=10000055=GBP/USD110=0279=1269=0270=1.25146271=50000055=GBP/USD110=100000279=1269=0270=1.25146271=100000055=GBP/USD110=500000279=1269=0270=1.25146271=300000055=GBP/USD110=1000000279=1269=0270=1.25146271=500000055=GBP/USD110=3000000279=1269=1270=1.43178271=10000055=GBP/USD110=0279=1269=1270=1.43178271=50000055=GBP/USD110=100000279=1269=1270=1.43178271=100000055=GBP/USD110=500000279=1269=1270=1.43178271=300000055=GBP/USD110=1000000279=1269=1270=1.43178271=500000055=GBP/USD110=300000010=042
20260109-09:17:42.458110000 : 8=FIX.4.49=043835=X49=NTPRO_IDBA_UAT56=SIRIUS_500007460_MD34=4952=20260109-09:17:41.558262=MD_EURUSD_091721268=6279=1269=0270=1.13959271=10000055=EUR/USD110=0279=1269=0270=1.13959271=50000055=EUR/USD110=100000279=1269=0270=1.13959271=100000055=EUR/USD110=500000279=1269=1270=1.18983271=10000055=EUR/USD110=0279=1269=1270=1.18983271=50000055=EUR/USD110=100000279=1269=1270=1.18983271=100000055=EUR/USD110=50000010=164
20260109-09:17:42.459190000 : 8=FIX.4.49=038935=X49=NTPRO_IDBA_UAT56=SIRIUS_500007460_MD34=5052=20260109-09:17:41.563262=MD_GBPUSD_091722268=5279=1269=0270=1.25145271=10000055=GBP/USD110=0279=1269=0270=1.25145271=50000055=GBP/USD110=100000279=1269=0270=1.25145271=100000055=GBP/USD110=500000279=1269=0270=1.25145271=300000055=GBP/USD110=1000000279=1269=0270=1.25145271=500000055=GBP/USD110=300000010=119
20260109-09:17:43.085431000 : 8=FIX.4.49=027135=X49=NTPRO_IDBA_UAT56=SIRIUS_500007460_MD34=5152=20260109-09:17:42.156262=MD_EURUSD_091721268=3279=1269=1270=1.18984271=10000055=EUR/USD110=0279=1269=1270=1.18984271=50000055=EUR/USD110=100000279=1269=1270=1.18984271=100000055=EUR/USD110=50000010=094
20260109-09:17:47.651114000 : 8=FIX.4.49=038935=X49=NTPRO_IDBA_UAT56=SIRIUS_500007460_MD34=5252=20260109-09:17:46.425262=MD_GBPUSD_091722268=5279=1269=0270=1.25146271=10000055=GBP/USD110=0279=1269=0270=1.25146271=50000055=GBP/USD110=100000279=1269=0270=1.25146271=100000055=GBP/USD110=500000279=1269=0270=1.25146271=300000055=GBP/USD110=1000000279=1269=0270=1.25146271=500000055=GBP/USD110=300000010=128
20260109-09:17:49.645464000 : 8=FIX.4.49=038935=X49=NTPRO_IDBA_UAT56=SIRIUS_500007460_MD34=5352=20260109-09:17:48.292262=MD_GBPUSD_091722268=5279=1269=0270=1.25145271=10000055=GBP/USD110=0279=1269=0270=1.25145271=50000055=GBP/USD110=100000279=1269=0270=1.25145271=100000055=GBP/USD110=500000279=1269=0270=1.25145271=300000055=GBP/USD110=1000000279=1269=0270=1.25145271=500000055=GBP/USD110=300000010=128
20260109-09:17:49.693522000 : 8=FIX.4.49=067535=X49=NTPRO_IDBA_UAT56=SIRIUS_500007460_MD34=5452=20260109-09:17:48.337262=MD_GBPUSD_091722268=10279=1269=0270=1.25148271=10000055=GBP/USD110=0279=1269=0270=1.25148271=50000055=GBP/USD110=100000279=1269=0270=1.25148271=100000055=GBP/USD110=500000279=1269=0270=1.25148271=300000055=GBP/USD110=1000000279=1269=0270=1.25148271=500000055=GBP/USD110=3000000279=1269=1270=1.43179271=10000055=GBP/USD110=0279=1269=1270=1.43179271=50000055=GBP/USD110=100000279=1269=1270=1.43179271=100000055=GBP/USD110=500000279=1269=1270=1.43179271=300000055=GBP/USD110=1000000279=1269=1270=1.43179271=500000055=GBP/USD110=300000010=066
20260109-09:17:49.730484000 : 8=FIX.4.49=026835=X49=NTPRO_IDBA_UAT56=SIRIUS_500007460_MD34=5552=20260109-09:17:48.353262=MD_EURUSD_091721268=3279=1269=0270=1.1396271=10000055=EUR/USD110=0279=1269=0270=1.1396271=50000055=EUR/USD110=100000279=1269=0270=1.1396271=100000055=EUR/USD110=50000010=185
20260109-09:17:49.755918000 : 8=FIX.4.49=067035=X49=NTPRO_IDBA_UAT56=SIRIUS_500007460_MD34=5652=20260109-09:17:48.396262=MD_GBPUSD_091722268=10279=1269=0270=1.2515271=10000055=GBP/USD110=0279=1269=0270=1.2515271=50000055=GBP/USD110=100000279=1269=0270=1.2515271=100000055=GBP/USD110=500000279=1269=0270=1.2515271=300000055=GBP/USD110=1000000279=1269=0270=1.2515271=500000055=GBP/USD110=3000000279=1269=1270=1.43182271=10000055=GBP/USD110=0279=1269=1270=1.43182271=50000055=GBP/USD110=100000279=1269=1270=1.43182271=100000055=GBP/USD110=500000279=1269=1270=1.43182271=300000055=GBP/USD110=1000000279=1269=1270=1.43182271=500000055=GBP/USD110=300000010=019
20260109-09:17:49.763005000 : 8=FIX.4.49=043835=X49=NTPRO_IDBA_UAT56=SIRIUS_500007460_MD34=5752=20260109-09:17:48.401262=MD_EURUSD_091721268=6279=1269=0270=1.13961271=10000055=EUR/USD110=0279=1269=0270=1.13961271=50000055=EUR/USD110=100000279=1269=0270=1.13961271=100000055=EUR/USD110=500000279=1269=1270=1.18985271=10000055=EUR/USD110=0279=1269=1270=1.18985271=50000055=EUR/USD110=100000279=1269=1270=1.18985271=100000055=EUR/USD110=50000010=142
20260109-09:17:49.864758000 : 8=FIX.4.49=007735=049=NTPRO_IDBA_UAT56=SIRIUS_500007460_MD34=5852=20260109-09:17:48.40710=193
20260109-09:17:49.866564000 : 8=FIX.4.49=038435=X49=NTPRO_IDBA_UAT56=SIRIUS_500007460_MD34=5952=20260109-09:17:48.477262=MD_GBPUSD_091722268=5279=1269=1270=1.4318271=10000055=GBP/USD110=0279=1269=1270=1.4318271=50000055=GBP/USD110=100000279=1269=1270=1.4318271=100000055=GBP/USD110=500000279=1269=1270=1.4318271=300000055=GBP/USD110=1000000279=1269=1270=1.4318271=500000055=GBP/USD110=300000010=150
20260109-09:17:49.883984000 : 8=FIX.4.49=038935=X49=NTPRO_IDBA_UAT56=SIRIUS_500007460_MD34=6052=20260109-09:17:48.516262=MD_GBPUSD_091722268=5279=1269=0270=1.25148271=10000055=GBP/USD110=0279=1269=0270=1.25148271=50000055=GBP/USD110=100000279=1269=0270=1.25148271=100000055=GBP/USD110=500000279=1269=0270=1.25148271=300000055=GBP/USD110=1000000279=1269=0270=1.25148271=500000055=GBP/USD110=300000010=140
20260109-09:17:49.892149000 : 8=FIX.4.49=043535=X49=NTPRO_IDBA_UAT56=SIRIUS_500007460_MD34=6152=20260109-09:17:48.524262=MD_EURUSD_091721268=6279=1269=0270=1.1396271=10000055=EUR/USD110=0279=1269=0270=1.1396271=50000055=EUR/USD110=100000279=1269=0270=1.1396271=100000055=EUR/USD110=500000279=1269=1270=1.18984271=10000055=EUR/USD110=0279=1269=1270=1.18984271=50000055=EUR/USD110=100000279=1269=1270=1.18984271=100000055=EUR/USD110=50000010=246
20260109-09:17:50.000716000 : 8=FIX.4.49=038435=X49=NTPRO_IDBA_UAT56=SIRIUS_500007460_MD34=6252=20260109-09:17:48.625262=MD_GBPUSD_091722268=5279=1269=0270=1.2515271=10000055=GBP/USD110=0279=1269=0270=1.2515271=50000055=GBP/USD110=100000279=1269=0270=1.2515271=100000055=GBP/USD110=500000279=1269=0270=1.2515271=300000055=GBP/USD110=1000000279=1269=0270=1.2515271=500000055=GBP/USD110=300000010=119
20260109-09:17:50.077249000 : 8=FIX.4.49=038935=X49=NTPRO_IDBA_UAT56=SIRIUS_500007460_MD34=6352=20260109-09:17:48.697262=MD_GBPUSD_091722268=5279=1269=1270=1.43181271=10000055=GBP/USD110=0279=1269=1270=1.43181271=50000055=GBP/USD110=100000279=1269=1270=1.43181271=100000055=GBP/USD110=500000279=1269=1270=1.43181271=300000055=GBP/USD110=1000000279=1269=1270=1.43181271=500000055=GBP/USD110=300000010=143
20260109-09:17:51.047654000 : 8=FIX.4.49=027135=X49=NTPRO_IDBA_UAT56=SIRIUS_500007460_MD34=6452=20260109-09:17:49.600262=MD_EURUSD_091721268=3279=1269=1270=1.18985271=10000055=EUR/USD110=0279=1269=1270=1.18985271=50000055=EUR/USD110=100000279=1269=1270=1.18985271=100000055=EUR/USD110=50000010=102
20260109-09:17:51.218213000 : 8=FIX.4.49=027135=X49=NTPRO_IDBA_UAT56=SIRIUS_500007460_MD34=6552=20260109-09:17:49.764262=MD_EURUSD_091721268=3279=1269=1270=1.18984271=10000055=EUR/USD110=0279=1269=1270=1.18984271=50000055=EUR/USD110=100000279=1269=1270=1.18984271=100000055=EUR/USD110=50000010=111
20260109-09:17:53.082588000 : 8=FIX.4.49=7635=534=649=SIRIUS_500007460_MD52=20260109-09:17:53.08156=NTPRO_IDBA_UAT10=040
20260109-09:17:53.186752000 : 8=FIX.4.49=010035=549=NTPRO_IDBA_UAT56=SIRIUS_500007460_MD34=6652=20260109-09:17:51.60558=Remote side request10=183
20260109-09:18:17.235461000 : 8=FIX.4.49=10735=A34=149=SIRIUS_500007460_MD52=20260109-09:18:17.22556=NTPRO_IDBA_UAT98=0108=30141=Y554=Df2Hy8nM10=013
20260109-09:18:17.360550000 : 8=FIX.4.49=009435=A49=NTPRO_IDBA_UAT56=SIRIUS_500007460_MD34=152=20260109-09:18:16.09298=0108=30141=Y10=215
20260109-09:18:17.361439000 : 8=FIX.4.49=011135=h49=NTPRO_IDBA_UAT56=SIRIUS_500007460_MD34=252=20260109-09:18:16.092336=Market Data340=258=version 510=148
20260109-09:18:19.389842000 : 8=FIX.4.49=15035=V34=249=SIRIUS_500007460_MD52=20260109-09:18:19.38856=NTPRO_IDBA_UAT146=155=EUR/USD262=MD_EURUSD_091819263=1264=1265=1267=2269=0269=110=190
20260109-09:18:19.541465000 : 8=FIX.4.49=038235=W49=NTPRO_IDBA_UAT56=SIRIUS_500007460_MD34=352=20260109-09:18:18.121262=MD_EURUSD_09181955=EUR/USD268=6269=0270=1.13963271=100000299=1110=0269=0270=1.13963271=500000299=2110=100000269=0270=1.13963271=1000000299=3110=500000269=1270=1.18988271=100000299=4110=0269=1270=1.18988271=500000299=5110=100000269=1270=1.18988271=1000000299=6110=50000010=022
20260109-09:18:19.732309000 : 8=FIX.4.49=043735=X49=NTPRO_IDBA_UAT56=SIRIUS_500007460_MD34=452=20260109-09:18:18.314262=MD_EURUSD_091819268=6279=1269=0270=1.13964271=10000055=EUR/USD110=0279=1269=0270=1.13964271=50000055=EUR/USD110=100000279=1269=0270=1.13964271=100000055=EUR/USD110=500000279=1269=1270=1.18989271=10000055=EUR/USD110=0279=1269=1270=1.18989271=50000055=EUR/USD110=100000279=1269=1270=1.18989271=100000055=EUR/USD110=50000010=115
20260109-09:18:20.460543000 : 8=FIX.4.49=15035=V34=349=SIRIUS_500007460_MD52=20260109-09:18:20.45656=NTPRO_IDBA_UAT146=155=GBP/USD262=MD_GBPUSD_091820263=1264=1265=1267=2269=0269=110=133
20260109-09:18:20.580857000 : 8=FIX.4.49=057635=W49=NTPRO_IDBA_UAT56=SIRIUS_500007460_MD34=552=20260109-09:18:19.114262=MD_GBPUSD_09182055=GBP/USD268=10269=0270=1.25152271=100000299=1110=0269=0270=1.25152271=500000299=2110=100000269=0270=1.25152271=1000000299=3110=500000269=0270=1.25152271=3000000299=4110=1000000269=0270=1.25152271=5000000299=5110=3000000269=1270=1.43185271=100000299=6110=0269=1270=1.43185271=500000299=7110=100000269=1270=1.43185271=1000000299=8110=500000269=1270=1.43185271=3000000299=9110=1000000269=1270=1.43185271=5000000299=10110=300000010=200
20260109-09:18:21.162665000 : 8=FIX.4.49=043735=X49=NTPRO_IDBA_UAT56=SIRIUS_500007460_MD34=652=20260109-09:18:19.658262=MD_EURUSD_091819268=6279=1269=0270=1.13962271=10000055=EUR/USD110=0279=1269=0270=1.13962271=50000055=EUR/USD110=100000279=1269=0270=1.13962271=100000055=EUR/USD110=500000279=1269=1270=1.18986271=10000055=EUR/USD110=0279=1269=1270=1.18986271=50000055=EUR/USD110=100000279=1269=1270=1.18986271=100000055=EUR/USD110=50000010=114
20260109-09:18:21.185899000 : 8=FIX.4.49=038835=X49=NTPRO_IDBA_UAT56=SIRIUS_500007460_MD34=752=20260109-09:18:19.678262=MD_GBPUSD_091820268=5279=1269=1270=1.43183271=10000055=GBP/USD110=0279=1269=1270=1.43183271=50000055=GBP/USD110=100000279=1269=1270=1.43183271=100000055=GBP/USD110=500000279=1269=1270=1.43183271=300000055=GBP/USD110=1000000279=1269=1270=1.43183271=500000055=GBP/USD110=300000010=099
20260109-09:18:21.230765000 : 8=FIX.4.49=043735=X49=NTPRO_IDBA_UAT56=SIRIUS_500007460_MD34=852=20260109-09:18:19.719262=MD_EURUSD_091819268=6279=1269=0270=1.13959271=10000055=EUR/USD110=0279=1269=0270=1.13959271=50000055=EUR/USD110=100000279=1269=0270=1.13959271=100000055=EUR/USD110=500000279=1269=1270=1.18984271=10000055=EUR/USD110=0279=1269=1270=1.18984271=50000055=EUR/USD110=100000279=1269=1270=1.18984271=100000055=EUR/USD110=50000010=126
20260109-09:18:21.307708000 : 8=FIX.4.49=067435=X49=NTPRO_IDBA_UAT56=SIRIUS_500007460_MD34=952=20260109-09:18:19.794262=MD_GBPUSD_091820268=10279=1269=0270=1.25145271=10000055=GBP/USD110=0279=1269=0270=1.25145271=50000055=GBP/USD110=100000279=1269=0270=1.25145271=100000055=GBP/USD110=500000279=1269=0270=1.25145271=300000055=GBP/USD110=1000000279=1269=0270=1.25145271=500000055=GBP/USD110=3000000279=1269=1270=1.43179271=10000055=GBP/USD110=0279=1269=1270=1.43179271=50000055=GBP/USD110=100000279=1269=1270=1.43179271=100000055=GBP/USD110=500000279=1269=1270=1.43179271=300000055=GBP/USD110=1000000279=1269=1270=1.43179271=500000055=GBP/USD110=300000010=007
20260109-09:18:21.394853000 : 8=FIX.4.49=15035=V34=449=SIRIUS_500007460_MD52=20260109-09:18:21.39256=NTPRO_IDBA_UAT146=155=USD/JPY262=MD_USDJPY_091821263=1264=1265=1267=2269=0269=110=187
20260109-09:18:21.401755000 : 8=FIX.4.49=038935=X49=NTPRO_IDBA_UAT56=SIRIUS_500007460_MD34=1052=20260109-09:18:19.878262=MD_GBPUSD_091820268=5279=1269=0270=1.25146271=10000055=GBP/USD110=0279=1269=0270=1.25146271=50000055=GBP/USD110=100000279=1269=0270=1.25146271=100000055=GBP/USD110=500000279=1269=0270=1.25146271=300000055=GBP/USD110=1000000279=1269=0270=1.25146271=500000055=GBP/USD110=300000010=134
20260109-09:18:21.503877000 : 8=FIX.4.49=011535=W49=NTPRO_IDBA_UAT56=SIRIUS_500007460_MD34=1152=20260109-09:18:19.976262=MD_USDJPY_09182155=USD/JPY268=010=223
20260109-09:18:21.558076000 : 8=FIX.4.49=038935=X49=NTPRO_IDBA_UAT56=SIRIUS_500007460_MD34=1252=20260109-09:18:20.027262=MD_GBPUSD_091820268=5279=1269=0270=1.25145271=10000055=GBP/USD110=0279=1269=0270=1.25145271=50000055=GBP/USD110=100000279=1269=0270=1.25145271=100000055=GBP/USD110=500000279=1269=0270=1.25145271=300000055=GBP/USD110=1000000279=1269=0270=1.25145271=500000055=GBP/USD110=300000010=109
20260109-09:18:21.693676000 : 8=FIX.4.49=067535=X49=NTPRO_IDBA_UAT56=SIRIUS_500007460_MD34=1352=20260109-09:18:20.154262=MD_GBPUSD_091820268=10279=1269=0270=1.25146271=10000055=GBP/USD110=0279=1269=0270=1.25146271=50000055=GBP/USD110=100000279=1269=0270=1.25146271=100000055=GBP/USD110=500000279=1269=0270=1.25146271=300000055=GBP/USD110=1000000279=1269=0270=1.25146271=500000055=GBP/USD110=3000000279=1269=1270=1.43178271=10000055=GBP/USD110=0279=1269=1270=1.43178271=50000055=GBP/USD110=100000279=1269=1270=1.43178271=100000055=GBP/USD110=500000279=1269=1270=1.43178271=300000055=GBP/USD110=1000000279=1269=1270=1.43178271=500000055=GBP/USD110=300000010=033
20260109-09:18:22.086781000 : 8=FIX.4.49=026835=X49=NTPRO_IDBA_UAT56=SIRIUS_500007460_MD34=1452=20260109-09:18:20.520262=MD_EURUSD_091819268=3279=1269=0270=1.1396271=10000055=EUR/USD110=0279=1269=0270=1.1396271=50000055=EUR/USD110=100000279=1269=0270=1.1396271=100000055=EUR/USD110=50000010=175
20260109-09:18:22.224013000 : 8=FIX.4.49=027135=X49=NTPRO_IDBA_UAT56=SIRIUS_500007460_MD34=1552=20260109-09:18:20.640262=MD_EURUSD_091819268=3279=1269=0270=1.13959271=10000055=EUR/USD110=0279=1269=0270=1.13959271=50000055=EUR/USD110=100000279=1269=0270=1.13959271=100000055=EUR/USD110=50000010=085
20260109-09:18:22.389301000 : 8=FIX.4.49=038935=X49=NTPRO_IDBA_UAT56=SIRIUS_500007460_MD34=1652=20260109-09:18:20.799262=MD_GBPUSD_091820268=5279=1269=0270=1.25145271=10000055=GBP/USD110=0279=1269=0270=1.25145271=50000055=GBP/USD110=100000279=1269=0270=1.25145271=100000055=GBP/USD110=500000279=1269=0270=1.25145271=300000055=GBP/USD110=1000000279=1269=0270=1.25145271=500000055=GBP/USD110=300000010=129
20260109-09:18:22.397466000 : 8=FIX.4.49=15035=V34=549=SIRIUS_500007460_MD52=20260109-09:18:22.39556=NTPRO_IDBA_UAT146=155=EUR/GBP262=MD_EURGBP_091822263=1264=1265=1267=2269=0269=110=141
20260109-09:18:22.508126000 : 8=FIX.4.49=011535=W49=NTPRO_IDBA_UAT56=SIRIUS_500007460_MD34=1752=20260109-09:18:20.915262=MD_EURGBP_09182255=EUR/GBP268=010=163
20260109-09:18:22.629831000 : 8=FIX.4.49=038935=X49=NTPRO_IDBA_UAT56=SIRIUS_500007460_MD34=1852=20260109-09:18:21.028262=MD_GBPUSD_091820268=5279=1269=0270=1.25146271=10000055=GBP/USD110=0279=1269=0270=1.25146271=50000055=GBP/USD110=100000279=1269=0270=1.25146271=100000055=GBP/USD110=500000279=1269=0270=1.25146271=300000055=GBP/USD110=1000000279=1269=0270=1.25146271=500000055=GBP/USD110=300000010=122
20260109-09:18:22.759706000 : 8=FIX.4.49=038935=X49=NTPRO_IDBA_UAT56=SIRIUS_500007460_MD34=1952=20260109-09:18:21.150262=MD_GBPUSD_091820268=5279=1269=0270=1.25145271=10000055=GBP/USD110=0279=1269=0270=1.25145271=50000055=GBP/USD110=100000279=1269=0270=1.25145271=100000055=GBP/USD110=500000279=1269=0270=1.25145271=300000055=GBP/USD110=1000000279=1269=0270=1.25145271=500000055=GBP/USD110=300000010=114
20260109-09:18:23.848627000 : 8=FIX.4.49=026835=X49=NTPRO_IDBA_UAT56=SIRIUS_500007460_MD34=2052=20260109-09:18:22.168262=MD_EURUSD_091819268=3279=1269=0270=1.1396271=10000055=EUR/USD110=0279=1269=0270=1.1396271=50000055=EUR/USD110=100000279=1269=0270=1.1396271=100000055=EUR/USD110=50000010=182
20260109-09:18:24.602844000 : 8=FIX.4.49=038935=X49=NTPRO_IDBA_UAT56=SIRIUS_500007460_MD34=2152=20260109-09:18:22.872262=MD_GBPUSD_091820268=5279=1269=0270=1.25146271=10000055=GBP/USD110=0279=1269=0270=1.25146271=50000055=GBP/USD110=100000279=1269=0270=1.25146271=100000055=GBP/USD110=500000279=1269=0270=1.25146271=300000055=GBP/USD110=1000000279=1269=0270=1.25146271=500000055=GBP/USD110=300000010=124
20260109-09:18:26.052273000 : 8=FIX.4.49=038935=X49=NTPRO_IDBA_UAT56=SIRIUS_500007460_MD34=2252=20260109-09:18:24.227262=MD_GBPUSD_091820268=5279=1269=1270=1.43179271=10000055=GBP/USD110=0279=1269=1270=1.43179271=50000055=GBP/USD110=100000279=1269=1270=1.43179271=100000055=GBP/USD110=500000279=1269=1270=1.43179271=300000055=GBP/USD110=1000000279=1269=1270=1.43179271=500000055=GBP/USD110=300000010=156
20260109-09:18:26.089307000 : 8=FIX.4.49=067535=X49=NTPRO_IDBA_UAT56=SIRIUS_500007460_MD34=2352=20260109-09:18:24.255262=MD_GBPUSD_091820268=10279=1269=0270=1.25145271=10000055=GBP/USD110=0279=1269=0270=1.25145271=50000055=GBP/USD110=100000279=1269=0270=1.25145271=100000055=GBP/USD110=500000279=1269=0270=1.25145271=300000055=GBP/USD110=1000000279=1269=0270=1.25145271=500000055=GBP/USD110=3000000279=1269=1270=1.43178271=10000055=GBP/USD110=0279=1269=1270=1.43178271=50000055=GBP/USD110=100000279=1269=1270=1.43178271=100000055=GBP/USD110=500000279=1269=1270=1.43178271=300000055=GBP/USD110=1000000279=1269=1270=1.43178271=500000055=GBP/USD110=300000010=035
20260109-09:18:26.203632000 : 8=FIX.4.49=067535=X49=NTPRO_IDBA_UAT56=SIRIUS_500007460_MD34=2452=20260109-09:18:24.368262=MD_GBPUSD_091820268=10279=1269=0270=1.25146271=10000055=GBP/USD110=0279=1269=0270=1.25146271=50000055=GBP/USD110=100000279=1269=0270=1.25146271=100000055=GBP/USD110=500000279=1269=0270=1.25146271=300000055=GBP/USD110=1000000279=1269=0270=1.25146271=500000055=GBP/USD110=3000000279=1269=1270=1.43179271=10000055=GBP/USD110=0279=1269=1270=1.43179271=50000055=GBP/USD110=100000279=1269=1270=1.43179271=100000055=GBP/USD110=500000279=1269=1270=1.43179271=300000055=GBP/USD110=1000000279=1269=1270=1.43179271=500000055=GBP/USD110=300000010=051
20260109-09:18:27.196293000 : 8=FIX.4.49=043835=X49=NTPRO_IDBA_UAT56=SIRIUS_500007460_MD34=2552=20260109-09:18:25.298262=MD_EURUSD_091819268=6279=1269=0270=1.13962271=10000055=EUR/USD110=0279=1269=0270=1.13962271=50000055=EUR/USD110=100000279=1269=0270=1.13962271=100000055=EUR/USD110=500000279=1269=1270=1.18986271=10000055=EUR/USD110=0279=1269=1270=1.18986271=50000055=EUR/USD110=100000279=1269=1270=1.18986271=100000055=EUR/USD110=50000010=161
20260109-09:18:27.349201000 : 8=FIX.4.49=067535=X49=NTPRO_IDBA_UAT56=SIRIUS_500007460_MD34=2652=20260109-09:18:25.440262=MD_GBPUSD_091820268=10279=2269=0270=1.25146271=10000055=GBP/USD110=0279=2269=0270=1.25146271=50000055=GBP/USD110=100000279=2269=0270=1.25146271=100000055=GBP/USD110=500000279=2269=0270=1.25146271=300000055=GBP/USD110=1000000279=2269=0270=1.25146271=500000055=GBP/USD110=3000000279=2269=1270=1.43179271=10000055=GBP/USD110=0279=2269=1270=1.43179271=50000055=GBP/USD110=100000279=2269=1270=1.43179271=100000055=GBP/USD110=500000279=2269=1270=1.43179271=300000055=GBP/USD110=1000000279=2269=1270=1.43179271=500000055=GBP/USD110=300000010=055
20260109-09:18:27.364809000 : 8=FIX.4.49=043835=X49=NTPRO_IDBA_UAT56=SIRIUS_500007460_MD34=2752=20260109-09:18:25.455262=MD_EURUSD_091819268=6279=1269=0270=1.13961271=10000055=EUR/USD110=0279=1269=0270=1.13961271=50000055=EUR/USD110=100000279=1269=0270=1.13961271=100000055=EUR/USD110=500000279=1269=1270=1.18985271=10000055=EUR/USD110=0279=1269=1270=1.18985271=50000055=EUR/USD110=100000279=1269=1270=1.18985271=100000055=EUR/USD110=50000010=152
20260109-09:18:27.593221000 : 8=FIX.4.49=067535=X49=NTPRO_IDBA_UAT56=SIRIUS_500007460_MD34=2852=20260109-09:18:25.529262=MD_GBPUSD_091820268=10279=0269=0270=1.25145271=10000055=GBP/USD110=0279=0269=0270=1.25145271=50000055=GBP/USD110=100000279=0269=0270=1.25145271=100000055=GBP/USD110=500000279=0269=0270=1.25145271=300000055=GBP/USD110=1000000279=0269=0270=1.25145271=500000055=GBP/USD110=3000000279=0269=1270=1.43178271=10000055=GBP/USD110=0279=0269=1270=1.43178271=50000055=GBP/USD110=100000279=0269=1270=1.43178271=100000055=GBP/USD110=500000279=0269=1270=1.43178271=300000055=GBP/USD110=1000000279=0269=1270=1.43178271=500000055=GBP/USD110=300000010=035
20260109-09:18:27.594365000 : 8=FIX.4.49=026835=X49=NTPRO_IDBA_UAT56=SIRIUS_500007460_MD34=2952=20260109-09:18:25.546262=MD_EURUSD_091819268=3279=1269=0270=1.1396271=10000055=EUR/USD110=0279=1269=0270=1.1396271=50000055=EUR/USD110=100000279=1269=0270=1.1396271=100000055=EUR/USD110=50000010=194
20260109-09:18:27.594928000 : 8=FIX.4.49=038935=X49=NTPRO_IDBA_UAT56=SIRIUS_500007460_MD34=3052=20260109-09:18:25.604262=MD_GBPUSD_091820268=5279=1269=0270=1.25146271=10000055=GBP/USD110=0279=1269=0270=1.25146271=50000055=GBP/USD110=100000279=1269=0270=1.25146271=100000055=GBP/USD110=500000279=1269=0270=1.25146271=300000055=GBP/USD110=1000000279=1269=0270=1.25146271=500000055=GBP/USD110=300000010=120
20260109-09:18:27.929266000 : 8=FIX.4.49=038935=X49=NTPRO_IDBA_UAT56=SIRIUS_500007460_MD34=3152=20260109-09:18:25.982262=MD_GBPUSD_091820268=5279=1269=0270=1.25145271=10000055=GBP/USD110=0279=1269=0270=1.25145271=50000055=GBP/USD110=100000279=1269=0270=1.25145271=100000055=GBP/USD110=500000279=1269=0270=1.25145271=300000055=GBP/USD110=1000000279=1269=0270=1.25145271=500000055=GBP/USD110=300000010=125
20260109-09:18:28.064555000 : 8=FIX.4.49=038935=X49=NTPRO_IDBA_UAT56=SIRIUS_500007460_MD34=3252=20260109-09:18:26.108262=MD_GBPUSD_091820268=5279=1269=0270=1.25146271=10000055=GBP/USD110=0279=1269=0270=1.25146271=50000055=GBP/USD110=100000279=1269=0270=1.25146271=100000055=GBP/USD110=500000279=1269=0270=1.25146271=300000055=GBP/USD110=1000000279=1269=0270=1.25146271=500000055=GBP/USD110=300000010=122
20260109-09:18:26.837359000 : 8=FIX.4.49=038935=X49=NTPRO_IDBA_UAT56=SIRIUS_500007460_MD34=3352=20260109-09:18:26.781262=MD_GBPUSD_091820268=5279=1269=1270=1.43179271=10000055=GBP/USD110=0279=1269=1270=1.43179271=50000055=GBP/USD110=100000279=1269=1270=1.43179271=100000055=GBP/USD110=500000279=1269=1270=1.43179271=300000055=GBP/USD110=1000000279=1269=1270=1.43179271=500000055=GBP/USD110=300000010=165
20260109-09:18:26.910075000 : 8=FIX.4.49=067535=X49=NTPRO_IDBA_UAT56=SIRIUS_500007460_MD34=3452=20260109-09:18:26.848262=MD_GBPUSD_091820268=10279=1269=0270=1.25145271=10000055=GBP/USD110=0279=1269=0270=1.25145271=50000055=GBP/USD110=100000279=1269=0270=1.25145271=100000055=GBP/USD110=500000279=1269=0270=1.25145271=300000055=GBP/USD110=1000000279=1269=0270=1.25145271=500000055=GBP/USD110=3000000279=1269=1270=1.43178271=10000055=GBP/USD110=0279=1269=1270=1.43178271=50000055=GBP/USD110=100000279=1269=1270=1.43178271=100000055=GBP/USD110=500000279=1269=1270=1.43178271=300000055=GBP/USD110=1000000279=1269=1270=1.43178271=500000055=GBP/USD110=300000010=047
20260109-09:18:27.680921000 : 8=FIX.4.49=027135=X49=NTPRO_IDBA_UAT56=SIRIUS_500007460_MD34=3552=20260109-09:18:27.569262=MD_EURUSD_091819268=3279=1269=1270=1.18984271=10000055=EUR/USD110=0279=1269=1270=1.18984271=50000055=EUR/USD110=100000279=1269=1270=1.18984271=100000055=EUR/USD110=50000010=116
20260109-09:18:27.839989000 : 8=FIX.4.49=027135=X49=NTPRO_IDBA_UAT56=SIRIUS_500007460_MD34=3652=20260109-09:18:27.718262=MD_EURUSD_091819268=3279=1269=0270=1.13959271=10000055=EUR/USD110=0279=1269=0270=1.13959271=50000055=EUR/USD110=100000279=1269=0270=1.13959271=100000055=EUR/USD110=50000010=101
20260109-09:18:27.850917000 : 8=FIX.4.49=067535=X49=NTPRO_IDBA_UAT56=SIRIUS_500007460_MD34=3752=20260109-09:18:27.729262=MD_GBPUSD_091820268=10279=1269=0270=1.25144271=10000055=GBP/USD110=0279=1269=0270=1.25144271=50000055=GBP/USD110=100000279=1269=0270=1.25144271=100000055=GBP/USD110=500000279=1269=0270=1.25144271=300000055=GBP/USD110=1000000279=1269=0270=1.25144271=500000055=GBP/USD110=3000000279=1269=1270=1.43177271=10000055=GBP/USD110=0279=1269=1270=1.43177271=50000055=GBP/USD110=100000279=1269=1270=1.43177271=100000055=GBP/USD110=500000279=1269=1270=1.43177271=300000055=GBP/USD110=1000000279=1269=1270=1.43177271=500000055=GBP/USD110=300000010=039
20260109-09:18:27.965847000 : 8=FIX.4.49=026835=X49=NTPRO_IDBA_UAT56=SIRIUS_500007460_MD34=3852=20260109-09:18:27.836262=MD_EURUSD_091819268=3279=1269=0270=1.1396271=10000055=EUR/USD110=0279=1269=0270=1.1396271=50000055=EUR/USD110=100000279=1269=0270=1.1396271=100000055=EUR/USD110=50000010=198
20260109-09:18:28.384354000 : 8=FIX.4.49=067535=X49=NTPRO_IDBA_UAT56=SIRIUS_500007460_MD34=3952=20260109-09:18:28.228262=MD_GBPUSD_091820268=10279=1269=0270=1.25145271=10000055=GBP/USD110=0279=1269=0270=1.25145271=50000055=GBP/USD110=100000279=1269=0270=1.25145271=100000055=GBP/USD110=500000279=1269=0270=1.25145271=300000055=GBP/USD110=1000000279=1269=0270=1.25145271=500000055=GBP/USD110=3000000279=1269=1270=1.43178271=10000055=GBP/USD110=0279=1269=1270=1.43178271=50000055=GBP/USD110=100000279=1269=1270=1.43178271=100000055=GBP/USD110=500000279=1269=1270=1.43178271=300000055=GBP/USD110=1000000279=1269=1270=1.43178271=500000055=GBP/USD110=300000010=046
20260109-09:18:28.605133000 : 8=FIX.4.49=038935=X49=NTPRO_IDBA_UAT56=SIRIUS_500007460_MD34=4052=20260109-09:18:28.433262=MD_GBPUSD_091820268=5279=1269=1270=1.43179271=10000055=GBP/USD110=0279=1269=1270=1.43179271=50000055=GBP/USD110=100000279=1269=1270=1.43179271=100000055=GBP/USD110=500000279=1269=1270=1.43179271=300000055=GBP/USD110=1000000279=1269=1270=1.43179271=500000055=GBP/USD110=300000010=159
20260109-09:18:29.301761000 : 8=FIX.4.49=038935=X49=NTPRO_IDBA_UAT56=SIRIUS_500007460_MD34=4152=20260109-09:18:29.068262=MD_GBPUSD_091820268=5279=1269=1270=1.43178271=10000055=GBP/USD110=0279=1269=1270=1.43178271=50000055=GBP/USD110=100000279=1269=1270=1.43178271=100000055=GBP/USD110=500000279=1269=1270=1.43178271=300000055=GBP/USD110=1000000279=1269=1270=1.43178271=500000055=GBP/USD110=300000010=160
20260109-09:18:30.518709000 : 8=FIX.4.49=067535=X49=NTPRO_IDBA_UAT56=SIRIUS_500007460_MD34=4252=20260109-09:18:30.224262=MD_GBPUSD_091820268=10279=2269=0270=1.25145271=10000055=GBP/USD110=0279=2269=0270=1.25145271=50000055=GBP/USD110=100000279=2269=0270=1.25145271=100000055=GBP/USD110=500000279=2269=0270=1.25145271=300000055=GBP/USD110=1000000279=2269=0270=1.25145271=500000055=GBP/USD110=3000000279=2269=1270=1.43178271=10000055=GBP/USD110=0279=2269=1270=1.43178271=50000055=GBP/USD110=100000279=2269=1270=1.43178271=100000055=GBP/USD110=500000279=2269=1270=1.43178271=300000055=GBP/USD110=1000000279=2269=1270=1.43178271=500000055=GBP/USD110=300000010=039
20260109-09:18:30.642736000 : 8=FIX.4.49=027135=X49=NTPRO_IDBA_UAT56=SIRIUS_500007460_MD34=4352=20260109-09:18:30.337262=MD_EURUSD_091819268=3279=1269=0270=1.13959271=10000055=EUR/USD110=0279=1269=0270=1.13959271=50000055=EUR/USD110=100000279=1269=0270=1.13959271=100000055=EUR/USD110=50000010=090
20260109-09:18:30.643757000 : 8=FIX.4.49=067535=X49=NTPRO_IDBA_UAT56=SIRIUS_500007460_MD34=4452=20260109-09:18:30.338262=MD_GBPUSD_091820268=10279=0269=0270=1.25145271=10000055=GBP/USD110=0279=0269=0270=1.25145271=50000055=GBP/USD110=100000279=0269=0270=1.25145271=100000055=GBP/USD110=500000279=0269=0270=1.25145271=300000055=GBP/USD110=1000000279=0269=0270=1.25145271=500000055=GBP/USD110=3000000279=0269=1270=1.43178271=10000055=GBP/USD110=0279=0269=1270=1.43178271=50000055=GBP/USD110=100000279=0269=1270=1.43178271=100000055=GBP/USD110=500000279=0269=1270=1.43178271=300000055=GBP/USD110=1000000279=0269=1270=1.43178271=500000055=GBP/USD110=300000010=027
20260109-09:18:30.690971000 : 8=FIX.4.49=026835=X49=NTPRO_IDBA_UAT56=SIRIUS_500007460_MD34=4552=20260109-09:18:30.385262=MD_EURUSD_091819268=3279=1269=0270=1.1396271=10000055=EUR/USD110=0279=1269=0270=1.1396271=50000055=EUR/USD110=100000279=1269=0270=1.1396271=100000055=EUR/USD110=50000010=189
20260109-09:18:30.885575000 : 8=FIX.4.49=038935=X49=NTPRO_IDBA_UAT56=SIRIUS_500007460_MD34=4652=20260109-09:18:30.560262=MD_GBPUSD_091820268=5279=1269=1270=1.43179271=10000055=GBP/USD110=0279=1269=1270=1.43179271=50000055=GBP/USD110=100000279=1269=1270=1.43179271=100000055=GBP/USD110=500000279=1269=1270=1.43179271=300000055=GBP/USD110=1000000279=1269=1270=1.43179271=500000055=GBP/USD110=300000010=159
20260109-09:18:31.027099000 : 8=FIX.4.49=038935=X49=NTPRO_IDBA_UAT56=SIRIUS_500007460_MD34=4752=20260109-09:18:30.698262=MD_GBPUSD_091820268=5279=1269=1270=1.43178271=10000055=GBP/USD110=0279=1269=1270=1.43178271=50000055=GBP/USD110=100000279=1269=1270=1.43178271=100000055=GBP/USD110=500000279=1269=1270=1.43178271=300000055=GBP/USD110=1000000279=1269=1270=1.43178271=500000055=GBP/USD110=300000010=167
20260109-09:18:31.299642000 : 8=FIX.4.49=043835=X49=NTPRO_IDBA_UAT56=SIRIUS_500007460_MD34=4852=20260109-09:18:30.954262=MD_EURUSD_091819268=6279=1269=0270=1.13959271=10000055=EUR/USD110=0279=1269=0270=1.13959271=50000055=EUR/USD110=100000279=1269=0270=1.13959271=100000055=EUR/USD110=500000279=1269=1270=1.18983271=10000055=EUR/USD110=0279=1269=1270=1.18983271=50000055=EUR/USD110=100000279=1269=1270=1.18983271=100000055=EUR/USD110=50000010=170
20260109-09:18:31.582230000 : 8=FIX.4.49=038935=X49=NTPRO_IDBA_UAT56=SIRIUS_500007460_MD34=4952=20260109-09:18:31.219262=MD_GBPUSD_091820268=5279=1269=0270=1.25144271=10000055=GBP/USD110=0279=1269=0270=1.25144271=50000055=GBP/USD110=100000279=1269=0270=1.25144271=100000055=GBP/USD110=500000279=1269=0270=1.25144271=300000055=GBP/USD110=1000000279=1269=0270=1.25144271=500000055=GBP/USD110=300000010=119
20260109-09:18:31.665972000 : 8=FIX.4.49=038935=X49=NTPRO_IDBA_UAT56=SIRIUS_500007460_MD34=5052=20260109-09:18:31.297262=MD_GBPUSD_091820268=5279=1269=1270=1.43177271=10000055=GBP/USD110=0279=1269=1270=1.43177271=50000055=GBP/USD110=100000279=1269=1270=1.43177271=100000055=GBP/USD110=500000279=1269=1270=1.43177271=300000055=GBP/USD110=1000000279=1269=1270=1.43177271=500000055=GBP/USD110=300000010=152
20260109-09:18:31.796834000 : 8=FIX.4.49=038935=X49=NTPRO_IDBA_UAT56=SIRIUS_500007460_MD34=5152=20260109-09:18:31.419262=MD_GBPUSD_091820268=5279=1269=1270=1.43178271=10000055=GBP/USD110=0279=1269=1270=1.43178271=50000055=GBP/USD110=100000279=1269=1270=1.43178271=100000055=GBP/USD110=500000279=1269=1270=1.43178271=300000055=GBP/USD110=1000000279=1269=1270=1.43178271=500000055=GBP/USD110=300000010=154
20260109-09:18:31.819852000 : 8=FIX.4.49=038935=X49=NTPRO_IDBA_UAT56=SIRIUS_500007460_MD34=5252=20260109-09:18:31.440262=MD_GBPUSD_091820268=5279=1269=0270=1.25145271=10000055=GBP/USD110=0279=1269=0270=1.25145271=50000055=GBP/USD110=100000279=1269=0270=1.25145271=100000055=GBP/USD110=500000279=1269=0270=1.25145271=300000055=GBP/USD110=1000000279=1269=0270=1.25145271=500000055=GBP/USD110=300000010=114
20260109-09:18:34.234403000 : 8=FIX.4.49=067535=X49=NTPRO_IDBA_UAT56=SIRIUS_500007460_MD34=5352=20260109-09:18:33.700262=MD_GBPUSD_091820268=10279=2269=0270=1.25145271=10000055=GBP/USD110=0279=2269=0270=1.25145271=50000055=GBP/USD110=100000279=2269=0270=1.25145271=100000055=GBP/USD110=500000279=2269=0270=1.25145271=300000055=GBP/USD110=1000000279=2269=0270=1.25145271=500000055=GBP/USD110=3000000279=2269=1270=1.43178271=10000055=GBP/USD110=0279=2269=1270=1.43178271=50000055=GBP/USD110=100000279=2269=1270=1.43178271=100000055=GBP/USD110=500000279=2269=1270=1.43178271=300000055=GBP/USD110=1000000279=2269=1270=1.43178271=500000055=GBP/USD110=300000010=043
20260109-09:18:34.637966000 : 8=FIX.4.49=067535=X49=NTPRO_IDBA_UAT56=SIRIUS_500007460_MD34=5452=20260109-09:18:34.076262=MD_GBPUSD_091820268=10279=0269=0270=1.25145271=10000055=GBP/USD110=0279=0269=0270=1.25145271=50000055=GBP/USD110=100000279=0269=0270=1.25145271=100000055=GBP/USD110=500000279=0269=0270=1.25145271=300000055=GBP/USD110=1000000279=0269=0270=1.25145271=500000055=GBP/USD110=3000000279=0269=1270=1.43178271=10000055=GBP/USD110=0279=0269=1270=1.43178271=50000055=GBP/USD110=100000279=0269=1270=1.43178271=100000055=GBP/USD110=500000279=0269=1270=1.43178271=300000055=GBP/USD110=1000000279=0269=1270=1.43178271=500000055=GBP/USD110=300000010=031
20260109-09:18:35.548874000 : 8=FIX.4.49=067535=X49=NTPRO_IDBA_UAT56=SIRIUS_500007460_MD34=5552=20260109-09:18:34.927262=MD_GBPUSD_091820268=10279=2269=0270=1.25145271=10000055=GBP/USD110=0279=2269=0270=1.25145271=50000055=GBP/USD110=100000279=2269=0270=1.25145271=100000055=GBP/USD110=500000279=2269=0270=1.25145271=300000055=GBP/USD110=1000000279=2269=0270=1.25145271=500000055=GBP/USD110=3000000279=2269=1270=1.43178271=10000055=GBP/USD110=0279=2269=1270=1.43178271=50000055=GBP/USD110=100000279=2269=1270=1.43178271=100000055=GBP/USD110=500000279=2269=1270=1.43178271=300000055=GBP/USD110=1000000279=2269=1270=1.43178271=500000055=GBP/USD110=300000010=057
20260109-09:18:36.668622000 : 8=FIX.4.49=067535=X49=NTPRO_IDBA_UAT56=SIRIUS_500007460_MD34=5652=20260109-09:18:35.977262=MD_GBPUSD_091820268=10279=0269=0270=1.25145271=10000055=GBP/USD110=0279=0269=0270=1.25145271=50000055=GBP/USD110=100000279=0269=0270=1.25145271=100000055=GBP/USD110=500000279=0269=0270=1.25145271=300000055=GBP/USD110=1000000279=0269=0270=1.25145271=500000055=GBP/USD110=3000000279=0269=1270=1.43178271=10000055=GBP/USD110=0279=0269=1270=1.43178271=50000055=GBP/USD110=100000279=0269=1270=1.43178271=100000055=GBP/USD110=500000279=0269=1270=1.43178271=300000055=GBP/USD110=1000000279=0269=1270=1.43178271=500000055=GBP/USD110=300000010=044
20260109-09:18:37.662360000 : 8=FIX.4.49=038935=X49=NTPRO_IDBA_UAT56=SIRIUS_500007460_MD34=5752=20260109-09:18:36.907262=MD_GBPUSD_091820268=5279=1269=1270=1.43179271=10000055=GBP/USD110=0279=1269=1270=1.43179271=50000055=GBP/USD110=100000279=1269=1270=1.43179271=100000055=GBP/USD110=500000279=1269=1270=1.43179271=300000055=GBP/USD110=1000000279=1269=1270=1.43179271=500000055=GBP/USD110=300000010=172
20260109-09:18:37.786047000 : 8=FIX.4.49=067535=X49=NTPRO_IDBA_UAT56=SIRIUS_500007460_MD34=5852=20260109-09:18:37.023262=MD_GBPUSD_091820268=10279=2269=0270=1.25145271=10000055=GBP/USD110=0279=2269=0270=1.25145271=50000055=GBP/USD110=100000279=2269=0270=1.25145271=100000055=GBP/USD110=500000279=2269=0270=1.25145271=300000055=GBP/USD110=1000000279=2269=0270=1.25145271=500000055=GBP/USD110=3000000279=2269=1270=1.43179271=10000055=GBP/USD110=0279=2269=1270=1.43179271=50000055=GBP/USD110=100000279=2269=1270=1.43179271=100000055=GBP/USD110=500000279=2269=1270=1.43179271=300000055=GBP/USD110=1000000279=2269=1270=1.43179271=500000055=GBP/USD110=300000010=055
20260109-09:18:37.934594000 : 8=FIX.4.49=027135=X49=NTPRO_IDBA_UAT56=SIRIUS_500007460_MD34=5952=20260109-09:18:37.158262=MD_EURUSD_091819268=3279=1269=1270=1.18984271=10000055=EUR/USD110=0279=1269=1270=1.18984271=50000055=EUR/USD110=100000279=1269=1270=1.18984271=100000055=EUR/USD110=50000010=117
20260109-09:18:38.447831000 : 8=FIX.4.49=067535=X49=NTPRO_IDBA_UAT56=SIRIUS_500007460_MD34=6052=20260109-09:18:37.641262=MD_GBPUSD_091820268=10279=0269=0270=1.25145271=10000055=GBP/USD110=0279=0269=0270=1.25145271=50000055=GBP/USD110=100000279=0269=0270=1.25145271=100000055=GBP/USD110=500000279=0269=0270=1.25145271=300000055=GBP/USD110=1000000279=0269=0270=1.25145271=500000055=GBP/USD110=3000000279=0269=1270=1.43179271=10000055=GBP/USD110=0279=0269=1270=1.43179271=50000055=GBP/USD110=100000279=0269=1270=1.43179271=100000055=GBP/USD110=500000279=0269=1270=1.43179271=300000055=GBP/USD110=1000000279=0269=1270=1.43179271=500000055=GBP/USD110=300000010=034
20260109-09:18:38.994386000 : 8=FIX.4.49=067535=X49=NTPRO_IDBA_UAT56=SIRIUS_500007460_MD34=6152=20260109-09:18:38.152262=MD_GBPUSD_091820268=10279=1269=0270=1.25146271=10000055=GBP/USD110=0279=1269=0270=1.25146271=50000055=GBP/USD110=100000279=1269=0270=1.25146271=100000055=GBP/USD110=500000279=1269=0270=1.25146271=300000055=GBP/USD110=1000000279=1269=0270=1.25146271=500000055=GBP/USD110=3000000279=1269=1270=1.43178271=10000055=GBP/USD110=0279=1269=1270=1.43178271=50000055=GBP/USD110=100000279=1269=1270=1.43178271=100000055=GBP/USD110=500000279=1269=1270=1.43178271=300000055=GBP/USD110=1000000279=1269=1270=1.43178271=500000055=GBP/USD110=300000010=043
20260109-09:18:42.455183000 : 8=FIX.4.49=027135=X49=NTPRO_IDBA_UAT56=SIRIUS_500007460_MD34=6252=20260109-09:18:41.391262=MD_EURUSD_091819268=3279=1269=1270=1.18983271=10000055=EUR/USD110=0279=1269=1270=1.18983271=50000055=EUR/USD110=100000279=1269=1270=1.18983271=100000055=EUR/USD110=50000010=102
20260109-09:18:42.566772000 : 8=FIX.4.49=027135=X49=NTPRO_IDBA_UAT56=SIRIUS_500007460_MD34=6352=20260109-09:18:41.482262=MD_EURUSD_091819268=3279=1269=1270=1.18984271=10000055=EUR/USD110=0279=1269=1270=1.18984271=50000055=EUR/USD110=100000279=1269=1270=1.18984271=100000055=EUR/USD110=50000010=107
20260109-09:18:43.763199000 : 8=FIX.4.49=027135=X49=NTPRO_IDBA_UAT56=SIRIUS_500007460_MD34=6452=20260109-09:18:42.612262=MD_EURUSD_091819268=3279=1269=1270=1.18983271=10000055=EUR/USD110=0279=1269=1270=1.18983271=50000055=EUR/USD110=100000279=1269=1270=1.18983271=100000055=EUR/USD110=50000010=101
20260109-09:18:44.553088000 : 8=FIX.4.49=038935=X49=NTPRO_IDBA_UAT56=SIRIUS_500007460_MD34=6552=20260109-09:18:43.354262=MD_GBPUSD_091820268=5279=1269=1270=1.43179271=10000055=GBP/USD110=0279=1269=1270=1.43179271=50000055=GBP/USD110=100000279=1269=1270=1.43179271=100000055=GBP/USD110=500000279=1269=1270=1.43179271=300000055=GBP/USD110=1000000279=1269=1270=1.43179271=500000055=GBP/USD110=300000010=165
20260109-09:18:45.619496000 : 8=FIX.4.49=038935=X49=NTPRO_IDBA_UAT56=SIRIUS_500007460_MD34=6652=20260109-09:18:44.351262=MD_GBPUSD_091820268=5279=1269=1270=1.43178271=10000055=GBP/USD110=0279=1269=1270=1.43178271=50000055=GBP/USD110=100000279=1269=1270=1.43178271=100000055=GBP/USD110=500000279=1269=1270=1.43178271=300000055=GBP/USD110=1000000279=1269=1270=1.43178271=500000055=GBP/USD110=300000010=159
20260109-09:18:45.719174000 : 8=FIX.4.49=038935=X49=NTPRO_IDBA_UAT56=SIRIUS_500007460_MD34=6752=20260109-09:18:44.440262=MD_GBPUSD_091820268=5279=1269=1270=1.43179271=10000055=GBP/USD110=0279=1269=1270=1.43179271=50000055=GBP/USD110=100000279=1269=1270=1.43179271=100000055=GBP/USD110=500000279=1269=1270=1.43179271=300000055=GBP/USD110=1000000279=1269=1270=1.43179271=500000055=GBP/USD110=300000010=164
20260109-09:18:45.750798000 : 8=FIX.4.49=038435=X49=NTPRO_IDBA_UAT56=SIRIUS_500007460_MD34=6852=20260109-09:18:44.473262=MD_GBPUSD_091820268=5279=1269=1270=1.4318271=10000055=GBP/USD110=0279=1269=1270=1.4318271=50000055=GBP/USD110=100000279=1269=1270=1.4318271=100000055=GBP/USD110=500000279=1269=1270=1.4318271=300000055=GBP/USD110=1000000279=1269=1270=1.4318271=500000055=GBP/USD110=300000010=142
20260109-09:18:45.804254000 : 8=FIX.4.49=038935=X49=NTPRO_IDBA_UAT56=SIRIUS_500007460_MD34=6952=20260109-09:18:44.524262=MD_GBPUSD_091820268=5279=1269=1270=1.43179271=10000055=GBP/USD110=0279=1269=1270=1.43179271=50000055=GBP/USD110=100000279=1269=1270=1.43179271=100000055=GBP/USD110=500000279=1269=1270=1.43179271=300000055=GBP/USD110=1000000279=1269=1270=1.43179271=500000055=GBP/USD110=300000010=169
20260109-09:18:45.856170000 : 8=FIX.4.49=038435=X49=NTPRO_IDBA_UAT56=SIRIUS_500007460_MD34=7052=20260109-09:18:44.572262=MD_GBPUSD_091820268=5279=1269=1270=1.4318271=10000055=GBP/USD110=0279=1269=1270=1.4318271=50000055=GBP/USD110=100000279=1269=1270=1.4318271=100000055=GBP/USD110=500000279=1269=1270=1.4318271=300000055=GBP/USD110=1000000279=1269=1270=1.4318271=500000055=GBP/USD110=300000010=135
20260109-09:18:46.393734000 : 8=FIX.4.49=038935=X49=NTPRO_IDBA_UAT56=SIRIUS_500007460_MD34=7152=20260109-09:18:45.075262=MD_GBPUSD_091820268=5279=1269=1270=1.43179271=10000055=GBP/USD110=0279=1269=1270=1.43179271=50000055=GBP/USD110=100000279=1269=1270=1.43179271=100000055=GBP/USD110=500000279=1269=1270=1.43179271=300000055=GBP/USD110=1000000279=1269=1270=1.43179271=500000055=GBP/USD110=300000010=164
20260109-09:18:46.675150000 : 8=FIX.4.49=027135=X49=NTPRO_IDBA_UAT56=SIRIUS_500007460_MD34=7252=20260109-09:18:45.336262=MD_EURUSD_091819268=3279=1269=1270=1.18984271=10000055=EUR/USD110=0279=1269=1270=1.18984271=50000055=EUR/USD110=100000279=1269=1270=1.18984271=100000055=EUR/USD110=50000010=109
20260109-09:18:46.677925000 : 8=FIX.4.49=7635=534=649=SIRIUS_500007460_MD52=20260109-09:18:46.67656=NTPRO_IDBA_UAT10=053
20260109-09:18:46.736010000 : 8=FIX.4.49=067035=X49=NTPRO_IDBA_UAT56=SIRIUS_500007460_MD34=7352=20260109-09:18:45.395262=MD_GBPUSD_091820268=10279=1269=0270=1.25148271=10000055=GBP/USD110=0279=1269=0270=1.25148271=50000055=GBP/USD110=100000279=1269=0270=1.25148271=100000055=GBP/USD110=500000279=1269=0270=1.25148271=300000055=GBP/USD110=1000000279=1269=0270=1.25148271=500000055=GBP/USD110=3000000279=1269=1270=1.4318271=10000055=GBP/USD110=0279=1269=1270=1.4318271=50000055=GBP/USD110=100000279=1269=1270=1.4318271=100000055=GBP/USD110=500000279=1269=1270=1.4318271=300000055=GBP/USD110=1000000279=1269=1270=1.4318271=500000055=GBP/USD110=300000010=039
20260109-09:18:46.791827000 : 8=FIX.4.49=067535=X49=NTPRO_IDBA_UAT56=SIRIUS_500007460_MD34=7452=20260109-09:18:45.447262=MD_GBPUSD_091820268=10279=1269=0270=1.25149271=10000055=GBP/USD110=0279=1269=0270=1.25149271=50000055=GBP/USD110=100000279=1269=0270=1.25149271=100000055=GBP/USD110=500000279=1269=0270=1.25149271=300000055=GBP/USD110=1000000279=1269=0270=1.25149271=500000055=GBP/USD110=3000000279=1269=1270=1.43181271=10000055=GBP/USD110=0279=1269=1270=1.43181271=50000055=GBP/USD110=100000279=1269=1270=1.43181271=100000055=GBP/USD110=500000279=1269=1270=1.43181271=300000055=GBP/USD110=1000000279=1269=1270=1.43181271=500000055=GBP/USD110=300000010=037
20260109-09:18:46.797720000 : 8=FIX.4.49=026835=X49=NTPRO_IDBA_UAT56=SIRIUS_500007460_MD34=7552=20260109-09:18:45.453262=MD_EURUSD_091819268=3279=1269=0270=1.1396271=10000055=EUR/USD110=0279=1269=0270=1.1396271=50000055=EUR/USD110=100000279=1269=0270=1.1396271=100000055=EUR/USD110=50000010=194
20260109-09:18:46.798513000 : 8=FIX.4.49=010035=549=NTPRO_IDBA_UAT56=SIRIUS_500007460_MD34=7652=20260109-09:18:45.45458=Remote side request10=190
