20260120-14:01:53.268903000 : 8=FIX.4.49=068335=X49=NTPRO_IDBA_UAT56=SIRIUS_500007460_MD34=41952=20260120-14:01:54.309262=MD_GBP/USD_140109778778268=10279=0269=0270=1.25493271=10000055=GBP/USD110=0279=0269=0270=1.25493271=50000055=GBP/USD110=100000279=0269=0270=1.25493271=100000055=GBP/USD110=500000279=0269=0270=1.25493271=300000055=GBP/USD110=1000000279=0269=0270=1.25493271=500000055=GBP/USD110=3000000279=0269=1270=1.43529271=10000055=GBP/USD110=0279=0269=1270=1.43529271=50000055=GBP/USD110=100000279=0269=1270=1.43529271=100000055=GBP/USD110=500000279=0269=1270=1.43529271=300000055=GBP/USD110=1000000279=0269=1270=1.43529271=500000055=GBP/USD110=300000010=213
20260120-14:01:53.304105000 : 8=FIX.4.49=044635=X49=NTPRO_IDBA_UAT56=SIRIUS_500007460_MD34=42052=20260120-14:01:54.347262=MD_EUR/USD_140109278614268=6279=1269=0270=1.14821271=10000055=EUR/USD110=0279=1269=0270=1.14821271=50000055=EUR/USD110=100000279=1269=0270=1.14821271=100000055=EUR/USD110=500000279=1269=1270=1.19845271=10000055=EUR/USD110=0279=1269=1270=1.19845271=50000055=EUR/USD110=100000279=1269=1270=1.19845271=100000055=EUR/USD110=50000010=249
20260120-14:01:53.338838000 : 8=FIX.4.49=068335=X49=NTPRO_IDBA_UAT56=SIRIUS_500007460_MD34=42152=20260120-14:01:54.382262=MD_GBP/USD_140109778778268=10279=2269=0270=1.25493271=10000055=GBP/USD110=0279=2269=0270=1.25493271=50000055=GBP/USD110=100000279=2269=0270=1.25493271=100000055=GBP/USD110=500000279=2269=0270=1.25493271=300000055=GBP/USD110=1000000279=2269=0270=1.25493271=500000055=GBP/USD110=3000000279=2269=1270=1.43529271=10000055=GBP/USD110=0279=2269=1270=1.43529271=50000055=GBP/USD110=100000279=2269=1270=1.43529271=100000055=GBP/USD110=500000279=2269=1270=1.43529271=300000055=GBP/USD110=1000000279=2269=1270=1.43529271=500000055=GBP/USD110=300000010=227
20260120-14:01:53.412402000 : 8=FIX.4.49=027635=X49=NTPRO_IDBA_UAT56=SIRIUS_500007460_MD34=42252=20260120-14:01:54.459262=MD_EUR/USD_140109278614268=3279=1269=0270=1.1482271=10000055=EUR/USD110=0279=1269=0270=1.1482271=50000055=EUR/USD110=100000279=1269=0270=1.1482271=100000055=EUR/USD110=50000010=050
20260120-14:01:53.459124000 : 8=FIX.4.49=068335=X49=NTPRO_IDBA_UAT56=SIRIUS_500007460_MD34=42352=20260120-14:01:54.506262=MD_GBP/USD_140109778778268=10279=0269=0270=1.25493271=10000055=GBP/USD110=0279=0269=0270=1.25493271=50000055=GBP/USD110=100000279=0269=0270=1.25493271=100000055=GBP/USD110=500000279=0269=0270=1.25493271=300000055=GBP/USD110=1000000279=0269=0270=1.25493271=500000055=GBP/USD110=3000000279=0269=1270=1.43528271=10000055=GBP/USD110=0279=0269=1270=1.43528271=50000055=GBP/USD110=100000279=0269=1270=1.43528271=100000055=GBP/USD110=500000279=0269=1270=1.43528271=300000055=GBP/USD110=1000000279=0269=1270=1.43528271=500000055=GBP/USD110=300000010=202
20260120-14:01:53.726500000 : 8=FIX.4.49=027935=X49=NTPRO_IDBA_UAT56=SIRIUS_500007460_MD34=42452=20260120-14:01:54.781262=MD_EUR/USD_140109278614268=3279=1269=0270=1.14821271=10000055=EUR/USD110=0279=1269=0270=1.14821271=50000055=EUR/USD110=100000279=1269=0270=1.14821271=100000055=EUR/USD110=50000010=200
20260120-14:01:53.765868000 : 8=FIX.4.49=068335=X49=NTPRO_IDBA_UAT56=SIRIUS_500007460_MD34=42552=20260120-14:01:54.820262=MD_GBP/USD_140109778778268=10279=2269=0270=1.25493271=10000055=GBP/USD110=0279=2269=0270=1.25493271=50000055=GBP/USD110=100000279=2269=0270=1.25493271=100000055=GBP/USD110=500000279=2269=0270=1.25493271=300000055=GBP/USD110=1000000279=2269=0270=1.25493271=500000055=GBP/USD110=3000000279=2269=1270=1.43528271=10000055=GBP/USD110=0279=2269=1270=1.43528271=50000055=GBP/USD110=100000279=2269=1270=1.43528271=100000055=GBP/USD110=500000279=2269=1270=1.43528271=300000055=GBP/USD110=1000000279=2269=1270=1.43528271=500000055=GBP/USD110=300000010=223
20260120-14:01:54.323056000 : 8=FIX.4.49=027635=X49=NTPRO_IDBA_UAT56=SIRIUS_500007460_MD34=42652=20260120-14:01:54.853262=MD_EUR/USD_140109278614268=3279=1269=0270=1.1482271=10000055=EUR/USD110=0279=1269=0270=1.1482271=50000055=EUR/USD110=100000279=1269=0270=1.1482271=100000055=EUR/USD110=50000010=052
20260120-14:01:55.177164000 : 8=FIX.4.49=044635=X49=NTPRO_IDBA_UAT56=SIRIUS_500007460_MD34=42752=20260120-14:01:55.099262=MD_EUR/USD_140109278614268=6279=1269=0270=1.14819271=10000055=EUR/USD110=0279=1269=0270=1.14819271=50000055=EUR/USD110=100000279=1269=0270=1.14819271=100000055=EUR/USD110=500000279=1269=1270=1.19844271=10000055=EUR/USD110=0279=1269=1270=1.19844271=50000055=EUR/USD110=100000279=1269=1270=1.19844271=100000055=EUR/USD110=50000010=023
20260120-14:01:55.279375000 : 8=FIX.4.49=068335=X49=NTPRO_IDBA_UAT56=SIRIUS_500007460_MD34=42852=20260120-14:01:55.200262=MD_GBP/USD_140109778778268=10279=0269=0270=1.25488271=10000055=GBP/USD110=0279=0269=0270=1.25488271=50000055=GBP/USD110=100000279=0269=0270=1.25488271=100000055=GBP/USD110=500000279=0269=0270=1.25488271=300000055=GBP/USD110=1000000279=0269=0270=1.25488271=500000055=GBP/USD110=3000000279=0269=1270=1.43524271=10000055=GBP/USD110=0279=0269=1270=1.43524271=50000055=GBP/USD110=100000279=0269=1270=1.43524271=100000055=GBP/USD110=500000279=0269=1270=1.43524271=300000055=GBP/USD110=1000000279=0269=1270=1.43524271=500000055=GBP/USD110=300000010=199
20260120-14:01:55.309983000 : 8=FIX.4.49=068335=X49=NTPRO_IDBA_UAT56=SIRIUS_500007460_MD34=42952=20260120-14:01:55.239262=MD_GBP/USD_140109778778268=10279=2269=0270=1.25488271=10000055=GBP/USD110=0279=2269=0270=1.25488271=50000055=GBP/USD110=100000279=2269=0270=1.25488271=100000055=GBP/USD110=500000279=2269=0270=1.25488271=300000055=GBP/USD110=1000000279=2269=0270=1.25488271=500000055=GBP/USD110=3000000279=2269=1270=1.43524271=10000055=GBP/USD110=0279=2269=1270=1.43524271=50000055=GBP/USD110=100000279=2269=1270=1.43524271=100000055=GBP/USD110=500000279=2269=1270=1.43524271=300000055=GBP/USD110=1000000279=2269=1270=1.43524271=500000055=GBP/USD110=300000010=232
20260120-14:01:55.349001000 : 8=FIX.4.49=068335=X49=NTPRO_IDBA_UAT56=SIRIUS_500007460_MD34=43052=20260120-14:01:55.279262=MD_GBP/USD_140109778778268=10279=0269=0270=1.25488271=10000055=GBP/USD110=0279=0269=0270=1.25488271=50000055=GBP/USD110=100000279=0269=0270=1.25488271=100000055=GBP/USD110=500000279=0269=0270=1.25488271=300000055=GBP/USD110=1000000279=0269=0270=1.25488271=500000055=GBP/USD110=3000000279=0269=1270=1.43524271=10000055=GBP/USD110=0279=0269=1270=1.43524271=50000055=GBP/USD110=100000279=0269=1270=1.43524271=100000055=GBP/USD110=500000279=0269=1270=1.43524271=300000055=GBP/USD110=1000000279=0269=1270=1.43524271=500000055=GBP/USD110=300000010=208
20260120-14:01:55.423062000 : 8=FIX.4.49=068335=X49=NTPRO_IDBA_UAT56=SIRIUS_500007460_MD34=43152=20260120-14:01:55.355262=MD_GBP/USD_140109778778268=10279=2269=0270=1.25488271=10000055=GBP/USD110=0279=2269=0270=1.25488271=50000055=GBP/USD110=100000279=2269=0270=1.25488271=100000055=GBP/USD110=500000279=2269=0270=1.25488271=300000055=GBP/USD110=1000000279=2269=0270=1.25488271=500000055=GBP/USD110=3000000279=2269=1270=1.43524271=10000055=GBP/USD110=0279=2269=1270=1.43524271=50000055=GBP/USD110=100000279=2269=1270=1.43524271=100000055=GBP/USD110=500000279=2269=1270=1.43524271=300000055=GBP/USD110=1000000279=2269=1270=1.43524271=500000055=GBP/USD110=300000010=224
20260120-14:01:55.423556000 : 8=FIX.4.49=044635=X49=NTPRO_IDBA_UAT56=SIRIUS_500007460_MD34=43252=20260120-14:01:55.356262=MD_EUR/USD_140109278614268=6279=1269=0270=1.14821271=10000055=EUR/USD110=0279=1269=0270=1.14821271=50000055=EUR/USD110=100000279=1269=0270=1.14821271=100000055=EUR/USD110=500000279=1269=1270=1.19846271=10000055=EUR/USD110=0279=1269=1270=1.19846271=50000055=EUR/USD110=100000279=1269=1270=1.19846271=100000055=EUR/USD110=50000010=000
20260120-14:01:55.564296000 : 8=FIX.4.49=044335=X49=NTPRO_IDBA_UAT56=SIRIUS_500007460_MD34=43352=20260120-14:01:55.499262=MD_EUR/USD_140109278614268=6279=1269=0270=1.1482271=10000055=EUR/USD110=0279=1269=0270=1.1482271=50000055=EUR/USD110=100000279=1269=0270=1.1482271=100000055=EUR/USD110=500000279=1269=1270=1.19845271=10000055=EUR/USD110=0279=1269=1270=1.19845271=50000055=EUR/USD110=100000279=1269=1270=1.19845271=100000055=EUR/USD110=50000010=112
20260120-14:01:55.574255000 : 8=FIX.4.49=067835=X49=NTPRO_IDBA_UAT56=SIRIUS_500007460_MD34=43452=20260120-14:01:55.502262=MD_GBP/USD_140109778778268=10279=0269=0270=1.2549271=10000055=GBP/USD110=0279=0269=0270=1.2549271=50000055=GBP/USD110=100000279=0269=0270=1.2549271=100000055=GBP/USD110=500000279=0269=0270=1.2549271=300000055=GBP/USD110=1000000279=0269=0270=1.2549271=500000055=GBP/USD110=3000000279=0269=1270=1.43526271=10000055=GBP/USD110=0279=0269=1270=1.43526271=50000055=GBP/USD110=100000279=0269=1270=1.43526271=100000055=GBP/USD110=500000279=0269=1270=1.43526271=300000055=GBP/USD110=1000000279=0269=1270=1.43526271=500000055=GBP/USD110=300000010=196
20260120-14:01:55.627916000 : 8=FIX.4.49=039735=X49=NTPRO_IDBA_UAT56=SIRIUS_500007460_MD34=43552=20260120-14:01:55.565262=MD_GBP/USD_140109778778268=5279=1269=1270=1.43525271=10000055=GBP/USD110=0279=1269=1270=1.43525271=50000055=GBP/USD110=100000279=1269=1270=1.43525271=100000055=GBP/USD110=500000279=1269=1270=1.43525271=300000055=GBP/USD110=1000000279=1269=1270=1.43525271=500000055=GBP/USD110=300000010=038
20260120-14:01:55.680810000 : 8=FIX.4.49=027935=X49=NTPRO_IDBA_UAT56=SIRIUS_500007460_MD34=43652=20260120-14:01:55.620262=MD_EUR/USD_140109278614268=3279=1269=1270=1.19844271=10000055=EUR/USD110=0279=1269=1270=1.19844271=50000055=EUR/USD110=100000279=1269=1270=1.19844271=100000055=EUR/USD110=50000010=229
20260120-14:01:55.681992000 : 8=FIX.4.49=039735=X49=NTPRO_IDBA_UAT56=SIRIUS_500007460_MD34=43752=20260120-14:01:55.620262=MD_GBP/USD_140109778778268=5279=1269=0270=1.25489271=10000055=GBP/USD110=0279=1269=0270=1.25489271=50000055=GBP/USD110=100000279=1269=0270=1.25489271=100000055=GBP/USD110=500000279=1269=0270=1.25489271=300000055=GBP/USD110=1000000279=1269=0270=1.25489271=500000055=GBP/USD110=300000010=072
20260120-14:01:55.770062000 : 8=FIX.4.49=027935=X49=NTPRO_IDBA_UAT56=SIRIUS_500007460_MD34=43852=20260120-14:01:55.711262=MD_EUR/USD_140109278614268=3279=1269=0270=1.14819271=10000055=EUR/USD110=0279=1269=0270=1.14819271=50000055=EUR/USD110=100000279=1269=0270=1.14819271=100000055=EUR/USD110=50000010=220
20260120-14:01:55.778917000 : 8=FIX.4.49=068335=X49=NTPRO_IDBA_UAT56=SIRIUS_500007460_MD34=43952=20260120-14:01:55.720262=MD_GBP/USD_140109778778268=10279=2269=0270=1.25489271=10000055=GBP/USD110=0279=2269=0270=1.25489271=50000055=GBP/USD110=100000279=2269=0270=1.25489271=100000055=GBP/USD110=500000279=2269=0270=1.25489271=300000055=GBP/USD110=1000000279=2269=0270=1.25489271=500000055=GBP/USD110=3000000279=2269=1270=1.43525271=10000055=GBP/USD110=0279=2269=1270=1.43525271=50000055=GBP/USD110=100000279=2269=1270=1.43525271=100000055=GBP/USD110=500000279=2269=1270=1.43525271=300000055=GBP/USD110=1000000279=2269=1270=1.43525271=500000055=GBP/USD110=300000010=238
20260120-14:01:55.890806000 : 8=FIX.4.49=068335=X49=NTPRO_IDBA_UAT56=SIRIUS_500007460_MD34=44052=20260120-14:01:55.834262=MD_GBP/USD_140109778778268=10279=0269=0270=1.25488271=10000055=GBP/USD110=0279=0269=0270=1.25488271=50000055=GBP/USD110=100000279=0269=0270=1.25488271=100000055=GBP/USD110=500000279=0269=0270=1.25488271=300000055=GBP/USD110=1000000279=0269=0270=1.25488271=500000055=GBP/USD110=3000000279=0269=1270=1.43523271=10000055=GBP/USD110=0279=0269=1270=1.43523271=50000055=GBP/USD110=100000279=0269=1270=1.43523271=100000055=GBP/USD110=500000279=0269=1270=1.43523271=300000055=GBP/USD110=1000000279=0269=1270=1.43523271=500000055=GBP/USD110=300000010=201
20260120-14:01:56.217457000 : 8=FIX.4.49=068335=X49=NTPRO_IDBA_UAT56=SIRIUS_500007460_MD34=44152=20260120-14:01:56.169262=MD_GBP/USD_140109778778268=10279=2269=0270=1.25488271=10000055=GBP/USD110=0279=2269=0270=1.25488271=50000055=GBP/USD110=100000279=2269=0270=1.25488271=100000055=GBP/USD110=500000279=2269=0270=1.25488271=300000055=GBP/USD110=1000000279=2269=0270=1.25488271=500000055=GBP/USD110=3000000279=2269=1270=1.43523271=10000055=GBP/USD110=0279=2269=1270=1.43523271=50000055=GBP/USD110=100000279=2269=1270=1.43523271=100000055=GBP/USD110=500000279=2269=1270=1.43523271=300000055=GBP/USD110=1000000279=2269=1270=1.43523271=500000055=GBP/USD110=300000010=224
20260120-14:01:56.276467000 : 8=FIX.4.49=068335=X49=NTPRO_IDBA_UAT56=SIRIUS_500007460_MD34=44252=20260120-14:01:56.225262=MD_GBP/USD_140109778778268=10279=0269=0270=1.25488271=10000055=GBP/USD110=0279=0269=0270=1.25488271=50000055=GBP/USD110=100000279=0269=0270=1.25488271=100000055=GBP/USD110=500000279=0269=0270=1.25488271=300000055=GBP/USD110=1000000279=0269=0270=1.25488271=500000055=GBP/USD110=3000000279=0269=1270=1.43522271=10000055=GBP/USD110=0279=0269=1270=1.43522271=50000055=GBP/USD110=100000279=0269=1270=1.43522271=100000055=GBP/USD110=500000279=0269=1270=1.43522271=300000055=GBP/USD110=1000000279=0269=1270=1.43522271=500000055=GBP/USD110=300000010=193
20260120-14:01:56.295985000 : 8=FIX.4.49=039735=X49=NTPRO_IDBA_UAT56=SIRIUS_500007460_MD34=44352=20260120-14:01:56.250262=MD_GBP/USD_140109778778268=5279=1269=0270=1.25486271=10000055=GBP/USD110=0279=1269=0270=1.25486271=50000055=GBP/USD110=100000279=1269=0270=1.25486271=100000055=GBP/USD110=500000279=1269=0270=1.25486271=300000055=GBP/USD110=1000000279=1269=0270=1.25486271=500000055=GBP/USD110=300000010=054
20260120-14:01:56.348758000 : 8=FIX.4.49=027635=X49=NTPRO_IDBA_UAT56=SIRIUS_500007460_MD34=44452=20260120-14:01:56.298262=MD_EUR/USD_140109278614268=3279=1269=0270=1.1482271=10000055=EUR/USD110=0279=1269=0270=1.1482271=50000055=EUR/USD110=100000279=1269=0270=1.1482271=100000055=EUR/USD110=50000010=057
20260120-14:01:56.382952000 : 8=FIX.4.49=044635=X49=NTPRO_IDBA_UAT56=SIRIUS_500007460_MD34=44552=20260120-14:01:56.335262=MD_EUR/USD_140109278614268=6279=1269=0270=1.14817271=10000055=EUR/USD110=0279=1269=0270=1.14817271=50000055=EUR/USD110=100000279=1269=0270=1.14817271=100000055=EUR/USD110=500000279=1269=1270=1.19842271=10000055=EUR/USD110=0279=1269=1270=1.19842271=50000055=EUR/USD110=100000279=1269=1270=1.19842271=100000055=EUR/USD110=50000010=005
20260120-14:01:56.396458000 : 8=FIX.4.49=068335=X49=NTPRO_IDBA_UAT56=SIRIUS_500007460_MD34=44652=20260120-14:01:56.354262=MD_GBP/USD_140109778778268=10279=1269=0270=1.25487271=10000055=GBP/USD110=0279=1269=0270=1.25487271=50000055=GBP/USD110=100000279=1269=0270=1.25487271=100000055=GBP/USD110=500000279=1269=0270=1.25487271=300000055=GBP/USD110=1000000279=1269=0270=1.25487271=500000055=GBP/USD110=3000000279=1269=1270=1.43523271=10000055=GBP/USD110=0279=1269=1270=1.43523271=50000055=GBP/USD110=100000279=1269=1270=1.43523271=100000055=GBP/USD110=500000279=1269=1270=1.43523271=300000055=GBP/USD110=1000000279=1269=1270=1.43523271=500000055=GBP/USD110=300000010=210
20260120-14:01:56.502051000 : 8=FIX.4.49=044635=X49=NTPRO_IDBA_UAT56=SIRIUS_500007460_MD34=44752=20260120-14:01:56.462262=MD_EUR/USD_140109278614268=6279=1269=0270=1.14818271=10000055=EUR/USD110=0279=1269=0270=1.14818271=50000055=EUR/USD110=100000279=1269=0270=1.14818271=100000055=EUR/USD110=500000279=1269=1270=1.19843271=10000055=EUR/USD110=0279=1269=1270=1.19843271=50000055=EUR/USD110=100000279=1269=1270=1.19843271=100000055=EUR/USD110=50000010=014
20260120-14:01:56.534326000 : 8=FIX.4.49=068335=X49=NTPRO_IDBA_UAT56=SIRIUS_500007460_MD34=44852=20260120-14:01:56.493262=MD_GBP/USD_140109778778268=10279=1269=0270=1.25485271=10000055=GBP/USD110=0279=1269=0270=1.25485271=50000055=GBP/USD110=100000279=1269=0270=1.25485271=100000055=GBP/USD110=500000279=1269=0270=1.25485271=300000055=GBP/USD110=1000000279=1269=0270=1.25485271=500000055=GBP/USD110=3000000279=1269=1270=1.43521271=10000055=GBP/USD110=0279=1269=1270=1.43521271=50000055=GBP/USD110=100000279=1269=1270=1.43521271=100000055=GBP/USD110=500000279=1269=1270=1.43521271=300000055=GBP/USD110=1000000279=1269=1270=1.43521271=500000055=GBP/USD110=300000010=196
20260120-14:01:56.635030000 : 8=FIX.4.49=044635=X49=NTPRO_IDBA_UAT56=SIRIUS_500007460_MD34=44952=20260120-14:01:56.599262=MD_EUR/USD_140109278614268=6279=1269=0270=1.14816271=10000055=EUR/USD110=0279=1269=0270=1.14816271=50000055=EUR/USD110=100000279=1269=0270=1.14816271=100000055=EUR/USD110=500000279=1269=1270=1.19841271=10000055=EUR/USD110=0279=1269=1270=1.19841271=50000055=EUR/USD110=100000279=1269=1270=1.19841271=100000055=EUR/USD110=50000010=015
20260120-14:01:56.681615000 : 8=FIX.4.49=068335=X49=NTPRO_IDBA_UAT56=SIRIUS_500007460_MD34=45052=20260120-14:01:56.646262=MD_GBP/USD_140109778778268=10279=1269=0270=1.25484271=10000055=GBP/USD110=0279=1269=0270=1.25484271=50000055=GBP/USD110=100000279=1269=0270=1.25484271=100000055=GBP/USD110=500000279=1269=0270=1.25484271=300000055=GBP/USD110=1000000279=1269=0270=1.25484271=500000055=GBP/USD110=3000000279=1269=1270=1.43519271=10000055=GBP/USD110=0279=1269=1270=1.43519271=50000055=GBP/USD110=100000279=1269=1270=1.43519271=100000055=GBP/USD110=500000279=1269=1270=1.43519271=300000055=GBP/USD110=1000000279=1269=1270=1.43519271=500000055=GBP/USD110=300000010=219
20260120-14:01:56.771722000 : 8=FIX.4.49=044335=X49=NTPRO_IDBA_UAT56=SIRIUS_500007460_MD34=45152=20260120-14:01:56.731262=MD_EUR/USD_140109278614268=6279=1269=0270=1.14815271=10000055=EUR/USD110=0279=1269=0270=1.14815271=50000055=EUR/USD110=100000279=1269=0270=1.14815271=100000055=EUR/USD110=500000279=1269=1270=1.1984271=10000055=EUR/USD110=0279=1269=1270=1.1984271=50000055=EUR/USD110=100000279=1269=1270=1.1984271=100000055=EUR/USD110=50000010=099
20260120-14:01:56.772661000 : 8=FIX.4.49=067835=X49=NTPRO_IDBA_UAT56=SIRIUS_500007460_MD34=45252=20260120-14:01:56.735262=MD_GBP/USD_140109778778268=10279=1269=0270=1.25485271=10000055=GBP/USD110=0279=1269=0270=1.25485271=50000055=GBP/USD110=100000279=1269=0270=1.25485271=100000055=GBP/USD110=500000279=1269=0270=1.25485271=300000055=GBP/USD110=1000000279=1269=0270=1.25485271=500000055=GBP/USD110=3000000279=1269=1270=1.4352271=10000055=GBP/USD110=0279=1269=1270=1.4352271=50000055=GBP/USD110=100000279=1269=1270=1.4352271=100000055=GBP/USD110=500000279=1269=1270=1.4352271=300000055=GBP/USD110=1000000279=1269=1270=1.4352271=500000055=GBP/USD110=300000010=205
20260120-14:01:56.806426000 : 8=FIX.4.49=067835=X49=NTPRO_IDBA_UAT56=SIRIUS_500007460_MD34=45352=20260120-14:01:56.774262=MD_GBP/USD_140109778778268=10279=2269=0270=1.25485271=10000055=GBP/USD110=0279=2269=0270=1.25485271=50000055=GBP/USD110=100000279=2269=0270=1.25485271=100000055=GBP/USD110=500000279=2269=0270=1.25485271=300000055=GBP/USD110=1000000279=2269=0270=1.25485271=500000055=GBP/USD110=3000000279=2269=1270=1.4352271=10000055=GBP/USD110=0279=2269=1270=1.4352271=50000055=GBP/USD110=100000279=2269=1270=1.4352271=100000055=GBP/USD110=500000279=2269=1270=1.4352271=300000055=GBP/USD110=1000000279=2269=1270=1.4352271=500000055=GBP/USD110=300000010=219
20260120-14:01:56.874260000 : 8=FIX.4.49=068335=X49=NTPRO_IDBA_UAT56=SIRIUS_500007460_MD34=45452=20260120-14:01:56.843262=MD_GBP/USD_140109778778268=10279=0269=0270=1.25483271=10000055=GBP/USD110=0279=0269=0270=1.25483271=50000055=GBP/USD110=100000279=0269=0270=1.25483271=100000055=GBP/USD110=500000279=0269=0270=1.25483271=300000055=GBP/USD110=1000000279=0269=0270=1.25483271=500000055=GBP/USD110=3000000279=0269=1270=1.43519271=10000055=GBP/USD110=0279=0269=1270=1.43519271=50000055=GBP/USD110=100000279=0269=1270=1.43519271=100000055=GBP/USD110=500000279=0269=1270=1.43519271=300000055=GBP/USD110=1000000279=0269=1270=1.43519271=500000055=GBP/USD110=300000010=207
20260120-14:01:56.999396000 : 8=FIX.4.49=044635=X49=NTPRO_IDBA_UAT56=SIRIUS_500007460_MD34=45552=20260120-14:01:56.959262=MD_EUR/USD_140109278614268=6279=1269=0270=1.14816271=10000055=EUR/USD110=0279=1269=0270=1.14816271=50000055=EUR/USD110=100000279=1269=0270=1.14816271=100000055=EUR/USD110=500000279=1269=1270=1.19841271=10000055=EUR/USD110=0279=1269=1270=1.19841271=50000055=EUR/USD110=100000279=1269=1270=1.19841271=100000055=EUR/USD110=50000010=012
20260120-14:01:57.673147000 : 8=FIX.4.49=067835=X49=NTPRO_IDBA_UAT56=SIRIUS_500007460_MD34=45652=20260120-14:01:57.663262=MD_GBP/USD_140109778778268=10279=1269=0270=1.25484271=10000055=GBP/USD110=0279=1269=0270=1.25484271=50000055=GBP/USD110=100000279=1269=0270=1.25484271=100000055=GBP/USD110=500000279=1269=0270=1.25484271=300000055=GBP/USD110=1000000279=1269=0270=1.25484271=500000055=GBP/USD110=3000000279=1269=1270=1.4352271=10000055=GBP/USD110=0279=1269=1270=1.4352271=50000055=GBP/USD110=100000279=1269=1270=1.4352271=100000055=GBP/USD110=500000279=1269=1270=1.4352271=300000055=GBP/USD110=1000000279=1269=1270=1.4352271=500000055=GBP/USD110=300000010=205
20260120-14:01:58.202721000 : 8=FIX.4.49=068335=X49=NTPRO_IDBA_UAT56=SIRIUS_500007460_MD34=45752=20260120-14:01:58.205262=MD_GBP/USD_140109778778268=10279=1269=0270=1.25485271=10000055=GBP/USD110=0279=1269=0270=1.25485271=50000055=GBP/USD110=100000279=1269=0270=1.25485271=100000055=GBP/USD110=500000279=1269=0270=1.25485271=300000055=GBP/USD110=1000000279=1269=0270=1.25485271=500000055=GBP/USD110=3000000279=1269=1270=1.43521271=10000055=GBP/USD110=0279=1269=1270=1.43521271=50000055=GBP/USD110=100000279=1269=1270=1.43521271=100000055=GBP/USD110=500000279=1269=1270=1.43521271=300000055=GBP/USD110=1000000279=1269=1270=1.43521271=500000055=GBP/USD110=300000010=189
20260120-14:01:58.518404000 : 8=FIX.4.49=039235=X49=NTPRO_IDBA_UAT56=SIRIUS_500007460_MD34=45852=20260120-14:01:58.530262=MD_GBP/USD_140109778778268=5279=1269=1270=1.4352271=10000055=GBP/USD110=0279=1269=1270=1.4352271=50000055=GBP/USD110=100000279=1269=1270=1.4352271=100000055=GBP/USD110=500000279=1269=1270=1.4352271=300000055=GBP/USD110=1000000279=1269=1270=1.4352271=500000055=GBP/USD110=300000010=024
20260120-14:01:58.561046000 : 8=FIX.4.49=039735=X49=NTPRO_IDBA_UAT56=SIRIUS_500007460_MD34=45952=20260120-14:01:58.572262=MD_GBP/USD_140109778778268=5279=1269=0270=1.25483271=10000055=GBP/USD110=0279=1269=0270=1.25483271=50000055=GBP/USD110=100000279=1269=0270=1.25483271=100000055=GBP/USD110=500000279=1269=0270=1.25483271=300000055=GBP/USD110=1000000279=1269=0270=1.25483271=500000055=GBP/USD110=300000010=055
20260120-14:01:58.916793000 : 8=FIX.4.49=067835=X49=NTPRO_IDBA_UAT56=SIRIUS_500007460_MD34=46052=20260120-14:01:58.935262=MD_GBP/USD_140109778778268=10279=2269=0270=1.25483271=10000055=GBP/USD110=0279=2269=0270=1.25483271=50000055=GBP/USD110=100000279=2269=0270=1.25483271=100000055=GBP/USD110=500000279=2269=0270=1.25483271=300000055=GBP/USD110=1000000279=2269=0270=1.25483271=500000055=GBP/USD110=3000000279=2269=1270=1.4352271=10000055=GBP/USD110=0279=2269=1270=1.4352271=50000055=GBP/USD110=100000279=2269=1270=1.4352271=100000055=GBP/USD110=500000279=2269=1270=1.4352271=300000055=GBP/USD110=1000000279=2269=1270=1.4352271=500000055=GBP/USD110=300000010=208
20260120-14:01:59.063490000 : 8=FIX.4.49=067835=X49=NTPRO_IDBA_UAT56=SIRIUS_500007460_MD34=46152=20260120-14:01:59.074262=MD_GBP/USD_140109778778268=10279=0269=0270=1.25484271=10000055=GBP/USD110=0279=0269=0270=1.25484271=50000055=GBP/USD110=100000279=0269=0270=1.25484271=100000055=GBP/USD110=500000279=0269=0270=1.25484271=300000055=GBP/USD110=1000000279=0269=0270=1.25484271=500000055=GBP/USD110=3000000279=0269=1270=1.4352271=10000055=GBP/USD110=0279=0269=1270=1.4352271=50000055=GBP/USD110=100000279=0269=1270=1.4352271=100000055=GBP/USD110=500000279=0269=1270=1.4352271=300000055=GBP/USD110=1000000279=0269=1270=1.4352271=500000055=GBP/USD110=300000010=189
20260120-14:01:59.167908000 : 8=FIX.4.49=044635=X49=NTPRO_IDBA_UAT56=SIRIUS_500007460_MD34=46252=20260120-14:01:59.194262=MD_EUR/USD_140109278614268=6279=1269=0270=1.14817271=10000055=EUR/USD110=0279=1269=0270=1.14817271=50000055=EUR/USD110=100000279=1269=0270=1.14817271=100000055=EUR/USD110=500000279=1269=1270=1.19842271=10000055=EUR/USD110=0279=1269=1270=1.19842271=50000055=EUR/USD110=100000279=1269=1270=1.19842271=100000055=EUR/USD110=50000010=010
20260120-14:01:59.262436000 : 8=FIX.4.49=039735=X49=NTPRO_IDBA_UAT56=SIRIUS_500007460_MD34=46352=20260120-14:01:59.284262=MD_GBP/USD_140109778778268=5279=1269=0270=1.25485271=10000055=GBP/USD110=0279=1269=0270=1.25485271=50000055=GBP/USD110=100000279=1269=0270=1.25485271=100000055=GBP/USD110=500000279=1269=0270=1.25485271=300000055=GBP/USD110=1000000279=1269=0270=1.25485271=500000055=GBP/USD110=300000010=061
20260120-14:01:59.407131000 : 8=FIX.4.49=067835=X49=NTPRO_IDBA_UAT56=SIRIUS_500007460_MD34=46452=20260120-14:01:59.440262=MD_GBP/USD_140109778778268=10279=2269=0270=1.25485271=10000055=GBP/USD110=0279=2269=0270=1.25485271=50000055=GBP/USD110=100000279=2269=0270=1.25485271=100000055=GBP/USD110=500000279=2269=0270=1.25485271=300000055=GBP/USD110=1000000279=2269=0270=1.25485271=500000055=GBP/USD110=3000000279=2269=1270=1.4352271=10000055=GBP/USD110=0279=2269=1270=1.4352271=50000055=GBP/USD110=100000279=2269=1270=1.4352271=100000055=GBP/USD110=500000279=2269=1270=1.4352271=300000055=GBP/USD110=1000000279=2269=1270=1.4352271=500000055=GBP/USD110=300000010=214
20260120-14:01:59.463651000 : 8=FIX.4.49=044635=X49=NTPRO_IDBA_UAT56=SIRIUS_500007460_MD34=46552=20260120-14:01:59.480262=MD_EUR/USD_140109278614268=6279=1269=0270=1.14818271=10000055=EUR/USD110=0279=1269=0270=1.14818271=50000055=EUR/USD110=100000279=1269=0270=1.14818271=100000055=EUR/USD110=500000279=1269=1270=1.19843271=10000055=EUR/USD110=0279=1269=1270=1.19843271=50000055=EUR/USD110=100000279=1269=1270=1.19843271=100000055=EUR/USD110=50000010=017
20260120-14:01:59.519729000 : 8=FIX.4.49=044635=X49=NTPRO_IDBA_UAT56=SIRIUS_500007460_MD34=46652=20260120-14:01:59.557262=MD_EUR/USD_140109278614268=6279=1269=0270=1.14817271=10000055=EUR/USD110=0279=1269=0270=1.14817271=50000055=EUR/USD110=100000279=1269=0270=1.14817271=100000055=EUR/USD110=500000279=1269=1270=1.19842271=10000055=EUR/USD110=0279=1269=1270=1.19842271=50000055=EUR/USD110=100000279=1269=1270=1.19842271=100000055=EUR/USD110=50000010=017
20260120-14:01:59.667513000 : 8=FIX.4.49=044635=X49=NTPRO_IDBA_UAT56=SIRIUS_500007460_MD34=46752=20260120-14:01:59.708262=MD_EUR/USD_140109278614268=6279=1269=0270=1.14818271=10000055=EUR/USD110=0279=1269=0270=1.14818271=50000055=EUR/USD110=100000279=1269=0270=1.14818271=100000055=EUR/USD110=500000279=1269=1270=1.19843271=10000055=EUR/USD110=0279=1269=1270=1.19843271=50000055=EUR/USD110=100000279=1269=1270=1.19843271=100000055=EUR/USD110=50000010=022
20260120-14:02:00.608088000 : 8=FIX.4.49=068335=X49=NTPRO_IDBA_UAT56=SIRIUS_500007460_MD34=46852=20260120-14:01:59.926262=MD_GBP/USD_140109778778268=10279=0269=0270=1.25485271=10000055=GBP/USD110=0279=0269=0270=1.25485271=50000055=GBP/USD110=100000279=0269=0270=1.25485271=100000055=GBP/USD110=500000279=0269=0270=1.25485271=300000055=GBP/USD110=1000000279=0269=0270=1.25485271=500000055=GBP/USD110=3000000279=0269=1270=1.43521271=10000055=GBP/USD110=0279=0269=1270=1.43521271=50000055=GBP/USD110=100000279=0269=1270=1.43521271=100000055=GBP/USD110=500000279=0269=1270=1.43521271=300000055=GBP/USD110=1000000279=0269=1270=1.43521271=500000055=GBP/USD110=300000010=192
20260120-14:02:00.608528000 : 8=FIX.4.49=068335=X49=NTPRO_IDBA_UAT56=SIRIUS_500007460_MD34=46952=20260120-14:02:00.237262=MD_GBP/USD_140109778778268=10279=2269=0270=1.25485271=10000055=GBP/USD110=0279=2269=0270=1.25485271=50000055=GBP/USD110=100000279=2269=0270=1.25485271=100000055=GBP/USD110=500000279=2269=0270=1.25485271=300000055=GBP/USD110=1000000279=2269=0270=1.25485271=500000055=GBP/USD110=3000000279=2269=1270=1.43521271=10000055=GBP/USD110=0279=2269=1270=1.43521271=50000055=GBP/USD110=100000279=2269=1270=1.43521271=100000055=GBP/USD110=500000279=2269=1270=1.43521271=300000055=GBP/USD110=1000000279=2269=1270=1.43521271=500000055=GBP/USD110=300000010=195
20260120-14:02:00.712578000 : 8=FIX.4.49=068335=X49=NTPRO_IDBA_UAT56=SIRIUS_500007460_MD34=47052=20260120-14:02:00.767262=MD_GBP/USD_140109778778268=10279=0269=0270=1.25485271=10000055=GBP/USD110=0279=0269=0270=1.25485271=50000055=GBP/USD110=100000279=0269=0270=1.25485271=100000055=GBP/USD110=500000279=0269=0270=1.25485271=300000055=GBP/USD110=1000000279=0269=0270=1.25485271=500000055=GBP/USD110=3000000279=0269=1270=1.43521271=10000055=GBP/USD110=0279=0269=1270=1.43521271=50000055=GBP/USD110=100000279=0269=1270=1.43521271=100000055=GBP/USD110=500000279=0269=1270=1.43521271=300000055=GBP/USD110=1000000279=0269=1270=1.43521271=500000055=GBP/USD110=300000010=175
20260120-14:02:00.738473000 : 8=FIX.4.49=007835=049=NTPRO_IDBA_UAT56=SIRIUS_500007460_MD34=47152=20260120-14:02:00.80010=209
20260120-14:02:00.838269000 : 8=FIX.4.49=027935=X49=NTPRO_IDBA_UAT56=SIRIUS_500007460_MD34=47252=20260120-14:02:00.809262=MD_EUR/USD_140109278614268=3279=1269=1270=1.19842271=10000055=EUR/USD110=0279=1269=1270=1.19842271=50000055=EUR/USD110=100000279=1269=1270=1.19842271=100000055=EUR/USD110=50000010=223
20260120-14:02:01.017820000 : 8=FIX.4.49=027935=X49=NTPRO_IDBA_UAT56=SIRIUS_500007460_MD34=47352=20260120-14:02:01.094262=MD_EUR/USD_140109278614268=3279=1269=0270=1.14817271=10000055=EUR/USD110=0279=1269=0270=1.14817271=50000055=EUR/USD110=100000279=1269=0270=1.14817271=100000055=EUR/USD110=50000010=209
20260120-14:02:01.164184000 : 8=FIX.4.49=044635=X49=NTPRO_IDBA_UAT56=SIRIUS_500007460_MD34=47452=20260120-14:02:01.244262=MD_EUR/USD_140109278614268=6279=1269=0270=1.14818271=10000055=EUR/USD110=0279=1269=0270=1.14818271=50000055=EUR/USD110=100000279=1269=0270=1.14818271=100000055=EUR/USD110=500000279=1269=1270=1.19843271=10000055=EUR/USD110=0279=1269=1270=1.19843271=50000055=EUR/USD110=100000279=1269=1270=1.19843271=100000055=EUR/USD110=50000010=003
20260120-14:02:01.212832000 : 8=FIX.4.49=044635=X49=NTPRO_IDBA_UAT56=SIRIUS_500007460_MD34=47552=20260120-14:02:01.294262=MD_EUR/USD_140109278614268=6279=1269=0270=1.14817271=10000055=EUR/USD110=0279=1269=0270=1.14817271=50000055=EUR/USD110=100000279=1269=0270=1.14817271=100000055=EUR/USD110=500000279=1269=1270=1.19842271=10000055=EUR/USD110=0279=1269=1270=1.19842271=50000055=EUR/USD110=100000279=1269=1270=1.19842271=100000055=EUR/USD110=50000010=003
20260120-14:02:01.859447000 : 8=FIX.4.49=039235=X49=NTPRO_IDBA_UAT56=SIRIUS_500007460_MD34=47652=20260120-14:02:01.912262=MD_GBP/USD_140109778778268=5279=1269=1270=1.4352271=10000055=GBP/USD110=0279=1269=1270=1.4352271=50000055=GBP/USD110=100000279=1269=1270=1.4352271=100000055=GBP/USD110=500000279=1269=1270=1.4352271=300000055=GBP/USD110=1000000279=1269=1270=1.4352271=500000055=GBP/USD110=300000010=017
20260120-14:02:01.973068000 : 8=FIX.4.49=039735=X49=NTPRO_IDBA_UAT56=SIRIUS_500007460_MD34=47752=20260120-14:02:02.073262=MD_GBP/USD_140109778778268=5279=1269=1270=1.43521271=10000055=GBP/USD110=0279=1269=1270=1.43521271=50000055=GBP/USD110=100000279=1269=1270=1.43521271=100000055=GBP/USD110=500000279=1269=1270=1.43521271=300000055=GBP/USD110=1000000279=1269=1270=1.43521271=500000055=GBP/USD110=300000010=011
20260120-14:02:02.519592000 : 8=FIX.4.49=039235=X49=NTPRO_IDBA_UAT56=SIRIUS_500007460_MD34=47852=20260120-14:02:02.632262=MD_GBP/USD_140109778778268=5279=1269=1270=1.4352271=10000055=GBP/USD110=0279=1269=1270=1.4352271=50000055=GBP/USD110=100000279=1269=1270=1.4352271=100000055=GBP/USD110=500000279=1269=1270=1.4352271=300000055=GBP/USD110=1000000279=1269=1270=1.4352271=500000055=GBP/USD110=300000010=019
20260120-14:02:02.654830000 : 8=FIX.4.49=044635=X49=NTPRO_IDBA_UAT56=SIRIUS_500007460_MD34=47952=20260120-14:02:02.765262=MD_EUR/USD_140109278614268=6279=1269=0270=1.14818271=10000055=EUR/USD110=0279=1269=0270=1.14818271=50000055=EUR/USD110=100000279=1269=0270=1.14818271=100000055=EUR/USD110=500000279=1269=1270=1.19843271=10000055=EUR/USD110=0279=1269=1270=1.19843271=50000055=EUR/USD110=100000279=1269=1270=1.19843271=100000055=EUR/USD110=50000010=017
20260120-14:02:02.673016000 : 8=FIX.4.49=044635=X49=NTPRO_IDBA_UAT56=SIRIUS_500007460_MD34=48052=20260120-14:02:02.790262=MD_EUR/USD_140109278614268=6279=1269=0270=1.14819271=10000055=EUR/USD110=0279=1269=0270=1.14819271=50000055=EUR/USD110=100000279=1269=0270=1.14819271=100000055=EUR/USD110=500000279=1269=1270=1.19844271=10000055=EUR/USD110=0279=1269=1270=1.19844271=50000055=EUR/USD110=100000279=1269=1270=1.19844271=100000055=EUR/USD110=50000010=013
20260120-14:02:02.899663000 : 8=FIX.4.49=039735=X49=NTPRO_IDBA_UAT56=SIRIUS_500007460_MD34=48152=20260120-14:02:03.023262=MD_GBP/USD_140109778778268=5279=1269=1270=1.43521271=10000055=GBP/USD110=0279=1269=1270=1.43521271=50000055=GBP/USD110=100000279=1269=1270=1.43521271=100000055=GBP/USD110=500000279=1269=1270=1.43521271=300000055=GBP/USD110=1000000279=1269=1270=1.43521271=500000055=GBP/USD110=300000010=002
20260120-14:02:02.935434000 : 8=FIX.4.49=068335=X49=NTPRO_IDBA_UAT56=SIRIUS_500007460_MD34=48252=20260120-14:02:03.058262=MD_GBP/USD_140109778778268=10279=1269=0270=1.25486271=10000055=GBP/USD110=0279=1269=0270=1.25486271=50000055=GBP/USD110=100000279=1269=0270=1.25486271=100000055=GBP/USD110=500000279=1269=0270=1.25486271=300000055=GBP/USD110=1000000279=1269=0270=1.25486271=500000055=GBP/USD110=3000000279=1269=1270=1.43522271=10000055=GBP/USD110=0279=1269=1270=1.43522271=50000055=GBP/USD110=100000279=1269=1270=1.43522271=100000055=GBP/USD110=500000279=1269=1270=1.43522271=300000055=GBP/USD110=1000000279=1269=1270=1.43522271=500000055=GBP/USD110=300000010=194
20260120-14:02:03.491255000 : 8=FIX.4.49=068335=X49=NTPRO_IDBA_UAT56=SIRIUS_500007460_MD34=48352=20260120-14:02:03.634262=MD_GBP/USD_140109778778268=10279=1269=0270=1.25487271=10000055=GBP/USD110=0279=1269=0270=1.25487271=50000055=GBP/USD110=100000279=1269=0270=1.25487271=100000055=GBP/USD110=500000279=1269=0270=1.25487271=300000055=GBP/USD110=1000000279=1269=0270=1.25487271=500000055=GBP/USD110=3000000279=1269=1270=1.43521271=10000055=GBP/USD110=0279=1269=1270=1.43521271=50000055=GBP/USD110=100000279=1269=1270=1.43521271=100000055=GBP/USD110=500000279=1269=1270=1.43521271=300000055=GBP/USD110=1000000279=1269=1270=1.43521271=500000055=GBP/USD110=300000010=195
20260120-14:02:03.523539000 : 8=FIX.4.49=027935=X49=NTPRO_IDBA_UAT56=SIRIUS_500007460_MD34=48452=20260120-14:02:03.668262=MD_EUR/USD_140109278614268=3279=1269=1270=1.19843271=10000055=EUR/USD110=0279=1269=1270=1.19843271=50000055=EUR/USD110=100000279=1269=1270=1.19843271=100000055=EUR/USD110=50000010=235
20260120-14:02:03.560659000 : 8=FIX.4.49=068335=X49=NTPRO_IDBA_UAT56=SIRIUS_500007460_MD34=48552=20260120-14:02:03.707262=MD_GBP/USD_140109778778268=10279=2269=0270=1.25487271=10000055=GBP/USD110=0279=2269=0270=1.25487271=50000055=GBP/USD110=100000279=2269=0270=1.25487271=100000055=GBP/USD110=500000279=2269=0270=1.25487271=300000055=GBP/USD110=1000000279=2269=0270=1.25487271=500000055=GBP/USD110=3000000279=2269=1270=1.43521271=10000055=GBP/USD110=0279=2269=1270=1.43521271=50000055=GBP/USD110=100000279=2269=1270=1.43521271=100000055=GBP/USD110=500000279=2269=1270=1.43521271=300000055=GBP/USD110=1000000279=2269=1270=1.43521271=500000055=GBP/USD110=300000010=208
20260120-14:02:03.649444000 : 8=FIX.4.49=044635=X49=NTPRO_IDBA_UAT56=SIRIUS_500007460_MD34=48652=20260120-14:02:03.774262=MD_EUR/USD_140109278614268=6279=2269=0270=1.14819271=10000055=EUR/USD110=0279=2269=0270=1.14819271=50000055=EUR/USD110=100000279=2269=0270=1.14819271=100000055=EUR/USD110=500000279=2269=1270=1.19843271=10000055=EUR/USD110=0279=2269=1270=1.19843271=50000055=EUR/USD110=100000279=2269=1270=1.19843271=100000055=EUR/USD110=50000010=025
20260120-14:02:03.722512000 : 8=FIX.4.49=044635=X49=NTPRO_IDBA_UAT56=SIRIUS_500007460_MD34=48752=20260120-14:02:03.870262=MD_EUR/USD_140109278614268=6279=0269=0270=1.14809271=10000055=EUR/USD110=0279=0269=0270=1.14809271=50000055=EUR/USD110=100000279=0269=0270=1.14809271=100000055=EUR/USD110=500000279=0269=1270=1.19834271=10000055=EUR/USD110=0279=0269=1270=1.19834271=50000055=EUR/USD110=100000279=0269=1270=1.19834271=100000055=EUR/USD110=50000010=008
20260120-14:02:03.723211000 : 8=FIX.4.49=068335=X49=NTPRO_IDBA_UAT56=SIRIUS_500007460_MD34=48852=20260120-14:02:03.878262=MD_GBP/USD_140109778778268=10279=0269=0270=1.25483271=10000055=GBP/USD110=0279=0269=0270=1.25483271=50000055=GBP/USD110=100000279=0269=0270=1.25483271=100000055=GBP/USD110=500000279=0269=0270=1.25483271=300000055=GBP/USD110=1000000279=0269=0270=1.25483271=500000055=GBP/USD110=3000000279=0269=1270=1.43518271=10000055=GBP/USD110=0279=0269=1270=1.43518271=50000055=GBP/USD110=100000279=0269=1270=1.43518271=100000055=GBP/USD110=500000279=0269=1270=1.43518271=300000055=GBP/USD110=1000000279=0269=1270=1.43518271=500000055=GBP/USD110=300000010=210
20260120-14:02:04.070785000 : 8=FIX.4.49=068335=X49=NTPRO_IDBA_UAT56=SIRIUS_500007460_MD34=48952=20260120-14:02:04.212262=MD_GBP/USD_140109778778268=10279=2269=0270=1.25483271=10000055=GBP/USD110=0279=2269=0270=1.25483271=50000055=GBP/USD110=100000279=2269=0270=1.25483271=100000055=GBP/USD110=500000279=2269=0270=1.25483271=300000055=GBP/USD110=1000000279=2269=0270=1.25483271=500000055=GBP/USD110=3000000279=2269=1270=1.43518271=10000055=GBP/USD110=0279=2269=1270=1.43518271=50000055=GBP/USD110=100000279=2269=1270=1.43518271=100000055=GBP/USD110=500000279=2269=1270=1.43518271=300000055=GBP/USD110=1000000279=2269=1270=1.43518271=500000055=GBP/USD110=300000010=214
20260120-14:02:04.188021000 : 8=FIX.4.49=044335=X49=NTPRO_IDBA_UAT56=SIRIUS_500007460_MD34=49052=20260120-14:02:04.368262=MD_EUR/USD_140109278614268=6279=1269=0270=1.1481271=10000055=EUR/USD110=0279=1269=0270=1.1481271=50000055=EUR/USD110=100000279=1269=0270=1.1481271=100000055=EUR/USD110=500000279=1269=1270=1.19835271=10000055=EUR/USD110=0279=1269=1270=1.19835271=50000055=EUR/USD110=100000279=1269=1270=1.19835271=100000055=EUR/USD110=50000010=099
20260120-14:02:04.232042000 : 8=FIX.4.49=068335=X49=NTPRO_IDBA_UAT56=SIRIUS_500007460_MD34=49152=20260120-14:02:04.390262=MD_GBP/USD_140109778778268=10279=0269=0270=1.25484271=10000055=GBP/USD110=0279=0269=0270=1.25484271=50000055=GBP/USD110=100000279=0269=0270=1.25484271=100000055=GBP/USD110=500000279=0269=0270=1.25484271=300000055=GBP/USD110=1000000279=0269=0270=1.25484271=500000055=GBP/USD110=3000000279=0269=1270=1.43519271=10000055=GBP/USD110=0279=0269=1270=1.43519271=50000055=GBP/USD110=100000279=0269=1270=1.43519271=100000055=GBP/USD110=500000279=0269=1270=1.43519271=300000055=GBP/USD110=1000000279=0269=1270=1.43519271=500000055=GBP/USD110=300000010=204
20260120-14:02:04.252340000 : 8=FIX.4.49=068335=X49=NTPRO_IDBA_UAT56=SIRIUS_500007460_MD34=49252=20260120-14:02:04.433262=MD_GBP/USD_140109778778268=10279=2269=0270=1.25484271=10000055=GBP/USD110=0279=2269=0270=1.25484271=50000055=GBP/USD110=100000279=2269=0270=1.25484271=100000055=GBP/USD110=500000279=2269=0270=1.25484271=300000055=GBP/USD110=1000000279=2269=0270=1.25484271=500000055=GBP/USD110=3000000279=2269=1270=1.43519271=10000055=GBP/USD110=0279=2269=1270=1.43519271=50000055=GBP/USD110=100000279=2269=1270=1.43519271=100000055=GBP/USD110=500000279=2269=1270=1.43519271=300000055=GBP/USD110=1000000279=2269=1270=1.43519271=500000055=GBP/USD110=300000010=223
20260120-14:02:04.274260000 : 8=FIX.4.49=044635=X49=NTPRO_IDBA_UAT56=SIRIUS_500007460_MD34=49352=20260120-14:02:04.456262=MD_EUR/USD_140109278614268=6279=1269=0270=1.14812271=10000055=EUR/USD110=0279=1269=0270=1.14812271=50000055=EUR/USD110=100000279=1269=0270=1.14812271=100000055=EUR/USD110=500000279=1269=1270=1.19836271=10000055=EUR/USD110=0279=1269=1270=1.19836271=50000055=EUR/USD110=100000279=1269=1270=1.19836271=100000055=EUR/USD110=50000010=000
20260120-14:02:04.350101000 : 8=FIX.4.49=027935=X49=NTPRO_IDBA_UAT56=SIRIUS_500007460_MD34=49452=20260120-14:02:04.535262=MD_EUR/USD_140109278614268=3279=1269=0270=1.14811271=10000055=EUR/USD110=0279=1269=0270=1.14811271=50000055=EUR/USD110=100000279=1269=0270=1.14811271=100000055=EUR/USD110=50000010=197
20260120-14:02:04.387662000 : 8=FIX.4.49=067835=X49=NTPRO_IDBA_UAT56=SIRIUS_500007460_MD34=49552=20260120-14:02:04.579262=MD_GBP/USD_140109778778268=10279=0269=0270=1.25484271=10000055=GBP/USD110=0279=0269=0270=1.25484271=50000055=GBP/USD110=100000279=0269=0270=1.25484271=100000055=GBP/USD110=500000279=0269=0270=1.25484271=300000055=GBP/USD110=1000000279=0269=0270=1.25484271=500000055=GBP/USD110=3000000279=0269=1270=1.4352271=10000055=GBP/USD110=0279=0269=1270=1.4352271=50000055=GBP/USD110=100000279=0269=1270=1.4352271=100000055=GBP/USD110=500000279=0269=1270=1.4352271=300000055=GBP/USD110=1000000279=0269=1270=1.4352271=500000055=GBP/USD110=300000010=197
20260120-14:02:04.439656000 : 8=FIX.4.49=044335=X49=NTPRO_IDBA_UAT56=SIRIUS_500007460_MD34=49652=20260120-14:02:04.631262=MD_EUR/USD_140109278614268=6279=1269=0270=1.1481271=10000055=EUR/USD110=0279=1269=0270=1.1481271=50000055=EUR/USD110=100000279=1269=0270=1.1481271=100000055=EUR/USD110=500000279=1269=1270=1.19835271=10000055=EUR/USD110=0279=1269=1270=1.19835271=50000055=EUR/USD110=100000279=1269=1270=1.19835271=100000055=EUR/USD110=50000010=098
20260120-14:02:04.522602000 : 8=FIX.4.49=044635=X49=NTPRO_IDBA_UAT56=SIRIUS_500007460_MD34=49752=20260120-14:02:04.710262=MD_EUR/USD_140109278614268=6279=1269=0270=1.14809271=10000055=EUR/USD110=0279=1269=0270=1.14809271=50000055=EUR/USD110=100000279=1269=0270=1.14809271=100000055=EUR/USD110=500000279=1269=1270=1.19834271=10000055=EUR/USD110=0279=1269=1270=1.19834271=50000055=EUR/USD110=100000279=1269=1270=1.19834271=100000055=EUR/USD110=50000010=009
20260120-14:02:04.694246000 : 8=FIX.4.49=044335=X49=NTPRO_IDBA_UAT56=SIRIUS_500007460_MD34=49852=20260120-14:02:04.900262=MD_EUR/USD_140109278614268=6279=1269=0270=1.1481271=10000055=EUR/USD110=0279=1269=0270=1.1481271=50000055=EUR/USD110=100000279=1269=0270=1.1481271=100000055=EUR/USD110=500000279=1269=1270=1.19835271=10000055=EUR/USD110=0279=1269=1270=1.19835271=50000055=EUR/USD110=100000279=1269=1270=1.19835271=100000055=EUR/USD110=50000010=099
20260120-14:02:04.839079000 : 8=FIX.4.49=039735=X49=NTPRO_IDBA_UAT56=SIRIUS_500007460_MD34=49952=20260120-14:02:05.055262=MD_GBP/USD_140109778778268=5279=1269=1270=1.43519271=10000055=GBP/USD110=0279=1269=1270=1.43519271=50000055=GBP/USD110=100000279=1269=1270=1.43519271=100000055=GBP/USD110=500000279=1269=1270=1.43519271=300000055=GBP/USD110=1000000279=1269=1270=1.43519271=500000055=GBP/USD110=300000010=053
20260120-14:02:04.921196000 : 8=FIX.4.49=027935=X49=NTPRO_IDBA_UAT56=SIRIUS_500007460_MD34=50052=20260120-14:02:05.137262=MD_EUR/USD_140109278614268=3279=1269=1270=1.19834271=10000055=EUR/USD110=0279=1269=1270=1.19834271=50000055=EUR/USD110=100000279=1269=1270=1.19834271=100000055=EUR/USD110=50000010=217
20260120-14:02:04.951002000 : 8=FIX.4.49=044635=X49=NTPRO_IDBA_UAT56=SIRIUS_500007460_MD34=50152=20260120-14:02:05.173262=MD_EUR/USD_140109278614268=6279=1269=0270=1.14808271=10000055=EUR/USD110=0279=1269=0270=1.14808271=50000055=EUR/USD110=100000279=1269=0270=1.14808271=100000055=EUR/USD110=500000279=1269=1270=1.19833271=10000055=EUR/USD110=0279=1269=1270=1.19833271=50000055=EUR/USD110=100000279=1269=1270=1.19833271=100000055=EUR/USD110=50000010=249
20260120-14:02:05.066814000 : 8=FIX.4.49=027935=X49=NTPRO_IDBA_UAT56=SIRIUS_500007460_MD34=50252=20260120-14:02:05.295262=MD_EUR/USD_140109278614268=3279=1269=1270=1.19832271=10000055=EUR/USD110=0279=1269=1270=1.19832271=50000055=EUR/USD110=100000279=1269=1270=1.19832271=100000055=EUR/USD110=50000010=218
20260120-14:02:05.125782000 : 8=FIX.4.49=027935=X49=NTPRO_IDBA_UAT56=SIRIUS_500007460_MD34=50352=20260120-14:02:05.356262=MD_EUR/USD_140109278614268=3279=1269=1270=1.19833271=10000055=EUR/USD110=0279=1269=1270=1.19833271=50000055=EUR/USD110=100000279=1269=1270=1.19833271=100000055=EUR/USD110=50000010=220
20260120-14:02:05.224091000 : 8=FIX.4.49=027935=X49=NTPRO_IDBA_UAT56=SIRIUS_500007460_MD34=50452=20260120-14:02:05.461262=MD_EUR/USD_140109278614268=3279=1269=1270=1.19832271=10000055=EUR/USD110=0279=1269=1270=1.19832271=50000055=EUR/USD110=100000279=1269=1270=1.19832271=100000055=EUR/USD110=50000010=215
20260120-14:02:05.257744000 : 8=FIX.4.49=027935=X49=NTPRO_IDBA_UAT56=SIRIUS_500007460_MD34=50552=20260120-14:02:05.496262=MD_EUR/USD_140109278614268=3279=1269=1270=1.19833271=10000055=EUR/USD110=0279=1269=1270=1.19833271=50000055=EUR/USD110=100000279=1269=1270=1.19833271=100000055=EUR/USD110=50000010=227
20260120-14:02:05.494720000 : 8=FIX.4.49=068335=X49=NTPRO_IDBA_UAT56=SIRIUS_500007460_MD34=50652=20260120-14:02:05.717262=MD_GBP/USD_140109778778268=10279=2269=0270=1.25484271=10000055=GBP/USD110=0279=2269=0270=1.25484271=50000055=GBP/USD110=100000279=2269=0270=1.25484271=100000055=GBP/USD110=500000279=2269=0270=1.25484271=300000055=GBP/USD110=1000000279=2269=0270=1.25484271=500000055=GBP/USD110=3000000279=2269=1270=1.43519271=10000055=GBP/USD110=0279=2269=1270=1.43519271=50000055=GBP/USD110=100000279=2269=1270=1.43519271=100000055=GBP/USD110=500000279=2269=1270=1.43519271=300000055=GBP/USD110=1000000279=2269=1270=1.43519271=500000055=GBP/USD110=300000010=225
20260120-14:02:07.186341000 : 8=FIX.4.49=12435=x34=749=SIRIUS_500007460_MD52=20260120-14:02:07.18556=NTPRO_IDBA_UAT320=SL_1768917727185322=SL_1768917727185559=410=172
20260120-14:02:07.291511000 : 8=FIX.4.49=013835=349=NTPRO_IDBA_UAT56=SIRIUS_500007460_MD34=50752=20260120-14:02:07.64145=7371=559372=x373=558=Invalid SecurityListRequestType10=168
20260120-14:02:26.205461000 : 8=FIX.4.49=008735=149=NTPRO_IDBA_UAT56=SIRIUS_500007460_MD34=50852=20260120-14:02:26.111112=TR-A10=188
20260120-14:02:26.206573000 : 8=FIX.4.49=8535=034=849=SIRIUS_500007460_MD52=20260120-14:02:26.20556=NTPRO_IDBA_UAT112=TR-A10=248
20260120-14:02:30.671278000 : 8=FIX.4.49=007835=049=NTPRO_IDBA_UAT56=SIRIUS_500007460_MD34=50952=20260120-14:02:30.81310=218
20260120-14:02:42.139431000 : 8=FIX.4.49=12435=x34=949=SIRIUS_500007460_MD52=20260120-14:02:42.13856=NTPRO_IDBA_UAT320=SL_1768917762138322=SL_1768917762138559=410=165
20260120-14:02:42.265422000 : 8=FIX.4.49=013835=349=NTPRO_IDBA_UAT56=SIRIUS_500007460_MD34=51052=20260120-14:02:42.81145=9371=559372=x373=558=Invalid SecurityListRequestType10=162
20260120-14:03:00.756527000 : 8=FIX.4.49=007835=049=NTPRO_IDBA_UAT56=SIRIUS_500007460_MD34=51152=20260120-14:03:00.82510=212
20260120-14:03:05.638640000 : 8=FIX.4.49=044635=X49=NTPRO_IDBA_UAT56=SIRIUS_500007460_MD34=51252=20260120-14:03:05.892262=MD_EUR/USD_140109278614268=6279=1269=0270=1.14799271=10000055=EUR/USD110=0279=1269=0270=1.14799271=50000055=EUR/USD110=100000279=1269=0270=1.14799271=100000055=EUR/USD110=500000279=1269=1270=1.19823271=10000055=EUR/USD110=0279=1269=1270=1.19823271=50000055=EUR/USD110=100000279=1269=1270=1.19823271=100000055=EUR/USD110=50000010=028
20260120-14:03:05.640846000 : 8=FIX.4.49=068335=X49=NTPRO_IDBA_UAT56=SIRIUS_500007460_MD34=51352=20260120-14:03:05.895262=MD_GBP/USD_140109778778268=10279=0269=0270=1.25462271=10000055=GBP/USD110=0279=0269=0270=1.25462271=50000055=GBP/USD110=100000279=0269=0270=1.25462271=100000055=GBP/USD110=500000279=0269=0270=1.25462271=300000055=GBP/USD110=1000000279=0269=0270=1.25462271=500000055=GBP/USD110=3000000279=0269=1270=1.43497271=10000055=GBP/USD110=0279=0269=1270=1.43497271=50000055=GBP/USD110=100000279=0269=1270=1.43497271=100000055=GBP/USD110=500000279=0269=1270=1.43497271=300000055=GBP/USD110=1000000279=0269=1270=1.43497271=500000055=GBP/USD110=300000010=216
20260120-14:03:05.691820000 : 8=FIX.4.49=039735=X49=NTPRO_IDBA_UAT56=SIRIUS_500007460_MD34=51452=20260120-14:03:05.939262=MD_GBP/USD_140109778778268=5279=1269=1270=1.43496271=10000055=GBP/USD110=0279=1269=1270=1.43496271=50000055=GBP/USD110=100000279=1269=1270=1.43496271=100000055=GBP/USD110=500000279=1269=1270=1.43496271=300000055=GBP/USD110=1000000279=1269=1270=1.43496271=500000055=GBP/USD110=300000010=073
20260120-14:03:05.844147000 : 8=FIX.4.49=044635=X49=NTPRO_IDBA_UAT56=SIRIUS_500007460_MD34=51552=20260120-14:03:06.105262=MD_EUR/USD_140109278614268=6279=1269=0270=1.14798271=10000055=EUR/USD110=0279=1269=0270=1.14798271=50000055=EUR/USD110=100000279=1269=0270=1.14798271=100000055=EUR/USD110=500000279=1269=1270=1.19822271=10000055=EUR/USD110=0279=1269=1270=1.19822271=50000055=EUR/USD110=100000279=1269=1270=1.19822271=100000055=EUR/USD110=50000010=013
20260120-14:03:05.879210000 : 8=FIX.4.49=068335=X49=NTPRO_IDBA_UAT56=SIRIUS_500007460_MD34=51652=20260120-14:03:06.133262=MD_GBP/USD_140109778778268=10279=1269=0270=1.25461271=10000055=GBP/USD110=0279=1269=0270=1.25461271=50000055=GBP/USD110=100000279=1269=0270=1.25461271=100000055=GBP/USD110=500000279=1269=0270=1.25461271=300000055=GBP/USD110=1000000279=1269=0270=1.25461271=500000055=GBP/USD110=3000000279=1269=1270=1.43494271=10000055=GBP/USD110=0279=1269=1270=1.43494271=50000055=GBP/USD110=100000279=1269=1270=1.43494271=100000055=GBP/USD110=500000279=1269=1270=1.43494271=300000055=GBP/USD110=1000000279=1269=1270=1.43494271=500000055=GBP/USD110=300000010=195
20260120-14:03:05.900611000 : 8=FIX.4.49=039735=X49=NTPRO_IDBA_UAT56=SIRIUS_500007460_MD34=51752=20260120-14:03:06.153262=MD_GBP/USD_140109778778268=5279=1269=1270=1.43493271=10000055=GBP/USD110=0279=1269=1270=1.43493271=50000055=GBP/USD110=100000279=1269=1270=1.43493271=100000055=GBP/USD110=500000279=1269=1270=1.43493271=300000055=GBP/USD110=1000000279=1269=1270=1.43493271=500000055=GBP/USD110=300000010=050
20260120-14:03:05.941313000 : 8=FIX.4.49=039735=X49=NTPRO_IDBA_UAT56=SIRIUS_500007460_MD34=51852=20260120-14:03:06.173262=MD_GBP/USD_140109778778268=5279=1269=0270=1.25459271=10000055=GBP/USD110=0279=1269=0270=1.25459271=50000055=GBP/USD110=100000279=1269=0270=1.25459271=100000055=GBP/USD110=500000279=1269=0270=1.25459271=300000055=GBP/USD110=1000000279=1269=0270=1.25459271=500000055=GBP/USD110=300000010=058
20260120-14:03:05.954442000 : 8=FIX.4.49=027935=X49=NTPRO_IDBA_UAT56=SIRIUS_500007460_MD34=51952=20260120-14:03:06.211262=MD_EUR/USD_140109278614268=3279=1269=1270=1.19823271=10000055=EUR/USD110=0279=1269=1270=1.19823271=50000055=EUR/USD110=100000279=1269=1270=1.19823271=100000055=EUR/USD110=50000010=216
20260120-14:03:06.040859000 : 8=FIX.4.49=027935=X49=NTPRO_IDBA_UAT56=SIRIUS_500007460_MD34=52052=20260120-14:03:06.307262=MD_EUR/USD_140109278614268=3279=1269=0270=1.14799271=10000055=EUR/USD110=0279=1269=0270=1.14799271=50000055=EUR/USD110=100000279=1269=0270=1.14799271=100000055=EUR/USD110=50000010=232
20260120-14:03:06.725411000 : 8=FIX.4.49=027935=X49=NTPRO_IDBA_UAT56=SIRIUS_500007460_MD34=52152=20260120-14:03:07.017262=MD_EUR/USD_140109278614268=3279=1269=1270=1.19824271=10000055=EUR/USD110=0279=1269=1270=1.19824271=50000055=EUR/USD110=100000279=1269=1270=1.19824271=100000055=EUR/USD110=50000010=217
20260120-14:03:06.821962000 : 8=FIX.4.49=027935=X49=NTPRO_IDBA_UAT56=SIRIUS_500007460_MD34=52252=20260120-14:03:07.118262=MD_EUR/USD_140109278614268=3279=1269=1270=1.19823271=10000055=EUR/USD110=0279=1269=1270=1.19823271=50000055=EUR/USD110=100000279=1269=1270=1.19823271=100000055=EUR/USD110=50000010=217
20260120-14:03:06.944985000 : 8=FIX.4.49=027935=X49=NTPRO_IDBA_UAT56=SIRIUS_500007460_MD34=52352=20260120-14:03:07.245262=MD_EUR/USD_140109278614268=3279=1269=1270=1.19824271=10000055=EUR/USD110=0279=1269=1270=1.19824271=50000055=EUR/USD110=100000279=1269=1270=1.19824271=100000055=EUR/USD110=50000010=222
20260120-14:03:06.994574000 : 8=FIX.4.49=044635=X49=NTPRO_IDBA_UAT56=SIRIUS_500007460_MD34=52452=20260120-14:03:07.277262=MD_EUR/USD_140109278614268=6279=1269=0270=1.14798271=10000055=EUR/USD110=0279=1269=0270=1.14798271=50000055=EUR/USD110=100000279=1269=0270=1.14798271=100000055=EUR/USD110=500000279=1269=1270=1.19823271=10000055=EUR/USD110=0279=1269=1270=1.19823271=50000055=EUR/USD110=100000279=1269=1270=1.19823271=100000055=EUR/USD110=50000010=027
20260120-14:03:06.995203000 : 8=FIX.4.49=039235=X49=NTPRO_IDBA_UAT56=SIRIUS_500007460_MD34=52552=20260120-14:03:07.290262=MD_GBP/USD_140109778778268=5279=1269=0270=1.2546271=10000055=GBP/USD110=0279=1269=0270=1.2546271=50000055=GBP/USD110=100000279=1269=0270=1.2546271=100000055=GBP/USD110=500000279=1269=0270=1.2546271=300000055=GBP/USD110=1000000279=1269=0270=1.2546271=500000055=GBP/USD110=300000010=028
20260120-14:03:07.110063000 : 8=FIX.4.49=027935=X49=NTPRO_IDBA_UAT56=SIRIUS_500007460_MD34=52652=20260120-14:03:07.414262=MD_EUR/USD_140109278614268=3279=1269=0270=1.14799271=10000055=EUR/USD110=0279=1269=0270=1.14799271=50000055=EUR/USD110=100000279=1269=0270=1.14799271=100000055=EUR/USD110=50000010=238
20260120-14:03:07.207241000 : 8=FIX.4.49=039735=X49=NTPRO_IDBA_UAT56=SIRIUS_500007460_MD34=52752=20260120-14:03:07.508262=MD_GBP/USD_140109778778268=5279=1269=0270=1.25459271=10000055=GBP/USD110=0279=1269=0270=1.25459271=50000055=GBP/USD110=100000279=1269=0270=1.25459271=100000055=GBP/USD110=500000279=1269=0270=1.25459271=300000055=GBP/USD110=1000000279=1269=0270=1.25459271=500000055=GBP/USD110=300000010=061
20260120-14:03:07.217540000 : 8=FIX.4.49=027935=X49=NTPRO_IDBA_UAT56=SIRIUS_500007460_MD34=52852=20260120-14:03:07.526262=MD_EUR/USD_140109278614268=3279=1269=0270=1.14798271=10000055=EUR/USD110=0279=1269=0270=1.14798271=50000055=EUR/USD110=100000279=1269=0270=1.14798271=100000055=EUR/USD110=50000010=241
20260120-14:03:07.347753000 : 8=FIX.4.49=027935=X49=NTPRO_IDBA_UAT56=SIRIUS_500007460_MD34=52952=20260120-14:03:07.660262=MD_EUR/USD_140109278614268=3279=1269=0270=1.14799271=10000055=EUR/USD110=0279=1269=0270=1.14799271=50000055=EUR/USD110=100000279=1269=0270=1.14799271=100000055=EUR/USD110=50000010=244
20260120-14:03:07.511505000 : 8=FIX.4.49=027935=X49=NTPRO_IDBA_UAT56=SIRIUS_500007460_MD34=53052=20260120-14:03:07.832262=MD_EUR/USD_140109278614268=3279=1269=0270=1.14798271=10000055=EUR/USD110=0279=1269=0270=1.14798271=50000055=EUR/USD110=100000279=1269=0270=1.14798271=100000055=EUR/USD110=50000010=234
20260120-14:03:07.585427000 : 8=FIX.4.49=039735=X49=NTPRO_IDBA_UAT56=SIRIUS_500007460_MD34=53152=20260120-14:03:07.888262=MD_GBP/USD_140109778778268=5279=1269=1270=1.43492271=10000055=GBP/USD110=0279=1269=1270=1.43492271=50000055=GBP/USD110=100000279=1269=1270=1.43492271=100000055=GBP/USD110=500000279=1269=1270=1.43492271=300000055=GBP/USD110=1000000279=1269=1270=1.43492271=500000055=GBP/USD110=300000010=057
20260120-14:03:07.596653000 : 8=FIX.4.49=044635=X49=NTPRO_IDBA_UAT56=SIRIUS_500007460_MD34=53252=20260120-14:03:07.920262=MD_EUR/USD_140109278614268=6279=1269=0270=1.14797271=10000055=EUR/USD110=0279=1269=0270=1.14797271=50000055=EUR/USD110=100000279=1269=0270=1.14797271=100000055=EUR/USD110=500000279=1269=1270=1.19822271=10000055=EUR/USD110=0279=1269=1270=1.19822271=50000055=EUR/USD110=100000279=1269=1270=1.19822271=100000055=EUR/USD110=50000010=015
20260120-14:03:07.617135000 : 8=FIX.4.49=039735=X49=NTPRO_IDBA_UAT56=SIRIUS_500007460_MD34=53352=20260120-14:03:07.941262=MD_GBP/USD_140109778778268=5279=1269=0270=1.25458271=10000055=GBP/USD110=0279=1269=0270=1.25458271=50000055=GBP/USD110=100000279=1269=0270=1.25458271=100000055=GBP/USD110=500000279=1269=0270=1.25458271=300000055=GBP/USD110=1000000279=1269=0270=1.25458271=500000055=GBP/USD110=300000010=054
20260120-14:03:07.693598000 : 8=FIX.4.49=044635=X49=NTPRO_IDBA_UAT56=SIRIUS_500007460_MD34=53452=20260120-14:03:08.020262=MD_EUR/USD_140109278614268=6279=1269=0270=1.14798271=10000055=EUR/USD110=0279=1269=0270=1.14798271=50000055=EUR/USD110=100000279=1269=0270=1.14798271=100000055=EUR/USD110=500000279=1269=1270=1.19823271=10000055=EUR/USD110=0279=1269=1270=1.19823271=50000055=EUR/USD110=100000279=1269=1270=1.19823271=100000055=EUR/USD110=50000010=015
20260120-14:03:07.746690000 : 8=FIX.4.49=027935=X49=NTPRO_IDBA_UAT56=SIRIUS_500007460_MD34=53552=20260120-14:03:08.075262=MD_EUR/USD_140109278614268=3279=1269=0270=1.14799271=10000055=EUR/USD110=0279=1269=0270=1.14799271=50000055=EUR/USD110=100000279=1269=0270=1.14799271=100000055=EUR/USD110=50000010=242
20260120-14:03:07.892164000 : 8=FIX.4.49=039735=X49=NTPRO_IDBA_UAT56=SIRIUS_500007460_MD34=53652=20260120-14:03:08.203262=MD_GBP/USD_140109778778268=5279=1269=0270=1.25457271=10000055=GBP/USD110=0279=1269=0270=1.25457271=50000055=GBP/USD110=100000279=1269=0270=1.25457271=100000055=GBP/USD110=500000279=1269=0270=1.25457271=300000055=GBP/USD110=1000000279=1269=0270=1.25457271=500000055=GBP/USD110=300000010=044
20260120-14:03:07.892771000 : 8=FIX.4.49=044635=X49=NTPRO_IDBA_UAT56=SIRIUS_500007460_MD34=53752=20260120-14:03:08.204262=MD_EUR/USD_140109278614268=6279=1269=0270=1.14797271=10000055=EUR/USD110=0279=1269=0270=1.14797271=50000055=EUR/USD110=100000279=1269=0270=1.14797271=100000055=EUR/USD110=500000279=1269=1270=1.19822271=10000055=EUR/USD110=0279=1269=1270=1.19822271=50000055=EUR/USD110=100000279=1269=1270=1.19822271=100000055=EUR/USD110=50000010=016
20260120-14:03:07.938855000 : 8=FIX.4.49=039735=X49=NTPRO_IDBA_UAT56=SIRIUS_500007460_MD34=53852=20260120-14:03:08.274262=MD_GBP/USD_140109778778268=5279=1269=0270=1.25458271=10000055=GBP/USD110=0279=1269=0270=1.25458271=50000055=GBP/USD110=100000279=1269=0270=1.25458271=100000055=GBP/USD110=500000279=1269=0270=1.25458271=300000055=GBP/USD110=1000000279=1269=0270=1.25458271=500000055=GBP/USD110=300000010=059
20260120-14:03:07.979719000 : 8=FIX.4.49=027935=X49=NTPRO_IDBA_UAT56=SIRIUS_500007460_MD34=53952=20260120-14:03:08.292262=MD_EUR/USD_140109278614268=3279=1269=0270=1.14798271=10000055=EUR/USD110=0279=1269=0270=1.14798271=50000055=EUR/USD110=100000279=1269=0270=1.14798271=100000055=EUR/USD110=50000010=244
20260120-14:03:08.092919000 : 8=FIX.4.49=039735=X49=NTPRO_IDBA_UAT56=SIRIUS_500007460_MD34=54052=20260120-14:03:08.399262=MD_GBP/USD_140109778778268=5279=1269=0270=1.25457271=10000055=GBP/USD110=0279=1269=0270=1.25457271=50000055=GBP/USD110=100000279=1269=0270=1.25457271=100000055=GBP/USD110=500000279=1269=0270=1.25457271=300000055=GBP/USD110=1000000279=1269=0270=1.25457271=500000055=GBP/USD110=300000010=055
20260120-14:03:08.178738000 : 8=FIX.4.49=027935=X49=NTPRO_IDBA_UAT56=SIRIUS_500007460_MD34=54152=20260120-14:03:08.522262=MD_EUR/USD_140109278614268=3279=1269=0270=1.14797271=10000055=EUR/USD110=0279=1269=0270=1.14797271=50000055=EUR/USD110=100000279=1269=0270=1.14797271=100000055=EUR/USD110=50000010=230
20260120-14:03:08.487110000 : 8=FIX.4.49=044635=X49=NTPRO_IDBA_UAT56=SIRIUS_500007460_MD34=54252=20260120-14:03:08.815262=MD_EUR/USD_140109278614268=6279=1269=0270=1.14799271=10000055=EUR/USD110=0279=1269=0270=1.14799271=50000055=EUR/USD110=100000279=1269=0270=1.14799271=100000055=EUR/USD110=500000279=1269=1270=1.19823271=10000055=EUR/USD110=0279=1269=1270=1.19823271=50000055=EUR/USD110=100000279=1269=1270=1.19823271=100000055=EUR/USD110=50000010=029
20260120-14:03:08.487481000 : 8=FIX.4.49=039735=X49=NTPRO_IDBA_UAT56=SIRIUS_500007460_MD34=54352=20260120-14:03:08.839262=MD_GBP/USD_140109778778268=5279=1269=0270=1.25458271=10000055=GBP/USD110=0279=1269=0270=1.25458271=50000055=GBP/USD110=100000279=1269=0270=1.25458271=100000055=GBP/USD110=500000279=1269=0270=1.25458271=300000055=GBP/USD110=1000000279=1269=0270=1.25458271=500000055=GBP/USD110=300000010=062
20260120-14:03:08.546640000 : 8=FIX.4.49=027935=X49=NTPRO_IDBA_UAT56=SIRIUS_500007460_MD34=54452=20260120-14:03:08.886262=MD_EUR/USD_140109278614268=3279=1269=1270=1.19824271=10000055=EUR/USD110=0279=1269=1270=1.19824271=50000055=EUR/USD110=100000279=1269=1270=1.19824271=100000055=EUR/USD110=50000010=237
20260120-14:03:08.574114000 : 8=FIX.4.49=039735=X49=NTPRO_IDBA_UAT56=SIRIUS_500007460_MD34=54552=20260120-14:03:08.916262=MD_GBP/USD_140109778778268=5279=1269=0270=1.25457271=10000055=GBP/USD110=0279=1269=0270=1.25457271=50000055=GBP/USD110=100000279=1269=0270=1.25457271=100000055=GBP/USD110=500000279=1269=0270=1.25457271=300000055=GBP/USD110=1000000279=1269=0270=1.25457271=500000055=GBP/USD110=300000010=055
20260120-14:03:08.574539000 : 8=FIX.4.49=044035=X49=NTPRO_IDBA_UAT56=SIRIUS_500007460_MD34=54652=20260120-14:03:08.931262=MD_EUR/USD_140109278614268=6279=1269=0270=1.148271=10000055=EUR/USD110=0279=1269=0270=1.148271=50000055=EUR/USD110=100000279=1269=0270=1.148271=100000055=EUR/USD110=500000279=1269=1270=1.19825271=10000055=EUR/USD110=0279=1269=1270=1.19825271=50000055=EUR/USD110=100000279=1269=1270=1.19825271=100000055=EUR/USD110=50000010=205
20260120-14:03:08.595267000 : 8=FIX.4.49=068335=X49=NTPRO_IDBA_UAT56=SIRIUS_500007460_MD34=54752=20260120-14:03:08.952262=MD_GBP/USD_140109778778268=10279=1269=0270=1.25459271=10000055=GBP/USD110=0279=1269=0270=1.25459271=50000055=GBP/USD110=100000279=1269=0270=1.25459271=100000055=GBP/USD110=500000279=1269=0270=1.25459271=300000055=GBP/USD110=1000000279=1269=0270=1.25459271=500000055=GBP/USD110=3000000279=1269=1270=1.43493271=10000055=GBP/USD110=0279=1269=1270=1.43493271=50000055=GBP/USD110=100000279=1269=1270=1.43493271=100000055=GBP/USD110=500000279=1269=1270=1.43493271=300000055=GBP/USD110=1000000279=1269=1270=1.43493271=500000055=GBP/USD110=300000010=240
20260120-14:03:08.672263000 : 8=FIX.4.49=039735=X49=NTPRO_IDBA_UAT56=SIRIUS_500007460_MD34=54852=20260120-14:03:09.019262=MD_GBP/USD_140109778778268=5279=1269=0270=1.25458271=10000055=GBP/USD110=0279=1269=0270=1.25458271=50000055=GBP/USD110=100000279=1269=0270=1.25458271=100000055=GBP/USD110=500000279=1269=0270=1.25458271=300000055=GBP/USD110=1000000279=1269=0270=1.25458271=500000055=GBP/USD110=300000010=058
20260120-14:03:08.680760000 : 8=FIX.4.49=039735=X49=NTPRO_IDBA_UAT56=SIRIUS_500007460_MD34=54952=20260120-14:03:09.042262=MD_GBP/USD_140109778778268=5279=1269=0270=1.25459271=10000055=GBP/USD110=0279=1269=0270=1.25459271=50000055=GBP/USD110=100000279=1269=0270=1.25459271=100000055=GBP/USD110=500000279=1269=0270=1.25459271=300000055=GBP/USD110=1000000279=1269=0270=1.25459271=500000055=GBP/USD110=300000010=060
20260120-14:03:08.889515000 : 8=FIX.4.49=027935=X49=NTPRO_IDBA_UAT56=SIRIUS_500007460_MD34=55052=20260120-14:03:09.219262=MD_EUR/USD_140109278614268=3279=1269=0270=1.14801271=10000055=EUR/USD110=0279=1269=0270=1.14801271=50000055=EUR/USD110=100000279=1269=0270=1.14801271=100000055=EUR/USD110=50000010=192
20260120-14:03:08.926623000 : 8=FIX.4.49=027335=X49=NTPRO_IDBA_UAT56=SIRIUS_500007460_MD34=55152=20260120-14:03:09.297262=MD_EUR/USD_140109278614268=3279=1269=0270=1.148271=10000055=EUR/USD110=0279=1269=0270=1.148271=50000055=EUR/USD110=100000279=1269=0270=1.148271=100000055=EUR/USD110=50000010=158
20260120-14:03:08.976423000 : 8=FIX.4.49=068335=X49=NTPRO_IDBA_UAT56=SIRIUS_500007460_MD34=55252=20260120-14:03:09.347262=MD_GBP/USD_140109778778268=10279=1269=0270=1.25462271=10000055=GBP/USD110=0279=1269=0270=1.25462271=50000055=GBP/USD110=100000279=1269=0270=1.25462271=100000055=GBP/USD110=500000279=1269=0270=1.25462271=300000055=GBP/USD110=1000000279=1269=0270=1.25462271=500000055=GBP/USD110=3000000279=1269=1270=1.43494271=10000055=GBP/USD110=0279=1269=1270=1.43494271=50000055=GBP/USD110=100000279=1269=1270=1.43494271=100000055=GBP/USD110=500000279=1269=1270=1.43494271=300000055=GBP/USD110=1000000279=1269=1270=1.43494271=500000055=GBP/USD110=300000010=210
20260120-14:03:09.028612000 : 8=FIX.4.49=068335=X49=NTPRO_IDBA_UAT56=SIRIUS_500007460_MD34=55352=20260120-14:03:09.395262=MD_GBP/USD_140109778778268=10279=1269=0270=1.25464271=10000055=GBP/USD110=0279=1269=0270=1.25464271=50000055=GBP/USD110=100000279=1269=0270=1.25464271=100000055=GBP/USD110=500000279=1269=0270=1.25464271=300000055=GBP/USD110=1000000279=1269=0270=1.25464271=500000055=GBP/USD110=3000000279=1269=1270=1.43495271=10000055=GBP/USD110=0279=1269=1270=1.43495271=50000055=GBP/USD110=100000279=1269=1270=1.43495271=100000055=GBP/USD110=500000279=1269=1270=1.43495271=300000055=GBP/USD110=1000000279=1269=1270=1.43495271=500000055=GBP/USD110=300000010=229
20260120-14:03:09.066219000 : 8=FIX.4.49=039735=X49=NTPRO_IDBA_UAT56=SIRIUS_500007460_MD34=55452=20260120-14:03:09.427262=MD_GBP/USD_140109778778268=5279=1269=1270=1.43498271=10000055=GBP/USD110=0279=1269=1270=1.43498271=50000055=GBP/USD110=100000279=1269=1270=1.43498271=100000055=GBP/USD110=500000279=1269=1270=1.43498271=300000055=GBP/USD110=1000000279=1269=1270=1.43498271=500000055=GBP/USD110=300000010=083
20260120-14:03:09.066867000 : 8=FIX.4.49=044635=X49=NTPRO_IDBA_UAT56=SIRIUS_500007460_MD34=55552=20260120-14:03:09.439262=MD_EUR/USD_140109278614268=6279=1269=0270=1.14801271=10000055=EUR/USD110=0279=1269=0270=1.14801271=50000055=EUR/USD110=100000279=1269=0270=1.14801271=100000055=EUR/USD110=500000279=1269=1270=1.19826271=10000055=EUR/USD110=0279=1269=1270=1.19826271=50000055=EUR/USD110=100000279=1269=1270=1.19826271=100000055=EUR/USD110=50000010=253
20260120-14:03:09.162078000 : 8=FIX.4.49=027935=X49=NTPRO_IDBA_UAT56=SIRIUS_500007460_MD34=55652=20260120-14:03:09.516262=MD_EUR/USD_140109278614268=3279=1269=0270=1.14802271=10000055=EUR/USD110=0279=1269=0270=1.14802271=50000055=EUR/USD110=100000279=1269=0270=1.14802271=100000055=EUR/USD110=50000010=201
20260120-14:03:09.572541000 : 8=FIX.4.49=039735=X49=NTPRO_IDBA_UAT56=SIRIUS_500007460_MD34=55752=20260120-14:03:09.965262=MD_GBP/USD_140109778778268=5279=1269=0270=1.25465271=10000055=GBP/USD110=0279=1269=0270=1.25465271=50000055=GBP/USD110=100000279=1269=0270=1.25465271=100000055=GBP/USD110=500000279=1269=0270=1.25465271=300000055=GBP/USD110=1000000279=1269=0270=1.25465271=500000055=GBP/USD110=300000010=058
20260120-14:03:09.585760000 : 8=FIX.4.49=039735=X49=NTPRO_IDBA_UAT56=SIRIUS_500007460_MD34=55852=20260120-14:03:09.980262=MD_GBP/USD_140109778778268=5279=1269=0270=1.25464271=10000055=GBP/USD110=0279=1269=0270=1.25464271=50000055=GBP/USD110=100000279=1269=0270=1.25464271=100000055=GBP/USD110=500000279=1269=0270=1.25464271=300000055=GBP/USD110=1000000279=1269=0270=1.25464271=500000055=GBP/USD110=300000010=051
20260120-14:03:10.284047000 : 8=FIX.4.49=027935=X49=NTPRO_IDBA_UAT56=SIRIUS_500007460_MD34=55952=20260120-14:03:10.703262=MD_EUR/USD_140109278614268=3279=1269=0270=1.14801271=10000055=EUR/USD110=0279=1269=0270=1.14801271=50000055=EUR/USD110=100000279=1269=0270=1.14801271=100000055=EUR/USD110=50000010=191
20260120-14:03:10.751794000 : 8=FIX.4.49=044635=X49=NTPRO_IDBA_UAT56=SIRIUS_500007460_MD34=56052=20260120-14:03:11.187262=MD_EUR/USD_140109278614268=6279=1269=0270=1.14799271=10000055=EUR/USD110=0279=1269=0270=1.14799271=50000055=EUR/USD110=100000279=1269=0270=1.14799271=100000055=EUR/USD110=500000279=1269=1270=1.19825271=10000055=EUR/USD110=0279=1269=1270=1.19825271=50000055=EUR/USD110=100000279=1269=1270=1.19825271=100000055=EUR/USD110=50000010=031
20260120-14:03:10.770000000 : 8=FIX.4.49=068335=X49=NTPRO_IDBA_UAT56=SIRIUS_500007460_MD34=56152=20260120-14:03:11.205262=MD_GBP/USD_140109778778268=10279=1269=0270=1.25463271=10000055=GBP/USD110=0279=1269=0270=1.25463271=50000055=GBP/USD110=100000279=1269=0270=1.25463271=100000055=GBP/USD110=500000279=1269=0270=1.25463271=300000055=GBP/USD110=1000000279=1269=0270=1.25463271=500000055=GBP/USD110=3000000279=1269=1270=1.43495271=10000055=GBP/USD110=0279=1269=1270=1.43495271=50000055=GBP/USD110=100000279=1269=1270=1.43495271=100000055=GBP/USD110=500000279=1269=1270=1.43495271=300000055=GBP/USD110=1000000279=1269=1270=1.43495271=500000055=GBP/USD110=300000010=206
20260120-14:03:10.823212000 : 8=FIX.4.49=044635=X49=NTPRO_IDBA_UAT56=SIRIUS_500007460_MD34=56252=20260120-14:03:11.243262=MD_EUR/USD_140109278614268=6279=1269=0270=1.14796271=10000055=EUR/USD110=0279=1269=0270=1.14796271=50000055=EUR/USD110=100000279=1269=0270=1.14796271=100000055=EUR/USD110=500000279=1269=1270=1.19821271=10000055=EUR/USD110=0279=1269=1270=1.19821271=50000055=EUR/USD110=100000279=1269=1270=1.19821271=100000055=EUR/USD110=50000010=005
20260120-14:03:10.823809000 : 8=FIX.4.49=068335=X49=NTPRO_IDBA_UAT56=SIRIUS_500007460_MD34=56352=20260120-14:03:11.253262=MD_GBP/USD_140109778778268=10279=1269=0270=1.25462271=10000055=GBP/USD110=0279=1269=0270=1.25462271=50000055=GBP/USD110=100000279=1269=0270=1.25462271=100000055=GBP/USD110=500000279=1269=0270=1.25462271=300000055=GBP/USD110=1000000279=1269=0270=1.25462271=500000055=GBP/USD110=3000000279=1269=1270=1.43492271=10000055=GBP/USD110=0279=1269=1270=1.43492271=50000055=GBP/USD110=100000279=1269=1270=1.43492271=100000055=GBP/USD110=500000279=1269=1270=1.43492271=300000055=GBP/USD110=1000000279=1269=1270=1.43492271=500000055=GBP/USD110=300000010=191
20260120-14:03:10.853838000 : 8=FIX.4.49=039235=X49=NTPRO_IDBA_UAT56=SIRIUS_500007460_MD34=56452=20260120-14:03:11.293262=MD_GBP/USD_140109778778268=5279=1269=0270=1.2546271=10000055=GBP/USD110=0279=1269=0270=1.2546271=50000055=GBP/USD110=100000279=1269=0270=1.2546271=100000055=GBP/USD110=500000279=1269=0270=1.2546271=300000055=GBP/USD110=1000000279=1269=0270=1.2546271=500000055=GBP/USD110=300000010=029
20260120-14:03:10.900603000 : 8=FIX.4.49=068335=X49=NTPRO_IDBA_UAT56=SIRIUS_500007460_MD34=56552=20260120-14:03:11.341262=MD_GBP/USD_140109778778268=10279=1269=0270=1.25457271=10000055=GBP/USD110=0279=1269=0270=1.25457271=50000055=GBP/USD110=100000279=1269=0270=1.25457271=100000055=GBP/USD110=500000279=1269=0270=1.25457271=300000055=GBP/USD110=1000000279=1269=0270=1.25457271=500000055=GBP/USD110=3000000279=1269=1270=1.43491271=10000055=GBP/USD110=0279=1269=1270=1.43491271=50000055=GBP/USD110=100000279=1269=1270=1.43491271=100000055=GBP/USD110=500000279=1269=1270=1.43491271=300000055=GBP/USD110=1000000279=1269=1270=1.43491271=500000055=GBP/USD110=300000010=206
20260120-14:03:10.960722000 : 8=FIX.4.49=027935=X49=NTPRO_IDBA_UAT56=SIRIUS_500007460_MD34=56652=20260120-14:03:11.369262=MD_EUR/USD_140109278614268=3279=1269=0270=1.14797271=10000055=EUR/USD110=0279=1269=0270=1.14797271=50000055=EUR/USD110=100000279=1269=0270=1.14797271=100000055=EUR/USD110=50000010=240
20260120-14:03:10.961407000 : 8=FIX.4.49=068335=X49=NTPRO_IDBA_UAT56=SIRIUS_500007460_MD34=56752=20260120-14:03:11.389262=MD_GBP/USD_140109778778268=10279=1269=0270=1.25458271=10000055=GBP/USD110=0279=1269=0270=1.25458271=50000055=GBP/USD110=100000279=1269=0270=1.25458271=100000055=GBP/USD110=500000279=1269=0270=1.25458271=300000055=GBP/USD110=1000000279=1269=0270=1.25458271=500000055=GBP/USD110=3000000279=1269=1270=1.43492271=10000055=GBP/USD110=0279=1269=1270=1.43492271=50000055=GBP/USD110=100000279=1269=1270=1.43492271=100000055=GBP/USD110=500000279=1269=1270=1.43492271=300000055=GBP/USD110=1000000279=1269=1270=1.43492271=500000055=GBP/USD110=300000010=230
20260120-14:03:10.985592000 : 8=FIX.4.49=008735=149=NTPRO_IDBA_UAT56=SIRIUS_500007460_MD34=56852=20260120-14:03:11.429112=TR-A10=201
20260120-14:03:10.986583000 : 8=FIX.4.49=8635=034=1049=SIRIUS_500007460_MD52=20260120-14:03:10.98556=NTPRO_IDBA_UAT112=TR-A10=043
20260120-14:03:11.019378000 : 8=FIX.4.49=039735=X49=NTPRO_IDBA_UAT56=SIRIUS_500007460_MD34=56952=20260120-14:03:11.465262=MD_GBP/USD_140109778778268=5279=1269=0270=1.25457271=10000055=GBP/USD110=0279=1269=0270=1.25457271=50000055=GBP/USD110=100000279=1269=0270=1.25457271=100000055=GBP/USD110=500000279=1269=0270=1.25457271=300000055=GBP/USD110=1000000279=1269=0270=1.25457271=500000055=GBP/USD110=300000010=054
20260120-14:03:11.041106000 : 8=FIX.4.49=027935=X49=NTPRO_IDBA_UAT56=SIRIUS_500007460_MD34=57052=20260120-14:03:11.477262=MD_EUR/USD_140109278614268=3279=1269=0270=1.14796271=10000055=EUR/USD110=0279=1269=0270=1.14796271=50000055=EUR/USD110=100000279=1269=0270=1.14796271=100000055=EUR/USD110=50000010=232
20260120-14:03:11.079027000 : 8=FIX.4.49=044335=X49=NTPRO_IDBA_UAT56=SIRIUS_500007460_MD34=57152=20260120-14:03:11.526262=MD_EUR/USD_140109278614268=6279=1269=0270=1.14795271=10000055=EUR/USD110=0279=1269=0270=1.14795271=50000055=EUR/USD110=100000279=1269=0270=1.14795271=100000055=EUR/USD110=500000279=1269=1270=1.1982271=10000055=EUR/USD110=0279=1269=1270=1.1982271=50000055=EUR/USD110=100000279=1269=1270=1.1982271=100000055=EUR/USD110=50000010=112
20260120-14:03:11.143591000 : 8=FIX.4.49=027935=X49=NTPRO_IDBA_UAT56=SIRIUS_500007460_MD34=57252=20260120-14:03:11.584262=MD_EUR/USD_140109278614268=3279=1269=0270=1.14796271=10000055=EUR/USD110=0279=1269=0270=1.14796271=50000055=EUR/USD110=100000279=1269=0270=1.14796271=100000055=EUR/USD110=50000010=233
20260120-14:03:11.238278000 : 8=FIX.4.49=027935=X49=NTPRO_IDBA_UAT56=SIRIUS_500007460_MD34=57352=20260120-14:03:11.677262=MD_EUR/USD_140109278614268=3279=1269=1270=1.19821271=10000055=EUR/USD110=0279=1269=1270=1.19821271=50000055=EUR/USD110=100000279=1269=1270=1.19821271=100000055=EUR/USD110=50000010=222
20260120-14:03:11.374215000 : 8=FIX.4.49=044635=X49=NTPRO_IDBA_UAT56=SIRIUS_500007460_MD34=57452=20260120-14:03:11.832262=MD_EUR/USD_140109278614268=6279=1269=0270=1.14795271=10000055=EUR/USD110=0279=1269=0270=1.14795271=50000055=EUR/USD110=100000279=1269=0270=1.14795271=100000055=EUR/USD110=500000279=1269=1270=1.19819271=10000055=EUR/USD110=0279=1269=1270=1.19819271=50000055=EUR/USD110=100000279=1269=1270=1.19819271=100000055=EUR/USD110=50000010=030
20260120-14:03:11.403912000 : 8=FIX.4.49=044635=X49=NTPRO_IDBA_UAT56=SIRIUS_500007460_MD34=57552=20260120-14:03:11.857262=MD_EUR/USD_140109278614268=6279=1269=0270=1.14796271=10000055=EUR/USD110=0279=1269=0270=1.14796271=50000055=EUR/USD110=100000279=1269=0270=1.14796271=100000055=EUR/USD110=500000279=1269=1270=1.19821271=10000055=EUR/USD110=0279=1269=1270=1.19821271=50000055=EUR/USD110=100000279=1269=1270=1.19821271=100000055=EUR/USD110=50000010=020
20260120-14:03:12.185770000 : 8=FIX.4.49=044335=X49=NTPRO_IDBA_UAT56=SIRIUS_500007460_MD34=57652=20260120-14:03:12.673262=MD_EUR/USD_140109278614268=6279=1269=0270=1.14795271=10000055=EUR/USD110=0279=1269=0270=1.14795271=50000055=EUR/USD110=100000279=1269=0270=1.14795271=100000055=EUR/USD110=500000279=1269=1270=1.1982271=10000055=EUR/USD110=0279=1269=1270=1.1982271=50000055=EUR/USD110=100000279=1269=1270=1.1982271=100000055=EUR/USD110=50000010=121
20260120-14:03:12.228307000 : 8=FIX.4.49=027935=X49=NTPRO_IDBA_UAT56=SIRIUS_500007460_MD34=57752=20260120-14:03:12.698262=MD_EUR/USD_140109278614268=3279=1269=1270=1.19819271=10000055=EUR/USD110=0279=1269=1270=1.19819271=50000055=EUR/USD110=100000279=1269=1270=1.19819271=100000055=EUR/USD110=50000010=251
20260120-14:03:12.265327000 : 8=FIX.4.49=027635=X49=NTPRO_IDBA_UAT56=SIRIUS_500007460_MD34=57852=20260120-14:03:12.755262=MD_EUR/USD_140109278614268=3279=1269=1270=1.1982271=10000055=EUR/USD110=0279=1269=1270=1.1982271=50000055=EUR/USD110=100000279=1269=1270=1.1982271=100000055=EUR/USD110=50000010=075
20260120-14:03:12.325759000 : 8=FIX.4.49=027935=X49=NTPRO_IDBA_UAT56=SIRIUS_500007460_MD34=57952=20260120-14:03:12.813262=MD_EUR/USD_140109278614268=3279=1269=0270=1.14796271=10000055=EUR/USD110=0279=1269=0270=1.14796271=50000055=EUR/USD110=100000279=1269=0270=1.14796271=100000055=EUR/USD110=50000010=236
20260120-14:03:12.451618000 : 8=FIX.4.49=027935=X49=NTPRO_IDBA_UAT56=SIRIUS_500007460_MD34=58052=20260120-14:03:12.947262=MD_EUR/USD_140109278614268=3279=1269=0270=1.14795271=10000055=EUR/USD110=0279=1269=0270=1.14795271=50000055=EUR/USD110=100000279=1269=0270=1.14795271=100000055=EUR/USD110=50000010=233
20260120-14:03:12.679580000 : 8=FIX.4.49=027935=X49=NTPRO_IDBA_UAT56=SIRIUS_500007460_MD34=58152=20260120-14:03:13.183262=MD_EUR/USD_140109278614268=3279=1269=0270=1.14796271=10000055=EUR/USD110=0279=1269=0270=1.14796271=50000055=EUR/USD110=100000279=1269=0270=1.14796271=100000055=EUR/USD110=50000010=230
20260120-14:03:12.955191000 : 8=FIX.4.49=027935=X49=NTPRO_IDBA_UAT56=SIRIUS_500007460_MD34=58252=20260120-14:03:13.466262=MD_EUR/USD_140109278614268=3279=1269=1270=1.19821271=10000055=EUR/USD110=0279=1269=1270=1.19821271=50000055=EUR/USD110=100000279=1269=1270=1.19821271=100000055=EUR/USD110=50000010=220
20260120-14:03:13.257780000 : 8=FIX.4.49=027635=X49=NTPRO_IDBA_UAT56=SIRIUS_500007460_MD34=58352=20260120-14:03:13.783262=MD_EUR/USD_140109278614268=3279=1269=1270=1.1982271=10000055=EUR/USD110=0279=1269=1270=1.1982271=50000055=EUR/USD110=100000279=1269=1270=1.1982271=100000055=EUR/USD110=50000010=073
20260120-14:03:13.344118000 : 8=FIX.4.49=027935=X49=NTPRO_IDBA_UAT56=SIRIUS_500007460_MD34=58452=20260120-14:03:13.872262=MD_EUR/USD_140109278614268=3279=1269=1270=1.19821271=10000055=EUR/USD110=0279=1269=1270=1.19821271=50000055=EUR/USD110=100000279=1269=1270=1.19821271=100000055=EUR/USD110=50000010=223
20260120-14:03:13.392022000 : 8=FIX.4.49=044335=X49=NTPRO_IDBA_UAT56=SIRIUS_500007460_MD34=58552=20260120-14:03:13.922262=MD_EUR/USD_140109278614268=6279=1269=0270=1.14795271=10000055=EUR/USD110=0279=1269=0270=1.14795271=50000055=EUR/USD110=100000279=1269=0270=1.14795271=100000055=EUR/USD110=500000279=1269=1270=1.1982271=10000055=EUR/USD110=0279=1269=1270=1.1982271=50000055=EUR/USD110=100000279=1269=1270=1.1982271=100000055=EUR/USD110=50000010=119
20260120-14:03:13.430986000 : 8=FIX.4.49=044635=X49=NTPRO_IDBA_UAT56=SIRIUS_500007460_MD34=58652=20260120-14:03:13.962262=MD_EUR/USD_140109278614268=6279=1269=0270=1.14792271=10000055=EUR/USD110=0279=1269=0270=1.14792271=50000055=EUR/USD110=100000279=1269=0270=1.14792271=100000055=EUR/USD110=500000279=1269=1270=1.19816271=10000055=EUR/USD110=0279=1269=1270=1.19816271=50000055=EUR/USD110=100000279=1269=1270=1.19816271=100000055=EUR/USD110=50000010=021
20260120-14:03:13.482599000 : 8=FIX.4.49=068335=X49=NTPRO_IDBA_UAT56=SIRIUS_500007460_MD34=58752=20260120-14:03:14.015262=MD_GBP/USD_140109778778268=10279=1269=0270=1.25451271=10000055=GBP/USD110=0279=1269=0270=1.25451271=50000055=GBP/USD110=100000279=1269=0270=1.25451271=100000055=GBP/USD110=500000279=1269=0270=1.25451271=300000055=GBP/USD110=1000000279=1269=0270=1.25451271=500000055=GBP/USD110=3000000279=1269=1270=1.43483271=10000055=GBP/USD110=0279=1269=1270=1.43483271=50000055=GBP/USD110=100000279=1269=1270=1.43483271=100000055=GBP/USD110=500000279=1269=1270=1.43483271=300000055=GBP/USD110=1000000279=1269=1270=1.43483271=500000055=GBP/USD110=300000010=186
20260120-14:03:13.512022000 : 8=FIX.4.49=044335=X49=NTPRO_IDBA_UAT56=SIRIUS_500007460_MD34=58852=20260120-14:03:14.038262=MD_EUR/USD_140109278614268=6279=1269=0270=1.1479271=10000055=EUR/USD110=0279=1269=0270=1.1479271=50000055=EUR/USD110=100000279=1269=0270=1.1479271=100000055=EUR/USD110=500000279=1269=1270=1.19814271=10000055=EUR/USD110=0279=1269=1270=1.19814271=50000055=EUR/USD110=100000279=1269=1270=1.19814271=100000055=EUR/USD110=50000010=115
20260120-14:03:13.570190000 : 8=FIX.4.49=039735=X49=NTPRO_IDBA_UAT56=SIRIUS_500007460_MD34=58952=20260120-14:03:14.106262=MD_GBP/USD_140109778778268=5279=1269=0270=1.25452271=10000055=GBP/USD110=0279=1269=0270=1.25452271=50000055=GBP/USD110=100000279=1269=0270=1.25452271=100000055=GBP/USD110=500000279=1269=0270=1.25452271=300000055=GBP/USD110=1000000279=1269=0270=1.25452271=500000055=GBP/USD110=300000010=026
20260120-14:03:13.626370000 : 8=FIX.4.49=039735=X49=NTPRO_IDBA_UAT56=SIRIUS_500007460_MD34=59052=20260120-14:03:14.164262=MD_GBP/USD_140109778778268=5279=1269=1270=1.43486271=10000055=GBP/USD110=0279=1269=1270=1.43486271=50000055=GBP/USD110=100000279=1269=1270=1.43486271=100000055=GBP/USD110=500000279=1269=1270=1.43486271=300000055=GBP/USD110=1000000279=1269=1270=1.43486271=500000055=GBP/USD110=300000010=062
20260120-14:03:13.651343000 : 8=FIX.4.49=044635=X49=NTPRO_IDBA_UAT56=SIRIUS_500007460_MD34=59152=20260120-14:03:14.190262=MD_EUR/USD_140109278614268=6279=1269=0270=1.14791271=10000055=EUR/USD110=0279=1269=0270=1.14791271=50000055=EUR/USD110=100000279=1269=0270=1.14791271=100000055=EUR/USD110=500000279=1269=1270=1.19815271=10000055=EUR/USD110=0279=1269=1270=1.19815271=50000055=EUR/USD110=100000279=1269=1270=1.19815271=100000055=EUR/USD110=50000010=005
20260120-14:03:13.713078000 : 8=FIX.4.49=039735=X49=NTPRO_IDBA_UAT56=SIRIUS_500007460_MD34=59252=20260120-14:03:14.235262=MD_GBP/USD_140109778778268=5279=1269=1270=1.43487271=10000055=GBP/USD110=0279=1269=1270=1.43487271=50000055=GBP/USD110=100000279=1269=1270=1.43487271=100000055=GBP/USD110=500000279=1269=1270=1.43487271=300000055=GBP/USD110=1000000279=1269=1270=1.43487271=500000055=GBP/USD110=300000010=068
20260120-14:03:13.909362000 : 8=FIX.4.49=027635=X49=NTPRO_IDBA_UAT56=SIRIUS_500007460_MD34=59352=20260120-14:03:14.445262=MD_EUR/USD_140109278614268=3279=1269=0270=1.1479271=10000055=EUR/USD110=0279=1269=0270=1.1479271=50000055=EUR/USD110=100000279=1269=0270=1.1479271=100000055=EUR/USD110=50000010=070
20260120-14:03:14.049545000 : 8=FIX.4.49=027935=X49=NTPRO_IDBA_UAT56=SIRIUS_500007460_MD34=59452=20260120-14:03:14.602262=MD_EUR/USD_140109278614268=3279=1269=1270=1.19814271=10000055=EUR/USD110=0279=1269=1270=1.19814271=50000055=EUR/USD110=100000279=1269=1270=1.19814271=100000055=EUR/USD110=50000010=222
20260120-14:03:14.060940000 : 8=FIX.4.49=039735=X49=NTPRO_IDBA_UAT56=SIRIUS_500007460_MD34=59552=20260120-14:03:14.615262=MD_GBP/USD_140109778778268=5279=1269=1270=1.43485271=10000055=GBP/USD110=0279=1269=1270=1.43485271=50000055=GBP/USD110=100000279=1269=1270=1.43485271=100000055=GBP/USD110=500000279=1269=1270=1.43485271=300000055=GBP/USD110=1000000279=1269=1270=1.43485271=500000055=GBP/USD110=300000010=063
20260120-14:03:14.106903000 : 8=FIX.4.49=039735=X49=NTPRO_IDBA_UAT56=SIRIUS_500007460_MD34=59652=20260120-14:03:14.660262=MD_GBP/USD_140109778778268=5279=1269=0270=1.25451271=10000055=GBP/USD110=0279=1269=0270=1.25451271=50000055=GBP/USD110=100000279=1269=0270=1.25451271=100000055=GBP/USD110=500000279=1269=0270=1.25451271=300000055=GBP/USD110=1000000279=1269=0270=1.25451271=500000055=GBP/USD110=300000010=024
20260120-14:03:14.166596000 : 8=FIX.4.49=027935=X49=NTPRO_IDBA_UAT56=SIRIUS_500007460_MD34=59752=20260120-14:03:14.724262=MD_EUR/USD_140109278614268=3279=1269=1270=1.19815271=10000055=EUR/USD110=0279=1269=1270=1.19815271=50000055=EUR/USD110=100000279=1269=1270=1.19815271=100000055=EUR/USD110=50000010=233
20260120-14:03:14.402513000 : 8=FIX.4.49=039735=X49=NTPRO_IDBA_UAT56=SIRIUS_500007460_MD34=59852=20260120-14:03:14.968262=MD_GBP/USD_140109778778268=5279=1269=0270=1.25452271=10000055=GBP/USD110=0279=1269=0270=1.25452271=50000055=GBP/USD110=100000279=1269=0270=1.25452271=100000055=GBP/USD110=500000279=1269=0270=1.25452271=300000055=GBP/USD110=1000000279=1269=0270=1.25452271=500000055=GBP/USD110=300000010=042
20260120-14:03:14.526730000 : 8=FIX.4.49=027935=X49=NTPRO_IDBA_UAT56=SIRIUS_500007460_MD34=59952=20260120-14:03:15.097262=MD_EUR/USD_140109278614268=3279=1269=1270=1.19814271=10000055=EUR/USD110=0279=1269=1270=1.19814271=50000055=EUR/USD110=100000279=1269=1270=1.19814271=100000055=EUR/USD110=50000010=236
20260120-14:03:14.603868000 : 8=FIX.4.49=027935=X49=NTPRO_IDBA_UAT56=SIRIUS_500007460_MD34=60052=20260120-14:03:15.177262=MD_EUR/USD_140109278614268=3279=1269=1270=1.19815271=10000055=EUR/USD110=0279=1269=1270=1.19815271=50000055=EUR/USD110=100000279=1269=1270=1.19815271=100000055=EUR/USD110=50000010=221
20260120-14:03:14.624809000 : 8=FIX.4.49=039735=X49=NTPRO_IDBA_UAT56=SIRIUS_500007460_MD34=60152=20260120-14:03:15.198262=MD_GBP/USD_140109778778268=5279=1269=1270=1.43486271=10000055=GBP/USD110=0279=1269=1270=1.43486271=50000055=GBP/USD110=100000279=1269=1270=1.43486271=100000055=GBP/USD110=500000279=1269=1270=1.43486271=300000055=GBP/USD110=1000000279=1269=1270=1.43486271=500000055=GBP/USD110=300000010=063
20260120-14:03:14.660564000 : 8=FIX.4.49=068335=X49=NTPRO_IDBA_UAT56=SIRIUS_500007460_MD34=60252=20260120-14:03:15.235262=MD_GBP/USD_140109778778268=10279=1269=0270=1.25453271=10000055=GBP/USD110=0279=1269=0270=1.25453271=50000055=GBP/USD110=100000279=1269=0270=1.25453271=100000055=GBP/USD110=500000279=1269=0270=1.25453271=300000055=GBP/USD110=1000000279=1269=0270=1.25453271=500000055=GBP/USD110=3000000279=1269=1270=1.43487271=10000055=GBP/USD110=0279=1269=1270=1.43487271=50000055=GBP/USD110=100000279=1269=1270=1.43487271=100000055=GBP/USD110=500000279=1269=1270=1.43487271=300000055=GBP/USD110=1000000279=1269=1270=1.43487271=500000055=GBP/USD110=300000010=209
20260120-14:03:14.995312000 : 8=FIX.4.49=039735=X49=NTPRO_IDBA_UAT56=SIRIUS_500007460_MD34=60352=20260120-14:03:15.575262=MD_GBP/USD_140109778778268=5279=1269=1270=1.43488271=10000055=GBP/USD110=0279=1269=1270=1.43488271=50000055=GBP/USD110=100000279=1269=1270=1.43488271=100000055=GBP/USD110=500000279=1269=1270=1.43488271=300000055=GBP/USD110=1000000279=1269=1270=1.43488271=500000055=GBP/USD110=300000010=074
20260120-14:03:15.047216000 : 8=FIX.4.49=027935=X49=NTPRO_IDBA_UAT56=SIRIUS_500007460_MD34=60452=20260120-14:03:15.636262=MD_EUR/USD_140109278614268=3279=1269=0270=1.14791271=10000055=EUR/USD110=0279=1269=0270=1.14791271=50000055=EUR/USD110=100000279=1269=0270=1.14791271=100000055=EUR/USD110=50000010=216
20260120-14:03:15.116958000 : 8=FIX.4.49=027635=X49=NTPRO_IDBA_UAT56=SIRIUS_500007460_MD34=60552=20260120-14:03:15.708262=MD_EUR/USD_140109278614268=3279=1269=0270=1.1479271=10000055=EUR/USD110=0279=1269=0270=1.1479271=50000055=EUR/USD110=100000279=1269=0270=1.1479271=100000055=EUR/USD110=50000010=067
20260120-14:03:15.591675000 : 8=FIX.4.49=027935=X49=NTPRO_IDBA_UAT56=SIRIUS_500007460_MD34=60652=20260120-14:03:16.190262=MD_EUR/USD_140109278614268=3279=1269=0270=1.14791271=10000055=EUR/USD110=0279=1269=0270=1.14791271=50000055=EUR/USD110=100000279=1269=0270=1.14791271=100000055=EUR/USD110=50000010=214
20260120-14:03:15.612246000 : 8=FIX.4.49=027635=X49=NTPRO_IDBA_UAT56=SIRIUS_500007460_MD34=60752=20260120-14:03:16.220262=MD_EUR/USD_140109278614268=3279=1269=0270=1.1479271=10000055=EUR/USD110=0279=1269=0270=1.1479271=50000055=EUR/USD110=100000279=1269=0270=1.1479271=100000055=EUR/USD110=50000010=059
20260120-14:03:15.683109000 : 8=FIX.4.49=12535=x34=1149=SIRIUS_500007460_MD52=20260120-14:03:15.68256=NTPRO_IDBA_UAT320=SL_1768917795682322=SL_1768917795682559=410=232
20260120-14:03:15.718112000 : 8=FIX.4.49=039735=X49=NTPRO_IDBA_UAT56=SIRIUS_500007460_MD34=60852=20260120-14:03:16.331262=MD_GBP/USD_140109778778268=5279=1269=1270=1.43487271=10000055=GBP/USD110=0279=1269=1270=1.43487271=50000055=GBP/USD110=100000279=1269=1270=1.43487271=100000055=GBP/USD110=500000279=1269=1270=1.43487271=300000055=GBP/USD110=1000000279=1269=1270=1.43487271=500000055=GBP/USD110=300000010=065
20260120-14:03:15.748681000 : 8=FIX.4.49=039735=X49=NTPRO_IDBA_UAT56=SIRIUS_500007460_MD34=60952=20260120-14:03:16.362262=MD_GBP/USD_140109778778268=5279=1269=0270=1.25452271=10000055=GBP/USD110=0279=1269=0270=1.25452271=50000055=GBP/USD110=100000279=1269=0270=1.25452271=100000055=GBP/USD110=500000279=1269=0270=1.25452271=300000055=GBP/USD110=1000000279=1269=0270=1.25452271=500000055=GBP/USD110=300000010=025
20260120-14:03:15.788006000 : 8=FIX.4.49=013935=349=NTPRO_IDBA_UAT56=SIRIUS_500007460_MD34=61052=20260120-14:03:16.40345=11371=559372=x373=558=Invalid SecurityListRequestType10=204
20260120-14:03:15.813098000 : 8=FIX.4.49=027935=X49=NTPRO_IDBA_UAT56=SIRIUS_500007460_MD34=61152=20260120-14:03:16.429262=MD_EUR/USD_140109278614268=3279=1269=0270=1.14791271=10000055=EUR/USD110=0279=1269=0270=1.14791271=50000055=EUR/USD110=100000279=1269=0270=1.14791271=100000055=EUR/USD110=50000010=215
20260120-14:03:16.183005000 : 8=FIX.4.49=068335=X49=NTPRO_IDBA_UAT56=SIRIUS_500007460_MD34=61252=20260120-14:03:16.800262=MD_GBP/USD_140109778778268=10279=1269=0270=1.25453271=10000055=GBP/USD110=0279=1269=0270=1.25453271=50000055=GBP/USD110=100000279=1269=0270=1.25453271=100000055=GBP/USD110=500000279=1269=0270=1.25453271=300000055=GBP/USD110=1000000279=1269=0270=1.25453271=500000055=GBP/USD110=3000000279=1269=1270=1.43488271=10000055=GBP/USD110=0279=1269=1270=1.43488271=50000055=GBP/USD110=100000279=1269=1270=1.43488271=100000055=GBP/USD110=500000279=1269=1270=1.43488271=300000055=GBP/USD110=1000000279=1269=1270=1.43488271=500000055=GBP/USD110=300000010=214
20260120-14:03:16.200402000 : 8=FIX.4.49=027635=X49=NTPRO_IDBA_UAT56=SIRIUS_500007460_MD34=61352=20260120-14:03:16.830262=MD_EUR/USD_140109278614268=3279=1269=0270=1.1479271=10000055=EUR/USD110=0279=1269=0270=1.1479271=50000055=EUR/USD110=100000279=1269=0270=1.1479271=100000055=EUR/USD110=50000010=063
20260120-14:03:16.310110000 : 8=FIX.4.49=027935=X49=NTPRO_IDBA_UAT56=SIRIUS_500007460_MD34=61452=20260120-14:03:16.943262=MD_EUR/USD_140109278614268=3279=1269=0270=1.14791271=10000055=EUR/USD110=0279=1269=0270=1.14791271=50000055=EUR/USD110=100000279=1269=0270=1.14791271=100000055=EUR/USD110=50000010=219
20260120-14:03:16.417188000 : 8=FIX.4.49=044335=X49=NTPRO_IDBA_UAT56=SIRIUS_500007460_MD34=61552=20260120-14:03:17.055262=MD_EUR/USD_140109278614268=6279=1269=0270=1.1479271=10000055=EUR/USD110=0279=1269=0270=1.1479271=50000055=EUR/USD110=100000279=1269=0270=1.1479271=100000055=EUR/USD110=500000279=1269=1270=1.19814271=10000055=EUR/USD110=0279=1269=1270=1.19814271=50000055=EUR/USD110=100000279=1269=1270=1.19814271=100000055=EUR/USD110=50000010=108
20260120-14:03:16.476991000 : 8=FIX.4.49=039735=X49=NTPRO_IDBA_UAT56=SIRIUS_500007460_MD34=61652=20260120-14:03:17.108262=MD_GBP/USD_140109778778268=5279=1269=0270=1.25454271=10000055=GBP/USD110=0279=1269=0270=1.25454271=50000055=GBP/USD110=100000279=1269=0270=1.25454271=100000055=GBP/USD110=500000279=1269=0270=1.25454271=300000055=GBP/USD110=1000000279=1269=0270=1.25454271=500000055=GBP/USD110=300000010=032
20260120-14:03:16.478238000 : 8=FIX.4.49=044635=X49=NTPRO_IDBA_UAT56=SIRIUS_500007460_MD34=61752=20260120-14:03:17.118262=MD_EUR/USD_140109278614268=6279=1269=0270=1.14791271=10000055=EUR/USD110=0279=1269=0270=1.14791271=50000055=EUR/USD110=100000279=1269=0270=1.14791271=100000055=EUR/USD110=500000279=1269=1270=1.19815271=10000055=EUR/USD110=0279=1269=1270=1.19815271=50000055=EUR/USD110=100000279=1269=1270=1.19815271=100000055=EUR/USD110=50000010=007
20260120-14:03:16.512874000 : 8=FIX.4.49=067835=X49=NTPRO_IDBA_UAT56=SIRIUS_500007460_MD34=61852=20260120-14:03:17.153262=MD_GBP/USD_140109778778268=10279=1269=0270=1.25455271=10000055=GBP/USD110=0279=1269=0270=1.25455271=50000055=GBP/USD110=100000279=1269=0270=1.25455271=100000055=GBP/USD110=500000279=1269=0270=1.25455271=300000055=GBP/USD110=1000000279=1269=0270=1.25455271=500000055=GBP/USD110=3000000279=1269=1270=1.4349271=10000055=GBP/USD110=0279=1269=1270=1.4349271=50000055=GBP/USD110=100000279=1269=1270=1.4349271=100000055=GBP/USD110=500000279=1269=1270=1.4349271=300000055=GBP/USD110=1000000279=1269=1270=1.4349271=500000055=GBP/USD110=300000010=217
20260120-14:03:16.634186000 : 8=FIX.4.49=044635=X49=NTPRO_IDBA_UAT56=SIRIUS_500007460_MD34=61952=20260120-14:03:17.278262=MD_EUR/USD_140109278614268=6279=1269=0270=1.14789271=10000055=EUR/USD110=0279=1269=0270=1.14789271=50000055=EUR/USD110=100000279=1269=0270=1.14789271=100000055=EUR/USD110=500000279=1269=1270=1.19814271=10000055=EUR/USD110=0279=1269=1270=1.19814271=50000055=EUR/USD110=100000279=1269=1270=1.19814271=100000055=EUR/USD110=50000010=034
20260120-14:03:16.677717000 : 8=FIX.4.49=044635=X49=NTPRO_IDBA_UAT56=SIRIUS_500007460_MD34=62052=20260120-14:03:17.323262=MD_EUR/USD_140109278614268=6279=1269=0270=1.14791271=10000055=EUR/USD110=0279=1269=0270=1.14791271=50000055=EUR/USD110=100000279=1269=0270=1.14791271=100000055=EUR/USD110=500000279=1269=1270=1.19815271=10000055=EUR/USD110=0279=1269=1270=1.19815271=50000055=EUR/USD110=100000279=1269=1270=1.19815271=100000055=EUR/USD110=50000010=255
20260120-14:03:16.701468000 : 8=FIX.4.49=027635=X49=NTPRO_IDBA_UAT56=SIRIUS_500007460_MD34=62152=20260120-14:03:17.349262=MD_EUR/USD_140109278614268=3279=1269=0270=1.1479271=10000055=EUR/USD110=0279=1269=0270=1.1479271=50000055=EUR/USD110=100000279=1269=0270=1.1479271=100000055=EUR/USD110=50000010=068
20260120-14:03:17.096576000 : 8=FIX.4.49=027935=X49=NTPRO_IDBA_UAT56=SIRIUS_500007460_MD34=62252=20260120-14:03:17.758262=MD_EUR/USD_140109278614268=3279=1269=0270=1.14791271=10000055=EUR/USD110=0279=1269=0270=1.14791271=50000055=EUR/USD110=100000279=1269=0270=1.14791271=100000055=EUR/USD110=50000010=223
20260120-14:03:17.113146000 : 8=FIX.4.49=039735=X49=NTPRO_IDBA_UAT56=SIRIUS_500007460_MD34=62352=20260120-14:03:17.774262=MD_GBP/USD_140109778778268=5279=1269=1270=1.43491271=10000055=GBP/USD110=0279=1269=1270=1.43491271=50000055=GBP/USD110=100000279=1269=1270=1.43491271=100000055=GBP/USD110=500000279=1269=1270=1.43491271=300000055=GBP/USD110=1000000279=1269=1270=1.43491271=500000055=GBP/USD110=300000010=049
20260120-14:03:17.179010000 : 8=FIX.4.49=027935=X49=NTPRO_IDBA_UAT56=SIRIUS_500007460_MD34=62452=20260120-14:03:17.844262=MD_EUR/USD_140109278614268=3279=1269=1270=1.19816271=10000055=EUR/USD110=0279=1269=1270=1.19816271=50000055=EUR/USD110=100000279=1269=1270=1.19816271=100000055=EUR/USD110=50000010=233
20260120-14:03:17.227367000 : 8=FIX.4.49=044335=X49=NTPRO_IDBA_UAT56=SIRIUS_500007460_MD34=62552=20260120-14:03:17.894262=MD_EUR/USD_140109278614268=6279=1269=0270=1.1479271=10000055=EUR/USD110=0279=1269=0270=1.1479271=50000055=EUR/USD110=100000279=1269=0270=1.1479271=100000055=EUR/USD110=500000279=1269=1270=1.19815271=10000055=EUR/USD110=0279=1269=1270=1.19815271=50000055=EUR/USD110=100000279=1269=1270=1.19815271=100000055=EUR/USD110=50000010=123
20260120-14:03:17.272100000 : 8=FIX.4.49=044635=X49=NTPRO_IDBA_UAT56=SIRIUS_500007460_MD34=62652=20260120-14:03:17.927262=MD_EUR/USD_140109278614268=6279=1269=0270=1.14791271=10000055=EUR/USD110=0279=1269=0270=1.14791271=50000055=EUR/USD110=100000279=1269=0270=1.14791271=100000055=EUR/USD110=500000279=1269=1270=1.19816271=10000055=EUR/USD110=0279=1269=1270=1.19816271=50000055=EUR/USD110=100000279=1269=1270=1.19816271=100000055=EUR/USD110=50000010=018
20260120-14:03:17.303752000 : 8=FIX.4.49=044335=X49=NTPRO_IDBA_UAT56=SIRIUS_500007460_MD34=62752=20260120-14:03:17.966262=MD_EUR/USD_140109278614268=6279=1269=0270=1.1479271=10000055=EUR/USD110=0279=1269=0270=1.1479271=50000055=EUR/USD110=100000279=1269=0270=1.1479271=100000055=EUR/USD110=500000279=1269=1270=1.19815271=10000055=EUR/USD110=0279=1269=1270=1.19815271=50000055=EUR/USD110=100000279=1269=1270=1.19815271=100000055=EUR/USD110=50000010=125
20260120-14:03:17.365992000 : 8=FIX.4.49=039735=X49=NTPRO_IDBA_UAT56=SIRIUS_500007460_MD34=62852=20260120-14:03:18.014262=MD_GBP/USD_140109778778268=5279=1269=0270=1.25457271=10000055=GBP/USD110=0279=1269=0270=1.25457271=50000055=GBP/USD110=100000279=1269=0270=1.25457271=100000055=GBP/USD110=500000279=1269=0270=1.25457271=300000055=GBP/USD110=1000000279=1269=0270=1.25457271=500000055=GBP/USD110=300000010=047
20260120-14:03:17.366676000 : 8=FIX.4.49=044635=X49=NTPRO_IDBA_UAT56=SIRIUS_500007460_MD34=62952=20260120-14:03:18.035262=MD_EUR/USD_140109278614268=6279=1269=0270=1.14792271=10000055=EUR/USD110=0279=1269=0270=1.14792271=50000055=EUR/USD110=100000279=1269=0270=1.14792271=100000055=EUR/USD110=500000279=1269=1270=1.19816271=10000055=EUR/USD110=0279=1269=1270=1.19816271=50000055=EUR/USD110=100000279=1269=1270=1.19816271=100000055=EUR/USD110=50000010=015
20260120-14:03:17.431111000 : 8=FIX.4.49=068335=X49=NTPRO_IDBA_UAT56=SIRIUS_500007460_MD34=63052=20260120-14:03:18.105262=MD_GBP/USD_140109778778268=10279=1269=0270=1.25459271=10000055=GBP/USD110=0279=1269=0270=1.25459271=50000055=GBP/USD110=100000279=1269=0270=1.25459271=100000055=GBP/USD110=500000279=1269=0270=1.25459271=300000055=GBP/USD110=1000000279=1269=0270=1.25459271=500000055=GBP/USD110=3000000279=1269=1270=1.43492271=10000055=GBP/USD110=0279=1269=1270=1.43492271=50000055=GBP/USD110=100000279=1269=1270=1.43492271=100000055=GBP/USD110=500000279=1269=1270=1.43492271=300000055=GBP/USD110=1000000279=1269=1270=1.43492271=500000055=GBP/USD110=300000010=219
20260120-14:03:17.447323000 : 8=FIX.4.49=044335=X49=NTPRO_IDBA_UAT56=SIRIUS_500007460_MD34=63152=20260120-14:03:18.118262=MD_EUR/USD_140109278614268=6279=1269=0270=1.14795271=10000055=EUR/USD110=0279=1269=0270=1.14795271=50000055=EUR/USD110=100000279=1269=0270=1.14795271=100000055=EUR/USD110=500000279=1269=1270=1.1982271=10000055=EUR/USD110=0279=1269=1270=1.1982271=50000055=EUR/USD110=100000279=1269=1270=1.1982271=100000055=EUR/USD110=50000010=113
20260120-14:03:17.472190000 : 8=FIX.4.49=068335=X49=NTPRO_IDBA_UAT56=SIRIUS_500007460_MD34=63252=20260120-14:03:18.147262=MD_GBP/USD_140109778778268=10279=2269=0270=1.25459271=10000055=GBP/USD110=0279=2269=0270=1.25459271=50000055=GBP/USD110=100000279=2269=0270=1.25459271=100000055=GBP/USD110=500000279=2269=0270=1.25459271=300000055=GBP/USD110=1000000279=2269=0270=1.25459271=500000055=GBP/USD110=3000000279=2269=1270=1.43492271=10000055=GBP/USD110=0279=2269=1270=1.43492271=50000055=GBP/USD110=100000279=2269=1270=1.43492271=100000055=GBP/USD110=500000279=2269=1270=1.43492271=300000055=GBP/USD110=1000000279=2269=1270=1.43492271=500000055=GBP/USD110=300000010=237
20260120-14:03:17.610045000 : 8=FIX.4.49=068335=X49=NTPRO_IDBA_UAT56=SIRIUS_500007460_MD34=63352=20260120-14:03:18.290262=MD_GBP/USD_140109778778268=10279=0269=0270=1.25462271=10000055=GBP/USD110=0279=0269=0270=1.25462271=50000055=GBP/USD110=100000279=0269=0270=1.25462271=100000055=GBP/USD110=500000279=0269=0270=1.25462271=300000055=GBP/USD110=1000000279=0269=0270=1.25462271=500000055=GBP/USD110=3000000279=0269=1270=1.43497271=10000055=GBP/USD110=0279=0269=1270=1.43497271=50000055=GBP/USD110=100000279=0269=1270=1.43497271=100000055=GBP/USD110=500000279=0269=1270=1.43497271=300000055=GBP/USD110=1000000279=0269=1270=1.43497271=500000055=GBP/USD110=300000010=212
20260120-14:03:17.645375000 : 8=FIX.4.49=039735=X49=NTPRO_IDBA_UAT56=SIRIUS_500007460_MD34=63452=20260120-14:03:18.326262=MD_GBP/USD_140109778778268=5279=1269=0270=1.25463271=10000055=GBP/USD110=0279=1269=0270=1.25463271=50000055=GBP/USD110=100000279=1269=0270=1.25463271=100000055=GBP/USD110=500000279=1269=0270=1.25463271=300000055=GBP/USD110=1000000279=1269=0270=1.25463271=500000055=GBP/USD110=300000010=035
20260120-14:03:17.664455000 : 8=FIX.4.49=044635=X49=NTPRO_IDBA_UAT56=SIRIUS_500007460_MD34=63552=20260120-14:03:18.330262=MD_EUR/USD_140109278614268=6279=1269=0270=1.14796271=10000055=EUR/USD110=0279=1269=0270=1.14796271=50000055=EUR/USD110=100000279=1269=0270=1.14796271=100000055=EUR/USD110=500000279=1269=1270=1.19821271=10000055=EUR/USD110=0279=1269=1270=1.19821271=50000055=EUR/USD110=100000279=1269=1270=1.19821271=100000055=EUR/USD110=50000010=010
20260120-14:03:17.680564000 : 8=FIX.4.49=039735=X49=NTPRO_IDBA_UAT56=SIRIUS_500007460_MD34=63652=20260120-14:03:18.363262=MD_GBP/USD_140109778778268=5279=1269=0270=1.25464271=10000055=GBP/USD110=0279=1269=0270=1.25464271=50000055=GBP/USD110=100000279=1269=0270=1.25464271=100000055=GBP/USD110=500000279=1269=0270=1.25464271=300000055=GBP/USD110=1000000279=1269=0270=1.25464271=500000055=GBP/USD110=300000010=043
20260120-14:03:17.689122000 : 8=FIX.4.49=027635=X49=NTPRO_IDBA_UAT56=SIRIUS_500007460_MD34=63752=20260120-14:03:18.370262=MD_EUR/USD_140109278614268=3279=1269=1270=1.1982271=10000055=EUR/USD110=0279=1269=1270=1.1982271=50000055=EUR/USD110=100000279=1269=1270=1.1982271=100000055=EUR/USD110=50000010=070
20260120-14:03:17.713892000 : 8=FIX.4.49=027935=X49=NTPRO_IDBA_UAT56=SIRIUS_500007460_MD34=63852=20260120-14:03:18.398262=MD_EUR/USD_140109278614268=3279=1269=1270=1.19821271=10000055=EUR/USD110=0279=1269=1270=1.19821271=50000055=EUR/USD110=100000279=1269=1270=1.19821271=100000055=EUR/USD110=50000010=231
20260120-14:03:17.833670000 : 8=FIX.4.49=027635=X49=NTPRO_IDBA_UAT56=SIRIUS_500007460_MD34=63952=20260120-14:03:18.521262=MD_EUR/USD_140109278614268=3279=1269=1270=1.1982271=10000055=EUR/USD110=0279=1269=1270=1.1982271=50000055=EUR/USD110=100000279=1269=1270=1.1982271=100000055=EUR/USD110=50000010=070
20260120-14:03:17.873623000 : 8=FIX.4.49=027935=X49=NTPRO_IDBA_UAT56=SIRIUS_500007460_MD34=64052=20260120-14:03:18.563262=MD_EUR/USD_140109278614268=3279=1269=0270=1.14795271=10000055=EUR/USD110=0279=1269=0270=1.14795271=50000055=EUR/USD110=100000279=1269=0270=1.14795271=100000055=EUR/USD110=50000010=230
20260120-14:03:17.890184000 : 8=FIX.4.49=039735=X49=NTPRO_IDBA_UAT56=SIRIUS_500007460_MD34=64152=20260120-14:03:18.579262=MD_GBP/USD_140109778778268=5279=1269=0270=1.25462271=10000055=GBP/USD110=0279=1269=0270=1.25462271=50000055=GBP/USD110=100000279=1269=0270=1.25462271=100000055=GBP/USD110=500000279=1269=0270=1.25462271=300000055=GBP/USD110=1000000279=1269=0270=1.25462271=500000055=GBP/USD110=300000010=038
20260120-14:03:17.998342000 : 8=FIX.4.49=039735=X49=NTPRO_IDBA_UAT56=SIRIUS_500007460_MD34=64252=20260120-14:03:18.692262=MD_GBP/USD_140109778778268=5279=1269=0270=1.25463271=10000055=GBP/USD110=0279=1269=0270=1.25463271=50000055=GBP/USD110=100000279=1269=0270=1.25463271=100000055=GBP/USD110=500000279=1269=0270=1.25463271=300000055=GBP/USD110=1000000279=1269=0270=1.25463271=500000055=GBP/USD110=300000010=040
20260120-14:03:18.183468000 : 8=FIX.4.49=027935=X49=NTPRO_IDBA_UAT56=SIRIUS_500007460_MD34=64352=20260120-14:03:18.881262=MD_EUR/USD_140109278614268=3279=1269=0270=1.14796271=10000055=EUR/USD110=0279=1269=0270=1.14796271=50000055=EUR/USD110=100000279=1269=0270=1.14796271=100000055=EUR/USD110=50000010=239
20260120-14:03:18.455665000 : 8=FIX.4.49=068335=X49=NTPRO_IDBA_UAT56=SIRIUS_500007460_MD34=64452=20260120-14:03:19.163262=MD_GBP/USD_140109778778268=10279=1269=0270=1.25464271=10000055=GBP/USD110=0279=1269=0270=1.25464271=50000055=GBP/USD110=100000279=1269=0270=1.25464271=100000055=GBP/USD110=500000279=1269=0270=1.25464271=300000055=GBP/USD110=1000000279=1269=0270=1.25464271=500000055=GBP/USD110=3000000279=1269=1270=1.43496271=10000055=GBP/USD110=0279=1269=1270=1.43496271=50000055=GBP/USD110=100000279=1269=1270=1.43496271=100000055=GBP/USD110=500000279=1269=1270=1.43496271=300000055=GBP/USD110=1000000279=1269=1270=1.43496271=500000055=GBP/USD110=300000010=229
20260120-14:03:18.483579000 : 8=FIX.4.49=039735=X49=NTPRO_IDBA_UAT56=SIRIUS_500007460_MD34=64552=20260120-14:03:19.191262=MD_GBP/USD_140109778778268=5279=1269=0270=1.25463271=10000055=GBP/USD110=0279=1269=0270=1.25463271=50000055=GBP/USD110=100000279=1269=0270=1.25463271=100000055=GBP/USD110=500000279=1269=0270=1.25463271=300000055=GBP/USD110=1000000279=1269=0270=1.25463271=500000055=GBP/USD110=300000010=038
20260120-14:03:18.516197000 : 8=FIX.4.49=044635=X49=NTPRO_IDBA_UAT56=SIRIUS_500007460_MD34=64652=20260120-14:03:19.228262=MD_EUR/USD_140109278614268=6279=1269=0270=1.14795271=10000055=EUR/USD110=0279=1269=0270=1.14795271=50000055=EUR/USD110=100000279=1269=0270=1.14795271=100000055=EUR/USD110=500000279=1269=1270=1.19819271=10000055=EUR/USD110=0279=1269=1270=1.19819271=50000055=EUR/USD110=100000279=1269=1270=1.19819271=100000055=EUR/USD110=50000010=037
20260120-14:03:18.523388000 : 8=FIX.4.49=067835=X49=NTPRO_IDBA_UAT56=SIRIUS_500007460_MD34=64752=20260120-14:03:19.235262=MD_GBP/USD_140109778778268=10279=1269=0270=1.2546271=10000055=GBP/USD110=0279=1269=0270=1.2546271=50000055=GBP/USD110=100000279=1269=0270=1.2546271=100000055=GBP/USD110=500000279=1269=0270=1.2546271=300000055=GBP/USD110=1000000279=1269=0270=1.2546271=500000055=GBP/USD110=3000000279=1269=1270=1.43494271=10000055=GBP/USD110=0279=1269=1270=1.43494271=50000055=GBP/USD110=100000279=1269=1270=1.43494271=100000055=GBP/USD110=500000279=1269=1270=1.43494271=300000055=GBP/USD110=1000000279=1269=1270=1.43494271=500000055=GBP/USD110=300000010=222
20260120-14:03:18.578534000 : 8=FIX.4.49=039735=X49=NTPRO_IDBA_UAT56=SIRIUS_500007460_MD34=64852=20260120-14:03:19.291262=MD_GBP/USD_140109778778268=5279=1269=1270=1.43495271=10000055=GBP/USD110=0279=1269=1270=1.43495271=50000055=GBP/USD110=100000279=1269=1270=1.43495271=100000055=GBP/USD110=500000279=1269=1270=1.43495271=300000055=GBP/USD110=1000000279=1269=1270=1.43495271=500000055=GBP/USD110=300000010=072
20260120-14:03:18.617205000 : 8=FIX.4.49=068335=X49=NTPRO_IDBA_UAT56=SIRIUS_500007460_MD34=64952=20260120-14:03:19.333262=MD_GBP/USD_140109778778268=10279=1269=0270=1.25461271=10000055=GBP/USD110=0279=1269=0270=1.25461271=50000055=GBP/USD110=100000279=1269=0270=1.25461271=100000055=GBP/USD110=500000279=1269=0270=1.25461271=300000055=GBP/USD110=1000000279=1269=0270=1.25461271=500000055=GBP/USD110=3000000279=1269=1270=1.43496271=10000055=GBP/USD110=0279=1269=1270=1.43496271=50000055=GBP/USD110=100000279=1269=1270=1.43496271=100000055=GBP/USD110=500000279=1269=1270=1.43496271=300000055=GBP/USD110=1000000279=1269=1270=1.43496271=500000055=GBP/USD110=300000010=218
20260120-14:03:18.648196000 : 8=FIX.4.49=044635=X49=NTPRO_IDBA_UAT56=SIRIUS_500007460_MD34=65052=20260120-14:03:19.357262=MD_EUR/USD_140109278614268=6279=1269=0270=1.14796271=10000055=EUR/USD110=0279=1269=0270=1.14796271=50000055=EUR/USD110=100000279=1269=0270=1.14796271=100000055=EUR/USD110=500000279=1269=1270=1.19821271=10000055=EUR/USD110=0279=1269=1270=1.19821271=50000055=EUR/USD110=100000279=1269=1270=1.19821271=100000055=EUR/USD110=50000010=017
20260120-14:03:18.776916000 : 8=FIX.4.49=068335=X49=NTPRO_IDBA_UAT56=SIRIUS_500007460_MD34=65152=20260120-14:03:19.495262=MD_GBP/USD_140109778778268=10279=1269=0270=1.25462271=10000055=GBP/USD110=0279=1269=0270=1.25462271=50000055=GBP/USD110=100000279=1269=0270=1.25462271=100000055=GBP/USD110=500000279=1269=0270=1.25462271=300000055=GBP/USD110=1000000279=1269=0270=1.25462271=500000055=GBP/USD110=3000000279=1269=1270=1.43497271=10000055=GBP/USD110=0279=1269=1270=1.43497271=50000055=GBP/USD110=100000279=1269=1270=1.43497271=100000055=GBP/USD110=500000279=1269=1270=1.43497271=300000055=GBP/USD110=1000000279=1269=1270=1.43497271=500000055=GBP/USD110=300000010=230
20260120-14:03:18.875325000 : 8=FIX.4.49=027635=X49=NTPRO_IDBA_UAT56=SIRIUS_500007460_MD34=65252=20260120-14:03:19.597262=MD_EUR/USD_140109278614268=3279=1269=1270=1.1982271=10000055=EUR/USD110=0279=1269=1270=1.1982271=50000055=EUR/USD110=100000279=1269=1270=1.1982271=100000055=EUR/USD110=50000010=079
20260120-14:03:18.891569000 : 8=FIX.4.49=027935=X49=NTPRO_IDBA_UAT56=SIRIUS_500007460_MD34=65352=20260120-14:03:19.617262=MD_EUR/USD_140109278614268=3279=1269=1270=1.19821271=10000055=EUR/USD110=0279=1269=1270=1.19821271=50000055=EUR/USD110=100000279=1269=1270=1.19821271=100000055=EUR/USD110=50000010=223
20260120-14:03:18.948229000 : 8=FIX.4.49=039735=X49=NTPRO_IDBA_UAT56=SIRIUS_500007460_MD34=65452=20260120-14:03:19.633262=MD_GBP/USD_140109778778268=5279=1269=0270=1.25463271=10000055=GBP/USD110=0279=1269=0270=1.25463271=50000055=GBP/USD110=100000279=1269=0270=1.25463271=100000055=GBP/USD110=500000279=1269=0270=1.25463271=300000055=GBP/USD110=1000000279=1269=0270=1.25463271=500000055=GBP/USD110=300000010=039
20260120-14:03:19.049455000 : 8=FIX.4.49=044635=X49=NTPRO_IDBA_UAT56=SIRIUS_500007460_MD34=65552=20260120-14:03:19.764262=MD_EUR/USD_140109278614268=6279=1269=0270=1.14798271=10000055=EUR/USD110=0279=1269=0270=1.14798271=50000055=EUR/USD110=100000279=1269=0270=1.14798271=100000055=EUR/USD110=500000279=1269=1270=1.19823271=10000055=EUR/USD110=0279=1269=1270=1.19823271=50000055=EUR/USD110=100000279=1269=1270=1.19823271=100000055=EUR/USD110=50000010=036
20260120-14:03:19.059816000 : 8=FIX.4.49=068335=X49=NTPRO_IDBA_UAT56=SIRIUS_500007460_MD34=65652=20260120-14:03:19.791262=MD_GBP/USD_140109778778268=10279=1269=0270=1.25464271=10000055=GBP/USD110=0279=1269=0270=1.25464271=50000055=GBP/USD110=100000279=1269=0270=1.25464271=100000055=GBP/USD110=500000279=1269=0270=1.25464271=300000055=GBP/USD110=1000000279=1269=0270=1.25464271=500000055=GBP/USD110=3000000279=1269=1270=1.43499271=10000055=GBP/USD110=0279=1269=1270=1.43499271=50000055=GBP/USD110=100000279=1269=1270=1.43499271=100000055=GBP/USD110=500000279=1269=1270=1.43499271=300000055=GBP/USD110=1000000279=1269=1270=1.43499271=500000055=GBP/USD110=300000010=254
20260120-14:03:19.181500000 : 8=FIX.4.49=039735=X49=NTPRO_IDBA_UAT56=SIRIUS_500007460_MD34=65752=20260120-14:03:19.918262=MD_GBP/USD_140109778778268=5279=1269=0270=1.25465271=10000055=GBP/USD110=0279=1269=0270=1.25465271=50000055=GBP/USD110=100000279=1269=0270=1.25465271=100000055=GBP/USD110=500000279=1269=0270=1.25465271=300000055=GBP/USD110=1000000279=1269=0270=1.25465271=500000055=GBP/USD110=300000010=058
20260120-14:03:19.207728000 : 8=FIX.4.49=067335=X49=NTPRO_IDBA_UAT56=SIRIUS_500007460_MD34=65852=20260120-14:03:19.945262=MD_GBP/USD_140109778778268=10279=1269=0270=1.25466271=10000055=GBP/USD110=0279=1269=0270=1.25466271=50000055=GBP/USD110=100000279=1269=0270=1.25466271=100000055=GBP/USD110=500000279=1269=0270=1.25466271=300000055=GBP/USD110=1000000279=1269=0270=1.25466271=500000055=GBP/USD110=3000000279=1269=1270=1.435271=10000055=GBP/USD110=0279=1269=1270=1.435271=50000055=GBP/USD110=100000279=1269=1270=1.435271=100000055=GBP/USD110=500000279=1269=1270=1.435271=300000055=GBP/USD110=1000000279=1269=1270=1.435271=500000055=GBP/USD110=300000010=213
20260120-14:03:19.217270000 : 8=FIX.4.49=044035=X49=NTPRO_IDBA_UAT56=SIRIUS_500007460_MD34=65952=20260120-14:03:19.954262=MD_EUR/USD_140109278614268=6279=1269=0270=1.148271=10000055=EUR/USD110=0279=1269=0270=1.148271=50000055=EUR/USD110=100000279=1269=0270=1.148271=100000055=EUR/USD110=500000279=1269=1270=1.19825271=10000055=EUR/USD110=0279=1269=1270=1.19825271=50000055=EUR/USD110=100000279=1269=1270=1.19825271=100000055=EUR/USD110=50000010=217
20260120-14:03:19.275536000 : 8=FIX.4.49=044635=X49=NTPRO_IDBA_UAT56=SIRIUS_500007460_MD34=66052=20260120-14:03:20.011262=MD_EUR/USD_140109278614268=6279=1269=0270=1.14796271=10000055=EUR/USD110=0279=1269=0270=1.14796271=50000055=EUR/USD110=100000279=1269=0270=1.14796271=100000055=EUR/USD110=500000279=1269=1270=1.19823271=10000055=EUR/USD110=0279=1269=1270=1.19823271=50000055=EUR/USD110=100000279=1269=1270=1.19823271=100000055=EUR/USD110=50000010=003
20260120-14:03:19.298256000 : 8=FIX.4.49=068335=X49=NTPRO_IDBA_UAT56=SIRIUS_500007460_MD34=66152=20260120-14:03:20.039262=MD_GBP/USD_140109778778268=10279=1269=0270=1.25464271=10000055=GBP/USD110=0279=1269=0270=1.25464271=50000055=GBP/USD110=100000279=1269=0270=1.25464271=100000055=GBP/USD110=500000279=1269=0270=1.25464271=300000055=GBP/USD110=1000000279=1269=0270=1.25464271=500000055=GBP/USD110=3000000279=1269=1270=1.43494271=10000055=GBP/USD110=0279=1269=1270=1.43494271=50000055=GBP/USD110=100000279=1269=1270=1.43494271=100000055=GBP/USD110=500000279=1269=1270=1.43494271=300000055=GBP/USD110=1000000279=1269=1270=1.43494271=500000055=GBP/USD110=300000010=212
20260120-14:03:19.346551000 : 8=FIX.4.49=044635=X49=NTPRO_IDBA_UAT56=SIRIUS_500007460_MD34=66252=20260120-14:03:20.071262=MD_EUR/USD_140109278614268=6279=2269=0270=1.14796271=10000055=EUR/USD110=0279=2269=0270=1.14796271=50000055=EUR/USD110=100000279=2269=0270=1.14796271=100000055=EUR/USD110=500000279=2269=1270=1.19823271=10000055=EUR/USD110=0279=2269=1270=1.19823271=50000055=EUR/USD110=100000279=2269=1270=1.19823271=100000055=EUR/USD110=50000010=017
20260120-14:03:19.407890000 : 8=FIX.4.49=068335=X49=NTPRO_IDBA_UAT56=SIRIUS_500007460_MD34=66352=20260120-14:03:20.152262=MD_GBP/USD_140109778778268=10279=1269=0270=1.25459271=10000055=GBP/USD110=0279=1269=0270=1.25459271=50000055=GBP/USD110=100000279=1269=0270=1.25459271=100000055=GBP/USD110=500000279=1269=0270=1.25459271=300000055=GBP/USD110=1000000279=1269=0270=1.25459271=500000055=GBP/USD110=3000000279=1269=1270=1.43492271=10000055=GBP/USD110=0279=1269=1270=1.43492271=50000055=GBP/USD110=100000279=1269=1270=1.43492271=100000055=GBP/USD110=500000279=1269=1270=1.43492271=300000055=GBP/USD110=1000000279=1269=1270=1.43492271=500000055=GBP/USD110=300000010=220
20260120-14:03:19.445383000 : 8=FIX.4.49=044635=X49=NTPRO_IDBA_UAT56=SIRIUS_500007460_MD34=66452=20260120-14:03:20.173262=MD_EUR/USD_140109278614268=6279=0269=0270=1.14792271=10000055=EUR/USD110=0279=0269=0270=1.14792271=50000055=EUR/USD110=100000279=0269=0270=1.14792271=100000055=EUR/USD110=500000279=0269=1270=1.19817271=10000055=EUR/USD110=0279=0269=1270=1.19817271=50000055=EUR/USD110=100000279=0269=1270=1.19817271=100000055=EUR/USD110=50000010=007
20260120-14:03:19.451622000 : 8=FIX.4.49=068335=X49=NTPRO_IDBA_UAT56=SIRIUS_500007460_MD34=66552=20260120-14:03:20.188262=MD_GBP/USD_140109778778268=10279=1269=0270=1.25458271=10000055=GBP/USD110=0279=1269=0270=1.25458271=50000055=GBP/USD110=100000279=1269=0270=1.25458271=100000055=GBP/USD110=500000279=1269=0270=1.25458271=300000055=GBP/USD110=1000000279=1269=0270=1.25458271=500000055=GBP/USD110=3000000279=1269=1270=1.43493271=10000055=GBP/USD110=0279=1269=1270=1.43493271=50000055=GBP/USD110=100000279=1269=1270=1.43493271=100000055=GBP/USD110=500000279=1269=1270=1.43493271=300000055=GBP/USD110=1000000279=1269=1270=1.43493271=500000055=GBP/USD110=300000010=231
20260120-14:03:19.555966000 : 8=FIX.4.49=027935=X49=NTPRO_IDBA_UAT56=SIRIUS_500007460_MD34=66652=20260120-14:03:20.305262=MD_EUR/USD_140109278614268=3279=1269=0270=1.14793271=10000055=EUR/USD110=0279=1269=0270=1.14793271=50000055=EUR/USD110=100000279=1269=0270=1.14793271=100000055=EUR/USD110=50000010=219
20260120-14:03:19.599829000 : 8=FIX.4.49=039735=X49=NTPRO_IDBA_UAT56=SIRIUS_500007460_MD34=66752=20260120-14:03:20.313262=MD_GBP/USD_140109778778268=5279=1269=0270=1.25459271=10000055=GBP/USD110=0279=1269=0270=1.25459271=50000055=GBP/USD110=100000279=1269=0270=1.25459271=100000055=GBP/USD110=500000279=1269=0270=1.25459271=300000055=GBP/USD110=1000000279=1269=0270=1.25459271=500000055=GBP/USD110=300000010=055
20260120-14:03:19.680906000 : 8=FIX.4.49=039735=X49=NTPRO_IDBA_UAT56=SIRIUS_500007460_MD34=66852=20260120-14:03:20.435262=MD_GBP/USD_140109778778268=5279=1269=0270=1.25458271=10000055=GBP/USD110=0279=1269=0270=1.25458271=50000055=GBP/USD110=100000279=1269=0270=1.25458271=100000055=GBP/USD110=500000279=1269=0270=1.25458271=300000055=GBP/USD110=1000000279=1269=0270=1.25458271=500000055=GBP/USD110=300000010=056
20260120-14:03:19.682883000 : 8=FIX.4.49=027935=X49=NTPRO_IDBA_UAT56=SIRIUS_500007460_MD34=66952=20260120-14:03:20.437262=MD_EUR/USD_140109278614268=3279=1269=0270=1.14792271=10000055=EUR/USD110=0279=1269=0270=1.14792271=50000055=EUR/USD110=100000279=1269=0270=1.14792271=100000055=EUR/USD110=50000010=225
20260120-14:03:19.756701000 : 8=FIX.4.49=068335=X49=NTPRO_IDBA_UAT56=SIRIUS_500007460_MD34=67052=20260120-14:03:20.511262=MD_GBP/USD_140109778778268=10279=1269=0270=1.25457271=10000055=GBP/USD110=0279=1269=0270=1.25457271=50000055=GBP/USD110=100000279=1269=0270=1.25457271=100000055=GBP/USD110=500000279=1269=0270=1.25457271=300000055=GBP/USD110=1000000279=1269=0270=1.25457271=500000055=GBP/USD110=3000000279=1269=1270=1.43492271=10000055=GBP/USD110=0279=1269=1270=1.43492271=50000055=GBP/USD110=100000279=1269=1270=1.43492271=100000055=GBP/USD110=500000279=1269=1270=1.43492271=300000055=GBP/USD110=1000000279=1269=1270=1.43492271=500000055=GBP/USD110=300000010=207
20260120-14:03:19.776253000 : 8=FIX.4.49=027935=X49=NTPRO_IDBA_UAT56=SIRIUS_500007460_MD34=67152=20260120-14:03:20.534262=MD_EUR/USD_140109278614268=3279=1269=1270=1.19816271=10000055=EUR/USD110=0279=1269=1270=1.19816271=50000055=EUR/USD110=100000279=1269=1270=1.19816271=100000055=EUR/USD110=50000010=225
20260120-14:03:19.837287000 : 8=FIX.4.49=027935=X49=NTPRO_IDBA_UAT56=SIRIUS_500007460_MD34=67252=20260120-14:03:20.594262=MD_EUR/USD_140109278614268=3279=1269=0270=1.14791271=10000055=EUR/USD110=0279=1269=0270=1.14791271=50000055=EUR/USD110=100000279=1269=0270=1.14791271=100000055=EUR/USD110=50000010=220
20260120-14:03:19.902850000 : 8=FIX.4.49=027935=X49=NTPRO_IDBA_UAT56=SIRIUS_500007460_MD34=67352=20260120-14:03:20.664262=MD_EUR/USD_140109278614268=3279=1269=0270=1.14792271=10000055=EUR/USD110=0279=1269=0270=1.14792271=50000055=EUR/USD110=100000279=1269=0270=1.14792271=100000055=EUR/USD110=50000010=222
20260120-14:03:20.156198000 : 8=FIX.4.49=027935=X49=NTPRO_IDBA_UAT56=SIRIUS_500007460_MD34=67452=20260120-14:03:20.918262=MD_EUR/USD_140109278614268=3279=1269=0270=1.14791271=10000055=EUR/USD110=0279=1269=0270=1.14791271=50000055=EUR/USD110=100000279=1269=0270=1.14791271=100000055=EUR/USD110=50000010=222
20260120-14:03:20.156737000 : 8=FIX.4.49=067835=X49=NTPRO_IDBA_UAT56=SIRIUS_500007460_MD34=67552=20260120-14:03:20.923262=MD_GBP/USD_140109778778268=10279=1269=0270=1.25456271=10000055=GBP/USD110=0279=1269=0270=1.25456271=50000055=GBP/USD110=100000279=1269=0270=1.25456271=100000055=GBP/USD110=500000279=1269=0270=1.25456271=300000055=GBP/USD110=1000000279=1269=0270=1.25456271=500000055=GBP/USD110=3000000279=1269=1270=1.4349271=10000055=GBP/USD110=0279=1269=1270=1.4349271=50000055=GBP/USD110=100000279=1269=1270=1.4349271=100000055=GBP/USD110=500000279=1269=1270=1.4349271=300000055=GBP/USD110=1000000279=1269=1270=1.4349271=500000055=GBP/USD110=300000010=224
20260120-14:03:20.391356000 : 8=FIX.4.49=039735=X49=NTPRO_IDBA_UAT56=SIRIUS_500007460_MD34=67652=20260120-14:03:21.171262=MD_GBP/USD_140109778778268=5279=1269=1270=1.43489271=10000055=GBP/USD110=0279=1269=1270=1.43489271=50000055=GBP/USD110=100000279=1269=1270=1.43489271=100000055=GBP/USD110=500000279=1269=1270=1.43489271=300000055=GBP/USD110=1000000279=1269=1270=1.43489271=500000055=GBP/USD110=300000010=078
20260120-14:03:20.431970000 : 8=FIX.4.49=039735=X49=NTPRO_IDBA_UAT56=SIRIUS_500007460_MD34=67752=20260120-14:03:21.212262=MD_GBP/USD_140109778778268=5279=1269=0270=1.25454271=10000055=GBP/USD110=0279=1269=0270=1.25454271=50000055=GBP/USD110=100000279=1269=0270=1.25454271=100000055=GBP/USD110=500000279=1269=0270=1.25454271=300000055=GBP/USD110=1000000279=1269=0270=1.25454271=500000055=GBP/USD110=300000010=030
20260120-14:03:20.451987000 : 8=FIX.4.49=039735=X49=NTPRO_IDBA_UAT56=SIRIUS_500007460_MD34=67852=20260120-14:03:21.233262=MD_GBP/USD_140109778778268=5279=1269=0270=1.25455271=10000055=GBP/USD110=0279=1269=0270=1.25455271=50000055=GBP/USD110=100000279=1269=0270=1.25455271=100000055=GBP/USD110=500000279=1269=0270=1.25455271=300000055=GBP/USD110=1000000279=1269=0270=1.25455271=500000055=GBP/USD110=300000010=039
20260120-14:03:20.709903000 : 8=FIX.4.49=039735=X49=NTPRO_IDBA_UAT56=SIRIUS_500007460_MD34=67952=20260120-14:03:21.438262=MD_GBP/USD_140109778778268=5279=1269=0270=1.25454271=10000055=GBP/USD110=0279=1269=0270=1.25454271=50000055=GBP/USD110=100000279=1269=0270=1.25454271=100000055=GBP/USD110=500000279=1269=0270=1.25454271=300000055=GBP/USD110=1000000279=1269=0270=1.25454271=500000055=GBP/USD110=300000010=042
20260120-14:03:21.137357000 : 8=FIX.4.49=039735=X49=NTPRO_IDBA_UAT56=SIRIUS_500007460_MD34=68052=20260120-14:03:21.921262=MD_GBP/USD_140109778778268=5279=1269=0270=1.25455271=10000055=GBP/USD110=0279=1269=0270=1.25455271=50000055=GBP/USD110=100000279=1269=0270=1.25455271=100000055=GBP/USD110=500000279=1269=0270=1.25455271=300000055=GBP/USD110=1000000279=1269=0270=1.25455271=500000055=GBP/USD110=300000010=036
20260120-14:03:21.522275000 : 8=FIX.4.49=039235=X49=NTPRO_IDBA_UAT56=SIRIUS_500007460_MD34=68152=20260120-14:03:22.334262=MD_GBP/USD_140109778778268=5279=1269=1270=1.4349271=10000055=GBP/USD110=0279=1269=1270=1.4349271=50000055=GBP/USD110=100000279=1269=1270=1.4349271=100000055=GBP/USD110=500000279=1269=1270=1.4349271=300000055=GBP/USD110=1000000279=1269=1270=1.4349271=500000055=GBP/USD110=300000010=047
20260120-14:03:21.565383000 : 8=FIX.4.49=039735=X49=NTPRO_IDBA_UAT56=SIRIUS_500007460_MD34=68252=20260120-14:03:22.385262=MD_GBP/USD_140109778778268=5279=1269=0270=1.25456271=10000055=GBP/USD110=0279=1269=0270=1.25456271=50000055=GBP/USD110=100000279=1269=0270=1.25456271=100000055=GBP/USD110=500000279=1269=0270=1.25456271=300000055=GBP/USD110=1000000279=1269=0270=1.25456271=500000055=GBP/USD110=300000010=048
20260120-14:03:21.589255000 : 8=FIX.4.49=044635=X49=NTPRO_IDBA_UAT56=SIRIUS_500007460_MD34=68352=20260120-14:03:22.411262=MD_EUR/USD_140109278614268=6279=1269=0270=1.14792271=10000055=EUR/USD110=0279=1269=0270=1.14792271=50000055=EUR/USD110=100000279=1269=0270=1.14792271=100000055=EUR/USD110=500000279=1269=1270=1.19817271=10000055=EUR/USD110=0279=1269=1270=1.19817271=50000055=EUR/USD110=100000279=1269=1270=1.19817271=100000055=EUR/USD110=50000010=011
20260120-14:03:21.657784000 : 8=FIX.4.49=044635=X49=NTPRO_IDBA_UAT56=SIRIUS_500007460_MD34=68452=20260120-14:03:22.482262=MD_EUR/USD_140109278614268=6279=1269=0270=1.14795271=10000055=EUR/USD110=0279=1269=0270=1.14795271=50000055=EUR/USD110=100000279=1269=0270=1.14795271=100000055=EUR/USD110=500000279=1269=1270=1.19819271=10000055=EUR/USD110=0279=1269=1270=1.19819271=50000055=EUR/USD110=100000279=1269=1270=1.19819271=100000055=EUR/USD110=50000010=035
20260120-14:03:21.720187000 : 8=FIX.4.49=027635=X49=NTPRO_IDBA_UAT56=SIRIUS_500007460_MD34=68552=20260120-14:03:22.547262=MD_EUR/USD_140109278614268=3279=1269=1270=1.1982271=10000055=EUR/USD110=0279=1269=1270=1.1982271=50000055=EUR/USD110=100000279=1269=1270=1.1982271=100000055=EUR/USD110=50000010=074
20260120-14:03:21.794159000 : 8=FIX.4.49=027935=X49=NTPRO_IDBA_UAT56=SIRIUS_500007460_MD34=68652=20260120-14:03:22.621262=MD_EUR/USD_140109278614268=3279=1269=1270=1.19819271=10000055=EUR/USD110=0279=1269=1270=1.19819271=50000055=EUR/USD110=100000279=1269=1270=1.19819271=100000055=EUR/USD110=50000010=239
20260120-14:03:22.053815000 : 8=FIX.4.49=027635=X49=NTPRO_IDBA_UAT56=SIRIUS_500007460_MD34=68752=20260120-14:03:22.892262=MD_EUR/USD_140109278614268=3279=1269=1270=1.1982271=10000055=EUR/USD110=0279=1269=1270=1.1982271=50000055=EUR/USD110=100000279=1269=1270=1.1982271=100000055=EUR/USD110=50000010=079
20260120-14:03:22.128152000 : 8=FIX.4.49=027935=X49=NTPRO_IDBA_UAT56=SIRIUS_500007460_MD34=68852=20260120-14:03:22.969262=MD_EUR/USD_140109278614268=3279=1269=1270=1.19819271=10000055=EUR/USD110=0279=1269=1270=1.19819271=50000055=EUR/USD110=100000279=1269=1270=1.19819271=100000055=EUR/USD110=50000010=000
20260120-14:03:22.147257000 : 8=FIX.4.49=027635=X49=NTPRO_IDBA_UAT56=SIRIUS_500007460_MD34=68952=20260120-14:03:22.989262=MD_EUR/USD_140109278614268=3279=1269=1270=1.1982271=10000055=EUR/USD110=0279=1269=1270=1.1982271=50000055=EUR/USD110=100000279=1269=1270=1.1982271=100000055=EUR/USD110=50000010=088
20260120-14:03:22.176967000 : 8=FIX.4.49=039735=X49=NTPRO_IDBA_UAT56=SIRIUS_500007460_MD34=69052=20260120-14:03:23.020262=MD_GBP/USD_140109778778268=5279=1269=0270=1.25457271=10000055=GBP/USD110=0279=1269=0270=1.25457271=50000055=GBP/USD110=100000279=1269=0270=1.25457271=100000055=GBP/USD110=500000279=1269=0270=1.25457271=300000055=GBP/USD110=1000000279=1269=0270=1.25457271=500000055=GBP/USD110=300000010=039
20260120-14:03:22.427395000 : 8=FIX.4.49=027935=X49=NTPRO_IDBA_UAT56=SIRIUS_500007460_MD34=69152=20260120-14:03:23.279262=MD_EUR/USD_140109278614268=3279=1269=0270=1.14796271=10000055=EUR/USD110=0279=1269=0270=1.14796271=50000055=EUR/USD110=100000279=1269=0270=1.14796271=100000055=EUR/USD110=50000010=239
20260120-14:03:22.509827000 : 8=FIX.4.49=039735=X49=NTPRO_IDBA_UAT56=SIRIUS_500007460_MD34=69252=20260120-14:03:23.347262=MD_GBP/USD_140109778778268=5279=1269=0270=1.25456271=10000055=GBP/USD110=0279=1269=0270=1.25456271=50000055=GBP/USD110=100000279=1269=0270=1.25456271=100000055=GBP/USD110=500000279=1269=0270=1.25456271=300000055=GBP/USD110=1000000279=1269=0270=1.25456271=500000055=GBP/USD110=300000010=048
20260120-14:03:22.664840000 : 8=FIX.4.49=068335=X49=NTPRO_IDBA_UAT56=SIRIUS_500007460_MD34=69352=20260120-14:03:23.525262=MD_GBP/USD_140109778778268=10279=1269=0270=1.25457271=10000055=GBP/USD110=0279=1269=0270=1.25457271=50000055=GBP/USD110=100000279=1269=0270=1.25457271=100000055=GBP/USD110=500000279=1269=0270=1.25457271=300000055=GBP/USD110=1000000279=1269=0270=1.25457271=500000055=GBP/USD110=3000000279=1269=1270=1.43491271=10000055=GBP/USD110=0279=1269=1270=1.43491271=50000055=GBP/USD110=100000279=1269=1270=1.43491271=100000055=GBP/USD110=500000279=1269=1270=1.43491271=300000055=GBP/USD110=1000000279=1269=1270=1.43491271=500000055=GBP/USD110=300000010=215
20260120-14:03:22.767046000 : 8=FIX.4.49=039735=X49=NTPRO_IDBA_UAT56=SIRIUS_500007460_MD34=69452=20260120-14:03:23.630262=MD_GBP/USD_140109778778268=5279=1269=0270=1.25456271=10000055=GBP/USD110=0279=1269=0270=1.25456271=50000055=GBP/USD110=100000279=1269=0270=1.25456271=100000055=GBP/USD110=500000279=1269=0270=1.25456271=300000055=GBP/USD110=1000000279=1269=0270=1.25456271=500000055=GBP/USD110=300000010=045
20260120-14:03:22.788453000 : 8=FIX.4.49=027935=X49=NTPRO_IDBA_UAT56=SIRIUS_500007460_MD34=69552=20260120-14:03:23.652262=MD_EUR/USD_140109278614268=3279=1269=0270=1.14795271=10000055=EUR/USD110=0279=1269=0270=1.14795271=50000055=EUR/USD110=100000279=1269=0270=1.14795271=100000055=EUR/USD110=50000010=235
20260120-14:03:22.905127000 : 8=FIX.4.49=027935=X49=NTPRO_IDBA_UAT56=SIRIUS_500007460_MD34=69652=20260120-14:03:23.769262=MD_EUR/USD_140109278614268=3279=1269=0270=1.14796271=10000055=EUR/USD110=0279=1269=0270=1.14796271=50000055=EUR/USD110=100000279=1269=0270=1.14796271=100000055=EUR/USD110=50000010=248
20260120-14:03:22.909356000 : 8=FIX.4.49=039735=X49=NTPRO_IDBA_UAT56=SIRIUS_500007460_MD34=69752=20260120-14:03:23.779262=MD_GBP/USD_140109778778268=5279=1269=0270=1.25457271=10000055=GBP/USD110=0279=1269=0270=1.25457271=50000055=GBP/USD110=100000279=1269=0270=1.25457271=100000055=GBP/USD110=500000279=1269=0270=1.25457271=300000055=GBP/USD110=1000000279=1269=0270=1.25457271=500000055=GBP/USD110=300000010=067
20260120-14:03:22.927017000 : 8=FIX.4.49=027935=X49=NTPRO_IDBA_UAT56=SIRIUS_500007460_MD34=69852=20260120-14:03:23.796262=MD_EUR/USD_140109278614268=3279=1269=1270=1.19821271=10000055=EUR/USD110=0279=1269=1270=1.19821271=50000055=EUR/USD110=100000279=1269=1270=1.19821271=100000055=EUR/USD110=50000010=235
20260120-14:03:23.219237000 : 8=FIX.4.49=039735=X49=NTPRO_IDBA_UAT56=SIRIUS_500007460_MD34=69952=20260120-14:03:24.099262=MD_GBP/USD_140109778778268=5279=1269=1270=1.43492271=10000055=GBP/USD110=0279=1269=1270=1.43492271=50000055=GBP/USD110=100000279=1269=1270=1.43492271=100000055=GBP/USD110=500000279=1269=1270=1.43492271=300000055=GBP/USD110=1000000279=1269=1270=1.43492271=500000055=GBP/USD110=300000010=065
20260120-14:03:23.478147000 : 8=FIX.4.49=068335=X49=NTPRO_IDBA_UAT56=SIRIUS_500007460_MD34=70052=20260120-14:03:24.367262=MD_GBP/USD_140109778778268=10279=1269=0270=1.25456271=10000055=GBP/USD110=0279=1269=0270=1.25456271=50000055=GBP/USD110=100000279=1269=0270=1.25456271=100000055=GBP/USD110=500000279=1269=0270=1.25456271=300000055=GBP/USD110=1000000279=1269=0270=1.25456271=500000055=GBP/USD110=3000000279=1269=1270=1.43491271=10000055=GBP/USD110=0279=1269=1270=1.43491271=50000055=GBP/USD110=100000279=1269=1270=1.43491271=100000055=GBP/USD110=500000279=1269=1270=1.43491271=300000055=GBP/USD110=1000000279=1269=1270=1.43491271=500000055=GBP/USD110=300000010=204
20260120-14:03:23.668859000 : 8=FIX.4.49=027635=X49=NTPRO_IDBA_UAT56=SIRIUS_500007460_MD34=70152=20260120-14:03:24.564262=MD_EUR/USD_140109278614268=3279=1269=1270=1.1982271=10000055=EUR/USD110=0279=1269=1270=1.1982271=50000055=EUR/USD110=100000279=1269=1270=1.1982271=100000055=EUR/USD110=50000010=064
20260120-14:03:23.833457000 : 8=FIX.4.49=027935=X49=NTPRO_IDBA_UAT56=SIRIUS_500007460_MD34=70252=20260120-14:03:24.735262=MD_EUR/USD_140109278614268=3279=1269=0270=1.14795271=10000055=EUR/USD110=0279=1269=0270=1.14795271=50000055=EUR/USD110=100000279=1269=0270=1.14795271=100000055=EUR/USD110=50000010=227
20260120-14:03:23.859065000 : 8=FIX.4.49=027935=X49=NTPRO_IDBA_UAT56=SIRIUS_500007460_MD34=70352=20260120-14:03:24.762262=MD_EUR/USD_140109278614268=3279=1269=0270=1.14796271=10000055=EUR/USD110=0279=1269=0270=1.14796271=50000055=EUR/USD110=100000279=1269=0270=1.14796271=100000055=EUR/USD110=50000010=231
20260120-14:03:23.893360000 : 8=FIX.4.49=027935=X49=NTPRO_IDBA_UAT56=SIRIUS_500007460_MD34=70452=20260120-14:03:24.792262=MD_EUR/USD_140109278614268=3279=1269=0270=1.14795271=10000055=EUR/USD110=0279=1269=0270=1.14795271=50000055=EUR/USD110=100000279=1269=0270=1.14795271=100000055=EUR/USD110=50000010=232
20260120-14:03:24.214658000 : 8=FIX.4.49=027935=X49=NTPRO_IDBA_UAT56=SIRIUS_500007460_MD34=70552=20260120-14:03:25.130262=MD_EUR/USD_140109278614268=3279=1269=0270=1.14796271=10000055=EUR/USD110=0279=1269=0270=1.14796271=50000055=EUR/USD110=100000279=1269=0270=1.14796271=100000055=EUR/USD110=50000010=223
20260120-14:03:24.343055000 : 8=FIX.4.49=027935=X49=NTPRO_IDBA_UAT56=SIRIUS_500007460_MD34=70652=20260120-14:03:25.262262=MD_EUR/USD_140109278614268=3279=1269=1270=1.19821271=10000055=EUR/USD110=0279=1269=1270=1.19821271=50000055=EUR/USD110=100000279=1269=1270=1.19821271=100000055=EUR/USD110=50000010=215
20260120-14:03:24.985845000 : 8=FIX.4.49=027635=X49=NTPRO_IDBA_UAT56=SIRIUS_500007460_MD34=70752=20260120-14:03:25.929262=MD_EUR/USD_140109278614268=3279=1269=1270=1.1982271=10000055=EUR/USD110=0279=1269=1270=1.1982271=50000055=EUR/USD110=100000279=1269=1270=1.1982271=100000055=EUR/USD110=50000010=076
20260120-14:03:25.043361000 : 8=FIX.4.49=068335=X49=NTPRO_IDBA_UAT56=SIRIUS_500007460_MD34=70852=20260120-14:03:25.988262=MD_GBP/USD_140109778778268=10279=2269=0270=1.25456271=10000055=GBP/USD110=0279=2269=0270=1.25456271=50000055=GBP/USD110=100000279=2269=0270=1.25456271=100000055=GBP/USD110=500000279=2269=0270=1.25456271=300000055=GBP/USD110=1000000279=2269=0270=1.25456271=500000055=GBP/USD110=3000000279=2269=1270=1.43491271=10000055=GBP/USD110=0279=2269=1270=1.43491271=50000055=GBP/USD110=100000279=2269=1270=1.43491271=100000055=GBP/USD110=500000279=2269=1270=1.43491271=300000055=GBP/USD110=1000000279=2269=1270=1.43491271=500000055=GBP/USD110=300000010=232
20260120-14:03:25.081411000 : 8=FIX.4.49=044635=X49=NTPRO_IDBA_UAT56=SIRIUS_500007460_MD34=70952=20260120-14:03:26.009262=MD_EUR/USD_140109278614268=6279=1269=0270=1.14797271=10000055=EUR/USD110=0279=1269=0270=1.14797271=50000055=EUR/USD110=100000279=1269=0270=1.14797271=100000055=EUR/USD110=500000279=1269=1270=1.19821271=10000055=EUR/USD110=0279=1269=1270=1.19821271=50000055=EUR/USD110=100000279=1269=1270=1.19821271=100000055=EUR/USD110=50000010=017
20260120-14:03:25.082274000 : 8=FIX.4.49=068335=X49=NTPRO_IDBA_UAT56=SIRIUS_500007460_MD34=71052=20260120-14:03:26.028262=MD_GBP/USD_140109778778268=10279=0269=0270=1.25459271=10000055=GBP/USD110=0279=0269=0270=1.25459271=50000055=GBP/USD110=100000279=0269=0270=1.25459271=100000055=GBP/USD110=500000279=0269=0270=1.25459271=300000055=GBP/USD110=1000000279=0269=0270=1.25459271=500000055=GBP/USD110=3000000279=0269=1270=1.43493271=10000055=GBP/USD110=0279=0269=1270=1.43493271=50000055=GBP/USD110=100000279=0269=1270=1.43493271=100000055=GBP/USD110=500000279=0269=1270=1.43493271=300000055=GBP/USD110=1000000279=0269=1270=1.43493271=500000055=GBP/USD110=300000010=216
20260120-14:03:25.150053000 : 8=FIX.4.49=068335=X49=NTPRO_IDBA_UAT56=SIRIUS_500007460_MD34=71152=20260120-14:03:26.097262=MD_GBP/USD_140109778778268=10279=1269=0270=1.25461271=10000055=GBP/USD110=0279=1269=0270=1.25461271=50000055=GBP/USD110=100000279=1269=0270=1.25461271=100000055=GBP/USD110=500000279=1269=0270=1.25461271=300000055=GBP/USD110=1000000279=1269=0270=1.25461271=500000055=GBP/USD110=3000000279=1269=1270=1.43495271=10000055=GBP/USD110=0279=1269=1270=1.43495271=50000055=GBP/USD110=100000279=1269=1270=1.43495271=100000055=GBP/USD110=500000279=1269=1270=1.43495271=300000055=GBP/USD110=1000000279=1269=1270=1.43495271=500000055=GBP/USD110=300000010=208
20260120-14:03:25.161026000 : 8=FIX.4.49=044635=X49=NTPRO_IDBA_UAT56=SIRIUS_500007460_MD34=71252=20260120-14:03:26.110262=MD_EUR/USD_140109278614268=6279=1269=0270=1.14799271=10000055=EUR/USD110=0279=1269=0270=1.14799271=50000055=EUR/USD110=100000279=1269=0270=1.14799271=100000055=EUR/USD110=500000279=1269=1270=1.19824271=10000055=EUR/USD110=0279=1269=1270=1.19824271=50000055=EUR/USD110=100000279=1269=1270=1.19824271=100000055=EUR/USD110=50000010=019
20260120-14:03:25.201091000 : 8=FIX.4.49=068335=X49=NTPRO_IDBA_UAT56=SIRIUS_500007460_MD34=71352=20260120-14:03:26.147262=MD_GBP/USD_140109778778268=10279=1269=0270=1.25464271=10000055=GBP/USD110=0279=1269=0270=1.25464271=50000055=GBP/USD110=100000279=1269=0270=1.25464271=100000055=GBP/USD110=500000279=1269=0270=1.25464271=300000055=GBP/USD110=1000000279=1269=0270=1.25464271=500000055=GBP/USD110=3000000279=1269=1270=1.43496271=10000055=GBP/USD110=0279=1269=1270=1.43496271=50000055=GBP/USD110=100000279=1269=1270=1.43496271=100000055=GBP/USD110=500000279=1269=1270=1.43496271=300000055=GBP/USD110=1000000279=1269=1270=1.43496271=500000055=GBP/USD110=300000010=226
20260120-14:03:25.228862000 : 8=FIX.4.49=044035=X49=NTPRO_IDBA_UAT56=SIRIUS_500007460_MD34=71452=20260120-14:03:26.181262=MD_EUR/USD_140109278614268=6279=1269=0270=1.148271=10000055=EUR/USD110=0279=1269=0270=1.148271=50000055=EUR/USD110=100000279=1269=0270=1.148271=100000055=EUR/USD110=500000279=1269=1270=1.19825271=10000055=EUR/USD110=0279=1269=1270=1.19825271=50000055=EUR/USD110=100000279=1269=1270=1.19825271=100000055=EUR/USD110=50000010=199
20260120-14:03:25.232117000 : 8=FIX.4.49=068335=X49=NTPRO_IDBA_UAT56=SIRIUS_500007460_MD34=71552=20260120-14:03:26.184262=MD_GBP/USD_140109778778268=10279=1269=0270=1.25466271=10000055=GBP/USD110=0279=1269=0270=1.25466271=50000055=GBP/USD110=100000279=1269=0270=1.25466271=100000055=GBP/USD110=500000279=1269=0270=1.25466271=300000055=GBP/USD110=1000000279=1269=0270=1.25466271=500000055=GBP/USD110=3000000279=1269=1270=1.43502271=10000055=GBP/USD110=0279=1269=1270=1.43502271=50000055=GBP/USD110=100000279=1269=1270=1.43502271=100000055=GBP/USD110=500000279=1269=1270=1.43502271=300000055=GBP/USD110=1000000279=1269=1270=1.43502271=500000055=GBP/USD110=300000010=179
20260120-14:03:25.289344000 : 8=FIX.4.49=038735=X49=NTPRO_IDBA_UAT56=SIRIUS_500007460_MD34=71652=20260120-14:03:26.225262=MD_GBP/USD_140109778778268=5279=1269=1270=1.435271=10000055=GBP/USD110=0279=1269=1270=1.435271=50000055=GBP/USD110=100000279=1269=1270=1.435271=100000055=GBP/USD110=500000279=1269=1270=1.435271=300000055=GBP/USD110=1000000279=1269=1270=1.435271=500000055=GBP/USD110=300000010=029
20260120-14:03:25.316928000 : 8=FIX.4.49=039735=X49=NTPRO_IDBA_UAT56=SIRIUS_500007460_MD34=71752=20260120-14:03:26.271262=MD_GBP/USD_140109778778268=5279=1269=1270=1.43501271=10000055=GBP/USD110=0279=1269=1270=1.43501271=50000055=GBP/USD110=100000279=1269=1270=1.43501271=100000055=GBP/USD110=500000279=1269=1270=1.43501271=300000055=GBP/USD110=1000000279=1269=1270=1.43501271=500000055=GBP/USD110=300000010=005
20260120-14:03:25.335775000 : 8=FIX.4.49=038735=X49=NTPRO_IDBA_UAT56=SIRIUS_500007460_MD34=71852=20260120-14:03:26.292262=MD_GBP/USD_140109778778268=5279=1269=1270=1.435271=10000055=GBP/USD110=0279=1269=1270=1.435271=50000055=GBP/USD110=100000279=1269=1270=1.435271=100000055=GBP/USD110=500000279=1269=1270=1.435271=300000055=GBP/USD110=1000000279=1269=1270=1.435271=500000055=GBP/USD110=300000010=035
20260120-14:03:25.347997000 : 8=FIX.4.49=044635=X49=NTPRO_IDBA_UAT56=SIRIUS_500007460_MD34=71952=20260120-14:03:26.298262=MD_EUR/USD_140109278614268=6279=1269=0270=1.14799271=10000055=EUR/USD110=0279=1269=0270=1.14799271=50000055=EUR/USD110=100000279=1269=0270=1.14799271=100000055=EUR/USD110=500000279=1269=1270=1.19824271=10000055=EUR/USD110=0279=1269=1270=1.19824271=50000055=EUR/USD110=100000279=1269=1270=1.19824271=100000055=EUR/USD110=50000010=043
20260120-14:03:25.386504000 : 8=FIX.4.49=027335=X49=NTPRO_IDBA_UAT56=SIRIUS_500007460_MD34=72052=20260120-14:03:26.339262=MD_EUR/USD_140109278614268=3279=1269=0270=1.148271=10000055=EUR/USD110=0279=1269=0270=1.148271=50000055=EUR/USD110=100000279=1269=0270=1.148271=100000055=EUR/USD110=50000010=152
20260120-14:03:25.484462000 : 8=FIX.4.49=027935=X49=NTPRO_IDBA_UAT56=SIRIUS_500007460_MD34=72152=20260120-14:03:26.445262=MD_EUR/USD_140109278614268=3279=1269=0270=1.14799271=10000055=EUR/USD110=0279=1269=0270=1.14799271=50000055=EUR/USD110=100000279=1269=0270=1.14799271=100000055=EUR/USD110=50000010=240
20260120-14:03:25.530178000 : 8=FIX.4.49=039735=X49=NTPRO_IDBA_UAT56=SIRIUS_500007460_MD34=72252=20260120-14:03:26.493262=MD_GBP/USD_140109778778268=5279=1269=1270=1.43501271=10000055=GBP/USD110=0279=1269=1270=1.43501271=50000055=GBP/USD110=100000279=1269=1270=1.43501271=100000055=GBP/USD110=500000279=1269=1270=1.43501271=300000055=GBP/USD110=1000000279=1269=1270=1.43501271=500000055=GBP/USD110=300000010=007
20260120-14:03:25.616308000 : 8=FIX.4.49=027335=X49=NTPRO_IDBA_UAT56=SIRIUS_500007460_MD34=72352=20260120-14:03:26.514262=MD_EUR/USD_140109278614268=3279=1269=0270=1.148271=10000055=EUR/USD110=0279=1269=0270=1.148271=50000055=EUR/USD110=100000279=1269=0270=1.148271=100000055=EUR/USD110=50000010=150
20260120-14:03:25.616713000 : 8=FIX.4.49=027935=X49=NTPRO_IDBA_UAT56=SIRIUS_500007460_MD34=72452=20260120-14:03:26.526262=MD_EUR/USD_140109278614268=3279=1269=1270=1.19825271=10000055=EUR/USD110=0279=1269=1270=1.19825271=50000055=EUR/USD110=100000279=1269=1270=1.19825271=100000055=EUR/USD110=50000010=231
20260120-14:03:25.617063000 : 8=FIX.4.49=038735=X49=NTPRO_IDBA_UAT56=SIRIUS_500007460_MD34=72552=20260120-14:03:26.579262=MD_GBP/USD_140109778778268=5279=1269=1270=1.435271=10000055=GBP/USD110=0279=1269=1270=1.435271=50000055=GBP/USD110=100000279=1269=1270=1.435271=100000055=GBP/USD110=500000279=1269=1270=1.435271=300000055=GBP/USD110=1000000279=1269=1270=1.435271=500000055=GBP/USD110=300000010=041
20260120-14:03:25.617410000 : 8=FIX.4.49=044635=X49=NTPRO_IDBA_UAT56=SIRIUS_500007460_MD34=72652=20260120-14:03:26.581262=MD_EUR/USD_140109278614268=6279=1269=0270=1.14799271=10000055=EUR/USD110=0279=1269=0270=1.14799271=50000055=EUR/USD110=100000279=1269=0270=1.14799271=100000055=EUR/USD110=500000279=1269=1270=1.19824271=10000055=EUR/USD110=0279=1269=1270=1.19824271=50000055=EUR/USD110=100000279=1269=1270=1.19824271=100000055=EUR/USD110=50000010=036
20260120-14:03:25.719504000 : 8=FIX.4.49=044635=X49=NTPRO_IDBA_UAT56=SIRIUS_500007460_MD34=72752=20260120-14:03:26.663262=MD_EUR/USD_140109278614268=6279=1269=0270=1.14798271=10000055=EUR/USD110=0279=1269=0270=1.14798271=50000055=EUR/USD110=100000279=1269=0270=1.14798271=100000055=EUR/USD110=500000279=1269=1270=1.19823271=10000055=EUR/USD110=0279=1269=1270=1.19823271=50000055=EUR/USD110=100000279=1269=1270=1.19823271=100000055=EUR/USD110=50000010=032
20260120-14:03:25.827225000 : 8=FIX.4.49=044635=X49=NTPRO_IDBA_UAT56=SIRIUS_500007460_MD34=72852=20260120-14:03:26.742262=MD_EUR/USD_140109278614268=6279=1269=0270=1.14799271=10000055=EUR/USD110=0279=1269=0270=1.14799271=50000055=EUR/USD110=100000279=1269=0270=1.14799271=100000055=EUR/USD110=500000279=1269=1270=1.19824271=10000055=EUR/USD110=0279=1269=1270=1.19824271=50000055=EUR/USD110=100000279=1269=1270=1.19824271=100000055=EUR/USD110=50000010=037
20260120-14:03:25.827585000 : 8=FIX.4.49=044035=X49=NTPRO_IDBA_UAT56=SIRIUS_500007460_MD34=72952=20260120-14:03:26.753262=MD_EUR/USD_140109278614268=6279=1269=0270=1.148271=10000055=EUR/USD110=0279=1269=0270=1.148271=50000055=EUR/USD110=100000279=1269=0270=1.148271=100000055=EUR/USD110=500000279=1269=1270=1.19825271=10000055=EUR/USD110=0279=1269=1270=1.19825271=50000055=EUR/USD110=100000279=1269=1270=1.19825271=100000055=EUR/USD110=50000010=210
20260120-14:03:26.120498000 : 8=FIX.4.49=044635=X49=NTPRO_IDBA_UAT56=SIRIUS_500007460_MD34=73052=20260120-14:03:27.034262=MD_EUR/USD_140109278614268=6279=1269=0270=1.14799271=10000055=EUR/USD110=0279=1269=0270=1.14799271=50000055=EUR/USD110=100000279=1269=0270=1.14799271=100000055=EUR/USD110=500000279=1269=1270=1.19823271=10000055=EUR/USD110=0279=1269=1270=1.19823271=50000055=EUR/USD110=100000279=1269=1270=1.19823271=100000055=EUR/USD110=50000010=022
20260120-14:03:26.135455000 : 8=FIX.4.49=027935=X49=NTPRO_IDBA_UAT56=SIRIUS_500007460_MD34=73152=20260120-14:03:27.120262=MD_EUR/USD_140109278614268=3279=1269=1270=1.19824271=10000055=EUR/USD110=0279=1269=1270=1.19824271=50000055=EUR/USD110=100000279=1269=1270=1.19824271=100000055=EUR/USD110=50000010=217
20260120-14:03:26.325131000 : 8=FIX.4.49=027935=X49=NTPRO_IDBA_UAT56=SIRIUS_500007460_MD34=73252=20260120-14:03:27.255262=MD_EUR/USD_140109278614268=3279=1269=1270=1.19823271=10000055=EUR/USD110=0279=1269=1270=1.19823271=50000055=EUR/USD110=100000279=1269=1270=1.19823271=100000055=EUR/USD110=50000010=224
20260120-14:03:26.325578000 : 8=FIX.4.49=027935=X49=NTPRO_IDBA_UAT56=SIRIUS_500007460_MD34=73352=20260120-14:03:27.291262=MD_EUR/USD_140109278614268=3279=1269=0270=1.14798271=10000055=EUR/USD110=0279=1269=0270=1.14798271=50000055=EUR/USD110=100000279=1269=0270=1.14798271=100000055=EUR/USD110=50000010=240
20260120-14:03:26.517023000 : 8=FIX.4.49=027935=X49=NTPRO_IDBA_UAT56=SIRIUS_500007460_MD34=73452=20260120-14:03:27.498262=MD_EUR/USD_140109278614268=3279=1269=1270=1.19822271=10000055=EUR/USD110=0279=1269=1270=1.19822271=50000055=EUR/USD110=100000279=1269=1270=1.19822271=100000055=EUR/USD110=50000010=232
20260120-14:03:26.529892000 : 8=FIX.4.49=068335=X49=NTPRO_IDBA_UAT56=SIRIUS_500007460_MD34=73552=20260120-14:03:27.528262=MD_GBP/USD_140109778778268=10279=1269=0270=1.25465271=10000055=GBP/USD110=0279=1269=0270=1.25465271=50000055=GBP/USD110=100000279=1269=0270=1.25465271=100000055=GBP/USD110=500000279=1269=0270=1.25465271=300000055=GBP/USD110=1000000279=1269=0270=1.25465271=500000055=GBP/USD110=3000000279=1269=1270=1.43499271=10000055=GBP/USD110=0279=1269=1270=1.43499271=50000055=GBP/USD110=100000279=1269=1270=1.43499271=100000055=GBP/USD110=500000279=1269=1270=1.43499271=300000055=GBP/USD110=1000000279=1269=1270=1.43499271=500000055=GBP/USD110=300000010=254
20260120-14:03:26.609539000 : 8=FIX.4.49=027935=X49=NTPRO_IDBA_UAT56=SIRIUS_500007460_MD34=73652=20260120-14:03:27.550262=MD_EUR/USD_140109278614268=3279=1269=0270=1.14797271=10000055=EUR/USD110=0279=1269=0270=1.14797271=50000055=EUR/USD110=100000279=1269=0270=1.14797271=100000055=EUR/USD110=50000010=238
20260120-14:03:26.721364000 : 8=FIX.4.49=068335=X49=NTPRO_IDBA_UAT56=SIRIUS_500007460_MD34=73752=20260120-14:03:27.666262=MD_GBP/USD_140109778778268=10279=1269=0270=1.25464271=10000055=GBP/USD110=0279=1269=0270=1.25464271=50000055=GBP/USD110=100000279=1269=0270=1.25464271=100000055=GBP/USD110=500000279=1269=0270=1.25464271=300000055=GBP/USD110=1000000279=1269=0270=1.25464271=500000055=GBP/USD110=3000000279=1269=1270=1.43498271=10000055=GBP/USD110=0279=1269=1270=1.43498271=50000055=GBP/USD110=100000279=1269=1270=1.43498271=100000055=GBP/USD110=500000279=1269=1270=1.43498271=300000055=GBP/USD110=1000000279=1269=1270=1.43498271=500000055=GBP/USD110=300000010=249
20260120-14:03:26.721965000 : 8=FIX.4.49=027935=X49=NTPRO_IDBA_UAT56=SIRIUS_500007460_MD34=73852=20260120-14:03:27.668262=MD_EUR/USD_140109278614268=3279=1269=1270=1.19823271=10000055=EUR/USD110=0279=1269=1270=1.19823271=50000055=EUR/USD110=100000279=1269=1270=1.19823271=100000055=EUR/USD110=50000010=238
20260120-14:03:26.819814000 : 8=FIX.4.49=039735=X49=NTPRO_IDBA_UAT56=SIRIUS_500007460_MD34=73952=20260120-14:03:27.761262=MD_GBP/USD_140109778778268=5279=1269=1270=1.43499271=10000055=GBP/USD110=0279=1269=1270=1.43499271=50000055=GBP/USD110=100000279=1269=1270=1.43499271=100000055=GBP/USD110=500000279=1269=1270=1.43499271=300000055=GBP/USD110=1000000279=1269=1270=1.43499271=500000055=GBP/USD110=300000010=094
20260120-14:03:26.907188000 : 8=FIX.4.49=044035=X49=NTPRO_IDBA_UAT56=SIRIUS_500007460_MD34=74052=20260120-14:03:27.848262=MD_EUR/USD_140109278614268=6279=1269=0270=1.148271=10000055=EUR/USD110=0279=1269=0270=1.148271=50000055=EUR/USD110=100000279=1269=0270=1.148271=100000055=EUR/USD110=500000279=1269=1270=1.19824271=10000055=EUR/USD110=0279=1269=1270=1.19824271=50000055=EUR/USD110=100000279=1269=1270=1.19824271=100000055=EUR/USD110=50000010=206
20260120-14:03:26.907644000 : 8=FIX.4.49=027935=X49=NTPRO_IDBA_UAT56=SIRIUS_500007460_MD34=74152=20260120-14:03:27.879262=MD_EUR/USD_140109278614268=3279=1269=0270=1.14799271=10000055=EUR/USD110=0279=1269=0270=1.14799271=50000055=EUR/USD110=100000279=1269=0270=1.14799271=100000055=EUR/USD110=50000010=254
20260120-14:03:26.908131000 : 8=FIX.4.49=027935=X49=NTPRO_IDBA_UAT56=SIRIUS_500007460_MD34=74252=20260120-14:03:27.894262=MD_EUR/USD_140109278614268=3279=1269=1270=1.19823271=10000055=EUR/USD110=0279=1269=1270=1.19823271=50000055=EUR/USD110=100000279=1269=1270=1.19823271=100000055=EUR/USD110=50000010=234
20260120-14:03:26.909947000 : 8=FIX.4.49=027935=X49=NTPRO_IDBA_UAT56=SIRIUS_500007460_MD34=74352=20260120-14:03:27.919262=MD_EUR/USD_140109278614268=3279=1269=1270=1.19824271=10000055=EUR/USD110=0279=1269=1270=1.19824271=50000055=EUR/USD110=100000279=1269=1270=1.19824271=100000055=EUR/USD110=50000010=236
20260120-14:03:27.007558000 : 8=FIX.4.49=027935=X49=NTPRO_IDBA_UAT56=SIRIUS_500007460_MD34=74452=20260120-14:03:27.971262=MD_EUR/USD_140109278614268=3279=1269=1270=1.19823271=10000055=EUR/USD110=0279=1269=1270=1.19823271=50000055=EUR/USD110=100000279=1269=1270=1.19823271=100000055=EUR/USD110=50000010=232
20260120-14:03:27.689496000 : 8=FIX.4.49=027935=X49=NTPRO_IDBA_UAT56=SIRIUS_500007460_MD34=74552=20260120-14:03:28.184262=MD_EUR/USD_140109278614268=3279=1269=1270=1.19824271=10000055=EUR/USD110=0279=1269=1270=1.19824271=50000055=EUR/USD110=100000279=1269=1270=1.19824271=100000055=EUR/USD110=50000010=233
20260120-14:03:28.659158000 : 8=FIX.4.49=039735=X49=NTPRO_IDBA_UAT56=SIRIUS_500007460_MD34=74652=20260120-14:03:28.609262=MD_GBP/USD_140109778778268=5279=1269=0270=1.25465271=10000055=GBP/USD110=0279=1269=0270=1.25465271=50000055=GBP/USD110=100000279=1269=0270=1.25465271=100000055=GBP/USD110=500000279=1269=0270=1.25465271=300000055=GBP/USD110=1000000279=1269=0270=1.25465271=500000055=GBP/USD110=300000010=054
20260120-14:03:28.754857000 : 8=FIX.4.49=044635=X49=NTPRO_IDBA_UAT56=SIRIUS_500007460_MD34=74752=20260120-14:03:28.707262=MD_EUR/USD_140109278614268=6279=1269=0270=1.14798271=10000055=EUR/USD110=0279=1269=0270=1.14798271=50000055=EUR/USD110=100000279=1269=0270=1.14798271=100000055=EUR/USD110=500000279=1269=1270=1.19823271=10000055=EUR/USD110=0279=1269=1270=1.19823271=50000055=EUR/USD110=100000279=1269=1270=1.19823271=100000055=EUR/USD110=50000010=035
20260120-14:03:28.835691000 : 8=FIX.4.49=027935=X49=NTPRO_IDBA_UAT56=SIRIUS_500007460_MD34=74852=20260120-14:03:28.776262=MD_EUR/USD_140109278614268=3279=1269=0270=1.14799271=10000055=EUR/USD110=0279=1269=0270=1.14799271=50000055=EUR/USD110=100000279=1269=0270=1.14799271=100000055=EUR/USD110=50000010=002
20260120-14:03:28.877598000 : 8=FIX.4.49=027935=X49=NTPRO_IDBA_UAT56=SIRIUS_500007460_MD34=74952=20260120-14:03:28.831262=MD_EUR/USD_140109278614268=3279=1269=1270=1.19824271=10000055=EUR/USD110=0279=1269=1270=1.19824271=50000055=EUR/USD110=100000279=1269=1270=1.19824271=100000055=EUR/USD110=50000010=236
20260120-14:03:29.056276000 : 8=FIX.4.49=039735=X49=NTPRO_IDBA_UAT56=SIRIUS_500007460_MD34=75052=20260120-14:03:29.020262=MD_GBP/USD_140109778778268=5279=1269=0270=1.25464271=10000055=GBP/USD110=0279=1269=0270=1.25464271=50000055=GBP/USD110=100000279=1269=0270=1.25464271=100000055=GBP/USD110=500000279=1269=0270=1.25464271=300000055=GBP/USD110=1000000279=1269=0270=1.25464271=500000055=GBP/USD110=300000010=032
20260120-14:03:29.286929000 : 8=FIX.4.49=039735=X49=NTPRO_IDBA_UAT56=SIRIUS_500007460_MD34=75152=20260120-14:03:29.259262=MD_GBP/USD_140109778778268=5279=1269=1270=1.43498271=10000055=GBP/USD110=0279=1269=1270=1.43498271=50000055=GBP/USD110=100000279=1269=1270=1.43498271=100000055=GBP/USD110=500000279=1269=1270=1.43498271=300000055=GBP/USD110=1000000279=1269=1270=1.43498271=500000055=GBP/USD110=300000010=087
20260120-14:03:29.331686000 : 8=FIX.4.49=044635=X49=NTPRO_IDBA_UAT56=SIRIUS_500007460_MD34=75252=20260120-14:03:29.301262=MD_EUR/USD_140109278614268=6279=1269=0270=1.14797271=10000055=EUR/USD110=0279=1269=0270=1.14797271=50000055=EUR/USD110=100000279=1269=0270=1.14797271=100000055=EUR/USD110=500000279=1269=1270=1.19822271=10000055=EUR/USD110=0279=1269=1270=1.19822271=50000055=EUR/USD110=100000279=1269=1270=1.19822271=100000055=EUR/USD110=50000010=016
20260120-14:03:29.332552000 : 8=FIX.4.49=068335=X49=NTPRO_IDBA_UAT56=SIRIUS_500007460_MD34=75352=20260120-14:03:29.306262=MD_GBP/USD_140109778778268=10279=1269=0270=1.25463271=10000055=GBP/USD110=0279=1269=0270=1.25463271=50000055=GBP/USD110=100000279=1269=0270=1.25463271=100000055=GBP/USD110=500000279=1269=0270=1.25463271=300000055=GBP/USD110=1000000279=1269=0270=1.25463271=500000055=GBP/USD110=3000000279=1269=1270=1.43497271=10000055=GBP/USD110=0279=1269=1270=1.43497271=50000055=GBP/USD110=100000279=1269=1270=1.43497271=100000055=GBP/USD110=500000279=1269=1270=1.43497271=300000055=GBP/USD110=1000000279=1269=1270=1.43497271=500000055=GBP/USD110=300000010=230
20260120-14:03:29.366624000 : 8=FIX.4.49=068335=X49=NTPRO_IDBA_UAT56=SIRIUS_500007460_MD34=75452=20260120-14:03:29.341262=MD_GBP/USD_140109778778268=10279=1269=0270=1.25461271=10000055=GBP/USD110=0279=1269=0270=1.25461271=50000055=GBP/USD110=100000279=1269=0270=1.25461271=100000055=GBP/USD110=500000279=1269=0270=1.25461271=300000055=GBP/USD110=1000000279=1269=0270=1.25461271=500000055=GBP/USD110=3000000279=1269=1270=1.43495271=10000055=GBP/USD110=0279=1269=1270=1.43495271=50000055=GBP/USD110=100000279=1269=1270=1.43495271=100000055=GBP/USD110=500000279=1269=1270=1.43495271=300000055=GBP/USD110=1000000279=1269=1270=1.43495271=500000055=GBP/USD110=300000010=210
20260120-14:03:29.432441000 : 8=FIX.4.49=067835=X49=NTPRO_IDBA_UAT56=SIRIUS_500007460_MD34=75552=20260120-14:03:29.408262=MD_GBP/USD_140109778778268=10279=1269=0270=1.2546271=10000055=GBP/USD110=0279=1269=0270=1.2546271=50000055=GBP/USD110=100000279=1269=0270=1.2546271=100000055=GBP/USD110=500000279=1269=0270=1.2546271=300000055=GBP/USD110=1000000279=1269=0270=1.2546271=500000055=GBP/USD110=3000000279=1269=1270=1.43494271=10000055=GBP/USD110=0279=1269=1270=1.43494271=50000055=GBP/USD110=100000279=1269=1270=1.43494271=100000055=GBP/USD110=500000279=1269=1270=1.43494271=300000055=GBP/USD110=1000000279=1269=1270=1.43494271=500000055=GBP/USD110=300000010=225
20260120-14:03:29.532086000 : 8=FIX.4.49=039735=X49=NTPRO_IDBA_UAT56=SIRIUS_500007460_MD34=75652=20260120-14:03:29.482262=MD_GBP/USD_140109778778268=5279=1269=1270=1.43495271=10000055=GBP/USD110=0279=1269=1270=1.43495271=50000055=GBP/USD110=100000279=1269=1270=1.43495271=100000055=GBP/USD110=500000279=1269=1270=1.43495271=300000055=GBP/USD110=1000000279=1269=1270=1.43495271=500000055=GBP/USD110=300000010=075
20260120-14:03:29.532691000 : 8=FIX.4.49=044635=X49=NTPRO_IDBA_UAT56=SIRIUS_500007460_MD34=75752=20260120-14:03:29.483262=MD_EUR/USD_140109278614268=6279=1269=0270=1.14796271=10000055=EUR/USD110=0279=1269=0270=1.14796271=50000055=EUR/USD110=100000279=1269=0270=1.14796271=100000055=EUR/USD110=500000279=1269=1270=1.19821271=10000055=EUR/USD110=0279=1269=1270=1.19821271=50000055=EUR/USD110=100000279=1269=1270=1.19821271=100000055=EUR/USD110=50000010=026
20260120-14:03:29.588540000 : 8=FIX.4.49=068335=X49=NTPRO_IDBA_UAT56=SIRIUS_500007460_MD34=75852=20260120-14:03:29.572262=MD_GBP/USD_140109778778268=10279=1269=0270=1.25459271=10000055=GBP/USD110=0279=1269=0270=1.25459271=50000055=GBP/USD110=100000279=1269=0270=1.25459271=100000055=GBP/USD110=500000279=1269=0270=1.25459271=300000055=GBP/USD110=1000000279=1269=0270=1.25459271=500000055=GBP/USD110=3000000279=1269=1270=1.43493271=10000055=GBP/USD110=0279=1269=1270=1.43493271=50000055=GBP/USD110=100000279=1269=1270=1.43493271=100000055=GBP/USD110=500000279=1269=1270=1.43493271=300000055=GBP/USD110=1000000279=1269=1270=1.43493271=500000055=GBP/USD110=300000010=245
20260120-14:03:30.036048000 : 8=FIX.4.49=027635=X49=NTPRO_IDBA_UAT56=SIRIUS_500007460_MD34=75952=20260120-14:03:30.035262=MD_EUR/USD_140109278614268=3279=1269=1270=1.1982271=10000055=EUR/USD110=0279=1269=1270=1.1982271=50000055=EUR/USD110=100000279=1269=1270=1.1982271=100000055=EUR/USD110=50000010=067
20260120-14:03:30.055699000 : 8=FIX.4.49=027935=X49=NTPRO_IDBA_UAT56=SIRIUS_500007460_MD34=76052=20260120-14:03:30.055262=MD_EUR/USD_140109278614268=3279=1269=0270=1.14794271=10000055=EUR/USD110=0279=1269=0270=1.14794271=50000055=EUR/USD110=100000279=1269=0270=1.14794271=100000055=EUR/USD110=50000010=220
20260120-14:03:30.115269000 : 8=FIX.4.49=039735=X49=NTPRO_IDBA_UAT56=SIRIUS_500007460_MD34=76152=20260120-14:03:30.110262=MD_GBP/USD_140109778778268=5279=1269=1270=1.43494271=10000055=GBP/USD110=0279=1269=1270=1.43494271=50000055=GBP/USD110=100000279=1269=1270=1.43494271=100000055=GBP/USD110=500000279=1269=1270=1.43494271=300000055=GBP/USD110=1000000279=1269=1270=1.43494271=500000055=GBP/USD110=300000010=046
20260120-14:03:30.164781000 : 8=FIX.4.49=027935=X49=NTPRO_IDBA_UAT56=SIRIUS_500007460_MD34=76252=20260120-14:03:30.166262=MD_EUR/USD_140109278614268=3279=1269=1270=1.19819271=10000055=EUR/USD110=0279=1269=1270=1.19819271=50000055=EUR/USD110=100000279=1269=1270=1.19819271=100000055=EUR/USD110=50000010=237
20260120-14:03:30.172939000 : 8=FIX.4.49=039235=X49=NTPRO_IDBA_UAT56=SIRIUS_500007460_MD34=76352=20260120-14:03:30.176262=MD_GBP/USD_140109778778268=5279=1269=0270=1.2546271=10000055=GBP/USD110=0279=1269=0270=1.2546271=50000055=GBP/USD110=100000279=1269=0270=1.2546271=100000055=GBP/USD110=500000279=1269=0270=1.2546271=300000055=GBP/USD110=1000000279=1269=0270=1.2546271=500000055=GBP/USD110=300000010=031
20260120-14:03:30.276097000 : 8=FIX.4.49=027935=X49=NTPRO_IDBA_UAT56=SIRIUS_500007460_MD34=76452=20260120-14:03:30.284262=MD_EUR/USD_140109278614268=3279=1269=0270=1.14795271=10000055=EUR/USD110=0279=1269=0270=1.14795271=50000055=EUR/USD110=100000279=1269=0270=1.14795271=100000055=EUR/USD110=50000010=231
20260120-14:03:30.333748000 : 8=FIX.4.49=039735=X49=NTPRO_IDBA_UAT56=SIRIUS_500007460_MD34=76552=20260120-14:03:30.343262=MD_GBP/USD_140109778778268=5279=1269=0270=1.25459271=10000055=GBP/USD110=0279=1269=0270=1.25459271=50000055=GBP/USD110=100000279=1269=0270=1.25459271=100000055=GBP/USD110=500000279=1269=0270=1.25459271=300000055=GBP/USD110=1000000279=1269=0270=1.25459271=500000055=GBP/USD110=300000010=058
20260120-14:03:30.397805000 : 8=FIX.4.49=039235=X49=NTPRO_IDBA_UAT56=SIRIUS_500007460_MD34=76652=20260120-14:03:30.410262=MD_GBP/USD_140109778778268=5279=1269=0270=1.2546271=10000055=GBP/USD110=0279=1269=0270=1.2546271=50000055=GBP/USD110=100000279=1269=0270=1.2546271=100000055=GBP/USD110=500000279=1269=0270=1.2546271=300000055=GBP/USD110=1000000279=1269=0270=1.2546271=500000055=GBP/USD110=300000010=025
20260120-14:03:30.592284000 : 8=FIX.4.49=039735=X49=NTPRO_IDBA_UAT56=SIRIUS_500007460_MD34=76752=20260120-14:03:30.608262=MD_GBP/USD_140109778778268=5279=1269=0270=1.25459271=10000055=GBP/USD110=0279=1269=0270=1.25459271=50000055=GBP/USD110=100000279=1269=0270=1.25459271=100000055=GBP/USD110=500000279=1269=0270=1.25459271=300000055=GBP/USD110=1000000279=1269=0270=1.25459271=500000055=GBP/USD110=300000010=064
20260120-14:03:30.678023000 : 8=FIX.4.49=027935=X49=NTPRO_IDBA_UAT56=SIRIUS_500007460_MD34=76852=20260120-14:03:30.699262=MD_EUR/USD_140109278614268=3279=1269=0270=1.14793271=10000055=EUR/USD110=0279=1269=0270=1.14793271=50000055=EUR/USD110=100000279=1269=0270=1.14793271=100000055=EUR/USD110=50000010=239
20260120-14:03:30.748613000 : 8=FIX.4.49=044335=X49=NTPRO_IDBA_UAT56=SIRIUS_500007460_MD34=76952=20260120-14:03:30.773262=MD_EUR/USD_140109278614268=6279=1269=0270=1.14795271=10000055=EUR/USD110=0279=1269=0270=1.14795271=50000055=EUR/USD110=100000279=1269=0270=1.14795271=100000055=EUR/USD110=500000279=1269=1270=1.1982271=10000055=EUR/USD110=0279=1269=1270=1.1982271=50000055=EUR/USD110=100000279=1269=1270=1.1982271=100000055=EUR/USD110=50000010=126
20260120-14:03:30.810737000 : 8=FIX.4.49=007835=049=NTPRO_IDBA_UAT56=SIRIUS_500007460_MD34=77052=20260120-14:03:30.83610=224
20260120-14:03:30.824600000 : 8=FIX.4.49=044635=X49=NTPRO_IDBA_UAT56=SIRIUS_500007460_MD34=77152=20260120-14:03:30.852262=MD_EUR/USD_140109278614268=6279=1269=0270=1.14794271=10000055=EUR/USD110=0279=1269=0270=1.14794271=50000055=EUR/USD110=100000279=1269=0270=1.14794271=100000055=EUR/USD110=500000279=1269=1270=1.19819271=10000055=EUR/USD110=0279=1269=1270=1.19819271=50000055=EUR/USD110=100000279=1269=1270=1.19819271=100000055=EUR/USD110=50000010=029
20260120-14:03:30.853412000 : 8=FIX.4.49=039735=X49=NTPRO_IDBA_UAT56=SIRIUS_500007460_MD34=77252=20260120-14:03:30.882262=MD_GBP/USD_140109778778268=5279=1269=1270=1.43493271=10000055=GBP/USD110=0279=1269=1270=1.43493271=50000055=GBP/USD110=100000279=1269=1270=1.43493271=100000055=GBP/USD110=500000279=1269=1270=1.43493271=300000055=GBP/USD110=1000000279=1269=1270=1.43493271=500000055=GBP/USD110=300000010=059
20260120-14:03:30.914100000 : 8=FIX.4.49=067835=X49=NTPRO_IDBA_UAT56=SIRIUS_500007460_MD34=77352=20260120-14:03:30.944262=MD_GBP/USD_140109778778268=10279=1269=0270=1.2546271=10000055=GBP/USD110=0279=1269=0270=1.2546271=50000055=GBP/USD110=100000279=1269=0270=1.2546271=100000055=GBP/USD110=500000279=1269=0270=1.2546271=300000055=GBP/USD110=1000000279=1269=0270=1.2546271=500000055=GBP/USD110=3000000279=1269=1270=1.43494271=10000055=GBP/USD110=0279=1269=1270=1.43494271=50000055=GBP/USD110=100000279=1269=1270=1.43494271=100000055=GBP/USD110=500000279=1269=1270=1.43494271=300000055=GBP/USD110=1000000279=1269=1270=1.43494271=500000055=GBP/USD110=300000010=222
20260120-14:03:30.914812000 : 8=FIX.4.49=044335=X49=NTPRO_IDBA_UAT56=SIRIUS_500007460_MD34=77452=20260120-14:03:30.945262=MD_EUR/USD_140109278614268=6279=1269=0270=1.14795271=10000055=EUR/USD110=0279=1269=0270=1.14795271=50000055=EUR/USD110=100000279=1269=0270=1.14795271=100000055=EUR/USD110=500000279=1269=1270=1.1982271=10000055=EUR/USD110=0279=1269=1270=1.1982271=50000055=EUR/USD110=100000279=1269=1270=1.1982271=100000055=EUR/USD110=50000010=123
20260120-14:03:30.957761000 : 8=FIX.4.49=044635=X49=NTPRO_IDBA_UAT56=SIRIUS_500007460_MD34=77552=20260120-14:03:30.989262=MD_EUR/USD_140109278614268=6279=1269=0270=1.14793271=10000055=EUR/USD110=0279=1269=0270=1.14793271=50000055=EUR/USD110=100000279=1269=0270=1.14793271=100000055=EUR/USD110=500000279=1269=1270=1.19818271=10000055=EUR/USD110=0279=1269=1270=1.19818271=50000055=EUR/USD110=100000279=1269=1270=1.19818271=100000055=EUR/USD110=50000010=038
20260120-14:03:30.991348000 : 8=FIX.4.49=039735=X49=NTPRO_IDBA_UAT56=SIRIUS_500007460_MD34=77652=20260120-14:03:31.024262=MD_GBP/USD_140109778778268=5279=1269=1270=1.43495271=10000055=GBP/USD110=0279=1269=1270=1.43495271=50000055=GBP/USD110=100000279=1269=1270=1.43495271=100000055=GBP/USD110=500000279=1269=1270=1.43495271=300000055=GBP/USD110=1000000279=1269=1270=1.43495271=500000055=GBP/USD110=300000010=062
20260120-14:03:31.011916000 : 8=FIX.4.49=044335=X49=NTPRO_IDBA_UAT56=SIRIUS_500007460_MD34=77752=20260120-14:03:31.035262=MD_EUR/USD_140109278614268=6279=1269=0270=1.14796271=10000055=EUR/USD110=0279=1269=0270=1.14796271=50000055=EUR/USD110=100000279=1269=0270=1.14796271=100000055=EUR/USD110=500000279=1269=1270=1.1982271=10000055=EUR/USD110=0279=1269=1270=1.1982271=50000055=EUR/USD110=100000279=1269=1270=1.1982271=100000055=EUR/USD110=50000010=120
20260120-14:03:31.046707000 : 8=FIX.4.49=068335=X49=NTPRO_IDBA_UAT56=SIRIUS_500007460_MD34=77852=20260120-14:03:31.082262=MD_GBP/USD_140109778778268=10279=1269=0270=1.25465271=10000055=GBP/USD110=0279=1269=0270=1.25465271=50000055=GBP/USD110=100000279=1269=0270=1.25465271=100000055=GBP/USD110=500000279=1269=0270=1.25465271=300000055=GBP/USD110=1000000279=1269=0270=1.25465271=500000055=GBP/USD110=3000000279=1269=1270=1.43499271=10000055=GBP/USD110=0279=1269=1270=1.43499271=50000055=GBP/USD110=100000279=1269=1270=1.43499271=100000055=GBP/USD110=500000279=1269=1270=1.43499271=300000055=GBP/USD110=1000000279=1269=1270=1.43499271=500000055=GBP/USD110=300000010=251
20260120-14:03:31.115337000 : 8=FIX.4.49=044635=X49=NTPRO_IDBA_UAT56=SIRIUS_500007460_MD34=77952=20260120-14:03:31.151262=MD_EUR/USD_140109278614268=6279=1269=0270=1.14797271=10000055=EUR/USD110=0279=1269=0270=1.14797271=50000055=EUR/USD110=100000279=1269=0270=1.14797271=100000055=EUR/USD110=500000279=1269=1270=1.19821271=10000055=EUR/USD110=0279=1269=1270=1.19821271=50000055=EUR/USD110=100000279=1269=1270=1.19821271=100000055=EUR/USD110=50000010=018
20260120-14:03:31.142562000 : 8=FIX.4.49=039735=X49=NTPRO_IDBA_UAT56=SIRIUS_500007460_MD34=78052=20260120-14:03:31.181262=MD_GBP/USD_140109778778268=5279=1269=0270=1.25464271=10000055=GBP/USD110=0279=1269=0270=1.25464271=50000055=GBP/USD110=100000279=1269=0270=1.25464271=100000055=GBP/USD110=500000279=1269=0270=1.25464271=300000055=GBP/USD110=1000000279=1269=0270=1.25464271=500000055=GBP/USD110=300000010=036
20260120-14:03:31.237211000 : 8=FIX.4.49=044335=X49=NTPRO_IDBA_UAT56=SIRIUS_500007460_MD34=78152=20260120-14:03:31.278262=MD_EUR/USD_140109278614268=6279=1269=0270=1.14795271=10000055=EUR/USD110=0279=1269=0270=1.14795271=50000055=EUR/USD110=100000279=1269=0270=1.14795271=100000055=EUR/USD110=500000279=1269=1270=1.1982271=10000055=EUR/USD110=0279=1269=1270=1.1982271=50000055=EUR/USD110=100000279=1269=1270=1.1982271=100000055=EUR/USD110=50000010=121
20260120-14:03:31.308049000 : 8=FIX.4.49=039735=X49=NTPRO_IDBA_UAT56=SIRIUS_500007460_MD34=78252=20260120-14:03:31.350262=MD_GBP/USD_140109778778268=5279=1269=1270=1.43498271=10000055=GBP/USD110=0279=1269=1270=1.43498271=50000055=GBP/USD110=100000279=1269=1270=1.43498271=100000055=GBP/USD110=500000279=1269=1270=1.43498271=300000055=GBP/USD110=1000000279=1269=1270=1.43498271=500000055=GBP/USD110=300000010=076
20260120-14:03:31.422774000 : 8=FIX.4.49=044635=X49=NTPRO_IDBA_UAT56=SIRIUS_500007460_MD34=78352=20260120-14:03:31.469262=MD_EUR/USD_140109278614268=6279=1269=0270=1.14797271=10000055=EUR/USD110=0279=1269=0270=1.14797271=50000055=EUR/USD110=100000279=1269=0270=1.14797271=100000055=EUR/USD110=500000279=1269=1270=1.19822271=10000055=EUR/USD110=0279=1269=1270=1.19822271=50000055=EUR/USD110=100000279=1269=1270=1.19822271=100000055=EUR/USD110=50000010=028
20260120-14:03:31.537110000 : 8=FIX.4.49=044635=X49=NTPRO_IDBA_UAT56=SIRIUS_500007460_MD34=78452=20260120-14:03:31.588262=MD_EUR/USD_140109278614268=6279=1269=0270=1.14798271=10000055=EUR/USD110=0279=1269=0270=1.14798271=50000055=EUR/USD110=100000279=1269=0270=1.14798271=100000055=EUR/USD110=500000279=1269=1270=1.19823271=10000055=EUR/USD110=0279=1269=1270=1.19823271=50000055=EUR/USD110=100000279=1269=1270=1.19823271=100000055=EUR/USD110=50000010=037
20260120-14:03:31.573822000 : 8=FIX.4.49=068335=X49=NTPRO_IDBA_UAT56=SIRIUS_500007460_MD34=78552=20260120-14:03:31.627262=MD_GBP/USD_140109778778268=10279=2269=0270=1.25464271=10000055=GBP/USD110=0279=2269=0270=1.25464271=50000055=GBP/USD110=100000279=2269=0270=1.25464271=100000055=GBP/USD110=500000279=2269=0270=1.25464271=300000055=GBP/USD110=1000000279=2269=0270=1.25464271=500000055=GBP/USD110=3000000279=2269=1270=1.43498271=10000055=GBP/USD110=0279=2269=1270=1.43498271=50000055=GBP/USD110=100000279=2269=1270=1.43498271=100000055=GBP/USD110=500000279=2269=1270=1.43498271=300000055=GBP/USD110=1000000279=2269=1270=1.43498271=500000055=GBP/USD110=300000010=254
20260120-14:03:31.626307000 : 8=FIX.4.49=067835=X49=NTPRO_IDBA_UAT56=SIRIUS_500007460_MD34=78652=20260120-14:03:31.680262=MD_GBP/USD_140109778778268=10279=0269=0270=1.2546271=10000055=GBP/USD110=0279=0269=0270=1.2546271=50000055=GBP/USD110=100000279=0269=0270=1.2546271=100000055=GBP/USD110=500000279=0269=0270=1.2546271=300000055=GBP/USD110=1000000279=0269=0270=1.2546271=500000055=GBP/USD110=3000000279=0269=1270=1.43495271=10000055=GBP/USD110=0279=0269=1270=1.43495271=50000055=GBP/USD110=100000279=0269=1270=1.43495271=100000055=GBP/USD110=500000279=0269=1270=1.43495271=300000055=GBP/USD110=1000000279=0269=1270=1.43495271=500000055=GBP/USD110=300000010=219
20260120-14:03:31.660303000 : 8=FIX.4.49=039735=X49=NTPRO_IDBA_UAT56=SIRIUS_500007460_MD34=78752=20260120-14:03:31.717262=MD_GBP/USD_140109778778268=5279=1269=1270=1.43494271=10000055=GBP/USD110=0279=1269=1270=1.43494271=50000055=GBP/USD110=100000279=1269=1270=1.43494271=100000055=GBP/USD110=500000279=1269=1270=1.43494271=300000055=GBP/USD110=1000000279=1269=1270=1.43494271=500000055=GBP/USD110=300000010=068
20260120-14:03:31.704604000 : 8=FIX.4.49=039735=X49=NTPRO_IDBA_UAT56=SIRIUS_500007460_MD34=78852=20260120-14:03:31.754262=MD_GBP/USD_140109778778268=5279=1269=0270=1.25459271=10000055=GBP/USD110=0279=1269=0270=1.25459271=50000055=GBP/USD110=100000279=1269=0270=1.25459271=100000055=GBP/USD110=500000279=1269=0270=1.25459271=300000055=GBP/USD110=1000000279=1269=0270=1.25459271=500000055=GBP/USD110=300000010=070
20260120-14:03:31.706818000 : 8=FIX.4.49=044635=X49=NTPRO_IDBA_UAT56=SIRIUS_500007460_MD34=78952=20260120-14:03:31.765262=MD_EUR/USD_140109278614268=6279=1269=0270=1.14794271=10000055=EUR/USD110=0279=1269=0270=1.14794271=50000055=EUR/USD110=100000279=1269=0270=1.14794271=100000055=EUR/USD110=500000279=1269=1270=1.19819271=10000055=EUR/USD110=0279=1269=1270=1.19819271=50000055=EUR/USD110=100000279=1269=1270=1.19819271=100000055=EUR/USD110=50000010=042
20260120-14:03:31.747642000 : 8=FIX.4.49=039735=X49=NTPRO_IDBA_UAT56=SIRIUS_500007460_MD34=79052=20260120-14:03:31.807262=MD_GBP/USD_140109778778268=5279=1269=1270=1.43493271=10000055=GBP/USD110=0279=1269=1270=1.43493271=50000055=GBP/USD110=100000279=1269=1270=1.43493271=100000055=GBP/USD110=500000279=1269=1270=1.43493271=300000055=GBP/USD110=1000000279=1269=1270=1.43493271=500000055=GBP/USD110=300000010=057
20260120-14:03:31.807648000 : 8=FIX.4.49=039735=X49=NTPRO_IDBA_UAT56=SIRIUS_500007460_MD34=79152=20260120-14:03:31.869262=MD_GBP/USD_140109778778268=5279=1269=0270=1.25458271=10000055=GBP/USD110=0279=1269=0270=1.25458271=50000055=GBP/USD110=100000279=1269=0270=1.25458271=100000055=GBP/USD110=500000279=1269=0270=1.25458271=300000055=GBP/USD110=1000000279=1269=0270=1.25458271=500000055=GBP/USD110=300000010=066
20260120-14:03:31.901002000 : 8=FIX.4.49=027935=X49=NTPRO_IDBA_UAT56=SIRIUS_500007460_MD34=79252=20260120-14:03:31.966262=MD_EUR/USD_140109278614268=3279=1269=0270=1.14795271=10000055=EUR/USD110=0279=1269=0270=1.14795271=50000055=EUR/USD110=100000279=1269=0270=1.14795271=100000055=EUR/USD110=50000010=240
20260120-14:03:32.189727000 : 8=FIX.4.49=039735=X49=NTPRO_IDBA_UAT56=SIRIUS_500007460_MD34=79352=20260120-14:03:32.259262=MD_GBP/USD_140109778778268=5279=1269=0270=1.25459271=10000055=GBP/USD110=0279=1269=0270=1.25459271=50000055=GBP/USD110=100000279=1269=0270=1.25459271=100000055=GBP/USD110=500000279=1269=0270=1.25459271=300000055=GBP/USD110=1000000279=1269=0270=1.25459271=500000055=GBP/USD110=300000010=067
20260120-14:03:32.423558000 : 8=FIX.4.49=027635=X49=NTPRO_IDBA_UAT56=SIRIUS_500007460_MD34=79452=20260120-14:03:32.507262=MD_EUR/USD_140109278614268=3279=1269=1270=1.1982271=10000055=EUR/USD110=0279=1269=1270=1.1982271=50000055=EUR/USD110=100000279=1269=1270=1.1982271=100000055=EUR/USD110=50000010=072
20260120-14:03:32.693858000 : 8=FIX.4.49=039735=X49=NTPRO_IDBA_UAT56=SIRIUS_500007460_MD34=79552=20260120-14:03:32.787262=MD_GBP/USD_140109778778268=5279=1269=0270=1.25458271=10000055=GBP/USD110=0279=1269=0270=1.25458271=50000055=GBP/USD110=100000279=1269=0270=1.25458271=100000055=GBP/USD110=500000279=1269=0270=1.25458271=300000055=GBP/USD110=1000000279=1269=0270=1.25458271=500000055=GBP/USD110=300000010=070
20260120-14:03:32.928428000 : 8=FIX.4.49=027935=X49=NTPRO_IDBA_UAT56=SIRIUS_500007460_MD34=79652=20260120-14:03:33.030262=MD_EUR/USD_140109278614268=3279=1269=1270=1.19819271=10000055=EUR/USD110=0279=1269=1270=1.19819271=50000055=EUR/USD110=100000279=1269=1270=1.19819271=100000055=EUR/USD110=50000010=237
20260120-14:03:33.218770000 : 8=FIX.4.49=039735=X49=NTPRO_IDBA_UAT56=SIRIUS_500007460_MD34=79752=20260120-14:03:33.330262=MD_GBP/USD_140109778778268=5279=1269=1270=1.43494271=10000055=GBP/USD110=0279=1269=1270=1.43494271=50000055=GBP/USD110=100000279=1269=1270=1.43494271=100000055=GBP/USD110=500000279=1269=1270=1.43494271=300000055=GBP/USD110=1000000279=1269=1270=1.43494271=500000055=GBP/USD110=300000010=062
20260120-14:03:33.219207000 : 8=FIX.4.49=044635=X49=NTPRO_IDBA_UAT56=SIRIUS_500007460_MD34=79852=20260120-14:03:33.331262=MD_EUR/USD_140109278614268=6279=1269=0270=1.14796271=10000055=EUR/USD110=0279=1269=0270=1.14796271=50000055=EUR/USD110=100000279=1269=0270=1.14796271=100000055=EUR/USD110=500000279=1269=1270=1.19821271=10000055=EUR/USD110=0279=1269=1270=1.19821271=50000055=EUR/USD110=100000279=1269=1270=1.19821271=100000055=EUR/USD110=50000010=018
20260120-14:03:33.264124000 : 8=FIX.4.49=039235=X49=NTPRO_IDBA_UAT56=SIRIUS_500007460_MD34=79952=20260120-14:03:33.377262=MD_GBP/USD_140109778778268=5279=1269=0270=1.2546271=10000055=GBP/USD110=0279=1269=0270=1.2546271=50000055=GBP/USD110=100000279=1269=0270=1.2546271=100000055=GBP/USD110=500000279=1269=0270=1.2546271=300000055=GBP/USD110=1000000279=1269=0270=1.2546271=500000055=GBP/USD110=300000010=046
20260120-14:03:33.278267000 : 8=FIX.4.49=044635=X49=NTPRO_IDBA_UAT56=SIRIUS_500007460_MD34=80052=20260120-14:03:33.382262=MD_EUR/USD_140109278614268=6279=1269=0270=1.14797271=10000055=EUR/USD110=0279=1269=0270=1.14797271=50000055=EUR/USD110=100000279=1269=0270=1.14797271=100000055=EUR/USD110=500000279=1269=1270=1.19822271=10000055=EUR/USD110=0279=1269=1270=1.19822271=50000055=EUR/USD110=100000279=1269=1270=1.19822271=100000055=EUR/USD110=50000010=014
20260120-14:03:33.310474000 : 8=FIX.4.49=067835=X49=NTPRO_IDBA_UAT56=SIRIUS_500007460_MD34=80152=20260120-14:03:33.425262=MD_GBP/USD_140109778778268=10279=2269=0270=1.2546271=10000055=GBP/USD110=0279=2269=0270=1.2546271=50000055=GBP/USD110=100000279=2269=0270=1.2546271=100000055=GBP/USD110=500000279=2269=0270=1.2546271=300000055=GBP/USD110=1000000279=2269=0270=1.2546271=500000055=GBP/USD110=3000000279=2269=1270=1.43494271=10000055=GBP/USD110=0279=2269=1270=1.43494271=50000055=GBP/USD110=100000279=2269=1270=1.43494271=100000055=GBP/USD110=500000279=2269=1270=1.43494271=300000055=GBP/USD110=1000000279=2269=1270=1.43494271=500000055=GBP/USD110=300000010=221
20260120-14:03:33.362111000 : 8=FIX.4.49=027935=X49=NTPRO_IDBA_UAT56=SIRIUS_500007460_MD34=80252=20260120-14:03:33.473262=MD_EUR/USD_140109278614268=3279=1269=1270=1.19823271=10000055=EUR/USD110=0279=1269=1270=1.19823271=50000055=EUR/USD110=100000279=1269=1270=1.19823271=100000055=EUR/USD110=50000010=221
20260120-14:03:33.402536000 : 8=FIX.4.49=068335=X49=NTPRO_IDBA_UAT56=SIRIUS_500007460_MD34=80352=20260120-14:03:33.521262=MD_GBP/USD_140109778778268=10279=0269=0270=1.25462271=10000055=GBP/USD110=0279=0269=0270=1.25462271=50000055=GBP/USD110=100000279=0269=0270=1.25462271=100000055=GBP/USD110=500000279=0269=0270=1.25462271=300000055=GBP/USD110=1000000279=0269=0270=1.25462271=500000055=GBP/USD110=3000000279=0269=1270=1.43498271=10000055=GBP/USD110=0279=0269=1270=1.43498271=50000055=GBP/USD110=100000279=0269=1270=1.43498271=100000055=GBP/USD110=500000279=0269=1270=1.43498271=300000055=GBP/USD110=1000000279=0269=1270=1.43498271=500000055=GBP/USD110=300000010=210
20260120-14:03:33.425273000 : 8=FIX.4.49=044635=X49=NTPRO_IDBA_UAT56=SIRIUS_500007460_MD34=80452=20260120-14:03:33.544262=MD_EUR/USD_140109278614268=6279=1269=0270=1.14799271=10000055=EUR/USD110=0279=1269=0270=1.14799271=50000055=EUR/USD110=100000279=1269=0270=1.14799271=100000055=EUR/USD110=500000279=1269=1270=1.19824271=10000055=EUR/USD110=0279=1269=1270=1.19824271=50000055=EUR/USD110=100000279=1269=1270=1.19824271=100000055=EUR/USD110=50000010=030
20260120-14:03:33.452964000 : 8=FIX.4.49=039735=X49=NTPRO_IDBA_UAT56=SIRIUS_500007460_MD34=80552=20260120-14:03:33.573262=MD_GBP/USD_140109778778268=5279=1269=0270=1.25463271=10000055=GBP/USD110=0279=1269=0270=1.25463271=50000055=GBP/USD110=100000279=1269=0270=1.25463271=100000055=GBP/USD110=500000279=1269=0270=1.25463271=300000055=GBP/USD110=1000000279=1269=0270=1.25463271=500000055=GBP/USD110=300000010=036
20260120-14:03:33.484979000 : 8=FIX.4.49=027935=X49=NTPRO_IDBA_UAT56=SIRIUS_500007460_MD34=80652=20260120-14:03:33.592262=MD_EUR/USD_140109278614268=3279=1269=1270=1.19823271=10000055=EUR/USD110=0279=1269=1270=1.19823271=50000055=EUR/USD110=100000279=1269=1270=1.19823271=100000055=EUR/USD110=50000010=227
20260120-14:03:33.561187000 : 8=FIX.4.49=027935=X49=NTPRO_IDBA_UAT56=SIRIUS_500007460_MD34=80752=20260120-14:03:33.685262=MD_EUR/USD_140109278614268=3279=1269=0270=1.14797271=10000055=EUR/USD110=0279=1269=0270=1.14797271=50000055=EUR/USD110=100000279=1269=0270=1.14797271=100000055=EUR/USD110=50000010=243
20260120-14:03:33.582508000 : 8=FIX.4.49=068335=X49=NTPRO_IDBA_UAT56=SIRIUS_500007460_MD34=80852=20260120-14:03:33.695262=MD_GBP/USD_140109778778268=10279=2269=0270=1.25463271=10000055=GBP/USD110=0279=2269=0270=1.25463271=50000055=GBP/USD110=100000279=2269=0270=1.25463271=100000055=GBP/USD110=500000279=2269=0270=1.25463271=300000055=GBP/USD110=1000000279=2269=0270=1.25463271=500000055=GBP/USD110=3000000279=2269=1270=1.43498271=10000055=GBP/USD110=0279=2269=1270=1.43498271=50000055=GBP/USD110=100000279=2269=1270=1.43498271=100000055=GBP/USD110=500000279=2269=1270=1.43498271=300000055=GBP/USD110=1000000279=2269=1270=1.43498271=500000055=GBP/USD110=300000010=252
20260120-14:03:33.662239000 : 8=FIX.4.49=027935=X49=NTPRO_IDBA_UAT56=SIRIUS_500007460_MD34=80952=20260120-14:03:33.786262=MD_EUR/USD_140109278614268=3279=1269=0270=1.14799271=10000055=EUR/USD110=0279=1269=0270=1.14799271=50000055=EUR/USD110=100000279=1269=0270=1.14799271=100000055=EUR/USD110=50000010=253
20260120-14:03:34.045756000 : 8=FIX.4.49=044635=X49=NTPRO_IDBA_UAT56=SIRIUS_500007460_MD34=81052=20260120-14:03:34.182262=MD_EUR/USD_140109278614268=6279=1269=0270=1.14797271=10000055=EUR/USD110=0279=1269=0270=1.14797271=50000055=EUR/USD110=100000279=1269=0270=1.14797271=100000055=EUR/USD110=500000279=1269=1270=1.19822271=10000055=EUR/USD110=0279=1269=1270=1.19822271=50000055=EUR/USD110=100000279=1269=1270=1.19822271=100000055=EUR/USD110=50000010=014
20260120-14:03:34.129547000 : 8=FIX.4.49=044635=X49=NTPRO_IDBA_UAT56=SIRIUS_500007460_MD34=81152=20260120-14:03:34.248262=MD_EUR/USD_140109278614268=6279=1269=0270=1.14794271=10000055=EUR/USD110=0279=1269=0270=1.14794271=50000055=EUR/USD110=100000279=1269=0270=1.14794271=100000055=EUR/USD110=500000279=1269=1270=1.19819271=10000055=EUR/USD110=0279=1269=1270=1.19819271=50000055=EUR/USD110=100000279=1269=1270=1.19819271=100000055=EUR/USD110=50000010=027
20260120-14:03:34.221361000 : 8=FIX.4.49=027635=X49=NTPRO_IDBA_UAT56=SIRIUS_500007460_MD34=81252=20260120-14:03:34.366262=MD_EUR/USD_140109278614268=3279=1269=1270=1.1982271=10000055=EUR/USD110=0279=1269=1270=1.1982271=50000055=EUR/USD110=100000279=1269=1270=1.1982271=100000055=EUR/USD110=50000010=068
20260120-14:03:34.307204000 : 8=FIX.4.49=044635=X49=NTPRO_IDBA_UAT56=SIRIUS_500007460_MD34=81352=20260120-14:03:34.456262=MD_EUR/USD_140109278614268=6279=1269=0270=1.14793271=10000055=EUR/USD110=0279=1269=0270=1.14793271=50000055=EUR/USD110=100000279=1269=0270=1.14793271=100000055=EUR/USD110=500000279=1269=1270=1.19819271=10000055=EUR/USD110=0279=1269=1270=1.19819271=50000055=EUR/USD110=100000279=1269=1270=1.19819271=100000055=EUR/USD110=50000010=027
20260120-14:03:34.341367000 : 8=FIX.4.49=068335=X49=NTPRO_IDBA_UAT56=SIRIUS_500007460_MD34=81452=20260120-14:03:34.492262=MD_GBP/USD_140109778778268=10279=0269=0270=1.25459271=10000055=GBP/USD110=0279=0269=0270=1.25459271=50000055=GBP/USD110=100000279=0269=0270=1.25459271=100000055=GBP/USD110=500000279=0269=0270=1.25459271=300000055=GBP/USD110=1000000279=0269=0270=1.25459271=500000055=GBP/USD110=3000000279=0269=1270=1.43494271=10000055=GBP/USD110=0279=0269=1270=1.43494271=50000055=GBP/USD110=100000279=0269=1270=1.43494271=100000055=GBP/USD110=500000279=0269=1270=1.43494271=300000055=GBP/USD110=1000000279=0269=1270=1.43494271=500000055=GBP/USD110=300000010=230
20260120-14:03:34.353820000 : 8=FIX.4.49=027935=X49=NTPRO_IDBA_UAT56=SIRIUS_500007460_MD34=81552=20260120-14:03:34.506262=MD_EUR/USD_140109278614268=3279=1269=0270=1.14794271=10000055=EUR/USD110=0279=1269=0270=1.14794271=50000055=EUR/USD110=100000279=1269=0270=1.14794271=100000055=EUR/USD110=50000010=226
20260120-14:03:34.478093000 : 8=FIX.4.49=068335=X49=NTPRO_IDBA_UAT56=SIRIUS_500007460_MD34=81652=20260120-14:03:34.626262=MD_GBP/USD_140109778778268=10279=1269=0270=1.25458271=10000055=GBP/USD110=0279=1269=0270=1.25458271=50000055=GBP/USD110=100000279=1269=0270=1.25458271=100000055=GBP/USD110=500000279=1269=0270=1.25458271=300000055=GBP/USD110=1000000279=1269=0270=1.25458271=500000055=GBP/USD110=3000000279=1269=1270=1.43493271=10000055=GBP/USD110=0279=1269=1270=1.43493271=50000055=GBP/USD110=100000279=1269=1270=1.43493271=100000055=GBP/USD110=500000279=1269=1270=1.43493271=300000055=GBP/USD110=1000000279=1269=1270=1.43493271=500000055=GBP/USD110=300000010=231
20260120-14:03:34.497494000 : 8=FIX.4.49=068335=X49=NTPRO_IDBA_UAT56=SIRIUS_500007460_MD34=81752=20260120-14:03:34.655262=MD_GBP/USD_140109778778268=10279=2269=0270=1.25458271=10000055=GBP/USD110=0279=2269=0270=1.25458271=50000055=GBP/USD110=100000279=2269=0270=1.25458271=100000055=GBP/USD110=500000279=2269=0270=1.25458271=300000055=GBP/USD110=1000000279=2269=0270=1.25458271=500000055=GBP/USD110=3000000279=2269=1270=1.43493271=10000055=GBP/USD110=0279=2269=1270=1.43493271=50000055=GBP/USD110=100000279=2269=1270=1.43493271=100000055=GBP/USD110=500000279=2269=1270=1.43493271=300000055=GBP/USD110=1000000279=2269=1270=1.43493271=500000055=GBP/USD110=300000010=244
20260120-14:03:34.538185000 : 8=FIX.4.49=068335=X49=NTPRO_IDBA_UAT56=SIRIUS_500007460_MD34=81852=20260120-14:03:34.693262=MD_GBP/USD_140109778778268=10279=0269=0270=1.25462271=10000055=GBP/USD110=0279=0269=0270=1.25462271=50000055=GBP/USD110=100000279=0269=0270=1.25462271=100000055=GBP/USD110=500000279=0269=0270=1.25462271=300000055=GBP/USD110=1000000279=0269=0270=1.25462271=500000055=GBP/USD110=3000000279=0269=1270=1.43498271=10000055=GBP/USD110=0279=0269=1270=1.43498271=50000055=GBP/USD110=100000279=0269=1270=1.43498271=100000055=GBP/USD110=500000279=0269=1270=1.43498271=300000055=GBP/USD110=1000000279=0269=1270=1.43498271=500000055=GBP/USD110=300000010=227
20260120-14:03:34.547530000 : 8=FIX.4.49=044335=X49=NTPRO_IDBA_UAT56=SIRIUS_500007460_MD34=81952=20260120-14:03:34.705262=MD_EUR/USD_140109278614268=6279=1269=0270=1.14796271=10000055=EUR/USD110=0279=1269=0270=1.14796271=50000055=EUR/USD110=100000279=1269=0270=1.14796271=100000055=EUR/USD110=500000279=1269=1270=1.1982271=10000055=EUR/USD110=0279=1269=1270=1.1982271=50000055=EUR/USD110=100000279=1269=1270=1.1982271=100000055=EUR/USD110=50000010=124
20260120-14:03:34.575227000 : 8=FIX.4.49=039735=X49=NTPRO_IDBA_UAT56=SIRIUS_500007460_MD34=82052=20260120-14:03:34.729262=MD_GBP/USD_140109778778268=5279=1269=1270=1.43499271=10000055=GBP/USD110=0279=1269=1270=1.43499271=50000055=GBP/USD110=100000279=1269=1270=1.43499271=100000055=GBP/USD110=500000279=1269=1270=1.43499271=300000055=GBP/USD110=1000000279=1269=1270=1.43499271=500000055=GBP/USD110=300000010=087
20260120-14:03:34.612107000 : 8=FIX.4.49=039735=X49=NTPRO_IDBA_UAT56=SIRIUS_500007460_MD34=82152=20260120-14:03:34.773262=MD_GBP/USD_140109778778268=5279=1269=0270=1.25464271=10000055=GBP/USD110=0279=1269=0270=1.25464271=50000055=GBP/USD110=100000279=1269=0270=1.25464271=100000055=GBP/USD110=500000279=1269=0270=1.25464271=300000055=GBP/USD110=1000000279=1269=0270=1.25464271=500000055=GBP/USD110=300000010=042
20260120-14:03:34.692473000 : 8=FIX.4.49=027935=X49=NTPRO_IDBA_UAT56=SIRIUS_500007460_MD34=82252=20260120-14:03:34.852262=MD_EUR/USD_140109278614268=3279=1269=1270=1.19821271=10000055=EUR/USD110=0279=1269=1270=1.19821271=50000055=EUR/USD110=100000279=1269=1270=1.19821271=100000055=EUR/USD110=50000010=219
20260120-14:03:34.727885000 : 8=FIX.4.49=044635=X49=NTPRO_IDBA_UAT56=SIRIUS_500007460_MD34=82352=20260120-14:03:34.893262=MD_EUR/USD_140109278614268=6279=1269=0270=1.14797271=10000055=EUR/USD110=0279=1269=0270=1.14797271=50000055=EUR/USD110=100000279=1269=0270=1.14797271=100000055=EUR/USD110=500000279=1269=1270=1.19823271=10000055=EUR/USD110=0279=1269=1270=1.19823271=50000055=EUR/USD110=100000279=1269=1270=1.19823271=100000055=EUR/USD110=50000010=030
20260120-14:03:34.891142000 : 8=FIX.4.49=044635=X49=NTPRO_IDBA_UAT56=SIRIUS_500007460_MD34=82452=20260120-14:03:35.059262=MD_EUR/USD_140109278614268=6279=1269=0270=1.14799271=10000055=EUR/USD110=0279=1269=0270=1.14799271=50000055=EUR/USD110=100000279=1269=0270=1.14799271=100000055=EUR/USD110=500000279=1269=1270=1.19824271=10000055=EUR/USD110=0279=1269=1270=1.19824271=50000055=EUR/USD110=100000279=1269=1270=1.19824271=100000055=EUR/USD110=50000010=035
20260120-14:03:35.071755000 : 8=FIX.4.49=027935=X49=NTPRO_IDBA_UAT56=SIRIUS_500007460_MD34=82552=20260120-14:03:35.249262=MD_EUR/USD_140109278614268=3279=1269=1270=1.19823271=10000055=EUR/USD110=0279=1269=1270=1.19823271=50000055=EUR/USD110=100000279=1269=1270=1.19823271=100000055=EUR/USD110=50000010=229
20260120-14:03:35.169361000 : 8=FIX.4.49=044035=X49=NTPRO_IDBA_UAT56=SIRIUS_500007460_MD34=82652=20260120-14:03:35.345262=MD_EUR/USD_140109278614268=6279=1269=0270=1.148271=10000055=EUR/USD110=0279=1269=0270=1.148271=50000055=EUR/USD110=100000279=1269=0270=1.148271=100000055=EUR/USD110=500000279=1269=1270=1.19824271=10000055=EUR/USD110=0279=1269=1270=1.19824271=50000055=EUR/USD110=100000279=1269=1270=1.19824271=100000055=EUR/USD110=50000010=202
20260120-14:03:35.173646000 : 8=FIX.4.49=038735=X49=NTPRO_IDBA_UAT56=SIRIUS_500007460_MD34=82752=20260120-14:03:35.354262=MD_GBP/USD_140109778778268=5279=1269=1270=1.435271=10000055=GBP/USD110=0279=1269=1270=1.435271=50000055=GBP/USD110=100000279=1269=1270=1.435271=100000055=GBP/USD110=500000279=1269=1270=1.435271=300000055=GBP/USD110=1000000279=1269=1270=1.435271=500000055=GBP/USD110=300000010=035
20260120-14:03:35.274304000 : 8=FIX.4.49=044635=X49=NTPRO_IDBA_UAT56=SIRIUS_500007460_MD34=82852=20260120-14:03:35.431262=MD_EUR/USD_140109278614268=6279=1269=0270=1.14798271=10000055=EUR/USD110=0279=1269=0270=1.14798271=50000055=EUR/USD110=100000279=1269=0270=1.14798271=100000055=EUR/USD110=500000279=1269=1270=1.19823271=10000055=EUR/USD110=0279=1269=1270=1.19823271=50000055=EUR/USD110=100000279=1269=1270=1.19823271=100000055=EUR/USD110=50000010=027
20260120-14:03:35.279354000 : 8=FIX.4.49=044635=X49=NTPRO_IDBA_UAT56=SIRIUS_500007460_MD34=82952=20260120-14:03:35.465262=MD_EUR/USD_140109278614268=6279=1269=0270=1.14799271=10000055=EUR/USD110=0279=1269=0270=1.14799271=50000055=EUR/USD110=100000279=1269=0270=1.14799271=100000055=EUR/USD110=500000279=1269=1270=1.19824271=10000055=EUR/USD110=0279=1269=1270=1.19824271=50000055=EUR/USD110=100000279=1269=1270=1.19824271=100000055=EUR/USD110=50000010=041
20260120-14:03:35.363405000 : 8=FIX.4.49=067335=X49=NTPRO_IDBA_UAT56=SIRIUS_500007460_MD34=83052=20260120-14:03:35.544262=MD_GBP/USD_140109778778268=10279=2269=0270=1.25464271=10000055=GBP/USD110=0279=2269=0270=1.25464271=50000055=GBP/USD110=100000279=2269=0270=1.25464271=100000055=GBP/USD110=500000279=2269=0270=1.25464271=300000055=GBP/USD110=1000000279=2269=0270=1.25464271=500000055=GBP/USD110=3000000279=2269=1270=1.435271=10000055=GBP/USD110=0279=2269=1270=1.435271=50000055=GBP/USD110=100000279=2269=1270=1.435271=100000055=GBP/USD110=500000279=2269=1270=1.435271=300000055=GBP/USD110=1000000279=2269=1270=1.435271=500000055=GBP/USD110=300000010=198
