20260120-14:03:35.365891000 : 8=FIX.4.49=027935=X49=NTPRO_IDBA_UAT56=SIRIUS_500007460_MD34=83152=20260120-14:03:35.553262=MD_EUR/USD_140109278614268=3279=1269=1270=1.19823271=10000055=EUR/USD110=0279=1269=1270=1.19823271=50000055=EUR/USD110=100000279=1269=1270=1.19823271=100000055=EUR/USD110=50000010=224
20260120-14:03:35.388864000 : 8=FIX.4.49=027935=X49=NTPRO_IDBA_UAT56=SIRIUS_500007460_MD34=83252=20260120-14:03:35.578262=MD_EUR/USD_140109278614268=3279=1269=0270=1.14798271=10000055=EUR/USD110=0279=1269=0270=1.14798271=50000055=EUR/USD110=100000279=1269=0270=1.14798271=100000055=EUR/USD110=50000010=247
20260120-14:03:35.428336000 : 8=FIX.4.49=044635=X49=NTPRO_IDBA_UAT56=SIRIUS_500007460_MD34=83352=20260120-14:03:35.619262=MD_EUR/USD_140109278614268=6279=1269=0270=1.14799271=10000055=EUR/USD110=0279=1269=0270=1.14799271=50000055=EUR/USD110=100000279=1269=0270=1.14799271=100000055=EUR/USD110=500000279=1269=1270=1.19824271=10000055=EUR/USD110=0279=1269=1270=1.19824271=50000055=EUR/USD110=100000279=1269=1270=1.19824271=100000055=EUR/USD110=50000010=037
20260120-14:03:35.477185000 : 8=FIX.4.49=044035=X49=NTPRO_IDBA_UAT56=SIRIUS_500007460_MD34=83452=20260120-14:03:35.669262=MD_EUR/USD_140109278614268=6279=1269=0270=1.148271=10000055=EUR/USD110=0279=1269=0270=1.148271=50000055=EUR/USD110=100000279=1269=0270=1.148271=100000055=EUR/USD110=500000279=1269=1270=1.19825271=10000055=EUR/USD110=0279=1269=1270=1.19825271=50000055=EUR/USD110=100000279=1269=1270=1.19825271=100000055=EUR/USD110=50000010=213
20260120-14:03:35.661195000 : 8=FIX.4.49=044635=X49=NTPRO_IDBA_UAT56=SIRIUS_500007460_MD34=83552=20260120-14:03:35.844262=MD_EUR/USD_140109278614268=6279=1269=0270=1.14799271=10000055=EUR/USD110=0279=1269=0270=1.14799271=50000055=EUR/USD110=100000279=1269=0270=1.14799271=100000055=EUR/USD110=500000279=1269=1270=1.19824271=10000055=EUR/USD110=0279=1269=1270=1.19824271=50000055=EUR/USD110=100000279=1269=1270=1.19824271=100000055=EUR/USD110=50000010=039
20260120-14:03:35.934765000 : 8=FIX.4.49=067335=X49=NTPRO_IDBA_UAT56=SIRIUS_500007460_MD34=83652=20260120-14:03:36.143262=MD_GBP/USD_140109778778268=10279=0269=0270=1.25465271=10000055=GBP/USD110=0279=0269=0270=1.25465271=50000055=GBP/USD110=100000279=0269=0270=1.25465271=100000055=GBP/USD110=500000279=0269=0270=1.25465271=300000055=GBP/USD110=1000000279=0269=0270=1.25465271=500000055=GBP/USD110=3000000279=0269=1270=1.435271=10000055=GBP/USD110=0279=0269=1270=1.435271=50000055=GBP/USD110=100000279=0269=1270=1.435271=100000055=GBP/USD110=500000279=0269=1270=1.435271=300000055=GBP/USD110=1000000279=0269=1270=1.435271=500000055=GBP/USD110=300000010=185
20260120-14:03:35.955170000 : 8=FIX.4.49=027335=X49=NTPRO_IDBA_UAT56=SIRIUS_500007460_MD34=83752=20260120-14:03:36.147262=MD_EUR/USD_140109278614268=3279=1269=0270=1.148271=10000055=EUR/USD110=0279=1269=0270=1.148271=50000055=EUR/USD110=100000279=1269=0270=1.148271=100000055=EUR/USD110=50000010=159
20260120-14:03:36.054503000 : 8=FIX.4.49=027935=X49=NTPRO_IDBA_UAT56=SIRIUS_500007460_MD34=83852=20260120-14:03:36.268262=MD_EUR/USD_140109278614268=3279=1269=0270=1.14799271=10000055=EUR/USD110=0279=1269=0270=1.14799271=50000055=EUR/USD110=100000279=1269=0270=1.14799271=100000055=EUR/USD110=50000010=253
20260120-14:03:36.073073000 : 8=FIX.4.49=068335=X49=NTPRO_IDBA_UAT56=SIRIUS_500007460_MD34=83952=20260120-14:03:36.286262=MD_GBP/USD_140109778778268=10279=1269=0270=1.25463271=10000055=GBP/USD110=0279=1269=0270=1.25463271=50000055=GBP/USD110=100000279=1269=0270=1.25463271=100000055=GBP/USD110=500000279=1269=0270=1.25463271=300000055=GBP/USD110=1000000279=1269=0270=1.25463271=500000055=GBP/USD110=3000000279=1269=1270=1.43499271=10000055=GBP/USD110=0279=1269=1270=1.43499271=50000055=GBP/USD110=100000279=1269=1270=1.43499271=100000055=GBP/USD110=500000279=1269=1270=1.43499271=300000055=GBP/USD110=1000000279=1269=1270=1.43499271=500000055=GBP/USD110=300000010=250
20260120-14:03:36.112008000 : 8=FIX.4.49=044635=X49=NTPRO_IDBA_UAT56=SIRIUS_500007460_MD34=84052=20260120-14:03:36.327262=MD_EUR/USD_140109278614268=6279=1269=0270=1.14796271=10000055=EUR/USD110=0279=1269=0270=1.14796271=50000055=EUR/USD110=100000279=1269=0270=1.14796271=100000055=EUR/USD110=500000279=1269=1270=1.19821271=10000055=EUR/USD110=0279=1269=1270=1.19821271=50000055=EUR/USD110=100000279=1269=1270=1.19821271=100000055=EUR/USD110=50000010=014
20260120-14:03:36.116013000 : 8=FIX.4.49=068335=X49=NTPRO_IDBA_UAT56=SIRIUS_500007460_MD34=84152=20260120-14:03:36.330262=MD_GBP/USD_140109778778268=10279=2269=0270=1.25463271=10000055=GBP/USD110=0279=2269=0270=1.25463271=50000055=GBP/USD110=100000279=2269=0270=1.25463271=100000055=GBP/USD110=500000279=2269=0270=1.25463271=300000055=GBP/USD110=1000000279=2269=0270=1.25463271=500000055=GBP/USD110=3000000279=2269=1270=1.43499271=10000055=GBP/USD110=0279=2269=1270=1.43499271=50000055=GBP/USD110=100000279=2269=1270=1.43499271=100000055=GBP/USD110=500000279=2269=1270=1.43499271=300000055=GBP/USD110=1000000279=2269=1270=1.43499271=500000055=GBP/USD110=300000010=243
20260120-14:03:36.165486000 : 8=FIX.4.49=068335=X49=NTPRO_IDBA_UAT56=SIRIUS_500007460_MD34=84252=20260120-14:03:36.382262=MD_GBP/USD_140109778778268=10279=0269=0270=1.25459271=10000055=GBP/USD110=0279=0269=0270=1.25459271=50000055=GBP/USD110=100000279=0269=0270=1.25459271=100000055=GBP/USD110=500000279=0269=0270=1.25459271=300000055=GBP/USD110=1000000279=0269=0270=1.25459271=500000055=GBP/USD110=3000000279=0269=1270=1.43494271=10000055=GBP/USD110=0279=0269=1270=1.43494271=50000055=GBP/USD110=100000279=0269=1270=1.43494271=100000055=GBP/USD110=500000279=0269=1270=1.43494271=300000055=GBP/USD110=1000000279=0269=1270=1.43494271=500000055=GBP/USD110=300000010=231
20260120-14:03:36.190788000 : 8=FIX.4.49=044635=X49=NTPRO_IDBA_UAT56=SIRIUS_500007460_MD34=84352=20260120-14:03:36.408262=MD_EUR/USD_140109278614268=6279=1269=0270=1.14794271=10000055=EUR/USD110=0279=1269=0270=1.14794271=50000055=EUR/USD110=100000279=1269=0270=1.14794271=100000055=EUR/USD110=500000279=1269=1270=1.19818271=10000055=EUR/USD110=0279=1269=1270=1.19818271=50000055=EUR/USD110=100000279=1269=1270=1.19818271=100000055=EUR/USD110=50000010=029
20260120-14:03:36.273869000 : 8=FIX.4.49=027935=X49=NTPRO_IDBA_UAT56=SIRIUS_500007460_MD34=84452=20260120-14:03:36.494262=MD_EUR/USD_140109278614268=3279=1269=1270=1.19819271=10000055=EUR/USD110=0279=1269=1270=1.19819271=50000055=EUR/USD110=100000279=1269=1270=1.19819271=100000055=EUR/USD110=50000010=248
20260120-14:03:36.295837000 : 8=FIX.4.49=039735=X49=NTPRO_IDBA_UAT56=SIRIUS_500007460_MD34=84552=20260120-14:03:36.518262=MD_GBP/USD_140109778778268=5279=1269=1270=1.43495271=10000055=GBP/USD110=0279=1269=1270=1.43495271=50000055=GBP/USD110=100000279=1269=1270=1.43495271=100000055=GBP/USD110=500000279=1269=1270=1.43495271=300000055=GBP/USD110=1000000279=1269=1270=1.43495271=500000055=GBP/USD110=300000010=072
20260120-14:03:36.315575000 : 8=FIX.4.49=027935=X49=NTPRO_IDBA_UAT56=SIRIUS_500007460_MD34=84652=20260120-14:03:36.538262=MD_EUR/USD_140109278614268=3279=1269=0270=1.14795271=10000055=EUR/USD110=0279=1269=0270=1.14795271=50000055=EUR/USD110=100000279=1269=0270=1.14795271=100000055=EUR/USD110=50000010=240
20260120-14:03:36.389632000 : 8=FIX.4.49=039735=X49=NTPRO_IDBA_UAT56=SIRIUS_500007460_MD34=84752=20260120-14:03:36.614262=MD_GBP/USD_140109778778268=5279=1269=1270=1.43494271=10000055=GBP/USD110=0279=1269=1270=1.43494271=50000055=GBP/USD110=100000279=1269=1270=1.43494271=100000055=GBP/USD110=500000279=1269=1270=1.43494271=300000055=GBP/USD110=1000000279=1269=1270=1.43494271=500000055=GBP/USD110=300000010=066
20260120-14:03:36.390720000 : 8=FIX.4.49=027635=X49=NTPRO_IDBA_UAT56=SIRIUS_500007460_MD34=84852=20260120-14:03:36.616262=MD_EUR/USD_140109278614268=3279=1269=1270=1.1982271=10000055=EUR/USD110=0279=1269=1270=1.1982271=50000055=EUR/USD110=100000279=1269=1270=1.1982271=100000055=EUR/USD110=50000010=077
20260120-14:03:36.543127000 : 8=FIX.4.49=027935=X49=NTPRO_IDBA_UAT56=SIRIUS_500007460_MD34=84952=20260120-14:03:36.763262=MD_EUR/USD_140109278614268=3279=1269=1270=1.19819271=10000055=EUR/USD110=0279=1269=1270=1.19819271=50000055=EUR/USD110=100000279=1269=1270=1.19819271=100000055=EUR/USD110=50000010=252
20260120-14:03:36.771502000 : 8=FIX.4.49=044635=X49=NTPRO_IDBA_UAT56=SIRIUS_500007460_MD34=85052=20260120-14:03:37.008262=MD_EUR/USD_140109278614268=6279=1269=0270=1.14793271=10000055=EUR/USD110=0279=1269=0270=1.14793271=50000055=EUR/USD110=100000279=1269=0270=1.14793271=100000055=EUR/USD110=500000279=1269=1270=1.19818271=10000055=EUR/USD110=0279=1269=1270=1.19818271=50000055=EUR/USD110=100000279=1269=1270=1.19818271=100000055=EUR/USD110=50000010=021
20260120-14:03:36.800886000 : 8=FIX.4.49=027935=X49=NTPRO_IDBA_UAT56=SIRIUS_500007460_MD34=85152=20260120-14:03:37.041262=MD_EUR/USD_140109278614268=3279=1269=0270=1.14794271=10000055=EUR/USD110=0279=1269=0270=1.14794271=50000055=EUR/USD110=100000279=1269=0270=1.14794271=100000055=EUR/USD110=50000010=223
20260120-14:03:36.925534000 : 8=FIX.4.49=044635=X49=NTPRO_IDBA_UAT56=SIRIUS_500007460_MD34=85252=20260120-14:03:37.169262=MD_EUR/USD_140109278614268=6279=1269=0270=1.14795271=10000055=EUR/USD110=0279=1269=0270=1.14795271=50000055=EUR/USD110=100000279=1269=0270=1.14795271=100000055=EUR/USD110=500000279=1269=1270=1.19819271=10000055=EUR/USD110=0279=1269=1270=1.19819271=50000055=EUR/USD110=100000279=1269=1270=1.19819271=100000055=EUR/USD110=50000010=040
20260120-14:03:37.048885000 : 8=FIX.4.49=067835=X49=NTPRO_IDBA_UAT56=SIRIUS_500007460_MD34=85352=20260120-14:03:37.297262=MD_GBP/USD_140109778778268=10279=1269=0270=1.2546271=10000055=GBP/USD110=0279=1269=0270=1.2546271=50000055=GBP/USD110=100000279=1269=0270=1.2546271=100000055=GBP/USD110=500000279=1269=0270=1.2546271=300000055=GBP/USD110=1000000279=1269=0270=1.2546271=500000055=GBP/USD110=3000000279=1269=1270=1.43495271=10000055=GBP/USD110=0279=1269=1270=1.43495271=50000055=GBP/USD110=100000279=1269=1270=1.43495271=100000055=GBP/USD110=500000279=1269=1270=1.43495271=300000055=GBP/USD110=1000000279=1269=1270=1.43495271=500000055=GBP/USD110=300000010=234
20260120-14:03:37.289047000 : 8=FIX.4.49=068335=X49=NTPRO_IDBA_UAT56=SIRIUS_500007460_MD34=85452=20260120-14:03:37.547262=MD_GBP/USD_140109778778268=10279=1269=0270=1.25461271=10000055=GBP/USD110=0279=1269=0270=1.25461271=50000055=GBP/USD110=100000279=1269=0270=1.25461271=100000055=GBP/USD110=500000279=1269=0270=1.25461271=300000055=GBP/USD110=1000000279=1269=0270=1.25461271=500000055=GBP/USD110=3000000279=1269=1270=1.43496271=10000055=GBP/USD110=0279=1269=1270=1.43496271=50000055=GBP/USD110=100000279=1269=1270=1.43496271=100000055=GBP/USD110=500000279=1269=1270=1.43496271=300000055=GBP/USD110=1000000279=1269=1270=1.43496271=500000055=GBP/USD110=300000010=223
20260120-14:03:37.339159000 : 8=FIX.4.49=039735=X49=NTPRO_IDBA_UAT56=SIRIUS_500007460_MD34=85552=20260120-14:03:37.582262=MD_GBP/USD_140109778778268=5279=1269=1270=1.43495271=10000055=GBP/USD110=0279=1269=1270=1.43495271=50000055=GBP/USD110=100000279=1269=1270=1.43495271=100000055=GBP/USD110=500000279=1269=1270=1.43495271=300000055=GBP/USD110=1000000279=1269=1270=1.43495271=500000055=GBP/USD110=300000010=075
20260120-14:03:37.339528000 : 8=FIX.4.49=027635=X49=NTPRO_IDBA_UAT56=SIRIUS_500007460_MD34=85652=20260120-14:03:37.591262=MD_EUR/USD_140109278614268=3279=1269=1270=1.1982271=10000055=EUR/USD110=0279=1269=1270=1.1982271=50000055=EUR/USD110=100000279=1269=1270=1.1982271=100000055=EUR/USD110=50000010=079
20260120-14:03:37.408979000 : 8=FIX.4.49=027935=X49=NTPRO_IDBA_UAT56=SIRIUS_500007460_MD34=85752=20260120-14:03:37.671262=MD_EUR/USD_140109278614268=3279=1269=1270=1.19819271=10000055=EUR/USD110=0279=1269=1270=1.19819271=50000055=EUR/USD110=100000279=1269=1270=1.19819271=100000055=EUR/USD110=50000010=250
20260120-14:03:37.409529000 : 8=FIX.4.49=068335=X49=NTPRO_IDBA_UAT56=SIRIUS_500007460_MD34=85852=20260120-14:03:37.671262=MD_GBP/USD_140109778778268=10279=1269=0270=1.25456271=10000055=GBP/USD110=0279=1269=0270=1.25456271=50000055=GBP/USD110=100000279=1269=0270=1.25456271=100000055=GBP/USD110=500000279=1269=0270=1.25456271=300000055=GBP/USD110=1000000279=1269=0270=1.25456271=500000055=GBP/USD110=3000000279=1269=1270=1.43492271=10000055=GBP/USD110=0279=1269=1270=1.43492271=50000055=GBP/USD110=100000279=1269=1270=1.43492271=100000055=GBP/USD110=500000279=1269=1270=1.43492271=300000055=GBP/USD110=1000000279=1269=1270=1.43492271=500000055=GBP/USD110=300000010=225
20260120-14:03:37.507356000 : 8=FIX.4.49=027935=X49=NTPRO_IDBA_UAT56=SIRIUS_500007460_MD34=85952=20260120-14:03:37.753262=MD_EUR/USD_140109278614268=3279=1269=0270=1.14794271=10000055=EUR/USD110=0279=1269=0270=1.14794271=50000055=EUR/USD110=100000279=1269=0270=1.14794271=100000055=EUR/USD110=50000010=241
20260120-14:03:37.507988000 : 8=FIX.4.49=068335=X49=NTPRO_IDBA_UAT56=SIRIUS_500007460_MD34=86052=20260120-14:03:37.753262=MD_GBP/USD_140109778778268=10279=1269=0270=1.25457271=10000055=GBP/USD110=0279=1269=0270=1.25457271=50000055=GBP/USD110=100000279=1269=0270=1.25457271=100000055=GBP/USD110=500000279=1269=0270=1.25457271=300000055=GBP/USD110=1000000279=1269=0270=1.25457271=500000055=GBP/USD110=3000000279=1269=1270=1.43493271=10000055=GBP/USD110=0279=1269=1270=1.43493271=50000055=GBP/USD110=100000279=1269=1270=1.43493271=100000055=GBP/USD110=500000279=1269=1270=1.43493271=300000055=GBP/USD110=1000000279=1269=1270=1.43493271=500000055=GBP/USD110=300000010=229
20260120-14:03:37.848873000 : 8=FIX.4.49=039735=X49=NTPRO_IDBA_UAT56=SIRIUS_500007460_MD34=86152=20260120-14:03:38.127262=MD_GBP/USD_140109778778268=5279=1269=1270=1.43494271=10000055=GBP/USD110=0279=1269=1270=1.43494271=50000055=GBP/USD110=100000279=1269=1270=1.43494271=100000055=GBP/USD110=500000279=1269=1270=1.43494271=300000055=GBP/USD110=1000000279=1269=1270=1.43494271=500000055=GBP/USD110=300000010=063
20260120-14:03:37.910919000 : 8=FIX.4.49=027935=X49=NTPRO_IDBA_UAT56=SIRIUS_500007460_MD34=86252=20260120-14:03:38.185262=MD_EUR/USD_140109278614268=3279=1269=0270=1.14795271=10000055=EUR/USD110=0279=1269=0270=1.14795271=50000055=EUR/USD110=100000279=1269=0270=1.14795271=100000055=EUR/USD110=50000010=238
20260120-14:03:37.951469000 : 8=FIX.4.49=039735=X49=NTPRO_IDBA_UAT56=SIRIUS_500007460_MD34=86352=20260120-14:03:38.233262=MD_GBP/USD_140109778778268=5279=1269=1270=1.43493271=10000055=GBP/USD110=0279=1269=1270=1.43493271=50000055=GBP/USD110=100000279=1269=1270=1.43493271=100000055=GBP/USD110=500000279=1269=1270=1.43493271=300000055=GBP/USD110=1000000279=1269=1270=1.43493271=500000055=GBP/USD110=300000010=058
20260120-14:03:38.200385000 : 8=FIX.4.49=044635=X49=NTPRO_IDBA_UAT56=SIRIUS_500007460_MD34=86452=20260120-14:03:38.491262=MD_EUR/USD_140109278614268=6279=1269=0270=1.14794271=10000055=EUR/USD110=0279=1269=0270=1.14794271=50000055=EUR/USD110=100000279=1269=0270=1.14794271=100000055=EUR/USD110=500000279=1269=1270=1.19818271=10000055=EUR/USD110=0279=1269=1270=1.19818271=50000055=EUR/USD110=100000279=1269=1270=1.19818271=100000055=EUR/USD110=50000010=036
20260120-14:03:38.276559000 : 8=FIX.4.49=068335=X49=NTPRO_IDBA_UAT56=SIRIUS_500007460_MD34=86552=20260120-14:03:38.569262=MD_GBP/USD_140109778778268=10279=2269=0270=1.25457271=10000055=GBP/USD110=0279=2269=0270=1.25457271=50000055=GBP/USD110=100000279=2269=0270=1.25457271=100000055=GBP/USD110=500000279=2269=0270=1.25457271=300000055=GBP/USD110=1000000279=2269=0270=1.25457271=500000055=GBP/USD110=3000000279=2269=1270=1.43493271=10000055=GBP/USD110=0279=2269=1270=1.43493271=50000055=GBP/USD110=100000279=2269=1270=1.43493271=100000055=GBP/USD110=500000279=2269=1270=1.43493271=300000055=GBP/USD110=1000000279=2269=1270=1.43493271=500000055=GBP/USD110=300000010=250
20260120-14:03:38.733792000 : 8=FIX.4.49=027935=X49=NTPRO_IDBA_UAT56=SIRIUS_500007460_MD34=86652=20260120-14:03:39.043262=MD_EUR/USD_140109278614268=3279=1269=0270=1.14793271=10000055=EUR/USD110=0279=1269=0270=1.14793271=50000055=EUR/USD110=100000279=1269=0270=1.14793271=100000055=EUR/USD110=50000010=230
20260120-14:03:38.763003000 : 8=FIX.4.49=044635=X49=NTPRO_IDBA_UAT56=SIRIUS_500007460_MD34=86752=20260120-14:03:39.074262=MD_EUR/USD_140109278614268=6279=1269=0270=1.14794271=10000055=EUR/USD110=0279=1269=0270=1.14794271=50000055=EUR/USD110=100000279=1269=0270=1.14794271=100000055=EUR/USD110=500000279=1269=1270=1.19819271=10000055=EUR/USD110=0279=1269=1270=1.19819271=50000055=EUR/USD110=100000279=1269=1270=1.19819271=100000055=EUR/USD110=50000010=040
20260120-14:03:38.832915000 : 8=FIX.4.49=027935=X49=NTPRO_IDBA_UAT56=SIRIUS_500007460_MD34=86852=20260120-14:03:39.144262=MD_EUR/USD_140109278614268=3279=1269=0270=1.14795271=10000055=EUR/USD110=0279=1269=0270=1.14795271=50000055=EUR/USD110=100000279=1269=0270=1.14795271=100000055=EUR/USD110=50000010=240
20260120-14:03:39.257888000 : 8=FIX.4.49=068335=X49=NTPRO_IDBA_UAT56=SIRIUS_500007460_MD34=86952=20260120-14:03:39.587262=MD_GBP/USD_140109778778268=10279=0269=0270=1.25457271=10000055=GBP/USD110=0279=0269=0270=1.25457271=50000055=GBP/USD110=100000279=0269=0270=1.25457271=100000055=GBP/USD110=500000279=0269=0270=1.25457271=300000055=GBP/USD110=1000000279=0269=0270=1.25457271=500000055=GBP/USD110=3000000279=0269=1270=1.43492271=10000055=GBP/USD110=0279=0269=1270=1.43492271=50000055=GBP/USD110=100000279=0269=1270=1.43492271=100000055=GBP/USD110=500000279=0269=1270=1.43492271=300000055=GBP/USD110=1000000279=0269=1270=1.43492271=500000055=GBP/USD110=300000010=230
20260120-14:03:39.296307000 : 8=FIX.4.49=027935=X49=NTPRO_IDBA_UAT56=SIRIUS_500007460_MD34=87052=20260120-14:03:39.625262=MD_EUR/USD_140109278614268=3279=1269=0270=1.14794271=10000055=EUR/USD110=0279=1269=0270=1.14794271=50000055=EUR/USD110=100000279=1269=0270=1.14794271=100000055=EUR/USD110=50000010=234
20260120-14:03:39.317827000 : 8=FIX.4.49=068335=X49=NTPRO_IDBA_UAT56=SIRIUS_500007460_MD34=87152=20260120-14:03:39.649262=MD_GBP/USD_140109778778268=10279=1269=0270=1.25459271=10000055=GBP/USD110=0279=1269=0270=1.25459271=50000055=GBP/USD110=100000279=1269=0270=1.25459271=100000055=GBP/USD110=500000279=1269=0270=1.25459271=300000055=GBP/USD110=1000000279=1269=0270=1.25459271=500000055=GBP/USD110=3000000279=1269=1270=1.43493271=10000055=GBP/USD110=0279=1269=1270=1.43493271=50000055=GBP/USD110=100000279=1269=1270=1.43493271=100000055=GBP/USD110=500000279=1269=1270=1.43493271=300000055=GBP/USD110=1000000279=1269=1270=1.43493271=500000055=GBP/USD110=300000010=247
20260120-14:03:39.381538000 : 8=FIX.4.49=039735=X49=NTPRO_IDBA_UAT56=SIRIUS_500007460_MD34=87252=20260120-14:03:39.715262=MD_GBP/USD_140109778778268=5279=1269=1270=1.43495271=10000055=GBP/USD110=0279=1269=1270=1.43495271=50000055=GBP/USD110=100000279=1269=1270=1.43495271=100000055=GBP/USD110=500000279=1269=1270=1.43495271=300000055=GBP/USD110=1000000279=1269=1270=1.43495271=500000055=GBP/USD110=300000010=074
20260120-14:03:39.415524000 : 8=FIX.4.49=039735=X49=NTPRO_IDBA_UAT56=SIRIUS_500007460_MD34=87352=20260120-14:03:39.737262=MD_GBP/USD_140109778778268=5279=1269=1270=1.43494271=10000055=GBP/USD110=0279=1269=1270=1.43494271=50000055=GBP/USD110=100000279=1269=1270=1.43494271=100000055=GBP/USD110=500000279=1269=1270=1.43494271=300000055=GBP/USD110=1000000279=1269=1270=1.43494271=500000055=GBP/USD110=300000010=074
20260120-14:03:39.425254000 : 8=FIX.4.49=027935=X49=NTPRO_IDBA_UAT56=SIRIUS_500007460_MD34=87452=20260120-14:03:39.758262=MD_EUR/USD_140109278614268=3279=1269=0270=1.14795271=10000055=EUR/USD110=0279=1269=0270=1.14795271=50000055=EUR/USD110=100000279=1269=0270=1.14795271=100000055=EUR/USD110=50000010=248
20260120-14:03:39.612463000 : 8=FIX.4.49=039235=X49=NTPRO_IDBA_UAT56=SIRIUS_500007460_MD34=87552=20260120-14:03:39.942262=MD_GBP/USD_140109778778268=5279=1269=0270=1.2546271=10000055=GBP/USD110=0279=1269=0270=1.2546271=50000055=GBP/USD110=100000279=1269=0270=1.2546271=100000055=GBP/USD110=500000279=1269=0270=1.2546271=300000055=GBP/USD110=1000000279=1269=0270=1.2546271=500000055=GBP/USD110=300000010=045
20260120-14:03:39.655346000 : 8=FIX.4.49=067835=X49=NTPRO_IDBA_UAT56=SIRIUS_500007460_MD34=87652=20260120-14:03:39.996262=MD_GBP/USD_140109778778268=10279=2269=0270=1.2546271=10000055=GBP/USD110=0279=2269=0270=1.2546271=50000055=GBP/USD110=100000279=2269=0270=1.2546271=100000055=GBP/USD110=500000279=2269=0270=1.2546271=300000055=GBP/USD110=1000000279=2269=0270=1.2546271=500000055=GBP/USD110=3000000279=2269=1270=1.43494271=10000055=GBP/USD110=0279=2269=1270=1.43494271=50000055=GBP/USD110=100000279=2269=1270=1.43494271=100000055=GBP/USD110=500000279=2269=1270=1.43494271=300000055=GBP/USD110=1000000279=2269=1270=1.43494271=500000055=GBP/USD110=300000010=252
20260120-14:03:39.655802000 : 8=FIX.4.49=027935=X49=NTPRO_IDBA_UAT56=SIRIUS_500007460_MD34=87752=20260120-14:03:39.996262=MD_EUR/USD_140109278614268=3279=1269=0270=1.14794271=10000055=EUR/USD110=0279=1269=0270=1.14794271=50000055=EUR/USD110=100000279=1269=0270=1.14794271=100000055=EUR/USD110=50000010=252
20260120-14:03:39.728267000 : 8=FIX.4.49=067335=X49=NTPRO_IDBA_UAT56=SIRIUS_500007460_MD34=87852=20260120-14:03:40.072262=MD_GBP/USD_140109778778268=10279=0269=0270=1.25464271=10000055=GBP/USD110=0279=0269=0270=1.25464271=50000055=GBP/USD110=100000279=0269=0270=1.25464271=100000055=GBP/USD110=500000279=0269=0270=1.25464271=300000055=GBP/USD110=1000000279=0269=0270=1.25464271=500000055=GBP/USD110=3000000279=0269=1270=1.435271=10000055=GBP/USD110=0279=0269=1270=1.435271=50000055=GBP/USD110=100000279=0269=1270=1.435271=100000055=GBP/USD110=500000279=0269=1270=1.435271=300000055=GBP/USD110=1000000279=0269=1270=1.435271=500000055=GBP/USD110=300000010=182
20260120-14:03:39.732733000 : 8=FIX.4.49=044335=X49=NTPRO_IDBA_UAT56=SIRIUS_500007460_MD34=87952=20260120-14:03:40.078262=MD_EUR/USD_140109278614268=6279=1269=0270=1.14795271=10000055=EUR/USD110=0279=1269=0270=1.14795271=50000055=EUR/USD110=100000279=1269=0270=1.14795271=100000055=EUR/USD110=500000279=1269=1270=1.1982271=10000055=EUR/USD110=0279=1269=1270=1.1982271=50000055=EUR/USD110=100000279=1269=1270=1.1982271=100000055=EUR/USD110=50000010=127
20260120-14:03:39.753715000 : 8=FIX.4.49=067335=X49=NTPRO_IDBA_UAT56=SIRIUS_500007460_MD34=88052=20260120-14:03:40.100262=MD_GBP/USD_140109778778268=10279=2269=0270=1.25464271=10000055=GBP/USD110=0279=2269=0270=1.25464271=50000055=GBP/USD110=100000279=2269=0270=1.25464271=100000055=GBP/USD110=500000279=2269=0270=1.25464271=300000055=GBP/USD110=1000000279=2269=0270=1.25464271=500000055=GBP/USD110=3000000279=2269=1270=1.435271=10000055=GBP/USD110=0279=2269=1270=1.435271=50000055=GBP/USD110=100000279=2269=1270=1.435271=100000055=GBP/USD110=500000279=2269=1270=1.435271=300000055=GBP/USD110=1000000279=2269=1270=1.435271=500000055=GBP/USD110=300000010=187
20260120-14:03:39.804366000 : 8=FIX.4.49=044635=X49=NTPRO_IDBA_UAT56=SIRIUS_500007460_MD34=88152=20260120-14:03:40.143262=MD_EUR/USD_140109278614268=6279=1269=0270=1.14792271=10000055=EUR/USD110=0279=1269=0270=1.14792271=50000055=EUR/USD110=100000279=1269=0270=1.14792271=100000055=EUR/USD110=500000279=1269=1270=1.19817271=10000055=EUR/USD110=0279=1269=1270=1.19817271=50000055=EUR/USD110=100000279=1269=1270=1.19817271=100000055=EUR/USD110=50000010=013
20260120-14:03:39.878726000 : 8=FIX.4.49=068335=X49=NTPRO_IDBA_UAT56=SIRIUS_500007460_MD34=88252=20260120-14:03:40.228262=MD_GBP/USD_140109778778268=10279=0269=0270=1.25459271=10000055=GBP/USD110=0279=0269=0270=1.25459271=50000055=GBP/USD110=100000279=0269=0270=1.25459271=100000055=GBP/USD110=500000279=0269=0270=1.25459271=300000055=GBP/USD110=1000000279=0269=0270=1.25459271=500000055=GBP/USD110=3000000279=0269=1270=1.43494271=10000055=GBP/USD110=0279=0269=1270=1.43494271=50000055=GBP/USD110=100000279=0269=1270=1.43494271=100000055=GBP/USD110=500000279=0269=1270=1.43494271=300000055=GBP/USD110=1000000279=0269=1270=1.43494271=500000055=GBP/USD110=300000010=229
20260120-14:03:39.885063000 : 8=FIX.4.49=044635=X49=NTPRO_IDBA_UAT56=SIRIUS_500007460_MD34=88352=20260120-14:03:40.235262=MD_EUR/USD_140109278614268=6279=1269=0270=1.14791271=10000055=EUR/USD110=0279=1269=0270=1.14791271=50000055=EUR/USD110=100000279=1269=0270=1.14791271=100000055=EUR/USD110=500000279=1269=1270=1.19816271=10000055=EUR/USD110=0279=1269=1270=1.19816271=50000055=EUR/USD110=100000279=1269=1270=1.19816271=100000055=EUR/USD110=50000010=011
20260120-14:03:39.910984000 : 8=FIX.4.49=067835=X49=NTPRO_IDBA_UAT56=SIRIUS_500007460_MD34=88452=20260120-14:03:40.263262=MD_GBP/USD_140109778778268=10279=1269=0270=1.2546271=10000055=GBP/USD110=0279=1269=0270=1.2546271=50000055=GBP/USD110=100000279=1269=0270=1.2546271=100000055=GBP/USD110=500000279=1269=0270=1.2546271=300000055=GBP/USD110=1000000279=1269=0270=1.2546271=500000055=GBP/USD110=3000000279=1269=1270=1.43495271=10000055=GBP/USD110=0279=1269=1270=1.43495271=50000055=GBP/USD110=100000279=1269=1270=1.43495271=100000055=GBP/USD110=500000279=1269=1270=1.43495271=300000055=GBP/USD110=1000000279=1269=1270=1.43495271=500000055=GBP/USD110=300000010=225
20260120-14:03:40.009681000 : 8=FIX.4.49=068335=X49=NTPRO_IDBA_UAT56=SIRIUS_500007460_MD34=88552=20260120-14:03:40.350262=MD_GBP/USD_140109778778268=10279=1269=0270=1.25461271=10000055=GBP/USD110=0279=1269=0270=1.25461271=50000055=GBP/USD110=100000279=1269=0270=1.25461271=100000055=GBP/USD110=500000279=1269=0270=1.25461271=300000055=GBP/USD110=1000000279=1269=0270=1.25461271=500000055=GBP/USD110=3000000279=1269=1270=1.43497271=10000055=GBP/USD110=0279=1269=1270=1.43497271=50000055=GBP/USD110=100000279=1269=1270=1.43497271=100000055=GBP/USD110=500000279=1269=1270=1.43497271=300000055=GBP/USD110=1000000279=1269=1270=1.43497271=500000055=GBP/USD110=300000010=218
20260120-14:03:40.063081000 : 8=FIX.4.49=067835=X49=NTPRO_IDBA_UAT56=SIRIUS_500007460_MD34=88652=20260120-14:03:40.421262=MD_GBP/USD_140109778778268=10279=1269=0270=1.2546271=10000055=GBP/USD110=0279=1269=0270=1.2546271=50000055=GBP/USD110=100000279=1269=0270=1.2546271=100000055=GBP/USD110=500000279=1269=0270=1.2546271=300000055=GBP/USD110=1000000279=1269=0270=1.2546271=500000055=GBP/USD110=3000000279=1269=1270=1.43496271=10000055=GBP/USD110=0279=1269=1270=1.43496271=50000055=GBP/USD110=100000279=1269=1270=1.43496271=100000055=GBP/USD110=500000279=1269=1270=1.43496271=300000055=GBP/USD110=1000000279=1269=1270=1.43496271=500000055=GBP/USD110=300000010=228
20260120-14:03:40.107190000 : 8=FIX.4.49=044635=X49=NTPRO_IDBA_UAT56=SIRIUS_500007460_MD34=88752=20260120-14:03:40.456262=MD_EUR/USD_140109278614268=6279=1269=0270=1.14789271=10000055=EUR/USD110=0279=1269=0270=1.14789271=50000055=EUR/USD110=100000279=1269=0270=1.14789271=100000055=EUR/USD110=500000279=1269=1270=1.19814271=10000055=EUR/USD110=0279=1269=1270=1.19814271=50000055=EUR/USD110=100000279=1269=1270=1.19814271=100000055=EUR/USD110=50000010=035
20260120-14:03:40.107603000 : 8=FIX.4.49=068335=X49=NTPRO_IDBA_UAT56=SIRIUS_500007460_MD34=88852=20260120-14:03:40.460262=MD_GBP/USD_140109778778268=10279=1269=0270=1.25458271=10000055=GBP/USD110=0279=1269=0270=1.25458271=50000055=GBP/USD110=100000279=1269=0270=1.25458271=100000055=GBP/USD110=500000279=1269=0270=1.25458271=300000055=GBP/USD110=1000000279=1269=0270=1.25458271=500000055=GBP/USD110=3000000279=1269=1270=1.43493271=10000055=GBP/USD110=0279=1269=1270=1.43493271=50000055=GBP/USD110=100000279=1269=1270=1.43493271=100000055=GBP/USD110=500000279=1269=1270=1.43493271=300000055=GBP/USD110=1000000279=1269=1270=1.43493271=500000055=GBP/USD110=300000010=233
20260120-14:03:40.251580000 : 8=FIX.4.49=068335=X49=NTPRO_IDBA_UAT56=SIRIUS_500007460_MD34=88952=20260120-14:03:40.616262=MD_GBP/USD_140109778778268=10279=2269=0270=1.25458271=10000055=GBP/USD110=0279=2269=0270=1.25458271=50000055=GBP/USD110=100000279=2269=0270=1.25458271=100000055=GBP/USD110=500000279=2269=0270=1.25458271=300000055=GBP/USD110=1000000279=2269=0270=1.25458271=500000055=GBP/USD110=3000000279=2269=1270=1.43493271=10000055=GBP/USD110=0279=2269=1270=1.43493271=50000055=GBP/USD110=100000279=2269=1270=1.43493271=100000055=GBP/USD110=500000279=2269=1270=1.43493271=300000055=GBP/USD110=1000000279=2269=1270=1.43493271=500000055=GBP/USD110=300000010=247
20260120-14:03:40.577933000 : 8=FIX.4.49=068335=X49=NTPRO_IDBA_UAT56=SIRIUS_500007460_MD34=89052=20260120-14:03:40.954262=MD_GBP/USD_140109778778268=10279=0269=0270=1.25458271=10000055=GBP/USD110=0279=0269=0270=1.25458271=50000055=GBP/USD110=100000279=0269=0270=1.25458271=100000055=GBP/USD110=500000279=0269=0270=1.25458271=300000055=GBP/USD110=1000000279=0269=0270=1.25458271=500000055=GBP/USD110=3000000279=0269=1270=1.43494271=10000055=GBP/USD110=0279=0269=1270=1.43494271=50000055=GBP/USD110=100000279=0269=1270=1.43494271=100000055=GBP/USD110=500000279=0269=1270=1.43494271=300000055=GBP/USD110=1000000279=0269=1270=1.43494271=500000055=GBP/USD110=300000010=229
20260120-14:03:40.997603000 : 8=FIX.4.49=068335=X49=NTPRO_IDBA_UAT56=SIRIUS_500007460_MD34=89152=20260120-14:03:41.377262=MD_GBP/USD_140109778778268=10279=2269=0270=1.25458271=10000055=GBP/USD110=0279=2269=0270=1.25458271=50000055=GBP/USD110=100000279=2269=0270=1.25458271=100000055=GBP/USD110=500000279=2269=0270=1.25458271=300000055=GBP/USD110=1000000279=2269=0270=1.25458271=500000055=GBP/USD110=3000000279=2269=1270=1.43494271=10000055=GBP/USD110=0279=2269=1270=1.43494271=50000055=GBP/USD110=100000279=2269=1270=1.43494271=100000055=GBP/USD110=500000279=2269=1270=1.43494271=300000055=GBP/USD110=1000000279=2269=1270=1.43494271=500000055=GBP/USD110=300000010=250
20260120-14:03:41.008548000 : 8=FIX.4.49=044635=X49=NTPRO_IDBA_UAT56=SIRIUS_500007460_MD34=89252=20260120-14:03:41.400262=MD_EUR/USD_140109278614268=6279=1269=0270=1.14788271=10000055=EUR/USD110=0279=1269=0270=1.14788271=50000055=EUR/USD110=100000279=1269=0270=1.14788271=100000055=EUR/USD110=500000279=1269=1270=1.19813271=10000055=EUR/USD110=0279=1269=1270=1.19813271=50000055=EUR/USD110=100000279=1269=1270=1.19813271=100000055=EUR/USD110=50000010=015
20260120-14:03:41.110948000 : 8=FIX.4.49=027935=X49=NTPRO_IDBA_UAT56=SIRIUS_500007460_MD34=89352=20260120-14:03:41.506262=MD_EUR/USD_140109278614268=3279=1269=1270=1.19812271=10000055=EUR/USD110=0279=1269=1270=1.19812271=50000055=EUR/USD110=100000279=1269=1270=1.19812271=100000055=EUR/USD110=50000010=221
20260120-14:03:41.123179000 : 8=FIX.4.49=068335=X49=NTPRO_IDBA_UAT56=SIRIUS_500007460_MD34=89452=20260120-14:03:41.519262=MD_GBP/USD_140109778778268=10279=0269=0270=1.25458271=10000055=GBP/USD110=0279=0269=0270=1.25458271=50000055=GBP/USD110=100000279=0269=0270=1.25458271=100000055=GBP/USD110=500000279=0269=0270=1.25458271=300000055=GBP/USD110=1000000279=0269=0270=1.25458271=500000055=GBP/USD110=3000000279=0269=1270=1.43493271=10000055=GBP/USD110=0279=0269=1270=1.43493271=50000055=GBP/USD110=100000279=0269=1270=1.43493271=100000055=GBP/USD110=500000279=0269=1270=1.43493271=300000055=GBP/USD110=1000000279=0269=1270=1.43493271=500000055=GBP/USD110=300000010=226
20260120-14:03:41.195531000 : 8=FIX.4.49=027935=X49=NTPRO_IDBA_UAT56=SIRIUS_500007460_MD34=89552=20260120-14:03:41.572262=MD_EUR/USD_140109278614268=3279=1269=1270=1.19813271=10000055=EUR/USD110=0279=1269=1270=1.19813271=50000055=EUR/USD110=100000279=1269=1270=1.19813271=100000055=EUR/USD110=50000010=229
20260120-14:03:41.296655000 : 8=FIX.4.49=027935=X49=NTPRO_IDBA_UAT56=SIRIUS_500007460_MD34=89652=20260120-14:03:41.684262=MD_EUR/USD_140109278614268=3279=1269=0270=1.14789271=10000055=EUR/USD110=0279=1269=0270=1.14789271=50000055=EUR/USD110=100000279=1269=0270=1.14789271=100000055=EUR/USD110=50000010=252
20260120-14:03:41.512534000 : 8=FIX.4.49=027935=X49=NTPRO_IDBA_UAT56=SIRIUS_500007460_MD34=89752=20260120-14:03:41.920262=MD_EUR/USD_140109278614268=3279=1269=1270=1.19814271=10000055=EUR/USD110=0279=1269=1270=1.19814271=50000055=EUR/USD110=100000279=1269=1270=1.19814271=100000055=EUR/USD110=50000010=231
20260120-14:03:41.556321000 : 8=FIX.4.49=027935=X49=NTPRO_IDBA_UAT56=SIRIUS_500007460_MD34=89852=20260120-14:03:41.968262=MD_EUR/USD_140109278614268=3279=1269=1270=1.19813271=10000055=EUR/USD110=0279=1269=1270=1.19813271=50000055=EUR/USD110=100000279=1269=1270=1.19813271=100000055=EUR/USD110=50000010=241
20260120-14:03:41.615554000 : 8=FIX.4.49=044635=X49=NTPRO_IDBA_UAT56=SIRIUS_500007460_MD34=89952=20260120-14:03:42.028262=MD_EUR/USD_140109278614268=6279=1269=0270=1.14787271=10000055=EUR/USD110=0279=1269=0270=1.14787271=50000055=EUR/USD110=100000279=1269=0270=1.14787271=100000055=EUR/USD110=500000279=1269=1270=1.19812271=10000055=EUR/USD110=0279=1269=1270=1.19812271=50000055=EUR/USD110=100000279=1269=1270=1.19812271=100000055=EUR/USD110=50000010=023
20260120-14:03:41.631813000 : 8=FIX.4.49=068335=X49=NTPRO_IDBA_UAT56=SIRIUS_500007460_MD34=90052=20260120-14:03:42.040262=MD_GBP/USD_140109778778268=10279=2269=0270=1.25458271=10000055=GBP/USD110=0279=2269=0270=1.25458271=50000055=GBP/USD110=100000279=2269=0270=1.25458271=100000055=GBP/USD110=500000279=2269=0270=1.25458271=300000055=GBP/USD110=1000000279=2269=0270=1.25458271=500000055=GBP/USD110=3000000279=2269=1270=1.43493271=10000055=GBP/USD110=0279=2269=1270=1.43493271=50000055=GBP/USD110=100000279=2269=1270=1.43493271=100000055=GBP/USD110=500000279=2269=1270=1.43493271=300000055=GBP/USD110=1000000279=2269=1270=1.43493271=500000055=GBP/USD110=300000010=224
20260120-14:03:41.701519000 : 8=FIX.4.49=044635=X49=NTPRO_IDBA_UAT56=SIRIUS_500007460_MD34=90152=20260120-14:03:42.117262=MD_EUR/USD_140109278614268=6279=1269=0270=1.14786271=10000055=EUR/USD110=0279=1269=0270=1.14786271=50000055=EUR/USD110=100000279=1269=0270=1.14786271=100000055=EUR/USD110=500000279=1269=1270=1.19811271=10000055=EUR/USD110=0279=1269=1270=1.19811271=50000055=EUR/USD110=100000279=1269=1270=1.19811271=100000055=EUR/USD110=50000010=000
20260120-14:03:41.788395000 : 8=FIX.4.49=044635=X49=NTPRO_IDBA_UAT56=SIRIUS_500007460_MD34=90252=20260120-14:03:42.204262=MD_EUR/USD_140109278614268=6279=1269=0270=1.14787271=10000055=EUR/USD110=0279=1269=0270=1.14787271=50000055=EUR/USD110=100000279=1269=0270=1.14787271=100000055=EUR/USD110=500000279=1269=1270=1.19812271=10000055=EUR/USD110=0279=1269=1270=1.19812271=50000055=EUR/USD110=100000279=1269=1270=1.19812271=100000055=EUR/USD110=50000010=004
20260120-14:03:41.886285000 : 8=FIX.4.49=068335=X49=NTPRO_IDBA_UAT56=SIRIUS_500007460_MD34=90352=20260120-14:03:42.292262=MD_GBP/USD_140109778778268=10279=0269=0270=1.25458271=10000055=GBP/USD110=0279=0269=0270=1.25458271=50000055=GBP/USD110=100000279=0269=0270=1.25458271=100000055=GBP/USD110=500000279=0269=0270=1.25458271=300000055=GBP/USD110=1000000279=0269=0270=1.25458271=500000055=GBP/USD110=3000000279=0269=1270=1.43493271=10000055=GBP/USD110=0279=0269=1270=1.43493271=50000055=GBP/USD110=100000279=0269=1270=1.43493271=100000055=GBP/USD110=500000279=0269=1270=1.43493271=300000055=GBP/USD110=1000000279=0269=1270=1.43493271=500000055=GBP/USD110=300000010=216
20260120-14:03:41.886868000 : 8=FIX.4.49=027935=X49=NTPRO_IDBA_UAT56=SIRIUS_500007460_MD34=90452=20260120-14:03:42.302262=MD_EUR/USD_140109278614268=3279=1269=1270=1.19811271=10000055=EUR/USD110=0279=1269=1270=1.19811271=50000055=EUR/USD110=100000279=1269=1270=1.19811271=100000055=EUR/USD110=50000010=206
20260120-14:03:41.955867000 : 8=FIX.4.49=068335=X49=NTPRO_IDBA_UAT56=SIRIUS_500007460_MD34=90552=20260120-14:03:42.379262=MD_GBP/USD_140109778778268=10279=2269=0270=1.25458271=10000055=GBP/USD110=0279=2269=0270=1.25458271=50000055=GBP/USD110=100000279=2269=0270=1.25458271=100000055=GBP/USD110=500000279=2269=0270=1.25458271=300000055=GBP/USD110=1000000279=2269=0270=1.25458271=500000055=GBP/USD110=3000000279=2269=1270=1.43493271=10000055=GBP/USD110=0279=2269=1270=1.43493271=50000055=GBP/USD110=100000279=2269=1270=1.43493271=100000055=GBP/USD110=500000279=2269=1270=1.43493271=300000055=GBP/USD110=1000000279=2269=1270=1.43493271=500000055=GBP/USD110=300000010=244
20260120-14:03:42.006316000 : 8=FIX.4.49=027935=X49=NTPRO_IDBA_UAT56=SIRIUS_500007460_MD34=90652=20260120-14:03:42.429262=MD_EUR/USD_140109278614268=3279=1269=0270=1.14786271=10000055=EUR/USD110=0279=1269=0270=1.14786271=50000055=EUR/USD110=100000279=1269=0270=1.14786271=100000055=EUR/USD110=50000010=233
20260120-14:03:42.060353000 : 8=FIX.4.49=068335=X49=NTPRO_IDBA_UAT56=SIRIUS_500007460_MD34=90752=20260120-14:03:42.486262=MD_GBP/USD_140109778778268=10279=0269=0270=1.25458271=10000055=GBP/USD110=0279=0269=0270=1.25458271=50000055=GBP/USD110=100000279=0269=0270=1.25458271=100000055=GBP/USD110=500000279=0269=0270=1.25458271=300000055=GBP/USD110=1000000279=0269=0270=1.25458271=500000055=GBP/USD110=3000000279=0269=1270=1.43493271=10000055=GBP/USD110=0279=0269=1270=1.43493271=50000055=GBP/USD110=100000279=0269=1270=1.43493271=100000055=GBP/USD110=500000279=0269=1270=1.43493271=300000055=GBP/USD110=1000000279=0269=1270=1.43493271=500000055=GBP/USD110=300000010=225
20260120-14:03:42.908535000 : 8=FIX.4.49=027935=X49=NTPRO_IDBA_UAT56=SIRIUS_500007460_MD34=90852=20260120-14:03:43.369262=MD_EUR/USD_140109278614268=3279=1269=0270=1.14787271=10000055=EUR/USD110=0279=1269=0270=1.14787271=50000055=EUR/USD110=100000279=1269=0270=1.14787271=100000055=EUR/USD110=50000010=242
20260120-14:03:42.950416000 : 8=FIX.4.49=027935=X49=NTPRO_IDBA_UAT56=SIRIUS_500007460_MD34=90952=20260120-14:03:43.409262=MD_EUR/USD_140109278614268=3279=1269=0270=1.14786271=10000055=EUR/USD110=0279=1269=0270=1.14786271=50000055=EUR/USD110=100000279=1269=0270=1.14786271=100000055=EUR/USD110=50000010=235
20260120-14:03:43.009682000 : 8=FIX.4.49=068335=X49=NTPRO_IDBA_UAT56=SIRIUS_500007460_MD34=91052=20260120-14:03:43.473262=MD_GBP/USD_140109778778268=10279=2269=0270=1.25458271=10000055=GBP/USD110=0279=2269=0270=1.25458271=50000055=GBP/USD110=100000279=2269=0270=1.25458271=100000055=GBP/USD110=500000279=2269=0270=1.25458271=300000055=GBP/USD110=1000000279=2269=0270=1.25458271=500000055=GBP/USD110=3000000279=2269=1270=1.43493271=10000055=GBP/USD110=0279=2269=1270=1.43493271=50000055=GBP/USD110=100000279=2269=1270=1.43493271=100000055=GBP/USD110=500000279=2269=1270=1.43493271=300000055=GBP/USD110=1000000279=2269=1270=1.43493271=500000055=GBP/USD110=300000010=236
20260120-14:03:43.032475000 : 8=FIX.4.49=044635=X49=NTPRO_IDBA_UAT56=SIRIUS_500007460_MD34=91152=20260120-14:03:43.495262=MD_EUR/USD_140109278614268=6279=1269=0270=1.14787271=10000055=EUR/USD110=0279=1269=0270=1.14787271=50000055=EUR/USD110=100000279=1269=0270=1.14787271=100000055=EUR/USD110=500000279=1269=1270=1.19812271=10000055=EUR/USD110=0279=1269=1270=1.19812271=50000055=EUR/USD110=100000279=1269=1270=1.19812271=100000055=EUR/USD110=50000010=017
20260120-14:03:43.695816000 : 8=FIX.4.49=068335=X49=NTPRO_IDBA_UAT56=SIRIUS_500007460_MD34=91252=20260120-14:03:44.185262=MD_GBP/USD_140109778778268=10279=0269=0270=1.25459271=10000055=GBP/USD110=0279=0269=0270=1.25459271=50000055=GBP/USD110=100000279=0269=0270=1.25459271=100000055=GBP/USD110=500000279=0269=0270=1.25459271=300000055=GBP/USD110=1000000279=0269=0270=1.25459271=500000055=GBP/USD110=3000000279=0269=1270=1.43495271=10000055=GBP/USD110=0279=0269=1270=1.43495271=50000055=GBP/USD110=100000279=0269=1270=1.43495271=100000055=GBP/USD110=500000279=0269=1270=1.43495271=300000055=GBP/USD110=1000000279=0269=1270=1.43495271=500000055=GBP/USD110=300000010=234
20260120-14:03:43.861401000 : 8=FIX.4.49=068335=X49=NTPRO_IDBA_UAT56=SIRIUS_500007460_MD34=91352=20260120-14:03:44.349262=MD_GBP/USD_140109778778268=10279=2269=0270=1.25459271=10000055=GBP/USD110=0279=2269=0270=1.25459271=50000055=GBP/USD110=100000279=2269=0270=1.25459271=100000055=GBP/USD110=500000279=2269=0270=1.25459271=300000055=GBP/USD110=1000000279=2269=0270=1.25459271=500000055=GBP/USD110=3000000279=2269=1270=1.43495271=10000055=GBP/USD110=0279=2269=1270=1.43495271=50000055=GBP/USD110=100000279=2269=1270=1.43495271=100000055=GBP/USD110=500000279=2269=1270=1.43495271=300000055=GBP/USD110=1000000279=2269=1270=1.43495271=500000055=GBP/USD110=300000010=001
20260120-14:03:43.870129000 : 8=FIX.4.49=044635=X49=NTPRO_IDBA_UAT56=SIRIUS_500007460_MD34=91452=20260120-14:03:44.366262=MD_EUR/USD_140109278614268=6279=1269=0270=1.14789271=10000055=EUR/USD110=0279=1269=0270=1.14789271=50000055=EUR/USD110=100000279=1269=0270=1.14789271=100000055=EUR/USD110=500000279=1269=1270=1.19813271=10000055=EUR/USD110=0279=1269=1270=1.19813271=50000055=EUR/USD110=100000279=1269=1270=1.19813271=100000055=EUR/USD110=50000010=027
20260120-14:03:43.919415000 : 8=FIX.4.49=067335=X49=NTPRO_IDBA_UAT56=SIRIUS_500007460_MD34=91552=20260120-14:03:44.417262=MD_GBP/USD_140109778778268=10279=0269=0270=1.25462271=10000055=GBP/USD110=0279=0269=0270=1.25462271=50000055=GBP/USD110=100000279=0269=0270=1.25462271=100000055=GBP/USD110=500000279=0269=0270=1.25462271=300000055=GBP/USD110=1000000279=0269=0270=1.25462271=500000055=GBP/USD110=3000000279=0269=1270=1.435271=10000055=GBP/USD110=0279=0269=1270=1.435271=50000055=GBP/USD110=100000279=0269=1270=1.435271=100000055=GBP/USD110=500000279=0269=1270=1.435271=300000055=GBP/USD110=1000000279=0269=1270=1.435271=500000055=GBP/USD110=300000010=171
20260120-14:03:43.960524000 : 8=FIX.4.49=044635=X49=NTPRO_IDBA_UAT56=SIRIUS_500007460_MD34=91652=20260120-14:03:44.447262=MD_EUR/USD_140109278614268=6279=1269=0270=1.14792271=10000055=EUR/USD110=0279=1269=0270=1.14792271=50000055=EUR/USD110=100000279=1269=0270=1.14792271=100000055=EUR/USD110=500000279=1269=1270=1.19817271=10000055=EUR/USD110=0279=1269=1270=1.19817271=50000055=EUR/USD110=100000279=1269=1270=1.19817271=100000055=EUR/USD110=50000010=023
20260120-14:03:43.968062000 : 8=FIX.4.49=039735=X49=NTPRO_IDBA_UAT56=SIRIUS_500007460_MD34=91752=20260120-14:03:44.467262=MD_GBP/USD_140109778778268=5279=1269=0270=1.25465271=10000055=GBP/USD110=0279=1269=0270=1.25465271=50000055=GBP/USD110=100000279=1269=0270=1.25465271=100000055=GBP/USD110=500000279=1269=0270=1.25465271=300000055=GBP/USD110=1000000279=1269=0270=1.25465271=500000055=GBP/USD110=300000010=054
20260120-14:03:44.060131000 : 8=FIX.4.49=044335=X49=NTPRO_IDBA_UAT56=SIRIUS_500007460_MD34=91852=20260120-14:03:44.559262=MD_EUR/USD_140109278614268=6279=1269=0270=1.14795271=10000055=EUR/USD110=0279=1269=0270=1.14795271=50000055=EUR/USD110=100000279=1269=0270=1.14795271=100000055=EUR/USD110=500000279=1269=1270=1.1982271=10000055=EUR/USD110=0279=1269=1270=1.1982271=50000055=EUR/USD110=100000279=1269=1270=1.1982271=100000055=EUR/USD110=50000010=129
20260120-14:03:44.088817000 : 8=FIX.4.49=068335=X49=NTPRO_IDBA_UAT56=SIRIUS_500007460_MD34=91952=20260120-14:03:44.593262=MD_GBP/USD_140109778778268=10279=1269=0270=1.25467271=10000055=GBP/USD110=0279=1269=0270=1.25467271=50000055=GBP/USD110=100000279=1269=0270=1.25467271=100000055=GBP/USD110=500000279=1269=0270=1.25467271=300000055=GBP/USD110=1000000279=1269=0270=1.25467271=500000055=GBP/USD110=3000000279=1269=1270=1.43502271=10000055=GBP/USD110=0279=1269=1270=1.43502271=50000055=GBP/USD110=100000279=1269=1270=1.43502271=100000055=GBP/USD110=500000279=1269=1270=1.43502271=300000055=GBP/USD110=1000000279=1269=1270=1.43502271=500000055=GBP/USD110=300000010=194
20260120-14:03:44.358791000 : 8=FIX.4.49=044635=X49=NTPRO_IDBA_UAT56=SIRIUS_500007460_MD34=92052=20260120-14:03:44.873262=MD_EUR/USD_140109278614268=6279=1269=0270=1.14796271=10000055=EUR/USD110=0279=1269=0270=1.14796271=50000055=EUR/USD110=100000279=1269=0270=1.14796271=100000055=EUR/USD110=500000279=1269=1270=1.19821271=10000055=EUR/USD110=0279=1269=1270=1.19821271=50000055=EUR/USD110=100000279=1269=1270=1.19821271=100000055=EUR/USD110=50000010=018
20260120-14:03:44.372621000 : 8=FIX.4.49=068335=X49=NTPRO_IDBA_UAT56=SIRIUS_500007460_MD34=92152=20260120-14:03:44.887262=MD_GBP/USD_140109778778268=10279=1269=0270=1.25468271=10000055=GBP/USD110=0279=1269=0270=1.25468271=50000055=GBP/USD110=100000279=1269=0270=1.25468271=100000055=GBP/USD110=500000279=1269=0270=1.25468271=300000055=GBP/USD110=1000000279=1269=0270=1.25468271=500000055=GBP/USD110=3000000279=1269=1270=1.43503271=10000055=GBP/USD110=0279=1269=1270=1.43503271=50000055=GBP/USD110=100000279=1269=1270=1.43503271=100000055=GBP/USD110=500000279=1269=1270=1.43503271=300000055=GBP/USD110=1000000279=1269=1270=1.43503271=500000055=GBP/USD110=300000010=203
20260120-14:03:44.400182000 : 8=FIX.4.49=039735=X49=NTPRO_IDBA_UAT56=SIRIUS_500007460_MD34=92252=20260120-14:03:44.916262=MD_GBP/USD_140109778778268=5279=1269=1270=1.43504271=10000055=GBP/USD110=0279=1269=1270=1.43504271=50000055=GBP/USD110=100000279=1269=1270=1.43504271=100000055=GBP/USD110=500000279=1269=1270=1.43504271=300000055=GBP/USD110=1000000279=1269=1270=1.43504271=500000055=GBP/USD110=300000010=024
20260120-14:03:44.455100000 : 8=FIX.4.49=039735=X49=NTPRO_IDBA_UAT56=SIRIUS_500007460_MD34=92352=20260120-14:03:44.971262=MD_GBP/USD_140109778778268=5279=1269=1270=1.43503271=10000055=GBP/USD110=0279=1269=1270=1.43503271=50000055=GBP/USD110=100000279=1269=1270=1.43503271=100000055=GBP/USD110=500000279=1269=1270=1.43503271=300000055=GBP/USD110=1000000279=1269=1270=1.43503271=500000055=GBP/USD110=300000010=021
20260120-14:03:44.465335000 : 8=FIX.4.49=027935=X49=NTPRO_IDBA_UAT56=SIRIUS_500007460_MD34=92452=20260120-14:03:44.984262=MD_EUR/USD_140109278614268=3279=1269=0270=1.14797271=10000055=EUR/USD110=0279=1269=0270=1.14797271=50000055=EUR/USD110=100000279=1269=0270=1.14797271=100000055=EUR/USD110=50000010=247
20260120-14:03:44.533776000 : 8=FIX.4.49=027935=X49=NTPRO_IDBA_UAT56=SIRIUS_500007460_MD34=92552=20260120-14:03:45.055262=MD_EUR/USD_140109278614268=3279=1269=0270=1.14796271=10000055=EUR/USD110=0279=1269=0270=1.14796271=50000055=EUR/USD110=100000279=1269=0270=1.14796271=100000055=EUR/USD110=50000010=235
20260120-14:03:44.587084000 : 8=FIX.4.49=039735=X49=NTPRO_IDBA_UAT56=SIRIUS_500007460_MD34=92652=20260120-14:03:45.110262=MD_GBP/USD_140109778778268=5279=1269=0270=1.25467271=10000055=GBP/USD110=0279=1269=0270=1.25467271=50000055=GBP/USD110=100000279=1269=0270=1.25467271=100000055=GBP/USD110=500000279=1269=0270=1.25467271=300000055=GBP/USD110=1000000279=1269=0270=1.25467271=500000055=GBP/USD110=300000010=050
20260120-14:03:44.594137000 : 8=FIX.4.49=044635=X49=NTPRO_IDBA_UAT56=SIRIUS_500007460_MD34=92752=20260120-14:03:45.117262=MD_EUR/USD_140109278614268=6279=1269=0270=1.14795271=10000055=EUR/USD110=0279=1269=0270=1.14795271=50000055=EUR/USD110=100000279=1269=0270=1.14795271=100000055=EUR/USD110=500000279=1269=1270=1.19819271=10000055=EUR/USD110=0279=1269=1270=1.19819271=50000055=EUR/USD110=100000279=1269=1270=1.19819271=100000055=EUR/USD110=50000010=035
20260120-14:03:44.617104000 : 8=FIX.4.49=039735=X49=NTPRO_IDBA_UAT56=SIRIUS_500007460_MD34=92852=20260120-14:03:45.140262=MD_GBP/USD_140109778778268=5279=1269=1270=1.43502271=10000055=GBP/USD110=0279=1269=1270=1.43502271=50000055=GBP/USD110=100000279=1269=1270=1.43502271=100000055=GBP/USD110=500000279=1269=1270=1.43502271=300000055=GBP/USD110=1000000279=1269=1270=1.43502271=500000055=GBP/USD110=300000010=010
20260120-14:03:44.710986000 : 8=FIX.4.49=027935=X49=NTPRO_IDBA_UAT56=SIRIUS_500007460_MD34=92952=20260120-14:03:45.237262=MD_EUR/USD_140109278614268=3279=1269=0270=1.14794271=10000055=EUR/USD110=0279=1269=0270=1.14794271=50000055=EUR/USD110=100000279=1269=0270=1.14794271=100000055=EUR/USD110=50000010=235
20260120-14:03:44.952663000 : 8=FIX.4.49=039735=X49=NTPRO_IDBA_UAT56=SIRIUS_500007460_MD34=93052=20260120-14:03:45.483262=MD_GBP/USD_140109778778268=5279=1269=1270=1.43503271=10000055=GBP/USD110=0279=1269=1270=1.43503271=50000055=GBP/USD110=100000279=1269=1270=1.43503271=100000055=GBP/USD110=500000279=1269=1270=1.43503271=300000055=GBP/USD110=1000000279=1269=1270=1.43503271=500000055=GBP/USD110=300000010=018
20260120-14:03:44.974343000 : 8=FIX.4.49=044335=X49=NTPRO_IDBA_UAT56=SIRIUS_500007460_MD34=93152=20260120-14:03:45.512262=MD_EUR/USD_140109278614268=6279=1269=0270=1.14795271=10000055=EUR/USD110=0279=1269=0270=1.14795271=50000055=EUR/USD110=100000279=1269=0270=1.14795271=100000055=EUR/USD110=500000279=1269=1270=1.1982271=10000055=EUR/USD110=0279=1269=1270=1.1982271=50000055=EUR/USD110=100000279=1269=1270=1.1982271=100000055=EUR/USD110=50000010=114
20260120-14:03:45.242469000 : 8=FIX.4.49=039735=X49=NTPRO_IDBA_UAT56=SIRIUS_500007460_MD34=93252=20260120-14:03:45.771262=MD_GBP/USD_140109778778268=5279=1269=0270=1.25468271=10000055=GBP/USD110=0279=1269=0270=1.25468271=50000055=GBP/USD110=100000279=1269=0270=1.25468271=100000055=GBP/USD110=500000279=1269=0270=1.25468271=300000055=GBP/USD110=1000000279=1269=0270=1.25468271=500000055=GBP/USD110=300000010=065
20260120-14:03:45.244486000 : 8=FIX.4.49=7735=034=1249=SIRIUS_500007460_MD52=20260120-14:03:45.24356=NTPRO_IDBA_UAT10=066
20260120-14:03:45.422758000 : 8=FIX.4.49=039735=X49=NTPRO_IDBA_UAT56=SIRIUS_500007460_MD34=93352=20260120-14:03:45.977262=MD_GBP/USD_140109778778268=5279=1269=0270=1.25467271=10000055=GBP/USD110=0279=1269=0270=1.25467271=50000055=GBP/USD110=100000279=1269=0270=1.25467271=100000055=GBP/USD110=500000279=1269=0270=1.25467271=300000055=GBP/USD110=1000000279=1269=0270=1.25467271=500000055=GBP/USD110=300000010=069
20260120-14:03:45.498039000 : 8=FIX.4.49=039735=X49=NTPRO_IDBA_UAT56=SIRIUS_500007460_MD34=93452=20260120-14:03:46.055262=MD_GBP/USD_140109778778268=5279=1269=1270=1.43502271=10000055=GBP/USD110=0279=1269=1270=1.43502271=50000055=GBP/USD110=100000279=1269=1270=1.43502271=100000055=GBP/USD110=500000279=1269=1270=1.43502271=300000055=GBP/USD110=1000000279=1269=1270=1.43502271=500000055=GBP/USD110=300000010=013
20260120-14:03:45.570777000 : 8=FIX.4.49=039735=X49=NTPRO_IDBA_UAT56=SIRIUS_500007460_MD34=93552=20260120-14:03:46.130262=MD_GBP/USD_140109778778268=5279=1269=1270=1.43503271=10000055=GBP/USD110=0279=1269=1270=1.43503271=50000055=GBP/USD110=100000279=1269=1270=1.43503271=100000055=GBP/USD110=500000279=1269=1270=1.43503271=300000055=GBP/USD110=1000000279=1269=1270=1.43503271=500000055=GBP/USD110=300000010=013
20260120-14:03:45.605558000 : 8=FIX.4.49=044635=X49=NTPRO_IDBA_UAT56=SIRIUS_500007460_MD34=93652=20260120-14:03:46.167262=MD_EUR/USD_140109278614268=6279=1269=0270=1.14794271=10000055=EUR/USD110=0279=1269=0270=1.14794271=50000055=EUR/USD110=100000279=1269=0270=1.14794271=100000055=EUR/USD110=500000279=1269=1270=1.19819271=10000055=EUR/USD110=0279=1269=1270=1.19819271=50000055=EUR/USD110=100000279=1269=1270=1.19819271=100000055=EUR/USD110=50000010=038
20260120-14:03:45.640974000 : 8=FIX.4.49=039735=X49=NTPRO_IDBA_UAT56=SIRIUS_500007460_MD34=93752=20260120-14:03:46.203262=MD_GBP/USD_140109778778268=5279=1269=1270=1.43502271=10000055=GBP/USD110=0279=1269=1270=1.43502271=50000055=GBP/USD110=100000279=1269=1270=1.43502271=100000055=GBP/USD110=500000279=1269=1270=1.43502271=300000055=GBP/USD110=1000000279=1269=1270=1.43502271=500000055=GBP/USD110=300000010=011
20260120-14:03:45.648841000 : 8=FIX.4.49=027935=X49=NTPRO_IDBA_UAT56=SIRIUS_500007460_MD34=93852=20260120-14:03:46.211262=MD_EUR/USD_140109278614268=3279=1269=0270=1.14795271=10000055=EUR/USD110=0279=1269=0270=1.14795271=50000055=EUR/USD110=100000279=1269=0270=1.14795271=100000055=EUR/USD110=50000010=231
20260120-14:03:45.674264000 : 8=FIX.4.49=039735=X49=NTPRO_IDBA_UAT56=SIRIUS_500007460_MD34=93952=20260120-14:03:46.238262=MD_GBP/USD_140109778778268=5279=1269=1270=1.43503271=10000055=GBP/USD110=0279=1269=1270=1.43503271=50000055=GBP/USD110=100000279=1269=1270=1.43503271=100000055=GBP/USD110=500000279=1269=1270=1.43503271=300000055=GBP/USD110=1000000279=1269=1270=1.43503271=500000055=GBP/USD110=300000010=026
20260120-14:03:46.151604000 : 8=FIX.4.49=027635=X49=NTPRO_IDBA_UAT56=SIRIUS_500007460_MD34=94052=20260120-14:03:46.732262=MD_EUR/USD_140109278614268=3279=1269=1270=1.1982271=10000055=EUR/USD110=0279=1269=1270=1.1982271=50000055=EUR/USD110=100000279=1269=1270=1.1982271=100000055=EUR/USD110=50000010=070
20260120-14:03:46.255559000 : 8=FIX.4.49=068335=X49=NTPRO_IDBA_UAT56=SIRIUS_500007460_MD34=94152=20260120-14:03:46.841262=MD_GBP/USD_140109778778268=10279=2269=0270=1.25467271=10000055=GBP/USD110=0279=2269=0270=1.25467271=50000055=GBP/USD110=100000279=2269=0270=1.25467271=100000055=GBP/USD110=500000279=2269=0270=1.25467271=300000055=GBP/USD110=1000000279=2269=0270=1.25467271=500000055=GBP/USD110=3000000279=2269=1270=1.43503271=10000055=GBP/USD110=0279=2269=1270=1.43503271=50000055=GBP/USD110=100000279=2269=1270=1.43503271=100000055=GBP/USD110=500000279=2269=1270=1.43503271=300000055=GBP/USD110=1000000279=2269=1270=1.43503271=500000055=GBP/USD110=300000010=202
20260120-14:03:46.493342000 : 8=FIX.4.49=027935=X49=NTPRO_IDBA_UAT56=SIRIUS_500007460_MD34=94252=20260120-14:03:47.087262=MD_EUR/USD_140109278614268=3279=1269=1270=1.19819271=10000055=EUR/USD110=0279=1269=1270=1.19819271=50000055=EUR/USD110=100000279=1269=1270=1.19819271=100000055=EUR/USD110=50000010=247
20260120-14:03:46.660607000 : 8=FIX.4.49=068335=X49=NTPRO_IDBA_UAT56=SIRIUS_500007460_MD34=94352=20260120-14:03:47.260262=MD_GBP/USD_140109778778268=10279=0269=0270=1.25468271=10000055=GBP/USD110=0279=0269=0270=1.25468271=50000055=GBP/USD110=100000279=0269=0270=1.25468271=100000055=GBP/USD110=500000279=0269=0270=1.25468271=300000055=GBP/USD110=1000000279=0269=0270=1.25468271=500000055=GBP/USD110=3000000279=0269=1270=1.43503271=10000055=GBP/USD110=0279=0269=1270=1.43503271=50000055=GBP/USD110=100000279=0269=1270=1.43503271=100000055=GBP/USD110=500000279=0269=1270=1.43503271=300000055=GBP/USD110=1000000279=0269=1270=1.43503271=500000055=GBP/USD110=300000010=185
20260120-14:03:46.731037000 : 8=FIX.4.49=044635=X49=NTPRO_IDBA_UAT56=SIRIUS_500007460_MD34=94452=20260120-14:03:47.333262=MD_EUR/USD_140109278614268=6279=1269=0270=1.14793271=10000055=EUR/USD110=0279=1269=0270=1.14793271=50000055=EUR/USD110=100000279=1269=0270=1.14793271=100000055=EUR/USD110=500000279=1269=1270=1.19817271=10000055=EUR/USD110=0279=1269=1270=1.19817271=50000055=EUR/USD110=100000279=1269=1270=1.19817271=100000055=EUR/USD110=50000010=024
20260120-14:03:46.748670000 : 8=FIX.4.49=039735=X49=NTPRO_IDBA_UAT56=SIRIUS_500007460_MD34=94552=20260120-14:03:47.352262=MD_GBP/USD_140109778778268=5279=1269=0270=1.25467271=10000055=GBP/USD110=0279=1269=0270=1.25467271=50000055=GBP/USD110=100000279=1269=0270=1.25467271=100000055=GBP/USD110=500000279=1269=0270=1.25467271=300000055=GBP/USD110=1000000279=1269=0270=1.25467271=500000055=GBP/USD110=300000010=061
20260120-14:03:46.857764000 : 8=FIX.4.49=027935=X49=NTPRO_IDBA_UAT56=SIRIUS_500007460_MD34=94652=20260120-14:03:47.465262=MD_EUR/USD_140109278614268=3279=1269=1270=1.19818271=10000055=EUR/USD110=0279=1269=1270=1.19818271=50000055=EUR/USD110=100000279=1269=1270=1.19818271=100000055=EUR/USD110=50000010=248
20260120-14:03:47.140984000 : 8=FIX.4.49=027935=X49=NTPRO_IDBA_UAT56=SIRIUS_500007460_MD34=94752=20260120-14:03:47.757262=MD_EUR/USD_140109278614268=3279=1269=0270=1.14794271=10000055=EUR/USD110=0279=1269=0270=1.14794271=50000055=EUR/USD110=100000279=1269=0270=1.14794271=100000055=EUR/USD110=50000010=244
20260120-14:03:47.294879000 : 8=FIX.4.49=044335=X49=NTPRO_IDBA_UAT56=SIRIUS_500007460_MD34=94852=20260120-14:03:47.919262=MD_EUR/USD_140109278614268=6279=1269=0270=1.14795271=10000055=EUR/USD110=0279=1269=0270=1.14795271=50000055=EUR/USD110=100000279=1269=0270=1.14795271=100000055=EUR/USD110=500000279=1269=1270=1.1982271=10000055=EUR/USD110=0279=1269=1270=1.1982271=50000055=EUR/USD110=100000279=1269=1270=1.1982271=100000055=EUR/USD110=50000010=135
20260120-14:03:47.366039000 : 8=FIX.4.49=027935=X49=NTPRO_IDBA_UAT56=SIRIUS_500007460_MD34=94952=20260120-14:03:47.992262=MD_EUR/USD_140109278614268=3279=1269=1270=1.19819271=10000055=EUR/USD110=0279=1269=1270=1.19819271=50000055=EUR/USD110=100000279=1269=1270=1.19819271=100000055=EUR/USD110=50000010=003
20260120-14:03:47.418517000 : 8=FIX.4.49=027635=X49=NTPRO_IDBA_UAT56=SIRIUS_500007460_MD34=95052=20260120-14:03:48.033262=MD_EUR/USD_140109278614268=3279=1269=1270=1.1982271=10000055=EUR/USD110=0279=1269=1270=1.1982271=50000055=EUR/USD110=100000279=1269=1270=1.1982271=100000055=EUR/USD110=50000010=067
20260120-14:03:47.452039000 : 8=FIX.4.49=039735=X49=NTPRO_IDBA_UAT56=SIRIUS_500007460_MD34=95152=20260120-14:03:48.081262=MD_GBP/USD_140109778778268=5279=1269=0270=1.25468271=10000055=GBP/USD110=0279=1269=0270=1.25468271=50000055=GBP/USD110=100000279=1269=0270=1.25468271=100000055=GBP/USD110=500000279=1269=0270=1.25468271=300000055=GBP/USD110=1000000279=1269=0270=1.25468271=500000055=GBP/USD110=300000010=063
20260120-14:03:47.570721000 : 8=FIX.4.49=027935=X49=NTPRO_IDBA_UAT56=SIRIUS_500007460_MD34=95252=20260120-14:03:48.187262=MD_EUR/USD_140109278614268=3279=1269=1270=1.19819271=10000055=EUR/USD110=0279=1269=1270=1.19819271=50000055=EUR/USD110=100000279=1269=1270=1.19819271=100000055=EUR/USD110=50000010=250
20260120-14:03:47.591597000 : 8=FIX.4.49=027635=X49=NTPRO_IDBA_UAT56=SIRIUS_500007460_MD34=95352=20260120-14:03:48.218262=MD_EUR/USD_140109278614268=3279=1269=1270=1.1982271=10000055=EUR/USD110=0279=1269=1270=1.1982271=50000055=EUR/USD110=100000279=1269=1270=1.1982271=100000055=EUR/USD110=50000010=075
20260120-14:03:48.058618000 : 8=FIX.4.49=068335=X49=NTPRO_IDBA_UAT56=SIRIUS_500007460_MD34=95452=20260120-14:03:48.711262=MD_GBP/USD_140109778778268=10279=2269=0270=1.25468271=10000055=GBP/USD110=0279=2269=0270=1.25468271=50000055=GBP/USD110=100000279=2269=0270=1.25468271=100000055=GBP/USD110=500000279=2269=0270=1.25468271=300000055=GBP/USD110=1000000279=2269=0270=1.25468271=500000055=GBP/USD110=3000000279=2269=1270=1.43503271=10000055=GBP/USD110=0279=2269=1270=1.43503271=50000055=GBP/USD110=100000279=2269=1270=1.43503271=100000055=GBP/USD110=500000279=2269=1270=1.43503271=300000055=GBP/USD110=1000000279=2269=1270=1.43503271=500000055=GBP/USD110=300000010=209
20260120-14:03:48.129741000 : 8=FIX.4.49=068335=X49=NTPRO_IDBA_UAT56=SIRIUS_500007460_MD34=95552=20260120-14:03:48.782262=MD_GBP/USD_140109778778268=10279=0269=0270=1.25467271=10000055=GBP/USD110=0279=0269=0270=1.25467271=50000055=GBP/USD110=100000279=0269=0270=1.25467271=100000055=GBP/USD110=500000279=0269=0270=1.25467271=300000055=GBP/USD110=1000000279=0269=0270=1.25467271=500000055=GBP/USD110=3000000279=0269=1270=1.43503271=10000055=GBP/USD110=0279=0269=1270=1.43503271=50000055=GBP/USD110=100000279=0269=1270=1.43503271=100000055=GBP/USD110=500000279=0269=1270=1.43503271=300000055=GBP/USD110=1000000279=0269=1270=1.43503271=500000055=GBP/USD110=300000010=193
20260120-14:03:48.351415000 : 8=FIX.4.49=039735=X49=NTPRO_IDBA_UAT56=SIRIUS_500007460_MD34=95652=20260120-14:03:49.013262=MD_GBP/USD_140109778778268=5279=1269=0270=1.25468271=10000055=GBP/USD110=0279=1269=0270=1.25468271=50000055=GBP/USD110=100000279=1269=0270=1.25468271=100000055=GBP/USD110=500000279=1269=0270=1.25468271=300000055=GBP/USD110=1000000279=1269=0270=1.25468271=500000055=GBP/USD110=300000010=064
20260120-14:03:48.382050000 : 8=FIX.4.49=067835=X49=NTPRO_IDBA_UAT56=SIRIUS_500007460_MD34=95752=20260120-14:03:49.046262=MD_GBP/USD_140109778778268=10279=1269=0270=1.2547271=10000055=GBP/USD110=0279=1269=0270=1.2547271=50000055=GBP/USD110=100000279=1269=0270=1.2547271=100000055=GBP/USD110=500000279=1269=0270=1.2547271=300000055=GBP/USD110=1000000279=1269=0270=1.2547271=500000055=GBP/USD110=3000000279=1269=1270=1.43504271=10000055=GBP/USD110=0279=1269=1270=1.43504271=50000055=GBP/USD110=100000279=1269=1270=1.43504271=100000055=GBP/USD110=500000279=1269=1270=1.43504271=300000055=GBP/USD110=1000000279=1269=1270=1.43504271=500000055=GBP/USD110=300000010=194
20260120-14:03:48.415799000 : 8=FIX.4.49=039735=X49=NTPRO_IDBA_UAT56=SIRIUS_500007460_MD34=95852=20260120-14:03:49.081262=MD_GBP/USD_140109778778268=5279=1269=0270=1.25472271=10000055=GBP/USD110=0279=1269=0270=1.25472271=50000055=GBP/USD110=100000279=1269=0270=1.25472271=100000055=GBP/USD110=500000279=1269=0270=1.25472271=300000055=GBP/USD110=1000000279=1269=0270=1.25472271=500000055=GBP/USD110=300000010=046
20260120-14:03:48.447486000 : 8=FIX.4.49=068335=X49=NTPRO_IDBA_UAT56=SIRIUS_500007460_MD34=95952=20260120-14:03:49.107262=MD_GBP/USD_140109778778268=10279=1269=0270=1.25473271=10000055=GBP/USD110=0279=1269=0270=1.25473271=50000055=GBP/USD110=100000279=1269=0270=1.25473271=100000055=GBP/USD110=500000279=1269=0270=1.25473271=300000055=GBP/USD110=1000000279=1269=0270=1.25473271=500000055=GBP/USD110=3000000279=1269=1270=1.43505271=10000055=GBP/USD110=0279=1269=1270=1.43505271=50000055=GBP/USD110=100000279=1269=1270=1.43505271=100000055=GBP/USD110=500000279=1269=1270=1.43505271=300000055=GBP/USD110=1000000279=1269=1270=1.43505271=500000055=GBP/USD110=300000010=194
20260120-14:03:48.501095000 : 8=FIX.4.49=068335=X49=NTPRO_IDBA_UAT56=SIRIUS_500007460_MD34=96052=20260120-14:03:49.157262=MD_GBP/USD_140109778778268=10279=1269=0270=1.25474271=10000055=GBP/USD110=0279=1269=0270=1.25474271=50000055=GBP/USD110=100000279=1269=0270=1.25474271=100000055=GBP/USD110=500000279=1269=0270=1.25474271=300000055=GBP/USD110=1000000279=1269=0270=1.25474271=500000055=GBP/USD110=3000000279=1269=1270=1.43509271=10000055=GBP/USD110=0279=1269=1270=1.43509271=50000055=GBP/USD110=100000279=1269=1270=1.43509271=100000055=GBP/USD110=500000279=1269=1270=1.43509271=300000055=GBP/USD110=1000000279=1269=1270=1.43509271=500000055=GBP/USD110=300000010=216
20260120-14:03:48.561362000 : 8=FIX.4.49=039235=X49=NTPRO_IDBA_UAT56=SIRIUS_500007460_MD34=96152=20260120-14:03:49.232262=MD_GBP/USD_140109778778268=5279=1269=1270=1.4351271=10000055=GBP/USD110=0279=1269=1270=1.4351271=50000055=GBP/USD110=100000279=1269=1270=1.4351271=100000055=GBP/USD110=500000279=1269=1270=1.4351271=300000055=GBP/USD110=1000000279=1269=1270=1.4351271=500000055=GBP/USD110=300000010=019
20260120-14:03:50.286520000 : 8=FIX.4.49=067835=X49=NTPRO_IDBA_UAT56=SIRIUS_500007460_MD34=96252=20260120-14:03:51.021262=MD_GBP/USD_140109778778268=10279=2269=0270=1.25474271=10000055=GBP/USD110=0279=2269=0270=1.25474271=50000055=GBP/USD110=100000279=2269=0270=1.25474271=100000055=GBP/USD110=500000279=2269=0270=1.25474271=300000055=GBP/USD110=1000000279=2269=0270=1.25474271=500000055=GBP/USD110=3000000279=2269=1270=1.4351271=10000055=GBP/USD110=0279=2269=1270=1.4351271=50000055=GBP/USD110=100000279=2269=1270=1.4351271=100000055=GBP/USD110=500000279=2269=1270=1.4351271=300000055=GBP/USD110=1000000279=2269=1270=1.4351271=500000055=GBP/USD110=300000010=191
20260120-14:03:51.227563000 : 8=FIX.4.49=068335=X49=NTPRO_IDBA_UAT56=SIRIUS_500007460_MD34=96352=20260120-14:03:51.997262=MD_GBP/USD_140109778778268=10279=0269=0270=1.25473271=10000055=GBP/USD110=0279=0269=0270=1.25473271=50000055=GBP/USD110=100000279=0269=0270=1.25473271=100000055=GBP/USD110=500000279=0269=0270=1.25473271=300000055=GBP/USD110=1000000279=0269=0270=1.25473271=500000055=GBP/USD110=3000000279=0269=1270=1.43509271=10000055=GBP/USD110=0279=0269=1270=1.43509271=50000055=GBP/USD110=100000279=0269=1270=1.43509271=100000055=GBP/USD110=500000279=0269=1270=1.43509271=300000055=GBP/USD110=1000000279=0269=1270=1.43509271=500000055=GBP/USD110=300000010=209
20260120-14:03:51.257871000 : 8=FIX.4.49=068335=X49=NTPRO_IDBA_UAT56=SIRIUS_500007460_MD34=96452=20260120-14:03:52.025262=MD_GBP/USD_140109778778268=10279=2269=0270=1.25473271=10000055=GBP/USD110=0279=2269=0270=1.25473271=50000055=GBP/USD110=100000279=2269=0270=1.25473271=100000055=GBP/USD110=500000279=2269=0270=1.25473271=300000055=GBP/USD110=1000000279=2269=0270=1.25473271=500000055=GBP/USD110=3000000279=2269=1270=1.43509271=10000055=GBP/USD110=0279=2269=1270=1.43509271=50000055=GBP/USD110=100000279=2269=1270=1.43509271=100000055=GBP/USD110=500000279=2269=1270=1.43509271=300000055=GBP/USD110=1000000279=2269=1270=1.43509271=500000055=GBP/USD110=300000010=213
20260120-14:03:51.276511000 : 8=FIX.4.49=044635=X49=NTPRO_IDBA_UAT56=SIRIUS_500007460_MD34=96552=20260120-14:03:52.045262=MD_EUR/USD_140109278614268=6279=1269=0270=1.14794271=10000055=EUR/USD110=0279=1269=0270=1.14794271=50000055=EUR/USD110=100000279=1269=0270=1.14794271=100000055=EUR/USD110=500000279=1269=1270=1.19818271=10000055=EUR/USD110=0279=1269=1270=1.19818271=50000055=EUR/USD110=100000279=1269=1270=1.19818271=100000055=EUR/USD110=50000010=029
20260120-14:03:51.304562000 : 8=FIX.4.49=068335=X49=NTPRO_IDBA_UAT56=SIRIUS_500007460_MD34=96652=20260120-14:03:52.076262=MD_GBP/USD_140109778778268=10279=0269=0270=1.25468271=10000055=GBP/USD110=0279=0269=0270=1.25468271=50000055=GBP/USD110=100000279=0269=0270=1.25468271=100000055=GBP/USD110=500000279=0269=0270=1.25468271=300000055=GBP/USD110=1000000279=0269=0270=1.25468271=500000055=GBP/USD110=3000000279=0269=1270=1.43506271=10000055=GBP/USD110=0279=0269=1270=1.43506271=50000055=GBP/USD110=100000279=0269=1270=1.43506271=100000055=GBP/USD110=500000279=0269=1270=1.43506271=300000055=GBP/USD110=1000000279=0269=1270=1.43506271=500000055=GBP/USD110=300000010=206
20260120-14:03:51.369160000 : 8=FIX.4.49=068335=X49=NTPRO_IDBA_UAT56=SIRIUS_500007460_MD34=96752=20260120-14:03:52.118262=MD_GBP/USD_140109778778268=10279=1269=0270=1.25467271=10000055=GBP/USD110=0279=1269=0270=1.25467271=50000055=GBP/USD110=100000279=1269=0270=1.25467271=100000055=GBP/USD110=500000279=1269=0270=1.25467271=300000055=GBP/USD110=1000000279=1269=0270=1.25467271=500000055=GBP/USD110=3000000279=1269=1270=1.43503271=10000055=GBP/USD110=0279=1269=1270=1.43503271=50000055=GBP/USD110=100000279=1269=1270=1.43503271=100000055=GBP/USD110=500000279=1269=1270=1.43503271=300000055=GBP/USD110=1000000279=1269=1270=1.43503271=500000055=GBP/USD110=300000010=194
20260120-14:03:51.392591000 : 8=FIX.4.49=039735=X49=NTPRO_IDBA_UAT56=SIRIUS_500007460_MD34=96852=20260120-14:03:52.168262=MD_GBP/USD_140109778778268=5279=1269=0270=1.25468271=10000055=GBP/USD110=0279=1269=0270=1.25468271=50000055=GBP/USD110=100000279=1269=0270=1.25468271=100000055=GBP/USD110=500000279=1269=0270=1.25468271=300000055=GBP/USD110=1000000279=1269=0270=1.25468271=500000055=GBP/USD110=300000010=072
20260120-14:03:51.542713000 : 8=FIX.4.49=039735=X49=NTPRO_IDBA_UAT56=SIRIUS_500007460_MD34=96952=20260120-14:03:52.324262=MD_GBP/USD_140109778778268=5279=1269=0270=1.25467271=10000055=GBP/USD110=0279=1269=0270=1.25467271=50000055=GBP/USD110=100000279=1269=0270=1.25467271=100000055=GBP/USD110=500000279=1269=0270=1.25467271=300000055=GBP/USD110=1000000279=1269=0270=1.25467271=500000055=GBP/USD110=300000010=062
20260120-14:03:51.698512000 : 8=FIX.4.49=027935=X49=NTPRO_IDBA_UAT56=SIRIUS_500007460_MD34=97052=20260120-14:03:52.485262=MD_EUR/USD_140109278614268=3279=1269=0270=1.14793271=10000055=EUR/USD110=0279=1269=0270=1.14793271=50000055=EUR/USD110=100000279=1269=0270=1.14793271=100000055=EUR/USD110=50000010=231
20260120-14:03:51.758053000 : 8=FIX.4.49=027935=X49=NTPRO_IDBA_UAT56=SIRIUS_500007460_MD34=97152=20260120-14:03:52.541262=MD_EUR/USD_140109278614268=3279=1269=1270=1.19817271=10000055=EUR/USD110=0279=1269=1270=1.19817271=50000055=EUR/USD110=100000279=1269=1270=1.19817271=100000055=EUR/USD110=50000010=234
20260120-14:03:51.771757000 : 8=FIX.4.49=039735=X49=NTPRO_IDBA_UAT56=SIRIUS_500007460_MD34=97252=20260120-14:03:52.558262=MD_GBP/USD_140109778778268=5279=1269=0270=1.25468271=10000055=GBP/USD110=0279=1269=0270=1.25468271=50000055=GBP/USD110=100000279=1269=0270=1.25468271=100000055=GBP/USD110=500000279=1269=0270=1.25468271=300000055=GBP/USD110=1000000279=1269=0270=1.25468271=500000055=GBP/USD110=300000010=070
20260120-14:03:52.335290000 : 8=FIX.4.49=027935=X49=NTPRO_IDBA_UAT56=SIRIUS_500007460_MD34=97352=20260120-14:03:53.144262=MD_EUR/USD_140109278614268=3279=1269=1270=1.19818271=10000055=EUR/USD110=0279=1269=1270=1.19818271=50000055=EUR/USD110=100000279=1269=1270=1.19818271=100000055=EUR/USD110=50000010=239
20260120-14:03:52.825298000 : 8=FIX.4.49=027935=X49=NTPRO_IDBA_UAT56=SIRIUS_500007460_MD34=97452=20260120-14:03:53.652262=MD_EUR/USD_140109278614268=3279=1269=1270=1.19817271=10000055=EUR/USD110=0279=1269=1270=1.19817271=50000055=EUR/USD110=100000279=1269=1270=1.19817271=100000055=EUR/USD110=50000010=241
20260120-14:03:52.845455000 : 8=FIX.4.49=039735=X49=NTPRO_IDBA_UAT56=SIRIUS_500007460_MD34=97552=20260120-14:03:53.665262=MD_GBP/USD_140109778778268=5279=1269=0270=1.25467271=10000055=GBP/USD110=0279=1269=0270=1.25467271=50000055=GBP/USD110=100000279=1269=0270=1.25467271=100000055=GBP/USD110=500000279=1269=0270=1.25467271=300000055=GBP/USD110=1000000279=1269=0270=1.25467271=500000055=GBP/USD110=300000010=068
20260120-14:03:52.849661000 : 8=FIX.4.49=027935=X49=NTPRO_IDBA_UAT56=SIRIUS_500007460_MD34=97652=20260120-14:03:53.676262=MD_EUR/USD_140109278614268=3279=1269=0270=1.14792271=10000055=EUR/USD110=0279=1269=0270=1.14792271=50000055=EUR/USD110=100000279=1269=0270=1.14792271=100000055=EUR/USD110=50000010=237
20260120-14:03:52.914225000 : 8=FIX.4.49=044635=X49=NTPRO_IDBA_UAT56=SIRIUS_500007460_MD34=97752=20260120-14:03:53.743262=MD_EUR/USD_140109278614268=6279=1269=0270=1.14793271=10000055=EUR/USD110=0279=1269=0270=1.14793271=50000055=EUR/USD110=100000279=1269=0270=1.14793271=100000055=EUR/USD110=500000279=1269=1270=1.19818271=10000055=EUR/USD110=0279=1269=1270=1.19818271=50000055=EUR/USD110=100000279=1269=1270=1.19818271=100000055=EUR/USD110=50000010=035
20260120-14:03:52.954576000 : 8=FIX.4.49=039735=X49=NTPRO_IDBA_UAT56=SIRIUS_500007460_MD34=97852=20260120-14:03:53.785262=MD_GBP/USD_140109778778268=5279=1269=0270=1.25468271=10000055=GBP/USD110=0279=1269=0270=1.25468271=50000055=GBP/USD110=100000279=1269=0270=1.25468271=100000055=GBP/USD110=500000279=1269=0270=1.25468271=300000055=GBP/USD110=1000000279=1269=0270=1.25468271=500000055=GBP/USD110=300000010=079
20260120-14:03:53.045740000 : 8=FIX.4.49=039735=X49=NTPRO_IDBA_UAT56=SIRIUS_500007460_MD34=97952=20260120-14:03:53.878262=MD_GBP/USD_140109778778268=5279=1269=0270=1.25467271=10000055=GBP/USD110=0279=1269=0270=1.25467271=50000055=GBP/USD110=100000279=1269=0270=1.25467271=100000055=GBP/USD110=500000279=1269=0270=1.25467271=300000055=GBP/USD110=1000000279=1269=0270=1.25467271=500000055=GBP/USD110=300000010=078
20260120-14:03:53.740039000 : 8=FIX.4.49=027935=X49=NTPRO_IDBA_UAT56=SIRIUS_500007460_MD34=98052=20260120-14:03:54.591262=MD_EUR/USD_140109278614268=3279=1269=1270=1.19817271=10000055=EUR/USD110=0279=1269=1270=1.19817271=50000055=EUR/USD110=100000279=1269=1270=1.19817271=100000055=EUR/USD110=50000010=241
20260120-14:03:53.793613000 : 8=FIX.4.49=027935=X49=NTPRO_IDBA_UAT56=SIRIUS_500007460_MD34=98152=20260120-14:03:54.655262=MD_EUR/USD_140109278614268=3279=1269=1270=1.19818271=10000055=EUR/USD110=0279=1269=1270=1.19818271=50000055=EUR/USD110=100000279=1269=1270=1.19818271=100000055=EUR/USD110=50000010=246
20260120-14:03:53.836044000 : 8=FIX.4.49=027935=X49=NTPRO_IDBA_UAT56=SIRIUS_500007460_MD34=98252=20260120-14:03:54.691262=MD_EUR/USD_140109278614268=3279=1269=1270=1.19817271=10000055=EUR/USD110=0279=1269=1270=1.19817271=50000055=EUR/USD110=100000279=1269=1270=1.19817271=100000055=EUR/USD110=50000010=244
20260120-14:03:54.332754000 : 8=FIX.4.49=027935=X49=NTPRO_IDBA_UAT56=SIRIUS_500007460_MD34=98352=20260120-14:03:55.212262=MD_EUR/USD_140109278614268=3279=1269=0270=1.14792271=10000055=EUR/USD110=0279=1269=0270=1.14792271=50000055=EUR/USD110=100000279=1269=0270=1.14792271=100000055=EUR/USD110=50000010=223
20260120-14:03:54.552136000 : 8=FIX.4.49=027935=X49=NTPRO_IDBA_UAT56=SIRIUS_500007460_MD34=98452=20260120-14:03:55.432262=MD_EUR/USD_140109278614268=3279=1269=0270=1.14793271=10000055=EUR/USD110=0279=1269=0270=1.14793271=50000055=EUR/USD110=100000279=1269=0270=1.14793271=100000055=EUR/USD110=50000010=231
20260120-14:03:54.926053000 : 8=FIX.4.49=068335=X49=NTPRO_IDBA_UAT56=SIRIUS_500007460_MD34=98552=20260120-14:03:55.810262=MD_GBP/USD_140109778778268=10279=2269=0270=1.25467271=10000055=GBP/USD110=0279=2269=0270=1.25467271=50000055=GBP/USD110=100000279=2269=0270=1.25467271=100000055=GBP/USD110=500000279=2269=0270=1.25467271=300000055=GBP/USD110=1000000279=2269=0270=1.25467271=500000055=GBP/USD110=3000000279=2269=1270=1.43503271=10000055=GBP/USD110=0279=2269=1270=1.43503271=50000055=GBP/USD110=100000279=2269=1270=1.43503271=100000055=GBP/USD110=500000279=2269=1270=1.43503271=300000055=GBP/USD110=1000000279=2269=1270=1.43503271=500000055=GBP/USD110=300000010=206
20260120-14:03:55.457613000 : 8=FIX.4.49=027935=X49=NTPRO_IDBA_UAT56=SIRIUS_500007460_MD34=98652=20260120-14:03:56.377262=MD_EUR/USD_140109278614268=3279=1269=0270=1.14792271=10000055=EUR/USD110=0279=1269=0270=1.14792271=50000055=EUR/USD110=100000279=1269=0270=1.14792271=100000055=EUR/USD110=50000010=239
20260120-14:03:55.477312000 : 8=FIX.4.49=027935=X49=NTPRO_IDBA_UAT56=SIRIUS_500007460_MD34=98752=20260120-14:03:56.396262=MD_EUR/USD_140109278614268=3279=1269=0270=1.14793271=10000055=EUR/USD110=0279=1269=0270=1.14793271=50000055=EUR/USD110=100000279=1269=0270=1.14793271=100000055=EUR/USD110=50000010=244
20260120-14:03:56.013452000 : 8=FIX.4.49=027935=X49=NTPRO_IDBA_UAT56=SIRIUS_500007460_MD34=98852=20260120-14:03:56.954262=MD_EUR/USD_140109278614268=3279=1269=0270=1.14792271=10000055=EUR/USD110=0279=1269=0270=1.14792271=50000055=EUR/USD110=100000279=1269=0270=1.14792271=100000055=EUR/USD110=50000010=242
20260120-14:03:56.072395000 : 8=FIX.4.49=027935=X49=NTPRO_IDBA_UAT56=SIRIUS_500007460_MD34=98952=20260120-14:03:57.015262=MD_EUR/USD_140109278614268=3279=1269=1270=1.19818271=10000055=EUR/USD110=0279=1269=1270=1.19818271=50000055=EUR/USD110=100000279=1269=1270=1.19818271=100000055=EUR/USD110=50000010=247
20260120-14:03:56.133749000 : 8=FIX.4.49=068335=X49=NTPRO_IDBA_UAT56=SIRIUS_500007460_MD34=99052=20260120-14:03:57.078262=MD_GBP/USD_140109778778268=10279=0269=0270=1.25467271=10000055=GBP/USD110=0279=0269=0270=1.25467271=50000055=GBP/USD110=100000279=0269=0270=1.25467271=100000055=GBP/USD110=500000279=0269=0270=1.25467271=300000055=GBP/USD110=1000000279=0269=0270=1.25467271=500000055=GBP/USD110=3000000279=0269=1270=1.43503271=10000055=GBP/USD110=0279=0269=1270=1.43503271=50000055=GBP/USD110=100000279=0269=1270=1.43503271=100000055=GBP/USD110=500000279=0269=1270=1.43503271=300000055=GBP/USD110=1000000279=0269=1270=1.43503271=500000055=GBP/USD110=300000010=190
20260120-14:03:56.145926000 : 8=FIX.4.49=044335=X49=NTPRO_IDBA_UAT56=SIRIUS_500007460_MD34=99152=20260120-14:03:57.091262=MD_EUR/USD_140109278614268=6279=1269=0270=1.14795271=10000055=EUR/USD110=0279=1269=0270=1.14795271=50000055=EUR/USD110=100000279=1269=0270=1.14795271=100000055=EUR/USD110=500000279=1269=1270=1.1982271=10000055=EUR/USD110=0279=1269=1270=1.1982271=50000055=EUR/USD110=100000279=1269=1270=1.1982271=100000055=EUR/USD110=50000010=125
20260120-14:03:56.185994000 : 8=FIX.4.49=068335=X49=NTPRO_IDBA_UAT56=SIRIUS_500007460_MD34=99252=20260120-14:03:57.131262=MD_GBP/USD_140109778778268=10279=2269=0270=1.25467271=10000055=GBP/USD110=0279=2269=0270=1.25467271=50000055=GBP/USD110=100000279=2269=0270=1.25467271=100000055=GBP/USD110=500000279=2269=0270=1.25467271=300000055=GBP/USD110=1000000279=2269=0270=1.25467271=500000055=GBP/USD110=3000000279=2269=1270=1.43503271=10000055=GBP/USD110=0279=2269=1270=1.43503271=50000055=GBP/USD110=100000279=2269=1270=1.43503271=100000055=GBP/USD110=500000279=2269=1270=1.43503271=300000055=GBP/USD110=1000000279=2269=1270=1.43503271=500000055=GBP/USD110=300000010=202
20260120-14:03:56.259453000 : 8=FIX.4.49=044635=X49=NTPRO_IDBA_UAT56=SIRIUS_500007460_MD34=99352=20260120-14:03:57.207262=MD_EUR/USD_140109278614268=6279=1269=0270=1.14794271=10000055=EUR/USD110=0279=1269=0270=1.14794271=50000055=EUR/USD110=100000279=1269=0270=1.14794271=100000055=EUR/USD110=500000279=1269=1270=1.19819271=10000055=EUR/USD110=0279=1269=1270=1.19819271=50000055=EUR/USD110=100000279=1269=1270=1.19819271=100000055=EUR/USD110=50000010=038
20260120-14:03:56.376025000 : 8=FIX.4.49=044335=X49=NTPRO_IDBA_UAT56=SIRIUS_500007460_MD34=99452=20260120-14:03:57.303262=MD_EUR/USD_140109278614268=6279=1269=0270=1.14796271=10000055=EUR/USD110=0279=1269=0270=1.14796271=50000055=EUR/USD110=100000279=1269=0270=1.14796271=100000055=EUR/USD110=500000279=1269=1270=1.1982271=10000055=EUR/USD110=0279=1269=1270=1.1982271=50000055=EUR/USD110=100000279=1269=1270=1.1982271=100000055=EUR/USD110=50000010=127
20260120-14:03:56.454772000 : 8=FIX.4.49=044635=X49=NTPRO_IDBA_UAT56=SIRIUS_500007460_MD34=99552=20260120-14:03:57.406262=MD_EUR/USD_140109278614268=6279=1269=0270=1.14798271=10000055=EUR/USD110=0279=1269=0270=1.14798271=50000055=EUR/USD110=100000279=1269=0270=1.14798271=100000055=EUR/USD110=500000279=1269=1270=1.19822271=10000055=EUR/USD110=0279=1269=1270=1.19822271=50000055=EUR/USD110=100000279=1269=1270=1.19822271=100000055=EUR/USD110=50000010=035
20260120-14:03:56.482250000 : 8=FIX.4.49=068335=X49=NTPRO_IDBA_UAT56=SIRIUS_500007460_MD34=99652=20260120-14:03:57.436262=MD_GBP/USD_140109778778268=10279=0269=0270=1.25471271=10000055=GBP/USD110=0279=0269=0270=1.25471271=50000055=GBP/USD110=100000279=0269=0270=1.25471271=100000055=GBP/USD110=500000279=0269=0270=1.25471271=300000055=GBP/USD110=1000000279=0269=0270=1.25471271=500000055=GBP/USD110=3000000279=0269=1270=1.43506271=10000055=GBP/USD110=0279=0269=1270=1.43506271=50000055=GBP/USD110=100000279=0269=1270=1.43506271=100000055=GBP/USD110=500000279=0269=1270=1.43506271=300000055=GBP/USD110=1000000279=0269=1270=1.43506271=500000055=GBP/USD110=300000010=184
20260120-14:03:56.544059000 : 8=FIX.4.49=068335=X49=NTPRO_IDBA_UAT56=SIRIUS_500007460_MD34=99752=20260120-14:03:57.504262=MD_GBP/USD_140109778778268=10279=1269=0270=1.25472271=10000055=GBP/USD110=0279=1269=0270=1.25472271=50000055=GBP/USD110=100000279=1269=0270=1.25472271=100000055=GBP/USD110=500000279=1269=0270=1.25472271=300000055=GBP/USD110=1000000279=1269=0270=1.25472271=500000055=GBP/USD110=3000000279=1269=1270=1.43508271=10000055=GBP/USD110=0279=1269=1270=1.43508271=50000055=GBP/USD110=100000279=1269=1270=1.43508271=100000055=GBP/USD110=500000279=1269=1270=1.43508271=300000055=GBP/USD110=1000000279=1269=1270=1.43508271=500000055=GBP/USD110=300000010=206
20260120-14:03:56.580936000 : 8=FIX.4.49=044635=X49=NTPRO_IDBA_UAT56=SIRIUS_500007460_MD34=99852=20260120-14:03:57.539262=MD_EUR/USD_140109278614268=6279=1269=0270=1.14796271=10000055=EUR/USD110=0279=1269=0270=1.14796271=50000055=EUR/USD110=100000279=1269=0270=1.14796271=100000055=EUR/USD110=500000279=1269=1270=1.19821271=10000055=EUR/USD110=0279=1269=1270=1.19821271=50000055=EUR/USD110=100000279=1269=1270=1.19821271=100000055=EUR/USD110=50000010=036
20260120-14:03:56.605046000 : 8=FIX.4.49=068335=X49=NTPRO_IDBA_UAT56=SIRIUS_500007460_MD34=99952=20260120-14:03:57.561262=MD_GBP/USD_140109778778268=10279=2269=0270=1.25472271=10000055=GBP/USD110=0279=2269=0270=1.25472271=50000055=GBP/USD110=100000279=2269=0270=1.25472271=100000055=GBP/USD110=500000279=2269=0270=1.25472271=300000055=GBP/USD110=1000000279=2269=0270=1.25472271=500000055=GBP/USD110=3000000279=2269=1270=1.43508271=10000055=GBP/USD110=0279=2269=1270=1.43508271=50000055=GBP/USD110=100000279=2269=1270=1.43508271=100000055=GBP/USD110=500000279=2269=1270=1.43508271=300000055=GBP/USD110=1000000279=2269=1270=1.43508271=500000055=GBP/USD110=300000010=221
20260120-14:03:56.695347000 : 8=FIX.4.49=044435=X49=NTPRO_IDBA_UAT56=SIRIUS_500007460_MD34=100052=20260120-14:03:57.658262=MD_EUR/USD_140109278614268=6279=1269=0270=1.14795271=10000055=EUR/USD110=0279=1269=0270=1.14795271=50000055=EUR/USD110=100000279=1269=0270=1.14795271=100000055=EUR/USD110=500000279=1269=1270=1.1982271=10000055=EUR/USD110=0279=1269=1270=1.1982271=50000055=EUR/USD110=100000279=1269=1270=1.1982271=100000055=EUR/USD110=50000010=165
20260120-14:03:56.855813000 : 8=FIX.4.49=068435=X49=NTPRO_IDBA_UAT56=SIRIUS_500007460_MD34=100152=20260120-14:03:57.826262=MD_GBP/USD_140109778778268=10279=0269=0270=1.25471271=10000055=GBP/USD110=0279=0269=0270=1.25471271=50000055=GBP/USD110=100000279=0269=0270=1.25471271=100000055=GBP/USD110=500000279=0269=0270=1.25471271=300000055=GBP/USD110=1000000279=0269=0270=1.25471271=500000055=GBP/USD110=3000000279=0269=1270=1.43506271=10000055=GBP/USD110=0279=0269=1270=1.43506271=50000055=GBP/USD110=100000279=0269=1270=1.43506271=100000055=GBP/USD110=500000279=0269=1270=1.43506271=300000055=GBP/USD110=1000000279=0269=1270=1.43506271=500000055=GBP/USD110=300000010=214
20260120-14:03:56.856454000 : 8=FIX.4.49=044735=X49=NTPRO_IDBA_UAT56=SIRIUS_500007460_MD34=100252=20260120-14:03:57.826262=MD_EUR/USD_140109278614268=6279=1269=0270=1.14796271=10000055=EUR/USD110=0279=1269=0270=1.14796271=50000055=EUR/USD110=100000279=1269=0270=1.14796271=100000055=EUR/USD110=500000279=1269=1270=1.19821271=10000055=EUR/USD110=0279=1269=1270=1.19821271=50000055=EUR/USD110=100000279=1269=1270=1.19821271=100000055=EUR/USD110=50000010=061
20260120-14:03:56.924297000 : 8=FIX.4.49=044735=X49=NTPRO_IDBA_UAT56=SIRIUS_500007460_MD34=100352=20260120-14:03:57.896262=MD_EUR/USD_140109278614268=6279=1269=0270=1.14797271=10000055=EUR/USD110=0279=1269=0270=1.14797271=50000055=EUR/USD110=100000279=1269=0270=1.14797271=100000055=EUR/USD110=500000279=1269=1270=1.19822271=10000055=EUR/USD110=0279=1269=1270=1.19822271=50000055=EUR/USD110=100000279=1269=1270=1.19822271=100000055=EUR/USD110=50000010=075
20260120-14:03:56.980001000 : 8=FIX.4.49=068435=X49=NTPRO_IDBA_UAT56=SIRIUS_500007460_MD34=100452=20260120-14:03:57.955262=MD_GBP/USD_140109778778268=10279=2269=0270=1.25471271=10000055=GBP/USD110=0279=2269=0270=1.25471271=50000055=GBP/USD110=100000279=2269=0270=1.25471271=100000055=GBP/USD110=500000279=2269=0270=1.25471271=300000055=GBP/USD110=1000000279=2269=0270=1.25471271=500000055=GBP/USD110=3000000279=2269=1270=1.43506271=10000055=GBP/USD110=0279=2269=1270=1.43506271=50000055=GBP/USD110=100000279=2269=1270=1.43506271=100000055=GBP/USD110=500000279=2269=1270=1.43506271=300000055=GBP/USD110=1000000279=2269=1270=1.43506271=500000055=GBP/USD110=300000010=240
20260120-14:03:57.041990000 : 8=FIX.4.49=028035=X49=NTPRO_IDBA_UAT56=SIRIUS_500007460_MD34=100552=20260120-14:03:58.019262=MD_EUR/USD_140109278614268=3279=1269=1270=1.19821271=10000055=EUR/USD110=0279=1269=1270=1.19821271=50000055=EUR/USD110=100000279=1269=1270=1.19821271=100000055=EUR/USD110=50000010=254
20260120-14:03:57.107140000 : 8=FIX.4.49=044735=X49=NTPRO_IDBA_UAT56=SIRIUS_500007460_MD34=100652=20260120-14:03:58.053262=MD_EUR/USD_140109278614268=6279=1269=0270=1.14794271=10000055=EUR/USD110=0279=1269=0270=1.14794271=50000055=EUR/USD110=100000279=1269=0270=1.14794271=100000055=EUR/USD110=500000279=1269=1270=1.19819271=10000055=EUR/USD110=0279=1269=1270=1.19819271=50000055=EUR/USD110=100000279=1269=1270=1.19819271=100000055=EUR/USD110=50000010=073
20260120-14:03:57.107518000 : 8=FIX.4.49=044735=X49=NTPRO_IDBA_UAT56=SIRIUS_500007460_MD34=100752=20260120-14:03:58.082262=MD_EUR/USD_140109278614268=6279=1269=0270=1.14793271=10000055=EUR/USD110=0279=1269=0270=1.14793271=50000055=EUR/USD110=100000279=1269=0270=1.14793271=100000055=EUR/USD110=500000279=1269=1270=1.19818271=10000055=EUR/USD110=0279=1269=1270=1.19818271=50000055=EUR/USD110=100000279=1269=1270=1.19818271=100000055=EUR/USD110=50000010=070
20260120-14:03:57.142827000 : 8=FIX.4.49=068435=X49=NTPRO_IDBA_UAT56=SIRIUS_500007460_MD34=100852=20260120-14:03:58.122262=MD_GBP/USD_140109778778268=10279=0269=0270=1.25468271=10000055=GBP/USD110=0279=0269=0270=1.25468271=50000055=GBP/USD110=100000279=0269=0270=1.25468271=100000055=GBP/USD110=500000279=0269=0270=1.25468271=300000055=GBP/USD110=1000000279=0269=0270=1.25468271=500000055=GBP/USD110=3000000279=0269=1270=1.43504271=10000055=GBP/USD110=0279=0269=1270=1.43504271=50000055=GBP/USD110=100000279=0269=1270=1.43504271=100000055=GBP/USD110=500000279=0269=1270=1.43504271=300000055=GBP/USD110=1000000279=0269=1270=1.43504271=500000055=GBP/USD110=300000010=231
20260120-14:03:57.198191000 : 8=FIX.4.49=028035=X49=NTPRO_IDBA_UAT56=SIRIUS_500007460_MD34=100952=20260120-14:03:58.173262=MD_EUR/USD_140109278614268=3279=1269=0270=1.14794271=10000055=EUR/USD110=0279=1269=0270=1.14794271=50000055=EUR/USD110=100000279=1269=0270=1.14794271=100000055=EUR/USD110=50000010=012
20260120-14:03:57.226946000 : 8=FIX.4.49=028035=X49=NTPRO_IDBA_UAT56=SIRIUS_500007460_MD34=101052=20260120-14:03:58.211262=MD_EUR/USD_140109278614268=3279=1269=0270=1.14793271=10000055=EUR/USD110=0279=1269=0270=1.14793271=50000055=EUR/USD110=100000279=1269=0270=1.14793271=100000055=EUR/USD110=50000010=250
20260120-14:03:57.318773000 : 8=FIX.4.49=039835=X49=NTPRO_IDBA_UAT56=SIRIUS_500007460_MD34=101152=20260120-14:03:58.298262=MD_GBP/USD_140109778778268=5279=1269=1270=1.43503271=10000055=GBP/USD110=0279=1269=1270=1.43503271=50000055=GBP/USD110=100000279=1269=1270=1.43503271=100000055=GBP/USD110=500000279=1269=1270=1.43503271=300000055=GBP/USD110=1000000279=1269=1270=1.43503271=500000055=GBP/USD110=300000010=066
20260120-14:03:58.769065000 : 8=FIX.4.49=068435=X49=NTPRO_IDBA_UAT56=SIRIUS_500007460_MD34=101252=20260120-14:03:59.308262=MD_GBP/USD_140109778778268=10279=1269=0270=1.25469271=10000055=GBP/USD110=0279=1269=0270=1.25469271=50000055=GBP/USD110=100000279=1269=0270=1.25469271=100000055=GBP/USD110=500000279=1269=0270=1.25469271=300000055=GBP/USD110=1000000279=1269=0270=1.25469271=500000055=GBP/USD110=3000000279=1269=1270=1.43504271=10000055=GBP/USD110=0279=1269=1270=1.43504271=50000055=GBP/USD110=100000279=1269=1270=1.43504271=100000055=GBP/USD110=500000279=1269=1270=1.43504271=300000055=GBP/USD110=1000000279=1269=1270=1.43504271=500000055=GBP/USD110=300000010=248
20260120-14:03:58.790036000 : 8=FIX.4.49=067935=X49=NTPRO_IDBA_UAT56=SIRIUS_500007460_MD34=101352=20260120-14:03:59.329262=MD_GBP/USD_140109778778268=10279=1269=0270=1.2547271=10000055=GBP/USD110=0279=1269=0270=1.2547271=50000055=GBP/USD110=100000279=1269=0270=1.2547271=100000055=GBP/USD110=500000279=1269=0270=1.2547271=300000055=GBP/USD110=1000000279=1269=0270=1.2547271=500000055=GBP/USD110=3000000279=1269=1270=1.43506271=10000055=GBP/USD110=0279=1269=1270=1.43506271=50000055=GBP/USD110=100000279=1269=1270=1.43506271=100000055=GBP/USD110=500000279=1269=1270=1.43506271=300000055=GBP/USD110=1000000279=1269=1270=1.43506271=500000055=GBP/USD110=300000010=242
20260120-14:03:58.905436000 : 8=FIX.4.49=067935=X49=NTPRO_IDBA_UAT56=SIRIUS_500007460_MD34=101452=20260120-14:03:59.451262=MD_GBP/USD_140109778778268=10279=2269=0270=1.2547271=10000055=GBP/USD110=0279=2269=0270=1.2547271=50000055=GBP/USD110=100000279=2269=0270=1.2547271=100000055=GBP/USD110=500000279=2269=0270=1.2547271=300000055=GBP/USD110=1000000279=2269=0270=1.2547271=500000055=GBP/USD110=3000000279=2269=1270=1.43506271=10000055=GBP/USD110=0279=2269=1270=1.43506271=50000055=GBP/USD110=100000279=2269=1270=1.43506271=100000055=GBP/USD110=500000279=2269=1270=1.43506271=300000055=GBP/USD110=1000000279=2269=1270=1.43506271=500000055=GBP/USD110=300000010=249
20260120-14:03:59.142337000 : 8=FIX.4.49=028035=X49=NTPRO_IDBA_UAT56=SIRIUS_500007460_MD34=101552=20260120-14:03:59.695262=MD_EUR/USD_140109278614268=3279=1269=0270=1.14794271=10000055=EUR/USD110=0279=1269=0270=1.14794271=50000055=EUR/USD110=100000279=1269=0270=1.14794271=100000055=EUR/USD110=50000010=019
20260120-14:03:59.213515000 : 8=FIX.4.49=068435=X49=NTPRO_IDBA_UAT56=SIRIUS_500007460_MD34=101652=20260120-14:03:59.770262=MD_GBP/USD_140109778778268=10279=0269=0270=1.25471271=10000055=GBP/USD110=0279=0269=0270=1.25471271=50000055=GBP/USD110=100000279=0269=0270=1.25471271=100000055=GBP/USD110=500000279=0269=0270=1.25471271=300000055=GBP/USD110=1000000279=0269=0270=1.25471271=500000055=GBP/USD110=3000000279=0269=1270=1.43507271=10000055=GBP/USD110=0279=0269=1270=1.43507271=50000055=GBP/USD110=100000279=0269=1270=1.43507271=100000055=GBP/USD110=500000279=0269=1270=1.43507271=300000055=GBP/USD110=1000000279=0269=1270=1.43507271=500000055=GBP/USD110=300000010=225
20260120-14:03:59.262597000 : 8=FIX.4.49=068435=X49=NTPRO_IDBA_UAT56=SIRIUS_500007460_MD34=101752=20260120-14:03:59.820262=MD_GBP/USD_140109778778268=10279=2269=0270=1.25471271=10000055=GBP/USD110=0279=2269=0270=1.25471271=50000055=GBP/USD110=100000279=2269=0270=1.25471271=100000055=GBP/USD110=500000279=2269=0270=1.25471271=300000055=GBP/USD110=1000000279=2269=0270=1.25471271=500000055=GBP/USD110=3000000279=2269=1270=1.43507271=10000055=GBP/USD110=0279=2269=1270=1.43507271=50000055=GBP/USD110=100000279=2269=1270=1.43507271=100000055=GBP/USD110=500000279=2269=1270=1.43507271=300000055=GBP/USD110=1000000279=2269=1270=1.43507271=500000055=GBP/USD110=300000010=242
20260120-14:03:59.375280000 : 8=FIX.4.49=068435=X49=NTPRO_IDBA_UAT56=SIRIUS_500007460_MD34=101852=20260120-14:03:59.937262=MD_GBP/USD_140109778778268=10279=0269=0270=1.25472271=10000055=GBP/USD110=0279=0269=0270=1.25472271=50000055=GBP/USD110=100000279=0269=0270=1.25472271=100000055=GBP/USD110=500000279=0269=0270=1.25472271=300000055=GBP/USD110=1000000279=0269=0270=1.25472271=500000055=GBP/USD110=3000000279=0269=1270=1.43508271=10000055=GBP/USD110=0279=0269=1270=1.43508271=50000055=GBP/USD110=100000279=0269=1270=1.43508271=100000055=GBP/USD110=500000279=0269=1270=1.43508271=300000055=GBP/USD110=1000000279=0269=1270=1.43508271=500000055=GBP/USD110=300000010=242
20260120-14:03:59.457922000 : 8=FIX.4.49=068435=X49=NTPRO_IDBA_UAT56=SIRIUS_500007460_MD34=101952=20260120-14:04:00.013262=MD_GBP/USD_140109778778268=10279=2269=0270=1.25472271=10000055=GBP/USD110=0279=2269=0270=1.25472271=50000055=GBP/USD110=100000279=2269=0270=1.25472271=100000055=GBP/USD110=500000279=2269=0270=1.25472271=300000055=GBP/USD110=1000000279=2269=0270=1.25472271=500000055=GBP/USD110=3000000279=2269=1270=1.43508271=10000055=GBP/USD110=0279=2269=1270=1.43508271=50000055=GBP/USD110=100000279=2269=1270=1.43508271=100000055=GBP/USD110=500000279=2269=1270=1.43508271=300000055=GBP/USD110=1000000279=2269=1270=1.43508271=500000055=GBP/USD110=300000010=235
20260120-14:03:59.471716000 : 8=FIX.4.49=044435=X49=NTPRO_IDBA_UAT56=SIRIUS_500007460_MD34=102052=20260120-14:04:00.037262=MD_EUR/USD_140109278614268=6279=1269=0270=1.14795271=10000055=EUR/USD110=0279=1269=0270=1.14795271=50000055=EUR/USD110=100000279=1269=0270=1.14795271=100000055=EUR/USD110=500000279=1269=1270=1.1982271=10000055=EUR/USD110=0279=1269=1270=1.1982271=50000055=EUR/USD110=100000279=1269=1270=1.1982271=100000055=EUR/USD110=50000010=147
20260120-14:03:59.505831000 : 8=FIX.4.49=068435=X49=NTPRO_IDBA_UAT56=SIRIUS_500007460_MD34=102152=20260120-14:04:00.072262=MD_GBP/USD_140109778778268=10279=0269=0270=1.25473271=10000055=GBP/USD110=0279=0269=0270=1.25473271=50000055=GBP/USD110=100000279=0269=0270=1.25473271=100000055=GBP/USD110=500000279=0269=0270=1.25473271=300000055=GBP/USD110=1000000279=0269=0270=1.25473271=500000055=GBP/USD110=3000000279=0269=1270=1.43508271=10000055=GBP/USD110=0279=0269=1270=1.43508271=50000055=GBP/USD110=100000279=0269=1270=1.43508271=100000055=GBP/USD110=500000279=0269=1270=1.43508271=300000055=GBP/USD110=1000000279=0269=1270=1.43508271=500000055=GBP/USD110=300000010=218
20260120-14:03:59.614800000 : 8=FIX.4.49=028035=X49=NTPRO_IDBA_UAT56=SIRIUS_500007460_MD34=102252=20260120-14:04:00.185262=MD_EUR/USD_140109278614268=3279=1269=1270=1.19819271=10000055=EUR/USD110=0279=1269=1270=1.19819271=50000055=EUR/USD110=100000279=1269=1270=1.19819271=100000055=EUR/USD110=50000010=010
20260120-14:03:59.657697000 : 8=FIX.4.49=067935=X49=NTPRO_IDBA_UAT56=SIRIUS_500007460_MD34=102352=20260120-14:04:00.214262=MD_GBP/USD_140109778778268=10279=1269=0270=1.25474271=10000055=GBP/USD110=0279=1269=0270=1.25474271=50000055=GBP/USD110=100000279=1269=0270=1.25474271=100000055=GBP/USD110=500000279=1269=0270=1.25474271=300000055=GBP/USD110=1000000279=1269=0270=1.25474271=500000055=GBP/USD110=3000000279=1269=1270=1.4351271=10000055=GBP/USD110=0279=1269=1270=1.4351271=50000055=GBP/USD110=100000279=1269=1270=1.4351271=100000055=GBP/USD110=500000279=1269=1270=1.4351271=300000055=GBP/USD110=1000000279=1269=1270=1.4351271=500000055=GBP/USD110=300000010=218
20260120-14:03:59.696751000 : 8=FIX.4.49=044735=X49=NTPRO_IDBA_UAT56=SIRIUS_500007460_MD34=102452=20260120-14:04:00.269262=MD_EUR/USD_140109278614268=6279=1269=0270=1.14796271=10000055=EUR/USD110=0279=1269=0270=1.14796271=50000055=EUR/USD110=100000279=1269=0270=1.14796271=100000055=EUR/USD110=500000279=1269=1270=1.19821271=10000055=EUR/USD110=0279=1269=1270=1.19821271=50000055=EUR/USD110=100000279=1269=1270=1.19821271=100000055=EUR/USD110=50000010=055
20260120-14:03:59.757369000 : 8=FIX.4.49=067935=X49=NTPRO_IDBA_UAT56=SIRIUS_500007460_MD34=102552=20260120-14:04:00.315262=MD_GBP/USD_140109778778268=10279=2269=0270=1.25474271=10000055=GBP/USD110=0279=2269=0270=1.25474271=50000055=GBP/USD110=100000279=2269=0270=1.25474271=100000055=GBP/USD110=500000279=2269=0270=1.25474271=300000055=GBP/USD110=1000000279=2269=0270=1.25474271=500000055=GBP/USD110=3000000279=2269=1270=1.4351271=10000055=GBP/USD110=0279=2269=1270=1.4351271=50000055=GBP/USD110=100000279=2269=1270=1.4351271=100000055=GBP/USD110=500000279=2269=1270=1.4351271=300000055=GBP/USD110=1000000279=2269=1270=1.4351271=500000055=GBP/USD110=300000010=232
20260120-14:03:59.783377000 : 8=FIX.4.49=068435=X49=NTPRO_IDBA_UAT56=SIRIUS_500007460_MD34=102652=20260120-14:04:00.359262=MD_GBP/USD_140109778778268=10279=0269=0270=1.25474271=10000055=GBP/USD110=0279=0269=0270=1.25474271=50000055=GBP/USD110=100000279=0269=0270=1.25474271=100000055=GBP/USD110=500000279=0269=0270=1.25474271=300000055=GBP/USD110=1000000279=0269=0270=1.25474271=500000055=GBP/USD110=3000000279=0269=1270=1.43509271=10000055=GBP/USD110=0279=0269=1270=1.43509271=50000055=GBP/USD110=100000279=0269=1270=1.43509271=100000055=GBP/USD110=500000279=0269=1270=1.43509271=300000055=GBP/USD110=1000000279=0269=1270=1.43509271=500000055=GBP/USD110=300000010=241
20260120-14:03:59.838331000 : 8=FIX.4.49=027735=X49=NTPRO_IDBA_UAT56=SIRIUS_500007460_MD34=102752=20260120-14:04:00.416262=MD_EUR/USD_140109278614268=3279=1269=1270=1.1982271=10000055=EUR/USD110=0279=1269=1270=1.1982271=50000055=EUR/USD110=100000279=1269=1270=1.1982271=100000055=EUR/USD110=50000010=106
20260120-14:03:59.879526000 : 8=FIX.4.49=028035=X49=NTPRO_IDBA_UAT56=SIRIUS_500007460_MD34=102852=20260120-14:04:00.458262=MD_EUR/USD_140109278614268=3279=1269=1270=1.19821271=10000055=EUR/USD110=0279=1269=1270=1.19821271=50000055=EUR/USD110=100000279=1269=1270=1.19821271=100000055=EUR/USD110=50000010=254
20260120-14:04:00.258112000 : 8=FIX.4.49=007935=049=NTPRO_IDBA_UAT56=SIRIUS_500007460_MD34=102952=20260120-14:04:00.85010=009
20260120-14:04:00.268060000 : 8=FIX.4.49=044735=X49=NTPRO_IDBA_UAT56=SIRIUS_500007460_MD34=103052=20260120-14:04:00.860262=MD_EUR/USD_140109278614268=6279=1269=0270=1.14798271=10000055=EUR/USD110=0279=1269=0270=1.14798271=50000055=EUR/USD110=100000279=1269=0270=1.14798271=100000055=EUR/USD110=500000279=1269=1270=1.19822271=10000055=EUR/USD110=0279=1269=1270=1.19822271=50000055=EUR/USD110=100000279=1269=1270=1.19822271=100000055=EUR/USD110=50000010=058
20260120-14:04:00.302390000 : 8=FIX.4.49=067935=X49=NTPRO_IDBA_UAT56=SIRIUS_500007460_MD34=103152=20260120-14:04:00.894262=MD_GBP/USD_140109778778268=10279=1269=0270=1.25476271=10000055=GBP/USD110=0279=1269=0270=1.25476271=50000055=GBP/USD110=100000279=1269=0270=1.25476271=100000055=GBP/USD110=500000279=1269=0270=1.25476271=300000055=GBP/USD110=1000000279=1269=0270=1.25476271=500000055=GBP/USD110=3000000279=1269=1270=1.4351271=10000055=GBP/USD110=0279=1269=1270=1.4351271=50000055=GBP/USD110=100000279=1269=1270=1.4351271=100000055=GBP/USD110=500000279=1269=1270=1.4351271=300000055=GBP/USD110=1000000279=1269=1270=1.4351271=500000055=GBP/USD110=300000010=241
20260120-14:04:00.359318000 : 8=FIX.4.49=068435=X49=NTPRO_IDBA_UAT56=SIRIUS_500007460_MD34=103252=20260120-14:04:00.954262=MD_GBP/USD_140109778778268=10279=1269=0270=1.25477271=10000055=GBP/USD110=0279=1269=0270=1.25477271=50000055=GBP/USD110=100000279=1269=0270=1.25477271=100000055=GBP/USD110=500000279=1269=0270=1.25477271=300000055=GBP/USD110=1000000279=1269=0270=1.25477271=500000055=GBP/USD110=3000000279=1269=1270=1.43512271=10000055=GBP/USD110=0279=1269=1270=1.43512271=50000055=GBP/USD110=100000279=1269=1270=1.43512271=100000055=GBP/USD110=500000279=1269=1270=1.43512271=300000055=GBP/USD110=1000000279=1269=1270=1.43512271=500000055=GBP/USD110=300000010=234
20260120-14:04:00.432409000 : 8=FIX.4.49=044735=X49=NTPRO_IDBA_UAT56=SIRIUS_500007460_MD34=103352=20260120-14:04:01.030262=MD_EUR/USD_140109278614268=6279=1269=0270=1.14799271=10000055=EUR/USD110=0279=1269=0270=1.14799271=50000055=EUR/USD110=100000279=1269=0270=1.14799271=100000055=EUR/USD110=500000279=1269=1270=1.19823271=10000055=EUR/USD110=0279=1269=1270=1.19823271=50000055=EUR/USD110=100000279=1269=1270=1.19823271=100000055=EUR/USD110=50000010=057
20260120-14:04:00.485657000 : 8=FIX.4.49=044735=X49=NTPRO_IDBA_UAT56=SIRIUS_500007460_MD34=103452=20260120-14:04:01.085262=MD_EUR/USD_140109278614268=6279=1269=0270=1.14798271=10000055=EUR/USD110=0279=1269=0270=1.14798271=50000055=EUR/USD110=100000279=1269=0270=1.14798271=100000055=EUR/USD110=500000279=1269=1270=1.19822271=10000055=EUR/USD110=0279=1269=1270=1.19822271=50000055=EUR/USD110=100000279=1269=1270=1.19822271=100000055=EUR/USD110=50000010=062
20260120-14:04:00.556349000 : 8=FIX.4.49=028035=X49=NTPRO_IDBA_UAT56=SIRIUS_500007460_MD34=103552=20260120-14:04:01.158262=MD_EUR/USD_140109278614268=3279=1269=1270=1.19823271=10000055=EUR/USD110=0279=1269=1270=1.19823271=50000055=EUR/USD110=100000279=1269=1270=1.19823271=100000055=EUR/USD110=50000010=000
20260120-14:04:00.585913000 : 8=FIX.4.49=028035=X49=NTPRO_IDBA_UAT56=SIRIUS_500007460_MD34=103652=20260120-14:04:01.189262=MD_EUR/USD_140109278614268=3279=1269=1270=1.19822271=10000055=EUR/USD110=0279=1269=1270=1.19822271=50000055=EUR/USD110=100000279=1269=1270=1.19822271=100000055=EUR/USD110=50000010=002
20260120-14:04:00.770069000 : 8=FIX.4.49=028035=X49=NTPRO_IDBA_UAT56=SIRIUS_500007460_MD34=103752=20260120-14:04:01.377262=MD_EUR/USD_140109278614268=3279=1269=1270=1.19823271=10000055=EUR/USD110=0279=1269=1270=1.19823271=50000055=EUR/USD110=100000279=1269=1270=1.19823271=100000055=EUR/USD110=50000010=005
20260120-14:04:00.777211000 : 8=FIX.4.49=068435=X49=NTPRO_IDBA_UAT56=SIRIUS_500007460_MD34=103852=20260120-14:04:01.386262=MD_GBP/USD_140109778778268=10279=1269=0270=1.25476271=10000055=GBP/USD110=0279=1269=0270=1.25476271=50000055=GBP/USD110=100000279=1269=0270=1.25476271=100000055=GBP/USD110=500000279=1269=0270=1.25476271=300000055=GBP/USD110=1000000279=1269=0270=1.25476271=500000055=GBP/USD110=3000000279=1269=1270=1.43511271=10000055=GBP/USD110=0279=1269=1270=1.43511271=50000055=GBP/USD110=100000279=1269=1270=1.43511271=100000055=GBP/USD110=500000279=1269=1270=1.43511271=300000055=GBP/USD110=1000000279=1269=1270=1.43511271=500000055=GBP/USD110=300000010=230
20260120-14:04:00.812975000 : 8=FIX.4.49=028035=X49=NTPRO_IDBA_UAT56=SIRIUS_500007460_MD34=103952=20260120-14:04:01.421262=MD_EUR/USD_140109278614268=3279=1269=0270=1.14799271=10000055=EUR/USD110=0279=1269=0270=1.14799271=50000055=EUR/USD110=100000279=1269=0270=1.14799271=100000055=EUR/USD110=50000010=015
20260120-14:04:00.881618000 : 8=FIX.4.49=039835=X49=NTPRO_IDBA_UAT56=SIRIUS_500007460_MD34=104052=20260120-14:04:01.472262=MD_GBP/USD_140109778778268=5279=1269=1270=1.43512271=10000055=GBP/USD110=0279=1269=1270=1.43512271=50000055=GBP/USD110=100000279=1269=1270=1.43512271=100000055=GBP/USD110=500000279=1269=1270=1.43512271=300000055=GBP/USD110=1000000279=1269=1270=1.43512271=500000055=GBP/USD110=300000010=051
20260120-14:04:00.882280000 : 8=FIX.4.49=028035=X49=NTPRO_IDBA_UAT56=SIRIUS_500007460_MD34=104152=20260120-14:04:01.483262=MD_EUR/USD_140109278614268=3279=1269=1270=1.19824271=10000055=EUR/USD110=0279=1269=1270=1.19824271=50000055=EUR/USD110=100000279=1269=1270=1.19824271=100000055=EUR/USD110=50000010=001
20260120-14:04:00.904762000 : 8=FIX.4.49=039835=X49=NTPRO_IDBA_UAT56=SIRIUS_500007460_MD34=104252=20260120-14:04:01.518262=MD_GBP/USD_140109778778268=5279=1269=0270=1.25477271=10000055=GBP/USD110=0279=1269=0270=1.25477271=50000055=GBP/USD110=100000279=1269=0270=1.25477271=100000055=GBP/USD110=500000279=1269=0270=1.25477271=300000055=GBP/USD110=1000000279=1269=0270=1.25477271=500000055=GBP/USD110=300000010=099
20260120-14:04:00.924781000 : 8=FIX.4.49=044135=X49=NTPRO_IDBA_UAT56=SIRIUS_500007460_MD34=104352=20260120-14:04:01.539262=MD_EUR/USD_140109278614268=6279=1269=0270=1.148271=10000055=EUR/USD110=0279=1269=0270=1.148271=50000055=EUR/USD110=100000279=1269=0270=1.148271=100000055=EUR/USD110=500000279=1269=1270=1.19825271=10000055=EUR/USD110=0279=1269=1270=1.19825271=50000055=EUR/USD110=100000279=1269=1270=1.19825271=100000055=EUR/USD110=50000010=245
20260120-14:04:01.022131000 : 8=FIX.4.49=044735=X49=NTPRO_IDBA_UAT56=SIRIUS_500007460_MD34=104452=20260120-14:04:01.636262=MD_EUR/USD_140109278614268=6279=1269=0270=1.14798271=10000055=EUR/USD110=0279=1269=0270=1.14798271=50000055=EUR/USD110=100000279=1269=0270=1.14798271=100000055=EUR/USD110=500000279=1269=1270=1.19823271=10000055=EUR/USD110=0279=1269=1270=1.19823271=50000055=EUR/USD110=100000279=1269=1270=1.19823271=100000055=EUR/USD110=50000010=068
20260120-14:04:01.080127000 : 8=FIX.4.49=028035=X49=NTPRO_IDBA_UAT56=SIRIUS_500007460_MD34=104552=20260120-14:04:01.699262=MD_EUR/USD_140109278614268=3279=1269=1270=1.19822271=10000055=EUR/USD110=0279=1269=1270=1.19822271=50000055=EUR/USD110=100000279=1269=1270=1.19822271=100000055=EUR/USD110=50000010=008
20260120-14:04:01.138583000 : 8=FIX.4.49=028035=X49=NTPRO_IDBA_UAT56=SIRIUS_500007460_MD34=104652=20260120-14:04:01.751262=MD_EUR/USD_140109278614268=3279=1269=1270=1.19823271=10000055=EUR/USD110=0279=1269=1270=1.19823271=50000055=EUR/USD110=100000279=1269=1270=1.19823271=100000055=EUR/USD110=50000010=001
20260120-14:04:01.636602000 : 8=FIX.4.49=028035=X49=NTPRO_IDBA_UAT56=SIRIUS_500007460_MD34=104752=20260120-14:04:02.273262=MD_EUR/USD_140109278614268=3279=1269=0270=1.14799271=10000055=EUR/USD110=0279=1269=0270=1.14799271=50000055=EUR/USD110=100000279=1269=0270=1.14799271=100000055=EUR/USD110=50000010=020
20260120-14:04:01.897471000 : 8=FIX.4.49=028035=X49=NTPRO_IDBA_UAT56=SIRIUS_500007460_MD34=104852=20260120-14:04:02.543262=MD_EUR/USD_140109278614268=3279=1269=0270=1.14798271=10000055=EUR/USD110=0279=1269=0270=1.14798271=50000055=EUR/USD110=100000279=1269=0270=1.14798271=100000055=EUR/USD110=50000010=018
20260120-14:04:02.167283000 : 8=FIX.4.49=044735=X49=NTPRO_IDBA_UAT56=SIRIUS_500007460_MD34=104952=20260120-14:04:02.823262=MD_EUR/USD_140109278614268=6279=1269=0270=1.14797271=10000055=EUR/USD110=0279=1269=0270=1.14797271=50000055=EUR/USD110=100000279=1269=0270=1.14797271=100000055=EUR/USD110=500000279=1269=1270=1.19822271=10000055=EUR/USD110=0279=1269=1270=1.19822271=50000055=EUR/USD110=100000279=1269=1270=1.19822271=100000055=EUR/USD110=50000010=066
20260120-14:04:02.297504000 : 8=FIX.4.49=044735=X49=NTPRO_IDBA_UAT56=SIRIUS_500007460_MD34=105052=20260120-14:04:02.957262=MD_EUR/USD_140109278614268=6279=1269=0270=1.14796271=10000055=EUR/USD110=0279=1269=0270=1.14796271=50000055=EUR/USD110=100000279=1269=0270=1.14796271=100000055=EUR/USD110=500000279=1269=1270=1.19821271=10000055=EUR/USD110=0279=1269=1270=1.19821271=50000055=EUR/USD110=100000279=1269=1270=1.19821271=100000055=EUR/USD110=50000010=060
20260120-14:04:02.332841000 : 8=FIX.4.49=039835=X49=NTPRO_IDBA_UAT56=SIRIUS_500007460_MD34=105152=20260120-14:04:02.993262=MD_GBP/USD_140109778778268=5279=1269=0270=1.25476271=10000055=GBP/USD110=0279=1269=0270=1.25476271=50000055=GBP/USD110=100000279=1269=0270=1.25476271=100000055=GBP/USD110=500000279=1269=0270=1.25476271=300000055=GBP/USD110=1000000279=1269=0270=1.25476271=500000055=GBP/USD110=300000010=102
20260120-14:04:02.377782000 : 8=FIX.4.49=039835=X49=NTPRO_IDBA_UAT56=SIRIUS_500007460_MD34=105252=20260120-14:04:03.040262=MD_GBP/USD_140109778778268=5279=1269=1270=1.43511271=10000055=GBP/USD110=0279=1269=1270=1.43511271=50000055=GBP/USD110=100000279=1269=1270=1.43511271=100000055=GBP/USD110=500000279=1269=1270=1.43511271=300000055=GBP/USD110=1000000279=1269=1270=1.43511271=500000055=GBP/USD110=300000010=042
20260120-14:04:02.423580000 : 8=FIX.4.49=067935=X49=NTPRO_IDBA_UAT56=SIRIUS_500007460_MD34=105352=20260120-14:04:03.084262=MD_GBP/USD_140109778778268=10279=1269=0270=1.25474271=10000055=GBP/USD110=0279=1269=0270=1.25474271=50000055=GBP/USD110=100000279=1269=0270=1.25474271=100000055=GBP/USD110=500000279=1269=0270=1.25474271=300000055=GBP/USD110=1000000279=1269=0270=1.25474271=500000055=GBP/USD110=3000000279=1269=1270=1.4351271=10000055=GBP/USD110=0279=1269=1270=1.4351271=50000055=GBP/USD110=100000279=1269=1270=1.4351271=100000055=GBP/USD110=500000279=1269=1270=1.4351271=300000055=GBP/USD110=1000000279=1269=1270=1.4351271=500000055=GBP/USD110=300000010=229
20260120-14:04:02.446813000 : 8=FIX.4.49=027735=X49=NTPRO_IDBA_UAT56=SIRIUS_500007460_MD34=105452=20260120-14:04:03.112262=MD_EUR/USD_140109278614268=3279=1269=1270=1.1982271=10000055=EUR/USD110=0279=1269=1270=1.1982271=50000055=EUR/USD110=100000279=1269=1270=1.1982271=100000055=EUR/USD110=50000010=102
20260120-14:04:02.542610000 : 8=FIX.4.49=039835=X49=NTPRO_IDBA_UAT56=SIRIUS_500007460_MD34=105552=20260120-14:04:03.210262=MD_GBP/USD_140109778778268=5279=1269=0270=1.25475271=10000055=GBP/USD110=0279=1269=0270=1.25475271=50000055=GBP/USD110=100000279=1269=0270=1.25475271=100000055=GBP/USD110=500000279=1269=0270=1.25475271=300000055=GBP/USD110=1000000279=1269=0270=1.25475271=500000055=GBP/USD110=300000010=084
20260120-14:04:02.562539000 : 8=FIX.4.49=039835=X49=NTPRO_IDBA_UAT56=SIRIUS_500007460_MD34=105652=20260120-14:04:03.231262=MD_GBP/USD_140109778778268=5279=1269=0270=1.25474271=10000055=GBP/USD110=0279=1269=0270=1.25474271=50000055=GBP/USD110=100000279=1269=0270=1.25474271=100000055=GBP/USD110=500000279=1269=0270=1.25474271=300000055=GBP/USD110=1000000279=1269=0270=1.25474271=500000055=GBP/USD110=300000010=083
20260120-14:04:02.783085000 : 8=FIX.4.49=039835=X49=NTPRO_IDBA_UAT56=SIRIUS_500007460_MD34=105752=20260120-14:04:03.458262=MD_GBP/USD_140109778778268=5279=1269=0270=1.25475271=10000055=GBP/USD110=0279=1269=0270=1.25475271=50000055=GBP/USD110=100000279=1269=0270=1.25475271=100000055=GBP/USD110=500000279=1269=0270=1.25475271=300000055=GBP/USD110=1000000279=1269=0270=1.25475271=500000055=GBP/USD110=300000010=100
20260120-14:04:02.860374000 : 8=FIX.4.49=028035=X49=NTPRO_IDBA_UAT56=SIRIUS_500007460_MD34=105852=20260120-14:04:03.526262=MD_EUR/USD_140109278614268=3279=1269=0270=1.14795271=10000055=EUR/USD110=0279=1269=0270=1.14795271=50000055=EUR/USD110=100000279=1269=0270=1.14795271=100000055=EUR/USD110=50000010=012
20260120-14:04:02.896920000 : 8=FIX.4.49=039835=X49=NTPRO_IDBA_UAT56=SIRIUS_500007460_MD34=105952=20260120-14:04:03.577262=MD_GBP/USD_140109778778268=5279=1269=0270=1.25474271=10000055=GBP/USD110=0279=1269=0270=1.25474271=50000055=GBP/USD110=100000279=1269=0270=1.25474271=100000055=GBP/USD110=500000279=1269=0270=1.25474271=300000055=GBP/USD110=1000000279=1269=0270=1.25474271=500000055=GBP/USD110=300000010=099
20260120-14:04:02.924465000 : 8=FIX.4.49=028035=X49=NTPRO_IDBA_UAT56=SIRIUS_500007460_MD34=106052=20260120-14:04:03.597262=MD_EUR/USD_140109278614268=3279=1269=0270=1.14796271=10000055=EUR/USD110=0279=1269=0270=1.14796271=50000055=EUR/USD110=100000279=1269=0270=1.14796271=100000055=EUR/USD110=50000010=016
20260120-14:04:03.547857000 : 8=FIX.4.49=039835=X49=NTPRO_IDBA_UAT56=SIRIUS_500007460_MD34=106152=20260120-14:04:04.244262=MD_GBP/USD_140109778778268=5279=1269=0270=1.25475271=10000055=GBP/USD110=0279=1269=0270=1.25475271=50000055=GBP/USD110=100000279=1269=0270=1.25475271=100000055=GBP/USD110=500000279=1269=0270=1.25475271=300000055=GBP/USD110=1000000279=1269=0270=1.25475271=500000055=GBP/USD110=300000010=089
20260120-14:04:03.895920000 : 8=FIX.4.49=039835=X49=NTPRO_IDBA_UAT56=SIRIUS_500007460_MD34=106252=20260120-14:04:04.609262=MD_GBP/USD_140109778778268=5279=1269=0270=1.25474271=10000055=GBP/USD110=0279=1269=0270=1.25474271=50000055=GBP/USD110=100000279=1269=0270=1.25474271=100000055=GBP/USD110=500000279=1269=0270=1.25474271=300000055=GBP/USD110=1000000279=1269=0270=1.25474271=500000055=GBP/USD110=300000010=090
20260120-14:04:03.957103000 : 8=FIX.4.49=044735=X49=NTPRO_IDBA_UAT56=SIRIUS_500007460_MD34=106352=20260120-14:04:04.673262=MD_EUR/USD_140109278614268=6279=1269=0270=1.14795271=10000055=EUR/USD110=0279=1269=0270=1.14795271=50000055=EUR/USD110=100000279=1269=0270=1.14795271=100000055=EUR/USD110=500000279=1269=1270=1.19819271=10000055=EUR/USD110=0279=1269=1270=1.19819271=50000055=EUR/USD110=100000279=1269=1270=1.19819271=100000055=EUR/USD110=50000010=079
20260120-14:04:03.957979000 : 8=FIX.4.49=039835=X49=NTPRO_IDBA_UAT56=SIRIUS_500007460_MD34=106452=20260120-14:04:04.674262=MD_GBP/USD_140109778778268=5279=1269=1270=1.43509271=10000055=GBP/USD110=0279=1269=1270=1.43509271=50000055=GBP/USD110=100000279=1269=1270=1.43509271=100000055=GBP/USD110=500000279=1269=1270=1.43509271=300000055=GBP/USD110=1000000279=1269=1270=1.43509271=500000055=GBP/USD110=300000010=094
20260120-14:04:03.988401000 : 8=FIX.4.49=068435=X49=NTPRO_IDBA_UAT56=SIRIUS_500007460_MD34=106552=20260120-14:04:04.705262=MD_GBP/USD_140109778778268=10279=1269=0270=1.25472271=10000055=GBP/USD110=0279=1269=0270=1.25472271=50000055=GBP/USD110=100000279=1269=0270=1.25472271=100000055=GBP/USD110=500000279=1269=0270=1.25472271=300000055=GBP/USD110=1000000279=1269=0270=1.25472271=500000055=GBP/USD110=3000000279=1269=1270=1.43508271=10000055=GBP/USD110=0279=1269=1270=1.43508271=50000055=GBP/USD110=100000279=1269=1270=1.43508271=100000055=GBP/USD110=500000279=1269=1270=1.43508271=300000055=GBP/USD110=1000000279=1269=1270=1.43508271=500000055=GBP/USD110=300000010=238
20260120-14:04:04.029227000 : 8=FIX.4.49=039835=X49=NTPRO_IDBA_UAT56=SIRIUS_500007460_MD34=106652=20260120-14:04:04.747262=MD_GBP/USD_140109778778268=5279=1269=0270=1.25473271=10000055=GBP/USD110=0279=1269=0270=1.25473271=50000055=GBP/USD110=100000279=1269=0270=1.25473271=100000055=GBP/USD110=500000279=1269=0270=1.25473271=300000055=GBP/USD110=1000000279=1269=0270=1.25473271=500000055=GBP/USD110=300000010=092
20260120-14:04:04.121950000 : 8=FIX.4.49=027735=X49=NTPRO_IDBA_UAT56=SIRIUS_500007460_MD34=106752=20260120-14:04:04.838262=MD_EUR/USD_140109278614268=3279=1269=1270=1.1982271=10000055=EUR/USD110=0279=1269=1270=1.1982271=50000055=EUR/USD110=100000279=1269=1270=1.1982271=100000055=EUR/USD110=50000010=122
20260120-14:04:04.126501000 : 8=FIX.4.49=039835=X49=NTPRO_IDBA_UAT56=SIRIUS_500007460_MD34=106852=20260120-14:04:04.847262=MD_GBP/USD_140109778778268=5279=1269=0270=1.25472271=10000055=GBP/USD110=0279=1269=0270=1.25472271=50000055=GBP/USD110=100000279=1269=0270=1.25472271=100000055=GBP/USD110=500000279=1269=0270=1.25472271=300000055=GBP/USD110=1000000279=1269=0270=1.25472271=500000055=GBP/USD110=300000010=090
20260120-14:04:04.197714000 : 8=FIX.4.49=039835=X49=NTPRO_IDBA_UAT56=SIRIUS_500007460_MD34=106952=20260120-14:04:04.920262=MD_GBP/USD_140109778778268=5279=1269=0270=1.25473271=10000055=GBP/USD110=0279=1269=0270=1.25473271=50000055=GBP/USD110=100000279=1269=0270=1.25473271=100000055=GBP/USD110=500000279=1269=0270=1.25473271=300000055=GBP/USD110=1000000279=1269=0270=1.25473271=500000055=GBP/USD110=300000010=088
20260120-14:04:04.218538000 : 8=FIX.4.49=039835=X49=NTPRO_IDBA_UAT56=SIRIUS_500007460_MD34=107052=20260120-14:04:04.943262=MD_GBP/USD_140109778778268=5279=1269=1270=1.43509271=10000055=GBP/USD110=0279=1269=1270=1.43509271=50000055=GBP/USD110=100000279=1269=1270=1.43509271=100000055=GBP/USD110=500000279=1269=1270=1.43509271=300000055=GBP/USD110=1000000279=1269=1270=1.43509271=500000055=GBP/USD110=300000010=090
20260120-14:04:04.295753000 : 8=FIX.4.49=039835=X49=NTPRO_IDBA_UAT56=SIRIUS_500007460_MD34=107152=20260120-14:04:05.022262=MD_GBP/USD_140109778778268=5279=1269=1270=1.43508271=10000055=GBP/USD110=0279=1269=1270=1.43508271=50000055=GBP/USD110=100000279=1269=1270=1.43508271=100000055=GBP/USD110=500000279=1269=1270=1.43508271=300000055=GBP/USD110=1000000279=1269=1270=1.43508271=500000055=GBP/USD110=300000010=075
20260120-14:04:04.343189000 : 8=FIX.4.49=039835=X49=NTPRO_IDBA_UAT56=SIRIUS_500007460_MD34=107252=20260120-14:04:05.072262=MD_GBP/USD_140109778778268=5279=1269=1270=1.43507271=10000055=GBP/USD110=0279=1269=1270=1.43507271=50000055=GBP/USD110=100000279=1269=1270=1.43507271=100000055=GBP/USD110=500000279=1269=1270=1.43507271=300000055=GBP/USD110=1000000279=1269=1270=1.43507271=500000055=GBP/USD110=300000010=076
20260120-14:04:04.353434000 : 8=FIX.4.49=044735=X49=NTPRO_IDBA_UAT56=SIRIUS_500007460_MD34=107352=20260120-14:04:05.082262=MD_EUR/USD_140109278614268=6279=1269=0270=1.14792271=10000055=EUR/USD110=0279=1269=0270=1.14792271=50000055=EUR/USD110=100000279=1269=0270=1.14792271=100000055=EUR/USD110=500000279=1269=1270=1.19816271=10000055=EUR/USD110=0279=1269=1270=1.19816271=50000055=EUR/USD110=100000279=1269=1270=1.19816271=100000055=EUR/USD110=50000010=057
20260120-14:04:04.378738000 : 8=FIX.4.49=068435=X49=NTPRO_IDBA_UAT56=SIRIUS_500007460_MD34=107452=20260120-14:04:05.108262=MD_GBP/USD_140109778778268=10279=2269=0270=1.25473271=10000055=GBP/USD110=0279=2269=0270=1.25473271=50000055=GBP/USD110=100000279=2269=0270=1.25473271=100000055=GBP/USD110=500000279=2269=0270=1.25473271=300000055=GBP/USD110=1000000279=2269=0270=1.25473271=500000055=GBP/USD110=3000000279=2269=1270=1.43507271=10000055=GBP/USD110=0279=2269=1270=1.43507271=50000055=GBP/USD110=100000279=2269=1270=1.43507271=100000055=GBP/USD110=500000279=2269=1270=1.43507271=300000055=GBP/USD110=1000000279=2269=1270=1.43507271=500000055=GBP/USD110=300000010=246
20260120-14:04:04.440399000 : 8=FIX.4.49=044735=X49=NTPRO_IDBA_UAT56=SIRIUS_500007460_MD34=107552=20260120-14:04:05.169262=MD_EUR/USD_140109278614268=6279=1269=0270=1.14794271=10000055=EUR/USD110=0279=1269=0270=1.14794271=50000055=EUR/USD110=100000279=1269=0270=1.14794271=100000055=EUR/USD110=500000279=1269=1270=1.19819271=10000055=EUR/USD110=0279=1269=1270=1.19819271=50000055=EUR/USD110=100000279=1269=1270=1.19819271=100000055=EUR/USD110=50000010=080
20260120-14:04:04.441206000 : 8=FIX.4.49=068435=X49=NTPRO_IDBA_UAT56=SIRIUS_500007460_MD34=107652=20260120-14:04:05.171262=MD_GBP/USD_140109778778268=10279=0269=0270=1.25469271=10000055=GBP/USD110=0279=0269=0270=1.25469271=50000055=GBP/USD110=100000279=0269=0270=1.25469271=100000055=GBP/USD110=500000279=0269=0270=1.25469271=300000055=GBP/USD110=1000000279=0269=0270=1.25469271=500000055=GBP/USD110=3000000279=0269=1270=1.43505271=10000055=GBP/USD110=0279=0269=1270=1.43505271=50000055=GBP/USD110=100000279=0269=1270=1.43505271=100000055=GBP/USD110=500000279=0269=1270=1.43505271=300000055=GBP/USD110=1000000279=0269=1270=1.43505271=500000055=GBP/USD110=300000010=243
20260120-14:04:04.510208000 : 8=FIX.4.49=068435=X49=NTPRO_IDBA_UAT56=SIRIUS_500007460_MD34=107752=20260120-14:04:05.233262=MD_GBP/USD_140109778778268=10279=2269=0270=1.25469271=10000055=GBP/USD110=0279=2269=0270=1.25469271=50000055=GBP/USD110=100000279=2269=0270=1.25469271=100000055=GBP/USD110=500000279=2269=0270=1.25469271=300000055=GBP/USD110=1000000279=2269=0270=1.25469271=500000055=GBP/USD110=3000000279=2269=1270=1.43505271=10000055=GBP/USD110=0279=2269=1270=1.43505271=50000055=GBP/USD110=100000279=2269=1270=1.43505271=100000055=GBP/USD110=500000279=2269=1270=1.43505271=300000055=GBP/USD110=1000000279=2269=1270=1.43505271=500000055=GBP/USD110=300000010=007
20260120-14:04:04.568611000 : 8=FIX.4.49=044435=X49=NTPRO_IDBA_UAT56=SIRIUS_500007460_MD34=107852=20260120-14:04:05.304262=MD_EUR/USD_140109278614268=6279=1269=0270=1.14795271=10000055=EUR/USD110=0279=1269=0270=1.14795271=50000055=EUR/USD110=100000279=1269=0270=1.14795271=100000055=EUR/USD110=500000279=1269=1270=1.1982271=10000055=EUR/USD110=0279=1269=1270=1.1982271=50000055=EUR/USD110=100000279=1269=1270=1.1982271=100000055=EUR/USD110=50000010=162
20260120-14:04:04.930971000 : 8=FIX.4.49=068435=X49=NTPRO_IDBA_UAT56=SIRIUS_500007460_MD34=107952=20260120-14:04:05.676262=MD_GBP/USD_140109778778268=10279=0269=0270=1.25471271=10000055=GBP/USD110=0279=0269=0270=1.25471271=50000055=GBP/USD110=100000279=0269=0270=1.25471271=100000055=GBP/USD110=500000279=0269=0270=1.25471271=300000055=GBP/USD110=1000000279=0269=0270=1.25471271=500000055=GBP/USD110=3000000279=0269=1270=1.43507271=10000055=GBP/USD110=0279=0269=1270=1.43507271=50000055=GBP/USD110=100000279=0269=1270=1.43507271=100000055=GBP/USD110=500000279=0269=1270=1.43507271=300000055=GBP/USD110=1000000279=0269=1270=1.43507271=500000055=GBP/USD110=300000010=231
20260120-14:04:04.933008000 : 8=FIX.4.49=028035=X49=NTPRO_IDBA_UAT56=SIRIUS_500007460_MD34=108052=20260120-14:04:05.681262=MD_EUR/USD_140109278614268=3279=1269=0270=1.14796271=10000055=EUR/USD110=0279=1269=0270=1.14796271=50000055=EUR/USD110=100000279=1269=0270=1.14796271=100000055=EUR/USD110=50000010=014
20260120-14:04:05.305734000 : 8=FIX.4.49=044735=X49=NTPRO_IDBA_UAT56=SIRIUS_500007460_MD34=108152=20260120-14:04:06.060262=MD_EUR/USD_140109278614268=6279=1269=0270=1.14795271=10000055=EUR/USD110=0279=1269=0270=1.14795271=50000055=EUR/USD110=100000279=1269=0270=1.14795271=100000055=EUR/USD110=500000279=1269=1270=1.19819271=10000055=EUR/USD110=0279=1269=1270=1.19819271=50000055=EUR/USD110=100000279=1269=1270=1.19819271=100000055=EUR/USD110=50000010=071
20260120-14:04:05.323063000 : 8=FIX.4.49=068435=X49=NTPRO_IDBA_UAT56=SIRIUS_500007460_MD34=108252=20260120-14:04:06.084262=MD_GBP/USD_140109778778268=10279=2269=0270=1.25471271=10000055=GBP/USD110=0279=2269=0270=1.25471271=50000055=GBP/USD110=100000279=2269=0270=1.25471271=100000055=GBP/USD110=500000279=2269=0270=1.25471271=300000055=GBP/USD110=1000000279=2269=0270=1.25471271=500000055=GBP/USD110=3000000279=2269=1270=1.43507271=10000055=GBP/USD110=0279=2269=1270=1.43507271=50000055=GBP/USD110=100000279=2269=1270=1.43507271=100000055=GBP/USD110=500000279=2269=1270=1.43507271=300000055=GBP/USD110=1000000279=2269=1270=1.43507271=500000055=GBP/USD110=300000010=239
20260120-14:04:05.360687000 : 8=FIX.4.49=044735=X49=NTPRO_IDBA_UAT56=SIRIUS_500007460_MD34=108352=20260120-14:04:06.123262=MD_EUR/USD_140109278614268=6279=1269=0270=1.14792271=10000055=EUR/USD110=0279=1269=0270=1.14792271=50000055=EUR/USD110=100000279=1269=0270=1.14792271=100000055=EUR/USD110=500000279=1269=1270=1.19817271=10000055=EUR/USD110=0279=1269=1270=1.19817271=50000055=EUR/USD110=100000279=1269=1270=1.19817271=100000055=EUR/USD110=50000010=058
20260120-14:04:05.468465000 : 8=FIX.4.49=044735=X49=NTPRO_IDBA_UAT56=SIRIUS_500007460_MD34=108452=20260120-14:04:06.234262=MD_EUR/USD_140109278614268=6279=1269=0270=1.14791271=10000055=EUR/USD110=0279=1269=0270=1.14791271=50000055=EUR/USD110=100000279=1269=0270=1.14791271=100000055=EUR/USD110=500000279=1269=1270=1.19816271=10000055=EUR/USD110=0279=1269=1270=1.19816271=50000055=EUR/USD110=100000279=1269=1270=1.19816271=100000055=EUR/USD110=50000010=056
20260120-14:04:05.529093000 : 8=FIX.4.49=028035=X49=NTPRO_IDBA_UAT56=SIRIUS_500007460_MD34=108552=20260120-14:04:06.295262=MD_EUR/USD_140109278614268=3279=1269=1270=1.19815271=10000055=EUR/USD110=0279=1269=1270=1.19815271=50000055=EUR/USD110=100000279=1269=1270=1.19815271=100000055=EUR/USD110=50000010=015
20260120-14:04:05.534167000 : 8=FIX.4.49=068435=X49=NTPRO_IDBA_UAT56=SIRIUS_500007460_MD34=108652=20260120-14:04:06.302262=MD_GBP/USD_140109778778268=10279=0269=0270=1.25468271=10000055=GBP/USD110=0279=0269=0270=1.25468271=50000055=GBP/USD110=100000279=0269=0270=1.25468271=100000055=GBP/USD110=500000279=0269=0270=1.25468271=300000055=GBP/USD110=1000000279=0269=0270=1.25468271=500000055=GBP/USD110=3000000279=0269=1270=1.43503271=10000055=GBP/USD110=0279=0269=1270=1.43503271=50000055=GBP/USD110=100000279=0269=1270=1.43503271=100000055=GBP/USD110=500000279=0269=1270=1.43503271=300000055=GBP/USD110=1000000279=0269=1270=1.43503271=500000055=GBP/USD110=300000010=226
20260120-14:04:05.604082000 : 8=FIX.4.49=027735=X49=NTPRO_IDBA_UAT56=SIRIUS_500007460_MD34=108752=20260120-14:04:06.367262=MD_EUR/USD_140109278614268=3279=1269=0270=1.1479271=10000055=EUR/USD110=0279=1269=0270=1.1479271=50000055=EUR/USD110=100000279=1269=0270=1.1479271=100000055=EUR/USD110=50000010=123
20260120-14:04:07.186082000 : 8=FIX.4.49=028035=X49=NTPRO_IDBA_UAT56=SIRIUS_500007460_MD34=108852=20260120-14:04:08.007262=MD_EUR/USD_140109278614268=3279=1269=1270=1.19814271=10000055=EUR/USD110=0279=1269=1270=1.19814271=50000055=EUR/USD110=100000279=1269=1270=1.19814271=100000055=EUR/USD110=50000010=008
20260120-14:04:07.215722000 : 8=FIX.4.49=068435=X49=NTPRO_IDBA_UAT56=SIRIUS_500007460_MD34=108952=20260120-14:04:08.037262=MD_GBP/USD_140109778778268=10279=1269=0270=1.25469271=10000055=GBP/USD110=0279=1269=0270=1.25469271=50000055=GBP/USD110=100000279=1269=0270=1.25469271=100000055=GBP/USD110=500000279=1269=0270=1.25469271=300000055=GBP/USD110=1000000279=1269=0270=1.25469271=500000055=GBP/USD110=3000000279=1269=1270=1.43505271=10000055=GBP/USD110=0279=1269=1270=1.43505271=50000055=GBP/USD110=100000279=1269=1270=1.43505271=100000055=GBP/USD110=500000279=1269=1270=1.43505271=300000055=GBP/USD110=1000000279=1269=1270=1.43505271=500000055=GBP/USD110=300000010=005
20260120-14:04:07.225160000 : 8=FIX.4.49=044735=X49=NTPRO_IDBA_UAT56=SIRIUS_500007460_MD34=109052=20260120-14:04:08.047262=MD_EUR/USD_140109278614268=6279=1269=0270=1.14792271=10000055=EUR/USD110=0279=1269=0270=1.14792271=50000055=EUR/USD110=100000279=1269=0270=1.14792271=100000055=EUR/USD110=500000279=1269=1270=1.19816271=10000055=EUR/USD110=0279=1269=1270=1.19816271=50000055=EUR/USD110=100000279=1269=1270=1.19816271=100000055=EUR/USD110=50000010=060
20260120-14:04:07.287736000 : 8=FIX.4.49=028035=X49=NTPRO_IDBA_UAT56=SIRIUS_500007460_MD34=109152=20260120-14:04:08.113262=MD_EUR/USD_140109278614268=3279=1269=0270=1.14791271=10000055=EUR/USD110=0279=1269=0270=1.14791271=50000055=EUR/USD110=100000279=1269=0270=1.14791271=100000055=EUR/USD110=50000010=250
20260120-14:04:07.298584000 : 8=FIX.4.49=039335=X49=NTPRO_IDBA_UAT56=SIRIUS_500007460_MD34=109252=20260120-14:04:08.126262=MD_GBP/USD_140109778778268=5279=1269=0270=1.2547271=10000055=GBP/USD110=0279=1269=0270=1.2547271=50000055=GBP/USD110=100000279=1269=0270=1.2547271=100000055=GBP/USD110=500000279=1269=0270=1.2547271=300000055=GBP/USD110=1000000279=1269=0270=1.2547271=500000055=GBP/USD110=300000010=082
20260120-14:04:07.308798000 : 8=FIX.4.49=044735=X49=NTPRO_IDBA_UAT56=SIRIUS_500007460_MD34=109352=20260120-14:04:08.137262=MD_EUR/USD_140109278614268=6279=1269=0270=1.14792271=10000055=EUR/USD110=0279=1269=0270=1.14792271=50000055=EUR/USD110=100000279=1269=0270=1.14792271=100000055=EUR/USD110=500000279=1269=1270=1.19817271=10000055=EUR/USD110=0279=1269=1270=1.19817271=50000055=EUR/USD110=100000279=1269=1270=1.19817271=100000055=EUR/USD110=50000010=066
20260120-14:04:07.357164000 : 8=FIX.4.49=067935=X49=NTPRO_IDBA_UAT56=SIRIUS_500007460_MD34=109452=20260120-14:04:08.187262=MD_GBP/USD_140109778778268=10279=2269=0270=1.2547271=10000055=GBP/USD110=0279=2269=0270=1.2547271=50000055=GBP/USD110=100000279=2269=0270=1.2547271=100000055=GBP/USD110=500000279=2269=0270=1.2547271=300000055=GBP/USD110=1000000279=2269=0270=1.2547271=500000055=GBP/USD110=3000000279=2269=1270=1.43505271=10000055=GBP/USD110=0279=2269=1270=1.43505271=50000055=GBP/USD110=100000279=2269=1270=1.43505271=100000055=GBP/USD110=500000279=2269=1270=1.43505271=300000055=GBP/USD110=1000000279=2269=1270=1.43505271=500000055=GBP/USD110=300000010=253
20260120-14:04:07.413709000 : 8=FIX.4.49=028035=X49=NTPRO_IDBA_UAT56=SIRIUS_500007460_MD34=109552=20260120-14:04:08.243262=MD_EUR/USD_140109278614268=3279=1269=0270=1.14793271=10000055=EUR/USD110=0279=1269=0270=1.14793271=50000055=EUR/USD110=100000279=1269=0270=1.14793271=100000055=EUR/USD110=50000010=008
20260120-14:04:07.465827000 : 8=FIX.4.49=044735=X49=NTPRO_IDBA_UAT56=SIRIUS_500007460_MD34=109652=20260120-14:04:08.299262=MD_EUR/USD_140109278614268=6279=1269=0270=1.14794271=10000055=EUR/USD110=0279=1269=0270=1.14794271=50000055=EUR/USD110=100000279=1269=0270=1.14794271=100000055=EUR/USD110=500000279=1269=1270=1.19818271=10000055=EUR/USD110=0279=1269=1270=1.19818271=50000055=EUR/USD110=100000279=1269=1270=1.19818271=100000055=EUR/USD110=50000010=087
20260120-14:04:07.596986000 : 8=FIX.4.49=044735=X49=NTPRO_IDBA_UAT56=SIRIUS_500007460_MD34=109752=20260120-14:04:08.434262=MD_EUR/USD_140109278614268=6279=1269=0270=1.14795271=10000055=EUR/USD110=0279=1269=0270=1.14795271=50000055=EUR/USD110=100000279=1269=0270=1.14795271=100000055=EUR/USD110=500000279=1269=1270=1.19819271=10000055=EUR/USD110=0279=1269=1270=1.19819271=50000055=EUR/USD110=100000279=1269=1270=1.19819271=100000055=EUR/USD110=50000010=085
20260120-14:04:07.603107000 : 8=FIX.4.49=068435=X49=NTPRO_IDBA_UAT56=SIRIUS_500007460_MD34=109852=20260120-14:04:08.440262=MD_GBP/USD_140109778778268=10279=0269=0270=1.25472271=10000055=GBP/USD110=0279=0269=0270=1.25472271=50000055=GBP/USD110=100000279=0269=0270=1.25472271=100000055=GBP/USD110=500000279=0269=0270=1.25472271=300000055=GBP/USD110=1000000279=0269=0270=1.25472271=500000055=GBP/USD110=3000000279=0269=1270=1.43508271=10000055=GBP/USD110=0279=0269=1270=1.43508271=50000055=GBP/USD110=100000279=0269=1270=1.43508271=100000055=GBP/USD110=500000279=0269=1270=1.43508271=300000055=GBP/USD110=1000000279=0269=1270=1.43508271=500000055=GBP/USD110=300000010=234
20260120-14:04:07.635772000 : 8=FIX.4.49=068435=X49=NTPRO_IDBA_UAT56=SIRIUS_500007460_MD34=109952=20260120-14:04:08.474262=MD_GBP/USD_140109778778268=10279=2269=0270=1.25472271=10000055=GBP/USD110=0279=2269=0270=1.25472271=50000055=GBP/USD110=100000279=2269=0270=1.25472271=100000055=GBP/USD110=500000279=2269=0270=1.25472271=300000055=GBP/USD110=1000000279=2269=0270=1.25472271=500000055=GBP/USD110=3000000279=2269=1270=1.43508271=10000055=GBP/USD110=0279=2269=1270=1.43508271=50000055=GBP/USD110=100000279=2269=1270=1.43508271=100000055=GBP/USD110=500000279=2269=1270=1.43508271=300000055=GBP/USD110=1000000279=2269=1270=1.43508271=500000055=GBP/USD110=300000010=006
20260120-14:04:07.644266000 : 8=FIX.4.49=028035=X49=NTPRO_IDBA_UAT56=SIRIUS_500007460_MD34=110052=20260120-14:04:08.483262=MD_EUR/USD_140109278614268=3279=1269=0270=1.14794271=10000055=EUR/USD110=0279=1269=0270=1.14794271=50000055=EUR/USD110=100000279=1269=0270=1.14794271=100000055=EUR/USD110=50000010=004
20260120-14:04:07.665661000 : 8=FIX.4.49=028035=X49=NTPRO_IDBA_UAT56=SIRIUS_500007460_MD34=110152=20260120-14:04:08.503262=MD_EUR/USD_140109278614268=3279=1269=0270=1.14795271=10000055=EUR/USD110=0279=1269=0270=1.14795271=50000055=EUR/USD110=100000279=1269=0270=1.14795271=100000055=EUR/USD110=50000010=001
20260120-14:04:08.254896000 : 8=FIX.4.49=028035=X49=NTPRO_IDBA_UAT56=SIRIUS_500007460_MD34=110252=20260120-14:04:09.112262=MD_EUR/USD_140109278614268=3279=1269=0270=1.14794271=10000055=EUR/USD110=0279=1269=0270=1.14794271=50000055=EUR/USD110=100000279=1269=0270=1.14794271=100000055=EUR/USD110=50000010=252
20260120-14:04:08.998510000 : 8=FIX.4.49=028035=X49=NTPRO_IDBA_UAT56=SIRIUS_500007460_MD34=110352=20260120-14:04:09.881262=MD_EUR/USD_140109278614268=3279=1269=1270=1.19818271=10000055=EUR/USD110=0279=1269=1270=1.19818271=50000055=EUR/USD110=100000279=1269=1270=1.19818271=100000055=EUR/USD110=50000010=019
20260120-14:04:09.204213000 : 8=FIX.4.49=068435=X49=NTPRO_IDBA_UAT56=SIRIUS_500007460_MD34=110452=20260120-14:04:10.090262=MD_GBP/USD_140109778778268=10279=0269=0270=1.25472271=10000055=GBP/USD110=0279=0269=0270=1.25472271=50000055=GBP/USD110=100000279=0269=0270=1.25472271=100000055=GBP/USD110=500000279=0269=0270=1.25472271=300000055=GBP/USD110=1000000279=0269=0270=1.25472271=500000055=GBP/USD110=3000000279=0269=1270=1.43507271=10000055=GBP/USD110=0279=0269=1270=1.43507271=50000055=GBP/USD110=100000279=0269=1270=1.43507271=100000055=GBP/USD110=500000279=0269=1270=1.43507271=300000055=GBP/USD110=1000000279=0269=1270=1.43507271=500000055=GBP/USD110=300000010=211
20260120-14:04:09.364813000 : 8=FIX.4.49=028035=X49=NTPRO_IDBA_UAT56=SIRIUS_500007460_MD34=110552=20260120-14:04:10.249262=MD_EUR/USD_140109278614268=3279=1269=0270=1.14793271=10000055=EUR/USD110=0279=1269=0270=1.14793271=50000055=EUR/USD110=100000279=1269=0270=1.14793271=100000055=EUR/USD110=50000010=255
20260120-14:04:09.395062000 : 8=FIX.4.49=039835=X49=NTPRO_IDBA_UAT56=SIRIUS_500007460_MD34=110652=20260120-14:04:10.290262=MD_GBP/USD_140109778778268=5279=1269=0270=1.25471271=10000055=GBP/USD110=0279=1269=0270=1.25471271=50000055=GBP/USD110=100000279=1269=0270=1.25471271=100000055=GBP/USD110=500000279=1269=0270=1.25471271=300000055=GBP/USD110=1000000279=1269=0270=1.25471271=500000055=GBP/USD110=300000010=067
20260120-14:04:09.466238000 : 8=FIX.4.49=028035=X49=NTPRO_IDBA_UAT56=SIRIUS_500007460_MD34=110752=20260120-14:04:10.348262=MD_EUR/USD_140109278614268=3279=1269=1270=1.19817271=10000055=EUR/USD110=0279=1269=1270=1.19817271=50000055=EUR/USD110=100000279=1269=1270=1.19817271=100000055=EUR/USD110=50000010=010
20260120-14:04:09.485701000 : 8=FIX.4.49=028035=X49=NTPRO_IDBA_UAT56=SIRIUS_500007460_MD34=110852=20260120-14:04:10.384262=MD_EUR/USD_140109278614268=3279=1269=1270=1.19818271=10000055=EUR/USD110=0279=1269=1270=1.19818271=50000055=EUR/USD110=100000279=1269=1270=1.19818271=100000055=EUR/USD110=50000010=014
20260120-14:04:09.538492000 : 8=FIX.4.49=039835=X49=NTPRO_IDBA_UAT56=SIRIUS_500007460_MD34=110952=20260120-14:04:10.439262=MD_GBP/USD_140109778778268=5279=1269=1270=1.43508271=10000055=GBP/USD110=0279=1269=1270=1.43508271=50000055=GBP/USD110=100000279=1269=1270=1.43508271=100000055=GBP/USD110=500000279=1269=1270=1.43508271=300000055=GBP/USD110=1000000279=1269=1270=1.43508271=500000055=GBP/USD110=300000010=085
20260120-14:04:09.596698000 : 8=FIX.4.49=044735=X49=NTPRO_IDBA_UAT56=SIRIUS_500007460_MD34=111052=20260120-14:04:10.497262=MD_EUR/USD_140109278614268=6279=1269=0270=1.14794271=10000055=EUR/USD110=0279=1269=0270=1.14794271=50000055=EUR/USD110=100000279=1269=0270=1.14794271=100000055=EUR/USD110=500000279=1269=1270=1.19819271=10000055=EUR/USD110=0279=1269=1270=1.19819271=50000055=EUR/USD110=100000279=1269=1270=1.19819271=100000055=EUR/USD110=50000010=070
20260120-14:04:09.643306000 : 8=FIX.4.49=067935=X49=NTPRO_IDBA_UAT56=SIRIUS_500007460_MD34=111152=20260120-14:04:10.541262=MD_GBP/USD_140109778778268=10279=1269=0270=1.2547271=10000055=GBP/USD110=0279=1269=0270=1.2547271=50000055=GBP/USD110=100000279=1269=0270=1.2547271=100000055=GBP/USD110=500000279=1269=0270=1.2547271=300000055=GBP/USD110=1000000279=1269=0270=1.2547271=500000055=GBP/USD110=3000000279=1269=1270=1.43507271=10000055=GBP/USD110=0279=1269=1270=1.43507271=50000055=GBP/USD110=100000279=1269=1270=1.43507271=100000055=GBP/USD110=500000279=1269=1270=1.43507271=300000055=GBP/USD110=1000000279=1269=1270=1.43507271=500000055=GBP/USD110=300000010=230
20260120-14:04:09.667390000 : 8=FIX.4.49=028035=X49=NTPRO_IDBA_UAT56=SIRIUS_500007460_MD34=111252=20260120-14:04:10.562262=MD_EUR/USD_140109278614268=3279=1269=1270=1.19818271=10000055=EUR/USD110=0279=1269=1270=1.19818271=50000055=EUR/USD110=100000279=1269=1270=1.19818271=100000055=EUR/USD110=50000010=007
20260120-14:04:09.699787000 : 8=FIX.4.49=028035=X49=NTPRO_IDBA_UAT56=SIRIUS_500007460_MD34=111352=20260120-14:04:10.598262=MD_EUR/USD_140109278614268=3279=1269=1270=1.19819271=10000055=EUR/USD110=0279=1269=1270=1.19819271=50000055=EUR/USD110=100000279=1269=1270=1.19819271=100000055=EUR/USD110=50000010=020
20260120-14:04:09.766800000 : 8=FIX.4.49=044735=X49=NTPRO_IDBA_UAT56=SIRIUS_500007460_MD34=111452=20260120-14:04:10.673262=MD_EUR/USD_140109278614268=6279=1269=0270=1.14793271=10000055=EUR/USD110=0279=1269=0270=1.14793271=50000055=EUR/USD110=100000279=1269=0270=1.14793271=100000055=EUR/USD110=500000279=1269=1270=1.19818271=10000055=EUR/USD110=0279=1269=1270=1.19818271=50000055=EUR/USD110=100000279=1269=1270=1.19818271=100000055=EUR/USD110=50000010=064
20260120-14:04:09.779795000 : 8=FIX.4.49=068435=X49=NTPRO_IDBA_UAT56=SIRIUS_500007460_MD34=111552=20260120-14:04:10.688262=MD_GBP/USD_140109778778268=10279=1269=0270=1.25471271=10000055=GBP/USD110=0279=1269=0270=1.25471271=50000055=GBP/USD110=100000279=1269=0270=1.25471271=100000055=GBP/USD110=500000279=1269=0270=1.25471271=300000055=GBP/USD110=1000000279=1269=0270=1.25471271=500000055=GBP/USD110=3000000279=1269=1270=1.43506271=10000055=GBP/USD110=0279=1269=1270=1.43506271=50000055=GBP/USD110=100000279=1269=1270=1.43506271=100000055=GBP/USD110=500000279=1269=1270=1.43506271=300000055=GBP/USD110=1000000279=1269=1270=1.43506271=500000055=GBP/USD110=300000010=226
20260120-14:04:09.833435000 : 8=FIX.4.49=028035=X49=NTPRO_IDBA_UAT56=SIRIUS_500007460_MD34=111652=20260120-14:04:10.743262=MD_EUR/USD_140109278614268=3279=1269=0270=1.14794271=10000055=EUR/USD110=0279=1269=0270=1.14794271=50000055=EUR/USD110=100000279=1269=0270=1.14794271=100000055=EUR/USD110=50000010=003
20260120-14:04:10.016975000 : 8=FIX.4.49=068435=X49=NTPRO_IDBA_UAT56=SIRIUS_500007460_MD34=111752=20260120-14:04:10.932262=MD_GBP/USD_140109778778268=10279=2269=0270=1.25471271=10000055=GBP/USD110=0279=2269=0270=1.25471271=50000055=GBP/USD110=100000279=2269=0270=1.25471271=100000055=GBP/USD110=500000279=2269=0270=1.25471271=300000055=GBP/USD110=1000000279=2269=0270=1.25471271=500000055=GBP/USD110=3000000279=2269=1270=1.43506271=10000055=GBP/USD110=0279=2269=1270=1.43506271=50000055=GBP/USD110=100000279=2269=1270=1.43506271=100000055=GBP/USD110=500000279=2269=1270=1.43506271=300000055=GBP/USD110=1000000279=2269=1270=1.43506271=500000055=GBP/USD110=300000010=230
20260120-14:04:10.361974000 : 8=FIX.4.49=028035=X49=NTPRO_IDBA_UAT56=SIRIUS_500007460_MD34=111852=20260120-14:04:11.273262=MD_EUR/USD_140109278614268=3279=1269=0270=1.14793271=10000055=EUR/USD110=0279=1269=0270=1.14793271=50000055=EUR/USD110=100000279=1269=0270=1.14793271=100000055=EUR/USD110=50000010=001
20260120-14:04:10.387059000 : 8=FIX.4.49=028035=X49=NTPRO_IDBA_UAT56=SIRIUS_500007460_MD34=111952=20260120-14:04:11.310262=MD_EUR/USD_140109278614268=3279=1269=1270=1.19817271=10000055=EUR/USD110=0279=1269=1270=1.19817271=50000055=EUR/USD110=100000279=1269=1270=1.19817271=100000055=EUR/USD110=50000010=003
20260120-14:04:10.413542000 : 8=FIX.4.49=068435=X49=NTPRO_IDBA_UAT56=SIRIUS_500007460_MD34=112052=20260120-14:04:11.341262=MD_GBP/USD_140109778778268=10279=0269=0270=1.25471271=10000055=GBP/USD110=0279=0269=0270=1.25471271=50000055=GBP/USD110=100000279=0269=0270=1.25471271=100000055=GBP/USD110=500000279=0269=0270=1.25471271=300000055=GBP/USD110=1000000279=0269=0270=1.25471271=500000055=GBP/USD110=3000000279=0269=1270=1.43506271=10000055=GBP/USD110=0279=0269=1270=1.43506271=50000055=GBP/USD110=100000279=0269=1270=1.43506271=100000055=GBP/USD110=500000279=0269=1270=1.43506271=300000055=GBP/USD110=1000000279=0269=1270=1.43506271=500000055=GBP/USD110=300000010=199
20260120-14:04:10.439879000 : 8=FIX.4.49=068435=X49=NTPRO_IDBA_UAT56=SIRIUS_500007460_MD34=112152=20260120-14:04:11.370262=MD_GBP/USD_140109778778268=10279=2269=0270=1.25471271=10000055=GBP/USD110=0279=2269=0270=1.25471271=50000055=GBP/USD110=100000279=2269=0270=1.25471271=100000055=GBP/USD110=500000279=2269=0270=1.25471271=300000055=GBP/USD110=1000000279=2269=0270=1.25471271=500000055=GBP/USD110=3000000279=2269=1270=1.43506271=10000055=GBP/USD110=0279=2269=1270=1.43506271=50000055=GBP/USD110=100000279=2269=1270=1.43506271=100000055=GBP/USD110=500000279=2269=1270=1.43506271=300000055=GBP/USD110=1000000279=2269=1270=1.43506271=500000055=GBP/USD110=300000010=222
20260120-14:04:10.485486000 : 8=FIX.4.49=044735=X49=NTPRO_IDBA_UAT56=SIRIUS_500007460_MD34=112252=20260120-14:04:11.416262=MD_EUR/USD_140109278614268=6279=1269=0270=1.14795271=10000055=EUR/USD110=0279=1269=0270=1.14795271=50000055=EUR/USD110=100000279=1269=0270=1.14795271=100000055=EUR/USD110=500000279=1269=1270=1.19819271=10000055=EUR/USD110=0279=1269=1270=1.19819271=50000055=EUR/USD110=100000279=1269=1270=1.19819271=100000055=EUR/USD110=50000010=068
20260120-14:04:10.601626000 : 8=FIX.4.49=027735=X49=NTPRO_IDBA_UAT56=SIRIUS_500007460_MD34=112352=20260120-14:04:11.536262=MD_EUR/USD_140109278614268=3279=1269=1270=1.1982271=10000055=EUR/USD110=0279=1269=1270=1.1982271=50000055=EUR/USD110=100000279=1269=1270=1.1982271=100000055=EUR/USD110=50000010=108
20260120-14:04:10.617678000 : 8=FIX.4.49=028035=X49=NTPRO_IDBA_UAT56=SIRIUS_500007460_MD34=112452=20260120-14:04:11.552262=MD_EUR/USD_140109278614268=3279=1269=1270=1.19819271=10000055=EUR/USD110=0279=1269=1270=1.19819271=50000055=EUR/USD110=100000279=1269=1270=1.19819271=100000055=EUR/USD110=50000010=013
20260120-14:04:10.756407000 : 8=FIX.4.49=027735=X49=NTPRO_IDBA_UAT56=SIRIUS_500007460_MD34=112552=20260120-14:04:11.695262=MD_EUR/USD_140109278614268=3279=1269=1270=1.1982271=10000055=EUR/USD110=0279=1269=1270=1.1982271=50000055=EUR/USD110=100000279=1269=1270=1.1982271=100000055=EUR/USD110=50000010=116
20260120-14:04:11.357048000 : 8=FIX.4.49=068435=X49=NTPRO_IDBA_UAT56=SIRIUS_500007460_MD34=112652=20260120-14:04:12.287262=MD_GBP/USD_140109778778268=10279=0269=0270=1.25472271=10000055=GBP/USD110=0279=0269=0270=1.25472271=50000055=GBP/USD110=100000279=0269=0270=1.25472271=100000055=GBP/USD110=500000279=0269=0270=1.25472271=300000055=GBP/USD110=1000000279=0269=0270=1.25472271=500000055=GBP/USD110=3000000279=0269=1270=1.43507271=10000055=GBP/USD110=0279=0269=1270=1.43507271=50000055=GBP/USD110=100000279=0269=1270=1.43507271=100000055=GBP/USD110=500000279=0269=1270=1.43507271=300000055=GBP/USD110=1000000279=0269=1270=1.43507271=500000055=GBP/USD110=300000010=225
20260120-14:04:11.385008000 : 8=FIX.4.49=028035=X49=NTPRO_IDBA_UAT56=SIRIUS_500007460_MD34=112752=20260120-14:04:12.345262=MD_EUR/USD_140109278614268=3279=1269=1270=1.19819271=10000055=EUR/USD110=0279=1269=1270=1.19819271=50000055=EUR/USD110=100000279=1269=1270=1.19819271=100000055=EUR/USD110=50000010=017
20260120-14:04:11.555965000 : 8=FIX.4.49=027735=X49=NTPRO_IDBA_UAT56=SIRIUS_500007460_MD34=112852=20260120-14:04:12.522262=MD_EUR/USD_140109278614268=3279=1269=1270=1.1982271=10000055=EUR/USD110=0279=1269=1270=1.1982271=50000055=EUR/USD110=100000279=1269=1270=1.1982271=100000055=EUR/USD110=50000010=109
20260120-14:04:11.749197000 : 8=FIX.4.49=039835=X49=NTPRO_IDBA_UAT56=SIRIUS_500007460_MD34=112952=20260120-14:04:12.718262=MD_GBP/USD_140109778778268=5279=1269=1270=1.43508271=10000055=GBP/USD110=0279=1269=1270=1.43508271=50000055=GBP/USD110=100000279=1269=1270=1.43508271=100000055=GBP/USD110=500000279=1269=1270=1.43508271=300000055=GBP/USD110=1000000279=1269=1270=1.43508271=500000055=GBP/USD110=300000010=089
20260120-14:04:11.775485000 : 8=FIX.4.49=028035=X49=NTPRO_IDBA_UAT56=SIRIUS_500007460_MD34=113052=20260120-14:04:12.749262=MD_EUR/USD_140109278614268=3279=1269=1270=1.19819271=10000055=EUR/USD110=0279=1269=1270=1.19819271=50000055=EUR/USD110=100000279=1269=1270=1.19819271=100000055=EUR/USD110=50000010=019
20260120-14:04:11.849997000 : 8=FIX.4.49=044435=X49=NTPRO_IDBA_UAT56=SIRIUS_500007460_MD34=113152=20260120-14:04:12.825262=MD_EUR/USD_140109278614268=6279=1269=0270=1.14796271=10000055=EUR/USD110=0279=1269=0270=1.14796271=50000055=EUR/USD110=100000279=1269=0270=1.14796271=100000055=EUR/USD110=500000279=1269=1270=1.1982271=10000055=EUR/USD110=0279=1269=1270=1.1982271=50000055=EUR/USD110=100000279=1269=1270=1.1982271=100000055=EUR/USD110=50000010=161
20260120-14:04:11.890006000 : 8=FIX.4.49=068435=X49=NTPRO_IDBA_UAT56=SIRIUS_500007460_MD34=113252=20260120-14:04:12.867262=MD_GBP/USD_140109778778268=10279=1269=0270=1.25473271=10000055=GBP/USD110=0279=1269=0270=1.25473271=50000055=GBP/USD110=100000279=1269=0270=1.25473271=100000055=GBP/USD110=500000279=1269=0270=1.25473271=300000055=GBP/USD110=1000000279=1269=0270=1.25473271=500000055=GBP/USD110=3000000279=1269=1270=1.43509271=10000055=GBP/USD110=0279=1269=1270=1.43509271=50000055=GBP/USD110=100000279=1269=1270=1.43509271=100000055=GBP/USD110=500000279=1269=1270=1.43509271=300000055=GBP/USD110=1000000279=1269=1270=1.43509271=500000055=GBP/USD110=300000010=251
20260120-14:04:11.945405000 : 8=FIX.4.49=044735=X49=NTPRO_IDBA_UAT56=SIRIUS_500007460_MD34=113352=20260120-14:04:12.923262=MD_EUR/USD_140109278614268=6279=1269=0270=1.14795271=10000055=EUR/USD110=0279=1269=0270=1.14795271=50000055=EUR/USD110=100000279=1269=0270=1.14795271=100000055=EUR/USD110=500000279=1269=1270=1.19819271=10000055=EUR/USD110=0279=1269=1270=1.19819271=50000055=EUR/USD110=100000279=1269=1270=1.19819271=100000055=EUR/USD110=50000010=074
20260120-14:04:12.092049000 : 8=FIX.4.49=027735=X49=NTPRO_IDBA_UAT56=SIRIUS_500007460_MD34=113452=20260120-14:04:13.076262=MD_EUR/USD_140109278614268=3279=1269=1270=1.1982271=10000055=EUR/USD110=0279=1269=1270=1.1982271=50000055=EUR/USD110=100000279=1269=1270=1.1982271=100000055=EUR/USD110=50000010=111
20260120-14:04:12.440182000 : 8=FIX.4.49=028035=X49=NTPRO_IDBA_UAT56=SIRIUS_500007460_MD34=113552=20260120-14:04:13.430262=MD_EUR/USD_140109278614268=3279=1269=1270=1.19819271=10000055=EUR/USD110=0279=1269=1270=1.19819271=50000055=EUR/USD110=100000279=1269=1270=1.19819271=100000055=EUR/USD110=50000010=012
20260120-14:04:12.572435000 : 8=FIX.4.49=027735=X49=NTPRO_IDBA_UAT56=SIRIUS_500007460_MD34=113652=20260120-14:04:13.572262=MD_EUR/USD_140109278614268=3279=1269=1270=1.1982271=10000055=EUR/USD110=0279=1269=1270=1.1982271=50000055=EUR/USD110=100000279=1269=1270=1.1982271=100000055=EUR/USD110=50000010=114
20260120-14:04:12.655479000 : 8=FIX.4.49=028035=X49=NTPRO_IDBA_UAT56=SIRIUS_500007460_MD34=113752=20260120-14:04:13.658262=MD_EUR/USD_140109278614268=3279=1269=0270=1.14796271=10000055=EUR/USD110=0279=1269=0270=1.14796271=50000055=EUR/USD110=100000279=1269=0270=1.14796271=100000055=EUR/USD110=50000010=020
20260120-14:04:12.743383000 : 8=FIX.4.49=039835=X49=NTPRO_IDBA_UAT56=SIRIUS_500007460_MD34=113852=20260120-14:04:13.715262=MD_GBP/USD_140109778778268=5279=1269=0270=1.25474271=10000055=GBP/USD110=0279=1269=0270=1.25474271=50000055=GBP/USD110=100000279=1269=0270=1.25474271=100000055=GBP/USD110=500000279=1269=0270=1.25474271=300000055=GBP/USD110=1000000279=1269=0270=1.25474271=500000055=GBP/USD110=300000010=092
20260120-14:04:12.840646000 : 8=FIX.4.49=039335=X49=NTPRO_IDBA_UAT56=SIRIUS_500007460_MD34=113952=20260120-14:04:13.833262=MD_GBP/USD_140109778778268=5279=1269=1270=1.4351271=10000055=GBP/USD110=0279=1269=1270=1.4351271=50000055=GBP/USD110=100000279=1269=1270=1.4351271=100000055=GBP/USD110=500000279=1269=1270=1.4351271=300000055=GBP/USD110=1000000279=1269=1270=1.4351271=500000055=GBP/USD110=300000010=065
20260120-14:04:12.846462000 : 8=FIX.4.49=028035=X49=NTPRO_IDBA_UAT56=SIRIUS_500007460_MD34=114052=20260120-14:04:13.855262=MD_EUR/USD_140109278614268=3279=1269=1270=1.19821271=10000055=EUR/USD110=0279=1269=1270=1.19821271=50000055=EUR/USD110=100000279=1269=1270=1.19821271=100000055=EUR/USD110=50000010=254
20260120-14:04:12.851238000 : 8=FIX.4.49=039835=X49=NTPRO_IDBA_UAT56=SIRIUS_500007460_MD34=114152=20260120-14:04:13.859262=MD_GBP/USD_140109778778268=5279=1269=0270=1.25475271=10000055=GBP/USD110=0279=1269=0270=1.25475271=50000055=GBP/USD110=100000279=1269=0270=1.25475271=100000055=GBP/USD110=500000279=1269=0270=1.25475271=300000055=GBP/USD110=1000000279=1269=0270=1.25475271=500000055=GBP/USD110=300000010=100
20260120-14:04:12.946626000 : 8=FIX.4.49=039835=X49=NTPRO_IDBA_UAT56=SIRIUS_500007460_MD34=114252=20260120-14:04:13.955262=MD_GBP/USD_140109778778268=5279=1269=1270=1.43511271=10000055=GBP/USD110=0279=1269=1270=1.43511271=50000055=GBP/USD110=100000279=1269=1270=1.43511271=100000055=GBP/USD110=500000279=1269=1270=1.43511271=300000055=GBP/USD110=1000000279=1269=1270=1.43511271=500000055=GBP/USD110=300000010=058
20260120-14:04:12.979138000 : 8=FIX.4.49=044735=X49=NTPRO_IDBA_UAT56=SIRIUS_500007460_MD34=114352=20260120-14:04:13.992262=MD_EUR/USD_140109278614268=6279=1269=0270=1.14797271=10000055=EUR/USD110=0279=1269=0270=1.14797271=50000055=EUR/USD110=100000279=1269=0270=1.14797271=100000055=EUR/USD110=500000279=1269=1270=1.19822271=10000055=EUR/USD110=0279=1269=1270=1.19822271=50000055=EUR/USD110=100000279=1269=1270=1.19822271=100000055=EUR/USD110=50000010=070
20260120-14:04:13.505026000 : 8=FIX.4.49=039335=X49=NTPRO_IDBA_UAT56=SIRIUS_500007460_MD34=114452=20260120-14:04:14.535262=MD_GBP/USD_140109778778268=5279=1269=1270=1.4351271=10000055=GBP/USD110=0279=1269=1270=1.4351271=50000055=GBP/USD110=100000279=1269=1270=1.4351271=100000055=GBP/USD110=500000279=1269=1270=1.4351271=300000055=GBP/USD110=1000000279=1269=1270=1.4351271=500000055=GBP/USD110=300000010=061
20260120-14:04:13.593033000 : 8=FIX.4.49=028035=X49=NTPRO_IDBA_UAT56=SIRIUS_500007460_MD34=114552=20260120-14:04:14.621262=MD_EUR/USD_140109278614268=3279=1269=0270=1.14798271=10000055=EUR/USD110=0279=1269=0270=1.14798271=50000055=EUR/USD110=100000279=1269=0270=1.14798271=100000055=EUR/USD110=50000010=016
20260120-14:04:13.693036000 : 8=FIX.4.49=044735=X49=NTPRO_IDBA_UAT56=SIRIUS_500007460_MD34=114652=20260120-14:04:14.729262=MD_EUR/USD_140109278614268=6279=1269=0270=1.14797271=10000055=EUR/USD110=0279=1269=0270=1.14797271=50000055=EUR/USD110=100000279=1269=0270=1.14797271=100000055=EUR/USD110=500000279=1269=1270=1.19821271=10000055=EUR/USD110=0279=1269=1270=1.19821271=50000055=EUR/USD110=100000279=1269=1270=1.19821271=100000055=EUR/USD110=50000010=069
20260120-14:04:13.741961000 : 8=FIX.4.49=068435=X49=NTPRO_IDBA_UAT56=SIRIUS_500007460_MD34=114752=20260120-14:04:14.778262=MD_GBP/USD_140109778778268=10279=1269=0270=1.25471271=10000055=GBP/USD110=0279=1269=0270=1.25471271=50000055=GBP/USD110=100000279=1269=0270=1.25471271=100000055=GBP/USD110=500000279=1269=0270=1.25471271=300000055=GBP/USD110=1000000279=1269=0270=1.25471271=500000055=GBP/USD110=3000000279=1269=1270=1.43507271=10000055=GBP/USD110=0279=1269=1270=1.43507271=50000055=GBP/USD110=100000279=1269=1270=1.43507271=100000055=GBP/USD110=500000279=1269=1270=1.43507271=300000055=GBP/USD110=1000000279=1269=1270=1.43507271=500000055=GBP/USD110=300000010=240
20260120-14:04:13.763151000 : 8=FIX.4.49=044735=X49=NTPRO_IDBA_UAT56=SIRIUS_500007460_MD34=114852=20260120-14:04:14.793262=MD_EUR/USD_140109278614268=6279=1269=0270=1.14795271=10000055=EUR/USD110=0279=1269=0270=1.14795271=50000055=EUR/USD110=100000279=1269=0270=1.14795271=100000055=EUR/USD110=500000279=1269=1270=1.19819271=10000055=EUR/USD110=0279=1269=1270=1.19819271=50000055=EUR/USD110=100000279=1269=1270=1.19819271=100000055=EUR/USD110=50000010=087
20260120-14:04:13.831523000 : 8=FIX.4.49=067935=X49=NTPRO_IDBA_UAT56=SIRIUS_500007460_MD34=114952=20260120-14:04:14.868262=MD_GBP/USD_140109778778268=10279=1269=0270=1.2547271=10000055=GBP/USD110=0279=1269=0270=1.2547271=50000055=GBP/USD110=100000279=1269=0270=1.2547271=100000055=GBP/USD110=500000279=1269=0270=1.2547271=300000055=GBP/USD110=1000000279=1269=0270=1.2547271=500000055=GBP/USD110=3000000279=1269=1270=1.43506271=10000055=GBP/USD110=0279=1269=1270=1.43506271=50000055=GBP/USD110=100000279=1269=1270=1.43506271=100000055=GBP/USD110=500000279=1269=1270=1.43506271=300000055=GBP/USD110=1000000279=1269=1270=1.43506271=500000055=GBP/USD110=300000010=252
20260120-14:04:13.885229000 : 8=FIX.4.49=044435=X49=NTPRO_IDBA_UAT56=SIRIUS_500007460_MD34=115052=20260120-14:04:14.927262=MD_EUR/USD_140109278614268=6279=1269=0270=1.14796271=10000055=EUR/USD110=0279=1269=0270=1.14796271=50000055=EUR/USD110=100000279=1269=0270=1.14796271=100000055=EUR/USD110=500000279=1269=1270=1.1982271=10000055=EUR/USD110=0279=1269=1270=1.1982271=50000055=EUR/USD110=100000279=1269=1270=1.1982271=100000055=EUR/USD110=50000010=167
20260120-14:04:15.075484000 : 8=FIX.4.49=044735=X49=NTPRO_IDBA_UAT56=SIRIUS_500007460_MD34=115152=20260120-14:04:15.027262=MD_EUR/USD_140109278614268=6279=1269=0270=1.14795271=10000055=EUR/USD110=0279=1269=0270=1.14795271=50000055=EUR/USD110=100000279=1269=0270=1.14795271=100000055=EUR/USD110=500000279=1269=1270=1.19819271=10000055=EUR/USD110=0279=1269=1270=1.19819271=50000055=EUR/USD110=100000279=1269=1270=1.19819271=100000055=EUR/USD110=50000010=072
20260120-14:04:15.077384000 : 8=FIX.4.49=7735=034=1349=SIRIUS_500007460_MD52=20260120-14:04:15.07656=NTPRO_IDBA_UAT10=069
20260120-14:04:15.332643000 : 8=FIX.4.49=039835=X49=NTPRO_IDBA_UAT56=SIRIUS_500007460_MD34=115252=20260120-14:04:15.293262=MD_GBP/USD_140109778778268=5279=1269=0270=1.25471271=10000055=GBP/USD110=0279=1269=0270=1.25471271=50000055=GBP/USD110=100000279=1269=0270=1.25471271=100000055=GBP/USD110=500000279=1269=0270=1.25471271=300000055=GBP/USD110=1000000279=1269=0270=1.25471271=500000055=GBP/USD110=300000010=076
20260120-14:04:15.349908000 : 8=FIX.4.49=027735=X49=NTPRO_IDBA_UAT56=SIRIUS_500007460_MD34=115352=20260120-14:04:15.310262=MD_EUR/USD_140109278614268=3279=1269=1270=1.1982271=10000055=EUR/USD110=0279=1269=1270=1.1982271=50000055=EUR/USD110=100000279=1269=1270=1.1982271=100000055=EUR/USD110=50000010=105
20260120-14:04:15.421074000 : 8=FIX.4.49=028035=X49=NTPRO_IDBA_UAT56=SIRIUS_500007460_MD34=115452=20260120-14:04:15.370262=MD_EUR/USD_140109278614268=3279=1269=1270=1.19819271=10000055=EUR/USD110=0279=1269=1270=1.19819271=50000055=EUR/USD110=100000279=1269=1270=1.19819271=100000055=EUR/USD110=50000010=018
20260120-14:04:15.768568000 : 8=FIX.4.49=067935=X49=NTPRO_IDBA_UAT56=SIRIUS_500007460_MD34=115552=20260120-14:04:15.743262=MD_GBP/USD_140109778778268=10279=1269=0270=1.2547271=10000055=GBP/USD110=0279=1269=0270=1.2547271=50000055=GBP/USD110=100000279=1269=0270=1.2547271=100000055=GBP/USD110=500000279=1269=0270=1.2547271=300000055=GBP/USD110=1000000279=1269=0270=1.2547271=500000055=GBP/USD110=3000000279=1269=1270=1.43505271=10000055=GBP/USD110=0279=1269=1270=1.43505271=50000055=GBP/USD110=100000279=1269=1270=1.43505271=100000055=GBP/USD110=500000279=1269=1270=1.43505271=300000055=GBP/USD110=1000000279=1269=1270=1.43505271=500000055=GBP/USD110=300000010=237
20260120-14:04:15.789273000 : 8=FIX.4.49=028035=X49=NTPRO_IDBA_UAT56=SIRIUS_500007460_MD34=115652=20260120-14:04:15.764262=MD_EUR/USD_140109278614268=3279=1269=0270=1.14794271=10000055=EUR/USD110=0279=1269=0270=1.14794271=50000055=EUR/USD110=100000279=1269=0270=1.14794271=100000055=EUR/USD110=50000010=015
20260120-14:04:15.819214000 : 8=FIX.4.49=068435=X49=NTPRO_IDBA_UAT56=SIRIUS_500007460_MD34=115752=20260120-14:04:15.789262=MD_GBP/USD_140109778778268=10279=1269=0270=1.25467271=10000055=GBP/USD110=0279=1269=0270=1.25467271=50000055=GBP/USD110=100000279=1269=0270=1.25467271=100000055=GBP/USD110=500000279=1269=0270=1.25467271=300000055=GBP/USD110=1000000279=1269=0270=1.25467271=500000055=GBP/USD110=3000000279=1269=1270=1.43503271=10000055=GBP/USD110=0279=1269=1270=1.43503271=50000055=GBP/USD110=100000279=1269=1270=1.43503271=100000055=GBP/USD110=500000279=1269=1270=1.43503271=300000055=GBP/USD110=1000000279=1269=1270=1.43503271=500000055=GBP/USD110=300000010=249
20260120-14:04:15.866078000 : 8=FIX.4.49=028035=X49=NTPRO_IDBA_UAT56=SIRIUS_500007460_MD34=115852=20260120-14:04:15.844262=MD_EUR/USD_140109278614268=3279=1269=1270=1.19818271=10000055=EUR/USD110=0279=1269=1270=1.19818271=50000055=EUR/USD110=100000279=1269=1270=1.19818271=100000055=EUR/USD110=50000010=025
20260120-14:04:16.160260000 : 8=FIX.4.49=039835=X49=NTPRO_IDBA_UAT56=SIRIUS_500007460_MD34=115952=20260120-14:04:16.147262=MD_GBP/USD_140109778778268=5279=1269=0270=1.25468271=10000055=GBP/USD110=0279=1269=0270=1.25468271=50000055=GBP/USD110=100000279=1269=0270=1.25468271=100000055=GBP/USD110=500000279=1269=0270=1.25468271=300000055=GBP/USD110=1000000279=1269=0270=1.25468271=500000055=GBP/USD110=300000010=112
20260120-14:04:16.273512000 : 8=FIX.4.49=028035=X49=NTPRO_IDBA_UAT56=SIRIUS_500007460_MD34=116052=20260120-14:04:16.264262=MD_EUR/USD_140109278614268=3279=1269=1270=1.19819271=10000055=EUR/USD110=0279=1269=1270=1.19819271=50000055=EUR/USD110=100000279=1269=1270=1.19819271=100000055=EUR/USD110=50000010=018
20260120-14:04:16.315419000 : 8=FIX.4.49=028035=X49=NTPRO_IDBA_UAT56=SIRIUS_500007460_MD34=116152=20260120-14:04:16.291262=MD_EUR/USD_140109278614268=3279=1269=0270=1.14795271=10000055=EUR/USD110=0279=1269=0270=1.14795271=50000055=EUR/USD110=100000279=1269=0270=1.14795271=100000055=EUR/USD110=50000010=010
20260120-14:04:16.351540000 : 8=FIX.4.49=068435=X49=NTPRO_IDBA_UAT56=SIRIUS_500007460_MD34=116252=20260120-14:04:16.344262=MD_GBP/USD_140109778778268=10279=2269=0270=1.25468271=10000055=GBP/USD110=0279=2269=0270=1.25468271=50000055=GBP/USD110=100000279=2269=0270=1.25468271=100000055=GBP/USD110=500000279=2269=0270=1.25468271=300000055=GBP/USD110=1000000279=2269=0270=1.25468271=500000055=GBP/USD110=3000000279=2269=1270=1.43503271=10000055=GBP/USD110=0279=2269=1270=1.43503271=50000055=GBP/USD110=100000279=2269=1270=1.43503271=100000055=GBP/USD110=500000279=2269=1270=1.43503271=300000055=GBP/USD110=1000000279=2269=1270=1.43503271=500000055=GBP/USD110=300000010=248
20260120-14:04:16.458898000 : 8=FIX.4.49=068435=X49=NTPRO_IDBA_UAT56=SIRIUS_500007460_MD34=116352=20260120-14:04:16.454262=MD_GBP/USD_140109778778268=10279=0269=0270=1.25468271=10000055=GBP/USD110=0279=0269=0270=1.25468271=50000055=GBP/USD110=100000279=0269=0270=1.25468271=100000055=GBP/USD110=500000279=0269=0270=1.25468271=300000055=GBP/USD110=1000000279=0269=0270=1.25468271=500000055=GBP/USD110=3000000279=0269=1270=1.43503271=10000055=GBP/USD110=0279=0269=1270=1.43503271=50000055=GBP/USD110=100000279=0269=1270=1.43503271=100000055=GBP/USD110=500000279=0269=1270=1.43503271=300000055=GBP/USD110=1000000279=0269=1270=1.43503271=500000055=GBP/USD110=300000010=231
20260120-14:04:16.491089000 : 8=FIX.4.49=068435=X49=NTPRO_IDBA_UAT56=SIRIUS_500007460_MD34=116452=20260120-14:04:16.485262=MD_GBP/USD_140109778778268=10279=2269=0270=1.25468271=10000055=GBP/USD110=0279=2269=0270=1.25468271=50000055=GBP/USD110=100000279=2269=0270=1.25468271=100000055=GBP/USD110=500000279=2269=0270=1.25468271=300000055=GBP/USD110=1000000279=2269=0270=1.25468271=500000055=GBP/USD110=3000000279=2269=1270=1.43503271=10000055=GBP/USD110=0279=2269=1270=1.43503271=50000055=GBP/USD110=100000279=2269=1270=1.43503271=100000055=GBP/USD110=500000279=2269=1270=1.43503271=300000055=GBP/USD110=1000000279=2269=1270=1.43503271=500000055=GBP/USD110=300000010=000
20260120-14:04:16.667412000 : 8=FIX.4.49=044435=X49=NTPRO_IDBA_UAT56=SIRIUS_500007460_MD34=116552=20260120-14:04:16.667262=MD_EUR/USD_140109278614268=6279=1269=0270=1.14796271=10000055=EUR/USD110=0279=1269=0270=1.14796271=50000055=EUR/USD110=100000279=1269=0270=1.14796271=100000055=EUR/USD110=500000279=1269=1270=1.1982271=10000055=EUR/USD110=0279=1269=1270=1.1982271=50000055=EUR/USD110=100000279=1269=1270=1.1982271=100000055=EUR/USD110=50000010=176
20260120-14:04:16.857220000 : 8=FIX.4.49=044735=X49=NTPRO_IDBA_UAT56=SIRIUS_500007460_MD34=116652=20260120-14:04:16.862262=MD_EUR/USD_140109278614268=6279=1269=0270=1.14795271=10000055=EUR/USD110=0279=1269=0270=1.14795271=50000055=EUR/USD110=100000279=1269=0270=1.14795271=100000055=EUR/USD110=500000279=1269=1270=1.19819271=10000055=EUR/USD110=0279=1269=1270=1.19819271=50000055=EUR/USD110=100000279=1269=1270=1.19819271=100000055=EUR/USD110=50000010=086
20260120-14:04:17.687886000 : 8=FIX.4.49=044435=X49=NTPRO_IDBA_UAT56=SIRIUS_500007460_MD34=116752=20260120-14:04:17.712262=MD_EUR/USD_140109278614268=6279=1269=0270=1.14796271=10000055=EUR/USD110=0279=1269=0270=1.14796271=50000055=EUR/USD110=100000279=1269=0270=1.14796271=100000055=EUR/USD110=500000279=1269=1270=1.1982271=10000055=EUR/USD110=0279=1269=1270=1.1982271=50000055=EUR/USD110=100000279=1269=1270=1.1982271=100000055=EUR/USD110=50000010=170
20260120-14:04:18.215505000 : 8=FIX.4.49=044735=X49=NTPRO_IDBA_UAT56=SIRIUS_500007460_MD34=116852=20260120-14:04:18.232262=MD_EUR/USD_140109278614268=6279=1269=0270=1.14795271=10000055=EUR/USD110=0279=1269=0270=1.14795271=50000055=EUR/USD110=100000279=1269=0270=1.14795271=100000055=EUR/USD110=500000279=1269=1270=1.19819271=10000055=EUR/USD110=0279=1269=1270=1.19819271=50000055=EUR/USD110=100000279=1269=1270=1.19819271=100000055=EUR/USD110=50000010=081
20260120-14:04:19.221982000 : 8=FIX.4.49=028035=X49=NTPRO_IDBA_UAT56=SIRIUS_500007460_MD34=116952=20260120-14:04:19.284262=MD_EUR/USD_140109278614268=3279=1269=0270=1.14794271=10000055=EUR/USD110=0279=1269=0270=1.14794271=50000055=EUR/USD110=100000279=1269=0270=1.14794271=100000055=EUR/USD110=50000010=020
20260120-14:04:19.273651000 : 8=FIX.4.49=068435=X49=NTPRO_IDBA_UAT56=SIRIUS_500007460_MD34=117052=20260120-14:04:19.332262=MD_GBP/USD_140109778778268=10279=0269=0270=1.25467271=10000055=GBP/USD110=0279=0269=0270=1.25467271=50000055=GBP/USD110=100000279=0269=0270=1.25467271=100000055=GBP/USD110=500000279=0269=0270=1.25467271=300000055=GBP/USD110=1000000279=0269=0270=1.25467271=500000055=GBP/USD110=3000000279=0269=1270=1.43503271=10000055=GBP/USD110=0279=0269=1270=1.43503271=50000055=GBP/USD110=100000279=0269=1270=1.43503271=100000055=GBP/USD110=500000279=0269=1270=1.43503271=300000055=GBP/USD110=1000000279=0269=1270=1.43503271=500000055=GBP/USD110=300000010=222
20260120-14:04:19.609738000 : 8=FIX.4.49=028035=X49=NTPRO_IDBA_UAT56=SIRIUS_500007460_MD34=117152=20260120-14:04:19.680262=MD_EUR/USD_140109278614268=3279=1269=0270=1.14795271=10000055=EUR/USD110=0279=1269=0270=1.14795271=50000055=EUR/USD110=100000279=1269=0270=1.14795271=100000055=EUR/USD110=50000010=016
20260120-14:04:20.343161000 : 8=FIX.4.49=028035=X49=NTPRO_IDBA_UAT56=SIRIUS_500007460_MD34=117252=20260120-14:04:20.438262=MD_EUR/USD_140109278614268=3279=1269=0270=1.14794271=10000055=EUR/USD110=0279=1269=0270=1.14794271=50000055=EUR/USD110=100000279=1269=0270=1.14794271=100000055=EUR/USD110=50000010=007
20260120-14:04:20.508396000 : 8=FIX.4.49=028035=X49=NTPRO_IDBA_UAT56=SIRIUS_500007460_MD34=117352=20260120-14:04:20.605262=MD_EUR/USD_140109278614268=3279=1269=0270=1.14795271=10000055=EUR/USD110=0279=1269=0270=1.14795271=50000055=EUR/USD110=100000279=1269=0270=1.14795271=100000055=EUR/USD110=50000010=007
20260120-14:04:20.610512000 : 8=FIX.4.49=068435=X49=NTPRO_IDBA_UAT56=SIRIUS_500007460_MD34=117452=20260120-14:04:20.713262=MD_GBP/USD_140109778778268=10279=2269=0270=1.25467271=10000055=GBP/USD110=0279=2269=0270=1.25467271=50000055=GBP/USD110=100000279=2269=0270=1.25467271=100000055=GBP/USD110=500000279=2269=0270=1.25467271=300000055=GBP/USD110=1000000279=2269=0270=1.25467271=500000055=GBP/USD110=3000000279=2269=1270=1.43503271=10000055=GBP/USD110=0279=2269=1270=1.43503271=50000055=GBP/USD110=100000279=2269=1270=1.43503271=100000055=GBP/USD110=500000279=2269=1270=1.43503271=300000055=GBP/USD110=1000000279=2269=1270=1.43503271=500000055=GBP/USD110=300000010=241
20260120-14:04:20.745144000 : 8=FIX.4.49=068435=X49=NTPRO_IDBA_UAT56=SIRIUS_500007460_MD34=117552=20260120-14:04:20.847262=MD_GBP/USD_140109778778268=10279=0269=0270=1.25467271=10000055=GBP/USD110=0279=0269=0270=1.25467271=50000055=GBP/USD110=100000279=0269=0270=1.25467271=100000055=GBP/USD110=500000279=0269=0270=1.25467271=300000055=GBP/USD110=1000000279=0269=0270=1.25467271=500000055=GBP/USD110=3000000279=0269=1270=1.43503271=10000055=GBP/USD110=0279=0269=1270=1.43503271=50000055=GBP/USD110=100000279=0269=1270=1.43503271=100000055=GBP/USD110=500000279=0269=1270=1.43503271=300000055=GBP/USD110=1000000279=0269=1270=1.43503271=500000055=GBP/USD110=300000010=230
20260120-14:04:21.164872000 : 8=FIX.4.49=028035=X49=NTPRO_IDBA_UAT56=SIRIUS_500007460_MD34=117652=20260120-14:04:21.260262=MD_EUR/USD_140109278614268=3279=1269=0270=1.14794271=10000055=EUR/USD110=0279=1269=0270=1.14794271=50000055=EUR/USD110=100000279=1269=0270=1.14794271=100000055=EUR/USD110=50000010=005
20260120-14:04:21.269351000 : 8=FIX.4.49=028035=X49=NTPRO_IDBA_UAT56=SIRIUS_500007460_MD34=117752=20260120-14:04:21.302262=MD_EUR/USD_140109278614268=3279=1269=0270=1.14795271=10000055=EUR/USD110=0279=1269=0270=1.14795271=50000055=EUR/USD110=100000279=1269=0270=1.14795271=100000055=EUR/USD110=50000010=006
20260120-14:04:21.269781000 : 8=FIX.4.49=044435=X49=NTPRO_IDBA_UAT56=SIRIUS_500007460_MD34=117852=20260120-14:04:21.334262=MD_EUR/USD_140109278614268=6279=1269=0270=1.14796271=10000055=EUR/USD110=0279=1269=0270=1.14796271=50000055=EUR/USD110=100000279=1269=0270=1.14796271=100000055=EUR/USD110=500000279=1269=1270=1.1982271=10000055=EUR/USD110=0279=1269=1270=1.1982271=50000055=EUR/USD110=100000279=1269=1270=1.1982271=100000055=EUR/USD110=50000010=167
20260120-14:04:21.463104000 : 8=FIX.4.49=044735=X49=NTPRO_IDBA_UAT56=SIRIUS_500007460_MD34=117952=20260120-14:04:21.551262=MD_EUR/USD_140109278614268=6279=1269=0270=1.14795271=10000055=EUR/USD110=0279=1269=0270=1.14795271=50000055=EUR/USD110=100000279=1269=0270=1.14795271=100000055=EUR/USD110=500000279=1269=1270=1.19819271=10000055=EUR/USD110=0279=1269=1270=1.19819271=50000055=EUR/USD110=100000279=1269=1270=1.19819271=100000055=EUR/USD110=50000010=081
20260120-14:04:21.463924000 : 8=FIX.4.49=028035=X49=NTPRO_IDBA_UAT56=SIRIUS_500007460_MD34=118052=20260120-14:04:21.580262=MD_EUR/USD_140109278614268=3279=1269=0270=1.14794271=10000055=EUR/USD110=0279=1269=0270=1.14794271=50000055=EUR/USD110=100000279=1269=0270=1.14794271=100000055=EUR/USD110=50000010=005
20260120-14:04:21.552010000 : 8=FIX.4.49=028035=X49=NTPRO_IDBA_UAT56=SIRIUS_500007460_MD34=118152=20260120-14:04:21.621262=MD_EUR/USD_140109278614268=3279=1269=0270=1.14795271=10000055=EUR/USD110=0279=1269=0270=1.14795271=50000055=EUR/USD110=100000279=1269=0270=1.14795271=100000055=EUR/USD110=50000010=005
20260120-14:04:21.552741000 : 8=FIX.4.49=028035=X49=NTPRO_IDBA_UAT56=SIRIUS_500007460_MD34=118252=20260120-14:04:21.641262=MD_EUR/USD_140109278614268=3279=1269=0270=1.14794271=10000055=EUR/USD110=0279=1269=0270=1.14794271=50000055=EUR/USD110=100000279=1269=0270=1.14794271=100000055=EUR/USD110=50000010=005
20260120-14:04:21.553053000 : 8=FIX.4.49=028035=X49=NTPRO_IDBA_UAT56=SIRIUS_500007460_MD34=118352=20260120-14:04:21.678262=MD_EUR/USD_140109278614268=3279=1269=0270=1.14795271=10000055=EUR/USD110=0279=1269=0270=1.14795271=50000055=EUR/USD110=100000279=1269=0270=1.14795271=100000055=EUR/USD110=50000010=019
20260120-14:04:22.054480000 : 8=FIX.4.49=068435=X49=NTPRO_IDBA_UAT56=SIRIUS_500007460_MD34=118452=20260120-14:04:22.179262=MD_GBP/USD_140109778778268=10279=2269=0270=1.25467271=10000055=GBP/USD110=0279=2269=0270=1.25467271=50000055=GBP/USD110=100000279=2269=0270=1.25467271=100000055=GBP/USD110=500000279=2269=0270=1.25467271=300000055=GBP/USD110=1000000279=2269=0270=1.25467271=500000055=GBP/USD110=3000000279=2269=1270=1.43503271=10000055=GBP/USD110=0279=2269=1270=1.43503271=50000055=GBP/USD110=100000279=2269=1270=1.43503271=100000055=GBP/USD110=500000279=2269=1270=1.43503271=300000055=GBP/USD110=1000000279=2269=1270=1.43503271=500000055=GBP/USD110=300000010=250
20260120-14:04:22.059715000 : 8=FIX.4.49=028035=X49=NTPRO_IDBA_UAT56=SIRIUS_500007460_MD34=118552=20260120-14:04:22.200262=MD_EUR/USD_140109278614268=3279=1269=0270=1.14793271=10000055=EUR/USD110=0279=1269=0270=1.14793271=50000055=EUR/USD110=100000279=1269=0270=1.14793271=100000055=EUR/USD110=50000010=253
20260120-14:04:22.162871000 : 8=FIX.4.49=044735=X49=NTPRO_IDBA_UAT56=SIRIUS_500007460_MD34=118652=20260120-14:04:22.286262=MD_EUR/USD_140109278614268=6279=1269=0270=1.14792271=10000055=EUR/USD110=0279=1269=0270=1.14792271=50000055=EUR/USD110=100000279=1269=0270=1.14792271=100000055=EUR/USD110=500000279=1269=1270=1.19818271=10000055=EUR/USD110=0279=1269=1270=1.19818271=50000055=EUR/USD110=100000279=1269=1270=1.19818271=100000055=EUR/USD110=50000010=073
20260120-14:04:22.171655000 : 8=FIX.4.49=068435=X49=NTPRO_IDBA_UAT56=SIRIUS_500007460_MD34=118752=20260120-14:04:22.314262=MD_GBP/USD_140109778778268=10279=0269=0270=1.25465271=10000055=GBP/USD110=0279=0269=0270=1.25465271=50000055=GBP/USD110=100000279=0269=0270=1.25465271=100000055=GBP/USD110=500000279=0269=0270=1.25465271=300000055=GBP/USD110=1000000279=0269=0270=1.25465271=500000055=GBP/USD110=3000000279=0269=1270=1.43501271=10000055=GBP/USD110=0279=0269=1270=1.43501271=50000055=GBP/USD110=100000279=0269=1270=1.43501271=100000055=GBP/USD110=500000279=0269=1270=1.43501271=300000055=GBP/USD110=1000000279=0269=1270=1.43501271=500000055=GBP/USD110=300000010=204
20260120-14:04:22.255496000 : 8=FIX.4.49=038835=X49=NTPRO_IDBA_UAT56=SIRIUS_500007460_MD34=118852=20260120-14:04:22.360262=MD_GBP/USD_140109778778268=5279=1269=1270=1.435271=10000055=GBP/USD110=0279=1269=1270=1.435271=50000055=GBP/USD110=100000279=1269=1270=1.435271=100000055=GBP/USD110=500000279=1269=1270=1.435271=300000055=GBP/USD110=1000000279=1269=1270=1.435271=500000055=GBP/USD110=300000010=079
20260120-14:04:22.256960000 : 8=FIX.4.49=039835=X49=NTPRO_IDBA_UAT56=SIRIUS_500007460_MD34=118952=20260120-14:04:22.385262=MD_GBP/USD_140109778778268=5279=1269=0270=1.25464271=10000055=GBP/USD110=0279=1269=0270=1.25464271=50000055=GBP/USD110=100000279=1269=0270=1.25464271=100000055=GBP/USD110=500000279=1269=0270=1.25464271=300000055=GBP/USD110=1000000279=1269=0270=1.25464271=500000055=GBP/USD110=300000010=096
20260120-14:04:22.365715000 : 8=FIX.4.49=044735=X49=NTPRO_IDBA_UAT56=SIRIUS_500007460_MD34=119052=20260120-14:04:22.438262=MD_EUR/USD_140109278614268=6279=1269=0270=1.14791271=10000055=EUR/USD110=0279=1269=0270=1.14791271=50000055=EUR/USD110=100000279=1269=0270=1.14791271=100000055=EUR/USD110=500000279=1269=1270=1.19816271=10000055=EUR/USD110=0279=1269=1270=1.19816271=50000055=EUR/USD110=100000279=1269=1270=1.19816271=100000055=EUR/USD110=50000010=058
20260120-14:04:22.366455000 : 8=FIX.4.49=068435=X49=NTPRO_IDBA_UAT56=SIRIUS_500007460_MD34=119152=20260120-14:04:22.465262=MD_GBP/USD_140109778778268=10279=1269=0270=1.25462271=10000055=GBP/USD110=0279=1269=0270=1.25462271=50000055=GBP/USD110=100000279=1269=0270=1.25462271=100000055=GBP/USD110=500000279=1269=0270=1.25462271=300000055=GBP/USD110=1000000279=1269=0270=1.25462271=500000055=GBP/USD110=3000000279=1269=1270=1.43497271=10000055=GBP/USD110=0279=1269=1270=1.43497271=50000055=GBP/USD110=100000279=1269=1270=1.43497271=100000055=GBP/USD110=500000279=1269=1270=1.43497271=300000055=GBP/USD110=1000000279=1269=1270=1.43497271=500000055=GBP/USD110=300000010=015
20260120-14:04:22.461077000 : 8=FIX.4.49=044735=X49=NTPRO_IDBA_UAT56=SIRIUS_500007460_MD34=119252=20260120-14:04:22.540262=MD_EUR/USD_140109278614268=6279=1269=0270=1.14789271=10000055=EUR/USD110=0279=1269=0270=1.14789271=50000055=EUR/USD110=100000279=1269=0270=1.14789271=100000055=EUR/USD110=500000279=1269=1270=1.19814271=10000055=EUR/USD110=0279=1269=1270=1.19814271=50000055=EUR/USD110=100000279=1269=1270=1.19814271=100000055=EUR/USD110=50000010=069
20260120-14:04:22.658682000 : 8=FIX.4.49=068435=X49=NTPRO_IDBA_UAT56=SIRIUS_500007460_MD34=119352=20260120-14:04:22.746262=MD_GBP/USD_140109778778268=10279=1269=0270=1.25461271=10000055=GBP/USD110=0279=1269=0270=1.25461271=50000055=GBP/USD110=100000279=1269=0270=1.25461271=100000055=GBP/USD110=500000279=1269=0270=1.25461271=300000055=GBP/USD110=1000000279=1269=0270=1.25461271=500000055=GBP/USD110=3000000279=1269=1270=1.43496271=10000055=GBP/USD110=0279=1269=1270=1.43496271=50000055=GBP/USD110=100000279=1269=1270=1.43496271=100000055=GBP/USD110=500000279=1269=1270=1.43496271=300000055=GBP/USD110=1000000279=1269=1270=1.43496271=500000055=GBP/USD110=300000010=009
20260120-14:04:23.461028000 : 8=FIX.4.49=068435=X49=NTPRO_IDBA_UAT56=SIRIUS_500007460_MD34=119452=20260120-14:04:23.620262=MD_GBP/USD_140109778778268=10279=2269=0270=1.25461271=10000055=GBP/USD110=0279=2269=0270=1.25461271=50000055=GBP/USD110=100000279=2269=0270=1.25461271=100000055=GBP/USD110=500000279=2269=0270=1.25461271=300000055=GBP/USD110=1000000279=2269=0270=1.25461271=500000055=GBP/USD110=3000000279=2269=1270=1.43496271=10000055=GBP/USD110=0279=2269=1270=1.43496271=50000055=GBP/USD110=100000279=2269=1270=1.43496271=100000055=GBP/USD110=500000279=2269=1270=1.43496271=300000055=GBP/USD110=1000000279=2269=1270=1.43496271=500000055=GBP/USD110=300000010=012
20260120-14:04:23.546608000 : 8=FIX.4.49=044435=X49=NTPRO_IDBA_UAT56=SIRIUS_500007460_MD34=119552=20260120-14:04:23.665262=MD_EUR/USD_140109278614268=6279=1269=0270=1.1479271=10000055=EUR/USD110=0279=1269=0270=1.1479271=50000055=EUR/USD110=100000279=1269=0270=1.1479271=100000055=EUR/USD110=500000279=1269=1270=1.19815271=10000055=EUR/USD110=0279=1269=1270=1.19815271=50000055=EUR/USD110=100000279=1269=1270=1.19815271=100000055=EUR/USD110=50000010=169
20260120-14:04:23.555808000 : 8=FIX.4.49=068435=X49=NTPRO_IDBA_UAT56=SIRIUS_500007460_MD34=119652=20260120-14:04:23.732262=MD_GBP/USD_140109778778268=10279=0269=0270=1.25462271=10000055=GBP/USD110=0279=0269=0270=1.25462271=50000055=GBP/USD110=100000279=0269=0270=1.25462271=100000055=GBP/USD110=500000279=0269=0270=1.25462271=300000055=GBP/USD110=1000000279=0269=0270=1.25462271=500000055=GBP/USD110=3000000279=0269=1270=1.43497271=10000055=GBP/USD110=0279=0269=1270=1.43497271=50000055=GBP/USD110=100000279=0269=1270=1.43497271=100000055=GBP/USD110=500000279=0269=1270=1.43497271=300000055=GBP/USD110=1000000279=0269=1270=1.43497271=500000055=GBP/USD110=300000010=008
20260120-14:04:23.748357000 : 8=FIX.4.49=039835=X49=NTPRO_IDBA_UAT56=SIRIUS_500007460_MD34=119752=20260120-14:04:23.891262=MD_GBP/USD_140109778778268=5279=1269=1270=1.43498271=10000055=GBP/USD110=0279=1269=1270=1.43498271=50000055=GBP/USD110=100000279=1269=1270=1.43498271=100000055=GBP/USD110=500000279=1269=1270=1.43498271=300000055=GBP/USD110=1000000279=1269=1270=1.43498271=500000055=GBP/USD110=300000010=138
20260120-14:04:23.854225000 : 8=FIX.4.49=039835=X49=NTPRO_IDBA_UAT56=SIRIUS_500007460_MD34=119852=20260120-14:04:23.950262=MD_GBP/USD_140109778778268=5279=1269=1270=1.43497271=10000055=GBP/USD110=0279=1269=1270=1.43497271=50000055=GBP/USD110=100000279=1269=1270=1.43497271=100000055=GBP/USD110=500000279=1269=1270=1.43497271=300000055=GBP/USD110=1000000279=1269=1270=1.43497271=500000055=GBP/USD110=300000010=130
20260120-14:04:23.854767000 : 8=FIX.4.49=039835=X49=NTPRO_IDBA_UAT56=SIRIUS_500007460_MD34=119952=20260120-14:04:24.027262=MD_GBP/USD_140109778778268=5279=1269=0270=1.25461271=10000055=GBP/USD110=0279=1269=0270=1.25461271=50000055=GBP/USD110=100000279=1269=0270=1.25461271=100000055=GBP/USD110=500000279=1269=0270=1.25461271=300000055=GBP/USD110=1000000279=1269=0270=1.25461271=500000055=GBP/USD110=300000010=077
20260120-14:04:24.046972000 : 8=FIX.4.49=039835=X49=NTPRO_IDBA_UAT56=SIRIUS_500007460_MD34=120052=20260120-14:04:24.200262=MD_GBP/USD_140109778778268=5279=1269=1270=1.43496271=10000055=GBP/USD110=0279=1269=1270=1.43496271=50000055=GBP/USD110=100000279=1269=1270=1.43496271=100000055=GBP/USD110=500000279=1269=1270=1.43496271=300000055=GBP/USD110=1000000279=1269=1270=1.43496271=500000055=GBP/USD110=300000010=098
20260120-14:04:24.047612000 : 8=FIX.4.49=067935=X49=NTPRO_IDBA_UAT56=SIRIUS_500007460_MD34=120152=20260120-14:04:24.228262=MD_GBP/USD_140109778778268=10279=1269=0270=1.2546271=10000055=GBP/USD110=0279=1269=0270=1.2546271=50000055=GBP/USD110=100000279=1269=0270=1.2546271=100000055=GBP/USD110=500000279=1269=0270=1.2546271=300000055=GBP/USD110=1000000279=1269=0270=1.2546271=500000055=GBP/USD110=3000000279=1269=1270=1.43495271=10000055=GBP/USD110=0279=1269=1270=1.43495271=50000055=GBP/USD110=100000279=1269=1270=1.43495271=100000055=GBP/USD110=500000279=1269=1270=1.43495271=300000055=GBP/USD110=1000000279=1269=1270=1.43495271=500000055=GBP/USD110=300000010=006
20260120-14:04:24.052575000 : 8=FIX.4.49=044735=X49=NTPRO_IDBA_UAT56=SIRIUS_500007460_MD34=120252=20260120-14:04:24.244262=MD_EUR/USD_140109278614268=6279=1269=0270=1.14788271=10000055=EUR/USD110=0279=1269=0270=1.14788271=50000055=EUR/USD110=100000279=1269=0270=1.14788271=100000055=EUR/USD110=500000279=1269=1270=1.19814271=10000055=EUR/USD110=0279=1269=1270=1.19814271=50000055=EUR/USD110=100000279=1269=1270=1.19814271=100000055=EUR/USD110=50000010=061
20260120-14:04:24.166583000 : 8=FIX.4.49=028035=X49=NTPRO_IDBA_UAT56=SIRIUS_500007460_MD34=120352=20260120-14:04:24.300262=MD_EUR/USD_140109278614268=3279=1269=0270=1.14789271=10000055=EUR/USD110=0279=1269=0270=1.14789271=50000055=EUR/USD110=100000279=1269=0270=1.14789271=100000055=EUR/USD110=50000010=006
20260120-14:04:24.167016000 : 8=FIX.4.49=068435=X49=NTPRO_IDBA_UAT56=SIRIUS_500007460_MD34=120452=20260120-14:04:24.309262=MD_GBP/USD_140109778778268=10279=1269=0270=1.25458271=10000055=GBP/USD110=0279=1269=0270=1.25458271=50000055=GBP/USD110=100000279=1269=0270=1.25458271=100000055=GBP/USD110=500000279=1269=0270=1.25458271=300000055=GBP/USD110=1000000279=1269=0270=1.25458271=500000055=GBP/USD110=3000000279=1269=1270=1.43493271=10000055=GBP/USD110=0279=1269=1270=1.43493271=50000055=GBP/USD110=100000279=1269=1270=1.43493271=100000055=GBP/USD110=500000279=1269=1270=1.43493271=300000055=GBP/USD110=1000000279=1269=1270=1.43493271=500000055=GBP/USD110=300000010=014
20260120-14:04:24.348596000 : 8=FIX.4.49=044735=X49=NTPRO_IDBA_UAT56=SIRIUS_500007460_MD34=120552=20260120-14:04:24.498262=MD_EUR/USD_140109278614268=6279=1269=0270=1.14788271=10000055=EUR/USD110=0279=1269=0270=1.14788271=50000055=EUR/USD110=100000279=1269=0270=1.14788271=100000055=EUR/USD110=500000279=1269=1270=1.19813271=10000055=EUR/USD110=0279=1269=1270=1.19813271=50000055=EUR/USD110=100000279=1269=1270=1.19813271=100000055=EUR/USD110=50000010=072
20260120-14:04:24.349938000 : 8=FIX.4.49=039835=X49=NTPRO_IDBA_UAT56=SIRIUS_500007460_MD34=120652=20260120-14:04:24.550262=MD_GBP/USD_140109778778268=5279=1269=0270=1.25457271=10000055=GBP/USD110=0279=1269=0270=1.25457271=50000055=GBP/USD110=100000279=1269=0270=1.25457271=100000055=GBP/USD110=500000279=1269=0270=1.25457271=300000055=GBP/USD110=1000000279=1269=0270=1.25457271=500000055=GBP/USD110=300000010=092
20260120-14:04:24.358953000 : 8=FIX.4.49=028035=X49=NTPRO_IDBA_UAT56=SIRIUS_500007460_MD34=120752=20260120-14:04:24.559262=MD_EUR/USD_140109278614268=3279=1269=0270=1.14787271=10000055=EUR/USD110=0279=1269=0270=1.14787271=50000055=EUR/USD110=100000279=1269=0270=1.14787271=100000055=EUR/USD110=50000010=020
20260120-14:04:24.449658000 : 8=FIX.4.49=028035=X49=NTPRO_IDBA_UAT56=SIRIUS_500007460_MD34=120852=20260120-14:04:24.596262=MD_EUR/USD_140109278614268=3279=1269=0270=1.14788271=10000055=EUR/USD110=0279=1269=0270=1.14788271=50000055=EUR/USD110=100000279=1269=0270=1.14788271=100000055=EUR/USD110=50000010=025
20260120-14:04:24.450379000 : 8=FIX.4.49=039835=X49=NTPRO_IDBA_UAT56=SIRIUS_500007460_MD34=120952=20260120-14:04:24.624262=MD_GBP/USD_140109778778268=5279=1269=0270=1.25458271=10000055=GBP/USD110=0279=1269=0270=1.25458271=50000055=GBP/USD110=100000279=1269=0270=1.25458271=100000055=GBP/USD110=500000279=1269=0270=1.25458271=300000055=GBP/USD110=1000000279=1269=0270=1.25458271=500000055=GBP/USD110=300000010=102
20260120-14:04:25.725618000 : 8=FIX.4.49=068435=X49=NTPRO_IDBA_UAT56=SIRIUS_500007460_MD34=121052=20260120-14:04:25.985262=MD_GBP/USD_140109778778268=10279=2269=0270=1.25458271=10000055=GBP/USD110=0279=2269=0270=1.25458271=50000055=GBP/USD110=100000279=2269=0270=1.25458271=100000055=GBP/USD110=500000279=2269=0270=1.25458271=300000055=GBP/USD110=1000000279=2269=0270=1.25458271=500000055=GBP/USD110=3000000279=2269=1270=1.43493271=10000055=GBP/USD110=0279=2269=1270=1.43493271=50000055=GBP/USD110=100000279=2269=1270=1.43493271=100000055=GBP/USD110=500000279=2269=1270=1.43493271=300000055=GBP/USD110=1000000279=2269=1270=1.43493271=500000055=GBP/USD110=300000010=032
20260120-14:04:25.819948000 : 8=FIX.4.49=028035=X49=NTPRO_IDBA_UAT56=SIRIUS_500007460_MD34=121152=20260120-14:04:26.052262=MD_EUR/USD_140109278614268=3279=1269=0270=1.14789271=10000055=EUR/USD110=0279=1269=0270=1.14789271=50000055=EUR/USD110=100000279=1269=0270=1.14789271=100000055=EUR/USD110=50000010=011
20260120-14:04:25.911708000 : 8=FIX.4.49=068435=X49=NTPRO_IDBA_UAT56=SIRIUS_500007460_MD34=121252=20260120-14:04:26.126262=MD_GBP/USD_140109778778268=10279=0269=0270=1.25464271=10000055=GBP/USD110=0279=0269=0270=1.25464271=50000055=GBP/USD110=100000279=0269=0270=1.25464271=100000055=GBP/USD110=500000279=0269=0270=1.25464271=300000055=GBP/USD110=1000000279=0269=0270=1.25464271=500000055=GBP/USD110=3000000279=0269=1270=1.43499271=10000055=GBP/USD110=0279=0269=1270=1.43499271=50000055=GBP/USD110=100000279=0269=1270=1.43499271=100000055=GBP/USD110=500000279=0269=1270=1.43499271=300000055=GBP/USD110=1000000279=0269=1270=1.43499271=500000055=GBP/USD110=300000010=017
20260120-14:04:25.912819000 : 8=FIX.4.49=044435=X49=NTPRO_IDBA_UAT56=SIRIUS_500007460_MD34=121352=20260120-14:04:26.172262=MD_EUR/USD_140109278614268=6279=1269=0270=1.1479271=10000055=EUR/USD110=0279=1269=0270=1.1479271=50000055=EUR/USD110=100000279=1269=0270=1.1479271=100000055=EUR/USD110=500000279=1269=1270=1.19815271=10000055=EUR/USD110=0279=1269=1270=1.19815271=50000055=EUR/USD110=100000279=1269=1270=1.19815271=100000055=EUR/USD110=50000010=156
20260120-14:04:25.913539000 : 8=FIX.4.49=039835=X49=NTPRO_IDBA_UAT56=SIRIUS_500007460_MD34=121452=20260120-14:04:26.177262=MD_GBP/USD_140109778778268=5279=1269=0270=1.25463271=10000055=GBP/USD110=0279=1269=0270=1.25463271=50000055=GBP/USD110=100000279=1269=0270=1.25463271=100000055=GBP/USD110=500000279=1269=0270=1.25463271=300000055=GBP/USD110=1000000279=1269=0270=1.25463271=500000055=GBP/USD110=300000010=083
20260120-14:04:26.015993000 : 8=FIX.4.49=039835=X49=NTPRO_IDBA_UAT56=SIRIUS_500007460_MD34=121552=20260120-14:04:26.295262=MD_GBP/USD_140109778778268=5279=1269=0270=1.25464271=10000055=GBP/USD110=0279=1269=0270=1.25464271=50000055=GBP/USD110=100000279=1269=0270=1.25464271=100000055=GBP/USD110=500000279=1269=0270=1.25464271=300000055=GBP/USD110=1000000279=1269=0270=1.25464271=500000055=GBP/USD110=300000010=090
20260120-14:04:26.109563000 : 8=FIX.4.49=028035=X49=NTPRO_IDBA_UAT56=SIRIUS_500007460_MD34=121652=20260120-14:04:26.354262=MD_EUR/USD_140109278614268=3279=1269=0270=1.14789271=10000055=EUR/USD110=0279=1269=0270=1.14789271=50000055=EUR/USD110=100000279=1269=0270=1.14789271=100000055=EUR/USD110=50000010=021
20260120-14:04:26.497016000 : 8=FIX.4.49=027735=X49=NTPRO_IDBA_UAT56=SIRIUS_500007460_MD34=121752=20260120-14:04:26.744262=MD_EUR/USD_140109278614268=3279=1269=0270=1.1479271=10000055=EUR/USD110=0279=1269=0270=1.1479271=50000055=EUR/USD110=100000279=1269=0270=1.1479271=100000055=EUR/USD110=50000010=119
20260120-14:04:26.497520000 : 8=FIX.4.49=038835=X49=NTPRO_IDBA_UAT56=SIRIUS_500007460_MD34=121852=20260120-14:04:26.803262=MD_GBP/USD_140109778778268=5279=1269=1270=1.435271=10000055=GBP/USD110=0279=1269=1270=1.435271=50000055=GBP/USD110=100000279=1269=1270=1.435271=100000055=GBP/USD110=500000279=1269=1270=1.435271=300000055=GBP/USD110=1000000279=1269=1270=1.435271=500000055=GBP/USD110=300000010=079
20260120-14:04:26.604819000 : 8=FIX.4.49=039835=X49=NTPRO_IDBA_UAT56=SIRIUS_500007460_MD34=121952=20260120-14:04:26.862262=MD_GBP/USD_140109778778268=5279=1269=1270=1.43498271=10000055=GBP/USD110=0279=1269=1270=1.43498271=50000055=GBP/USD110=100000279=1269=1270=1.43498271=100000055=GBP/USD110=500000279=1269=1270=1.43498271=300000055=GBP/USD110=1000000279=1269=1270=1.43498271=500000055=GBP/USD110=300000010=134
20260120-14:04:26.605631000 : 8=FIX.4.49=068435=X49=NTPRO_IDBA_UAT56=SIRIUS_500007460_MD34=122052=20260120-14:04:26.900262=MD_GBP/USD_140109778778268=10279=2269=0270=1.25464271=10000055=GBP/USD110=0279=2269=0270=1.25464271=50000055=GBP/USD110=100000279=2269=0270=1.25464271=100000055=GBP/USD110=500000279=2269=0270=1.25464271=300000055=GBP/USD110=1000000279=2269=0270=1.25464271=500000055=GBP/USD110=3000000279=2269=1270=1.43498271=10000055=GBP/USD110=0279=2269=1270=1.43498271=50000055=GBP/USD110=100000279=2269=1270=1.43498271=100000055=GBP/USD110=500000279=2269=1270=1.43498271=300000055=GBP/USD110=1000000279=2269=1270=1.43498271=500000055=GBP/USD110=300000010=031
20260120-14:04:26.981062000 : 8=FIX.4.49=044735=X49=NTPRO_IDBA_UAT56=SIRIUS_500007460_MD34=122152=20260120-14:04:27.249262=MD_EUR/USD_140109278614268=6279=1269=0270=1.14791271=10000055=EUR/USD110=0279=1269=0270=1.14791271=50000055=EUR/USD110=100000279=1269=0270=1.14791271=100000055=EUR/USD110=500000279=1269=1270=1.19816271=10000055=EUR/USD110=0279=1269=1270=1.19816271=50000055=EUR/USD110=100000279=1269=1270=1.19816271=100000055=EUR/USD110=50000010=058
20260120-14:04:27.082342000 : 8=FIX.4.49=044435=X49=NTPRO_IDBA_UAT56=SIRIUS_500007460_MD34=122252=20260120-14:04:27.396262=MD_EUR/USD_140109278614268=6279=1269=0270=1.1479271=10000055=EUR/USD110=0279=1269=0270=1.1479271=50000055=EUR/USD110=100000279=1269=0270=1.1479271=100000055=EUR/USD110=500000279=1269=1270=1.19815271=10000055=EUR/USD110=0279=1269=1270=1.19815271=50000055=EUR/USD110=100000279=1269=1270=1.19815271=100000055=EUR/USD110=50000010=165
20260120-14:04:27.190444000 : 8=FIX.4.49=028035=X49=NTPRO_IDBA_UAT56=SIRIUS_500007460_MD34=122352=20260120-14:04:27.518262=MD_EUR/USD_140109278614268=3279=1269=0270=1.14791271=10000055=EUR/USD110=0279=1269=0270=1.14791271=50000055=EUR/USD110=100000279=1269=0270=1.14791271=100000055=EUR/USD110=50000010=001
20260120-14:04:27.375969000 : 8=FIX.4.49=068435=X49=NTPRO_IDBA_UAT56=SIRIUS_500007460_MD34=122452=20260120-14:04:27.680262=MD_GBP/USD_140109778778268=10279=0269=0270=1.25463271=10000055=GBP/USD110=0279=0269=0270=1.25463271=50000055=GBP/USD110=100000279=0269=0270=1.25463271=100000055=GBP/USD110=500000279=0269=0270=1.25463271=300000055=GBP/USD110=1000000279=0269=0270=1.25463271=500000055=GBP/USD110=3000000279=0269=1270=1.43499271=10000055=GBP/USD110=0279=0269=1270=1.43499271=50000055=GBP/USD110=100000279=0269=1270=1.43499271=100000055=GBP/USD110=500000279=0269=1270=1.43499271=300000055=GBP/USD110=1000000279=0269=1270=1.43499271=500000055=GBP/USD110=300000010=021
20260120-14:04:27.478203000 : 8=FIX.4.49=044735=X49=NTPRO_IDBA_UAT56=SIRIUS_500007460_MD34=122552=20260120-14:04:27.786262=MD_EUR/USD_140109278614268=6279=1269=0270=1.14792271=10000055=EUR/USD110=0279=1269=0270=1.14792271=50000055=EUR/USD110=100000279=1269=0270=1.14792271=100000055=EUR/USD110=500000279=1269=1270=1.19816271=10000055=EUR/USD110=0279=1269=1270=1.19816271=50000055=EUR/USD110=100000279=1269=1270=1.19816271=100000055=EUR/USD110=50000010=071
20260120-14:04:27.478676000 : 8=FIX.4.49=039835=X49=NTPRO_IDBA_UAT56=SIRIUS_500007460_MD34=122652=20260120-14:04:27.786262=MD_GBP/USD_140109778778268=5279=1269=0270=1.25466271=10000055=GBP/USD110=0279=1269=0270=1.25466271=50000055=GBP/USD110=100000279=1269=0270=1.25466271=100000055=GBP/USD110=500000279=1269=0270=1.25466271=300000055=GBP/USD110=1000000279=1269=0270=1.25466271=500000055=GBP/USD110=300000010=108
20260120-14:04:27.479192000 : 8=FIX.4.49=028035=X49=NTPRO_IDBA_UAT56=SIRIUS_500007460_MD34=122752=20260120-14:04:27.824262=MD_EUR/USD_140109278614268=3279=1269=1270=1.19818271=10000055=EUR/USD110=0279=1269=1270=1.19818271=50000055=EUR/USD110=100000279=1269=1270=1.19818271=100000055=EUR/USD110=50000010=023
