20260120-14:01:00.487979000 : 8=FIX.4.49=10735=A34=149=SIRIUS_500007460_MD52=20260120-14:01:00.48056=NTPRO_IDBA_UAT98=0108=30141=Y554=Df2Hy8nM10=245
20260120-14:01:00.590050000 : 8=FIX.4.49=009435=A49=NTPRO_IDBA_UAT56=SIRIUS_500007460_MD34=152=20260120-14:01:00.76198=0108=30141=Y10=192
20260120-14:01:00.596208000 : 8=FIX.4.49=011135=h49=NTPRO_IDBA_UAT56=SIRIUS_500007460_MD34=252=20260120-14:01:00.762336=Market Data340=258=version 510=126
20260120-14:01:09.280305000 : 8=FIX.4.49=15735=V34=249=SIRIUS_500007460_MD52=20260120-14:01:09.27856=NTPRO_IDBA_UAT146=155=EUR/USD262=MD_EUR/USD_140109278614263=1264=0265=1267=2269=0269=110=012
20260120-14:01:09.379889000 : 8=FIX.4.49=038935=W49=NTPRO_IDBA_UAT56=SIRIUS_500007460_MD34=352=20260120-14:01:09.869262=MD_EUR/USD_14010927861455=EUR/USD268=6269=0270=1.14853271=100000299=1110=0269=0270=1.14853271=500000299=2110=100000269=0270=1.14853271=1000000299=3110=500000269=1270=1.19877271=100000299=4110=0269=1270=1.19877271=500000299=5110=100000269=1270=1.19877271=1000000299=6110=50000010=114
20260120-14:01:09.443096000 : 8=FIX.4.49=027735=X49=NTPRO_IDBA_UAT56=SIRIUS_500007460_MD34=452=20260120-14:01:09.931262=MD_EUR/USD_140109278614268=3279=1269=0270=1.14852271=10000055=EUR/USD110=0279=1269=0270=1.14852271=50000055=EUR/USD110=100000279=1269=0270=1.14852271=100000055=EUR/USD110=50000010=105
20260120-14:01:09.465108000 : 8=FIX.4.49=027735=X49=NTPRO_IDBA_UAT56=SIRIUS_500007460_MD34=552=20260120-14:01:09.956262=MD_EUR/USD_140109278614268=3279=1269=0270=1.14853271=10000055=EUR/USD110=0279=1269=0270=1.14853271=50000055=EUR/USD110=100000279=1269=0270=1.14853271=100000055=EUR/USD110=50000010=116
20260120-14:01:09.780507000 : 8=FIX.4.49=15735=V34=349=SIRIUS_500007460_MD52=20260120-14:01:09.77856=NTPRO_IDBA_UAT146=155=GBP/USD262=MD_GBP/USD_140109778778263=1264=0265=1267=2269=0269=110=252
20260120-14:01:09.887634000 : 8=FIX.4.49=058335=W49=NTPRO_IDBA_UAT56=SIRIUS_500007460_MD34=652=20260120-14:01:10.396262=MD_GBP/USD_14010977877855=GBP/USD268=10269=0270=1.25532271=100000299=1110=0269=0270=1.25532271=500000299=2110=100000269=0270=1.25532271=1000000299=3110=500000269=0270=1.25532271=3000000299=4110=1000000269=0270=1.25532271=5000000299=5110=3000000269=1270=1.43566271=100000299=6110=0269=1270=1.43566271=500000299=7110=100000269=1270=1.43566271=1000000299=8110=500000269=1270=1.43566271=3000000299=9110=1000000269=1270=1.43566271=5000000299=10110=300000010=070
20260120-14:01:09.998779000 : 8=FIX.4.49=027735=X49=NTPRO_IDBA_UAT56=SIRIUS_500007460_MD34=752=20260120-14:01:10.496262=MD_EUR/USD_140109278614268=3279=1269=1270=1.19878271=10000055=EUR/USD110=0279=1269=1270=1.19878271=50000055=EUR/USD110=100000279=1269=1270=1.19878271=100000055=EUR/USD110=50000010=148
20260120-14:01:10.077837000 : 8=FIX.4.49=068135=X49=NTPRO_IDBA_UAT56=SIRIUS_500007460_MD34=852=20260120-14:01:10.592262=MD_GBP/USD_140109778778268=10279=1269=0270=1.25533271=10000055=GBP/USD110=0279=1269=0270=1.25533271=50000055=GBP/USD110=100000279=1269=0270=1.25533271=100000055=GBP/USD110=500000279=1269=0270=1.25533271=300000055=GBP/USD110=1000000279=1269=0270=1.25533271=500000055=GBP/USD110=3000000279=1269=1270=1.43567271=10000055=GBP/USD110=0279=1269=1270=1.43567271=50000055=GBP/USD110=100000279=1269=1270=1.43567271=100000055=GBP/USD110=500000279=1269=1270=1.43567271=300000055=GBP/USD110=1000000279=1269=1270=1.43567271=500000055=GBP/USD110=300000010=100
20260120-14:01:10.157569000 : 8=FIX.4.49=039535=X49=NTPRO_IDBA_UAT56=SIRIUS_500007460_MD34=952=20260120-14:01:10.674262=MD_GBP/USD_140109778778268=5279=1269=0270=1.25532271=10000055=GBP/USD110=0279=1269=0270=1.25532271=50000055=GBP/USD110=100000279=1269=0270=1.25532271=100000055=GBP/USD110=500000279=1269=0270=1.25532271=300000055=GBP/USD110=1000000279=1269=0270=1.25532271=500000055=GBP/USD110=300000010=170
20260120-14:01:10.196285000 : 8=FIX.4.49=039635=X49=NTPRO_IDBA_UAT56=SIRIUS_500007460_MD34=1052=20260120-14:01:10.713262=MD_GBP/USD_140109778778268=5279=1269=1270=1.43566271=10000055=GBP/USD110=0279=1269=1270=1.43566271=50000055=GBP/USD110=100000279=1269=1270=1.43566271=100000055=GBP/USD110=500000279=1269=1270=1.43566271=300000055=GBP/USD110=1000000279=1269=1270=1.43566271=500000055=GBP/USD110=300000010=245
20260120-14:01:10.281296000 : 8=FIX.4.49=15735=V34=449=SIRIUS_500007460_MD52=20260120-14:01:10.27956=NTPRO_IDBA_UAT146=155=USD/JPY262=MD_USD/JPY_140110279084263=1264=0265=1267=2269=0269=110=015
20260120-14:01:10.409610000 : 8=FIX.4.49=012235=W49=NTPRO_IDBA_UAT56=SIRIUS_500007460_MD34=1152=20260120-14:01:10.911262=MD_USD/JPY_14011027908455=USD/JPY268=010=021
20260120-14:01:10.780217000 : 8=FIX.4.49=15735=V34=549=SIRIUS_500007460_MD52=20260120-14:01:10.77956=NTPRO_IDBA_UAT146=155=USD/CAD262=MD_USD/CAD_140110779161263=1264=0265=1267=2269=0269=110=192
20260120-14:01:10.843368000 : 8=FIX.4.49=044535=X49=NTPRO_IDBA_UAT56=SIRIUS_500007460_MD34=1252=20260120-14:01:11.359262=MD_EUR/USD_140109278614268=6279=1269=0270=1.14852271=10000055=EUR/USD110=0279=1269=0270=1.14852271=50000055=EUR/USD110=100000279=1269=0270=1.14852271=100000055=EUR/USD110=500000279=1269=1270=1.19877271=10000055=EUR/USD110=0279=1269=1270=1.19877271=50000055=EUR/USD110=100000279=1269=1270=1.19877271=100000055=EUR/USD110=50000010=220
20260120-14:01:10.895780000 : 8=FIX.4.49=012235=W49=NTPRO_IDBA_UAT56=SIRIUS_500007460_MD34=1352=20260120-14:01:11.434262=MD_USD/CAD_14011077916155=USD/CAD268=010=195
20260120-14:01:10.965443000 : 8=FIX.4.49=044535=X49=NTPRO_IDBA_UAT56=SIRIUS_500007460_MD34=1452=20260120-14:01:11.492262=MD_EUR/USD_140109278614268=6279=1269=0270=1.14853271=10000055=EUR/USD110=0279=1269=0270=1.14853271=50000055=EUR/USD110=100000279=1269=0270=1.14853271=100000055=EUR/USD110=500000279=1269=1270=1.19878271=10000055=EUR/USD110=0279=1269=1270=1.19878271=50000055=EUR/USD110=100000279=1269=1270=1.19878271=100000055=EUR/USD110=50000010=226
20260120-14:01:11.347376000 : 8=FIX.4.49=039635=X49=NTPRO_IDBA_UAT56=SIRIUS_500007460_MD34=1552=20260120-14:01:11.910262=MD_GBP/USD_140109778778268=5279=1269=1270=1.43567271=10000055=GBP/USD110=0279=1269=1270=1.43567271=50000055=GBP/USD110=100000279=1269=1270=1.43567271=100000055=GBP/USD110=500000279=1269=1270=1.43567271=300000055=GBP/USD110=1000000279=1269=1270=1.43567271=500000055=GBP/USD110=300000010=255
20260120-14:01:11.376805000 : 8=FIX.4.49=044535=X49=NTPRO_IDBA_UAT56=SIRIUS_500007460_MD34=1652=20260120-14:01:11.940262=MD_EUR/USD_140109278614268=6279=1269=0270=1.14854271=10000055=EUR/USD110=0279=1269=0270=1.14854271=50000055=EUR/USD110=100000279=1269=0270=1.14854271=100000055=EUR/USD110=500000279=1269=1270=1.19879271=10000055=EUR/USD110=0279=1269=1270=1.19879271=50000055=EUR/USD110=100000279=1269=1270=1.19879271=100000055=EUR/USD110=50000010=232
20260120-14:01:11.452957000 : 8=FIX.4.49=039635=X49=NTPRO_IDBA_UAT56=SIRIUS_500007460_MD34=1752=20260120-14:01:12.019262=MD_GBP/USD_140109778778268=5279=1269=1270=1.43566271=10000055=GBP/USD110=0279=1269=1270=1.43566271=50000055=GBP/USD110=100000279=1269=1270=1.43566271=100000055=GBP/USD110=500000279=1269=1270=1.43566271=300000055=GBP/USD110=1000000279=1269=1270=1.43566271=500000055=GBP/USD110=300000010=253
20260120-14:01:11.473385000 : 8=FIX.4.49=039635=X49=NTPRO_IDBA_UAT56=SIRIUS_500007460_MD34=1852=20260120-14:01:12.041262=MD_GBP/USD_140109778778268=5279=1269=1270=1.43564271=10000055=GBP/USD110=0279=1269=1270=1.43564271=50000055=GBP/USD110=100000279=1269=1270=1.43564271=100000055=GBP/USD110=500000279=1269=1270=1.43564271=300000055=GBP/USD110=1000000279=1269=1270=1.43564271=500000055=GBP/USD110=300000010=239
20260120-14:01:11.515025000 : 8=FIX.4.49=027835=X49=NTPRO_IDBA_UAT56=SIRIUS_500007460_MD34=1952=20260120-14:01:12.083262=MD_EUR/USD_140109278614268=3279=1269=0270=1.14855271=10000055=EUR/USD110=0279=1269=0270=1.14855271=50000055=EUR/USD110=100000279=1269=0270=1.14855271=100000055=EUR/USD110=50000010=161
20260120-14:01:11.526727000 : 8=FIX.4.49=039635=X49=NTPRO_IDBA_UAT56=SIRIUS_500007460_MD34=2052=20260120-14:01:12.093262=MD_GBP/USD_140109778778268=5279=1269=1270=1.43565271=10000055=GBP/USD110=0279=1269=1270=1.43565271=50000055=GBP/USD110=100000279=1269=1270=1.43565271=100000055=GBP/USD110=500000279=1269=1270=1.43565271=300000055=GBP/USD110=1000000279=1269=1270=1.43565271=500000055=GBP/USD110=300000010=244
20260120-14:01:11.558271000 : 8=FIX.4.49=039135=X49=NTPRO_IDBA_UAT56=SIRIUS_500007460_MD34=2152=20260120-14:01:12.129262=MD_GBP/USD_140109778778268=5279=1269=0270=1.2553271=10000055=GBP/USD110=0279=1269=0270=1.2553271=50000055=GBP/USD110=100000279=1269=0270=1.2553271=100000055=GBP/USD110=500000279=1269=0270=1.2553271=300000055=GBP/USD110=1000000279=1269=0270=1.2553271=500000055=GBP/USD110=300000010=211
20260120-14:01:11.572008000 : 8=FIX.4.49=027835=X49=NTPRO_IDBA_UAT56=SIRIUS_500007460_MD34=2252=20260120-14:01:12.143262=MD_EUR/USD_140109278614268=3279=1269=0270=1.14854271=10000055=EUR/USD110=0279=1269=0270=1.14854271=50000055=EUR/USD110=100000279=1269=0270=1.14854271=100000055=EUR/USD110=50000010=149
20260120-14:01:11.618285000 : 8=FIX.4.49=039635=X49=NTPRO_IDBA_UAT56=SIRIUS_500007460_MD34=2352=20260120-14:01:12.159262=MD_GBP/USD_140109778778268=5279=1269=0270=1.25531271=10000055=GBP/USD110=0279=1269=0270=1.25531271=50000055=GBP/USD110=100000279=1269=0270=1.25531271=100000055=GBP/USD110=500000279=1269=0270=1.25531271=300000055=GBP/USD110=1000000279=1269=0270=1.25531271=500000055=GBP/USD110=300000010=210
20260120-14:01:11.618931000 : 8=FIX.4.49=039635=X49=NTPRO_IDBA_UAT56=SIRIUS_500007460_MD34=2452=20260120-14:01:12.179262=MD_GBP/USD_140109778778268=5279=1269=1270=1.43566271=10000055=GBP/USD110=0279=1269=1270=1.43566271=50000055=GBP/USD110=100000279=1269=1270=1.43566271=100000055=GBP/USD110=500000279=1269=1270=1.43566271=300000055=GBP/USD110=1000000279=1269=1270=1.43566271=500000055=GBP/USD110=300000010=002
20260120-14:01:11.619246000 : 8=FIX.4.49=027835=X49=NTPRO_IDBA_UAT56=SIRIUS_500007460_MD34=2552=20260120-14:01:12.186262=MD_EUR/USD_140109278614268=3279=1269=0270=1.14853271=10000055=EUR/USD110=0279=1269=0270=1.14853271=50000055=EUR/USD110=100000279=1269=0270=1.14853271=100000055=EUR/USD110=50000010=156
20260120-14:01:11.633189000 : 8=FIX.4.49=039635=X49=NTPRO_IDBA_UAT56=SIRIUS_500007460_MD34=2652=20260120-14:01:12.206262=MD_GBP/USD_140109778778268=5279=1269=1270=1.43565271=10000055=GBP/USD110=0279=1269=1270=1.43565271=50000055=GBP/USD110=100000279=1269=1270=1.43565271=100000055=GBP/USD110=500000279=1269=1270=1.43565271=300000055=GBP/USD110=1000000279=1269=1270=1.43565271=500000055=GBP/USD110=300000010=246
20260120-14:01:11.658010000 : 8=FIX.4.49=068235=X49=NTPRO_IDBA_UAT56=SIRIUS_500007460_MD34=2752=20260120-14:01:12.232262=MD_GBP/USD_140109778778268=10279=1269=0270=1.25532271=10000055=GBP/USD110=0279=1269=0270=1.25532271=50000055=GBP/USD110=100000279=1269=0270=1.25532271=100000055=GBP/USD110=500000279=1269=0270=1.25532271=300000055=GBP/USD110=1000000279=1269=0270=1.25532271=500000055=GBP/USD110=3000000279=1269=1270=1.43566271=10000055=GBP/USD110=0279=1269=1270=1.43566271=50000055=GBP/USD110=100000279=1269=1270=1.43566271=100000055=GBP/USD110=500000279=1269=1270=1.43566271=300000055=GBP/USD110=1000000279=1269=1270=1.43566271=500000055=GBP/USD110=300000010=133
20260120-14:01:11.712318000 : 8=FIX.4.49=027835=X49=NTPRO_IDBA_UAT56=SIRIUS_500007460_MD34=2852=20260120-14:01:12.282262=MD_EUR/USD_140109278614268=3279=1269=1270=1.19878271=10000055=EUR/USD110=0279=1269=1270=1.19878271=50000055=EUR/USD110=100000279=1269=1270=1.19878271=100000055=EUR/USD110=50000010=195
20260120-14:01:11.775745000 : 8=FIX.4.49=039635=X49=NTPRO_IDBA_UAT56=SIRIUS_500007460_MD34=2952=20260120-14:01:12.354262=MD_GBP/USD_140109778778268=5279=1269=1270=1.43565271=10000055=GBP/USD110=0279=1269=1270=1.43565271=50000055=GBP/USD110=100000279=1269=1270=1.43565271=100000055=GBP/USD110=500000279=1269=1270=1.43565271=300000055=GBP/USD110=1000000279=1269=1270=1.43565271=500000055=GBP/USD110=300000010=253
20260120-14:01:11.831712000 : 8=FIX.4.49=039635=X49=NTPRO_IDBA_UAT56=SIRIUS_500007460_MD34=3052=20260120-14:01:12.412262=MD_GBP/USD_140109778778268=5279=1269=0270=1.25531271=10000055=GBP/USD110=0279=1269=0270=1.25531271=50000055=GBP/USD110=100000279=1269=0270=1.25531271=100000055=GBP/USD110=500000279=1269=0270=1.25531271=300000055=GBP/USD110=1000000279=1269=0270=1.25531271=500000055=GBP/USD110=300000010=200
20260120-14:01:11.910172000 : 8=FIX.4.49=027835=X49=NTPRO_IDBA_UAT56=SIRIUS_500007460_MD34=3152=20260120-14:01:12.489262=MD_EUR/USD_140109278614268=3279=1269=1270=1.19879271=10000055=EUR/USD110=0279=1269=1270=1.19879271=50000055=EUR/USD110=100000279=1269=1270=1.19879271=100000055=EUR/USD110=50000010=201
20260120-14:01:12.017350000 : 8=FIX.4.49=027835=X49=NTPRO_IDBA_UAT56=SIRIUS_500007460_MD34=3252=20260120-14:01:12.605262=MD_EUR/USD_140109278614268=3279=1269=1270=1.19878271=10000055=EUR/USD110=0279=1269=1270=1.19878271=50000055=EUR/USD110=100000279=1269=1270=1.19878271=100000055=EUR/USD110=50000010=189
20260120-14:01:12.223155000 : 8=FIX.4.49=044535=X49=NTPRO_IDBA_UAT56=SIRIUS_500007460_MD34=3352=20260120-14:01:12.815262=MD_EUR/USD_140109278614268=6279=1269=0270=1.14854271=10000055=EUR/USD110=0279=1269=0270=1.14854271=50000055=EUR/USD110=100000279=1269=0270=1.14854271=100000055=EUR/USD110=500000279=1269=1270=1.19879271=10000055=EUR/USD110=0279=1269=1270=1.19879271=50000055=EUR/USD110=100000279=1269=1270=1.19879271=100000055=EUR/USD110=50000010=233
20260120-14:01:13.124607000 : 8=FIX.4.49=039635=X49=NTPRO_IDBA_UAT56=SIRIUS_500007460_MD34=3452=20260120-14:01:13.753262=MD_GBP/USD_140109778778268=5279=1269=1270=1.43566271=10000055=GBP/USD110=0279=1269=1270=1.43566271=50000055=GBP/USD110=100000279=1269=1270=1.43566271=100000055=GBP/USD110=500000279=1269=1270=1.43566271=300000055=GBP/USD110=1000000279=1269=1270=1.43566271=500000055=GBP/USD110=300000010=002
20260120-14:01:13.156258000 : 8=FIX.4.49=068235=X49=NTPRO_IDBA_UAT56=SIRIUS_500007460_MD34=3552=20260120-14:01:13.786262=MD_GBP/USD_140109778778268=10279=1269=0270=1.25532271=10000055=GBP/USD110=0279=1269=0270=1.25532271=50000055=GBP/USD110=100000279=1269=0270=1.25532271=100000055=GBP/USD110=500000279=1269=0270=1.25532271=300000055=GBP/USD110=1000000279=1269=0270=1.25532271=500000055=GBP/USD110=3000000279=1269=1270=1.43567271=10000055=GBP/USD110=0279=1269=1270=1.43567271=50000055=GBP/USD110=100000279=1269=1270=1.43567271=100000055=GBP/USD110=500000279=1269=1270=1.43567271=300000055=GBP/USD110=1000000279=1269=1270=1.43567271=500000055=GBP/USD110=300000010=152
20260120-14:01:13.172597000 : 8=FIX.4.49=044535=X49=NTPRO_IDBA_UAT56=SIRIUS_500007460_MD34=3652=20260120-14:01:13.799262=MD_EUR/USD_140109278614268=6279=1269=0270=1.14856271=10000055=EUR/USD110=0279=1269=0270=1.14856271=50000055=EUR/USD110=100000279=1269=0270=1.14856271=100000055=EUR/USD110=500000279=1269=1270=1.19881271=10000055=EUR/USD110=0279=1269=1270=1.19881271=50000055=EUR/USD110=100000279=1269=1270=1.19881271=100000055=EUR/USD110=50000010=233
20260120-14:01:13.213551000 : 8=FIX.4.49=068235=X49=NTPRO_IDBA_UAT56=SIRIUS_500007460_MD34=3752=20260120-14:01:13.816262=MD_GBP/USD_140109778778268=10279=1269=0270=1.25533271=10000055=GBP/USD110=0279=1269=0270=1.25533271=50000055=GBP/USD110=100000279=1269=0270=1.25533271=100000055=GBP/USD110=500000279=1269=0270=1.25533271=300000055=GBP/USD110=1000000279=1269=0270=1.25533271=500000055=GBP/USD110=3000000279=1269=1270=1.43568271=10000055=GBP/USD110=0279=1269=1270=1.43568271=50000055=GBP/USD110=100000279=1269=1270=1.43568271=100000055=GBP/USD110=500000279=1269=1270=1.43568271=300000055=GBP/USD110=1000000279=1269=1270=1.43568271=500000055=GBP/USD110=300000010=158
20260120-14:01:13.213978000 : 8=FIX.4.49=039635=X49=NTPRO_IDBA_UAT56=SIRIUS_500007460_MD34=3852=20260120-14:01:13.843262=MD_GBP/USD_140109778778268=5279=1269=0270=1.25535271=10000055=GBP/USD110=0279=1269=0270=1.25535271=50000055=GBP/USD110=100000279=1269=0270=1.25535271=100000055=GBP/USD110=500000279=1269=0270=1.25535271=300000055=GBP/USD110=1000000279=1269=0270=1.25535271=500000055=GBP/USD110=300000010=237
20260120-14:01:13.243379000 : 8=FIX.4.49=068235=X49=NTPRO_IDBA_UAT56=SIRIUS_500007460_MD34=3952=20260120-14:01:13.875262=MD_GBP/USD_140109778778268=10279=1269=0270=1.25536271=10000055=GBP/USD110=0279=1269=0270=1.25536271=50000055=GBP/USD110=100000279=1269=0270=1.25536271=100000055=GBP/USD110=500000279=1269=0270=1.25536271=300000055=GBP/USD110=1000000279=1269=0270=1.25536271=500000055=GBP/USD110=3000000279=1269=1270=1.43569271=10000055=GBP/USD110=0279=1269=1270=1.43569271=50000055=GBP/USD110=100000279=1269=1270=1.43569271=100000055=GBP/USD110=500000279=1269=1270=1.43569271=300000055=GBP/USD110=1000000279=1269=1270=1.43569271=500000055=GBP/USD110=300000010=185
20260120-14:01:13.317472000 : 8=FIX.4.49=039135=X49=NTPRO_IDBA_UAT56=SIRIUS_500007460_MD34=4052=20260120-14:01:13.928262=MD_GBP/USD_140109778778268=5279=1269=1270=1.4357271=10000055=GBP/USD110=0279=1269=1270=1.4357271=50000055=GBP/USD110=100000279=1269=1270=1.4357271=100000055=GBP/USD110=500000279=1269=1270=1.4357271=300000055=GBP/USD110=1000000279=1269=1270=1.4357271=500000055=GBP/USD110=300000010=245
20260120-14:01:13.330987000 : 8=FIX.4.49=027535=X49=NTPRO_IDBA_UAT56=SIRIUS_500007460_MD34=4152=20260120-14:01:13.967262=MD_EUR/USD_140109278614268=3279=1269=1270=1.1988271=10000055=EUR/USD110=0279=1269=1270=1.1988271=50000055=EUR/USD110=100000279=1269=1270=1.1988271=100000055=EUR/USD110=50000010=033
20260120-14:01:13.409810000 : 8=FIX.4.49=027835=X49=NTPRO_IDBA_UAT56=SIRIUS_500007460_MD34=4252=20260120-14:01:14.036262=MD_EUR/USD_140109278614268=3279=1269=1270=1.19881271=10000055=EUR/USD110=0279=1269=1270=1.19881271=50000055=EUR/USD110=100000279=1269=1270=1.19881271=100000055=EUR/USD110=50000010=172
20260120-14:01:13.410592000 : 8=FIX.4.49=039635=X49=NTPRO_IDBA_UAT56=SIRIUS_500007460_MD34=4352=20260120-14:01:14.046262=MD_GBP/USD_140109778778268=5279=1269=1270=1.43569271=10000055=GBP/USD110=0279=1269=1270=1.43569271=50000055=GBP/USD110=100000279=1269=1270=1.43569271=100000055=GBP/USD110=500000279=1269=1270=1.43569271=300000055=GBP/USD110=1000000279=1269=1270=1.43569271=500000055=GBP/USD110=300000010=013
20260120-14:01:13.692769000 : 8=FIX.4.49=027835=X49=NTPRO_IDBA_UAT56=SIRIUS_500007460_MD34=4452=20260120-14:01:14.341262=MD_EUR/USD_140109278614268=3279=1269=0270=1.14857271=10000055=EUR/USD110=0279=1269=0270=1.14857271=50000055=EUR/USD110=100000279=1269=0270=1.14857271=100000055=EUR/USD110=50000010=164
20260120-14:01:13.843995000 : 8=FIX.4.49=027835=X49=NTPRO_IDBA_UAT56=SIRIUS_500007460_MD34=4552=20260120-14:01:14.499262=MD_EUR/USD_140109278614268=3279=1269=0270=1.14856271=10000055=EUR/USD110=0279=1269=0270=1.14856271=50000055=EUR/USD110=100000279=1269=0270=1.14856271=100000055=EUR/USD110=50000010=176
20260120-14:01:13.872578000 : 8=FIX.4.49=044235=X49=NTPRO_IDBA_UAT56=SIRIUS_500007460_MD34=4652=20260120-14:01:14.525262=MD_EUR/USD_140109278614268=6279=1269=0270=1.14855271=10000055=EUR/USD110=0279=1269=0270=1.14855271=50000055=EUR/USD110=100000279=1269=0270=1.14855271=100000055=EUR/USD110=500000279=1269=1270=1.1988271=10000055=EUR/USD110=0279=1269=1270=1.1988271=50000055=EUR/USD110=100000279=1269=1270=1.1988271=100000055=EUR/USD110=50000010=069
20260120-14:01:13.909806000 : 8=FIX.4.49=068235=X49=NTPRO_IDBA_UAT56=SIRIUS_500007460_MD34=4752=20260120-14:01:14.565262=MD_GBP/USD_140109778778268=10279=1269=0270=1.25535271=10000055=GBP/USD110=0279=1269=0270=1.25535271=50000055=GBP/USD110=100000279=1269=0270=1.25535271=100000055=GBP/USD110=500000279=1269=0270=1.25535271=300000055=GBP/USD110=1000000279=1269=0270=1.25535271=500000055=GBP/USD110=3000000279=1269=1270=1.43565271=10000055=GBP/USD110=0279=1269=1270=1.43565271=50000055=GBP/USD110=100000279=1269=1270=1.43565271=100000055=GBP/USD110=500000279=1269=1270=1.43565271=300000055=GBP/USD110=1000000279=1269=1270=1.43565271=500000055=GBP/USD110=300000010=156
20260120-14:01:13.945592000 : 8=FIX.4.49=039635=X49=NTPRO_IDBA_UAT56=SIRIUS_500007460_MD34=4852=20260120-14:01:14.604262=MD_GBP/USD_140109778778268=5279=1269=0270=1.25534271=10000055=GBP/USD110=0279=1269=0270=1.25534271=50000055=GBP/USD110=100000279=1269=0270=1.25534271=100000055=GBP/USD110=500000279=1269=0270=1.25534271=300000055=GBP/USD110=1000000279=1269=0270=1.25534271=500000055=GBP/USD110=300000010=229
20260120-14:01:13.993010000 : 8=FIX.4.49=044535=X49=NTPRO_IDBA_UAT56=SIRIUS_500007460_MD34=4952=20260120-14:01:14.634262=MD_EUR/USD_140109278614268=6279=1269=0270=1.14854271=10000055=EUR/USD110=0279=1269=0270=1.14854271=50000055=EUR/USD110=100000279=1269=0270=1.14854271=100000055=EUR/USD110=500000279=1269=1270=1.19879271=10000055=EUR/USD110=0279=1269=1270=1.19879271=50000055=EUR/USD110=100000279=1269=1270=1.19879271=100000055=EUR/USD110=50000010=241
20260120-14:01:13.999510000 : 8=FIX.4.49=067735=X49=NTPRO_IDBA_UAT56=SIRIUS_500007460_MD34=5052=20260120-14:01:14.660262=MD_GBP/USD_140109778778268=10279=1269=0270=1.2553271=10000055=GBP/USD110=0279=1269=0270=1.2553271=50000055=GBP/USD110=100000279=1269=0270=1.2553271=100000055=GBP/USD110=500000279=1269=0270=1.2553271=300000055=GBP/USD110=1000000279=1269=0270=1.2553271=500000055=GBP/USD110=3000000279=1269=1270=1.43564271=10000055=GBP/USD110=0279=1269=1270=1.43564271=50000055=GBP/USD110=100000279=1269=1270=1.43564271=100000055=GBP/USD110=500000279=1269=1270=1.43564271=300000055=GBP/USD110=1000000279=1269=1270=1.43564271=500000055=GBP/USD110=300000010=136
20260120-14:01:14.232100000 : 8=FIX.4.49=039635=X49=NTPRO_IDBA_UAT56=SIRIUS_500007460_MD34=5152=20260120-14:01:14.901262=MD_GBP/USD_140109778778268=5279=1269=0270=1.25529271=10000055=GBP/USD110=0279=1269=0270=1.25529271=50000055=GBP/USD110=100000279=1269=0270=1.25529271=100000055=GBP/USD110=500000279=1269=0270=1.25529271=300000055=GBP/USD110=1000000279=1269=0270=1.25529271=500000055=GBP/USD110=300000010=243
20260120-14:01:14.379336000 : 8=FIX.4.49=027835=X49=NTPRO_IDBA_UAT56=SIRIUS_500007460_MD34=5252=20260120-14:01:15.029262=MD_EUR/USD_140109278614268=3279=1269=0270=1.14855271=10000055=EUR/USD110=0279=1269=0270=1.14855271=50000055=EUR/USD110=100000279=1269=0270=1.14855271=100000055=EUR/USD110=50000010=161
20260120-14:01:14.489770000 : 8=FIX.4.49=027835=X49=NTPRO_IDBA_UAT56=SIRIUS_500007460_MD34=5352=20260120-14:01:15.138262=MD_EUR/USD_140109278614268=3279=1269=0270=1.14854271=10000055=EUR/USD110=0279=1269=0270=1.14854271=50000055=EUR/USD110=100000279=1269=0270=1.14854271=100000055=EUR/USD110=50000010=160
20260120-14:01:14.491073000 : 8=FIX.4.49=039635=X49=NTPRO_IDBA_UAT56=SIRIUS_500007460_MD34=5452=20260120-14:01:15.144262=MD_GBP/USD_140109778778268=5279=1269=1270=1.43563271=10000055=GBP/USD110=0279=1269=1270=1.43563271=50000055=GBP/USD110=100000279=1269=1270=1.43563271=100000055=GBP/USD110=500000279=1269=1270=1.43563271=300000055=GBP/USD110=1000000279=1269=1270=1.43563271=500000055=GBP/USD110=300000010=241
20260120-14:01:14.495281000 : 8=FIX.4.49=039635=X49=NTPRO_IDBA_UAT56=SIRIUS_500007460_MD34=5552=20260120-14:01:15.170262=MD_GBP/USD_140109778778268=5279=1269=0270=1.25528271=10000055=GBP/USD110=0279=1269=0270=1.25528271=50000055=GBP/USD110=100000279=1269=0270=1.25528271=100000055=GBP/USD110=500000279=1269=0270=1.25528271=300000055=GBP/USD110=1000000279=1269=0270=1.25528271=500000055=GBP/USD110=300000010=241
20260120-14:01:14.531351000 : 8=FIX.4.49=039635=X49=NTPRO_IDBA_UAT56=SIRIUS_500007460_MD34=5652=20260120-14:01:15.211262=MD_GBP/USD_140109778778268=5279=1269=1270=1.43562271=10000055=GBP/USD110=0279=1269=1270=1.43562271=50000055=GBP/USD110=100000279=1269=1270=1.43562271=100000055=GBP/USD110=500000279=1269=1270=1.43562271=300000055=GBP/USD110=1000000279=1269=1270=1.43562271=500000055=GBP/USD110=300000010=233
20260120-14:01:14.679583000 : 8=FIX.4.49=044535=X49=NTPRO_IDBA_UAT56=SIRIUS_500007460_MD34=5752=20260120-14:01:15.342262=MD_EUR/USD_140109278614268=6279=1269=0270=1.14853271=10000055=EUR/USD110=0279=1269=0270=1.14853271=50000055=EUR/USD110=100000279=1269=0270=1.14853271=100000055=EUR/USD110=500000279=1269=1270=1.19878271=10000055=EUR/USD110=0279=1269=1270=1.19878271=50000055=EUR/USD110=100000279=1269=1270=1.19878271=100000055=EUR/USD110=50000010=231
20260120-14:01:14.829782000 : 8=FIX.4.49=039635=X49=NTPRO_IDBA_UAT56=SIRIUS_500007460_MD34=5852=20260120-14:01:15.520262=MD_GBP/USD_140109778778268=5279=1269=0270=1.25527271=10000055=GBP/USD110=0279=1269=0270=1.25527271=50000055=GBP/USD110=100000279=1269=0270=1.25527271=100000055=GBP/USD110=500000279=1269=0270=1.25527271=300000055=GBP/USD110=1000000279=1269=0270=1.25527271=500000055=GBP/USD110=300000010=238
20260120-14:01:14.887660000 : 8=FIX.4.49=027835=X49=NTPRO_IDBA_UAT56=SIRIUS_500007460_MD34=5952=20260120-14:01:15.559262=MD_EUR/USD_140109278614268=3279=1269=1270=1.19877271=10000055=EUR/USD110=0279=1269=1270=1.19877271=50000055=EUR/USD110=100000279=1269=1270=1.19877271=100000055=EUR/USD110=50000010=206
20260120-14:01:15.426625000 : 8=FIX.4.49=027835=X49=NTPRO_IDBA_UAT56=SIRIUS_500007460_MD34=6052=20260120-14:01:16.135262=MD_EUR/USD_140109278614268=3279=1269=1270=1.19878271=10000055=EUR/USD110=0279=1269=1270=1.19878271=50000055=EUR/USD110=100000279=1269=1270=1.19878271=100000055=EUR/USD110=50000010=192
20260120-14:01:15.538445000 : 8=FIX.4.49=027835=X49=NTPRO_IDBA_UAT56=SIRIUS_500007460_MD34=6152=20260120-14:01:16.247262=MD_EUR/USD_140109278614268=3279=1269=1270=1.19877271=10000055=EUR/USD110=0279=1269=1270=1.19877271=50000055=EUR/USD110=100000279=1269=1270=1.19877271=100000055=EUR/USD110=50000010=194
20260120-14:01:15.611252000 : 8=FIX.4.49=027835=X49=NTPRO_IDBA_UAT56=SIRIUS_500007460_MD34=6252=20260120-14:01:16.324262=MD_EUR/USD_140109278614268=3279=1269=1270=1.19878271=10000055=EUR/USD110=0279=1269=1270=1.19878271=50000055=EUR/USD110=100000279=1269=1270=1.19878271=100000055=EUR/USD110=50000010=194
20260120-14:01:15.725408000 : 8=FIX.4.49=027835=X49=NTPRO_IDBA_UAT56=SIRIUS_500007460_MD34=6352=20260120-14:01:16.448262=MD_EUR/USD_140109278614268=3279=1269=0270=1.14854271=10000055=EUR/USD110=0279=1269=0270=1.14854271=50000055=EUR/USD110=100000279=1269=0270=1.14854271=100000055=EUR/USD110=50000010=166
20260120-14:01:15.788986000 : 8=FIX.4.49=068235=X49=NTPRO_IDBA_UAT56=SIRIUS_500007460_MD34=6452=20260120-14:01:16.513262=MD_GBP/USD_140109778778268=10279=1269=0270=1.25528271=10000055=GBP/USD110=0279=1269=0270=1.25528271=50000055=GBP/USD110=100000279=1269=0270=1.25528271=100000055=GBP/USD110=500000279=1269=0270=1.25528271=300000055=GBP/USD110=1000000279=1269=0270=1.25528271=500000055=GBP/USD110=3000000279=1269=1270=1.43563271=10000055=GBP/USD110=0279=1269=1270=1.43563271=50000055=GBP/USD110=100000279=1269=1270=1.43563271=100000055=GBP/USD110=500000279=1269=1270=1.43563271=300000055=GBP/USD110=1000000279=1269=1270=1.43563271=500000055=GBP/USD110=300000010=150
20260120-14:01:15.829494000 : 8=FIX.4.49=044535=X49=NTPRO_IDBA_UAT56=SIRIUS_500007460_MD34=6552=20260120-14:01:16.556262=MD_EUR/USD_140109278614268=6279=1269=0270=1.14853271=10000055=EUR/USD110=0279=1269=0270=1.14853271=50000055=EUR/USD110=100000279=1269=0270=1.14853271=100000055=EUR/USD110=500000279=1269=1270=1.19877271=10000055=EUR/USD110=0279=1269=1270=1.19877271=50000055=EUR/USD110=100000279=1269=1270=1.19877271=100000055=EUR/USD110=50000010=235
20260120-14:01:15.843846000 : 8=FIX.4.49=044535=X49=NTPRO_IDBA_UAT56=SIRIUS_500007460_MD34=6652=20260120-14:01:16.571262=MD_EUR/USD_140109278614268=6279=1269=0270=1.14854271=10000055=EUR/USD110=0279=1269=0270=1.14854271=50000055=EUR/USD110=100000279=1269=0270=1.14854271=100000055=EUR/USD110=500000279=1269=1270=1.19878271=10000055=EUR/USD110=0279=1269=1270=1.19878271=50000055=EUR/USD110=100000279=1269=1270=1.19878271=100000055=EUR/USD110=50000010=239
20260120-14:01:15.973513000 : 8=FIX.4.49=027835=X49=NTPRO_IDBA_UAT56=SIRIUS_500007460_MD34=6752=20260120-14:01:16.703262=MD_EUR/USD_140109278614268=3279=1269=0270=1.14853271=10000055=EUR/USD110=0279=1269=0270=1.14853271=50000055=EUR/USD110=100000279=1269=0270=1.14853271=100000055=EUR/USD110=50000010=161
20260120-14:01:16.281524000 : 8=FIX.4.49=044535=X49=NTPRO_IDBA_UAT56=SIRIUS_500007460_MD34=6852=20260120-14:01:17.014262=MD_EUR/USD_140109278614268=6279=1269=0270=1.14855271=10000055=EUR/USD110=0279=1269=0270=1.14855271=50000055=EUR/USD110=100000279=1269=0270=1.14855271=100000055=EUR/USD110=500000279=1269=1270=1.19879271=10000055=EUR/USD110=0279=1269=1270=1.19879271=50000055=EUR/USD110=100000279=1269=1270=1.19879271=100000055=EUR/USD110=50000010=240
20260120-14:01:16.715360000 : 8=FIX.4.49=044535=X49=NTPRO_IDBA_UAT56=SIRIUS_500007460_MD34=6952=20260120-14:01:17.464262=MD_EUR/USD_140109278614268=6279=1269=0270=1.14853271=10000055=EUR/USD110=0279=1269=0270=1.14853271=50000055=EUR/USD110=100000279=1269=0270=1.14853271=100000055=EUR/USD110=500000279=1269=1270=1.19878271=10000055=EUR/USD110=0279=1269=1270=1.19878271=50000055=EUR/USD110=100000279=1269=1270=1.19878271=100000055=EUR/USD110=50000010=241
20260120-14:01:16.767721000 : 8=FIX.4.49=039635=X49=NTPRO_IDBA_UAT56=SIRIUS_500007460_MD34=7052=20260120-14:01:17.529262=MD_GBP/USD_140109778778268=5279=1269=1270=1.43562271=10000055=GBP/USD110=0279=1269=1270=1.43562271=50000055=GBP/USD110=100000279=1269=1270=1.43562271=100000055=GBP/USD110=500000279=1269=1270=1.43562271=300000055=GBP/USD110=1000000279=1269=1270=1.43562271=500000055=GBP/USD110=300000010=243
20260120-14:01:16.854450000 : 8=FIX.4.49=039635=X49=NTPRO_IDBA_UAT56=SIRIUS_500007460_MD34=7152=20260120-14:01:17.598262=MD_GBP/USD_140109778778268=5279=1269=1270=1.43563271=10000055=GBP/USD110=0279=1269=1270=1.43563271=50000055=GBP/USD110=100000279=1269=1270=1.43563271=100000055=GBP/USD110=500000279=1269=1270=1.43563271=300000055=GBP/USD110=1000000279=1269=1270=1.43563271=500000055=GBP/USD110=300000010=255
20260120-14:01:17.002157000 : 8=FIX.4.49=039635=X49=NTPRO_IDBA_UAT56=SIRIUS_500007460_MD34=7252=20260120-14:01:17.754262=MD_GBP/USD_140109778778268=5279=1269=1270=1.43562271=10000055=GBP/USD110=0279=1269=1270=1.43562271=50000055=GBP/USD110=100000279=1269=1270=1.43562271=100000055=GBP/USD110=500000279=1269=1270=1.43562271=300000055=GBP/USD110=1000000279=1269=1270=1.43562271=500000055=GBP/USD110=300000010=245
20260120-14:01:17.201581000 : 8=FIX.4.49=039635=X49=NTPRO_IDBA_UAT56=SIRIUS_500007460_MD34=7352=20260120-14:01:17.929262=MD_GBP/USD_140109778778268=5279=1269=1270=1.43563271=10000055=GBP/USD110=0279=1269=1270=1.43563271=50000055=GBP/USD110=100000279=1269=1270=1.43563271=100000055=GBP/USD110=500000279=1269=1270=1.43563271=300000055=GBP/USD110=1000000279=1269=1270=1.43563271=500000055=GBP/USD110=300000010=255
20260120-14:01:17.318254000 : 8=FIX.4.49=027835=X49=NTPRO_IDBA_UAT56=SIRIUS_500007460_MD34=7452=20260120-14:01:18.099262=MD_EUR/USD_140109278614268=3279=1269=0270=1.14854271=10000055=EUR/USD110=0279=1269=0270=1.14854271=50000055=EUR/USD110=100000279=1269=0270=1.14854271=100000055=EUR/USD110=50000010=172
20260120-14:01:17.387680000 : 8=FIX.4.49=027835=X49=NTPRO_IDBA_UAT56=SIRIUS_500007460_MD34=7552=20260120-14:01:18.171262=MD_EUR/USD_140109278614268=3279=1269=1270=1.19879271=10000055=EUR/USD110=0279=1269=1270=1.19879271=50000055=EUR/USD110=100000279=1269=1270=1.19879271=100000055=EUR/USD110=50000010=203
20260120-14:01:17.652618000 : 8=FIX.4.49=039635=X49=NTPRO_IDBA_UAT56=SIRIUS_500007460_MD34=7652=20260120-14:01:18.445262=MD_GBP/USD_140109778778268=5279=1269=1270=1.43562271=10000055=GBP/USD110=0279=1269=1270=1.43562271=50000055=GBP/USD110=100000279=1269=1270=1.43562271=100000055=GBP/USD110=500000279=1269=1270=1.43562271=300000055=GBP/USD110=1000000279=1269=1270=1.43562271=500000055=GBP/USD110=300000010=247
20260120-14:01:17.726815000 : 8=FIX.4.49=027835=X49=NTPRO_IDBA_UAT56=SIRIUS_500007460_MD34=7752=20260120-14:01:18.522262=MD_EUR/USD_140109278614268=3279=1269=1270=1.19878271=10000055=EUR/USD110=0279=1269=1270=1.19878271=50000055=EUR/USD110=100000279=1269=1270=1.19878271=100000055=EUR/USD110=50000010=202
20260120-14:01:17.744942000 : 8=FIX.4.49=068235=X49=NTPRO_IDBA_UAT56=SIRIUS_500007460_MD34=7852=20260120-14:01:18.536262=MD_GBP/USD_140109778778268=10279=1269=0270=1.25527271=10000055=GBP/USD110=0279=1269=0270=1.25527271=50000055=GBP/USD110=100000279=1269=0270=1.25527271=100000055=GBP/USD110=500000279=1269=0270=1.25527271=300000055=GBP/USD110=1000000279=1269=0270=1.25527271=500000055=GBP/USD110=3000000279=1269=1270=1.43561271=10000055=GBP/USD110=0279=1269=1270=1.43561271=50000055=GBP/USD110=100000279=1269=1270=1.43561271=100000055=GBP/USD110=500000279=1269=1270=1.43561271=300000055=GBP/USD110=1000000279=1269=1270=1.43561271=500000055=GBP/USD110=300000010=147
20260120-14:01:17.778218000 : 8=FIX.4.49=044535=X49=NTPRO_IDBA_UAT56=SIRIUS_500007460_MD34=7952=20260120-14:01:18.576262=MD_EUR/USD_140109278614268=6279=1269=0270=1.14852271=10000055=EUR/USD110=0279=1269=0270=1.14852271=50000055=EUR/USD110=100000279=1269=0270=1.14852271=100000055=EUR/USD110=500000279=1269=1270=1.19876271=10000055=EUR/USD110=0279=1269=1270=1.19876271=50000055=EUR/USD110=100000279=1269=1270=1.19876271=100000055=EUR/USD110=50000010=238
20260120-14:01:17.803415000 : 8=FIX.4.49=039635=X49=NTPRO_IDBA_UAT56=SIRIUS_500007460_MD34=8052=20260120-14:01:18.602262=MD_GBP/USD_140109778778268=5279=1269=0270=1.25526271=10000055=GBP/USD110=0279=1269=0270=1.25526271=50000055=GBP/USD110=100000279=1269=0270=1.25526271=100000055=GBP/USD110=500000279=1269=0270=1.25526271=300000055=GBP/USD110=1000000279=1269=0270=1.25526271=500000055=GBP/USD110=300000010=232
20260120-14:01:17.886125000 : 8=FIX.4.49=027835=X49=NTPRO_IDBA_UAT56=SIRIUS_500007460_MD34=8152=20260120-14:01:18.684262=MD_EUR/USD_140109278614268=3279=1269=1270=1.19877271=10000055=EUR/USD110=0279=1269=1270=1.19877271=50000055=EUR/USD110=100000279=1269=1270=1.19877271=100000055=EUR/USD110=50000010=203
20260120-14:01:17.895624000 : 8=FIX.4.49=039635=X49=NTPRO_IDBA_UAT56=SIRIUS_500007460_MD34=8252=20260120-14:01:18.697262=MD_GBP/USD_140109778778268=5279=1269=0270=1.25527271=10000055=GBP/USD110=0279=1269=0270=1.25527271=50000055=GBP/USD110=100000279=1269=0270=1.25527271=100000055=GBP/USD110=500000279=1269=0270=1.25527271=300000055=GBP/USD110=1000000279=1269=0270=1.25527271=500000055=GBP/USD110=300000010=253
20260120-14:01:17.955608000 : 8=FIX.4.49=039635=X49=NTPRO_IDBA_UAT56=SIRIUS_500007460_MD34=8352=20260120-14:01:18.758262=MD_GBP/USD_140109778778268=5279=1269=1270=1.43562271=10000055=GBP/USD110=0279=1269=1270=1.43562271=50000055=GBP/USD110=100000279=1269=1270=1.43562271=100000055=GBP/USD110=500000279=1269=1270=1.43562271=300000055=GBP/USD110=1000000279=1269=1270=1.43562271=500000055=GBP/USD110=300000010=252
20260120-14:01:17.984373000 : 8=FIX.4.49=027835=X49=NTPRO_IDBA_UAT56=SIRIUS_500007460_MD34=8452=20260120-14:01:18.781262=MD_EUR/USD_140109278614268=3279=1269=1270=1.19876271=10000055=EUR/USD110=0279=1269=1270=1.19876271=50000055=EUR/USD110=100000279=1269=1270=1.19876271=100000055=EUR/USD110=50000010=201
20260120-14:01:18.038338000 : 8=FIX.4.49=044535=X49=NTPRO_IDBA_UAT56=SIRIUS_500007460_MD34=8552=20260120-14:01:18.836262=MD_EUR/USD_140109278614268=6279=1269=0270=1.14849271=10000055=EUR/USD110=0279=1269=0270=1.14849271=50000055=EUR/USD110=100000279=1269=0270=1.14849271=100000055=EUR/USD110=500000279=1269=1270=1.19873271=10000055=EUR/USD110=0279=1269=1270=1.19873271=50000055=EUR/USD110=100000279=1269=1270=1.19873271=100000055=EUR/USD110=50000010=243
20260120-14:01:18.052966000 : 8=FIX.4.49=067735=X49=NTPRO_IDBA_UAT56=SIRIUS_500007460_MD34=8652=20260120-14:01:18.860262=MD_GBP/USD_140109778778268=10279=1269=0270=1.25526271=10000055=GBP/USD110=0279=1269=0270=1.25526271=50000055=GBP/USD110=100000279=1269=0270=1.25526271=100000055=GBP/USD110=500000279=1269=0270=1.25526271=300000055=GBP/USD110=1000000279=1269=0270=1.25526271=500000055=GBP/USD110=3000000279=1269=1270=1.4356271=10000055=GBP/USD110=0279=1269=1270=1.4356271=50000055=GBP/USD110=100000279=1269=1270=1.4356271=100000055=GBP/USD110=500000279=1269=1270=1.4356271=300000055=GBP/USD110=1000000279=1269=1270=1.4356271=500000055=GBP/USD110=300000010=156
20260120-14:01:18.102240000 : 8=FIX.4.49=027835=X49=NTPRO_IDBA_UAT56=SIRIUS_500007460_MD34=8752=20260120-14:01:18.910262=MD_EUR/USD_140109278614268=3279=1269=0270=1.14848271=10000055=EUR/USD110=0279=1269=0270=1.14848271=50000055=EUR/USD110=100000279=1269=0270=1.14848271=100000055=EUR/USD110=50000010=177
20260120-14:01:18.738702000 : 8=FIX.4.49=039635=X49=NTPRO_IDBA_UAT56=SIRIUS_500007460_MD34=8852=20260120-14:01:19.571262=MD_GBP/USD_140109778778268=5279=1269=0270=1.25525271=10000055=GBP/USD110=0279=1269=0270=1.25525271=50000055=GBP/USD110=100000279=1269=0270=1.25525271=100000055=GBP/USD110=500000279=1269=0270=1.25525271=300000055=GBP/USD110=1000000279=1269=0270=1.25525271=500000055=GBP/USD110=300000010=241
20260120-14:01:18.766393000 : 8=FIX.4.49=044535=X49=NTPRO_IDBA_UAT56=SIRIUS_500007460_MD34=8952=20260120-14:01:19.599262=MD_EUR/USD_140109278614268=6279=1269=0270=1.14847271=10000055=EUR/USD110=0279=1269=0270=1.14847271=50000055=EUR/USD110=100000279=1269=0270=1.14847271=100000055=EUR/USD110=500000279=1269=1270=1.19871271=10000055=EUR/USD110=0279=1269=1270=1.19871271=50000055=EUR/USD110=100000279=1269=1270=1.19871271=100000055=EUR/USD110=50000010=242
20260120-14:01:18.800916000 : 8=FIX.4.49=027835=X49=NTPRO_IDBA_UAT56=SIRIUS_500007460_MD34=9052=20260120-14:01:19.636262=MD_EUR/USD_140109278614268=3279=1269=0270=1.14846271=10000055=EUR/USD110=0279=1269=0270=1.14846271=50000055=EUR/USD110=100000279=1269=0270=1.14846271=100000055=EUR/USD110=50000010=171
20260120-14:01:18.838400000 : 8=FIX.4.49=044535=X49=NTPRO_IDBA_UAT56=SIRIUS_500007460_MD34=9152=20260120-14:01:19.674262=MD_EUR/USD_140109278614268=6279=1269=0270=1.14848271=10000055=EUR/USD110=0279=1269=0270=1.14848271=50000055=EUR/USD110=100000279=1269=0270=1.14848271=100000055=EUR/USD110=500000279=1269=1270=1.19872271=10000055=EUR/USD110=0279=1269=1270=1.19872271=50000055=EUR/USD110=100000279=1269=1270=1.19872271=100000055=EUR/USD110=50000010=235
20260120-14:01:19.003729000 : 8=FIX.4.49=027835=X49=NTPRO_IDBA_UAT56=SIRIUS_500007460_MD34=9252=20260120-14:01:19.841262=MD_EUR/USD_140109278614268=3279=1269=1270=1.19873271=10000055=EUR/USD110=0279=1269=1270=1.19873271=50000055=EUR/USD110=100000279=1269=1270=1.19873271=100000055=EUR/USD110=50000010=189
20260120-14:01:19.044567000 : 8=FIX.4.49=044535=X49=NTPRO_IDBA_UAT56=SIRIUS_500007460_MD34=9352=20260120-14:01:19.888262=MD_EUR/USD_140109278614268=6279=1269=0270=1.14847271=10000055=EUR/USD110=0279=1269=0270=1.14847271=50000055=EUR/USD110=100000279=1269=0270=1.14847271=100000055=EUR/USD110=500000279=1269=1270=1.19872271=10000055=EUR/USD110=0279=1269=1270=1.19872271=50000055=EUR/USD110=100000279=1269=1270=1.19872271=100000055=EUR/USD110=50000010=241
20260120-14:01:19.166182000 : 8=FIX.4.49=044235=X49=NTPRO_IDBA_UAT56=SIRIUS_500007460_MD34=9452=20260120-14:01:20.014262=MD_EUR/USD_140109278614268=6279=1269=0270=1.14846271=10000055=EUR/USD110=0279=1269=0270=1.14846271=50000055=EUR/USD110=100000279=1269=0270=1.14846271=100000055=EUR/USD110=500000279=1269=1270=1.1987271=10000055=EUR/USD110=0279=1269=1270=1.1987271=50000055=EUR/USD110=100000279=1269=1270=1.1987271=100000055=EUR/USD110=50000010=059
20260120-14:01:19.176271000 : 8=FIX.4.49=068235=X49=NTPRO_IDBA_UAT56=SIRIUS_500007460_MD34=9552=20260120-14:01:20.022262=MD_GBP/USD_140109778778268=10279=1269=0270=1.25524271=10000055=GBP/USD110=0279=1269=0270=1.25524271=50000055=GBP/USD110=100000279=1269=0270=1.25524271=100000055=GBP/USD110=500000279=1269=0270=1.25524271=300000055=GBP/USD110=1000000279=1269=0270=1.25524271=500000055=GBP/USD110=3000000279=1269=1270=1.43559271=10000055=GBP/USD110=0279=1269=1270=1.43559271=50000055=GBP/USD110=100000279=1269=1270=1.43559271=100000055=GBP/USD110=500000279=1269=1270=1.43559271=300000055=GBP/USD110=1000000279=1269=1270=1.43559271=500000055=GBP/USD110=300000010=149
20260120-14:01:19.225847000 : 8=FIX.4.49=039635=X49=NTPRO_IDBA_UAT56=SIRIUS_500007460_MD34=9652=20260120-14:01:20.058262=MD_GBP/USD_140109778778268=5279=1269=1270=1.43554271=10000055=GBP/USD110=0279=1269=1270=1.43554271=50000055=GBP/USD110=100000279=1269=1270=1.43554271=100000055=GBP/USD110=500000279=1269=1270=1.43554271=300000055=GBP/USD110=1000000279=1269=1270=1.43554271=500000055=GBP/USD110=300000010=247
20260120-14:01:19.234588000 : 8=FIX.4.49=044535=X49=NTPRO_IDBA_UAT56=SIRIUS_500007460_MD34=9752=20260120-14:01:20.085262=MD_EUR/USD_140109278614268=6279=1269=0270=1.14841271=10000055=EUR/USD110=0279=1269=0270=1.14841271=50000055=EUR/USD110=100000279=1269=0270=1.14841271=100000055=EUR/USD110=500000279=1269=1270=1.19866271=10000055=EUR/USD110=0279=1269=1270=1.19866271=50000055=EUR/USD110=100000279=1269=1270=1.19866271=100000055=EUR/USD110=50000010=217
20260120-14:01:19.252641000 : 8=FIX.4.49=068235=X49=NTPRO_IDBA_UAT56=SIRIUS_500007460_MD34=9852=20260120-14:01:20.104262=MD_GBP/USD_140109778778268=10279=1269=0270=1.25522271=10000055=GBP/USD110=0279=1269=0270=1.25522271=50000055=GBP/USD110=100000279=1269=0270=1.25522271=100000055=GBP/USD110=500000279=1269=0270=1.25522271=300000055=GBP/USD110=1000000279=1269=0270=1.25522271=500000055=GBP/USD110=3000000279=1269=1270=1.43552271=10000055=GBP/USD110=0279=1269=1270=1.43552271=50000055=GBP/USD110=100000279=1269=1270=1.43552271=100000055=GBP/USD110=500000279=1269=1270=1.43552271=300000055=GBP/USD110=1000000279=1269=1270=1.43552271=500000055=GBP/USD110=300000010=108
20260120-14:01:19.299202000 : 8=FIX.4.49=039635=X49=NTPRO_IDBA_UAT56=SIRIUS_500007460_MD34=9952=20260120-14:01:20.148262=MD_GBP/USD_140109778778268=5279=1269=0270=1.25517271=10000055=GBP/USD110=0279=1269=0270=1.25517271=50000055=GBP/USD110=100000279=1269=0270=1.25517271=100000055=GBP/USD110=500000279=1269=0270=1.25517271=300000055=GBP/USD110=1000000279=1269=0270=1.25517271=500000055=GBP/USD110=300000010=240
20260120-14:01:19.307315000 : 8=FIX.4.49=027935=X49=NTPRO_IDBA_UAT56=SIRIUS_500007460_MD34=10052=20260120-14:01:20.160262=MD_EUR/USD_140109278614268=3279=1269=1270=1.19865271=10000055=EUR/USD110=0279=1269=1270=1.19865271=50000055=EUR/USD110=100000279=1269=1270=1.19865271=100000055=EUR/USD110=50000010=217
20260120-14:01:19.398583000 : 8=FIX.4.49=067835=X49=NTPRO_IDBA_UAT56=SIRIUS_500007460_MD34=10152=20260120-14:01:20.245262=MD_GBP/USD_140109778778268=10279=1269=0270=1.25516271=10000055=GBP/USD110=0279=1269=0270=1.25516271=50000055=GBP/USD110=100000279=1269=0270=1.25516271=100000055=GBP/USD110=500000279=1269=0270=1.25516271=300000055=GBP/USD110=1000000279=1269=0270=1.25516271=500000055=GBP/USD110=3000000279=1269=1270=1.4355271=10000055=GBP/USD110=0279=1269=1270=1.4355271=50000055=GBP/USD110=100000279=1269=1270=1.4355271=100000055=GBP/USD110=500000279=1269=1270=1.4355271=300000055=GBP/USD110=1000000279=1269=1270=1.4355271=500000055=GBP/USD110=300000010=173
20260120-14:01:19.421637000 : 8=FIX.4.49=044635=X49=NTPRO_IDBA_UAT56=SIRIUS_500007460_MD34=10252=20260120-14:01:20.276262=MD_EUR/USD_140109278614268=6279=1269=0270=1.14842271=10000055=EUR/USD110=0279=1269=0270=1.14842271=50000055=EUR/USD110=100000279=1269=0270=1.14842271=100000055=EUR/USD110=500000279=1269=1270=1.19866271=10000055=EUR/USD110=0279=1269=1270=1.19866271=50000055=EUR/USD110=100000279=1269=1270=1.19866271=100000055=EUR/USD110=50000010=002
20260120-14:01:19.436931000 : 8=FIX.4.49=039735=X49=NTPRO_IDBA_UAT56=SIRIUS_500007460_MD34=10352=20260120-14:01:20.295262=MD_GBP/USD_140109778778268=5279=1269=1270=1.43551271=10000055=GBP/USD110=0279=1269=1270=1.43551271=50000055=GBP/USD110=100000279=1269=1270=1.43551271=100000055=GBP/USD110=500000279=1269=1270=1.43551271=300000055=GBP/USD110=1000000279=1269=1270=1.43551271=500000055=GBP/USD110=300000010=017
20260120-14:01:19.601033000 : 8=FIX.4.49=039735=X49=NTPRO_IDBA_UAT56=SIRIUS_500007460_MD34=10452=20260120-14:01:20.451262=MD_GBP/USD_140109778778268=5279=1269=1270=1.43549271=10000055=GBP/USD110=0279=1269=1270=1.43549271=50000055=GBP/USD110=100000279=1269=1270=1.43549271=100000055=GBP/USD110=500000279=1269=1270=1.43549271=300000055=GBP/USD110=1000000279=1269=1270=1.43549271=500000055=GBP/USD110=300000010=047
20260120-14:01:19.670638000 : 8=FIX.4.49=044635=X49=NTPRO_IDBA_UAT56=SIRIUS_500007460_MD34=10552=20260120-14:01:20.526262=MD_EUR/USD_140109278614268=6279=1269=0270=1.14841271=10000055=EUR/USD110=0279=1269=0270=1.14841271=50000055=EUR/USD110=100000279=1269=0270=1.14841271=100000055=EUR/USD110=500000279=1269=1270=1.19865271=10000055=EUR/USD110=0279=1269=1270=1.19865271=50000055=EUR/USD110=100000279=1269=1270=1.19865271=100000055=EUR/USD110=50000010=253
20260120-14:01:19.703265000 : 8=FIX.4.49=027635=X49=NTPRO_IDBA_UAT56=SIRIUS_500007460_MD34=10652=20260120-14:01:20.569262=MD_EUR/USD_140109278614268=3279=1269=0270=1.1484271=10000055=EUR/USD110=0279=1269=0270=1.1484271=50000055=EUR/USD110=100000279=1269=0270=1.1484271=100000055=EUR/USD110=50000010=050
20260120-14:01:19.793360000 : 8=FIX.4.49=039235=X49=NTPRO_IDBA_UAT56=SIRIUS_500007460_MD34=10752=20260120-14:01:20.662262=MD_GBP/USD_140109778778268=5279=1269=1270=1.4355271=10000055=GBP/USD110=0279=1269=1270=1.4355271=50000055=GBP/USD110=100000279=1269=1270=1.4355271=100000055=GBP/USD110=500000279=1269=1270=1.4355271=300000055=GBP/USD110=1000000279=1269=1270=1.4355271=500000055=GBP/USD110=300000010=025
20260120-14:01:19.829248000 : 8=FIX.4.49=068335=X49=NTPRO_IDBA_UAT56=SIRIUS_500007460_MD34=10852=20260120-14:01:20.701262=MD_GBP/USD_140109778778268=10279=1269=0270=1.25515271=10000055=GBP/USD110=0279=1269=0270=1.25515271=50000055=GBP/USD110=100000279=1269=0270=1.25515271=100000055=GBP/USD110=500000279=1269=0270=1.25515271=300000055=GBP/USD110=1000000279=1269=0270=1.25515271=500000055=GBP/USD110=3000000279=1269=1270=1.43546271=10000055=GBP/USD110=0279=1269=1270=1.43546271=50000055=GBP/USD110=100000279=1269=1270=1.43546271=100000055=GBP/USD110=500000279=1269=1270=1.43546271=300000055=GBP/USD110=1000000279=1269=1270=1.43546271=500000055=GBP/USD110=300000010=177
20260120-14:01:19.856575000 : 8=FIX.4.49=039735=X49=NTPRO_IDBA_UAT56=SIRIUS_500007460_MD34=10952=20260120-14:01:20.730262=MD_GBP/USD_140109778778268=5279=1269=0270=1.25514271=10000055=GBP/USD110=0279=1269=0270=1.25514271=50000055=GBP/USD110=100000279=1269=0270=1.25514271=100000055=GBP/USD110=500000279=1269=0270=1.25514271=300000055=GBP/USD110=1000000279=1269=0270=1.25514271=500000055=GBP/USD110=300000010=007
20260120-14:01:19.878149000 : 8=FIX.4.49=027935=X49=NTPRO_IDBA_UAT56=SIRIUS_500007460_MD34=11052=20260120-14:01:20.752262=MD_EUR/USD_140109278614268=3279=1269=1270=1.19864271=10000055=EUR/USD110=0279=1269=1270=1.19864271=50000055=EUR/USD110=100000279=1269=1270=1.19864271=100000055=EUR/USD110=50000010=222
20260120-14:01:19.900288000 : 8=FIX.4.49=039735=X49=NTPRO_IDBA_UAT56=SIRIUS_500007460_MD34=11152=20260120-14:01:20.775262=MD_GBP/USD_140109778778268=5279=1269=1270=1.43545271=10000055=GBP/USD110=0279=1269=1270=1.43545271=50000055=GBP/USD110=100000279=1269=1270=1.43545271=100000055=GBP/USD110=500000279=1269=1270=1.43545271=300000055=GBP/USD110=1000000279=1269=1270=1.43545271=500000055=GBP/USD110=300000010=034
20260120-14:01:19.940561000 : 8=FIX.4.49=039735=X49=NTPRO_IDBA_UAT56=SIRIUS_500007460_MD34=11252=20260120-14:01:20.816262=MD_GBP/USD_140109778778268=5279=1269=0270=1.25511271=10000055=GBP/USD110=0279=1269=0270=1.25511271=50000055=GBP/USD110=100000279=1269=0270=1.25511271=100000055=GBP/USD110=500000279=1269=0270=1.25511271=300000055=GBP/USD110=1000000279=1269=0270=1.25511271=500000055=GBP/USD110=300000010=247
20260120-14:01:20.257624000 : 8=FIX.4.49=027935=X49=NTPRO_IDBA_UAT56=SIRIUS_500007460_MD34=11352=20260120-14:01:21.123262=MD_EUR/USD_140109278614268=3279=1269=0270=1.14839271=10000055=EUR/USD110=0279=1269=0270=1.14839271=50000055=EUR/USD110=100000279=1269=0270=1.14839271=100000055=EUR/USD110=50000010=206
20260120-14:01:20.314905000 : 8=FIX.4.49=039235=X49=NTPRO_IDBA_UAT56=SIRIUS_500007460_MD34=11452=20260120-14:01:21.187262=MD_GBP/USD_140109778778268=5279=1269=0270=1.2551271=10000055=GBP/USD110=0279=1269=0270=1.2551271=50000055=GBP/USD110=100000279=1269=0270=1.2551271=100000055=GBP/USD110=500000279=1269=0270=1.2551271=300000055=GBP/USD110=1000000279=1269=0270=1.2551271=500000055=GBP/USD110=300000010=001
20260120-14:01:20.420950000 : 8=FIX.4.49=068335=X49=NTPRO_IDBA_UAT56=SIRIUS_500007460_MD34=11552=20260120-14:01:21.314262=MD_GBP/USD_140109778778268=10279=1269=0270=1.25509271=10000055=GBP/USD110=0279=1269=0270=1.25509271=50000055=GBP/USD110=100000279=1269=0270=1.25509271=100000055=GBP/USD110=500000279=1269=0270=1.25509271=300000055=GBP/USD110=1000000279=1269=0270=1.25509271=500000055=GBP/USD110=3000000279=1269=1270=1.43544271=10000055=GBP/USD110=0279=1269=1270=1.43544271=50000055=GBP/USD110=100000279=1269=1270=1.43544271=100000055=GBP/USD110=500000279=1269=1270=1.43544271=300000055=GBP/USD110=1000000279=1269=1270=1.43544271=500000055=GBP/USD110=300000010=181
20260120-14:01:20.904205000 : 8=FIX.4.49=039235=X49=NTPRO_IDBA_UAT56=SIRIUS_500007460_MD34=11652=20260120-14:01:21.813262=MD_GBP/USD_140109778778268=5279=1269=0270=1.2551271=10000055=GBP/USD110=0279=1269=0270=1.2551271=50000055=GBP/USD110=100000279=1269=0270=1.2551271=100000055=GBP/USD110=500000279=1269=0270=1.2551271=300000055=GBP/USD110=1000000279=1269=0270=1.2551271=500000055=GBP/USD110=300000010=255
20260120-14:01:20.928156000 : 8=FIX.4.49=044635=X49=NTPRO_IDBA_UAT56=SIRIUS_500007460_MD34=11752=20260120-14:01:21.839262=MD_EUR/USD_140109278614268=6279=1269=0270=1.14841271=10000055=EUR/USD110=0279=1269=0270=1.14841271=50000055=EUR/USD110=100000279=1269=0270=1.14841271=100000055=EUR/USD110=500000279=1269=1270=1.19866271=10000055=EUR/USD110=0279=1269=1270=1.19866271=50000055=EUR/USD110=100000279=1269=1270=1.19866271=100000055=EUR/USD110=50000010=011
20260120-14:01:20.951757000 : 8=FIX.4.49=068335=X49=NTPRO_IDBA_UAT56=SIRIUS_500007460_MD34=11852=20260120-14:01:21.864262=MD_GBP/USD_140109778778268=10279=1269=0270=1.25512271=10000055=GBP/USD110=0279=1269=0270=1.25512271=50000055=GBP/USD110=100000279=1269=0270=1.25512271=100000055=GBP/USD110=500000279=1269=0270=1.25512271=300000055=GBP/USD110=1000000279=1269=0270=1.25512271=500000055=GBP/USD110=3000000279=1269=1270=1.43546271=10000055=GBP/USD110=0279=1269=1270=1.43546271=50000055=GBP/USD110=100000279=1269=1270=1.43546271=100000055=GBP/USD110=500000279=1269=1270=1.43546271=300000055=GBP/USD110=1000000279=1269=1270=1.43546271=500000055=GBP/USD110=300000010=174
20260120-14:01:21.017288000 : 8=FIX.4.49=068335=X49=NTPRO_IDBA_UAT56=SIRIUS_500007460_MD34=11952=20260120-14:01:21.932262=MD_GBP/USD_140109778778268=10279=1269=0270=1.25513271=10000055=GBP/USD110=0279=1269=0270=1.25513271=50000055=GBP/USD110=100000279=1269=0270=1.25513271=100000055=GBP/USD110=500000279=1269=0270=1.25513271=300000055=GBP/USD110=1000000279=1269=0270=1.25513271=500000055=GBP/USD110=3000000279=1269=1270=1.43548271=10000055=GBP/USD110=0279=1269=1270=1.43548271=50000055=GBP/USD110=100000279=1269=1270=1.43548271=100000055=GBP/USD110=500000279=1269=1270=1.43548271=300000055=GBP/USD110=1000000279=1269=1270=1.43548271=500000055=GBP/USD110=300000010=186
20260120-14:01:21.033573000 : 8=FIX.4.49=044635=X49=NTPRO_IDBA_UAT56=SIRIUS_500007460_MD34=12052=20260120-14:01:21.949262=MD_EUR/USD_140109278614268=6279=1269=0270=1.14843271=10000055=EUR/USD110=0279=1269=0270=1.14843271=50000055=EUR/USD110=100000279=1269=0270=1.14843271=100000055=EUR/USD110=500000279=1269=1270=1.19868271=10000055=EUR/USD110=0279=1269=1270=1.19868271=50000055=EUR/USD110=100000279=1269=1270=1.19868271=100000055=EUR/USD110=50000010=019
20260120-14:01:21.102403000 : 8=FIX.4.49=027935=X49=NTPRO_IDBA_UAT56=SIRIUS_500007460_MD34=12152=20260120-14:01:22.010262=MD_EUR/USD_140109278614268=3279=1269=0270=1.14844271=10000055=EUR/USD110=0279=1269=0270=1.14844271=50000055=EUR/USD110=100000279=1269=0270=1.14844271=100000055=EUR/USD110=50000010=189
20260120-14:01:21.103177000 : 8=FIX.4.49=039735=X49=NTPRO_IDBA_UAT56=SIRIUS_500007460_MD34=12252=20260120-14:01:22.019262=MD_GBP/USD_140109778778268=5279=1269=1270=1.43546271=10000055=GBP/USD110=0279=1269=1270=1.43546271=50000055=GBP/USD110=100000279=1269=1270=1.43546271=100000055=GBP/USD110=500000279=1269=1270=1.43546271=300000055=GBP/USD110=1000000279=1269=1270=1.43546271=500000055=GBP/USD110=300000010=034
20260120-14:01:21.205732000 : 8=FIX.4.49=027935=X49=NTPRO_IDBA_UAT56=SIRIUS_500007460_MD34=12352=20260120-14:01:22.116262=MD_EUR/USD_140109278614268=3279=1269=1270=1.19869271=10000055=EUR/USD110=0279=1269=1270=1.19869271=50000055=EUR/USD110=100000279=1269=1270=1.19869271=100000055=EUR/USD110=50000010=237
20260120-14:01:21.238413000 : 8=FIX.4.49=039735=X49=NTPRO_IDBA_UAT56=SIRIUS_500007460_MD34=12452=20260120-14:01:22.143262=MD_GBP/USD_140109778778268=5279=1269=1270=1.43547271=10000055=GBP/USD110=0279=1269=1270=1.43547271=50000055=GBP/USD110=100000279=1269=1270=1.43547271=100000055=GBP/USD110=500000279=1269=1270=1.43547271=300000055=GBP/USD110=1000000279=1269=1270=1.43547271=500000055=GBP/USD110=300000010=039
20260120-14:01:21.732597000 : 8=FIX.4.49=039735=X49=NTPRO_IDBA_UAT56=SIRIUS_500007460_MD34=12552=20260120-14:01:22.670262=MD_GBP/USD_140109778778268=5279=1269=1270=1.43546271=10000055=GBP/USD110=0279=1269=1270=1.43546271=50000055=GBP/USD110=100000279=1269=1270=1.43546271=100000055=GBP/USD110=500000279=1269=1270=1.43546271=300000055=GBP/USD110=1000000279=1269=1270=1.43546271=500000055=GBP/USD110=300000010=040
20260120-14:01:21.797096000 : 8=FIX.4.49=027935=X49=NTPRO_IDBA_UAT56=SIRIUS_500007460_MD34=12652=20260120-14:01:22.739262=MD_EUR/USD_140109278614268=3279=1269=0270=1.14845271=10000055=EUR/USD110=0279=1269=0270=1.14845271=50000055=EUR/USD110=100000279=1269=0270=1.14845271=100000055=EUR/USD110=50000010=215
20260120-14:01:21.838562000 : 8=FIX.4.49=027635=X49=NTPRO_IDBA_UAT56=SIRIUS_500007460_MD34=12752=20260120-14:01:22.780262=MD_EUR/USD_140109278614268=3279=1269=1270=1.1987271=10000055=EUR/USD110=0279=1269=1270=1.1987271=50000055=EUR/USD110=100000279=1269=1270=1.1987271=100000055=EUR/USD110=50000010=077
20260120-14:01:21.940702000 : 8=FIX.4.49=027935=X49=NTPRO_IDBA_UAT56=SIRIUS_500007460_MD34=12852=20260120-14:01:22.888262=MD_EUR/USD_140109278614268=3279=1269=1270=1.19869271=10000055=EUR/USD110=0279=1269=1270=1.19869271=50000055=EUR/USD110=100000279=1269=1270=1.19869271=100000055=EUR/USD110=50000010=002
20260120-14:01:21.999371000 : 8=FIX.4.49=044635=X49=NTPRO_IDBA_UAT56=SIRIUS_500007460_MD34=12952=20260120-14:01:22.949262=MD_EUR/USD_140109278614268=6279=1269=0270=1.14844271=10000055=EUR/USD110=0279=1269=0270=1.14844271=50000055=EUR/USD110=100000279=1269=0270=1.14844271=100000055=EUR/USD110=500000279=1269=1270=1.19868271=10000055=EUR/USD110=0279=1269=1270=1.19868271=50000055=EUR/USD110=100000279=1269=1270=1.19868271=100000055=EUR/USD110=50000010=032
20260120-14:01:22.170125000 : 8=FIX.4.49=039735=X49=NTPRO_IDBA_UAT56=SIRIUS_500007460_MD34=13052=20260120-14:01:23.115262=MD_GBP/USD_140109778778268=5279=1269=1270=1.43547271=10000055=GBP/USD110=0279=1269=1270=1.43547271=50000055=GBP/USD110=100000279=1269=1270=1.43547271=100000055=GBP/USD110=500000279=1269=1270=1.43547271=300000055=GBP/USD110=1000000279=1269=1270=1.43547271=500000055=GBP/USD110=300000010=036
20260120-14:01:22.210956000 : 8=FIX.4.49=027935=X49=NTPRO_IDBA_UAT56=SIRIUS_500007460_MD34=13152=20260120-14:01:23.166262=MD_EUR/USD_140109278614268=3279=1269=0270=1.14843271=10000055=EUR/USD110=0279=1269=0270=1.14843271=50000055=EUR/USD110=100000279=1269=0270=1.14843271=100000055=EUR/USD110=50000010=200
20260120-14:01:22.265927000 : 8=FIX.4.49=044635=X49=NTPRO_IDBA_UAT56=SIRIUS_500007460_MD34=13252=20260120-14:01:23.224262=MD_EUR/USD_140109278614268=6279=1269=0270=1.14841271=10000055=EUR/USD110=0279=1269=0270=1.14841271=50000055=EUR/USD110=100000279=1269=0270=1.14841271=100000055=EUR/USD110=500000279=1269=1270=1.19866271=10000055=EUR/USD110=0279=1269=1270=1.19866271=50000055=EUR/USD110=100000279=1269=1270=1.19866271=100000055=EUR/USD110=50000010=254
20260120-14:01:22.321774000 : 8=FIX.4.49=068335=X49=NTPRO_IDBA_UAT56=SIRIUS_500007460_MD34=13352=20260120-14:01:23.282262=MD_GBP/USD_140109778778268=10279=1269=0270=1.25512271=10000055=GBP/USD110=0279=1269=0270=1.25512271=50000055=GBP/USD110=100000279=1269=0270=1.25512271=100000055=GBP/USD110=500000279=1269=0270=1.25512271=300000055=GBP/USD110=1000000279=1269=0270=1.25512271=500000055=GBP/USD110=3000000279=1269=1270=1.43543271=10000055=GBP/USD110=0279=1269=1270=1.43543271=50000055=GBP/USD110=100000279=1269=1270=1.43543271=100000055=GBP/USD110=500000279=1269=1270=1.43543271=300000055=GBP/USD110=1000000279=1269=1270=1.43543271=500000055=GBP/USD110=300000010=152
20260120-14:01:22.339978000 : 8=FIX.4.49=044635=X49=NTPRO_IDBA_UAT56=SIRIUS_500007460_MD34=13452=20260120-14:01:23.302262=MD_EUR/USD_140109278614268=6279=1269=0270=1.14837271=10000055=EUR/USD110=0279=1269=0270=1.14837271=50000055=EUR/USD110=100000279=1269=0270=1.14837271=100000055=EUR/USD110=500000279=1269=1270=1.19861271=10000055=EUR/USD110=0279=1269=1270=1.19861271=50000055=EUR/USD110=100000279=1269=1270=1.19861271=100000055=EUR/USD110=50000010=253
20260120-14:01:22.388280000 : 8=FIX.4.49=068335=X49=NTPRO_IDBA_UAT56=SIRIUS_500007460_MD34=13552=20260120-14:01:23.345262=MD_GBP/USD_140109778778268=10279=1269=0270=1.25508271=10000055=GBP/USD110=0279=1269=0270=1.25508271=50000055=GBP/USD110=100000279=1269=0270=1.25508271=100000055=GBP/USD110=500000279=1269=0270=1.25508271=300000055=GBP/USD110=1000000279=1269=0270=1.25508271=500000055=GBP/USD110=3000000279=1269=1270=1.43542271=10000055=GBP/USD110=0279=1269=1270=1.43542271=50000055=GBP/USD110=100000279=1269=1270=1.43542271=100000055=GBP/USD110=500000279=1269=1270=1.43542271=300000055=GBP/USD110=1000000279=1269=1270=1.43542271=500000055=GBP/USD110=300000010=174
20260120-14:01:22.440778000 : 8=FIX.4.49=039735=X49=NTPRO_IDBA_UAT56=SIRIUS_500007460_MD34=13652=20260120-14:01:23.406262=MD_GBP/USD_140109778778268=5279=1269=1270=1.43543271=10000055=GBP/USD110=0279=1269=1270=1.43543271=50000055=GBP/USD110=100000279=1269=1270=1.43543271=100000055=GBP/USD110=500000279=1269=1270=1.43543271=300000055=GBP/USD110=1000000279=1269=1270=1.43543271=500000055=GBP/USD110=300000010=025
20260120-14:01:22.453495000 : 8=FIX.4.49=044635=X49=NTPRO_IDBA_UAT56=SIRIUS_500007460_MD34=13752=20260120-14:01:23.419262=MD_EUR/USD_140109278614268=6279=1269=0270=1.14838271=10000055=EUR/USD110=0279=1269=0270=1.14838271=50000055=EUR/USD110=100000279=1269=0270=1.14838271=100000055=EUR/USD110=500000279=1269=1270=1.19863271=10000055=EUR/USD110=0279=1269=1270=1.19863271=50000055=EUR/USD110=100000279=1269=1270=1.19863271=100000055=EUR/USD110=50000010=018
20260120-14:01:22.586279000 : 8=FIX.4.49=044635=X49=NTPRO_IDBA_UAT56=SIRIUS_500007460_MD34=13852=20260120-14:01:23.555262=MD_EUR/USD_140109278614268=6279=1269=0270=1.14837271=10000055=EUR/USD110=0279=1269=0270=1.14837271=50000055=EUR/USD110=100000279=1269=0270=1.14837271=100000055=EUR/USD110=500000279=1269=1270=1.19862271=10000055=EUR/USD110=0279=1269=1270=1.19862271=50000055=EUR/USD110=100000279=1269=1270=1.19862271=100000055=EUR/USD110=50000010=014
20260120-14:01:22.587060000 : 8=FIX.4.49=039735=X49=NTPRO_IDBA_UAT56=SIRIUS_500007460_MD34=13952=20260120-14:01:23.557262=MD_GBP/USD_140109778778268=5279=1269=1270=1.43542271=10000055=GBP/USD110=0279=1269=1270=1.43542271=50000055=GBP/USD110=100000279=1269=1270=1.43542271=100000055=GBP/USD110=500000279=1269=1270=1.43542271=300000055=GBP/USD110=1000000279=1269=1270=1.43542271=500000055=GBP/USD110=300000010=030
20260120-14:01:22.665789000 : 8=FIX.4.49=044335=X49=NTPRO_IDBA_UAT56=SIRIUS_500007460_MD34=14052=20260120-14:01:23.638262=MD_EUR/USD_140109278614268=6279=1269=0270=1.14836271=10000055=EUR/USD110=0279=1269=0270=1.14836271=50000055=EUR/USD110=100000279=1269=0270=1.14836271=100000055=EUR/USD110=500000279=1269=1270=1.1986271=10000055=EUR/USD110=0279=1269=1270=1.1986271=50000055=EUR/USD110=100000279=1269=1270=1.1986271=100000055=EUR/USD110=50000010=109
20260120-14:01:22.692477000 : 8=FIX.4.49=039735=X49=NTPRO_IDBA_UAT56=SIRIUS_500007460_MD34=14152=20260120-14:01:23.666262=MD_GBP/USD_140109778778268=5279=1269=0270=1.25507271=10000055=GBP/USD110=0279=1269=0270=1.25507271=50000055=GBP/USD110=100000279=1269=0270=1.25507271=100000055=GBP/USD110=500000279=1269=0270=1.25507271=300000055=GBP/USD110=1000000279=1269=0270=1.25507271=500000055=GBP/USD110=300000010=024
20260120-14:01:23.225355000 : 8=FIX.4.49=027935=X49=NTPRO_IDBA_UAT56=SIRIUS_500007460_MD34=14252=20260120-14:01:23.749262=MD_EUR/USD_140109278614268=3279=1269=0270=1.14835271=10000055=EUR/USD110=0279=1269=0270=1.14835271=50000055=EUR/USD110=100000279=1269=0270=1.14835271=100000055=EUR/USD110=50000010=212
20260120-14:01:23.951056000 : 8=FIX.4.49=039735=X49=NTPRO_IDBA_UAT56=SIRIUS_500007460_MD34=14352=20260120-14:01:23.901262=MD_GBP/USD_140109778778268=5279=1269=0270=1.25508271=10000055=GBP/USD110=0279=1269=0270=1.25508271=50000055=GBP/USD110=100000279=1269=0270=1.25508271=100000055=GBP/USD110=500000279=1269=0270=1.25508271=300000055=GBP/USD110=1000000279=1269=0270=1.25508271=500000055=GBP/USD110=300000010=023
20260120-14:01:24.078359000 : 8=FIX.4.49=039735=X49=NTPRO_IDBA_UAT56=SIRIUS_500007460_MD34=14452=20260120-14:01:24.033262=MD_GBP/USD_140109778778268=5279=1269=0270=1.25507271=10000055=GBP/USD110=0279=1269=0270=1.25507271=50000055=GBP/USD110=100000279=1269=0270=1.25507271=100000055=GBP/USD110=500000279=1269=0270=1.25507271=300000055=GBP/USD110=1000000279=1269=0270=1.25507271=500000055=GBP/USD110=300000010=016
20260120-14:01:24.358830000 : 8=FIX.4.49=044635=X49=NTPRO_IDBA_UAT56=SIRIUS_500007460_MD34=14552=20260120-14:01:24.323262=MD_EUR/USD_140109278614268=6279=1269=0270=1.14837271=10000055=EUR/USD110=0279=1269=0270=1.14837271=50000055=EUR/USD110=100000279=1269=0270=1.14837271=100000055=EUR/USD110=500000279=1269=1270=1.19861271=10000055=EUR/USD110=0279=1269=1270=1.19861271=50000055=EUR/USD110=100000279=1269=1270=1.19861271=100000055=EUR/USD110=50000010=003
20260120-14:01:24.362594000 : 8=FIX.4.49=068335=X49=NTPRO_IDBA_UAT56=SIRIUS_500007460_MD34=14652=20260120-14:01:24.325262=MD_GBP/USD_140109778778268=10279=1269=0270=1.25508271=10000055=GBP/USD110=0279=1269=0270=1.25508271=50000055=GBP/USD110=100000279=1269=0270=1.25508271=100000055=GBP/USD110=500000279=1269=0270=1.25508271=300000055=GBP/USD110=1000000279=1269=0270=1.25508271=500000055=GBP/USD110=3000000279=1269=1270=1.43543271=10000055=GBP/USD110=0279=1269=1270=1.43543271=50000055=GBP/USD110=100000279=1269=1270=1.43543271=100000055=GBP/USD110=500000279=1269=1270=1.43543271=300000055=GBP/USD110=1000000279=1269=1270=1.43543271=500000055=GBP/USD110=300000010=180
20260120-14:01:24.431505000 : 8=FIX.4.49=027935=X49=NTPRO_IDBA_UAT56=SIRIUS_500007460_MD34=14752=20260120-14:01:24.398262=MD_EUR/USD_140109278614268=3279=1269=1270=1.19862271=10000055=EUR/USD110=0279=1269=1270=1.19862271=50000055=EUR/USD110=100000279=1269=1270=1.19862271=100000055=EUR/USD110=50000010=236
20260120-14:01:24.483982000 : 8=FIX.4.49=027935=X49=NTPRO_IDBA_UAT56=SIRIUS_500007460_MD34=14852=20260120-14:01:24.450262=MD_EUR/USD_140109278614268=3279=1269=0270=1.14838271=10000055=EUR/USD110=0279=1269=0270=1.14838271=50000055=EUR/USD110=100000279=1269=0270=1.14838271=100000055=EUR/USD110=50000010=217
20260120-14:01:24.539985000 : 8=FIX.4.49=044635=X49=NTPRO_IDBA_UAT56=SIRIUS_500007460_MD34=14952=20260120-14:01:24.511262=MD_EUR/USD_140109278614268=6279=1269=0270=1.14837271=10000055=EUR/USD110=0279=1269=0270=1.14837271=50000055=EUR/USD110=100000279=1269=0270=1.14837271=100000055=EUR/USD110=500000279=1269=1270=1.19861271=10000055=EUR/USD110=0279=1269=1270=1.19861271=50000055=EUR/USD110=100000279=1269=1270=1.19861271=100000055=EUR/USD110=50000010=006
20260120-14:01:24.569050000 : 8=FIX.4.49=039735=X49=NTPRO_IDBA_UAT56=SIRIUS_500007460_MD34=15052=20260120-14:01:24.533262=MD_GBP/USD_140109778778268=5279=1269=1270=1.43542271=10000055=GBP/USD110=0279=1269=1270=1.43542271=50000055=GBP/USD110=100000279=1269=1270=1.43542271=100000055=GBP/USD110=500000279=1269=1270=1.43542271=300000055=GBP/USD110=1000000279=1269=1270=1.43542271=500000055=GBP/USD110=300000010=018
20260120-14:01:24.682726000 : 8=FIX.4.49=027935=X49=NTPRO_IDBA_UAT56=SIRIUS_500007460_MD34=15152=20260120-14:01:24.658262=MD_EUR/USD_140109278614268=3279=1269=1270=1.19862271=10000055=EUR/USD110=0279=1269=1270=1.19862271=50000055=EUR/USD110=100000279=1269=1270=1.19862271=100000055=EUR/USD110=50000010=230
20260120-14:01:24.690689000 : 8=FIX.4.49=039735=X49=NTPRO_IDBA_UAT56=SIRIUS_500007460_MD34=15252=20260120-14:01:24.660262=MD_GBP/USD_140109778778268=5279=1269=1270=1.43543271=10000055=GBP/USD110=0279=1269=1270=1.43543271=50000055=GBP/USD110=100000279=1269=1270=1.43543271=100000055=GBP/USD110=500000279=1269=1270=1.43543271=300000055=GBP/USD110=1000000279=1269=1270=1.43543271=500000055=GBP/USD110=300000010=026
20260120-14:01:24.771935000 : 8=FIX.4.49=044635=X49=NTPRO_IDBA_UAT56=SIRIUS_500007460_MD34=15352=20260120-14:01:24.749262=MD_EUR/USD_140109278614268=6279=1269=0270=1.14836271=10000055=EUR/USD110=0279=1269=0270=1.14836271=50000055=EUR/USD110=100000279=1269=0270=1.14836271=100000055=EUR/USD110=500000279=1269=1270=1.19861271=10000055=EUR/USD110=0279=1269=1270=1.19861271=50000055=EUR/USD110=100000279=1269=1270=1.19861271=100000055=EUR/USD110=50000010=011
20260120-14:01:24.816897000 : 8=FIX.4.49=068335=X49=NTPRO_IDBA_UAT56=SIRIUS_500007460_MD34=15452=20260120-14:01:24.797262=MD_GBP/USD_140109778778268=10279=1269=0270=1.25507271=10000055=GBP/USD110=0279=1269=0270=1.25507271=50000055=GBP/USD110=100000279=1269=0270=1.25507271=100000055=GBP/USD110=500000279=1269=0270=1.25507271=300000055=GBP/USD110=1000000279=1269=0270=1.25507271=500000055=GBP/USD110=3000000279=1269=1270=1.43542271=10000055=GBP/USD110=0279=1269=1270=1.43542271=50000055=GBP/USD110=100000279=1269=1270=1.43542271=100000055=GBP/USD110=500000279=1269=1270=1.43542271=300000055=GBP/USD110=1000000279=1269=1270=1.43542271=500000055=GBP/USD110=300000010=182
20260120-14:01:24.854602000 : 8=FIX.4.49=027635=X49=NTPRO_IDBA_UAT56=SIRIUS_500007460_MD34=15552=20260120-14:01:24.836262=MD_EUR/USD_140109278614268=3279=1269=1270=1.1986271=10000055=EUR/USD110=0279=1269=1270=1.1986271=50000055=EUR/USD110=100000279=1269=1270=1.1986271=100000055=EUR/USD110=50000010=079
20260120-14:01:24.921782000 : 8=FIX.4.49=044635=X49=NTPRO_IDBA_UAT56=SIRIUS_500007460_MD34=15652=20260120-14:01:24.906262=MD_EUR/USD_140109278614268=6279=1269=0270=1.14837271=10000055=EUR/USD110=0279=1269=0270=1.14837271=50000055=EUR/USD110=100000279=1269=0270=1.14837271=100000055=EUR/USD110=500000279=1269=1270=1.19861271=10000055=EUR/USD110=0279=1269=1270=1.19861271=50000055=EUR/USD110=100000279=1269=1270=1.19861271=100000055=EUR/USD110=50000010=012
20260120-14:01:24.941513000 : 8=FIX.4.49=068335=X49=NTPRO_IDBA_UAT56=SIRIUS_500007460_MD34=15752=20260120-14:01:24.925262=MD_GBP/USD_140109778778268=10279=1269=0270=1.25508271=10000055=GBP/USD110=0279=1269=0270=1.25508271=50000055=GBP/USD110=100000279=1269=0270=1.25508271=100000055=GBP/USD110=500000279=1269=0270=1.25508271=300000055=GBP/USD110=1000000279=1269=0270=1.25508271=500000055=GBP/USD110=3000000279=1269=1270=1.43543271=10000055=GBP/USD110=0279=1269=1270=1.43543271=50000055=GBP/USD110=100000279=1269=1270=1.43543271=100000055=GBP/USD110=500000279=1269=1270=1.43543271=300000055=GBP/USD110=1000000279=1269=1270=1.43543271=500000055=GBP/USD110=300000010=188
20260120-14:01:24.967256000 : 8=FIX.4.49=039735=X49=NTPRO_IDBA_UAT56=SIRIUS_500007460_MD34=15852=20260120-14:01:24.953262=MD_GBP/USD_140109778778268=5279=1269=0270=1.25507271=10000055=GBP/USD110=0279=1269=0270=1.25507271=50000055=GBP/USD110=100000279=1269=0270=1.25507271=100000055=GBP/USD110=500000279=1269=0270=1.25507271=300000055=GBP/USD110=1000000279=1269=0270=1.25507271=500000055=GBP/USD110=300000010=032
20260120-14:01:24.987004000 : 8=FIX.4.49=039735=X49=NTPRO_IDBA_UAT56=SIRIUS_500007460_MD34=15952=20260120-14:01:24.970262=MD_GBP/USD_140109778778268=5279=1269=0270=1.25508271=10000055=GBP/USD110=0279=1269=0270=1.25508271=50000055=GBP/USD110=100000279=1269=0270=1.25508271=100000055=GBP/USD110=500000279=1269=0270=1.25508271=300000055=GBP/USD110=1000000279=1269=0270=1.25508271=500000055=GBP/USD110=300000010=037
20260120-14:01:25.026339000 : 8=FIX.4.49=027935=X49=NTPRO_IDBA_UAT56=SIRIUS_500007460_MD34=16052=20260120-14:01:25.007262=MD_EUR/USD_140109278614268=3279=1269=1270=1.19862271=10000055=EUR/USD110=0279=1269=1270=1.19862271=50000055=EUR/USD110=100000279=1269=1270=1.19862271=100000055=EUR/USD110=50000010=219
20260120-14:01:25.103664000 : 8=FIX.4.49=044635=X49=NTPRO_IDBA_UAT56=SIRIUS_500007460_MD34=16152=20260120-14:01:25.094262=MD_EUR/USD_140109278614268=6279=1269=0270=1.14838271=10000055=EUR/USD110=0279=1269=0270=1.14838271=50000055=EUR/USD110=100000279=1269=0270=1.14838271=100000055=EUR/USD110=500000279=1269=1270=1.19863271=10000055=EUR/USD110=0279=1269=1270=1.19863271=50000055=EUR/USD110=100000279=1269=1270=1.19863271=100000055=EUR/USD110=50000010=016
20260120-14:01:25.149260000 : 8=FIX.4.49=039735=X49=NTPRO_IDBA_UAT56=SIRIUS_500007460_MD34=16252=20260120-14:01:25.138262=MD_GBP/USD_140109778778268=5279=1269=1270=1.43542271=10000055=GBP/USD110=0279=1269=1270=1.43542271=50000055=GBP/USD110=100000279=1269=1270=1.43542271=100000055=GBP/USD110=500000279=1269=1270=1.43542271=300000055=GBP/USD110=1000000279=1269=1270=1.43542271=500000055=GBP/USD110=300000010=023
20260120-14:01:25.179157000 : 8=FIX.4.49=044635=X49=NTPRO_IDBA_UAT56=SIRIUS_500007460_MD34=16352=20260120-14:01:25.170262=MD_EUR/USD_140109278614268=6279=1269=0270=1.14837271=10000055=EUR/USD110=0279=1269=0270=1.14837271=50000055=EUR/USD110=100000279=1269=0270=1.14837271=100000055=EUR/USD110=500000279=1269=1270=1.19862271=10000055=EUR/USD110=0279=1269=1270=1.19862271=50000055=EUR/USD110=100000279=1269=1270=1.19862271=100000055=EUR/USD110=50000010=007
20260120-14:01:25.201613000 : 8=FIX.4.49=068335=X49=NTPRO_IDBA_UAT56=SIRIUS_500007460_MD34=16452=20260120-14:01:25.190262=MD_GBP/USD_140109778778268=10279=1269=0270=1.25507271=10000055=GBP/USD110=0279=1269=0270=1.25507271=50000055=GBP/USD110=100000279=1269=0270=1.25507271=100000055=GBP/USD110=500000279=1269=0270=1.25507271=300000055=GBP/USD110=1000000279=1269=0270=1.25507271=500000055=GBP/USD110=3000000279=1269=1270=1.43541271=10000055=GBP/USD110=0279=1269=1270=1.43541271=50000055=GBP/USD110=100000279=1269=1270=1.43541271=100000055=GBP/USD110=500000279=1269=1270=1.43541271=300000055=GBP/USD110=1000000279=1269=1270=1.43541271=500000055=GBP/USD110=300000010=166
20260120-14:01:25.242929000 : 8=FIX.4.49=044335=X49=NTPRO_IDBA_UAT56=SIRIUS_500007460_MD34=16552=20260120-14:01:25.238262=MD_EUR/USD_140109278614268=6279=1269=0270=1.14836271=10000055=EUR/USD110=0279=1269=0270=1.14836271=50000055=EUR/USD110=100000279=1269=0270=1.14836271=100000055=EUR/USD110=500000279=1269=1270=1.1986271=10000055=EUR/USD110=0279=1269=1270=1.1986271=50000055=EUR/USD110=100000279=1269=1270=1.1986271=100000055=EUR/USD110=50000010=114
20260120-14:01:25.307012000 : 8=FIX.4.49=039735=X49=NTPRO_IDBA_UAT56=SIRIUS_500007460_MD34=16652=20260120-14:01:25.304262=MD_GBP/USD_140109778778268=5279=1269=0270=1.25506271=10000055=GBP/USD110=0279=1269=0270=1.25506271=50000055=GBP/USD110=100000279=1269=0270=1.25506271=100000055=GBP/USD110=500000279=1269=0270=1.25506271=300000055=GBP/USD110=1000000279=1269=0270=1.25506271=500000055=GBP/USD110=300000010=017
20260120-14:01:25.313484000 : 8=FIX.4.49=027935=X49=NTPRO_IDBA_UAT56=SIRIUS_500007460_MD34=16752=20260120-14:01:25.309262=MD_EUR/USD_140109278614268=3279=1269=0270=1.14835271=10000055=EUR/USD110=0279=1269=0270=1.14835271=50000055=EUR/USD110=100000279=1269=0270=1.14835271=100000055=EUR/USD110=50000010=213
20260120-14:01:25.395993000 : 8=FIX.4.49=044635=X49=NTPRO_IDBA_UAT56=SIRIUS_500007460_MD34=16852=20260120-14:01:25.396262=MD_EUR/USD_140109278614268=6279=1269=0270=1.14834271=10000055=EUR/USD110=0279=1269=0270=1.14834271=50000055=EUR/USD110=100000279=1269=0270=1.14834271=100000055=EUR/USD110=500000279=1269=1270=1.19859271=10000055=EUR/USD110=0279=1269=1270=1.19859271=50000055=EUR/USD110=100000279=1269=1270=1.19859271=100000055=EUR/USD110=50000010=031
20260120-14:01:25.420623000 : 8=FIX.4.49=039235=X49=NTPRO_IDBA_UAT56=SIRIUS_500007460_MD34=16952=20260120-14:01:25.420262=MD_GBP/USD_140109778778268=5279=1269=1270=1.4354271=10000055=GBP/USD110=0279=1269=1270=1.4354271=50000055=GBP/USD110=100000279=1269=1270=1.4354271=100000055=GBP/USD110=500000279=1269=1270=1.4354271=300000055=GBP/USD110=1000000279=1269=1270=1.4354271=500000055=GBP/USD110=300000010=025
20260120-14:01:25.475290000 : 8=FIX.4.49=044635=X49=NTPRO_IDBA_UAT56=SIRIUS_500007460_MD34=17052=20260120-14:01:25.477262=MD_EUR/USD_140109278614268=6279=1269=0270=1.14833271=10000055=EUR/USD110=0279=1269=0270=1.14833271=50000055=EUR/USD110=100000279=1269=0270=1.14833271=100000055=EUR/USD110=500000279=1269=1270=1.19857271=10000055=EUR/USD110=0279=1269=1270=1.19857271=50000055=EUR/USD110=100000279=1269=1270=1.19857271=100000055=EUR/USD110=50000010=015
20260120-14:01:25.852180000 : 8=FIX.4.49=027935=X49=NTPRO_IDBA_UAT56=SIRIUS_500007460_MD34=17152=20260120-14:01:25.754262=MD_EUR/USD_140109278614268=3279=1269=1270=1.19858271=10000055=EUR/USD110=0279=1269=1270=1.19858271=50000055=EUR/USD110=100000279=1269=1270=1.19858271=100000055=EUR/USD110=50000010=245
20260120-14:01:25.852795000 : 8=FIX.4.49=027935=X49=NTPRO_IDBA_UAT56=SIRIUS_500007460_MD34=17252=20260120-14:01:25.791262=MD_EUR/USD_140109278614268=3279=1269=1270=1.19857271=10000055=EUR/USD110=0279=1269=1270=1.19857271=50000055=EUR/USD110=100000279=1269=1270=1.19857271=100000055=EUR/USD110=50000010=244
20260120-14:01:25.853818000 : 8=FIX.4.49=027935=X49=NTPRO_IDBA_UAT56=SIRIUS_500007460_MD34=17352=20260120-14:01:25.828262=MD_EUR/USD_140109278614268=3279=1269=1270=1.19858271=10000055=EUR/USD110=0279=1269=1270=1.19858271=50000055=EUR/USD110=100000279=1269=1270=1.19858271=100000055=EUR/USD110=50000010=249
20260120-14:01:25.945034000 : 8=FIX.4.49=027935=X49=NTPRO_IDBA_UAT56=SIRIUS_500007460_MD34=17452=20260120-14:01:25.903262=MD_EUR/USD_140109278614268=3279=1269=1270=1.19857271=10000055=EUR/USD110=0279=1269=1270=1.19857271=50000055=EUR/USD110=100000279=1269=1270=1.19857271=100000055=EUR/USD110=50000010=241
20260120-14:01:26.037311000 : 8=FIX.4.49=027935=X49=NTPRO_IDBA_UAT56=SIRIUS_500007460_MD34=17552=20260120-14:01:25.996262=MD_EUR/USD_140109278614268=3279=1269=1270=1.19858271=10000055=EUR/USD110=0279=1269=1270=1.19858271=50000055=EUR/USD110=100000279=1269=1270=1.19858271=100000055=EUR/USD110=50000010=001
20260120-14:01:26.037718000 : 8=FIX.4.49=068335=X49=NTPRO_IDBA_UAT56=SIRIUS_500007460_MD34=17652=20260120-14:01:26.011262=MD_GBP/USD_140109778778268=10279=1269=0270=1.25505271=10000055=GBP/USD110=0279=1269=0270=1.25505271=50000055=GBP/USD110=100000279=1269=0270=1.25505271=100000055=GBP/USD110=500000279=1269=0270=1.25505271=300000055=GBP/USD110=1000000279=1269=0270=1.25505271=500000055=GBP/USD110=3000000279=1269=1270=1.43539271=10000055=GBP/USD110=0279=1269=1270=1.43539271=50000055=GBP/USD110=100000279=1269=1270=1.43539271=100000055=GBP/USD110=500000279=1269=1270=1.43539271=300000055=GBP/USD110=1000000279=1269=1270=1.43539271=500000055=GBP/USD110=300000010=187
20260120-14:01:26.038214000 : 8=FIX.4.49=044635=X49=NTPRO_IDBA_UAT56=SIRIUS_500007460_MD34=17752=20260120-14:01:26.040262=MD_EUR/USD_140109278614268=6279=1269=0270=1.14832271=10000055=EUR/USD110=0279=1269=0270=1.14832271=50000055=EUR/USD110=100000279=1269=0270=1.14832271=100000055=EUR/USD110=500000279=1269=1270=1.19857271=10000055=EUR/USD110=0279=1269=1270=1.19857271=50000055=EUR/USD110=100000279=1269=1270=1.19857271=100000055=EUR/USD110=50000010=006
20260120-14:01:26.141030000 : 8=FIX.4.49=044635=X49=NTPRO_IDBA_UAT56=SIRIUS_500007460_MD34=17852=20260120-14:01:26.095262=MD_EUR/USD_140109278614268=6279=1269=0270=1.14831271=10000055=EUR/USD110=0279=1269=0270=1.14831271=50000055=EUR/USD110=100000279=1269=0270=1.14831271=100000055=EUR/USD110=500000279=1269=1270=1.19856271=10000055=EUR/USD110=0279=1269=1270=1.19856271=50000055=EUR/USD110=100000279=1269=1270=1.19856271=100000055=EUR/USD110=50000010=011
20260120-14:01:26.142103000 : 8=FIX.4.49=068335=X49=NTPRO_IDBA_UAT56=SIRIUS_500007460_MD34=17952=20260120-14:01:26.111262=MD_GBP/USD_140109778778268=10279=1269=0270=1.25503271=10000055=GBP/USD110=0279=1269=0270=1.25503271=50000055=GBP/USD110=100000279=1269=0270=1.25503271=100000055=GBP/USD110=500000279=1269=0270=1.25503271=300000055=GBP/USD110=1000000279=1269=0270=1.25503271=500000055=GBP/USD110=3000000279=1269=1270=1.43536271=10000055=GBP/USD110=0279=1269=1270=1.43536271=50000055=GBP/USD110=100000279=1269=1270=1.43536271=100000055=GBP/USD110=500000279=1269=1270=1.43536271=300000055=GBP/USD110=1000000279=1269=1270=1.43536271=500000055=GBP/USD110=300000010=166
20260120-14:01:26.142758000 : 8=FIX.4.49=039735=X49=NTPRO_IDBA_UAT56=SIRIUS_500007460_MD34=18052=20260120-14:01:26.124262=MD_GBP/USD_140109778778268=5279=1269=1270=1.43535271=10000055=GBP/USD110=0279=1269=1270=1.43535271=50000055=GBP/USD110=100000279=1269=1270=1.43535271=100000055=GBP/USD110=500000279=1269=1270=1.43535271=300000055=GBP/USD110=1000000279=1269=1270=1.43535271=500000055=GBP/USD110=300000010=029
20260120-14:01:26.143304000 : 8=FIX.4.49=039735=X49=NTPRO_IDBA_UAT56=SIRIUS_500007460_MD34=18152=20260120-14:01:26.155262=MD_GBP/USD_140109778778268=5279=1269=0270=1.25501271=10000055=GBP/USD110=0279=1269=0270=1.25501271=50000055=GBP/USD110=100000279=1269=0270=1.25501271=100000055=GBP/USD110=500000279=1269=0270=1.25501271=300000055=GBP/USD110=1000000279=1269=0270=1.25501271=500000055=GBP/USD110=300000010=250
20260120-14:01:26.251082000 : 8=FIX.4.49=067335=X49=NTPRO_IDBA_UAT56=SIRIUS_500007460_MD34=18252=20260120-14:01:26.201262=MD_GBP/USD_140109778778268=10279=1269=0270=1.255271=10000055=GBP/USD110=0279=1269=0270=1.255271=50000055=GBP/USD110=100000279=1269=0270=1.255271=100000055=GBP/USD110=500000279=1269=0270=1.255271=300000055=GBP/USD110=1000000279=1269=0270=1.255271=500000055=GBP/USD110=3000000279=1269=1270=1.43533271=10000055=GBP/USD110=0279=1269=1270=1.43533271=50000055=GBP/USD110=100000279=1269=1270=1.43533271=100000055=GBP/USD110=500000279=1269=1270=1.43533271=300000055=GBP/USD110=1000000279=1269=1270=1.43533271=500000055=GBP/USD110=300000010=161
20260120-14:01:26.251509000 : 8=FIX.4.49=044635=X49=NTPRO_IDBA_UAT56=SIRIUS_500007460_MD34=18352=20260120-14:01:26.236262=MD_EUR/USD_140109278614268=6279=1269=0270=1.14829271=10000055=EUR/USD110=0279=1269=0270=1.14829271=50000055=EUR/USD110=100000279=1269=0270=1.14829271=100000055=EUR/USD110=500000279=1269=1270=1.19854271=10000055=EUR/USD110=0279=1269=1270=1.19854271=50000055=EUR/USD110=100000279=1269=1270=1.19854271=100000055=EUR/USD110=50000010=019
20260120-14:01:26.251986000 : 8=FIX.4.49=039735=X49=NTPRO_IDBA_UAT56=SIRIUS_500007460_MD34=18452=20260120-14:01:26.273262=MD_GBP/USD_140109778778268=5279=1269=1270=1.43532271=10000055=GBP/USD110=0279=1269=1270=1.43532271=50000055=GBP/USD110=100000279=1269=1270=1.43532271=100000055=GBP/USD110=500000279=1269=1270=1.43532271=300000055=GBP/USD110=1000000279=1269=1270=1.43532271=500000055=GBP/USD110=300000010=023
20260120-14:01:26.344916000 : 8=FIX.4.49=044635=X49=NTPRO_IDBA_UAT56=SIRIUS_500007460_MD34=18552=20260120-14:01:26.324262=MD_EUR/USD_140109278614268=6279=1269=0270=1.14828271=10000055=EUR/USD110=0279=1269=0270=1.14828271=50000055=EUR/USD110=100000279=1269=0270=1.14828271=100000055=EUR/USD110=500000279=1269=1270=1.19853271=10000055=EUR/USD110=0279=1269=1270=1.19853271=50000055=EUR/USD110=100000279=1269=1270=1.19853271=100000055=EUR/USD110=50000010=013
20260120-14:01:26.345690000 : 8=FIX.4.49=068335=X49=NTPRO_IDBA_UAT56=SIRIUS_500007460_MD34=18652=20260120-14:01:26.334262=MD_GBP/USD_140109778778268=10279=1269=0270=1.25497271=10000055=GBP/USD110=0279=1269=0270=1.25497271=50000055=GBP/USD110=100000279=1269=0270=1.25497271=100000055=GBP/USD110=500000279=1269=0270=1.25497271=300000055=GBP/USD110=1000000279=1269=0270=1.25497271=500000055=GBP/USD110=3000000279=1269=1270=1.43531271=10000055=GBP/USD110=0279=1269=1270=1.43531271=50000055=GBP/USD110=100000279=1269=1270=1.43531271=100000055=GBP/USD110=500000279=1269=1270=1.43531271=300000055=GBP/USD110=1000000279=1269=1270=1.43531271=500000055=GBP/USD110=300000010=206
20260120-14:01:26.548777000 : 8=FIX.4.49=027935=X49=NTPRO_IDBA_UAT56=SIRIUS_500007460_MD34=18752=20260120-14:01:26.588262=MD_EUR/USD_140109278614268=3279=1269=1270=1.19852271=10000055=EUR/USD110=0279=1269=1270=1.19852271=50000055=EUR/USD110=100000279=1269=1270=1.19852271=100000055=EUR/USD110=50000010=240
20260120-14:01:26.653050000 : 8=FIX.4.49=027935=X49=NTPRO_IDBA_UAT56=SIRIUS_500007460_MD34=18852=20260120-14:01:26.613262=MD_EUR/USD_140109278614268=3279=1269=0270=1.14827271=10000055=EUR/USD110=0279=1269=0270=1.14827271=50000055=EUR/USD110=100000279=1269=0270=1.14827271=100000055=EUR/USD110=50000010=218
20260120-14:01:26.748758000 : 8=FIX.4.49=044635=X49=NTPRO_IDBA_UAT56=SIRIUS_500007460_MD34=18952=20260120-14:01:26.791262=MD_EUR/USD_140109278614268=6279=1269=0270=1.14829271=10000055=EUR/USD110=0279=1269=0270=1.14829271=50000055=EUR/USD110=100000279=1269=0270=1.14829271=100000055=EUR/USD110=500000279=1269=1270=1.19855271=10000055=EUR/USD110=0279=1269=1270=1.19855271=50000055=EUR/USD110=100000279=1269=1270=1.19855271=100000055=EUR/USD110=50000010=034
20260120-14:01:26.842483000 : 8=FIX.4.49=039735=X49=NTPRO_IDBA_UAT56=SIRIUS_500007460_MD34=19052=20260120-14:01:26.866262=MD_GBP/USD_140109778778268=5279=1269=0270=1.25496271=10000055=GBP/USD110=0279=1269=0270=1.25496271=50000055=GBP/USD110=100000279=1269=0270=1.25496271=100000055=GBP/USD110=500000279=1269=0270=1.25496271=300000055=GBP/USD110=1000000279=1269=0270=1.25496271=500000055=GBP/USD110=300000010=068
20260120-14:01:27.033917000 : 8=FIX.4.49=044635=X49=NTPRO_IDBA_UAT56=SIRIUS_500007460_MD34=19152=20260120-14:01:27.034262=MD_EUR/USD_140109278614268=6279=1269=0270=1.14827271=10000055=EUR/USD110=0279=1269=0270=1.14827271=50000055=EUR/USD110=100000279=1269=0270=1.14827271=100000055=EUR/USD110=500000279=1269=1270=1.19853271=10000055=EUR/USD110=0279=1269=1270=1.19853271=50000055=EUR/USD110=100000279=1269=1270=1.19853271=100000055=EUR/USD110=50000010=006
20260120-14:01:27.035104000 : 8=FIX.4.49=067835=X49=NTPRO_IDBA_UAT56=SIRIUS_500007460_MD34=19252=20260120-14:01:27.049262=MD_GBP/USD_140109778778268=10279=1269=0270=1.25497271=10000055=GBP/USD110=0279=1269=0270=1.25497271=50000055=GBP/USD110=100000279=1269=0270=1.25497271=100000055=GBP/USD110=500000279=1269=0270=1.25497271=300000055=GBP/USD110=1000000279=1269=0270=1.25497271=500000055=GBP/USD110=3000000279=1269=1270=1.4353271=10000055=GBP/USD110=0279=1269=1270=1.4353271=50000055=GBP/USD110=100000279=1269=1270=1.4353271=100000055=GBP/USD110=500000279=1269=1270=1.4353271=300000055=GBP/USD110=1000000279=1269=1270=1.4353271=500000055=GBP/USD110=300000010=222
20260120-14:01:27.149220000 : 8=FIX.4.49=044635=X49=NTPRO_IDBA_UAT56=SIRIUS_500007460_MD34=19352=20260120-14:01:27.130262=MD_EUR/USD_140109278614268=6279=1269=0270=1.14833271=10000055=EUR/USD110=0279=1269=0270=1.14833271=50000055=EUR/USD110=100000279=1269=0270=1.14833271=100000055=EUR/USD110=500000279=1269=1270=1.19857271=10000055=EUR/USD110=0279=1269=1270=1.19857271=50000055=EUR/USD110=100000279=1269=1270=1.19857271=100000055=EUR/USD110=50000010=008
20260120-14:01:27.245552000 : 8=FIX.4.49=044335=X49=NTPRO_IDBA_UAT56=SIRIUS_500007460_MD34=19452=20260120-14:01:27.217262=MD_EUR/USD_140109278614268=6279=1269=0270=1.14835271=10000055=EUR/USD110=0279=1269=0270=1.14835271=50000055=EUR/USD110=100000279=1269=0270=1.14835271=100000055=EUR/USD110=500000279=1269=1270=1.1986271=10000055=EUR/USD110=0279=1269=1270=1.1986271=50000055=EUR/USD110=100000279=1269=1270=1.1986271=100000055=EUR/USD110=50000010=112
20260120-14:01:27.246137000 : 8=FIX.4.49=068335=X49=NTPRO_IDBA_UAT56=SIRIUS_500007460_MD34=19552=20260120-14:01:27.249262=MD_GBP/USD_140109778778268=10279=1269=0270=1.25505271=10000055=GBP/USD110=0279=1269=0270=1.25505271=50000055=GBP/USD110=100000279=1269=0270=1.25505271=100000055=GBP/USD110=500000279=1269=0270=1.25505271=300000055=GBP/USD110=1000000279=1269=0270=1.25505271=500000055=GBP/USD110=3000000279=1269=1270=1.43538271=10000055=GBP/USD110=0279=1269=1270=1.43538271=50000055=GBP/USD110=100000279=1269=1270=1.43538271=100000055=GBP/USD110=500000279=1269=1270=1.43538271=300000055=GBP/USD110=1000000279=1269=1270=1.43538271=500000055=GBP/USD110=300000010=197
20260120-14:01:27.248997000 : 8=FIX.4.49=044635=X49=NTPRO_IDBA_UAT56=SIRIUS_500007460_MD34=19652=20260120-14:01:27.314262=MD_EUR/USD_140109278614268=6279=1269=0270=1.14836271=10000055=EUR/USD110=0279=1269=0270=1.14836271=50000055=EUR/USD110=100000279=1269=0270=1.14836271=100000055=EUR/USD110=500000279=1269=1270=1.19861271=10000055=EUR/USD110=0279=1269=1270=1.19861271=50000055=EUR/USD110=100000279=1269=1270=1.19861271=100000055=EUR/USD110=50000010=009
20260120-14:01:27.309251000 : 8=FIX.4.49=039735=X49=NTPRO_IDBA_UAT56=SIRIUS_500007460_MD34=19752=20260120-14:01:27.330262=MD_GBP/USD_140109778778268=5279=1269=0270=1.25506271=10000055=GBP/USD110=0279=1269=0270=1.25506271=50000055=GBP/USD110=100000279=1269=0270=1.25506271=100000055=GBP/USD110=500000279=1269=0270=1.25506271=300000055=GBP/USD110=1000000279=1269=0270=1.25506271=500000055=GBP/USD110=300000010=022
20260120-14:01:27.309871000 : 8=FIX.4.49=039235=X49=NTPRO_IDBA_UAT56=SIRIUS_500007460_MD34=19852=20260120-14:01:27.375262=MD_GBP/USD_140109778778268=5279=1269=1270=1.4354271=10000055=GBP/USD110=0279=1269=1270=1.4354271=50000055=GBP/USD110=100000279=1269=1270=1.4354271=100000055=GBP/USD110=500000279=1269=1270=1.4354271=300000055=GBP/USD110=1000000279=1269=1270=1.4354271=500000055=GBP/USD110=300000010=038
20260120-14:01:27.336056000 : 8=FIX.4.49=044635=X49=NTPRO_IDBA_UAT56=SIRIUS_500007460_MD34=19952=20260120-14:01:27.399262=MD_EUR/USD_140109278614268=6279=1269=0270=1.14838271=10000055=EUR/USD110=0279=1269=0270=1.14838271=50000055=EUR/USD110=100000279=1269=0270=1.14838271=100000055=EUR/USD110=500000279=1269=1270=1.19863271=10000055=EUR/USD110=0279=1269=1270=1.19863271=50000055=EUR/USD110=100000279=1269=1270=1.19863271=100000055=EUR/USD110=50000010=037
20260120-14:01:27.377132000 : 8=FIX.4.49=068335=X49=NTPRO_IDBA_UAT56=SIRIUS_500007460_MD34=20052=20260120-14:01:27.428262=MD_GBP/USD_140109778778268=10279=1269=0270=1.25507271=10000055=GBP/USD110=0279=1269=0270=1.25507271=50000055=GBP/USD110=100000279=1269=0270=1.25507271=100000055=GBP/USD110=500000279=1269=0270=1.25507271=300000055=GBP/USD110=1000000279=1269=0270=1.25507271=500000055=GBP/USD110=3000000279=1269=1270=1.43542271=10000055=GBP/USD110=0279=1269=1270=1.43542271=50000055=GBP/USD110=100000279=1269=1270=1.43542271=100000055=GBP/USD110=500000279=1269=1270=1.43542271=300000055=GBP/USD110=1000000279=1269=1270=1.43542271=500000055=GBP/USD110=300000010=168
20260120-14:01:27.433555000 : 8=FIX.4.49=027935=X49=NTPRO_IDBA_UAT56=SIRIUS_500007460_MD34=20152=20260120-14:01:27.475262=MD_EUR/USD_140109278614268=3279=1269=1270=1.19862271=10000055=EUR/USD110=0279=1269=1270=1.19862271=50000055=EUR/USD110=100000279=1269=1270=1.19862271=100000055=EUR/USD110=50000010=226
20260120-14:01:27.478338000 : 8=FIX.4.49=027935=X49=NTPRO_IDBA_UAT56=SIRIUS_500007460_MD34=20252=20260120-14:01:27.550262=MD_EUR/USD_140109278614268=3279=1269=0270=1.14837271=10000055=EUR/USD110=0279=1269=0270=1.14837271=50000055=EUR/USD110=100000279=1269=0270=1.14837271=100000055=EUR/USD110=50000010=209
20260120-14:01:27.512057000 : 8=FIX.4.49=067835=X49=NTPRO_IDBA_UAT56=SIRIUS_500007460_MD34=20352=20260120-14:01:27.587262=MD_GBP/USD_140109778778268=10279=1269=0270=1.25506271=10000055=GBP/USD110=0279=1269=0270=1.25506271=50000055=GBP/USD110=100000279=1269=0270=1.25506271=100000055=GBP/USD110=500000279=1269=0270=1.25506271=300000055=GBP/USD110=1000000279=1269=0270=1.25506271=500000055=GBP/USD110=3000000279=1269=1270=1.4354271=10000055=GBP/USD110=0279=1269=1270=1.4354271=50000055=GBP/USD110=100000279=1269=1270=1.4354271=100000055=GBP/USD110=500000279=1269=1270=1.4354271=300000055=GBP/USD110=1000000279=1269=1270=1.4354271=500000055=GBP/USD110=300000010=182
20260120-14:01:27.679953000 : 8=FIX.4.49=068335=X49=NTPRO_IDBA_UAT56=SIRIUS_500007460_MD34=20452=20260120-14:01:27.761262=MD_GBP/USD_140109778778268=10279=1269=0270=1.25507271=10000055=GBP/USD110=0279=1269=0270=1.25507271=50000055=GBP/USD110=100000279=1269=0270=1.25507271=100000055=GBP/USD110=500000279=1269=0270=1.25507271=300000055=GBP/USD110=1000000279=1269=0270=1.25507271=500000055=GBP/USD110=3000000279=1269=1270=1.43541271=10000055=GBP/USD110=0279=1269=1270=1.43541271=50000055=GBP/USD110=100000279=1269=1270=1.43541271=100000055=GBP/USD110=500000279=1269=1270=1.43541271=300000055=GBP/USD110=1000000279=1269=1270=1.43541271=500000055=GBP/USD110=300000010=167
20260120-14:01:27.732540000 : 8=FIX.4.49=027935=X49=NTPRO_IDBA_UAT56=SIRIUS_500007460_MD34=20552=20260120-14:01:27.812262=MD_EUR/USD_140109278614268=3279=1269=0270=1.14838271=10000055=EUR/USD110=0279=1269=0270=1.14838271=50000055=EUR/USD110=100000279=1269=0270=1.14838271=100000055=EUR/USD110=50000010=216
20260120-14:01:27.772215000 : 8=FIX.4.49=027935=X49=NTPRO_IDBA_UAT56=SIRIUS_500007460_MD34=20652=20260120-14:01:27.837262=MD_EUR/USD_140109278614268=3279=1269=0270=1.14837271=10000055=EUR/USD110=0279=1269=0270=1.14837271=50000055=EUR/USD110=100000279=1269=0270=1.14837271=100000055=EUR/USD110=50000010=221
20260120-14:01:27.800033000 : 8=FIX.4.49=039735=X49=NTPRO_IDBA_UAT56=SIRIUS_500007460_MD34=20752=20260120-14:01:27.882262=MD_GBP/USD_140109778778268=5279=1269=0270=1.25506271=10000055=GBP/USD110=0279=1269=0270=1.25506271=50000055=GBP/USD110=100000279=1269=0270=1.25506271=100000055=GBP/USD110=500000279=1269=0270=1.25506271=300000055=GBP/USD110=1000000279=1269=0270=1.25506271=500000055=GBP/USD110=300000010=026
20260120-14:01:27.839696000 : 8=FIX.4.49=027935=X49=NTPRO_IDBA_UAT56=SIRIUS_500007460_MD34=20852=20260120-14:01:27.926262=MD_EUR/USD_140109278614268=3279=1269=0270=1.14838271=10000055=EUR/USD110=0279=1269=0270=1.14838271=50000055=EUR/USD110=100000279=1269=0270=1.14838271=100000055=EUR/USD110=50000010=225
20260120-14:01:27.872139000 : 8=FIX.4.49=027935=X49=NTPRO_IDBA_UAT56=SIRIUS_500007460_MD34=20952=20260120-14:01:27.955262=MD_EUR/USD_140109278614268=3279=1269=0270=1.14837271=10000055=EUR/USD110=0279=1269=0270=1.14837271=50000055=EUR/USD110=100000279=1269=0270=1.14837271=100000055=EUR/USD110=50000010=225
20260120-14:01:27.919882000 : 8=FIX.4.49=044335=X49=NTPRO_IDBA_UAT56=SIRIUS_500007460_MD34=21052=20260120-14:01:28.007262=MD_EUR/USD_140109278614268=6279=1269=0270=1.14835271=10000055=EUR/USD110=0279=1269=0270=1.14835271=50000055=EUR/USD110=100000279=1269=0270=1.14835271=100000055=EUR/USD110=500000279=1269=1270=1.1986271=10000055=EUR/USD110=0279=1269=1270=1.1986271=50000055=EUR/USD110=100000279=1269=1270=1.1986271=100000055=EUR/USD110=50000010=099
20260120-14:01:27.937314000 : 8=FIX.4.49=039235=X49=NTPRO_IDBA_UAT56=SIRIUS_500007460_MD34=21152=20260120-14:01:28.027262=MD_GBP/USD_140109778778268=5279=1269=1270=1.4354271=10000055=GBP/USD110=0279=1269=1270=1.4354271=50000055=GBP/USD110=100000279=1269=1270=1.4354271=100000055=GBP/USD110=500000279=1269=1270=1.4354271=300000055=GBP/USD110=1000000279=1269=1270=1.4354271=500000055=GBP/USD110=300000010=019
20260120-14:01:28.003203000 : 8=FIX.4.49=068335=X49=NTPRO_IDBA_UAT56=SIRIUS_500007460_MD34=21252=20260120-14:01:28.081262=MD_GBP/USD_140109778778268=10279=1269=0270=1.25505271=10000055=GBP/USD110=0279=1269=0270=1.25505271=50000055=GBP/USD110=100000279=1269=0270=1.25505271=100000055=GBP/USD110=500000279=1269=0270=1.25505271=300000055=GBP/USD110=1000000279=1269=0270=1.25505271=500000055=GBP/USD110=3000000279=1269=1270=1.43539271=10000055=GBP/USD110=0279=1269=1270=1.43539271=50000055=GBP/USD110=100000279=1269=1270=1.43539271=100000055=GBP/USD110=500000279=1269=1270=1.43539271=300000055=GBP/USD110=1000000279=1269=1270=1.43539271=500000055=GBP/USD110=300000010=187
20260120-14:01:28.271675000 : 8=FIX.4.49=027935=X49=NTPRO_IDBA_UAT56=SIRIUS_500007460_MD34=21352=20260120-14:01:28.336262=MD_EUR/USD_140109278614268=3279=1269=1270=1.19859271=10000055=EUR/USD110=0279=1269=1270=1.19859271=50000055=EUR/USD110=100000279=1269=1270=1.19859271=100000055=EUR/USD110=50000010=244
20260120-14:01:28.402750000 : 8=FIX.4.49=027635=X49=NTPRO_IDBA_UAT56=SIRIUS_500007460_MD34=21452=20260120-14:01:28.508262=MD_EUR/USD_140109278614268=3279=1269=1270=1.1986271=10000055=EUR/USD110=0279=1269=1270=1.1986271=50000055=EUR/USD110=100000279=1269=1270=1.1986271=100000055=EUR/USD110=50000010=075
20260120-14:01:28.657012000 : 8=FIX.4.49=039735=X49=NTPRO_IDBA_UAT56=SIRIUS_500007460_MD34=21552=20260120-14:01:28.764262=MD_GBP/USD_140109778778268=5279=1269=0270=1.25504271=10000055=GBP/USD110=0279=1269=0270=1.25504271=50000055=GBP/USD110=100000279=1269=0270=1.25504271=100000055=GBP/USD110=500000279=1269=0270=1.25504271=300000055=GBP/USD110=1000000279=1269=0270=1.25504271=500000055=GBP/USD110=300000010=015
20260120-14:01:28.680548000 : 8=FIX.4.49=027935=X49=NTPRO_IDBA_UAT56=SIRIUS_500007460_MD34=21652=20260120-14:01:28.796262=MD_EUR/USD_140109278614268=3279=1269=1270=1.19859271=10000055=EUR/USD110=0279=1269=1270=1.19859271=50000055=EUR/USD110=100000279=1269=1270=1.19859271=100000055=EUR/USD110=50000010=001
20260120-14:01:28.700215000 : 8=FIX.4.49=068335=X49=NTPRO_IDBA_UAT56=SIRIUS_500007460_MD34=21752=20260120-14:01:28.816262=MD_GBP/USD_140109778778268=10279=1269=0270=1.25503271=10000055=GBP/USD110=0279=1269=0270=1.25503271=50000055=GBP/USD110=100000279=1269=0270=1.25503271=100000055=GBP/USD110=500000279=1269=0270=1.25503271=300000055=GBP/USD110=1000000279=1269=0270=1.25503271=500000055=GBP/USD110=3000000279=1269=1270=1.43535271=10000055=GBP/USD110=0279=1269=1270=1.43535271=50000055=GBP/USD110=100000279=1269=1270=1.43535271=100000055=GBP/USD110=500000279=1269=1270=1.43535271=300000055=GBP/USD110=1000000279=1269=1270=1.43535271=500000055=GBP/USD110=300000010=168
20260120-14:01:28.761786000 : 8=FIX.4.49=039735=X49=NTPRO_IDBA_UAT56=SIRIUS_500007460_MD34=21852=20260120-14:01:28.867262=MD_GBP/USD_140109778778268=5279=1269=1270=1.43534271=10000055=GBP/USD110=0279=1269=1270=1.43534271=50000055=GBP/USD110=100000279=1269=1270=1.43534271=100000055=GBP/USD110=500000279=1269=1270=1.43534271=300000055=GBP/USD110=1000000279=1269=1270=1.43534271=500000055=GBP/USD110=300000010=042
20260120-14:01:28.762649000 : 8=FIX.4.49=044635=X49=NTPRO_IDBA_UAT56=SIRIUS_500007460_MD34=21952=20260120-14:01:28.867262=MD_EUR/USD_140109278614268=6279=1269=0270=1.14832271=10000055=EUR/USD110=0279=1269=0270=1.14832271=50000055=EUR/USD110=100000279=1269=0270=1.14832271=100000055=EUR/USD110=500000279=1269=1270=1.19857271=10000055=EUR/USD110=0279=1269=1270=1.19857271=50000055=EUR/USD110=100000279=1269=1270=1.19857271=100000055=EUR/USD110=50000010=022
20260120-14:01:28.784953000 : 8=FIX.4.49=068335=X49=NTPRO_IDBA_UAT56=SIRIUS_500007460_MD34=22052=20260120-14:01:28.902262=MD_GBP/USD_140109778778268=10279=1269=0270=1.25502271=10000055=GBP/USD110=0279=1269=0270=1.25502271=50000055=GBP/USD110=100000279=1269=0270=1.25502271=100000055=GBP/USD110=500000279=1269=0270=1.25502271=300000055=GBP/USD110=1000000279=1269=0270=1.25502271=500000055=GBP/USD110=3000000279=1269=1270=1.43536271=10000055=GBP/USD110=0279=1269=1270=1.43536271=50000055=GBP/USD110=100000279=1269=1270=1.43536271=100000055=GBP/USD110=500000279=1269=1270=1.43536271=300000055=GBP/USD110=1000000279=1269=1270=1.43536271=500000055=GBP/USD110=300000010=158
20260120-14:01:28.803114000 : 8=FIX.4.49=027935=X49=NTPRO_IDBA_UAT56=SIRIUS_500007460_MD34=22152=20260120-14:01:28.924262=MD_EUR/USD_140109278614268=3279=1269=0270=1.14833271=10000055=EUR/USD110=0279=1269=0270=1.14833271=50000055=EUR/USD110=100000279=1269=0270=1.14833271=100000055=EUR/USD110=50000010=204
20260120-14:01:28.832500000 : 8=FIX.4.49=039735=X49=NTPRO_IDBA_UAT56=SIRIUS_500007460_MD34=22252=20260120-14:01:28.953262=MD_GBP/USD_140109778778268=5279=1269=1270=1.43537271=10000055=GBP/USD110=0279=1269=1270=1.43537271=50000055=GBP/USD110=100000279=1269=1270=1.43537271=100000055=GBP/USD110=500000279=1269=1270=1.43537271=300000055=GBP/USD110=1000000279=1269=1270=1.43537271=500000055=GBP/USD110=300000010=048
20260120-14:01:28.913501000 : 8=FIX.4.49=027935=X49=NTPRO_IDBA_UAT56=SIRIUS_500007460_MD34=22352=20260120-14:01:29.015262=MD_EUR/USD_140109278614268=3279=1269=1270=1.19858271=10000055=EUR/USD110=0279=1269=1270=1.19858271=50000055=EUR/USD110=100000279=1269=1270=1.19858271=100000055=EUR/USD110=50000010=237
20260120-14:01:28.959887000 : 8=FIX.4.49=027935=X49=NTPRO_IDBA_UAT56=SIRIUS_500007460_MD34=22452=20260120-14:01:29.084262=MD_EUR/USD_140109278614268=3279=1269=0270=1.14834271=10000055=EUR/USD110=0279=1269=0270=1.14834271=50000055=EUR/USD110=100000279=1269=0270=1.14834271=100000055=EUR/USD110=50000010=208
20260120-14:01:29.013506000 : 8=FIX.4.49=039735=X49=NTPRO_IDBA_UAT56=SIRIUS_500007460_MD34=22552=20260120-14:01:29.141262=MD_GBP/USD_140109778778268=5279=1269=1270=1.43536271=10000055=GBP/USD110=0279=1269=1270=1.43536271=50000055=GBP/USD110=100000279=1269=1270=1.43536271=100000055=GBP/USD110=500000279=1269=1270=1.43536271=300000055=GBP/USD110=1000000279=1269=1270=1.43536271=500000055=GBP/USD110=300000010=036
20260120-14:01:29.067812000 : 8=FIX.4.49=044635=X49=NTPRO_IDBA_UAT56=SIRIUS_500007460_MD34=22652=20260120-14:01:29.197262=MD_EUR/USD_140109278614268=6279=1269=0270=1.14832271=10000055=EUR/USD110=0279=1269=0270=1.14832271=50000055=EUR/USD110=100000279=1269=0270=1.14832271=100000055=EUR/USD110=500000279=1269=1270=1.19857271=10000055=EUR/USD110=0279=1269=1270=1.19857271=50000055=EUR/USD110=100000279=1269=1270=1.19857271=100000055=EUR/USD110=50000010=017
20260120-14:01:29.195498000 : 8=FIX.4.49=027935=X49=NTPRO_IDBA_UAT56=SIRIUS_500007460_MD34=22752=20260120-14:01:29.330262=MD_EUR/USD_140109278614268=3279=1269=1270=1.19856271=10000055=EUR/USD110=0279=1269=1270=1.19856271=50000055=EUR/USD110=100000279=1269=1270=1.19856271=100000055=EUR/USD110=50000010=235
20260120-14:01:29.287479000 : 8=FIX.4.49=027935=X49=NTPRO_IDBA_UAT56=SIRIUS_500007460_MD34=22852=20260120-14:01:29.425262=MD_EUR/USD_140109278614268=3279=1269=0270=1.14831271=10000055=EUR/USD110=0279=1269=0270=1.14831271=50000055=EUR/USD110=100000279=1269=0270=1.14831271=100000055=EUR/USD110=50000010=202
20260120-14:01:29.727209000 : 8=FIX.4.49=027935=X49=NTPRO_IDBA_UAT56=SIRIUS_500007460_MD34=22952=20260120-14:01:29.880262=MD_EUR/USD_140109278614268=3279=1269=0270=1.14832271=10000055=EUR/USD110=0279=1269=0270=1.14832271=50000055=EUR/USD110=100000279=1269=0270=1.14832271=100000055=EUR/USD110=50000010=211
20260120-14:01:29.789984000 : 8=FIX.4.49=027935=X49=NTPRO_IDBA_UAT56=SIRIUS_500007460_MD34=23052=20260120-14:01:29.945262=MD_EUR/USD_140109278614268=3279=1269=1270=1.19857271=10000055=EUR/USD110=0279=1269=1270=1.19857271=50000055=EUR/USD110=100000279=1269=1270=1.19857271=100000055=EUR/USD110=50000010=244
20260120-14:01:29.850062000 : 8=FIX.4.49=044635=X49=NTPRO_IDBA_UAT56=SIRIUS_500007460_MD34=23152=20260120-14:01:29.995262=MD_EUR/USD_140109278614268=6279=1269=0270=1.14831271=10000055=EUR/USD110=0279=1269=0270=1.14831271=50000055=EUR/USD110=100000279=1269=0270=1.14831271=100000055=EUR/USD110=500000279=1269=1270=1.19856271=10000055=EUR/USD110=0279=1269=1270=1.19856271=50000055=EUR/USD110=100000279=1269=1270=1.19856271=100000055=EUR/USD110=50000010=013
20260120-14:01:29.925967000 : 8=FIX.4.49=068335=X49=NTPRO_IDBA_UAT56=SIRIUS_500007460_MD34=23252=20260120-14:01:30.078262=MD_GBP/USD_140109778778268=10279=1269=0270=1.25503271=10000055=GBP/USD110=0279=1269=0270=1.25503271=50000055=GBP/USD110=100000279=1269=0270=1.25503271=100000055=GBP/USD110=500000279=1269=0270=1.25503271=300000055=GBP/USD110=1000000279=1269=0270=1.25503271=500000055=GBP/USD110=3000000279=1269=1270=1.43537271=10000055=GBP/USD110=0279=1269=1270=1.43537271=50000055=GBP/USD110=100000279=1269=1270=1.43537271=100000055=GBP/USD110=500000279=1269=1270=1.43537271=300000055=GBP/USD110=1000000279=1269=1270=1.43537271=500000055=GBP/USD110=300000010=168
20260120-14:01:29.963946000 : 8=FIX.4.49=027935=X49=NTPRO_IDBA_UAT56=SIRIUS_500007460_MD34=23352=20260120-14:01:30.125262=MD_EUR/USD_140109278614268=3279=1269=0270=1.14832271=10000055=EUR/USD110=0279=1269=0270=1.14832271=50000055=EUR/USD110=100000279=1269=0270=1.14832271=100000055=EUR/USD110=50000010=190
20260120-14:01:30.017951000 : 8=FIX.4.49=027935=X49=NTPRO_IDBA_UAT56=SIRIUS_500007460_MD34=23452=20260120-14:01:30.181262=MD_EUR/USD_140109278614268=3279=1269=1270=1.19857271=10000055=EUR/USD110=0279=1269=1270=1.19857271=50000055=EUR/USD110=100000279=1269=1270=1.19857271=100000055=EUR/USD110=50000010=232
20260120-14:01:30.323074000 : 8=FIX.4.49=044635=X49=NTPRO_IDBA_UAT56=SIRIUS_500007460_MD34=23552=20260120-14:01:30.494262=MD_EUR/USD_140109278614268=6279=1269=0270=1.14831271=10000055=EUR/USD110=0279=1269=0270=1.14831271=50000055=EUR/USD110=100000279=1269=0270=1.14831271=100000055=EUR/USD110=500000279=1269=1270=1.19856271=10000055=EUR/USD110=0279=1269=1270=1.19856271=50000055=EUR/USD110=100000279=1269=1270=1.19856271=100000055=EUR/USD110=50000010=003
20260120-14:01:30.603011000 : 8=FIX.4.49=007835=049=NTPRO_IDBA_UAT56=SIRIUS_500007460_MD34=23652=20260120-14:01:30.78810=225
20260120-14:01:30.736389000 : 8=FIX.4.49=039735=X49=NTPRO_IDBA_UAT56=SIRIUS_500007460_MD34=23752=20260120-14:01:30.924262=MD_GBP/USD_140109778778268=5279=1269=1270=1.43536271=10000055=GBP/USD110=0279=1269=1270=1.43536271=50000055=GBP/USD110=100000279=1269=1270=1.43536271=100000055=GBP/USD110=500000279=1269=1270=1.43536271=300000055=GBP/USD110=1000000279=1269=1270=1.43536271=500000055=GBP/USD110=300000010=040
20260120-14:01:30.838497000 : 8=FIX.4.49=027935=X49=NTPRO_IDBA_UAT56=SIRIUS_500007460_MD34=23852=20260120-14:01:31.029262=MD_EUR/USD_140109278614268=3279=1269=0270=1.14832271=10000055=EUR/USD110=0279=1269=0270=1.14832271=50000055=EUR/USD110=100000279=1269=0270=1.14832271=100000055=EUR/USD110=50000010=199
20260120-14:01:31.118687000 : 8=FIX.4.49=039735=X49=NTPRO_IDBA_UAT56=SIRIUS_500007460_MD34=23952=20260120-14:01:31.321262=MD_GBP/USD_140109778778268=5279=1269=1270=1.43537271=10000055=GBP/USD110=0279=1269=1270=1.43537271=50000055=GBP/USD110=100000279=1269=1270=1.43537271=100000055=GBP/USD110=500000279=1269=1270=1.43537271=300000055=GBP/USD110=1000000279=1269=1270=1.43537271=500000055=GBP/USD110=300000010=039
20260120-14:01:31.157900000 : 8=FIX.4.49=027935=X49=NTPRO_IDBA_UAT56=SIRIUS_500007460_MD34=24052=20260120-14:01:31.363262=MD_EUR/USD_140109278614268=3279=1269=0270=1.14831271=10000055=EUR/USD110=0279=1269=0270=1.14831271=50000055=EUR/USD110=100000279=1269=0270=1.14831271=100000055=EUR/USD110=50000010=190
20260120-14:01:31.232892000 : 8=FIX.4.49=068335=X49=NTPRO_IDBA_UAT56=SIRIUS_500007460_MD34=24152=20260120-14:01:31.412262=MD_GBP/USD_140109778778268=10279=1269=0270=1.25504271=10000055=GBP/USD110=0279=1269=0270=1.25504271=50000055=GBP/USD110=100000279=1269=0270=1.25504271=100000055=GBP/USD110=500000279=1269=0270=1.25504271=300000055=GBP/USD110=1000000279=1269=0270=1.25504271=500000055=GBP/USD110=3000000279=1269=1270=1.43539271=10000055=GBP/USD110=0279=1269=1270=1.43539271=50000055=GBP/USD110=100000279=1269=1270=1.43539271=100000055=GBP/USD110=500000279=1269=1270=1.43539271=300000055=GBP/USD110=1000000279=1269=1270=1.43539271=500000055=GBP/USD110=300000010=176
20260120-14:01:31.234308000 : 8=FIX.4.49=044635=X49=NTPRO_IDBA_UAT56=SIRIUS_500007460_MD34=24252=20260120-14:01:31.443262=MD_EUR/USD_140109278614268=6279=1269=0270=1.14832271=10000055=EUR/USD110=0279=1269=0270=1.14832271=50000055=EUR/USD110=100000279=1269=0270=1.14832271=100000055=EUR/USD110=500000279=1269=1270=1.19857271=10000055=EUR/USD110=0279=1269=1270=1.19857271=50000055=EUR/USD110=100000279=1269=1270=1.19857271=100000055=EUR/USD110=50000010=002
20260120-14:01:31.272740000 : 8=FIX.4.49=044635=X49=NTPRO_IDBA_UAT56=SIRIUS_500007460_MD34=24352=20260120-14:01:31.480262=MD_EUR/USD_140109278614268=6279=1269=0270=1.14833271=10000055=EUR/USD110=0279=1269=0270=1.14833271=50000055=EUR/USD110=100000279=1269=0270=1.14833271=100000055=EUR/USD110=500000279=1269=1270=1.19858271=10000055=EUR/USD110=0279=1269=1270=1.19858271=50000055=EUR/USD110=100000279=1269=1270=1.19858271=100000055=EUR/USD110=50000010=010
20260120-14:01:31.498879000 : 8=FIX.4.49=027935=X49=NTPRO_IDBA_UAT56=SIRIUS_500007460_MD34=24452=20260120-14:01:31.717262=MD_EUR/USD_140109278614268=3279=1269=1270=1.19857271=10000055=EUR/USD110=0279=1269=1270=1.19857271=50000055=EUR/USD110=100000279=1269=1270=1.19857271=100000055=EUR/USD110=50000010=239
20260120-14:01:31.985333000 : 8=FIX.4.49=027935=X49=NTPRO_IDBA_UAT56=SIRIUS_500007460_MD34=24552=20260120-14:01:32.222262=MD_EUR/USD_140109278614268=3279=1269=0270=1.14832271=10000055=EUR/USD110=0279=1269=0270=1.14832271=50000055=EUR/USD110=100000279=1269=0270=1.14832271=100000055=EUR/USD110=50000010=193
20260120-14:01:32.019204000 : 8=FIX.4.49=044635=X49=NTPRO_IDBA_UAT56=SIRIUS_500007460_MD34=24652=20260120-14:01:32.255262=MD_EUR/USD_140109278614268=6279=1269=0270=1.14833271=10000055=EUR/USD110=0279=1269=0270=1.14833271=50000055=EUR/USD110=100000279=1269=0270=1.14833271=100000055=EUR/USD110=500000279=1269=1270=1.19858271=10000055=EUR/USD110=0279=1269=1270=1.19858271=50000055=EUR/USD110=100000279=1269=1270=1.19858271=100000055=EUR/USD110=50000010=014
20260120-14:01:32.069066000 : 8=FIX.4.49=067835=X49=NTPRO_IDBA_UAT56=SIRIUS_500007460_MD34=24752=20260120-14:01:32.307262=MD_GBP/USD_140109778778268=10279=1269=0270=1.25505271=10000055=GBP/USD110=0279=1269=0270=1.25505271=50000055=GBP/USD110=100000279=1269=0270=1.25505271=100000055=GBP/USD110=500000279=1269=0270=1.25505271=300000055=GBP/USD110=1000000279=1269=0270=1.25505271=500000055=GBP/USD110=3000000279=1269=1270=1.4354271=10000055=GBP/USD110=0279=1269=1270=1.4354271=50000055=GBP/USD110=100000279=1269=1270=1.4354271=100000055=GBP/USD110=500000279=1269=1270=1.4354271=300000055=GBP/USD110=1000000279=1269=1270=1.4354271=500000055=GBP/USD110=300000010=171
20260120-14:01:32.105077000 : 8=FIX.4.49=044335=X49=NTPRO_IDBA_UAT56=SIRIUS_500007460_MD34=24852=20260120-14:01:32.333262=MD_EUR/USD_140109278614268=6279=1269=0270=1.14834271=10000055=EUR/USD110=0279=1269=0270=1.14834271=50000055=EUR/USD110=100000279=1269=0270=1.14834271=100000055=EUR/USD110=500000279=1269=1270=1.1986271=10000055=EUR/USD110=0279=1269=1270=1.1986271=50000055=EUR/USD110=100000279=1269=1270=1.1986271=100000055=EUR/USD110=50000010=104
20260120-14:01:32.145048000 : 8=FIX.4.49=039735=X49=NTPRO_IDBA_UAT56=SIRIUS_500007460_MD34=24952=20260120-14:01:32.387262=MD_GBP/USD_140109778778268=5279=1269=0270=1.25506271=10000055=GBP/USD110=0279=1269=0270=1.25506271=50000055=GBP/USD110=100000279=1269=0270=1.25506271=100000055=GBP/USD110=500000279=1269=0270=1.25506271=300000055=GBP/USD110=1000000279=1269=0270=1.25506271=500000055=GBP/USD110=300000010=028
20260120-14:01:32.213107000 : 8=FIX.4.49=044635=X49=NTPRO_IDBA_UAT56=SIRIUS_500007460_MD34=25052=20260120-14:01:32.454262=MD_EUR/USD_140109278614268=6279=1269=0270=1.14836271=10000055=EUR/USD110=0279=1269=0270=1.14836271=50000055=EUR/USD110=100000279=1269=0270=1.14836271=100000055=EUR/USD110=500000279=1269=1270=1.19861271=10000055=EUR/USD110=0279=1269=1270=1.19861271=50000055=EUR/USD110=100000279=1269=1270=1.19861271=100000055=EUR/USD110=50000010=001
20260120-14:01:32.295614000 : 8=FIX.4.49=027635=X49=NTPRO_IDBA_UAT56=SIRIUS_500007460_MD34=25152=20260120-14:01:32.544262=MD_EUR/USD_140109278614268=3279=1269=1270=1.1986271=10000055=EUR/USD110=0279=1269=1270=1.1986271=50000055=EUR/USD110=100000279=1269=1270=1.1986271=100000055=EUR/USD110=50000010=071
20260120-14:01:32.333845000 : 8=FIX.4.49=027935=X49=NTPRO_IDBA_UAT56=SIRIUS_500007460_MD34=25252=20260120-14:01:32.584262=MD_EUR/USD_140109278614268=3279=1269=0270=1.14835271=10000055=EUR/USD110=0279=1269=0270=1.14835271=50000055=EUR/USD110=100000279=1269=0270=1.14835271=100000055=EUR/USD110=50000010=211
20260120-14:01:32.614133000 : 8=FIX.4.49=027935=X49=NTPRO_IDBA_UAT56=SIRIUS_500007460_MD34=25352=20260120-14:01:32.874262=MD_EUR/USD_140109278614268=3279=1269=0270=1.14836271=10000055=EUR/USD110=0279=1269=0270=1.14836271=50000055=EUR/USD110=100000279=1269=0270=1.14836271=100000055=EUR/USD110=50000010=217
20260120-14:01:32.638552000 : 8=FIX.4.49=027935=X49=NTPRO_IDBA_UAT56=SIRIUS_500007460_MD34=25452=20260120-14:01:32.900262=MD_EUR/USD_140109278614268=3279=1269=1270=1.19861271=10000055=EUR/USD110=0279=1269=1270=1.19861271=50000055=EUR/USD110=100000279=1269=1270=1.19861271=100000055=EUR/USD110=50000010=220
20260120-14:01:32.740506000 : 8=FIX.4.49=027635=X49=NTPRO_IDBA_UAT56=SIRIUS_500007460_MD34=25552=20260120-14:01:33.001262=MD_EUR/USD_140109278614268=3279=1269=1270=1.1986271=10000055=EUR/USD110=0279=1269=1270=1.1986271=50000055=EUR/USD110=100000279=1269=1270=1.1986271=100000055=EUR/USD110=50000010=064
20260120-14:01:32.740939000 : 8=FIX.4.49=068335=X49=NTPRO_IDBA_UAT56=SIRIUS_500007460_MD34=25652=20260120-14:01:33.004262=MD_GBP/USD_140109778778268=10279=1269=0270=1.25505271=10000055=GBP/USD110=0279=1269=0270=1.25505271=50000055=GBP/USD110=100000279=1269=0270=1.25505271=100000055=GBP/USD110=500000279=1269=0270=1.25505271=300000055=GBP/USD110=1000000279=1269=0270=1.25505271=500000055=GBP/USD110=3000000279=1269=1270=1.43539271=10000055=GBP/USD110=0279=1269=1270=1.43539271=50000055=GBP/USD110=100000279=1269=1270=1.43539271=100000055=GBP/USD110=500000279=1269=1270=1.43539271=300000055=GBP/USD110=1000000279=1269=1270=1.43539271=500000055=GBP/USD110=300000010=186
20260120-14:01:32.822758000 : 8=FIX.4.49=027935=X49=NTPRO_IDBA_UAT56=SIRIUS_500007460_MD34=25752=20260120-14:01:33.091262=MD_EUR/USD_140109278614268=3279=1269=0270=1.14835271=10000055=EUR/USD110=0279=1269=0270=1.14835271=50000055=EUR/USD110=100000279=1269=0270=1.14835271=100000055=EUR/USD110=50000010=210
20260120-14:01:32.881096000 : 8=FIX.4.49=039235=X49=NTPRO_IDBA_UAT56=SIRIUS_500007460_MD34=25852=20260120-14:01:33.142262=MD_GBP/USD_140109778778268=5279=1269=1270=1.4354271=10000055=GBP/USD110=0279=1269=1270=1.4354271=50000055=GBP/USD110=100000279=1269=1270=1.4354271=100000055=GBP/USD110=500000279=1269=1270=1.4354271=300000055=GBP/USD110=1000000279=1269=1270=1.4354271=500000055=GBP/USD110=300000010=024
20260120-14:01:32.971412000 : 8=FIX.4.49=039735=X49=NTPRO_IDBA_UAT56=SIRIUS_500007460_MD34=25952=20260120-14:01:33.237262=MD_GBP/USD_140109778778268=5279=1269=0270=1.25506271=10000055=GBP/USD110=0279=1269=0270=1.25506271=50000055=GBP/USD110=100000279=1269=0270=1.25506271=100000055=GBP/USD110=500000279=1269=0270=1.25506271=300000055=GBP/USD110=1000000279=1269=0270=1.25506271=500000055=GBP/USD110=300000010=024
20260120-14:01:33.067449000 : 8=FIX.4.49=039735=X49=NTPRO_IDBA_UAT56=SIRIUS_500007460_MD34=26052=20260120-14:01:33.344262=MD_GBP/USD_140109778778268=5279=1269=0270=1.25505271=10000055=GBP/USD110=0279=1269=0270=1.25505271=50000055=GBP/USD110=100000279=1269=0270=1.25505271=100000055=GBP/USD110=500000279=1269=0270=1.25505271=300000055=GBP/USD110=1000000279=1269=0270=1.25505271=500000055=GBP/USD110=300000010=010
20260120-14:01:33.254964000 : 8=FIX.4.49=039735=X49=NTPRO_IDBA_UAT56=SIRIUS_500007460_MD34=26152=20260120-14:01:33.537262=MD_GBP/USD_140109778778268=5279=1269=1270=1.43539271=10000055=GBP/USD110=0279=1269=1270=1.43539271=50000055=GBP/USD110=100000279=1269=1270=1.43539271=100000055=GBP/USD110=500000279=1269=1270=1.43539271=300000055=GBP/USD110=1000000279=1269=1270=1.43539271=500000055=GBP/USD110=300000010=055
20260120-14:01:33.409165000 : 8=FIX.4.49=039235=X49=NTPRO_IDBA_UAT56=SIRIUS_500007460_MD34=26252=20260120-14:01:33.673262=MD_GBP/USD_140109778778268=5279=1269=1270=1.4354271=10000055=GBP/USD110=0279=1269=1270=1.4354271=50000055=GBP/USD110=100000279=1269=1270=1.4354271=100000055=GBP/USD110=500000279=1269=1270=1.4354271=300000055=GBP/USD110=1000000279=1269=1270=1.4354271=500000055=GBP/USD110=300000010=028
20260120-14:01:33.696487000 : 8=FIX.4.49=039735=X49=NTPRO_IDBA_UAT56=SIRIUS_500007460_MD34=26352=20260120-14:01:33.994262=MD_GBP/USD_140109778778268=5279=1269=1270=1.43539271=10000055=GBP/USD110=0279=1269=1270=1.43539271=50000055=GBP/USD110=100000279=1269=1270=1.43539271=100000055=GBP/USD110=500000279=1269=1270=1.43539271=300000055=GBP/USD110=1000000279=1269=1270=1.43539271=500000055=GBP/USD110=300000010=064
20260120-14:01:33.960722000 : 8=FIX.4.49=039735=X49=NTPRO_IDBA_UAT56=SIRIUS_500007460_MD34=26452=20260120-14:01:34.272262=MD_GBP/USD_140109778778268=5279=1269=1270=1.43538271=10000055=GBP/USD110=0279=1269=1270=1.43538271=50000055=GBP/USD110=100000279=1269=1270=1.43538271=100000055=GBP/USD110=500000279=1269=1270=1.43538271=300000055=GBP/USD110=1000000279=1269=1270=1.43538271=500000055=GBP/USD110=300000010=050
20260120-14:01:33.997964000 : 8=FIX.4.49=039735=X49=NTPRO_IDBA_UAT56=SIRIUS_500007460_MD34=26552=20260120-14:01:34.298262=MD_GBP/USD_140109778778268=5279=1269=1270=1.43539271=10000055=GBP/USD110=0279=1269=1270=1.43539271=50000055=GBP/USD110=100000279=1269=1270=1.43539271=100000055=GBP/USD110=500000279=1269=1270=1.43539271=300000055=GBP/USD110=1000000279=1269=1270=1.43539271=500000055=GBP/USD110=300000010=064
20260120-14:01:34.042399000 : 8=FIX.4.49=044635=X49=NTPRO_IDBA_UAT56=SIRIUS_500007460_MD34=26652=20260120-14:01:34.357262=MD_EUR/USD_140109278614268=6279=1269=0270=1.14834271=10000055=EUR/USD110=0279=1269=0270=1.14834271=50000055=EUR/USD110=100000279=1269=0270=1.14834271=100000055=EUR/USD110=500000279=1269=1270=1.19858271=10000055=EUR/USD110=0279=1269=1270=1.19858271=50000055=EUR/USD110=100000279=1269=1270=1.19858271=100000055=EUR/USD110=50000010=024
20260120-14:01:34.094579000 : 8=FIX.4.49=039735=X49=NTPRO_IDBA_UAT56=SIRIUS_500007460_MD34=26752=20260120-14:01:34.385262=MD_GBP/USD_140109778778268=5279=1269=0270=1.25504271=10000055=GBP/USD110=0279=1269=0270=1.25504271=50000055=GBP/USD110=100000279=1269=0270=1.25504271=100000055=GBP/USD110=500000279=1269=0270=1.25504271=300000055=GBP/USD110=1000000279=1269=0270=1.25504271=500000055=GBP/USD110=300000010=018
20260120-14:01:34.100386000 : 8=FIX.4.49=027935=X49=NTPRO_IDBA_UAT56=SIRIUS_500007460_MD34=26852=20260120-14:01:34.416262=MD_EUR/USD_140109278614268=3279=1269=1270=1.19859271=10000055=EUR/USD110=0279=1269=1270=1.19859271=50000055=EUR/USD110=100000279=1269=1270=1.19859271=100000055=EUR/USD110=50000010=250
20260120-14:01:34.157445000 : 8=FIX.4.49=044335=X49=NTPRO_IDBA_UAT56=SIRIUS_500007460_MD34=26952=20260120-14:01:34.476262=MD_EUR/USD_140109278614268=6279=1269=0270=1.14835271=10000055=EUR/USD110=0279=1269=0270=1.14835271=50000055=EUR/USD110=100000279=1269=0270=1.14835271=100000055=EUR/USD110=500000279=1269=1270=1.1986271=10000055=EUR/USD110=0279=1269=1270=1.1986271=50000055=EUR/USD110=100000279=1269=1270=1.1986271=100000055=EUR/USD110=50000010=120
20260120-14:01:34.184020000 : 8=FIX.4.49=039735=X49=NTPRO_IDBA_UAT56=SIRIUS_500007460_MD34=27052=20260120-14:01:34.487262=MD_GBP/USD_140109778778268=5279=1269=0270=1.25505271=10000055=GBP/USD110=0279=1269=0270=1.25505271=50000055=GBP/USD110=100000279=1269=0270=1.25505271=100000055=GBP/USD110=500000279=1269=0270=1.25505271=300000055=GBP/USD110=1000000279=1269=0270=1.25505271=500000055=GBP/USD110=300000010=020
20260120-14:01:34.214397000 : 8=FIX.4.49=039735=X49=NTPRO_IDBA_UAT56=SIRIUS_500007460_MD34=27152=20260120-14:01:34.535262=MD_GBP/USD_140109778778268=5279=1269=1270=1.43538271=10000055=GBP/USD110=0279=1269=1270=1.43538271=50000055=GBP/USD110=100000279=1269=1270=1.43538271=100000055=GBP/USD110=500000279=1269=1270=1.43538271=300000055=GBP/USD110=1000000279=1269=1270=1.43538271=500000055=GBP/USD110=300000010=050
20260120-14:01:34.243810000 : 8=FIX.4.49=044635=X49=NTPRO_IDBA_UAT56=SIRIUS_500007460_MD34=27252=20260120-14:01:34.566262=MD_EUR/USD_140109278614268=6279=1269=0270=1.14834271=10000055=EUR/USD110=0279=1269=0270=1.14834271=50000055=EUR/USD110=100000279=1269=0270=1.14834271=100000055=EUR/USD110=500000279=1269=1270=1.19859271=10000055=EUR/USD110=0279=1269=1270=1.19859271=50000055=EUR/USD110=100000279=1269=1270=1.19859271=100000055=EUR/USD110=50000010=026
20260120-14:01:34.305291000 : 8=FIX.4.49=039735=X49=NTPRO_IDBA_UAT56=SIRIUS_500007460_MD34=27352=20260120-14:01:34.595262=MD_GBP/USD_140109778778268=5279=1269=1270=1.43539271=10000055=GBP/USD110=0279=1269=1270=1.43539271=50000055=GBP/USD110=100000279=1269=1270=1.43539271=100000055=GBP/USD110=500000279=1269=1270=1.43539271=300000055=GBP/USD110=1000000279=1269=1270=1.43539271=500000055=GBP/USD110=300000010=063
20260120-14:01:34.306341000 : 8=FIX.4.49=027935=X49=NTPRO_IDBA_UAT56=SIRIUS_500007460_MD34=27452=20260120-14:01:34.600262=MD_EUR/USD_140109278614268=3279=1269=0270=1.14835271=10000055=EUR/USD110=0279=1269=0270=1.14835271=50000055=EUR/USD110=100000279=1269=0270=1.14835271=100000055=EUR/USD110=50000010=206
20260120-14:01:34.306891000 : 8=FIX.4.49=039735=X49=NTPRO_IDBA_UAT56=SIRIUS_500007460_MD34=27552=20260120-14:01:34.615262=MD_GBP/USD_140109778778268=5279=1269=0270=1.25504271=10000055=GBP/USD110=0279=1269=0270=1.25504271=50000055=GBP/USD110=100000279=1269=0270=1.25504271=100000055=GBP/USD110=500000279=1269=0270=1.25504271=300000055=GBP/USD110=1000000279=1269=0270=1.25504271=500000055=GBP/USD110=300000010=013
20260120-14:01:34.333686000 : 8=FIX.4.49=039735=X49=NTPRO_IDBA_UAT56=SIRIUS_500007460_MD34=27652=20260120-14:01:34.655262=MD_GBP/USD_140109778778268=5279=1269=0270=1.25503271=10000055=GBP/USD110=0279=1269=0270=1.25503271=50000055=GBP/USD110=100000279=1269=0270=1.25503271=100000055=GBP/USD110=500000279=1269=0270=1.25503271=300000055=GBP/USD110=1000000279=1269=0270=1.25503271=500000055=GBP/USD110=300000010=013
20260120-14:01:34.566826000 : 8=FIX.4.49=039735=X49=NTPRO_IDBA_UAT56=SIRIUS_500007460_MD34=27752=20260120-14:01:34.899262=MD_GBP/USD_140109778778268=5279=1269=0270=1.25504271=10000055=GBP/USD110=0279=1269=0270=1.25504271=50000055=GBP/USD110=100000279=1269=0270=1.25504271=100000055=GBP/USD110=500000279=1269=0270=1.25504271=300000055=GBP/USD110=1000000279=1269=0270=1.25504271=500000055=GBP/USD110=300000010=029
20260120-14:01:34.586483000 : 8=FIX.4.49=027635=X49=NTPRO_IDBA_UAT56=SIRIUS_500007460_MD34=27852=20260120-14:01:34.920262=MD_EUR/USD_140109278614268=3279=1269=1270=1.1986271=10000055=EUR/USD110=0279=1269=1270=1.1986271=50000055=EUR/USD110=100000279=1269=1270=1.1986271=100000055=EUR/USD110=50000010=080
20260120-14:01:34.638943000 : 8=FIX.4.49=027935=X49=NTPRO_IDBA_UAT56=SIRIUS_500007460_MD34=27952=20260120-14:01:34.975262=MD_EUR/USD_140109278614268=3279=1269=0270=1.14836271=10000055=EUR/USD110=0279=1269=0270=1.14836271=50000055=EUR/USD110=100000279=1269=0270=1.14836271=100000055=EUR/USD110=50000010=229
20260120-14:01:34.696219000 : 8=FIX.4.49=027935=X49=NTPRO_IDBA_UAT56=SIRIUS_500007460_MD34=28052=20260120-14:01:35.035262=MD_EUR/USD_140109278614268=3279=1269=0270=1.14835271=10000055=EUR/USD110=0279=1269=0270=1.14835271=50000055=EUR/USD110=100000279=1269=0270=1.14835271=100000055=EUR/USD110=50000010=206
20260120-14:01:34.708333000 : 8=FIX.4.49=067835=X49=NTPRO_IDBA_UAT56=SIRIUS_500007460_MD34=28152=20260120-14:01:35.045262=MD_GBP/USD_140109778778268=10279=1269=0270=1.25505271=10000055=GBP/USD110=0279=1269=0270=1.25505271=50000055=GBP/USD110=100000279=1269=0270=1.25505271=100000055=GBP/USD110=500000279=1269=0270=1.25505271=300000055=GBP/USD110=1000000279=1269=0270=1.25505271=500000055=GBP/USD110=3000000279=1269=1270=1.4354271=10000055=GBP/USD110=0279=1269=1270=1.4354271=50000055=GBP/USD110=100000279=1269=1270=1.4354271=100000055=GBP/USD110=500000279=1269=1270=1.4354271=300000055=GBP/USD110=1000000279=1269=1270=1.4354271=500000055=GBP/USD110=300000010=171
20260120-14:01:34.786227000 : 8=FIX.4.49=027935=X49=NTPRO_IDBA_UAT56=SIRIUS_500007460_MD34=28252=20260120-14:01:35.125262=MD_EUR/USD_140109278614268=3279=1269=0270=1.14836271=10000055=EUR/USD110=0279=1269=0270=1.14836271=50000055=EUR/USD110=100000279=1269=0270=1.14836271=100000055=EUR/USD110=50000010=211
20260120-14:01:34.825070000 : 8=FIX.4.49=027935=X49=NTPRO_IDBA_UAT56=SIRIUS_500007460_MD34=28352=20260120-14:01:35.162262=MD_EUR/USD_140109278614268=3279=1269=0270=1.14835271=10000055=EUR/USD110=0279=1269=0270=1.14835271=50000055=EUR/USD110=100000279=1269=0270=1.14835271=100000055=EUR/USD110=50000010=210
20260120-14:01:34.843720000 : 8=FIX.4.49=044635=X49=NTPRO_IDBA_UAT56=SIRIUS_500007460_MD34=28452=20260120-14:01:35.188262=MD_EUR/USD_140109278614268=6279=1269=0270=1.14836271=10000055=EUR/USD110=0279=1269=0270=1.14836271=50000055=EUR/USD110=100000279=1269=0270=1.14836271=100000055=EUR/USD110=500000279=1269=1270=1.19861271=10000055=EUR/USD110=0279=1269=1270=1.19861271=50000055=EUR/USD110=100000279=1269=1270=1.19861271=100000055=EUR/USD110=50000010=015
20260120-14:01:34.900841000 : 8=FIX.4.49=068335=X49=NTPRO_IDBA_UAT56=SIRIUS_500007460_MD34=28552=20260120-14:01:35.233262=MD_GBP/USD_140109778778268=10279=1269=0270=1.25506271=10000055=GBP/USD110=0279=1269=0270=1.25506271=50000055=GBP/USD110=100000279=1269=0270=1.25506271=100000055=GBP/USD110=500000279=1269=0270=1.25506271=300000055=GBP/USD110=1000000279=1269=0270=1.25506271=500000055=GBP/USD110=3000000279=1269=1270=1.43541271=10000055=GBP/USD110=0279=1269=1270=1.43541271=50000055=GBP/USD110=100000279=1269=1270=1.43541271=100000055=GBP/USD110=500000279=1269=1270=1.43541271=300000055=GBP/USD110=1000000279=1269=1270=1.43541271=500000055=GBP/USD110=300000010=164
20260120-14:01:34.989257000 : 8=FIX.4.49=027635=X49=NTPRO_IDBA_UAT56=SIRIUS_500007460_MD34=28652=20260120-14:01:35.331262=MD_EUR/USD_140109278614268=3279=1269=1270=1.1986271=10000055=EUR/USD110=0279=1269=1270=1.1986271=50000055=EUR/USD110=100000279=1269=1270=1.1986271=100000055=EUR/USD110=50000010=076
20260120-14:01:35.083158000 : 8=FIX.4.49=027935=X49=NTPRO_IDBA_UAT56=SIRIUS_500007460_MD34=28752=20260120-14:01:35.432262=MD_EUR/USD_140109278614268=3279=1269=0270=1.14835271=10000055=EUR/USD110=0279=1269=0270=1.14835271=50000055=EUR/USD110=100000279=1269=0270=1.14835271=100000055=EUR/USD110=50000010=214
20260120-14:01:35.120972000 : 8=FIX.4.49=068335=X49=NTPRO_IDBA_UAT56=SIRIUS_500007460_MD34=28852=20260120-14:01:35.475262=MD_GBP/USD_140109778778268=10279=1269=0270=1.25505271=10000055=GBP/USD110=0279=1269=0270=1.25505271=50000055=GBP/USD110=100000279=1269=0270=1.25505271=100000055=GBP/USD110=500000279=1269=0270=1.25505271=300000055=GBP/USD110=1000000279=1269=0270=1.25505271=500000055=GBP/USD110=3000000279=1269=1270=1.43539271=10000055=GBP/USD110=0279=1269=1270=1.43539271=50000055=GBP/USD110=100000279=1269=1270=1.43539271=100000055=GBP/USD110=500000279=1269=1270=1.43539271=300000055=GBP/USD110=1000000279=1269=1270=1.43539271=500000055=GBP/USD110=300000010=205
20260120-14:01:35.229004000 : 8=FIX.4.49=039735=X49=NTPRO_IDBA_UAT56=SIRIUS_500007460_MD34=28952=20260120-14:01:35.586262=MD_GBP/USD_140109778778268=5279=1269=0270=1.25506271=10000055=GBP/USD110=0279=1269=0270=1.25506271=50000055=GBP/USD110=100000279=1269=0270=1.25506271=100000055=GBP/USD110=500000279=1269=0270=1.25506271=300000055=GBP/USD110=1000000279=1269=0270=1.25506271=500000055=GBP/USD110=300000010=036
20260120-14:01:35.499674000 : 8=FIX.4.49=027935=X49=NTPRO_IDBA_UAT56=SIRIUS_500007460_MD34=29052=20260120-14:01:35.820262=MD_EUR/USD_140109278614268=3279=1269=1270=1.19859271=10000055=EUR/USD110=0279=1269=1270=1.19859271=50000055=EUR/USD110=100000279=1269=1270=1.19859271=100000055=EUR/USD110=50000010=245
20260120-14:01:35.532267000 : 8=FIX.4.49=027635=X49=NTPRO_IDBA_UAT56=SIRIUS_500007460_MD34=29152=20260120-14:01:35.902262=MD_EUR/USD_140109278614268=3279=1269=1270=1.1986271=10000055=EUR/USD110=0279=1269=1270=1.1986271=50000055=EUR/USD110=100000279=1269=1270=1.1986271=100000055=EUR/USD110=50000010=076
20260120-14:01:35.591846000 : 8=FIX.4.49=039235=X49=NTPRO_IDBA_UAT56=SIRIUS_500007460_MD34=29252=20260120-14:01:35.957262=MD_GBP/USD_140109778778268=5279=1269=1270=1.4354271=10000055=GBP/USD110=0279=1269=1270=1.4354271=50000055=GBP/USD110=100000279=1269=1270=1.4354271=100000055=GBP/USD110=500000279=1269=1270=1.4354271=300000055=GBP/USD110=1000000279=1269=1270=1.4354271=500000055=GBP/USD110=300000010=038
20260120-14:01:35.639479000 : 8=FIX.4.49=044635=X49=NTPRO_IDBA_UAT56=SIRIUS_500007460_MD34=29352=20260120-14:01:36.014262=MD_EUR/USD_140109278614268=6279=1269=0270=1.14829271=10000055=EUR/USD110=0279=1269=0270=1.14829271=50000055=EUR/USD110=100000279=1269=0270=1.14829271=100000055=EUR/USD110=500000279=1269=1270=1.19854271=10000055=EUR/USD110=0279=1269=1270=1.19854271=50000055=EUR/USD110=100000279=1269=1270=1.19854271=100000055=EUR/USD110=50000010=016
20260120-14:01:35.680440000 : 8=FIX.4.49=039735=X49=NTPRO_IDBA_UAT56=SIRIUS_500007460_MD34=29452=20260120-14:01:36.055262=MD_GBP/USD_140109778778268=5279=1269=1270=1.43537271=10000055=GBP/USD110=0279=1269=1270=1.43537271=50000055=GBP/USD110=100000279=1269=1270=1.43537271=100000055=GBP/USD110=500000279=1269=1270=1.43537271=300000055=GBP/USD110=1000000279=1269=1270=1.43537271=500000055=GBP/USD110=300000010=049
20260120-14:01:35.752858000 : 8=FIX.4.49=068335=X49=NTPRO_IDBA_UAT56=SIRIUS_500007460_MD34=29552=20260120-14:01:36.127262=MD_GBP/USD_140109778778268=10279=1269=0270=1.25504271=10000055=GBP/USD110=0279=1269=0270=1.25504271=50000055=GBP/USD110=100000279=1269=0270=1.25504271=100000055=GBP/USD110=500000279=1269=0270=1.25504271=300000055=GBP/USD110=1000000279=1269=0270=1.25504271=500000055=GBP/USD110=3000000279=1269=1270=1.43538271=10000055=GBP/USD110=0279=1269=1270=1.43538271=50000055=GBP/USD110=100000279=1269=1270=1.43538271=100000055=GBP/USD110=500000279=1269=1270=1.43538271=300000055=GBP/USD110=1000000279=1269=1270=1.43538271=500000055=GBP/USD110=300000010=188
20260120-14:01:35.801474000 : 8=FIX.4.49=068335=X49=NTPRO_IDBA_UAT56=SIRIUS_500007460_MD34=29652=20260120-14:01:36.180262=MD_GBP/USD_140109778778268=10279=1269=0270=1.25503271=10000055=GBP/USD110=0279=1269=0270=1.25503271=50000055=GBP/USD110=100000279=1269=0270=1.25503271=100000055=GBP/USD110=500000279=1269=0270=1.25503271=300000055=GBP/USD110=1000000279=1269=0270=1.25503271=500000055=GBP/USD110=3000000279=1269=1270=1.43537271=10000055=GBP/USD110=0279=1269=1270=1.43537271=50000055=GBP/USD110=100000279=1269=1270=1.43537271=100000055=GBP/USD110=500000279=1269=1270=1.43537271=300000055=GBP/USD110=1000000279=1269=1270=1.43537271=500000055=GBP/USD110=300000010=178
20260120-14:01:35.816734000 : 8=FIX.4.49=044635=X49=NTPRO_IDBA_UAT56=SIRIUS_500007460_MD34=29752=20260120-14:01:36.198262=MD_EUR/USD_140109278614268=6279=1269=0270=1.14828271=10000055=EUR/USD110=0279=1269=0270=1.14828271=50000055=EUR/USD110=100000279=1269=0270=1.14828271=100000055=EUR/USD110=500000279=1269=1270=1.19853271=10000055=EUR/USD110=0279=1269=1270=1.19853271=50000055=EUR/USD110=100000279=1269=1270=1.19853271=100000055=EUR/USD110=50000010=027
20260120-14:01:35.851643000 : 8=FIX.4.49=027935=X49=NTPRO_IDBA_UAT56=SIRIUS_500007460_MD34=29852=20260120-14:01:36.234262=MD_EUR/USD_140109278614268=3279=1269=1270=1.19852271=10000055=EUR/USD110=0279=1269=1270=1.19852271=50000055=EUR/USD110=100000279=1269=1270=1.19852271=100000055=EUR/USD110=50000010=232
20260120-14:01:35.996259000 : 8=FIX.4.49=027935=X49=NTPRO_IDBA_UAT56=SIRIUS_500007460_MD34=29952=20260120-14:01:36.382262=MD_EUR/USD_140109278614268=3279=1269=1270=1.19853271=10000055=EUR/USD110=0279=1269=1270=1.19853271=50000055=EUR/USD110=100000279=1269=1270=1.19853271=100000055=EUR/USD110=50000010=240
20260120-14:01:36.024096000 : 8=FIX.4.49=027935=X49=NTPRO_IDBA_UAT56=SIRIUS_500007460_MD34=30052=20260120-14:01:36.408262=MD_EUR/USD_140109278614268=3279=1269=0270=1.14829271=10000055=EUR/USD110=0279=1269=0270=1.14829271=50000055=EUR/USD110=100000279=1269=0270=1.14829271=100000055=EUR/USD110=50000010=213
20260120-14:01:36.049055000 : 8=FIX.4.49=027935=X49=NTPRO_IDBA_UAT56=SIRIUS_500007460_MD34=30152=20260120-14:01:36.437262=MD_EUR/USD_140109278614268=3279=1269=0270=1.14828271=10000055=EUR/USD110=0279=1269=0270=1.14828271=50000055=EUR/USD110=100000279=1269=0270=1.14828271=100000055=EUR/USD110=50000010=213
20260120-14:01:36.184484000 : 8=FIX.4.49=044635=X49=NTPRO_IDBA_UAT56=SIRIUS_500007460_MD34=30252=20260120-14:01:36.578262=MD_EUR/USD_140109278614268=6279=1269=0270=1.14827271=10000055=EUR/USD110=0279=1269=0270=1.14827271=50000055=EUR/USD110=100000279=1269=0270=1.14827271=100000055=EUR/USD110=500000279=1269=1270=1.19852271=10000055=EUR/USD110=0279=1269=1270=1.19852271=50000055=EUR/USD110=100000279=1269=1270=1.19852271=100000055=EUR/USD110=50000010=010
20260120-14:01:36.282951000 : 8=FIX.4.49=044635=X49=NTPRO_IDBA_UAT56=SIRIUS_500007460_MD34=30352=20260120-14:01:36.642262=MD_EUR/USD_140109278614268=6279=1269=0270=1.14828271=10000055=EUR/USD110=0279=1269=0270=1.14828271=50000055=EUR/USD110=100000279=1269=0270=1.14828271=100000055=EUR/USD110=500000279=1269=1270=1.19853271=10000055=EUR/USD110=0279=1269=1270=1.19853271=50000055=EUR/USD110=100000279=1269=1270=1.19853271=100000055=EUR/USD110=50000010=009
20260120-14:01:36.381348000 : 8=FIX.4.49=027935=X49=NTPRO_IDBA_UAT56=SIRIUS_500007460_MD34=30452=20260120-14:01:36.784262=MD_EUR/USD_140109278614268=3279=1269=0270=1.14829271=10000055=EUR/USD110=0279=1269=0270=1.14829271=50000055=EUR/USD110=100000279=1269=0270=1.14829271=100000055=EUR/USD110=50000010=224
20260120-14:01:36.463686000 : 8=FIX.4.49=039735=X49=NTPRO_IDBA_UAT56=SIRIUS_500007460_MD34=30552=20260120-14:01:36.860262=MD_GBP/USD_140109778778268=5279=1269=1270=1.43535271=10000055=GBP/USD110=0279=1269=1270=1.43535271=50000055=GBP/USD110=100000279=1269=1270=1.43535271=100000055=GBP/USD110=500000279=1269=1270=1.43535271=300000055=GBP/USD110=1000000279=1269=1270=1.43535271=500000055=GBP/USD110=300000010=036
20260120-14:01:36.464187000 : 8=FIX.4.49=044635=X49=NTPRO_IDBA_UAT56=SIRIUS_500007460_MD34=30652=20260120-14:01:36.866262=MD_EUR/USD_140109278614268=6279=1269=0270=1.14828271=10000055=EUR/USD110=0279=1269=0270=1.14828271=50000055=EUR/USD110=100000279=1269=0270=1.14828271=100000055=EUR/USD110=500000279=1269=1270=1.19852271=10000055=EUR/USD110=0279=1269=1270=1.19852271=50000055=EUR/USD110=100000279=1269=1270=1.19852271=100000055=EUR/USD110=50000010=017
20260120-14:01:36.486342000 : 8=FIX.4.49=039735=X49=NTPRO_IDBA_UAT56=SIRIUS_500007460_MD34=30752=20260120-14:01:36.892262=MD_GBP/USD_140109778778268=5279=1269=1270=1.43534271=10000055=GBP/USD110=0279=1269=1270=1.43534271=50000055=GBP/USD110=100000279=1269=1270=1.43534271=100000055=GBP/USD110=500000279=1269=1270=1.43534271=300000055=GBP/USD110=1000000279=1269=1270=1.43534271=500000055=GBP/USD110=300000010=038
20260120-14:01:36.500994000 : 8=FIX.4.49=027935=X49=NTPRO_IDBA_UAT56=SIRIUS_500007460_MD34=30852=20260120-14:01:36.908262=MD_EUR/USD_140109278614268=3279=1269=0270=1.14827271=10000055=EUR/USD110=0279=1269=0270=1.14827271=50000055=EUR/USD110=100000279=1269=0270=1.14827271=100000055=EUR/USD110=50000010=220
20260120-14:01:36.517488000 : 8=FIX.4.49=039735=X49=NTPRO_IDBA_UAT56=SIRIUS_500007460_MD34=30952=20260120-14:01:36.924262=MD_GBP/USD_140109778778268=5279=1269=1270=1.43533271=10000055=GBP/USD110=0279=1269=1270=1.43533271=50000055=GBP/USD110=100000279=1269=1270=1.43533271=100000055=GBP/USD110=500000279=1269=1270=1.43533271=300000055=GBP/USD110=1000000279=1269=1270=1.43533271=500000055=GBP/USD110=300000010=031
20260120-14:01:36.557935000 : 8=FIX.4.49=039735=X49=NTPRO_IDBA_UAT56=SIRIUS_500007460_MD34=31052=20260120-14:01:36.957262=MD_GBP/USD_140109778778268=5279=1269=1270=1.43534271=10000055=GBP/USD110=0279=1269=1270=1.43534271=50000055=GBP/USD110=100000279=1269=1270=1.43534271=100000055=GBP/USD110=500000279=1269=1270=1.43534271=300000055=GBP/USD110=1000000279=1269=1270=1.43534271=500000055=GBP/USD110=300000010=034
20260120-14:01:36.576058000 : 8=FIX.4.49=039735=X49=NTPRO_IDBA_UAT56=SIRIUS_500007460_MD34=31152=20260120-14:01:36.986262=MD_GBP/USD_140109778778268=5279=1269=0270=1.25499271=10000055=GBP/USD110=0279=1269=0270=1.25499271=50000055=GBP/USD110=100000279=1269=0270=1.25499271=100000055=GBP/USD110=500000279=1269=0270=1.25499271=300000055=GBP/USD110=1000000279=1269=0270=1.25499271=500000055=GBP/USD110=300000010=082
20260120-14:01:36.592788000 : 8=FIX.4.49=044335=X49=NTPRO_IDBA_UAT56=SIRIUS_500007460_MD34=31252=20260120-14:01:37.003262=MD_EUR/USD_140109278614268=6279=1269=0270=1.14826271=10000055=EUR/USD110=0279=1269=0270=1.14826271=50000055=EUR/USD110=100000279=1269=0270=1.14826271=100000055=EUR/USD110=500000279=1269=1270=1.1985271=10000055=EUR/USD110=0279=1269=1270=1.1985271=50000055=EUR/USD110=100000279=1269=1270=1.1985271=100000055=EUR/USD110=50000010=095
20260120-14:01:36.680982000 : 8=FIX.4.49=027935=X49=NTPRO_IDBA_UAT56=SIRIUS_500007460_MD34=31352=20260120-14:01:37.092262=MD_EUR/USD_140109278614268=3279=1269=0270=1.14825271=10000055=EUR/USD110=0279=1269=0270=1.14825271=50000055=EUR/USD110=100000279=1269=0270=1.14825271=100000055=EUR/USD110=50000010=205
20260120-14:01:36.694360000 : 8=FIX.4.49=038735=X49=NTPRO_IDBA_UAT56=SIRIUS_500007460_MD34=31452=20260120-14:01:37.097262=MD_GBP/USD_140109778778268=5279=1269=0270=1.255271=10000055=GBP/USD110=0279=1269=0270=1.255271=50000055=GBP/USD110=100000279=1269=0270=1.255271=100000055=GBP/USD110=500000279=1269=0270=1.255271=300000055=GBP/USD110=1000000279=1269=0270=1.255271=500000055=GBP/USD110=300000010=025
20260120-14:01:37.979349000 : 8=FIX.4.49=027935=X49=NTPRO_IDBA_UAT56=SIRIUS_500007460_MD34=31552=20260120-14:01:38.438262=MD_EUR/USD_140109278614268=3279=1269=0270=1.14826271=10000055=EUR/USD110=0279=1269=0270=1.14826271=50000055=EUR/USD110=100000279=1269=0270=1.14826271=100000055=EUR/USD110=50000010=215
20260120-14:01:38.216034000 : 8=FIX.4.49=027935=X49=NTPRO_IDBA_UAT56=SIRIUS_500007460_MD34=31652=20260120-14:01:38.688262=MD_EUR/USD_140109278614268=3279=1269=0270=1.14825271=10000055=EUR/USD110=0279=1269=0270=1.14825271=50000055=EUR/USD110=100000279=1269=0270=1.14825271=100000055=EUR/USD110=50000010=220
20260120-14:01:38.474651000 : 8=FIX.4.49=068335=X49=NTPRO_IDBA_UAT56=SIRIUS_500007460_MD34=31752=20260120-14:01:38.956262=MD_GBP/USD_140109778778268=10279=1269=0270=1.25499271=10000055=GBP/USD110=0279=1269=0270=1.25499271=50000055=GBP/USD110=100000279=1269=0270=1.25499271=100000055=GBP/USD110=500000279=1269=0270=1.25499271=300000055=GBP/USD110=1000000279=1269=0270=1.25499271=500000055=GBP/USD110=3000000279=1269=1270=1.43533271=10000055=GBP/USD110=0279=1269=1270=1.43533271=50000055=GBP/USD110=100000279=1269=1270=1.43533271=100000055=GBP/USD110=500000279=1269=1270=1.43533271=300000055=GBP/USD110=1000000279=1269=1270=1.43533271=500000055=GBP/USD110=300000010=235
20260120-14:01:38.574851000 : 8=FIX.4.49=039735=X49=NTPRO_IDBA_UAT56=SIRIUS_500007460_MD34=31852=20260120-14:01:39.061262=MD_GBP/USD_140109778778268=5279=1269=1270=1.43532271=10000055=GBP/USD110=0279=1269=1270=1.43532271=50000055=GBP/USD110=100000279=1269=1270=1.43532271=100000055=GBP/USD110=500000279=1269=1270=1.43532271=300000055=GBP/USD110=1000000279=1269=1270=1.43532271=500000055=GBP/USD110=300000010=021
20260120-14:01:38.712316000 : 8=FIX.4.49=039735=X49=NTPRO_IDBA_UAT56=SIRIUS_500007460_MD34=31952=20260120-14:01:39.203262=MD_GBP/USD_140109778778268=5279=1269=0270=1.25498271=10000055=GBP/USD110=0279=1269=0270=1.25498271=50000055=GBP/USD110=100000279=1269=0270=1.25498271=100000055=GBP/USD110=500000279=1269=0270=1.25498271=300000055=GBP/USD110=1000000279=1269=0270=1.25498271=500000055=GBP/USD110=300000010=070
20260120-14:01:38.836833000 : 8=FIX.4.49=027935=X49=NTPRO_IDBA_UAT56=SIRIUS_500007460_MD34=32052=20260120-14:01:39.333262=MD_EUR/USD_140109278614268=3279=1269=1270=1.19849271=10000055=EUR/USD110=0279=1269=1270=1.19849271=50000055=EUR/USD110=100000279=1269=1270=1.19849271=100000055=EUR/USD110=50000010=239
20260120-14:01:38.868466000 : 8=FIX.4.49=068335=X49=NTPRO_IDBA_UAT56=SIRIUS_500007460_MD34=32152=20260120-14:01:39.366262=MD_GBP/USD_140109778778268=10279=1269=0270=1.25497271=10000055=GBP/USD110=0279=1269=0270=1.25497271=50000055=GBP/USD110=100000279=1269=0270=1.25497271=100000055=GBP/USD110=500000279=1269=0270=1.25497271=300000055=GBP/USD110=1000000279=1269=0270=1.25497271=500000055=GBP/USD110=3000000279=1269=1270=1.43531271=10000055=GBP/USD110=0279=1269=1270=1.43531271=50000055=GBP/USD110=100000279=1269=1270=1.43531271=100000055=GBP/USD110=500000279=1269=1270=1.43531271=300000055=GBP/USD110=1000000279=1269=1270=1.43531271=500000055=GBP/USD110=300000010=206
20260120-14:01:38.985706000 : 8=FIX.4.49=027935=X49=NTPRO_IDBA_UAT56=SIRIUS_500007460_MD34=32252=20260120-14:01:39.488262=MD_EUR/USD_140109278614268=3279=1269=0270=1.14824271=10000055=EUR/USD110=0279=1269=0270=1.14824271=50000055=EUR/USD110=100000279=1269=0270=1.14824271=100000055=EUR/USD110=50000010=213
20260120-14:01:39.055314000 : 8=FIX.4.49=044635=X49=NTPRO_IDBA_UAT56=SIRIUS_500007460_MD34=32352=20260120-14:01:39.561262=MD_EUR/USD_140109278614268=6279=1269=0270=1.14827271=10000055=EUR/USD110=0279=1269=0270=1.14827271=50000055=EUR/USD110=100000279=1269=0270=1.14827271=100000055=EUR/USD110=500000279=1269=1270=1.19851271=10000055=EUR/USD110=0279=1269=1270=1.19851271=50000055=EUR/USD110=100000279=1269=1270=1.19851271=100000055=EUR/USD110=50000010=005
20260120-14:01:39.109705000 : 8=FIX.4.49=027935=X49=NTPRO_IDBA_UAT56=SIRIUS_500007460_MD34=32452=20260120-14:01:39.615262=MD_EUR/USD_140109278614268=3279=1269=1270=1.19852271=10000055=EUR/USD110=0279=1269=1270=1.19852271=50000055=EUR/USD110=100000279=1269=1270=1.19852271=100000055=EUR/USD110=50000010=228
20260120-14:01:39.166154000 : 8=FIX.4.49=044635=X49=NTPRO_IDBA_UAT56=SIRIUS_500007460_MD34=32552=20260120-14:01:39.676262=MD_EUR/USD_140109278614268=6279=1269=0270=1.14826271=10000055=EUR/USD110=0279=1269=0270=1.14826271=50000055=EUR/USD110=100000279=1269=0270=1.14826271=100000055=EUR/USD110=500000279=1269=1270=1.19851271=10000055=EUR/USD110=0279=1269=1270=1.19851271=50000055=EUR/USD110=100000279=1269=1270=1.19851271=100000055=EUR/USD110=50000010=011
20260120-14:01:39.276562000 : 8=FIX.4.49=027635=X49=NTPRO_IDBA_UAT56=SIRIUS_500007460_MD34=32652=20260120-14:01:39.791262=MD_EUR/USD_140109278614268=3279=1269=1270=1.1985271=10000055=EUR/USD110=0279=1269=1270=1.1985271=50000055=EUR/USD110=100000279=1269=1270=1.1985271=100000055=EUR/USD110=50000010=082
20260120-14:01:39.596560000 : 8=FIX.4.49=027935=X49=NTPRO_IDBA_UAT56=SIRIUS_500007460_MD34=32752=20260120-14:01:40.113262=MD_EUR/USD_140109278614268=3279=1269=1270=1.19851271=10000055=EUR/USD110=0279=1269=1270=1.19851271=50000055=EUR/USD110=100000279=1269=1270=1.19851271=100000055=EUR/USD110=50000010=213
20260120-14:01:39.626625000 : 8=FIX.4.49=039735=X49=NTPRO_IDBA_UAT56=SIRIUS_500007460_MD34=32852=20260120-14:01:40.154262=MD_GBP/USD_140109778778268=5279=1269=1270=1.43532271=10000055=GBP/USD110=0279=1269=1270=1.43532271=50000055=GBP/USD110=100000279=1269=1270=1.43532271=100000055=GBP/USD110=500000279=1269=1270=1.43532271=300000055=GBP/USD110=1000000279=1269=1270=1.43532271=500000055=GBP/USD110=300000010=017
20260120-14:01:39.666157000 : 8=FIX.4.49=044635=X49=NTPRO_IDBA_UAT56=SIRIUS_500007460_MD34=32952=20260120-14:01:40.196262=MD_EUR/USD_140109278614268=6279=1269=0270=1.14827271=10000055=EUR/USD110=0279=1269=0270=1.14827271=50000055=EUR/USD110=100000279=1269=0270=1.14827271=100000055=EUR/USD110=500000279=1269=1270=1.19852271=10000055=EUR/USD110=0279=1269=1270=1.19852271=50000055=EUR/USD110=100000279=1269=1270=1.19852271=100000055=EUR/USD110=50000010=010
20260120-14:01:39.686773000 : 8=FIX.4.49=068335=X49=NTPRO_IDBA_UAT56=SIRIUS_500007460_MD34=33052=20260120-14:01:40.217262=MD_GBP/USD_140109778778268=10279=1269=0270=1.25498271=10000055=GBP/USD110=0279=1269=0270=1.25498271=50000055=GBP/USD110=100000279=1269=0270=1.25498271=100000055=GBP/USD110=500000279=1269=0270=1.25498271=300000055=GBP/USD110=1000000279=1269=0270=1.25498271=500000055=GBP/USD110=3000000279=1269=1270=1.43533271=10000055=GBP/USD110=0279=1269=1270=1.43533271=50000055=GBP/USD110=100000279=1269=1270=1.43533271=100000055=GBP/USD110=500000279=1269=1270=1.43533271=300000055=GBP/USD110=1000000279=1269=1270=1.43533271=500000055=GBP/USD110=300000010=208
20260120-14:01:39.751927000 : 8=FIX.4.49=027935=X49=NTPRO_IDBA_UAT56=SIRIUS_500007460_MD34=33152=20260120-14:01:40.285262=MD_EUR/USD_140109278614268=3279=1269=1270=1.19851271=10000055=EUR/USD110=0279=1269=1270=1.19851271=50000055=EUR/USD110=100000279=1269=1270=1.19851271=100000055=EUR/USD110=50000010=218
20260120-14:01:39.774939000 : 8=FIX.4.49=039735=X49=NTPRO_IDBA_UAT56=SIRIUS_500007460_MD34=33252=20260120-14:01:40.309262=MD_GBP/USD_140109778778268=5279=1269=1270=1.43531271=10000055=GBP/USD110=0279=1269=1270=1.43531271=50000055=GBP/USD110=100000279=1269=1270=1.43531271=100000055=GBP/USD110=500000279=1269=1270=1.43531271=300000055=GBP/USD110=1000000279=1269=1270=1.43531271=500000055=GBP/USD110=300000010=009
20260120-14:01:39.823285000 : 8=FIX.4.49=027935=X49=NTPRO_IDBA_UAT56=SIRIUS_500007460_MD34=33352=20260120-14:01:40.359262=MD_EUR/USD_140109278614268=3279=1269=0270=1.14826271=10000055=EUR/USD110=0279=1269=0270=1.14826271=50000055=EUR/USD110=100000279=1269=0270=1.14826271=100000055=EUR/USD110=50000010=210
20260120-14:01:39.868728000 : 8=FIX.4.49=027635=X49=NTPRO_IDBA_UAT56=SIRIUS_500007460_MD34=33452=20260120-14:01:40.406262=MD_EUR/USD_140109278614268=3279=1269=1270=1.1985271=10000055=EUR/USD110=0279=1269=1270=1.1985271=50000055=EUR/USD110=100000279=1269=1270=1.1985271=100000055=EUR/USD110=50000010=066
20260120-14:01:39.880137000 : 8=FIX.4.49=039735=X49=NTPRO_IDBA_UAT56=SIRIUS_500007460_MD34=33552=20260120-14:01:40.418262=MD_GBP/USD_140109778778268=5279=1269=0270=1.25497271=10000055=GBP/USD110=0279=1269=0270=1.25497271=50000055=GBP/USD110=100000279=1269=0270=1.25497271=100000055=GBP/USD110=500000279=1269=0270=1.25497271=300000055=GBP/USD110=1000000279=1269=0270=1.25497271=500000055=GBP/USD110=300000010=063
20260120-14:01:40.411863000 : 8=FIX.4.49=039735=X49=NTPRO_IDBA_UAT56=SIRIUS_500007460_MD34=33652=20260120-14:01:40.971262=MD_GBP/USD_140109778778268=5279=1269=0270=1.25496271=10000055=GBP/USD110=0279=1269=0270=1.25496271=50000055=GBP/USD110=100000279=1269=0270=1.25496271=100000055=GBP/USD110=500000279=1269=0270=1.25496271=300000055=GBP/USD110=1000000279=1269=0270=1.25496271=500000055=GBP/USD110=300000010=063
20260120-14:01:40.413702000 : 8=FIX.4.49=7635=034=649=SIRIUS_500007460_MD52=20260120-14:01:40.41256=NTPRO_IDBA_UAT10=011
20260120-14:01:40.664277000 : 8=FIX.4.49=039735=X49=NTPRO_IDBA_UAT56=SIRIUS_500007460_MD34=33752=20260120-14:01:41.234262=MD_GBP/USD_140109778778268=5279=1269=0270=1.25495271=10000055=GBP/USD110=0279=1269=0270=1.25495271=50000055=GBP/USD110=100000279=1269=0270=1.25495271=100000055=GBP/USD110=500000279=1269=0270=1.25495271=300000055=GBP/USD110=1000000279=1269=0270=1.25495271=500000055=GBP/USD110=300000010=052
20260120-14:01:40.725262000 : 8=FIX.4.49=039235=X49=NTPRO_IDBA_UAT56=SIRIUS_500007460_MD34=33852=20260120-14:01:41.296262=MD_GBP/USD_140109778778268=5279=1269=1270=1.4353271=10000055=GBP/USD110=0279=1269=1270=1.4353271=50000055=GBP/USD110=100000279=1269=1270=1.4353271=100000055=GBP/USD110=500000279=1269=1270=1.4353271=300000055=GBP/USD110=1000000279=1269=1270=1.4353271=500000055=GBP/USD110=300000010=027
20260120-14:01:40.777583000 : 8=FIX.4.49=039735=X49=NTPRO_IDBA_UAT56=SIRIUS_500007460_MD34=33952=20260120-14:01:41.345262=MD_GBP/USD_140109778778268=5279=1269=1270=1.43529271=10000055=GBP/USD110=0279=1269=1270=1.43529271=50000055=GBP/USD110=100000279=1269=1270=1.43529271=100000055=GBP/USD110=500000279=1269=1270=1.43529271=300000055=GBP/USD110=1000000279=1269=1270=1.43529271=500000055=GBP/USD110=300000010=052
20260120-14:01:40.801254000 : 8=FIX.4.49=039235=X49=NTPRO_IDBA_UAT56=SIRIUS_500007460_MD34=34052=20260120-14:01:41.371262=MD_GBP/USD_140109778778268=5279=1269=1270=1.4353271=10000055=GBP/USD110=0279=1269=1270=1.4353271=50000055=GBP/USD110=100000279=1269=1270=1.4353271=100000055=GBP/USD110=500000279=1269=1270=1.4353271=300000055=GBP/USD110=1000000279=1269=1270=1.4353271=500000055=GBP/USD110=300000010=014
20260120-14:01:40.996238000 : 8=FIX.4.49=027935=X49=NTPRO_IDBA_UAT56=SIRIUS_500007460_MD34=34152=20260120-14:01:41.575262=MD_EUR/USD_140109278614268=3279=1269=0270=1.14825271=10000055=EUR/USD110=0279=1269=0270=1.14825271=50000055=EUR/USD110=100000279=1269=0270=1.14825271=100000055=EUR/USD110=50000010=207
20260120-14:01:40.997160000 : 8=FIX.4.49=068335=X49=NTPRO_IDBA_UAT56=SIRIUS_500007460_MD34=34252=20260120-14:01:41.576262=MD_GBP/USD_140109778778268=10279=1269=0270=1.25494271=10000055=GBP/USD110=0279=1269=0270=1.25494271=50000055=GBP/USD110=100000279=1269=0270=1.25494271=100000055=GBP/USD110=500000279=1269=0270=1.25494271=300000055=GBP/USD110=1000000279=1269=0270=1.25494271=500000055=GBP/USD110=3000000279=1269=1270=1.43529271=10000055=GBP/USD110=0279=1269=1270=1.43529271=50000055=GBP/USD110=100000279=1269=1270=1.43529271=100000055=GBP/USD110=500000279=1269=1270=1.43529271=300000055=GBP/USD110=1000000279=1269=1270=1.43529271=500000055=GBP/USD110=300000010=225
20260120-14:01:41.699148000 : 8=FIX.4.49=039735=X49=NTPRO_IDBA_UAT56=SIRIUS_500007460_MD34=34352=20260120-14:01:42.309262=MD_GBP/USD_140109778778268=5279=1269=0270=1.25495271=10000055=GBP/USD110=0279=1269=0270=1.25495271=50000055=GBP/USD110=100000279=1269=0270=1.25495271=100000055=GBP/USD110=500000279=1269=0270=1.25495271=300000055=GBP/USD110=1000000279=1269=0270=1.25495271=500000055=GBP/USD110=300000010=053
20260120-14:01:41.794295000 : 8=FIX.4.49=044635=X49=NTPRO_IDBA_UAT56=SIRIUS_500007460_MD34=34452=20260120-14:01:42.409262=MD_EUR/USD_140109278614268=6279=1269=0270=1.14826271=10000055=EUR/USD110=0279=1269=0270=1.14826271=50000055=EUR/USD110=100000279=1269=0270=1.14826271=100000055=EUR/USD110=500000279=1269=1270=1.19851271=10000055=EUR/USD110=0279=1269=1270=1.19851271=50000055=EUR/USD110=100000279=1269=1270=1.19851271=100000055=EUR/USD110=50000010=000
20260120-14:01:41.810379000 : 8=FIX.4.49=067835=X49=NTPRO_IDBA_UAT56=SIRIUS_500007460_MD34=34552=20260120-14:01:42.425262=MD_GBP/USD_140109778778268=10279=1269=0270=1.25494271=10000055=GBP/USD110=0279=1269=0270=1.25494271=50000055=GBP/USD110=100000279=1269=0270=1.25494271=100000055=GBP/USD110=500000279=1269=0270=1.25494271=300000055=GBP/USD110=1000000279=1269=0270=1.25494271=500000055=GBP/USD110=3000000279=1269=1270=1.4353271=10000055=GBP/USD110=0279=1269=1270=1.4353271=50000055=GBP/USD110=100000279=1269=1270=1.4353271=100000055=GBP/USD110=500000279=1269=1270=1.4353271=300000055=GBP/USD110=1000000279=1269=1270=1.4353271=500000055=GBP/USD110=300000010=202
20260120-14:01:41.951680000 : 8=FIX.4.49=039735=X49=NTPRO_IDBA_UAT56=SIRIUS_500007460_MD34=34652=20260120-14:01:42.569262=MD_GBP/USD_140109778778268=5279=1269=1270=1.43529271=10000055=GBP/USD110=0279=1269=1270=1.43529271=50000055=GBP/USD110=100000279=1269=1270=1.43529271=100000055=GBP/USD110=500000279=1269=1270=1.43529271=300000055=GBP/USD110=1000000279=1269=1270=1.43529271=500000055=GBP/USD110=300000010=059
20260120-14:01:41.987234000 : 8=FIX.4.49=067835=X49=NTPRO_IDBA_UAT56=SIRIUS_500007460_MD34=34752=20260120-14:01:42.608262=MD_GBP/USD_140109778778268=10279=1269=0270=1.25495271=10000055=GBP/USD110=0279=1269=0270=1.25495271=50000055=GBP/USD110=100000279=1269=0270=1.25495271=100000055=GBP/USD110=500000279=1269=0270=1.25495271=300000055=GBP/USD110=1000000279=1269=0270=1.25495271=500000055=GBP/USD110=3000000279=1269=1270=1.4353271=10000055=GBP/USD110=0279=1269=1270=1.4353271=50000055=GBP/USD110=100000279=1269=1270=1.4353271=100000055=GBP/USD110=500000279=1269=1270=1.4353271=300000055=GBP/USD110=1000000279=1269=1270=1.4353271=500000055=GBP/USD110=300000010=212
20260120-14:01:42.172512000 : 8=FIX.4.49=044635=X49=NTPRO_IDBA_UAT56=SIRIUS_500007460_MD34=34852=20260120-14:01:42.793262=MD_EUR/USD_140109278614268=6279=1269=0270=1.14828271=10000055=EUR/USD110=0279=1269=0270=1.14828271=50000055=EUR/USD110=100000279=1269=0270=1.14828271=100000055=EUR/USD110=500000279=1269=1270=1.19852271=10000055=EUR/USD110=0279=1269=1270=1.19852271=50000055=EUR/USD110=100000279=1269=1270=1.19852271=100000055=EUR/USD110=50000010=019
20260120-14:01:42.172897000 : 8=FIX.4.49=039735=X49=NTPRO_IDBA_UAT56=SIRIUS_500007460_MD34=34952=20260120-14:01:42.798262=MD_GBP/USD_140109778778268=5279=1269=0270=1.25494271=10000055=GBP/USD110=0279=1269=0270=1.25494271=50000055=GBP/USD110=100000279=1269=0270=1.25494271=100000055=GBP/USD110=500000279=1269=0270=1.25494271=300000055=GBP/USD110=1000000279=1269=0270=1.25494271=500000055=GBP/USD110=300000010=066
20260120-14:01:42.195438000 : 8=FIX.4.49=039735=X49=NTPRO_IDBA_UAT56=SIRIUS_500007460_MD34=35052=20260120-14:01:42.826262=MD_GBP/USD_140109778778268=5279=1269=0270=1.25496271=10000055=GBP/USD110=0279=1269=0270=1.25496271=50000055=GBP/USD110=100000279=1269=0270=1.25496271=100000055=GBP/USD110=500000279=1269=0270=1.25496271=300000055=GBP/USD110=1000000279=1269=0270=1.25496271=500000055=GBP/USD110=300000010=060
20260120-14:01:42.232542000 : 8=FIX.4.49=039735=X49=NTPRO_IDBA_UAT56=SIRIUS_500007460_MD34=35152=20260120-14:01:42.865262=MD_GBP/USD_140109778778268=5279=1269=1270=1.43532271=10000055=GBP/USD110=0279=1269=1270=1.43532271=50000055=GBP/USD110=100000279=1269=1270=1.43532271=100000055=GBP/USD110=500000279=1269=1270=1.43532271=300000055=GBP/USD110=1000000279=1269=1270=1.43532271=500000055=GBP/USD110=300000010=024
20260120-14:01:42.276248000 : 8=FIX.4.49=068335=X49=NTPRO_IDBA_UAT56=SIRIUS_500007460_MD34=35252=20260120-14:01:42.910262=MD_GBP/USD_140109778778268=10279=1269=0270=1.25497271=10000055=GBP/USD110=0279=1269=0270=1.25497271=50000055=GBP/USD110=100000279=1269=0270=1.25497271=100000055=GBP/USD110=500000279=1269=0270=1.25497271=300000055=GBP/USD110=1000000279=1269=0270=1.25497271=500000055=GBP/USD110=3000000279=1269=1270=1.43531271=10000055=GBP/USD110=0279=1269=1270=1.43531271=50000055=GBP/USD110=100000279=1269=1270=1.43531271=100000055=GBP/USD110=500000279=1269=1270=1.43531271=300000055=GBP/USD110=1000000279=1269=1270=1.43531271=500000055=GBP/USD110=300000010=199
20260120-14:01:43.197094000 : 8=FIX.4.49=027935=X49=NTPRO_IDBA_UAT56=SIRIUS_500007460_MD34=35352=20260120-14:01:43.866262=MD_EUR/USD_140109278614268=3279=1269=0270=1.14827271=10000055=EUR/USD110=0279=1269=0270=1.14827271=50000055=EUR/USD110=100000279=1269=0270=1.14827271=100000055=EUR/USD110=50000010=221
20260120-14:01:43.463638000 : 8=FIX.4.49=044635=X49=NTPRO_IDBA_UAT56=SIRIUS_500007460_MD34=35452=20260120-14:01:44.127262=MD_EUR/USD_140109278614268=6279=1269=0270=1.14828271=10000055=EUR/USD110=0279=1269=0270=1.14828271=50000055=EUR/USD110=100000279=1269=0270=1.14828271=100000055=EUR/USD110=500000279=1269=1270=1.19853271=10000055=EUR/USD110=0279=1269=1270=1.19853271=50000055=EUR/USD110=100000279=1269=1270=1.19853271=100000055=EUR/USD110=50000010=012
20260120-14:01:43.492397000 : 8=FIX.4.49=027935=X49=NTPRO_IDBA_UAT56=SIRIUS_500007460_MD34=35552=20260120-14:01:44.172262=MD_EUR/USD_140109278614268=3279=1269=0270=1.14829271=10000055=EUR/USD110=0279=1269=0270=1.14829271=50000055=EUR/USD110=100000279=1269=0270=1.14829271=100000055=EUR/USD110=50000010=220
20260120-14:01:43.598114000 : 8=FIX.4.49=027935=X49=NTPRO_IDBA_UAT56=SIRIUS_500007460_MD34=35652=20260120-14:01:44.283262=MD_EUR/USD_140109278614268=3279=1269=1270=1.19854271=10000055=EUR/USD110=0279=1269=1270=1.19854271=50000055=EUR/USD110=100000279=1269=1270=1.19854271=100000055=EUR/USD110=50000010=236
20260120-14:01:44.026068000 : 8=FIX.4.49=027935=X49=NTPRO_IDBA_UAT56=SIRIUS_500007460_MD34=35752=20260120-14:01:44.724262=MD_EUR/USD_140109278614268=3279=1269=1270=1.19853271=10000055=EUR/USD110=0279=1269=1270=1.19853271=50000055=EUR/USD110=100000279=1269=1270=1.19853271=100000055=EUR/USD110=50000010=234
20260120-14:01:44.083918000 : 8=FIX.4.49=039235=X49=NTPRO_IDBA_UAT56=SIRIUS_500007460_MD34=35852=20260120-14:01:44.788262=MD_GBP/USD_140109778778268=5279=1269=1270=1.4353271=10000055=GBP/USD110=0279=1269=1270=1.4353271=50000055=GBP/USD110=100000279=1269=1270=1.4353271=100000055=GBP/USD110=500000279=1269=1270=1.4353271=300000055=GBP/USD110=1000000279=1269=1270=1.4353271=500000055=GBP/USD110=300000010=038
20260120-14:01:44.084407000 : 8=FIX.4.49=027935=X49=NTPRO_IDBA_UAT56=SIRIUS_500007460_MD34=35952=20260120-14:01:44.790262=MD_EUR/USD_140109278614268=3279=1269=0270=1.14828271=10000055=EUR/USD110=0279=1269=0270=1.14828271=50000055=EUR/USD110=100000279=1269=0270=1.14828271=100000055=EUR/USD110=50000010=227
20260120-14:01:44.145062000 : 8=FIX.4.49=067835=X49=NTPRO_IDBA_UAT56=SIRIUS_500007460_MD34=36052=20260120-14:01:44.839262=MD_GBP/USD_140109778778268=10279=2269=0270=1.25497271=10000055=GBP/USD110=0279=2269=0270=1.25497271=50000055=GBP/USD110=100000279=2269=0270=1.25497271=100000055=GBP/USD110=500000279=2269=0270=1.25497271=300000055=GBP/USD110=1000000279=2269=0270=1.25497271=500000055=GBP/USD110=3000000279=2269=1270=1.4353271=10000055=GBP/USD110=0279=2269=1270=1.4353271=50000055=GBP/USD110=100000279=2269=1270=1.4353271=100000055=GBP/USD110=500000279=2269=1270=1.4353271=300000055=GBP/USD110=1000000279=2269=1270=1.4353271=500000055=GBP/USD110=300000010=235
20260120-14:01:44.157229000 : 8=FIX.4.49=027935=X49=NTPRO_IDBA_UAT56=SIRIUS_500007460_MD34=36152=20260120-14:01:44.866262=MD_EUR/USD_140109278614268=3279=1269=1270=1.19852271=10000055=EUR/USD110=0279=1269=1270=1.19852271=50000055=EUR/USD110=100000279=1269=1270=1.19852271=100000055=EUR/USD110=50000010=233
20260120-14:01:44.179799000 : 8=FIX.4.49=068335=X49=NTPRO_IDBA_UAT56=SIRIUS_500007460_MD34=36252=20260120-14:01:44.888262=MD_GBP/USD_140109778778268=10279=0269=0270=1.25495271=10000055=GBP/USD110=0279=0269=0270=1.25495271=50000055=GBP/USD110=100000279=0269=0270=1.25495271=100000055=GBP/USD110=500000279=0269=0270=1.25495271=300000055=GBP/USD110=1000000279=0269=0270=1.25495271=500000055=GBP/USD110=3000000279=0269=1270=1.43531271=10000055=GBP/USD110=0279=0269=1270=1.43531271=50000055=GBP/USD110=100000279=0269=1270=1.43531271=100000055=GBP/USD110=500000279=0269=1270=1.43531271=300000055=GBP/USD110=1000000279=0269=1270=1.43531271=500000055=GBP/USD110=300000010=196
20260120-14:01:44.511568000 : 8=FIX.4.49=039735=X49=NTPRO_IDBA_UAT56=SIRIUS_500007460_MD34=36352=20260120-14:01:45.233262=MD_GBP/USD_140109778778268=5279=1269=0270=1.25496271=10000055=GBP/USD110=0279=1269=0270=1.25496271=50000055=GBP/USD110=100000279=1269=0270=1.25496271=100000055=GBP/USD110=500000279=1269=0270=1.25496271=300000055=GBP/USD110=1000000279=1269=0270=1.25496271=500000055=GBP/USD110=300000010=059
20260120-14:01:44.617283000 : 8=FIX.4.49=068335=X49=NTPRO_IDBA_UAT56=SIRIUS_500007460_MD34=36452=20260120-14:01:45.343262=MD_GBP/USD_140109778778268=10279=1269=0270=1.25497271=10000055=GBP/USD110=0279=1269=0270=1.25497271=50000055=GBP/USD110=100000279=1269=0270=1.25497271=100000055=GBP/USD110=500000279=1269=0270=1.25497271=300000055=GBP/USD110=1000000279=1269=0270=1.25497271=500000055=GBP/USD110=3000000279=1269=1270=1.43532271=10000055=GBP/USD110=0279=1269=1270=1.43532271=50000055=GBP/USD110=100000279=1269=1270=1.43532271=100000055=GBP/USD110=500000279=1269=1270=1.43532271=300000055=GBP/USD110=1000000279=1269=1270=1.43532271=500000055=GBP/USD110=300000010=210
20260120-14:01:44.640252000 : 8=FIX.4.49=044635=X49=NTPRO_IDBA_UAT56=SIRIUS_500007460_MD34=36552=20260120-14:01:45.364262=MD_EUR/USD_140109278614268=6279=1269=0270=1.14827271=10000055=EUR/USD110=0279=1269=0270=1.14827271=50000055=EUR/USD110=100000279=1269=0270=1.14827271=100000055=EUR/USD110=500000279=1269=1270=1.19851271=10000055=EUR/USD110=0279=1269=1270=1.19851271=50000055=EUR/USD110=100000279=1269=1270=1.19851271=100000055=EUR/USD110=50000010=009
20260120-14:01:44.685413000 : 8=FIX.4.49=044335=X49=NTPRO_IDBA_UAT56=SIRIUS_500007460_MD34=36652=20260120-14:01:45.413262=MD_EUR/USD_140109278614268=6279=1269=0270=1.14825271=10000055=EUR/USD110=0279=1269=0270=1.14825271=50000055=EUR/USD110=100000279=1269=0270=1.14825271=100000055=EUR/USD110=500000279=1269=1270=1.1985271=10000055=EUR/USD110=0279=1269=1270=1.1985271=50000055=EUR/USD110=100000279=1269=1270=1.1985271=100000055=EUR/USD110=50000010=105
20260120-14:01:44.721577000 : 8=FIX.4.49=068335=X49=NTPRO_IDBA_UAT56=SIRIUS_500007460_MD34=36752=20260120-14:01:45.446262=MD_GBP/USD_140109778778268=10279=1269=0270=1.25496271=10000055=GBP/USD110=0279=1269=0270=1.25496271=50000055=GBP/USD110=100000279=1269=0270=1.25496271=100000055=GBP/USD110=500000279=1269=0270=1.25496271=300000055=GBP/USD110=1000000279=1269=0270=1.25496271=500000055=GBP/USD110=3000000279=1269=1270=1.43531271=10000055=GBP/USD110=0279=1269=1270=1.43531271=50000055=GBP/USD110=100000279=1269=1270=1.43531271=100000055=GBP/USD110=500000279=1269=1270=1.43531271=300000055=GBP/USD110=1000000279=1269=1270=1.43531271=500000055=GBP/USD110=300000010=207
20260120-14:01:45.099950000 : 8=FIX.4.49=039735=X49=NTPRO_IDBA_UAT56=SIRIUS_500007460_MD34=36852=20260120-14:01:45.502262=MD_GBP/USD_140109778778268=5279=1269=1270=1.43532271=10000055=GBP/USD110=0279=1269=1270=1.43532271=50000055=GBP/USD110=100000279=1269=1270=1.43532271=100000055=GBP/USD110=500000279=1269=1270=1.43532271=300000055=GBP/USD110=1000000279=1269=1270=1.43532271=500000055=GBP/USD110=300000010=023
20260120-14:01:45.100426000 : 8=FIX.4.49=068335=X49=NTPRO_IDBA_UAT56=SIRIUS_500007460_MD34=36952=20260120-14:01:45.743262=MD_GBP/USD_140109778778268=10279=2269=0270=1.25496271=10000055=GBP/USD110=0279=2269=0270=1.25496271=50000055=GBP/USD110=100000279=2269=0270=1.25496271=100000055=GBP/USD110=500000279=2269=0270=1.25496271=300000055=GBP/USD110=1000000279=2269=0270=1.25496271=500000055=GBP/USD110=3000000279=2269=1270=1.43532271=10000055=GBP/USD110=0279=2269=1270=1.43532271=50000055=GBP/USD110=100000279=2269=1270=1.43532271=100000055=GBP/USD110=500000279=2269=1270=1.43532271=300000055=GBP/USD110=1000000279=2269=1270=1.43532271=500000055=GBP/USD110=300000010=224
20260120-14:01:45.205850000 : 8=FIX.4.49=068335=X49=NTPRO_IDBA_UAT56=SIRIUS_500007460_MD34=37052=20260120-14:01:45.904262=MD_GBP/USD_140109778778268=10279=0269=0270=1.25496271=10000055=GBP/USD110=0279=0269=0270=1.25496271=50000055=GBP/USD110=100000279=0269=0270=1.25496271=100000055=GBP/USD110=500000279=0269=0270=1.25496271=300000055=GBP/USD110=1000000279=0269=0270=1.25496271=500000055=GBP/USD110=3000000279=0269=1270=1.43532271=10000055=GBP/USD110=0279=0269=1270=1.43532271=50000055=GBP/USD110=100000279=0269=1270=1.43532271=100000055=GBP/USD110=500000279=0269=1270=1.43532271=300000055=GBP/USD110=1000000279=0269=1270=1.43532271=500000055=GBP/USD110=300000010=195
20260120-14:01:45.617330000 : 8=FIX.4.49=039735=X49=NTPRO_IDBA_UAT56=SIRIUS_500007460_MD34=37152=20260120-14:01:46.376262=MD_GBP/USD_140109778778268=5279=1269=0270=1.25497271=10000055=GBP/USD110=0279=1269=0270=1.25497271=50000055=GBP/USD110=100000279=1269=0270=1.25497271=100000055=GBP/USD110=500000279=1269=0270=1.25497271=300000055=GBP/USD110=1000000279=1269=0270=1.25497271=500000055=GBP/USD110=300000010=072
20260120-14:01:45.635004000 : 8=FIX.4.49=044635=X49=NTPRO_IDBA_UAT56=SIRIUS_500007460_MD34=37252=20260120-14:01:46.400262=MD_EUR/USD_140109278614268=6279=1269=0270=1.14827271=10000055=EUR/USD110=0279=1269=0270=1.14827271=50000055=EUR/USD110=100000279=1269=0270=1.14827271=100000055=EUR/USD110=500000279=1269=1270=1.19851271=10000055=EUR/USD110=0279=1269=1270=1.19851271=50000055=EUR/USD110=100000279=1269=1270=1.19851271=100000055=EUR/USD110=50000010=255
20260120-14:01:45.645635000 : 8=FIX.4.49=068335=X49=NTPRO_IDBA_UAT56=SIRIUS_500007460_MD34=37352=20260120-14:01:46.410262=MD_GBP/USD_140109778778268=10279=2269=0270=1.25497271=10000055=GBP/USD110=0279=2269=0270=1.25497271=50000055=GBP/USD110=100000279=2269=0270=1.25497271=100000055=GBP/USD110=500000279=2269=0270=1.25497271=300000055=GBP/USD110=1000000279=2269=0270=1.25497271=500000055=GBP/USD110=3000000279=2269=1270=1.43532271=10000055=GBP/USD110=0279=2269=1270=1.43532271=50000055=GBP/USD110=100000279=2269=1270=1.43532271=100000055=GBP/USD110=500000279=2269=1270=1.43532271=300000055=GBP/USD110=1000000279=2269=1270=1.43532271=500000055=GBP/USD110=300000010=216
20260120-14:01:45.683220000 : 8=FIX.4.49=068335=X49=NTPRO_IDBA_UAT56=SIRIUS_500007460_MD34=37452=20260120-14:01:46.452262=MD_GBP/USD_140109778778268=10279=0269=0270=1.25503271=10000055=GBP/USD110=0279=0269=0270=1.25503271=50000055=GBP/USD110=100000279=0269=0270=1.25503271=100000055=GBP/USD110=500000279=0269=0270=1.25503271=300000055=GBP/USD110=1000000279=0269=0270=1.25503271=500000055=GBP/USD110=3000000279=0269=1270=1.43537271=10000055=GBP/USD110=0279=0269=1270=1.43537271=50000055=GBP/USD110=100000279=0269=1270=1.43537271=100000055=GBP/USD110=500000279=0269=1270=1.43537271=300000055=GBP/USD110=1000000279=0269=1270=1.43537271=500000055=GBP/USD110=300000010=168
20260120-14:01:45.737891000 : 8=FIX.4.49=027935=X49=NTPRO_IDBA_UAT56=SIRIUS_500007460_MD34=37552=20260120-14:01:46.496262=MD_EUR/USD_140109278614268=3279=1269=1270=1.19852271=10000055=EUR/USD110=0279=1269=1270=1.19852271=50000055=EUR/USD110=100000279=1269=1270=1.19852271=100000055=EUR/USD110=50000010=239
20260120-14:01:45.738489000 : 8=FIX.4.49=039735=X49=NTPRO_IDBA_UAT56=SIRIUS_500007460_MD34=37652=20260120-14:01:46.499262=MD_GBP/USD_140109778778268=5279=1269=1270=1.43538271=10000055=GBP/USD110=0279=1269=1270=1.43538271=50000055=GBP/USD110=100000279=1269=1270=1.43538271=100000055=GBP/USD110=500000279=1269=1270=1.43538271=300000055=GBP/USD110=1000000279=1269=1270=1.43538271=500000055=GBP/USD110=300000010=068
20260120-14:01:45.769899000 : 8=FIX.4.49=068335=X49=NTPRO_IDBA_UAT56=SIRIUS_500007460_MD34=37752=20260120-14:01:46.538262=MD_GBP/USD_140109778778268=10279=2269=0270=1.25503271=10000055=GBP/USD110=0279=2269=0270=1.25503271=50000055=GBP/USD110=100000279=2269=0270=1.25503271=100000055=GBP/USD110=500000279=2269=0270=1.25503271=300000055=GBP/USD110=1000000279=2269=0270=1.25503271=500000055=GBP/USD110=3000000279=2269=1270=1.43538271=10000055=GBP/USD110=0279=2269=1270=1.43538271=50000055=GBP/USD110=100000279=2269=1270=1.43538271=100000055=GBP/USD110=500000279=2269=1270=1.43538271=300000055=GBP/USD110=1000000279=2269=1270=1.43538271=500000055=GBP/USD110=300000010=201
20260120-14:01:45.899064000 : 8=FIX.4.49=027935=X49=NTPRO_IDBA_UAT56=SIRIUS_500007460_MD34=37852=20260120-14:01:46.677262=MD_EUR/USD_140109278614268=3279=1269=0270=1.14828271=10000055=EUR/USD110=0279=1269=0270=1.14828271=50000055=EUR/USD110=100000279=1269=0270=1.14828271=100000055=EUR/USD110=50000010=234
20260120-14:01:45.994994000 : 8=FIX.4.49=068335=X49=NTPRO_IDBA_UAT56=SIRIUS_500007460_MD34=37952=20260120-14:01:46.776262=MD_GBP/USD_140109778778268=10279=0269=0270=1.25503271=10000055=GBP/USD110=0279=0269=0270=1.25503271=50000055=GBP/USD110=100000279=0269=0270=1.25503271=100000055=GBP/USD110=500000279=0269=0270=1.25503271=300000055=GBP/USD110=1000000279=0269=0270=1.25503271=500000055=GBP/USD110=3000000279=0269=1270=1.43538271=10000055=GBP/USD110=0279=0269=1270=1.43538271=50000055=GBP/USD110=100000279=0269=1270=1.43538271=100000055=GBP/USD110=500000279=0269=1270=1.43538271=300000055=GBP/USD110=1000000279=0269=1270=1.43538271=500000055=GBP/USD110=300000010=187
20260120-14:01:46.066762000 : 8=FIX.4.49=039735=X49=NTPRO_IDBA_UAT56=SIRIUS_500007460_MD34=38052=20260120-14:01:46.852262=MD_GBP/USD_140109778778268=5279=1269=1270=1.43537271=10000055=GBP/USD110=0279=1269=1270=1.43537271=50000055=GBP/USD110=100000279=1269=1270=1.43537271=100000055=GBP/USD110=500000279=1269=1270=1.43537271=300000055=GBP/USD110=1000000279=1269=1270=1.43537271=500000055=GBP/USD110=300000010=051
20260120-14:01:46.119600000 : 8=FIX.4.49=039735=X49=NTPRO_IDBA_UAT56=SIRIUS_500007460_MD34=38152=20260120-14:01:46.892262=MD_GBP/USD_140109778778268=5279=1269=1270=1.43538271=10000055=GBP/USD110=0279=1269=1270=1.43538271=50000055=GBP/USD110=100000279=1269=1270=1.43538271=100000055=GBP/USD110=500000279=1269=1270=1.43538271=300000055=GBP/USD110=1000000279=1269=1270=1.43538271=500000055=GBP/USD110=300000010=061
20260120-14:01:46.160075000 : 8=FIX.4.49=039735=X49=NTPRO_IDBA_UAT56=SIRIUS_500007460_MD34=38252=20260120-14:01:46.949262=MD_GBP/USD_140109778778268=5279=1269=1270=1.43537271=10000055=GBP/USD110=0279=1269=1270=1.43537271=50000055=GBP/USD110=100000279=1269=1270=1.43537271=100000055=GBP/USD110=500000279=1269=1270=1.43537271=300000055=GBP/USD110=1000000279=1269=1270=1.43537271=500000055=GBP/USD110=300000010=060
20260120-14:01:46.315569000 : 8=FIX.4.49=039735=X49=NTPRO_IDBA_UAT56=SIRIUS_500007460_MD34=38352=20260120-14:01:47.081262=MD_GBP/USD_140109778778268=5279=1269=1270=1.43538271=10000055=GBP/USD110=0279=1269=1270=1.43538271=50000055=GBP/USD110=100000279=1269=1270=1.43538271=100000055=GBP/USD110=500000279=1269=1270=1.43538271=300000055=GBP/USD110=1000000279=1269=1270=1.43538271=500000055=GBP/USD110=300000010=054
20260120-14:01:46.345058000 : 8=FIX.4.49=039735=X49=NTPRO_IDBA_UAT56=SIRIUS_500007460_MD34=38452=20260120-14:01:47.140262=MD_GBP/USD_140109778778268=5279=1269=1270=1.43537271=10000055=GBP/USD110=0279=1269=1270=1.43537271=50000055=GBP/USD110=100000279=1269=1270=1.43537271=100000055=GBP/USD110=500000279=1269=1270=1.43537271=300000055=GBP/USD110=1000000279=1269=1270=1.43537271=500000055=GBP/USD110=300000010=046
20260120-14:01:46.375256000 : 8=FIX.4.49=027935=X49=NTPRO_IDBA_UAT56=SIRIUS_500007460_MD34=38552=20260120-14:01:47.172262=MD_EUR/USD_140109278614268=3279=1269=0270=1.14827271=10000055=EUR/USD110=0279=1269=0270=1.14827271=50000055=EUR/USD110=100000279=1269=0270=1.14827271=100000055=EUR/USD110=50000010=220
20260120-14:01:46.410438000 : 8=FIX.4.49=039735=X49=NTPRO_IDBA_UAT56=SIRIUS_500007460_MD34=38652=20260120-14:01:47.206262=MD_GBP/USD_140109778778268=5279=1269=1270=1.43536271=10000055=GBP/USD110=0279=1269=1270=1.43536271=50000055=GBP/USD110=100000279=1269=1270=1.43536271=100000055=GBP/USD110=500000279=1269=1270=1.43536271=300000055=GBP/USD110=1000000279=1269=1270=1.43536271=500000055=GBP/USD110=300000010=046
20260120-14:01:46.446894000 : 8=FIX.4.49=039735=X49=NTPRO_IDBA_UAT56=SIRIUS_500007460_MD34=38752=20260120-14:01:47.246262=MD_GBP/USD_140109778778268=5279=1269=1270=1.43535271=10000055=GBP/USD110=0279=1269=1270=1.43535271=50000055=GBP/USD110=100000279=1269=1270=1.43535271=100000055=GBP/USD110=500000279=1269=1270=1.43535271=300000055=GBP/USD110=1000000279=1269=1270=1.43535271=500000055=GBP/USD110=300000010=046
20260120-14:01:46.478663000 : 8=FIX.4.49=044635=X49=NTPRO_IDBA_UAT56=SIRIUS_500007460_MD34=38852=20260120-14:01:47.279262=MD_EUR/USD_140109278614268=6279=1269=0270=1.14826271=10000055=EUR/USD110=0279=1269=0270=1.14826271=50000055=EUR/USD110=100000279=1269=0270=1.14826271=100000055=EUR/USD110=500000279=1269=1270=1.19851271=10000055=EUR/USD110=0279=1269=1270=1.19851271=50000055=EUR/USD110=100000279=1269=1270=1.19851271=100000055=EUR/USD110=50000010=018
20260120-14:01:46.487042000 : 8=FIX.4.49=068335=X49=NTPRO_IDBA_UAT56=SIRIUS_500007460_MD34=38952=20260120-14:01:47.287262=MD_GBP/USD_140109778778268=10279=1269=0270=1.25499271=10000055=GBP/USD110=0279=1269=0270=1.25499271=50000055=GBP/USD110=100000279=1269=0270=1.25499271=100000055=GBP/USD110=500000279=1269=0270=1.25499271=300000055=GBP/USD110=1000000279=1269=0270=1.25499271=500000055=GBP/USD110=3000000279=1269=1270=1.43534271=10000055=GBP/USD110=0279=1269=1270=1.43534271=50000055=GBP/USD110=100000279=1269=1270=1.43534271=100000055=GBP/USD110=500000279=1269=1270=1.43534271=300000055=GBP/USD110=1000000279=1269=1270=1.43534271=500000055=GBP/USD110=300000010=246
20260120-14:01:46.609104000 : 8=FIX.4.49=039735=X49=NTPRO_IDBA_UAT56=SIRIUS_500007460_MD34=39052=20260120-14:01:47.409262=MD_GBP/USD_140109778778268=5279=1269=0270=1.25498271=10000055=GBP/USD110=0279=1269=0270=1.25498271=50000055=GBP/USD110=100000279=1269=0270=1.25498271=100000055=GBP/USD110=500000279=1269=0270=1.25498271=300000055=GBP/USD110=1000000279=1269=0270=1.25498271=500000055=GBP/USD110=300000010=076
20260120-14:01:46.693014000 : 8=FIX.4.49=027635=X49=NTPRO_IDBA_UAT56=SIRIUS_500007460_MD34=39152=20260120-14:01:47.497262=MD_EUR/USD_140109278614268=3279=1269=1270=1.1985271=10000055=EUR/USD110=0279=1269=1270=1.1985271=50000055=EUR/USD110=100000279=1269=1270=1.1985271=100000055=EUR/USD110=50000010=086
20260120-14:01:46.721596000 : 8=FIX.4.49=039735=X49=NTPRO_IDBA_UAT56=SIRIUS_500007460_MD34=39252=20260120-14:01:47.531262=MD_GBP/USD_140109778778268=5279=1269=0270=1.25497271=10000055=GBP/USD110=0279=1269=0270=1.25497271=50000055=GBP/USD110=100000279=1269=0270=1.25497271=100000055=GBP/USD110=500000279=1269=0270=1.25497271=300000055=GBP/USD110=1000000279=1269=0270=1.25497271=500000055=GBP/USD110=300000010=069
20260120-14:01:46.759724000 : 8=FIX.4.49=039735=X49=NTPRO_IDBA_UAT56=SIRIUS_500007460_MD34=39352=20260120-14:01:47.571262=MD_GBP/USD_140109778778268=5279=1269=1270=1.43532271=10000055=GBP/USD110=0279=1269=1270=1.43532271=50000055=GBP/USD110=100000279=1269=1270=1.43532271=100000055=GBP/USD110=500000279=1269=1270=1.43532271=300000055=GBP/USD110=1000000279=1269=1270=1.43532271=500000055=GBP/USD110=300000010=029
20260120-14:01:46.851998000 : 8=FIX.4.49=027935=X49=NTPRO_IDBA_UAT56=SIRIUS_500007460_MD34=39452=20260120-14:01:47.666262=MD_EUR/USD_140109278614268=3279=1269=0270=1.14825271=10000055=EUR/USD110=0279=1269=0270=1.14825271=50000055=EUR/USD110=100000279=1269=0270=1.14825271=100000055=EUR/USD110=50000010=222
20260120-14:01:46.965848000 : 8=FIX.4.49=068335=X49=NTPRO_IDBA_UAT56=SIRIUS_500007460_MD34=39552=20260120-14:01:47.783262=MD_GBP/USD_140109778778268=10279=2269=0270=1.25497271=10000055=GBP/USD110=0279=2269=0270=1.25497271=50000055=GBP/USD110=100000279=2269=0270=1.25497271=100000055=GBP/USD110=500000279=2269=0270=1.25497271=300000055=GBP/USD110=1000000279=2269=0270=1.25497271=500000055=GBP/USD110=3000000279=2269=1270=1.43532271=10000055=GBP/USD110=0279=2269=1270=1.43532271=50000055=GBP/USD110=100000279=2269=1270=1.43532271=100000055=GBP/USD110=500000279=2269=1270=1.43532271=300000055=GBP/USD110=1000000279=2269=1270=1.43532271=500000055=GBP/USD110=300000010=234
20260120-14:01:47.475694000 : 8=FIX.4.49=068335=X49=NTPRO_IDBA_UAT56=SIRIUS_500007460_MD34=39652=20260120-14:01:48.309262=MD_GBP/USD_140109778778268=10279=0269=0270=1.25497271=10000055=GBP/USD110=0279=0269=0270=1.25497271=50000055=GBP/USD110=100000279=0269=0270=1.25497271=100000055=GBP/USD110=500000279=0269=0270=1.25497271=300000055=GBP/USD110=1000000279=0269=0270=1.25497271=500000055=GBP/USD110=3000000279=0269=1270=1.43532271=10000055=GBP/USD110=0279=0269=1270=1.43532271=50000055=GBP/USD110=100000279=0269=1270=1.43532271=100000055=GBP/USD110=500000279=0269=1270=1.43532271=300000055=GBP/USD110=1000000279=0269=1270=1.43532271=500000055=GBP/USD110=300000010=210
20260120-14:01:47.761831000 : 8=FIX.4.49=039735=X49=NTPRO_IDBA_UAT56=SIRIUS_500007460_MD34=39752=20260120-14:01:48.608262=MD_GBP/USD_140109778778268=5279=1269=1270=1.43533271=10000055=GBP/USD110=0279=1269=1270=1.43533271=50000055=GBP/USD110=100000279=1269=1270=1.43533271=100000055=GBP/USD110=500000279=1269=1270=1.43533271=300000055=GBP/USD110=1000000279=1269=1270=1.43533271=500000055=GBP/USD110=300000010=040
20260120-14:01:47.928723000 : 8=FIX.4.49=068335=X49=NTPRO_IDBA_UAT56=SIRIUS_500007460_MD34=39852=20260120-14:01:48.781262=MD_GBP/USD_140109778778268=10279=2269=0270=1.25497271=10000055=GBP/USD110=0279=2269=0270=1.25497271=50000055=GBP/USD110=100000279=2269=0270=1.25497271=100000055=GBP/USD110=500000279=2269=0270=1.25497271=300000055=GBP/USD110=1000000279=2269=0270=1.25497271=500000055=GBP/USD110=3000000279=2269=1270=1.43533271=10000055=GBP/USD110=0279=2269=1270=1.43533271=50000055=GBP/USD110=100000279=2269=1270=1.43533271=100000055=GBP/USD110=500000279=2269=1270=1.43533271=300000055=GBP/USD110=1000000279=2269=1270=1.43533271=500000055=GBP/USD110=300000010=241
20260120-14:01:48.046687000 : 8=FIX.4.49=068335=X49=NTPRO_IDBA_UAT56=SIRIUS_500007460_MD34=39952=20260120-14:01:48.903262=MD_GBP/USD_140109778778268=10279=0269=0270=1.25497271=10000055=GBP/USD110=0279=0269=0270=1.25497271=50000055=GBP/USD110=100000279=0269=0270=1.25497271=100000055=GBP/USD110=500000279=0269=0270=1.25497271=300000055=GBP/USD110=1000000279=0269=0270=1.25497271=500000055=GBP/USD110=3000000279=0269=1270=1.43532271=10000055=GBP/USD110=0279=0269=1270=1.43532271=50000055=GBP/USD110=100000279=0269=1270=1.43532271=100000055=GBP/USD110=500000279=0269=1270=1.43532271=300000055=GBP/USD110=1000000279=0269=1270=1.43532271=500000055=GBP/USD110=300000010=213
20260120-14:01:48.748815000 : 8=FIX.4.49=068335=X49=NTPRO_IDBA_UAT56=SIRIUS_500007460_MD34=40052=20260120-14:01:49.628262=MD_GBP/USD_140109778778268=10279=2269=0270=1.25497271=10000055=GBP/USD110=0279=2269=0270=1.25497271=50000055=GBP/USD110=100000279=2269=0270=1.25497271=100000055=GBP/USD110=500000279=2269=0270=1.25497271=300000055=GBP/USD110=1000000279=2269=0270=1.25497271=500000055=GBP/USD110=3000000279=2269=1270=1.43532271=10000055=GBP/USD110=0279=2269=1270=1.43532271=50000055=GBP/USD110=100000279=2269=1270=1.43532271=100000055=GBP/USD110=500000279=2269=1270=1.43532271=300000055=GBP/USD110=1000000279=2269=1270=1.43532271=500000055=GBP/USD110=300000010=221
20260120-14:01:48.899424000 : 8=FIX.4.49=027935=X49=NTPRO_IDBA_UAT56=SIRIUS_500007460_MD34=40152=20260120-14:01:49.786262=MD_EUR/USD_140109278614268=3279=1269=1270=1.19849271=10000055=EUR/USD110=0279=1269=1270=1.19849271=50000055=EUR/USD110=100000279=1269=1270=1.19849271=100000055=EUR/USD110=50000010=252
20260120-14:01:49.019911000 : 8=FIX.4.49=027635=X49=NTPRO_IDBA_UAT56=SIRIUS_500007460_MD34=40252=20260120-14:01:49.908262=MD_EUR/USD_140109278614268=3279=1269=1270=1.1985271=10000055=EUR/USD110=0279=1269=1270=1.1985271=50000055=EUR/USD110=100000279=1269=1270=1.1985271=100000055=EUR/USD110=50000010=078
20260120-14:01:49.717912000 : 8=FIX.4.49=068335=X49=NTPRO_IDBA_UAT56=SIRIUS_500007460_MD34=40352=20260120-14:01:50.632262=MD_GBP/USD_140109778778268=10279=0269=0270=1.25498271=10000055=GBP/USD110=0279=0269=0270=1.25498271=50000055=GBP/USD110=100000279=0269=0270=1.25498271=100000055=GBP/USD110=500000279=0269=0270=1.25498271=300000055=GBP/USD110=1000000279=0269=0270=1.25498271=500000055=GBP/USD110=3000000279=0269=1270=1.43534271=10000055=GBP/USD110=0279=0269=1270=1.43534271=50000055=GBP/USD110=100000279=0269=1270=1.43534271=100000055=GBP/USD110=500000279=0269=1270=1.43534271=300000055=GBP/USD110=1000000279=0269=1270=1.43534271=500000055=GBP/USD110=300000010=206
20260120-14:01:49.801276000 : 8=FIX.4.49=039735=X49=NTPRO_IDBA_UAT56=SIRIUS_500007460_MD34=40452=20260120-14:01:50.720262=MD_GBP/USD_140109778778268=5279=1269=1270=1.43533271=10000055=GBP/USD110=0279=1269=1270=1.43533271=50000055=GBP/USD110=100000279=1269=1270=1.43533271=100000055=GBP/USD110=500000279=1269=1270=1.43533271=300000055=GBP/USD110=1000000279=1269=1270=1.43533271=500000055=GBP/USD110=300000010=017
20260120-14:01:49.870562000 : 8=FIX.4.49=039735=X49=NTPRO_IDBA_UAT56=SIRIUS_500007460_MD34=40552=20260120-14:01:50.791262=MD_GBP/USD_140109778778268=5279=1269=0270=1.25497271=10000055=GBP/USD110=0279=1269=0270=1.25497271=50000055=GBP/USD110=100000279=1269=0270=1.25497271=100000055=GBP/USD110=500000279=1269=0270=1.25497271=300000055=GBP/USD110=1000000279=1269=0270=1.25497271=500000055=GBP/USD110=300000010=066
20260120-14:01:50.310797000 : 8=FIX.4.49=068335=X49=NTPRO_IDBA_UAT56=SIRIUS_500007460_MD34=40652=20260120-14:01:51.248262=MD_GBP/USD_140109778778268=10279=2269=0270=1.25497271=10000055=GBP/USD110=0279=2269=0270=1.25497271=50000055=GBP/USD110=100000279=2269=0270=1.25497271=100000055=GBP/USD110=500000279=2269=0270=1.25497271=300000055=GBP/USD110=1000000279=2269=0270=1.25497271=500000055=GBP/USD110=3000000279=2269=1270=1.43533271=10000055=GBP/USD110=0279=2269=1270=1.43533271=50000055=GBP/USD110=100000279=2269=1270=1.43533271=100000055=GBP/USD110=500000279=2269=1270=1.43533271=300000055=GBP/USD110=1000000279=2269=1270=1.43533271=500000055=GBP/USD110=300000010=223
20260120-14:01:50.730606000 : 8=FIX.4.49=068335=X49=NTPRO_IDBA_UAT56=SIRIUS_500007460_MD34=40752=20260120-14:01:51.682262=MD_GBP/USD_140109778778268=10279=0269=0270=1.25498271=10000055=GBP/USD110=0279=0269=0270=1.25498271=50000055=GBP/USD110=100000279=0269=0270=1.25498271=100000055=GBP/USD110=500000279=0269=0270=1.25498271=300000055=GBP/USD110=1000000279=0269=0270=1.25498271=500000055=GBP/USD110=3000000279=0269=1270=1.43534271=10000055=GBP/USD110=0279=0269=1270=1.43534271=50000055=GBP/USD110=100000279=0269=1270=1.43534271=100000055=GBP/USD110=500000279=0269=1270=1.43534271=300000055=GBP/USD110=1000000279=0269=1270=1.43534271=500000055=GBP/USD110=300000010=216
20260120-14:01:50.887052000 : 8=FIX.4.49=039735=X49=NTPRO_IDBA_UAT56=SIRIUS_500007460_MD34=40852=20260120-14:01:51.845262=MD_GBP/USD_140109778778268=5279=1269=0270=1.25499271=10000055=GBP/USD110=0279=1269=0270=1.25499271=50000055=GBP/USD110=100000279=1269=0270=1.25499271=100000055=GBP/USD110=500000279=1269=0270=1.25499271=300000055=GBP/USD110=1000000279=1269=0270=1.25499271=500000055=GBP/USD110=300000010=080
20260120-14:01:50.911981000 : 8=FIX.4.49=068335=X49=NTPRO_IDBA_UAT56=SIRIUS_500007460_MD34=40952=20260120-14:01:51.870262=MD_GBP/USD_140109778778268=10279=1269=0270=1.25498271=10000055=GBP/USD110=0279=1269=0270=1.25498271=50000055=GBP/USD110=100000279=1269=0270=1.25498271=100000055=GBP/USD110=500000279=1269=0270=1.25498271=300000055=GBP/USD110=1000000279=1269=0270=1.25498271=500000055=GBP/USD110=3000000279=1269=1270=1.43533271=10000055=GBP/USD110=0279=1269=1270=1.43533271=50000055=GBP/USD110=100000279=1269=1270=1.43533271=100000055=GBP/USD110=500000279=1269=1270=1.43533271=300000055=GBP/USD110=1000000279=1269=1270=1.43533271=500000055=GBP/USD110=300000010=222
20260120-14:01:51.291929000 : 8=FIX.4.49=039735=X49=NTPRO_IDBA_UAT56=SIRIUS_500007460_MD34=41052=20260120-14:01:52.260262=MD_GBP/USD_140109778778268=5279=1269=0270=1.25497271=10000055=GBP/USD110=0279=1269=0270=1.25497271=50000055=GBP/USD110=100000279=1269=0270=1.25497271=100000055=GBP/USD110=500000279=1269=0270=1.25497271=300000055=GBP/USD110=1000000279=1269=0270=1.25497271=500000055=GBP/USD110=300000010=055
20260120-14:01:51.392290000 : 8=FIX.4.49=068335=X49=NTPRO_IDBA_UAT56=SIRIUS_500007460_MD34=41152=20260120-14:01:52.367262=MD_GBP/USD_140109778778268=10279=2269=0270=1.25497271=10000055=GBP/USD110=0279=2269=0270=1.25497271=50000055=GBP/USD110=100000279=2269=0270=1.25497271=100000055=GBP/USD110=500000279=2269=0270=1.25497271=300000055=GBP/USD110=1000000279=2269=0270=1.25497271=500000055=GBP/USD110=3000000279=2269=1270=1.43533271=10000055=GBP/USD110=0279=2269=1270=1.43533271=50000055=GBP/USD110=100000279=2269=1270=1.43533271=100000055=GBP/USD110=500000279=2269=1270=1.43533271=300000055=GBP/USD110=1000000279=2269=1270=1.43533271=500000055=GBP/USD110=300000010=222
20260120-14:01:51.989176000 : 8=FIX.4.49=067835=X49=NTPRO_IDBA_UAT56=SIRIUS_500007460_MD34=41252=20260120-14:01:52.986262=MD_GBP/USD_140109778778268=10279=0269=0270=1.25495271=10000055=GBP/USD110=0279=0269=0270=1.25495271=50000055=GBP/USD110=100000279=0269=0270=1.25495271=100000055=GBP/USD110=500000279=0269=0270=1.25495271=300000055=GBP/USD110=1000000279=0269=0270=1.25495271=500000055=GBP/USD110=3000000279=0269=1270=1.4353271=10000055=GBP/USD110=0279=0269=1270=1.4353271=50000055=GBP/USD110=100000279=0269=1270=1.4353271=100000055=GBP/USD110=500000279=0269=1270=1.4353271=300000055=GBP/USD110=1000000279=0269=1270=1.4353271=500000055=GBP/USD110=300000010=205
20260120-14:01:52.049957000 : 8=FIX.4.49=039735=X49=NTPRO_IDBA_UAT56=SIRIUS_500007460_MD34=41352=20260120-14:01:53.040262=MD_GBP/USD_140109778778268=5279=1269=0270=1.25494271=10000055=GBP/USD110=0279=1269=0270=1.25494271=50000055=GBP/USD110=100000279=1269=0270=1.25494271=100000055=GBP/USD110=500000279=1269=0270=1.25494271=300000055=GBP/USD110=1000000279=1269=0270=1.25494271=500000055=GBP/USD110=300000010=040
20260120-14:01:52.212979000 : 8=FIX.4.49=068335=X49=NTPRO_IDBA_UAT56=SIRIUS_500007460_MD34=41452=20260120-14:01:53.216262=MD_GBP/USD_140109778778268=10279=1269=0270=1.25493271=10000055=GBP/USD110=0279=1269=0270=1.25493271=50000055=GBP/USD110=100000279=1269=0270=1.25493271=100000055=GBP/USD110=500000279=1269=0270=1.25493271=300000055=GBP/USD110=1000000279=1269=0270=1.25493271=500000055=GBP/USD110=3000000279=1269=1270=1.43529271=10000055=GBP/USD110=0279=1269=1270=1.43529271=50000055=GBP/USD110=100000279=1269=1270=1.43529271=100000055=GBP/USD110=500000279=1269=1270=1.43529271=300000055=GBP/USD110=1000000279=1269=1270=1.43529271=500000055=GBP/USD110=300000010=214
20260120-14:01:52.347942000 : 8=FIX.4.49=068335=X49=NTPRO_IDBA_UAT56=SIRIUS_500007460_MD34=41552=20260120-14:01:53.343262=MD_GBP/USD_140109778778268=10279=2269=0270=1.25493271=10000055=GBP/USD110=0279=2269=0270=1.25493271=50000055=GBP/USD110=100000279=2269=0270=1.25493271=100000055=GBP/USD110=500000279=2269=0270=1.25493271=300000055=GBP/USD110=1000000279=2269=0270=1.25493271=500000055=GBP/USD110=3000000279=2269=1270=1.43529271=10000055=GBP/USD110=0279=2269=1270=1.43529271=50000055=GBP/USD110=100000279=2269=1270=1.43529271=100000055=GBP/USD110=500000279=2269=1270=1.43529271=300000055=GBP/USD110=1000000279=2269=1270=1.43529271=500000055=GBP/USD110=300000010=226
20260120-14:01:53.096893000 : 8=FIX.4.49=068335=X49=NTPRO_IDBA_UAT56=SIRIUS_500007460_MD34=41652=20260120-14:01:54.133262=MD_GBP/USD_140109778778268=10279=0269=0270=1.25493271=10000055=GBP/USD110=0279=0269=0270=1.25493271=50000055=GBP/USD110=100000279=0269=0270=1.25493271=100000055=GBP/USD110=500000279=0269=0270=1.25493271=300000055=GBP/USD110=1000000279=0269=0270=1.25493271=500000055=GBP/USD110=3000000279=0269=1270=1.43529271=10000055=GBP/USD110=0279=0269=1270=1.43529271=50000055=GBP/USD110=100000279=0269=1270=1.43529271=100000055=GBP/USD110=500000279=0269=1270=1.43529271=300000055=GBP/USD110=1000000279=0269=1270=1.43529271=500000055=GBP/USD110=300000010=205
20260120-14:01:53.182160000 : 8=FIX.4.49=068335=X49=NTPRO_IDBA_UAT56=SIRIUS_500007460_MD34=41752=20260120-14:01:54.213262=MD_GBP/USD_140109778778268=10279=2269=0270=1.25493271=10000055=GBP/USD110=0279=2269=0270=1.25493271=50000055=GBP/USD110=100000279=2269=0270=1.25493271=100000055=GBP/USD110=500000279=2269=0270=1.25493271=300000055=GBP/USD110=1000000279=2269=0270=1.25493271=500000055=GBP/USD110=3000000279=2269=1270=1.43529271=10000055=GBP/USD110=0279=2269=1270=1.43529271=50000055=GBP/USD110=100000279=2269=1270=1.43529271=100000055=GBP/USD110=500000279=2269=1270=1.43529271=300000055=GBP/USD110=1000000279=2269=1270=1.43529271=500000055=GBP/USD110=300000010=225
20260120-14:01:53.234950000 : 8=FIX.4.49=044635=X49=NTPRO_IDBA_UAT56=SIRIUS_500007460_MD34=41852=20260120-14:01:54.276262=MD_EUR/USD_140109278614268=6279=1269=0270=1.14823271=10000055=EUR/USD110=0279=1269=0270=1.14823271=50000055=EUR/USD110=100000279=1269=0270=1.14823271=100000055=EUR/USD110=500000279=1269=1270=1.19848271=10000055=EUR/USD110=0279=1269=1270=1.19848271=50000055=EUR/USD110=100000279=1269=1270=1.19848271=100000055=EUR/USD110=50000010=016
