20260120-14:04:27.479491000 : 8=FIX.4.49=039835=X49=NTPRO_IDBA_UAT56=SIRIUS_500007460_MD34=122852=20260120-14:04:27.825262=MD_GBP/USD_140109778778268=5279=1269=1270=1.43501271=10000055=GBP/USD110=0279=1269=1270=1.43501271=50000055=GBP/USD110=100000279=1269=1270=1.43501271=100000055=GBP/USD110=500000279=1269=1270=1.43501271=300000055=GBP/USD110=1000000279=1269=1270=1.43501271=500000055=GBP/USD110=300000010=059
20260120-14:04:27.575845000 : 8=FIX.4.49=028035=X49=NTPRO_IDBA_UAT56=SIRIUS_500007460_MD34=122952=20260120-14:04:27.923262=MD_EUR/USD_140109278614268=3279=1269=1270=1.19816271=10000055=EUR/USD110=0279=1269=1270=1.19816271=50000055=EUR/USD110=100000279=1269=1270=1.19816271=100000055=EUR/USD110=50000010=019
20260120-14:04:27.576622000 : 8=FIX.4.49=039835=X49=NTPRO_IDBA_UAT56=SIRIUS_500007460_MD34=123052=20260120-14:04:27.932262=MD_GBP/USD_140109778778268=5279=1269=0270=1.25465271=10000055=GBP/USD110=0279=1269=0270=1.25465271=50000055=GBP/USD110=100000279=1269=0270=1.25465271=100000055=GBP/USD110=500000279=1269=0270=1.25465271=300000055=GBP/USD110=1000000279=1269=0270=1.25465271=500000055=GBP/USD110=300000010=091
20260120-14:04:27.666092000 : 8=FIX.4.49=068435=X49=NTPRO_IDBA_UAT56=SIRIUS_500007460_MD34=123152=20260120-14:04:27.951262=MD_GBP/USD_140109778778268=10279=2269=0270=1.25465271=10000055=GBP/USD110=0279=2269=0270=1.25465271=50000055=GBP/USD110=100000279=2269=0270=1.25465271=100000055=GBP/USD110=500000279=2269=0270=1.25465271=300000055=GBP/USD110=1000000279=2269=0270=1.25465271=500000055=GBP/USD110=3000000279=2269=1270=1.43501271=10000055=GBP/USD110=0279=2269=1270=1.43501271=50000055=GBP/USD110=100000279=2269=1270=1.43501271=100000055=GBP/USD110=500000279=2269=1270=1.43501271=300000055=GBP/USD110=1000000279=2269=1270=1.43501271=500000055=GBP/USD110=300000010=226
20260120-14:04:27.666526000 : 8=FIX.4.49=028035=X49=NTPRO_IDBA_UAT56=SIRIUS_500007460_MD34=123252=20260120-14:04:28.009262=MD_EUR/USD_140109278614268=3279=1269=0270=1.14791271=10000055=EUR/USD110=0279=1269=0270=1.14791271=50000055=EUR/USD110=100000279=1269=0270=1.14791271=100000055=EUR/USD110=50000010=253
20260120-14:04:27.775691000 : 8=FIX.4.49=027735=X49=NTPRO_IDBA_UAT56=SIRIUS_500007460_MD34=123352=20260120-14:04:28.078262=MD_EUR/USD_140109278614268=3279=1269=0270=1.1479271=10000055=EUR/USD110=0279=1269=0270=1.1479271=50000055=EUR/USD110=100000279=1269=0270=1.1479271=100000055=EUR/USD110=50000010=119
20260120-14:04:27.776102000 : 8=FIX.4.49=067435=X49=NTPRO_IDBA_UAT56=SIRIUS_500007460_MD34=123452=20260120-14:04:28.146262=MD_GBP/USD_140109778778268=10279=0269=0270=1.25465271=10000055=GBP/USD110=0279=0269=0270=1.25465271=50000055=GBP/USD110=100000279=0269=0270=1.25465271=100000055=GBP/USD110=500000279=0269=0270=1.25465271=300000055=GBP/USD110=1000000279=0269=0270=1.25465271=500000055=GBP/USD110=3000000279=0269=1270=1.435271=10000055=GBP/USD110=0279=0269=1270=1.435271=50000055=GBP/USD110=100000279=0269=1270=1.435271=100000055=GBP/USD110=500000279=0269=1270=1.435271=300000055=GBP/USD110=1000000279=0269=1270=1.435271=500000055=GBP/USD110=300000010=232
20260120-14:04:28.346661000 : 8=FIX.4.49=039835=X49=NTPRO_IDBA_UAT56=SIRIUS_500007460_MD34=123552=20260120-14:04:28.686262=MD_GBP/USD_140109778778268=5279=1269=0270=1.25464271=10000055=GBP/USD110=0279=1269=0270=1.25464271=50000055=GBP/USD110=100000279=1269=0270=1.25464271=100000055=GBP/USD110=500000279=1269=0270=1.25464271=300000055=GBP/USD110=1000000279=1269=0270=1.25464271=500000055=GBP/USD110=300000010=098
20260120-14:04:28.958236000 : 8=FIX.4.49=044735=X49=NTPRO_IDBA_UAT56=SIRIUS_500007460_MD34=123652=20260120-14:04:29.386262=MD_EUR/USD_140109278614268=6279=1269=0270=1.14793271=10000055=EUR/USD110=0279=1269=0270=1.14793271=50000055=EUR/USD110=100000279=1269=0270=1.14793271=100000055=EUR/USD110=500000279=1269=1270=1.19817271=10000055=EUR/USD110=0279=1269=1270=1.19817271=50000055=EUR/USD110=100000279=1269=1270=1.19817271=100000055=EUR/USD110=50000010=077
20260120-14:04:28.986441000 : 8=FIX.4.49=068435=X49=NTPRO_IDBA_UAT56=SIRIUS_500007460_MD34=123752=20260120-14:04:29.418262=MD_GBP/USD_140109778778268=10279=1269=0270=1.25466271=10000055=GBP/USD110=0279=1269=0270=1.25466271=50000055=GBP/USD110=100000279=1269=0270=1.25466271=100000055=GBP/USD110=500000279=1269=0270=1.25466271=300000055=GBP/USD110=1000000279=1269=0270=1.25466271=500000055=GBP/USD110=3000000279=1269=1270=1.43501271=10000055=GBP/USD110=0279=1269=1270=1.43501271=50000055=GBP/USD110=100000279=1269=1270=1.43501271=100000055=GBP/USD110=500000279=1269=1270=1.43501271=300000055=GBP/USD110=1000000279=1269=1270=1.43501271=500000055=GBP/USD110=300000010=227
20260120-14:04:29.023786000 : 8=FIX.4.49=068435=X49=NTPRO_IDBA_UAT56=SIRIUS_500007460_MD34=123852=20260120-14:04:29.456262=MD_GBP/USD_140109778778268=10279=1269=0270=1.25467271=10000055=GBP/USD110=0279=1269=0270=1.25467271=50000055=GBP/USD110=100000279=1269=0270=1.25467271=100000055=GBP/USD110=500000279=1269=0270=1.25467271=300000055=GBP/USD110=1000000279=1269=0270=1.25467271=500000055=GBP/USD110=3000000279=1269=1270=1.43502271=10000055=GBP/USD110=0279=1269=1270=1.43502271=50000055=GBP/USD110=100000279=1269=1270=1.43502271=100000055=GBP/USD110=500000279=1269=1270=1.43502271=300000055=GBP/USD110=1000000279=1269=1270=1.43502271=500000055=GBP/USD110=300000010=240
20260120-14:04:29.047526000 : 8=FIX.4.49=044735=X49=NTPRO_IDBA_UAT56=SIRIUS_500007460_MD34=123952=20260120-14:04:29.483262=MD_EUR/USD_140109278614268=6279=1269=0270=1.14794271=10000055=EUR/USD110=0279=1269=0270=1.14794271=50000055=EUR/USD110=100000279=1269=0270=1.14794271=100000055=EUR/USD110=500000279=1269=1270=1.19818271=10000055=EUR/USD110=0279=1269=1270=1.19818271=50000055=EUR/USD110=100000279=1269=1270=1.19818271=100000055=EUR/USD110=50000010=084
20260120-14:04:29.105144000 : 8=FIX.4.49=028035=X49=NTPRO_IDBA_UAT56=SIRIUS_500007460_MD34=124052=20260120-14:04:29.543262=MD_EUR/USD_140109278614268=3279=1269=1270=1.19819271=10000055=EUR/USD110=0279=1269=1270=1.19819271=50000055=EUR/USD110=100000279=1269=1270=1.19819271=100000055=EUR/USD110=50000010=021
20260120-14:04:29.147569000 : 8=FIX.4.49=039835=X49=NTPRO_IDBA_UAT56=SIRIUS_500007460_MD34=124152=20260120-14:04:29.588262=MD_GBP/USD_140109778778268=5279=1269=1270=1.43503271=10000055=GBP/USD110=0279=1269=1270=1.43503271=50000055=GBP/USD110=100000279=1269=1270=1.43503271=100000055=GBP/USD110=500000279=1269=1270=1.43503271=300000055=GBP/USD110=1000000279=1269=1270=1.43503271=500000055=GBP/USD110=300000010=072
20260120-14:04:29.201522000 : 8=FIX.4.49=044735=X49=NTPRO_IDBA_UAT56=SIRIUS_500007460_MD34=124252=20260120-14:04:29.644262=MD_EUR/USD_140109278614268=6279=1269=0270=1.14797271=10000055=EUR/USD110=0279=1269=0270=1.14797271=50000055=EUR/USD110=100000279=1269=0270=1.14797271=100000055=EUR/USD110=500000279=1269=1270=1.19822271=10000055=EUR/USD110=0279=1269=1270=1.19822271=50000055=EUR/USD110=100000279=1269=1270=1.19822271=100000055=EUR/USD110=50000010=071
20260120-14:04:29.204590000 : 8=FIX.4.49=068435=X49=NTPRO_IDBA_UAT56=SIRIUS_500007460_MD34=124352=20260120-14:04:29.647262=MD_GBP/USD_140109778778268=10279=1269=0270=1.25472271=10000055=GBP/USD110=0279=1269=0270=1.25472271=50000055=GBP/USD110=100000279=1269=0270=1.25472271=100000055=GBP/USD110=500000279=1269=0270=1.25472271=300000055=GBP/USD110=1000000279=1269=0270=1.25472271=500000055=GBP/USD110=3000000279=1269=1270=1.43504271=10000055=GBP/USD110=0279=1269=1270=1.43504271=50000055=GBP/USD110=100000279=1269=1270=1.43504271=100000055=GBP/USD110=500000279=1269=1270=1.43504271=300000055=GBP/USD110=1000000279=1269=1270=1.43504271=500000055=GBP/USD110=300000010=228
20260120-14:04:29.275276000 : 8=FIX.4.49=039835=X49=NTPRO_IDBA_UAT56=SIRIUS_500007460_MD34=124452=20260120-14:04:29.699262=MD_GBP/USD_140109778778268=5279=1269=1270=1.43505271=10000055=GBP/USD110=0279=1269=1270=1.43505271=50000055=GBP/USD110=100000279=1269=1270=1.43505271=100000055=GBP/USD110=500000279=1269=1270=1.43505271=300000055=GBP/USD110=1000000279=1269=1270=1.43505271=500000055=GBP/USD110=300000010=088
20260120-14:04:29.293505000 : 8=FIX.4.49=028035=X49=NTPRO_IDBA_UAT56=SIRIUS_500007460_MD34=124552=20260120-14:04:29.741262=MD_EUR/USD_140109278614268=3279=1269=0270=1.14796271=10000055=EUR/USD110=0279=1269=0270=1.14796271=50000055=EUR/USD110=100000279=1269=0270=1.14796271=100000055=EUR/USD110=50000010=020
20260120-14:04:29.309860000 : 8=FIX.4.49=068435=X49=NTPRO_IDBA_UAT56=SIRIUS_500007460_MD34=124652=20260120-14:04:29.758262=MD_GBP/USD_140109778778268=10279=2269=0270=1.25472271=10000055=GBP/USD110=0279=2269=0270=1.25472271=50000055=GBP/USD110=100000279=2269=0270=1.25472271=100000055=GBP/USD110=500000279=2269=0270=1.25472271=300000055=GBP/USD110=1000000279=2269=0270=1.25472271=500000055=GBP/USD110=3000000279=2269=1270=1.43505271=10000055=GBP/USD110=0279=2269=1270=1.43505271=50000055=GBP/USD110=100000279=2269=1270=1.43505271=100000055=GBP/USD110=500000279=2269=1270=1.43505271=300000055=GBP/USD110=1000000279=2269=1270=1.43505271=500000055=GBP/USD110=300000010=249
20260120-14:04:29.377131000 : 8=FIX.4.49=068435=X49=NTPRO_IDBA_UAT56=SIRIUS_500007460_MD34=124752=20260120-14:04:29.829262=MD_GBP/USD_140109778778268=10279=0269=0270=1.25472271=10000055=GBP/USD110=0279=0269=0270=1.25472271=50000055=GBP/USD110=100000279=0269=0270=1.25472271=100000055=GBP/USD110=500000279=0269=0270=1.25472271=300000055=GBP/USD110=1000000279=0269=0270=1.25472271=500000055=GBP/USD110=3000000279=0269=1270=1.43507271=10000055=GBP/USD110=0279=0269=1270=1.43507271=50000055=GBP/USD110=100000279=0269=1270=1.43507271=100000055=GBP/USD110=500000279=0269=1270=1.43507271=300000055=GBP/USD110=1000000279=0269=1270=1.43507271=500000055=GBP/USD110=300000010=239
20260120-14:04:29.388941000 : 8=FIX.4.49=044435=X49=NTPRO_IDBA_UAT56=SIRIUS_500007460_MD34=124852=20260120-14:04:29.841262=MD_EUR/USD_140109278614268=6279=1269=0270=1.14795271=10000055=EUR/USD110=0279=1269=0270=1.14795271=50000055=EUR/USD110=100000279=1269=0270=1.14795271=100000055=EUR/USD110=500000279=1269=1270=1.1982271=10000055=EUR/USD110=0279=1269=1270=1.1982271=50000055=EUR/USD110=100000279=1269=1270=1.1982271=100000055=EUR/USD110=50000010=173
20260120-14:04:29.515364000 : 8=FIX.4.49=044735=X49=NTPRO_IDBA_UAT56=SIRIUS_500007460_MD34=124952=20260120-14:04:29.973262=MD_EUR/USD_140109278614268=6279=1269=0270=1.14796271=10000055=EUR/USD110=0279=1269=0270=1.14796271=50000055=EUR/USD110=100000279=1269=0270=1.14796271=100000055=EUR/USD110=500000279=1269=1270=1.19821271=10000055=EUR/USD110=0279=1269=1270=1.19821271=50000055=EUR/USD110=100000279=1269=1270=1.19821271=100000055=EUR/USD110=50000010=077
20260120-14:04:29.673437000 : 8=FIX.4.49=044735=X49=NTPRO_IDBA_UAT56=SIRIUS_500007460_MD34=125052=20260120-14:04:30.212262=MD_EUR/USD_140109278614268=6279=1269=0270=1.14797271=10000055=EUR/USD110=0279=1269=0270=1.14797271=50000055=EUR/USD110=100000279=1269=0270=1.14797271=100000055=EUR/USD110=500000279=1269=1270=1.19822271=10000055=EUR/USD110=0279=1269=1270=1.19822271=50000055=EUR/USD110=100000279=1269=1270=1.19822271=100000055=EUR/USD110=50000010=053
20260120-14:04:29.706239000 : 8=FIX.4.49=044735=X49=NTPRO_IDBA_UAT56=SIRIUS_500007460_MD34=125152=20260120-14:04:30.243262=MD_EUR/USD_140109278614268=6279=1269=0270=1.14795271=10000055=EUR/USD110=0279=1269=0270=1.14795271=50000055=EUR/USD110=100000279=1269=0270=1.14795271=100000055=EUR/USD110=500000279=1269=1270=1.19821271=10000055=EUR/USD110=0279=1269=1270=1.19821271=50000055=EUR/USD110=100000279=1269=1270=1.19821271=100000055=EUR/USD110=50000010=049
20260120-14:04:29.718253000 : 8=FIX.4.49=039835=X49=NTPRO_IDBA_UAT56=SIRIUS_500007460_MD34=125252=20260120-14:04:30.259262=MD_GBP/USD_140109778778268=5279=1269=1270=1.43508271=10000055=GBP/USD110=0279=1269=1270=1.43508271=50000055=GBP/USD110=100000279=1269=1270=1.43508271=100000055=GBP/USD110=500000279=1269=1270=1.43508271=300000055=GBP/USD110=1000000279=1269=1270=1.43508271=500000055=GBP/USD110=300000010=086
20260120-14:04:30.422056000 : 8=FIX.4.49=044735=X49=NTPRO_IDBA_UAT56=SIRIUS_500007460_MD34=125352=20260120-14:04:30.379262=MD_EUR/USD_140109278614268=6279=1269=0270=1.14794271=10000055=EUR/USD110=0279=1269=0270=1.14794271=50000055=EUR/USD110=100000279=1269=0270=1.14794271=100000055=EUR/USD110=500000279=1269=1270=1.19819271=10000055=EUR/USD110=0279=1269=1270=1.19819271=50000055=EUR/USD110=100000279=1269=1270=1.19819271=100000055=EUR/USD110=50000010=079
20260120-14:04:30.651297000 : 8=FIX.4.49=039835=X49=NTPRO_IDBA_UAT56=SIRIUS_500007460_MD34=125452=20260120-14:04:30.619262=MD_GBP/USD_140109778778268=5279=1269=1270=1.43507271=10000055=GBP/USD110=0279=1269=1270=1.43507271=50000055=GBP/USD110=100000279=1269=1270=1.43507271=100000055=GBP/USD110=500000279=1269=1270=1.43507271=300000055=GBP/USD110=1000000279=1269=1270=1.43507271=500000055=GBP/USD110=300000010=083
20260120-14:04:30.785140000 : 8=FIX.4.49=007935=049=NTPRO_IDBA_UAT56=SIRIUS_500007460_MD34=125552=20260120-14:04:30.76110=014
20260120-14:04:30.934011000 : 8=FIX.4.49=028035=X49=NTPRO_IDBA_UAT56=SIRIUS_500007460_MD34=125652=20260120-14:04:30.917262=MD_EUR/USD_140109278614268=3279=1269=0270=1.14793271=10000055=EUR/USD110=0279=1269=0270=1.14793271=50000055=EUR/USD110=100000279=1269=0270=1.14793271=100000055=EUR/USD110=50000010=010
20260120-14:04:31.605087000 : 8=FIX.4.49=039835=X49=NTPRO_IDBA_UAT56=SIRIUS_500007460_MD34=125752=20260120-14:04:31.615262=MD_GBP/USD_140109778778268=5279=1269=0270=1.25471271=10000055=GBP/USD110=0279=1269=0270=1.25471271=50000055=GBP/USD110=100000279=1269=0270=1.25471271=100000055=GBP/USD110=500000279=1269=0270=1.25471271=300000055=GBP/USD110=1000000279=1269=0270=1.25471271=500000055=GBP/USD110=300000010=078
20260120-14:04:31.631136000 : 8=FIX.4.49=068435=X49=NTPRO_IDBA_UAT56=SIRIUS_500007460_MD34=125852=20260120-14:04:31.642262=MD_GBP/USD_140109778778268=10279=1269=0270=1.25468271=10000055=GBP/USD110=0279=1269=0270=1.25468271=50000055=GBP/USD110=100000279=1269=0270=1.25468271=100000055=GBP/USD110=500000279=1269=0270=1.25468271=300000055=GBP/USD110=1000000279=1269=0270=1.25468271=500000055=GBP/USD110=3000000279=1269=1270=1.43503271=10000055=GBP/USD110=0279=1269=1270=1.43503271=50000055=GBP/USD110=100000279=1269=1270=1.43503271=100000055=GBP/USD110=500000279=1269=1270=1.43503271=300000055=GBP/USD110=1000000279=1269=1270=1.43503271=500000055=GBP/USD110=300000010=242
20260120-14:04:31.716837000 : 8=FIX.4.49=044735=X49=NTPRO_IDBA_UAT56=SIRIUS_500007460_MD34=125952=20260120-14:04:31.728262=MD_EUR/USD_140109278614268=6279=1269=0270=1.14792271=10000055=EUR/USD110=0279=1269=0270=1.14792271=50000055=EUR/USD110=100000279=1269=0270=1.14792271=100000055=EUR/USD110=500000279=1269=1270=1.19818271=10000055=EUR/USD110=0279=1269=1270=1.19818271=50000055=EUR/USD110=100000279=1269=1270=1.19818271=100000055=EUR/USD110=50000010=075
20260120-14:04:31.760370000 : 8=FIX.4.49=039835=X49=NTPRO_IDBA_UAT56=SIRIUS_500007460_MD34=126052=20260120-14:04:31.776262=MD_GBP/USD_140109778778268=5279=1269=0270=1.25467271=10000055=GBP/USD110=0279=1269=0270=1.25467271=50000055=GBP/USD110=100000279=1269=0270=1.25467271=100000055=GBP/USD110=500000279=1269=0270=1.25467271=300000055=GBP/USD110=1000000279=1269=0270=1.25467271=500000055=GBP/USD110=300000010=105
20260120-14:04:31.767308000 : 8=FIX.4.49=028035=X49=NTPRO_IDBA_UAT56=SIRIUS_500007460_MD34=126152=20260120-14:04:31.783262=MD_EUR/USD_140109278614268=3279=1269=0270=1.14794271=10000055=EUR/USD110=0279=1269=0270=1.14794271=50000055=EUR/USD110=100000279=1269=0270=1.14794271=100000055=EUR/USD110=50000010=011
20260120-14:04:31.895826000 : 8=FIX.4.49=028035=X49=NTPRO_IDBA_UAT56=SIRIUS_500007460_MD34=126252=20260120-14:04:31.915262=MD_EUR/USD_140109278614268=3279=1269=0270=1.14793271=10000055=EUR/USD110=0279=1269=0270=1.14793271=50000055=EUR/USD110=100000279=1269=0270=1.14793271=100000055=EUR/USD110=50000010=006
20260120-14:04:31.961533000 : 8=FIX.4.49=039835=X49=NTPRO_IDBA_UAT56=SIRIUS_500007460_MD34=126352=20260120-14:04:31.984262=MD_GBP/USD_140109778778268=5279=1269=1270=1.43502271=10000055=GBP/USD110=0279=1269=1270=1.43502271=50000055=GBP/USD110=100000279=1269=1270=1.43502271=100000055=GBP/USD110=500000279=1269=1270=1.43502271=300000055=GBP/USD110=1000000279=1269=1270=1.43502271=500000055=GBP/USD110=300000010=064
20260120-14:04:31.962574000 : 8=FIX.4.49=044435=X49=NTPRO_IDBA_UAT56=SIRIUS_500007460_MD34=126452=20260120-14:04:31.985262=MD_EUR/USD_140109278614268=6279=1269=0270=1.1479271=10000055=EUR/USD110=0279=1269=0270=1.1479271=50000055=EUR/USD110=100000279=1269=0270=1.1479271=100000055=EUR/USD110=500000279=1269=1270=1.19814271=10000055=EUR/USD110=0279=1269=1270=1.19814271=50000055=EUR/USD110=100000279=1269=1270=1.19814271=100000055=EUR/USD110=50000010=167
20260120-14:04:32.016557000 : 8=FIX.4.49=039835=X49=NTPRO_IDBA_UAT56=SIRIUS_500007460_MD34=126552=20260120-14:04:32.041262=MD_GBP/USD_140109778778268=5279=1269=1270=1.43501271=10000055=GBP/USD110=0279=1269=1270=1.43501271=50000055=GBP/USD110=100000279=1269=1270=1.43501271=100000055=GBP/USD110=500000279=1269=1270=1.43501271=300000055=GBP/USD110=1000000279=1269=1270=1.43501271=500000055=GBP/USD110=300000010=046
20260120-14:04:32.118985000 : 8=FIX.4.49=044735=X49=NTPRO_IDBA_UAT56=SIRIUS_500007460_MD34=126652=20260120-14:04:32.147262=MD_EUR/USD_140109278614268=6279=1269=0270=1.14789271=10000055=EUR/USD110=0279=1269=0270=1.14789271=50000055=EUR/USD110=100000279=1269=0270=1.14789271=100000055=EUR/USD110=500000279=1269=1270=1.19815271=10000055=EUR/USD110=0279=1269=1270=1.19815271=50000055=EUR/USD110=100000279=1269=1270=1.19815271=100000055=EUR/USD110=50000010=078
20260120-14:04:32.128873000 : 8=FIX.4.49=039835=X49=NTPRO_IDBA_UAT56=SIRIUS_500007460_MD34=126752=20260120-14:04:32.157262=MD_GBP/USD_140109778778268=5279=1269=0270=1.25465271=10000055=GBP/USD110=0279=1269=0270=1.25465271=50000055=GBP/USD110=100000279=1269=0270=1.25465271=100000055=GBP/USD110=500000279=1269=0270=1.25465271=300000055=GBP/USD110=1000000279=1269=0270=1.25465271=500000055=GBP/USD110=300000010=096
20260120-14:04:32.206374000 : 8=FIX.4.49=044435=X49=NTPRO_IDBA_UAT56=SIRIUS_500007460_MD34=126852=20260120-14:04:32.237262=MD_EUR/USD_140109278614268=6279=1269=0270=1.1479271=10000055=EUR/USD110=0279=1269=0270=1.1479271=50000055=EUR/USD110=100000279=1269=0270=1.1479271=100000055=EUR/USD110=500000279=1269=1270=1.19814271=10000055=EUR/USD110=0279=1269=1270=1.19814271=50000055=EUR/USD110=100000279=1269=1270=1.19814271=100000055=EUR/USD110=50000010=162
20260120-14:04:32.453996000 : 8=FIX.4.49=028035=X49=NTPRO_IDBA_UAT56=SIRIUS_500007460_MD34=126952=20260120-14:04:32.494262=MD_EUR/USD_140109278614268=3279=1269=1270=1.19815271=10000055=EUR/USD110=0279=1269=1270=1.19815271=50000055=EUR/USD110=100000279=1269=1270=1.19815271=100000055=EUR/USD110=50000010=019
20260120-14:04:32.614814000 : 8=FIX.4.49=028035=X49=NTPRO_IDBA_UAT56=SIRIUS_500007460_MD34=127052=20260120-14:04:32.659262=MD_EUR/USD_140109278614268=3279=1269=1270=1.19814271=10000055=EUR/USD110=0279=1269=1270=1.19814271=50000055=EUR/USD110=100000279=1269=1270=1.19814271=100000055=EUR/USD110=50000010=011
20260120-14:04:32.834318000 : 8=FIX.4.49=038835=X49=NTPRO_IDBA_UAT56=SIRIUS_500007460_MD34=127152=20260120-14:04:32.867262=MD_GBP/USD_140109778778268=5279=1269=1270=1.435271=10000055=GBP/USD110=0279=1269=1270=1.435271=50000055=GBP/USD110=100000279=1269=1270=1.435271=100000055=GBP/USD110=500000279=1269=1270=1.435271=300000055=GBP/USD110=1000000279=1269=1270=1.435271=500000055=GBP/USD110=300000010=085
20260120-14:04:32.989397000 : 8=FIX.4.49=039835=X49=NTPRO_IDBA_UAT56=SIRIUS_500007460_MD34=127252=20260120-14:04:33.048262=MD_GBP/USD_140109778778268=5279=1269=0270=1.25464271=10000055=GBP/USD110=0279=1269=0270=1.25464271=50000055=GBP/USD110=100000279=1269=0270=1.25464271=100000055=GBP/USD110=500000279=1269=0270=1.25464271=300000055=GBP/USD110=1000000279=1269=0270=1.25464271=500000055=GBP/USD110=300000010=087
20260120-14:04:33.015033000 : 8=FIX.4.49=028035=X49=NTPRO_IDBA_UAT56=SIRIUS_500007460_MD34=127352=20260120-14:04:33.071262=MD_EUR/USD_140109278614268=3279=1269=0270=1.14789271=10000055=EUR/USD110=0279=1269=0270=1.14789271=50000055=EUR/USD110=100000279=1269=0270=1.14789271=100000055=EUR/USD110=50000010=018
20260120-14:04:33.053545000 : 8=FIX.4.49=028035=X49=NTPRO_IDBA_UAT56=SIRIUS_500007460_MD34=127452=20260120-14:04:33.115262=MD_EUR/USD_140109278614268=3279=1269=1270=1.19813271=10000055=EUR/USD110=0279=1269=1270=1.19813271=50000055=EUR/USD110=100000279=1269=1270=1.19813271=100000055=EUR/USD110=50000010=000
20260120-14:04:33.096999000 : 8=FIX.4.49=068435=X49=NTPRO_IDBA_UAT56=SIRIUS_500007460_MD34=127552=20260120-14:04:33.156262=MD_GBP/USD_140109778778268=10279=1269=0270=1.25465271=10000055=GBP/USD110=0279=1269=0270=1.25465271=50000055=GBP/USD110=100000279=1269=0270=1.25465271=100000055=GBP/USD110=500000279=1269=0270=1.25465271=300000055=GBP/USD110=1000000279=1269=0270=1.25465271=500000055=GBP/USD110=3000000279=1269=1270=1.43499271=10000055=GBP/USD110=0279=1269=1270=1.43499271=50000055=GBP/USD110=100000279=1269=1270=1.43499271=100000055=GBP/USD110=500000279=1269=1270=1.43499271=300000055=GBP/USD110=1000000279=1269=1270=1.43499271=500000055=GBP/USD110=300000010=042
20260120-14:04:33.194598000 : 8=FIX.4.49=038835=X49=NTPRO_IDBA_UAT56=SIRIUS_500007460_MD34=127652=20260120-14:04:33.261262=MD_GBP/USD_140109778778268=5279=1269=1270=1.435271=10000055=GBP/USD110=0279=1269=1270=1.435271=50000055=GBP/USD110=100000279=1269=1270=1.435271=100000055=GBP/USD110=500000279=1269=1270=1.435271=300000055=GBP/USD110=1000000279=1269=1270=1.435271=500000055=GBP/USD110=300000010=079
20260120-14:04:33.295052000 : 8=FIX.4.49=028035=X49=NTPRO_IDBA_UAT56=SIRIUS_500007460_MD34=127752=20260120-14:04:33.365262=MD_EUR/USD_140109278614268=3279=1269=1270=1.19814271=10000055=EUR/USD110=0279=1269=1270=1.19814271=50000055=EUR/USD110=100000279=1269=1270=1.19814271=100000055=EUR/USD110=50000010=013
20260120-14:04:33.486934000 : 8=FIX.4.49=039835=X49=NTPRO_IDBA_UAT56=SIRIUS_500007460_MD34=127852=20260120-14:04:33.564262=MD_GBP/USD_140109778778268=5279=1269=1270=1.43499271=10000055=GBP/USD110=0279=1269=1270=1.43499271=50000055=GBP/USD110=100000279=1269=1270=1.43499271=100000055=GBP/USD110=500000279=1269=1270=1.43499271=300000055=GBP/USD110=1000000279=1269=1270=1.43499271=500000055=GBP/USD110=300000010=141
20260120-14:04:33.700653000 : 8=FIX.4.49=028035=X49=NTPRO_IDBA_UAT56=SIRIUS_500007460_MD34=127952=20260120-14:04:33.786262=MD_EUR/USD_140109278614268=3279=1269=1270=1.19813271=10000055=EUR/USD110=0279=1269=1270=1.19813271=50000055=EUR/USD110=100000279=1269=1270=1.19813271=100000055=EUR/USD110=50000010=019
20260120-14:04:33.934435000 : 8=FIX.4.49=067435=X49=NTPRO_IDBA_UAT56=SIRIUS_500007460_MD34=128052=20260120-14:04:34.028262=MD_GBP/USD_140109778778268=10279=1269=0270=1.25464271=10000055=GBP/USD110=0279=1269=0270=1.25464271=50000055=GBP/USD110=100000279=1269=0270=1.25464271=100000055=GBP/USD110=500000279=1269=0270=1.25464271=300000055=GBP/USD110=1000000279=1269=0270=1.25464271=500000055=GBP/USD110=3000000279=1269=1270=1.435271=10000055=GBP/USD110=0279=1269=1270=1.435271=50000055=GBP/USD110=100000279=1269=1270=1.435271=100000055=GBP/USD110=500000279=1269=1270=1.435271=300000055=GBP/USD110=1000000279=1269=1270=1.435271=500000055=GBP/USD110=300000010=234
20260120-14:04:33.936373000 : 8=FIX.4.49=044735=X49=NTPRO_IDBA_UAT56=SIRIUS_500007460_MD34=128152=20260120-14:04:34.031262=MD_EUR/USD_140109278614268=6279=1269=0270=1.14788271=10000055=EUR/USD110=0279=1269=0270=1.14788271=50000055=EUR/USD110=100000279=1269=0270=1.14788271=100000055=EUR/USD110=500000279=1269=1270=1.19812271=10000055=EUR/USD110=0279=1269=1270=1.19812271=50000055=EUR/USD110=100000279=1269=1270=1.19812271=100000055=EUR/USD110=50000010=057
20260120-14:04:34.033710000 : 8=FIX.4.49=039835=X49=NTPRO_IDBA_UAT56=SIRIUS_500007460_MD34=128252=20260120-14:04:34.115262=MD_GBP/USD_140109778778268=5279=1269=1270=1.43499271=10000055=GBP/USD110=0279=1269=1270=1.43499271=50000055=GBP/USD110=100000279=1269=1270=1.43499271=100000055=GBP/USD110=500000279=1269=1270=1.43499271=300000055=GBP/USD110=1000000279=1269=1270=1.43499271=500000055=GBP/USD110=300000010=129
20260120-14:04:34.061692000 : 8=FIX.4.49=067935=X49=NTPRO_IDBA_UAT56=SIRIUS_500007460_MD34=128352=20260120-14:04:34.160262=MD_GBP/USD_140109778778268=10279=1269=0270=1.2546271=10000055=GBP/USD110=0279=1269=0270=1.2546271=50000055=GBP/USD110=100000279=1269=0270=1.2546271=100000055=GBP/USD110=500000279=1269=0270=1.2546271=300000055=GBP/USD110=1000000279=1269=0270=1.2546271=500000055=GBP/USD110=3000000279=1269=1270=1.43494271=10000055=GBP/USD110=0279=1269=1270=1.43494271=50000055=GBP/USD110=100000279=1269=1270=1.43494271=100000055=GBP/USD110=500000279=1269=1270=1.43494271=300000055=GBP/USD110=1000000279=1269=1270=1.43494271=500000055=GBP/USD110=300000010=007
20260120-14:04:34.119793000 : 8=FIX.4.49=028035=X49=NTPRO_IDBA_UAT56=SIRIUS_500007460_MD34=128452=20260120-14:04:34.211262=MD_EUR/USD_140109278614268=3279=1269=0270=1.14787271=10000055=EUR/USD110=0279=1269=0270=1.14787271=50000055=EUR/USD110=100000279=1269=0270=1.14787271=100000055=EUR/USD110=50000010=011
20260120-14:04:34.120391000 : 8=FIX.4.49=039835=X49=NTPRO_IDBA_UAT56=SIRIUS_500007460_MD34=128552=20260120-14:04:34.211262=MD_GBP/USD_140109778778268=5279=1269=0270=1.25459271=10000055=GBP/USD110=0279=1269=0270=1.25459271=50000055=GBP/USD110=100000279=1269=0270=1.25459271=100000055=GBP/USD110=500000279=1269=0270=1.25459271=300000055=GBP/USD110=1000000279=1269=0270=1.25459271=500000055=GBP/USD110=300000010=104
20260120-14:04:34.135581000 : 8=FIX.4.49=039835=X49=NTPRO_IDBA_UAT56=SIRIUS_500007460_MD34=128652=20260120-14:04:34.237262=MD_GBP/USD_140109778778268=5279=1269=0270=1.25458271=10000055=GBP/USD110=0279=1269=0270=1.25458271=50000055=GBP/USD110=100000279=1269=0270=1.25458271=100000055=GBP/USD110=500000279=1269=0270=1.25458271=300000055=GBP/USD110=1000000279=1269=0270=1.25458271=500000055=GBP/USD110=300000010=108
20260120-14:04:34.149683000 : 8=FIX.4.49=039835=X49=NTPRO_IDBA_UAT56=SIRIUS_500007460_MD34=128752=20260120-14:04:34.252262=MD_GBP/USD_140109778778268=5279=1269=1270=1.43493271=10000055=GBP/USD110=0279=1269=1270=1.43493271=50000055=GBP/USD110=100000279=1269=1270=1.43493271=100000055=GBP/USD110=500000279=1269=1270=1.43493271=300000055=GBP/USD110=1000000279=1269=1270=1.43493271=500000055=GBP/USD110=300000010=106
20260120-14:04:34.799097000 : 8=FIX.4.49=028035=X49=NTPRO_IDBA_UAT56=SIRIUS_500007460_MD34=128852=20260120-14:04:34.925262=MD_EUR/USD_140109278614268=3279=1269=1270=1.19811271=10000055=EUR/USD110=0279=1269=1270=1.19811271=50000055=EUR/USD110=100000279=1269=1270=1.19811271=100000055=EUR/USD110=50000010=009
20260120-14:04:34.832219000 : 8=FIX.4.49=028035=X49=NTPRO_IDBA_UAT56=SIRIUS_500007460_MD34=128952=20260120-14:04:34.960262=MD_EUR/USD_140109278614268=3279=1269=1270=1.19812271=10000055=EUR/USD110=0279=1269=1270=1.19812271=50000055=EUR/USD110=100000279=1269=1270=1.19812271=100000055=EUR/USD110=50000010=012
20260120-14:04:35.017200000 : 8=FIX.4.49=039335=X49=NTPRO_IDBA_UAT56=SIRIUS_500007460_MD34=129052=20260120-14:04:35.151262=MD_GBP/USD_140109778778268=5279=1269=0270=1.2546271=10000055=GBP/USD110=0279=1269=0270=1.2546271=50000055=GBP/USD110=100000279=1269=0270=1.2546271=100000055=GBP/USD110=500000279=1269=0270=1.2546271=300000055=GBP/USD110=1000000279=1269=0270=1.2546271=500000055=GBP/USD110=300000010=075
20260120-14:04:35.059833000 : 8=FIX.4.49=068435=X49=NTPRO_IDBA_UAT56=SIRIUS_500007460_MD34=129152=20260120-14:04:35.196262=MD_GBP/USD_140109778778268=10279=1269=0270=1.25463271=10000055=GBP/USD110=0279=1269=0270=1.25463271=50000055=GBP/USD110=100000279=1269=0270=1.25463271=100000055=GBP/USD110=500000279=1269=0270=1.25463271=300000055=GBP/USD110=1000000279=1269=0270=1.25463271=500000055=GBP/USD110=3000000279=1269=1270=1.43494271=10000055=GBP/USD110=0279=1269=1270=1.43494271=50000055=GBP/USD110=100000279=1269=1270=1.43494271=100000055=GBP/USD110=500000279=1269=1270=1.43494271=300000055=GBP/USD110=1000000279=1269=1270=1.43494271=500000055=GBP/USD110=300000010=011
20260120-14:04:35.114406000 : 8=FIX.4.49=067435=X49=NTPRO_IDBA_UAT56=SIRIUS_500007460_MD34=129252=20260120-14:04:35.251262=MD_GBP/USD_140109778778268=10279=1269=0270=1.25465271=10000055=GBP/USD110=0279=1269=0270=1.25465271=50000055=GBP/USD110=100000279=1269=0270=1.25465271=100000055=GBP/USD110=500000279=1269=0270=1.25465271=300000055=GBP/USD110=1000000279=1269=0270=1.25465271=500000055=GBP/USD110=3000000279=1269=1270=1.435271=10000055=GBP/USD110=0279=1269=1270=1.435271=50000055=GBP/USD110=100000279=1269=1270=1.435271=100000055=GBP/USD110=500000279=1269=1270=1.435271=300000055=GBP/USD110=1000000279=1269=1270=1.435271=500000055=GBP/USD110=300000010=241
20260120-14:04:35.154785000 : 8=FIX.4.49=044435=X49=NTPRO_IDBA_UAT56=SIRIUS_500007460_MD34=129352=20260120-14:04:35.294262=MD_EUR/USD_140109278614268=6279=1269=0270=1.1479271=10000055=EUR/USD110=0279=1269=0270=1.1479271=50000055=EUR/USD110=100000279=1269=0270=1.1479271=100000055=EUR/USD110=500000279=1269=1270=1.19814271=10000055=EUR/USD110=0279=1269=1270=1.19814271=50000055=EUR/USD110=100000279=1269=1270=1.19814271=100000055=EUR/USD110=50000010=166
20260120-14:04:35.286154000 : 8=FIX.4.49=067435=X49=NTPRO_IDBA_UAT56=SIRIUS_500007460_MD34=129452=20260120-14:04:35.427262=MD_GBP/USD_140109778778268=10279=2269=0270=1.25465271=10000055=GBP/USD110=0279=2269=0270=1.25465271=50000055=GBP/USD110=100000279=2269=0270=1.25465271=100000055=GBP/USD110=500000279=2269=0270=1.25465271=300000055=GBP/USD110=1000000279=2269=0270=1.25465271=500000055=GBP/USD110=3000000279=2269=1270=1.435271=10000055=GBP/USD110=0279=2269=1270=1.435271=50000055=GBP/USD110=100000279=2269=1270=1.435271=100000055=GBP/USD110=500000279=2269=1270=1.435271=300000055=GBP/USD110=1000000279=2269=1270=1.435271=500000055=GBP/USD110=300000010=002
20260120-14:04:35.289632000 : 8=FIX.4.49=044735=X49=NTPRO_IDBA_UAT56=SIRIUS_500007460_MD34=129552=20260120-14:04:35.434262=MD_EUR/USD_140109278614268=6279=1269=0270=1.14788271=10000055=EUR/USD110=0279=1269=0270=1.14788271=50000055=EUR/USD110=100000279=1269=0270=1.14788271=100000055=EUR/USD110=500000279=1269=1270=1.19813271=10000055=EUR/USD110=0279=1269=1270=1.19813271=50000055=EUR/USD110=100000279=1269=1270=1.19813271=100000055=EUR/USD110=50000010=073
20260120-14:04:35.335475000 : 8=FIX.4.49=068435=X49=NTPRO_IDBA_UAT56=SIRIUS_500007460_MD34=129652=20260120-14:04:35.480262=MD_GBP/USD_140109778778268=10279=0269=0270=1.25462271=10000055=GBP/USD110=0279=0269=0270=1.25462271=50000055=GBP/USD110=100000279=0269=0270=1.25462271=100000055=GBP/USD110=500000279=0269=0270=1.25462271=300000055=GBP/USD110=1000000279=0269=0270=1.25462271=500000055=GBP/USD110=3000000279=0269=1270=1.43497271=10000055=GBP/USD110=0279=0269=1270=1.43497271=50000055=GBP/USD110=100000279=0269=1270=1.43497271=100000055=GBP/USD110=500000279=0269=1270=1.43497271=300000055=GBP/USD110=1000000279=0269=1270=1.43497271=500000055=GBP/USD110=300000010=012
20260120-14:04:35.370066000 : 8=FIX.4.49=044735=X49=NTPRO_IDBA_UAT56=SIRIUS_500007460_MD34=129752=20260120-14:04:35.517262=MD_EUR/USD_140109278614268=6279=1269=0270=1.14787271=10000055=EUR/USD110=0279=1269=0270=1.14787271=50000055=EUR/USD110=100000279=1269=0270=1.14787271=100000055=EUR/USD110=500000279=1269=1270=1.19812271=10000055=EUR/USD110=0279=1269=1270=1.19812271=50000055=EUR/USD110=100000279=1269=1270=1.19812271=100000055=EUR/USD110=50000010=071
20260120-14:04:35.484934000 : 8=FIX.4.49=039835=X49=NTPRO_IDBA_UAT56=SIRIUS_500007460_MD34=129852=20260120-14:04:35.636262=MD_GBP/USD_140109778778268=5279=1269=0270=1.25463271=10000055=GBP/USD110=0279=1269=0270=1.25463271=50000055=GBP/USD110=100000279=1269=0270=1.25463271=100000055=GBP/USD110=500000279=1269=0270=1.25463271=300000055=GBP/USD110=1000000279=1269=0270=1.25463271=500000055=GBP/USD110=300000010=095
20260120-14:04:35.515900000 : 8=FIX.4.49=028035=X49=NTPRO_IDBA_UAT56=SIRIUS_500007460_MD34=129952=20260120-14:04:35.669262=MD_EUR/USD_140109278614268=3279=1269=0270=1.14788271=10000055=EUR/USD110=0279=1269=0270=1.14788271=50000055=EUR/USD110=100000279=1269=0270=1.14788271=100000055=EUR/USD110=50000010=038
20260120-14:04:35.606599000 : 8=FIX.4.49=039835=X49=NTPRO_IDBA_UAT56=SIRIUS_500007460_MD34=130052=20260120-14:04:35.747262=MD_GBP/USD_140109778778268=5279=1269=1270=1.43498271=10000055=GBP/USD110=0279=1269=1270=1.43498271=50000055=GBP/USD110=100000279=1269=1270=1.43498271=100000055=GBP/USD110=500000279=1269=1270=1.43498271=300000055=GBP/USD110=1000000279=1269=1270=1.43498271=500000055=GBP/USD110=300000010=127
20260120-14:04:35.648556000 : 8=FIX.4.49=028035=X49=NTPRO_IDBA_UAT56=SIRIUS_500007460_MD34=130152=20260120-14:04:35.805262=MD_EUR/USD_140109278614268=3279=1269=1270=1.19813271=10000055=EUR/USD110=0279=1269=1270=1.19813271=50000055=EUR/USD110=100000279=1269=1270=1.19813271=100000055=EUR/USD110=50000010=255
20260120-14:04:36.167185000 : 8=FIX.4.49=068435=X49=NTPRO_IDBA_UAT56=SIRIUS_500007460_MD34=130252=20260120-14:04:36.344262=MD_GBP/USD_140109778778268=10279=2269=0270=1.25463271=10000055=GBP/USD110=0279=2269=0270=1.25463271=50000055=GBP/USD110=100000279=2269=0270=1.25463271=100000055=GBP/USD110=500000279=2269=0270=1.25463271=300000055=GBP/USD110=1000000279=2269=0270=1.25463271=500000055=GBP/USD110=3000000279=2269=1270=1.43498271=10000055=GBP/USD110=0279=2269=1270=1.43498271=50000055=GBP/USD110=100000279=2269=1270=1.43498271=100000055=GBP/USD110=500000279=2269=1270=1.43498271=300000055=GBP/USD110=1000000279=2269=1270=1.43498271=500000055=GBP/USD110=300000010=030
20260120-14:04:36.521079000 : 8=FIX.4.49=028035=X49=NTPRO_IDBA_UAT56=SIRIUS_500007460_MD34=130352=20260120-14:04:36.709262=MD_EUR/USD_140109278614268=3279=1269=0270=1.14789271=10000055=EUR/USD110=0279=1269=0270=1.14789271=50000055=EUR/USD110=100000279=1269=0270=1.14789271=100000055=EUR/USD110=50000010=023
20260120-14:04:36.550774000 : 8=FIX.4.49=068435=X49=NTPRO_IDBA_UAT56=SIRIUS_500007460_MD34=130452=20260120-14:04:36.742262=MD_GBP/USD_140109778778268=10279=0269=0270=1.25465271=10000055=GBP/USD110=0279=0269=0270=1.25465271=50000055=GBP/USD110=100000279=0269=0270=1.25465271=100000055=GBP/USD110=500000279=0269=0270=1.25465271=300000055=GBP/USD110=1000000279=0269=0270=1.25465271=500000055=GBP/USD110=3000000279=0269=1270=1.43499271=10000055=GBP/USD110=0279=0269=1270=1.43499271=50000055=GBP/USD110=100000279=0269=1270=1.43499271=100000055=GBP/USD110=500000279=0269=1270=1.43499271=300000055=GBP/USD110=1000000279=0269=1270=1.43499271=500000055=GBP/USD110=300000010=029
20260120-14:04:36.591421000 : 8=FIX.4.49=028035=X49=NTPRO_IDBA_UAT56=SIRIUS_500007460_MD34=130552=20260120-14:04:36.775262=MD_EUR/USD_140109278614268=3279=1269=1270=1.19814271=10000055=EUR/USD110=0279=1269=1270=1.19814271=50000055=EUR/USD110=100000279=1269=1270=1.19814271=100000055=EUR/USD110=50000010=013
20260120-14:04:36.645742000 : 8=FIX.4.49=038835=X49=NTPRO_IDBA_UAT56=SIRIUS_500007460_MD34=130652=20260120-14:04:36.840262=MD_GBP/USD_140109778778268=5279=1269=1270=1.435271=10000055=GBP/USD110=0279=1269=1270=1.435271=50000055=GBP/USD110=100000279=1269=1270=1.435271=100000055=GBP/USD110=500000279=1269=1270=1.435271=300000055=GBP/USD110=1000000279=1269=1270=1.435271=500000055=GBP/USD110=300000010=079
20260120-14:04:38.374721000 : 8=FIX.4.49=067435=X49=NTPRO_IDBA_UAT56=SIRIUS_500007460_MD34=130752=20260120-14:04:38.625262=MD_GBP/USD_140109778778268=10279=2269=0270=1.25465271=10000055=GBP/USD110=0279=2269=0270=1.25465271=50000055=GBP/USD110=100000279=2269=0270=1.25465271=100000055=GBP/USD110=500000279=2269=0270=1.25465271=300000055=GBP/USD110=1000000279=2269=0270=1.25465271=500000055=GBP/USD110=3000000279=2269=1270=1.435271=10000055=GBP/USD110=0279=2269=1270=1.435271=50000055=GBP/USD110=100000279=2269=1270=1.435271=100000055=GBP/USD110=500000279=2269=1270=1.435271=300000055=GBP/USD110=1000000279=2269=1270=1.435271=500000055=GBP/USD110=300000010=000
20260120-14:04:38.382181000 : 8=FIX.4.49=028035=X49=NTPRO_IDBA_UAT56=SIRIUS_500007460_MD34=130852=20260120-14:04:38.641262=MD_EUR/USD_140109278614268=3279=1269=1270=1.19813271=10000055=EUR/USD110=0279=1269=1270=1.19813271=50000055=EUR/USD110=100000279=1269=1270=1.19813271=100000055=EUR/USD110=50000010=007
20260120-14:04:38.433229000 : 8=FIX.4.49=068435=X49=NTPRO_IDBA_UAT56=SIRIUS_500007460_MD34=130952=20260120-14:04:38.694262=MD_GBP/USD_140109778778268=10279=0269=0270=1.25461271=10000055=GBP/USD110=0279=0269=0270=1.25461271=50000055=GBP/USD110=100000279=0269=0270=1.25461271=100000055=GBP/USD110=500000279=0269=0270=1.25461271=300000055=GBP/USD110=1000000279=0269=0270=1.25461271=500000055=GBP/USD110=3000000279=0269=1270=1.43498271=10000055=GBP/USD110=0279=0269=1270=1.43498271=50000055=GBP/USD110=100000279=0269=1270=1.43498271=100000055=GBP/USD110=500000279=0269=1270=1.43498271=300000055=GBP/USD110=1000000279=0269=1270=1.43498271=500000055=GBP/USD110=300000010=017
20260120-14:04:38.470603000 : 8=FIX.4.49=068435=X49=NTPRO_IDBA_UAT56=SIRIUS_500007460_MD34=131052=20260120-14:04:38.720262=MD_GBP/USD_140109778778268=10279=1269=0270=1.25458271=10000055=GBP/USD110=0279=1269=0270=1.25458271=50000055=GBP/USD110=100000279=1269=0270=1.25458271=100000055=GBP/USD110=500000279=1269=0270=1.25458271=300000055=GBP/USD110=1000000279=1269=0270=1.25458271=500000055=GBP/USD110=3000000279=1269=1270=1.43493271=10000055=GBP/USD110=0279=1269=1270=1.43493271=50000055=GBP/USD110=100000279=1269=1270=1.43493271=100000055=GBP/USD110=500000279=1269=1270=1.43493271=300000055=GBP/USD110=1000000279=1269=1270=1.43493271=500000055=GBP/USD110=300000010=014
20260120-14:04:38.698705000 : 8=FIX.4.49=028035=X49=NTPRO_IDBA_UAT56=SIRIUS_500007460_MD34=131152=20260120-14:04:38.970262=MD_EUR/USD_140109278614268=3279=1269=0270=1.14788271=10000055=EUR/USD110=0279=1269=0270=1.14788271=50000055=EUR/USD110=100000279=1269=0270=1.14788271=100000055=EUR/USD110=50000010=021
20260120-14:04:38.916903000 : 8=FIX.4.49=039835=X49=NTPRO_IDBA_UAT56=SIRIUS_500007460_MD34=131252=20260120-14:04:39.196262=MD_GBP/USD_140109778778268=5279=1269=0270=1.25459271=10000055=GBP/USD110=0279=1269=0270=1.25459271=50000055=GBP/USD110=100000279=1269=0270=1.25459271=100000055=GBP/USD110=500000279=1269=0270=1.25459271=300000055=GBP/USD110=1000000279=1269=0270=1.25459271=500000055=GBP/USD110=300000010=112
20260120-14:04:39.065179000 : 8=FIX.4.49=039835=X49=NTPRO_IDBA_UAT56=SIRIUS_500007460_MD34=131352=20260120-14:04:39.347262=MD_GBP/USD_140109778778268=5279=1269=0270=1.25458271=10000055=GBP/USD110=0279=1269=0270=1.25458271=50000055=GBP/USD110=100000279=1269=0270=1.25458271=100000055=GBP/USD110=500000279=1269=0270=1.25458271=300000055=GBP/USD110=1000000279=1269=0270=1.25458271=500000055=GBP/USD110=300000010=106
20260120-14:04:39.105291000 : 8=FIX.4.49=028035=X49=NTPRO_IDBA_UAT56=SIRIUS_500007460_MD34=131452=20260120-14:04:39.390262=MD_EUR/USD_140109278614268=3279=1269=1270=1.19812271=10000055=EUR/USD110=0279=1269=1270=1.19812271=50000055=EUR/USD110=100000279=1269=1270=1.19812271=100000055=EUR/USD110=50000010=003
20260120-14:04:39.264433000 : 8=FIX.4.49=039835=X49=NTPRO_IDBA_UAT56=SIRIUS_500007460_MD34=131552=20260120-14:04:39.552262=MD_GBP/USD_140109778778268=5279=1269=0270=1.25459271=10000055=GBP/USD110=0279=1269=0270=1.25459271=50000055=GBP/USD110=100000279=1269=0270=1.25459271=100000055=GBP/USD110=500000279=1269=0270=1.25459271=300000055=GBP/USD110=1000000279=1269=0270=1.25459271=500000055=GBP/USD110=300000010=111
20260120-14:04:39.313726000 : 8=FIX.4.49=039835=X49=NTPRO_IDBA_UAT56=SIRIUS_500007460_MD34=131652=20260120-14:04:39.607262=MD_GBP/USD_140109778778268=5279=1269=0270=1.25458271=10000055=GBP/USD110=0279=1269=0270=1.25458271=50000055=GBP/USD110=100000279=1269=0270=1.25458271=100000055=GBP/USD110=500000279=1269=0270=1.25458271=300000055=GBP/USD110=1000000279=1269=0270=1.25458271=500000055=GBP/USD110=300000010=108
20260120-14:04:39.358587000 : 8=FIX.4.49=044735=X49=NTPRO_IDBA_UAT56=SIRIUS_500007460_MD34=131752=20260120-14:04:39.640262=MD_EUR/USD_140109278614268=6279=1269=0270=1.14786271=10000055=EUR/USD110=0279=1269=0270=1.14786271=50000055=EUR/USD110=100000279=1269=0270=1.14786271=100000055=EUR/USD110=500000279=1269=1270=1.19811271=10000055=EUR/USD110=0279=1269=1270=1.19811271=50000055=EUR/USD110=100000279=1269=1270=1.19811271=100000055=EUR/USD110=50000010=059
20260120-14:04:39.414047000 : 8=FIX.4.49=039835=X49=NTPRO_IDBA_UAT56=SIRIUS_500007460_MD34=131852=20260120-14:04:39.711262=MD_GBP/USD_140109778778268=5279=1269=0270=1.25457271=10000055=GBP/USD110=0279=1269=0270=1.25457271=50000055=GBP/USD110=100000279=1269=0270=1.25457271=100000055=GBP/USD110=500000279=1269=0270=1.25457271=300000055=GBP/USD110=1000000279=1269=0270=1.25457271=500000055=GBP/USD110=300000010=101
20260120-14:04:39.418674000 : 8=FIX.4.49=044735=X49=NTPRO_IDBA_UAT56=SIRIUS_500007460_MD34=131952=20260120-14:04:39.716262=MD_EUR/USD_140109278614268=6279=2269=0270=1.14786271=10000055=EUR/USD110=0279=2269=0270=1.14786271=50000055=EUR/USD110=100000279=2269=0270=1.14786271=100000055=EUR/USD110=500000279=2269=1270=1.19811271=10000055=EUR/USD110=0279=2269=1270=1.19811271=50000055=EUR/USD110=100000279=2269=1270=1.19811271=100000055=EUR/USD110=50000010=071
20260120-14:04:39.463649000 : 8=FIX.4.49=068435=X49=NTPRO_IDBA_UAT56=SIRIUS_500007460_MD34=132052=20260120-14:04:39.762262=MD_GBP/USD_140109778778268=10279=1269=0270=1.25456271=10000055=GBP/USD110=0279=1269=0270=1.25456271=50000055=GBP/USD110=100000279=1269=0270=1.25456271=100000055=GBP/USD110=500000279=1269=0270=1.25456271=300000055=GBP/USD110=1000000279=1269=0270=1.25456271=500000055=GBP/USD110=3000000279=1269=1270=1.43492271=10000055=GBP/USD110=0279=1269=1270=1.43492271=50000055=GBP/USD110=100000279=1269=1270=1.43492271=100000055=GBP/USD110=500000279=1269=1270=1.43492271=300000055=GBP/USD110=1000000279=1269=1270=1.43492271=500000055=GBP/USD110=300000010=007
20260120-14:04:39.484173000 : 8=FIX.4.49=044435=X49=NTPRO_IDBA_UAT56=SIRIUS_500007460_MD34=132152=20260120-14:04:39.784262=MD_EUR/USD_140109278614268=6279=0269=0270=1.1478271=10000055=EUR/USD110=0279=0269=0270=1.1478271=50000055=EUR/USD110=100000279=0269=0270=1.1478271=100000055=EUR/USD110=500000279=0269=1270=1.19804271=10000055=EUR/USD110=0279=0269=1270=1.19804271=50000055=EUR/USD110=100000279=0269=1270=1.19804271=100000055=EUR/USD110=50000010=154
20260120-14:04:39.531818000 : 8=FIX.4.49=068435=X49=NTPRO_IDBA_UAT56=SIRIUS_500007460_MD34=132252=20260120-14:04:39.833262=MD_GBP/USD_140109778778268=10279=1269=0270=1.25452271=10000055=GBP/USD110=0279=1269=0270=1.25452271=50000055=GBP/USD110=100000279=1269=0270=1.25452271=100000055=GBP/USD110=500000279=1269=0270=1.25452271=300000055=GBP/USD110=1000000279=1269=0270=1.25452271=500000055=GBP/USD110=3000000279=1269=1270=1.43486271=10000055=GBP/USD110=0279=1269=1270=1.43486271=50000055=GBP/USD110=100000279=1269=1270=1.43486271=100000055=GBP/USD110=500000279=1269=1270=1.43486271=300000055=GBP/USD110=1000000279=1269=1270=1.43486271=500000055=GBP/USD110=300000010=003
20260120-14:04:39.573345000 : 8=FIX.4.49=028035=X49=NTPRO_IDBA_UAT56=SIRIUS_500007460_MD34=132352=20260120-14:04:39.873262=MD_EUR/USD_140109278614268=3279=1269=0270=1.14779271=10000055=EUR/USD110=0279=1269=0270=1.14779271=50000055=EUR/USD110=100000279=1269=0270=1.14779271=100000055=EUR/USD110=50000010=027
20260120-14:04:39.587368000 : 8=FIX.4.49=068435=X49=NTPRO_IDBA_UAT56=SIRIUS_500007460_MD34=132452=20260120-14:04:39.888262=MD_GBP/USD_140109778778268=10279=1269=0270=1.25454271=10000055=GBP/USD110=0279=1269=0270=1.25454271=50000055=GBP/USD110=100000279=1269=0270=1.25454271=100000055=GBP/USD110=500000279=1269=0270=1.25454271=300000055=GBP/USD110=1000000279=1269=0270=1.25454271=500000055=GBP/USD110=3000000279=1269=1270=1.43489271=10000055=GBP/USD110=0279=1269=1270=1.43489271=50000055=GBP/USD110=100000279=1269=1270=1.43489271=100000055=GBP/USD110=500000279=1269=1270=1.43489271=300000055=GBP/USD110=1000000279=1269=1270=1.43489271=500000055=GBP/USD110=300000010=040
20260120-14:04:39.676671000 : 8=FIX.4.49=028035=X49=NTPRO_IDBA_UAT56=SIRIUS_500007460_MD34=132552=20260120-14:04:39.981262=MD_EUR/USD_140109278614268=3279=1269=1270=1.19803271=10000055=EUR/USD110=0279=1269=1270=1.19803271=50000055=EUR/USD110=100000279=1269=1270=1.19803271=100000055=EUR/USD110=50000010=011
20260120-14:04:39.747872000 : 8=FIX.4.49=044435=X49=NTPRO_IDBA_UAT56=SIRIUS_500007460_MD34=132652=20260120-14:04:40.055262=MD_EUR/USD_140109278614268=6279=1269=0270=1.1478271=10000055=EUR/USD110=0279=1269=0270=1.1478271=50000055=EUR/USD110=100000279=1269=0270=1.1478271=100000055=EUR/USD110=500000279=1269=1270=1.19804271=10000055=EUR/USD110=0279=1269=1270=1.19804271=50000055=EUR/USD110=100000279=1269=1270=1.19804271=100000055=EUR/USD110=50000010=148
20260120-14:04:39.853687000 : 8=FIX.4.49=044735=X49=NTPRO_IDBA_UAT56=SIRIUS_500007460_MD34=132752=20260120-14:04:40.152262=MD_EUR/USD_140109278614268=6279=1269=0270=1.14779271=10000055=EUR/USD110=0279=1269=0270=1.14779271=50000055=EUR/USD110=100000279=1269=0270=1.14779271=100000055=EUR/USD110=500000279=1269=1270=1.19803271=10000055=EUR/USD110=0279=1269=1270=1.19803271=50000055=EUR/USD110=100000279=1269=1270=1.19803271=100000055=EUR/USD110=50000010=059
20260120-14:04:40.015420000 : 8=FIX.4.49=044735=X49=NTPRO_IDBA_UAT56=SIRIUS_500007460_MD34=132852=20260120-14:04:40.335262=MD_EUR/USD_140109278614268=6279=1269=0270=1.14777271=10000055=EUR/USD110=0279=1269=0270=1.14777271=50000055=EUR/USD110=100000279=1269=0270=1.14777271=100000055=EUR/USD110=500000279=1269=1270=1.19802271=10000055=EUR/USD110=0279=1269=1270=1.19802271=50000055=EUR/USD110=100000279=1269=1270=1.19802271=100000055=EUR/USD110=50000010=054
20260120-14:04:40.114126000 : 8=FIX.4.49=068435=X49=NTPRO_IDBA_UAT56=SIRIUS_500007460_MD34=132952=20260120-14:04:40.437262=MD_GBP/USD_140109778778268=10279=2269=0270=1.25454271=10000055=GBP/USD110=0279=2269=0270=1.25454271=50000055=GBP/USD110=100000279=2269=0270=1.25454271=100000055=GBP/USD110=500000279=2269=0270=1.25454271=300000055=GBP/USD110=1000000279=2269=0270=1.25454271=500000055=GBP/USD110=3000000279=2269=1270=1.43489271=10000055=GBP/USD110=0279=2269=1270=1.43489271=50000055=GBP/USD110=100000279=2269=1270=1.43489271=100000055=GBP/USD110=500000279=2269=1270=1.43489271=300000055=GBP/USD110=1000000279=2269=1270=1.43489271=500000055=GBP/USD110=300000010=037
20260120-14:04:40.247727000 : 8=FIX.4.49=068435=X49=NTPRO_IDBA_UAT56=SIRIUS_500007460_MD34=133052=20260120-14:04:40.575262=MD_GBP/USD_140109778778268=10279=0269=0270=1.25453271=10000055=GBP/USD110=0279=0269=0270=1.25453271=50000055=GBP/USD110=100000279=0269=0270=1.25453271=100000055=GBP/USD110=500000279=0269=0270=1.25453271=300000055=GBP/USD110=1000000279=0269=0270=1.25453271=500000055=GBP/USD110=3000000279=0269=1270=1.43488271=10000055=GBP/USD110=0279=0269=1270=1.43488271=50000055=GBP/USD110=100000279=0269=1270=1.43488271=100000055=GBP/USD110=500000279=0269=1270=1.43488271=300000055=GBP/USD110=1000000279=0269=1270=1.43488271=500000055=GBP/USD110=300000010=002
20260120-14:04:40.411170000 : 8=FIX.4.49=044735=X49=NTPRO_IDBA_UAT56=SIRIUS_500007460_MD34=133152=20260120-14:04:40.744262=MD_EUR/USD_140109278614268=6279=1269=0270=1.14776271=10000055=EUR/USD110=0279=1269=0270=1.14776271=50000055=EUR/USD110=100000279=1269=0270=1.14776271=100000055=EUR/USD110=500000279=1269=1270=1.19801271=10000055=EUR/USD110=0279=1269=1270=1.19801271=50000055=EUR/USD110=100000279=1269=1270=1.19801271=100000055=EUR/USD110=50000010=046
20260120-14:04:40.484658000 : 8=FIX.4.49=028035=X49=NTPRO_IDBA_UAT56=SIRIUS_500007460_MD34=133252=20260120-14:04:40.822262=MD_EUR/USD_140109278614268=3279=1269=0270=1.14777271=10000055=EUR/USD110=0279=1269=0270=1.14777271=50000055=EUR/USD110=100000279=1269=0270=1.14777271=100000055=EUR/USD110=50000010=007
20260120-14:04:40.588482000 : 8=FIX.4.49=028035=X49=NTPRO_IDBA_UAT56=SIRIUS_500007460_MD34=133352=20260120-14:04:40.929262=MD_EUR/USD_140109278614268=3279=1269=1270=1.19802271=10000055=EUR/USD110=0279=1269=1270=1.19802271=50000055=EUR/USD110=100000279=1269=1270=1.19802271=100000055=EUR/USD110=50000010=001
20260120-14:04:40.740904000 : 8=FIX.4.49=044735=X49=NTPRO_IDBA_UAT56=SIRIUS_500007460_MD34=133452=20260120-14:04:41.087262=MD_EUR/USD_140109278614268=6279=1269=0270=1.14778271=10000055=EUR/USD110=0279=1269=0270=1.14778271=50000055=EUR/USD110=100000279=1269=0270=1.14778271=100000055=EUR/USD110=500000279=1269=1270=1.19803271=10000055=EUR/USD110=0279=1269=1270=1.19803271=50000055=EUR/USD110=100000279=1269=1270=1.19803271=100000055=EUR/USD110=50000010=062
20260120-14:04:40.753726000 : 8=FIX.4.49=067935=X49=NTPRO_IDBA_UAT56=SIRIUS_500007460_MD34=133552=20260120-14:04:41.101262=MD_GBP/USD_140109778778268=10279=1269=0270=1.25454271=10000055=GBP/USD110=0279=1269=0270=1.25454271=50000055=GBP/USD110=100000279=1269=0270=1.25454271=100000055=GBP/USD110=500000279=1269=0270=1.25454271=300000055=GBP/USD110=1000000279=1269=0270=1.25454271=500000055=GBP/USD110=3000000279=1269=1270=1.4349271=10000055=GBP/USD110=0279=1269=1270=1.4349271=50000055=GBP/USD110=100000279=1269=1270=1.4349271=100000055=GBP/USD110=500000279=1269=1270=1.4349271=300000055=GBP/USD110=1000000279=1269=1270=1.4349271=500000055=GBP/USD110=300000010=249
20260120-14:04:40.843157000 : 8=FIX.4.49=068435=X49=NTPRO_IDBA_UAT56=SIRIUS_500007460_MD34=133652=20260120-14:04:41.192262=MD_GBP/USD_140109778778268=10279=1269=0270=1.25453271=10000055=GBP/USD110=0279=1269=0270=1.25453271=50000055=GBP/USD110=100000279=1269=0270=1.25453271=100000055=GBP/USD110=500000279=1269=0270=1.25453271=300000055=GBP/USD110=1000000279=1269=0270=1.25453271=500000055=GBP/USD110=3000000279=1269=1270=1.43488271=10000055=GBP/USD110=0279=1269=1270=1.43488271=50000055=GBP/USD110=100000279=1269=1270=1.43488271=100000055=GBP/USD110=500000279=1269=1270=1.43488271=300000055=GBP/USD110=1000000279=1269=1270=1.43488271=500000055=GBP/USD110=300000010=014
20260120-14:04:40.971524000 : 8=FIX.4.49=068435=X49=NTPRO_IDBA_UAT56=SIRIUS_500007460_MD34=133752=20260120-14:04:41.329262=MD_GBP/USD_140109778778268=10279=2269=0270=1.25453271=10000055=GBP/USD110=0279=2269=0270=1.25453271=50000055=GBP/USD110=100000279=2269=0270=1.25453271=100000055=GBP/USD110=500000279=2269=0270=1.25453271=300000055=GBP/USD110=1000000279=2269=0270=1.25453271=500000055=GBP/USD110=3000000279=2269=1270=1.43488271=10000055=GBP/USD110=0279=2269=1270=1.43488271=50000055=GBP/USD110=100000279=2269=1270=1.43488271=100000055=GBP/USD110=500000279=2269=1270=1.43488271=300000055=GBP/USD110=1000000279=2269=1270=1.43488271=500000055=GBP/USD110=300000010=027
20260120-14:04:41.207381000 : 8=FIX.4.49=028035=X49=NTPRO_IDBA_UAT56=SIRIUS_500007460_MD34=133852=20260120-14:04:41.578262=MD_EUR/USD_140109278614268=3279=1269=1270=1.19802271=10000055=EUR/USD110=0279=1269=1270=1.19802271=50000055=EUR/USD110=100000279=1269=1270=1.19802271=100000055=EUR/USD110=50000010=007
20260120-14:04:41.228852000 : 8=FIX.4.49=068435=X49=NTPRO_IDBA_UAT56=SIRIUS_500007460_MD34=133952=20260120-14:04:41.600262=MD_GBP/USD_140109778778268=10279=0269=0270=1.25452271=10000055=GBP/USD110=0279=0269=0270=1.25452271=50000055=GBP/USD110=100000279=0269=0270=1.25452271=100000055=GBP/USD110=500000279=0269=0270=1.25452271=300000055=GBP/USD110=1000000279=0269=0270=1.25452271=500000055=GBP/USD110=3000000279=0269=1270=1.43486271=10000055=GBP/USD110=0279=0269=1270=1.43486271=50000055=GBP/USD110=100000279=0269=1270=1.43486271=100000055=GBP/USD110=500000279=0269=1270=1.43486271=300000055=GBP/USD110=1000000279=0269=1270=1.43486271=500000055=GBP/USD110=300000010=242
20260120-14:04:41.258545000 : 8=FIX.4.49=039835=X49=NTPRO_IDBA_UAT56=SIRIUS_500007460_MD34=134052=20260120-14:04:41.632262=MD_GBP/USD_140109778778268=5279=1269=1270=1.43487271=10000055=GBP/USD110=0279=1269=1270=1.43487271=50000055=GBP/USD110=100000279=1269=1270=1.43487271=100000055=GBP/USD110=500000279=1269=1270=1.43487271=300000055=GBP/USD110=1000000279=1269=1270=1.43487271=500000055=GBP/USD110=300000010=111
20260120-14:04:41.363469000 : 8=FIX.4.49=044135=X49=NTPRO_IDBA_UAT56=SIRIUS_500007460_MD34=134152=20260120-14:04:41.739262=MD_EUR/USD_140109278614268=6279=1269=0270=1.14776271=10000055=EUR/USD110=0279=1269=0270=1.14776271=50000055=EUR/USD110=100000279=1269=0270=1.14776271=100000055=EUR/USD110=500000279=1269=1270=1.198271=10000055=EUR/USD110=0279=1269=1270=1.198271=50000055=EUR/USD110=100000279=1269=1270=1.198271=100000055=EUR/USD110=50000010=011
20260120-14:04:41.371233000 : 8=FIX.4.49=067935=X49=NTPRO_IDBA_UAT56=SIRIUS_500007460_MD34=134252=20260120-14:04:41.752262=MD_GBP/USD_140109778778268=10279=1269=0270=1.2545271=10000055=GBP/USD110=0279=1269=0270=1.2545271=50000055=GBP/USD110=100000279=1269=0270=1.2545271=100000055=GBP/USD110=500000279=1269=0270=1.2545271=300000055=GBP/USD110=1000000279=1269=0270=1.2545271=500000055=GBP/USD110=3000000279=1269=1270=1.43485271=10000055=GBP/USD110=0279=1269=1270=1.43485271=50000055=GBP/USD110=100000279=1269=1270=1.43485271=100000055=GBP/USD110=500000279=1269=1270=1.43485271=300000055=GBP/USD110=1000000279=1269=1270=1.43485271=500000055=GBP/USD110=300000010=003
20260120-14:04:41.421284000 : 8=FIX.4.49=039835=X49=NTPRO_IDBA_UAT56=SIRIUS_500007460_MD34=134352=20260120-14:04:41.793262=MD_GBP/USD_140109778778268=5279=1269=0270=1.25449271=10000055=GBP/USD110=0279=1269=0270=1.25449271=50000055=GBP/USD110=100000279=1269=0270=1.25449271=100000055=GBP/USD110=500000279=1269=0270=1.25449271=300000055=GBP/USD110=1000000279=1269=0270=1.25449271=500000055=GBP/USD110=300000010=107
20260120-14:04:41.438742000 : 8=FIX.4.49=068435=X49=NTPRO_IDBA_UAT56=SIRIUS_500007460_MD34=134452=20260120-14:04:41.823262=MD_GBP/USD_140109778778268=10279=1269=0270=1.25448271=10000055=GBP/USD110=0279=1269=0270=1.25448271=50000055=GBP/USD110=100000279=1269=0270=1.25448271=100000055=GBP/USD110=500000279=1269=0270=1.25448271=300000055=GBP/USD110=1000000279=1269=0270=1.25448271=500000055=GBP/USD110=3000000279=1269=1270=1.43483271=10000055=GBP/USD110=0279=1269=1270=1.43483271=50000055=GBP/USD110=100000279=1269=1270=1.43483271=100000055=GBP/USD110=500000279=1269=1270=1.43483271=300000055=GBP/USD110=1000000279=1269=1270=1.43483271=500000055=GBP/USD110=300000010=009
20260120-14:04:41.451519000 : 8=FIX.4.49=028035=X49=NTPRO_IDBA_UAT56=SIRIUS_500007460_MD34=134552=20260120-14:04:41.837262=MD_EUR/USD_140109278614268=3279=1269=1270=1.19801271=10000055=EUR/USD110=0279=1269=1270=1.19801271=50000055=EUR/USD110=100000279=1269=1270=1.19801271=100000055=EUR/USD110=50000010=000
20260120-14:04:41.529432000 : 8=FIX.4.49=044735=X49=NTPRO_IDBA_UAT56=SIRIUS_500007460_MD34=134652=20260120-14:04:41.918262=MD_EUR/USD_140109278614268=6279=1269=0270=1.14777271=10000055=EUR/USD110=0279=1269=0270=1.14777271=50000055=EUR/USD110=100000279=1269=0270=1.14777271=100000055=EUR/USD110=500000279=1269=1270=1.19802271=10000055=EUR/USD110=0279=1269=1270=1.19802271=50000055=EUR/USD110=100000279=1269=1270=1.19802271=100000055=EUR/USD110=50000010=062
20260120-14:04:41.570786000 : 8=FIX.4.49=044135=X49=NTPRO_IDBA_UAT56=SIRIUS_500007460_MD34=134752=20260120-14:04:41.962262=MD_EUR/USD_140109278614268=6279=1269=0270=1.14775271=10000055=EUR/USD110=0279=1269=0270=1.14775271=50000055=EUR/USD110=100000279=1269=0270=1.14775271=100000055=EUR/USD110=500000279=1269=1270=1.198271=10000055=EUR/USD110=0279=1269=1270=1.198271=50000055=EUR/USD110=100000279=1269=1270=1.198271=100000055=EUR/USD110=50000010=012
20260120-14:04:41.652258000 : 8=FIX.4.49=044735=X49=NTPRO_IDBA_UAT56=SIRIUS_500007460_MD34=134852=20260120-14:04:42.049262=MD_EUR/USD_140109278614268=6279=1269=0270=1.14777271=10000055=EUR/USD110=0279=1269=0270=1.14777271=50000055=EUR/USD110=100000279=1269=0270=1.14777271=100000055=EUR/USD110=500000279=1269=1270=1.19802271=10000055=EUR/USD110=0279=1269=1270=1.19802271=50000055=EUR/USD110=100000279=1269=1270=1.19802271=100000055=EUR/USD110=50000010=060
20260120-14:04:41.671140000 : 8=FIX.4.49=028035=X49=NTPRO_IDBA_UAT56=SIRIUS_500007460_MD34=134952=20260120-14:04:42.069262=MD_EUR/USD_140109278614268=3279=1269=1270=1.19801271=10000055=EUR/USD110=0279=1269=1270=1.19801271=50000055=EUR/USD110=100000279=1269=1270=1.19801271=100000055=EUR/USD110=50000010=002
20260120-14:04:41.805625000 : 8=FIX.4.49=044135=X49=NTPRO_IDBA_UAT56=SIRIUS_500007460_MD34=135052=20260120-14:04:42.186262=MD_EUR/USD_140109278614268=6279=1269=0270=1.14775271=10000055=EUR/USD110=0279=1269=0270=1.14775271=50000055=EUR/USD110=100000279=1269=0270=1.14775271=100000055=EUR/USD110=500000279=1269=1270=1.198271=10000055=EUR/USD110=0279=1269=1270=1.198271=50000055=EUR/USD110=100000279=1269=1270=1.198271=100000055=EUR/USD110=50000010=005
20260120-14:04:41.910593000 : 8=FIX.4.49=044735=X49=NTPRO_IDBA_UAT56=SIRIUS_500007460_MD34=135152=20260120-14:04:42.304262=MD_EUR/USD_140109278614268=6279=1269=0270=1.14777271=10000055=EUR/USD110=0279=1269=0270=1.14777271=50000055=EUR/USD110=100000279=1269=0270=1.14777271=100000055=EUR/USD110=500000279=1269=1270=1.19802271=10000055=EUR/USD110=0279=1269=1270=1.19802271=50000055=EUR/USD110=100000279=1269=1270=1.19802271=100000055=EUR/USD110=50000010=048
20260120-14:04:41.937462000 : 8=FIX.4.49=044135=X49=NTPRO_IDBA_UAT56=SIRIUS_500007460_MD34=135252=20260120-14:04:42.349262=MD_EUR/USD_140109278614268=6279=1269=0270=1.14775271=10000055=EUR/USD110=0279=1269=0270=1.14775271=50000055=EUR/USD110=100000279=1269=0270=1.14775271=100000055=EUR/USD110=500000279=1269=1270=1.198271=10000055=EUR/USD110=0279=1269=1270=1.198271=50000055=EUR/USD110=100000279=1269=1270=1.198271=100000055=EUR/USD110=50000010=008
20260120-14:04:42.054760000 : 8=FIX.4.49=039835=X49=NTPRO_IDBA_UAT56=SIRIUS_500007460_MD34=135352=20260120-14:04:42.474262=MD_GBP/USD_140109778778268=5279=1269=1270=1.43484271=10000055=GBP/USD110=0279=1269=1270=1.43484271=50000055=GBP/USD110=100000279=1269=1270=1.43484271=100000055=GBP/USD110=500000279=1269=1270=1.43484271=300000055=GBP/USD110=1000000279=1269=1270=1.43484271=500000055=GBP/USD110=300000010=105
20260120-14:04:42.246487000 : 8=FIX.4.49=044735=X49=NTPRO_IDBA_UAT56=SIRIUS_500007460_MD34=135452=20260120-14:04:42.677262=MD_EUR/USD_140109278614268=6279=1269=0270=1.14776271=10000055=EUR/USD110=0279=1269=0270=1.14776271=50000055=EUR/USD110=100000279=1269=0270=1.14776271=100000055=EUR/USD110=500000279=1269=1270=1.19801271=10000055=EUR/USD110=0279=1269=1270=1.19801271=50000055=EUR/USD110=100000279=1269=1270=1.19801271=100000055=EUR/USD110=50000010=058
20260120-14:04:42.268377000 : 8=FIX.4.49=068435=X49=NTPRO_IDBA_UAT56=SIRIUS_500007460_MD34=135552=20260120-14:04:42.697262=MD_GBP/USD_140109778778268=10279=2269=0270=1.25448271=10000055=GBP/USD110=0279=2269=0270=1.25448271=50000055=GBP/USD110=100000279=2269=0270=1.25448271=100000055=GBP/USD110=500000279=2269=0270=1.25448271=300000055=GBP/USD110=1000000279=2269=0270=1.25448271=500000055=GBP/USD110=3000000279=2269=1270=1.43484271=10000055=GBP/USD110=0279=2269=1270=1.43484271=50000055=GBP/USD110=100000279=2269=1270=1.43484271=100000055=GBP/USD110=500000279=2269=1270=1.43484271=300000055=GBP/USD110=1000000279=2269=1270=1.43484271=500000055=GBP/USD110=300000010=036
20260120-14:04:42.365203000 : 8=FIX.4.49=068435=X49=NTPRO_IDBA_UAT56=SIRIUS_500007460_MD34=135652=20260120-14:04:42.802262=MD_GBP/USD_140109778778268=10279=0269=0270=1.25448271=10000055=GBP/USD110=0279=0269=0270=1.25448271=50000055=GBP/USD110=100000279=0269=0270=1.25448271=100000055=GBP/USD110=500000279=0269=0270=1.25448271=300000055=GBP/USD110=1000000279=0269=0270=1.25448271=500000055=GBP/USD110=3000000279=0269=1270=1.43484271=10000055=GBP/USD110=0279=0269=1270=1.43484271=50000055=GBP/USD110=100000279=0269=1270=1.43484271=100000055=GBP/USD110=500000279=0269=1270=1.43484271=300000055=GBP/USD110=1000000279=0269=1270=1.43484271=500000055=GBP/USD110=300000010=005
20260120-14:04:42.596250000 : 8=FIX.4.49=068435=X49=NTPRO_IDBA_UAT56=SIRIUS_500007460_MD34=135752=20260120-14:04:43.047262=MD_GBP/USD_140109778778268=10279=1269=0270=1.25449271=10000055=GBP/USD110=0279=1269=0270=1.25449271=50000055=GBP/USD110=100000279=1269=0270=1.25449271=100000055=GBP/USD110=500000279=1269=0270=1.25449271=300000055=GBP/USD110=1000000279=1269=0270=1.25449271=500000055=GBP/USD110=3000000279=1269=1270=1.43485271=10000055=GBP/USD110=0279=1269=1270=1.43485271=50000055=GBP/USD110=100000279=1269=1270=1.43485271=100000055=GBP/USD110=500000279=1269=1270=1.43485271=300000055=GBP/USD110=1000000279=1269=1270=1.43485271=500000055=GBP/USD110=300000010=028
20260120-14:04:42.696247000 : 8=FIX.4.49=027435=X49=NTPRO_IDBA_UAT56=SIRIUS_500007460_MD34=135852=20260120-14:04:43.154262=MD_EUR/USD_140109278614268=3279=1269=1270=1.198271=10000055=EUR/USD110=0279=1269=1270=1.198271=50000055=EUR/USD110=100000279=1269=1270=1.198271=100000055=EUR/USD110=50000010=222
20260120-14:04:42.712125000 : 8=FIX.4.49=068435=X49=NTPRO_IDBA_UAT56=SIRIUS_500007460_MD34=135952=20260120-14:04:43.170262=MD_GBP/USD_140109778778268=10279=2269=0270=1.25449271=10000055=GBP/USD110=0279=2269=0270=1.25449271=50000055=GBP/USD110=100000279=2269=0270=1.25449271=100000055=GBP/USD110=500000279=2269=0270=1.25449271=300000055=GBP/USD110=1000000279=2269=0270=1.25449271=500000055=GBP/USD110=3000000279=2269=1270=1.43485271=10000055=GBP/USD110=0279=2269=1270=1.43485271=50000055=GBP/USD110=100000279=2269=1270=1.43485271=100000055=GBP/USD110=500000279=2269=1270=1.43485271=300000055=GBP/USD110=1000000279=2269=1270=1.43485271=500000055=GBP/USD110=300000010=037
20260120-14:04:42.740995000 : 8=FIX.4.49=044735=X49=NTPRO_IDBA_UAT56=SIRIUS_500007460_MD34=136052=20260120-14:04:43.201262=MD_EUR/USD_140109278614268=6279=1269=0270=1.14773271=10000055=EUR/USD110=0279=1269=0270=1.14773271=50000055=EUR/USD110=100000279=1269=0270=1.14773271=100000055=EUR/USD110=500000279=1269=1270=1.19799271=10000055=EUR/USD110=0279=1269=1270=1.19799271=50000055=EUR/USD110=100000279=1269=1270=1.19799271=100000055=EUR/USD110=50000010=078
20260120-14:04:42.757779000 : 8=FIX.4.49=068435=X49=NTPRO_IDBA_UAT56=SIRIUS_500007460_MD34=136152=20260120-14:04:43.219262=MD_GBP/USD_140109778778268=10279=0269=0270=1.25447271=10000055=GBP/USD110=0279=0269=0270=1.25447271=50000055=GBP/USD110=100000279=0269=0270=1.25447271=100000055=GBP/USD110=500000279=0269=0270=1.25447271=300000055=GBP/USD110=1000000279=0269=0270=1.25447271=500000055=GBP/USD110=3000000279=0269=1270=1.43483271=10000055=GBP/USD110=0279=0269=1270=1.43483271=50000055=GBP/USD110=100000279=0269=1270=1.43483271=100000055=GBP/USD110=500000279=0269=1270=1.43483271=300000055=GBP/USD110=1000000279=0269=1270=1.43483271=500000055=GBP/USD110=300000010=250
20260120-14:04:42.810876000 : 8=FIX.4.49=028035=X49=NTPRO_IDBA_UAT56=SIRIUS_500007460_MD34=136252=20260120-14:04:43.275262=MD_EUR/USD_140109278614268=3279=1269=1270=1.19798271=10000055=EUR/USD110=0279=1269=1270=1.19798271=50000055=EUR/USD110=100000279=1269=1270=1.19798271=100000055=EUR/USD110=50000010=042
20260120-14:04:42.873510000 : 8=FIX.4.49=044735=X49=NTPRO_IDBA_UAT56=SIRIUS_500007460_MD34=136352=20260120-14:04:43.341262=MD_EUR/USD_140109278614268=6279=1269=0270=1.14772271=10000055=EUR/USD110=0279=1269=0270=1.14772271=50000055=EUR/USD110=100000279=1269=0270=1.14772271=100000055=EUR/USD110=500000279=1269=1270=1.19797271=10000055=EUR/USD110=0279=1269=1270=1.19797271=50000055=EUR/USD110=100000279=1269=1270=1.19797271=100000055=EUR/USD110=50000010=077
20260120-14:04:42.965515000 : 8=FIX.4.49=028035=X49=NTPRO_IDBA_UAT56=SIRIUS_500007460_MD34=136452=20260120-14:04:43.426262=MD_EUR/USD_140109278614268=3279=1269=0270=1.14773271=10000055=EUR/USD110=0279=1269=0270=1.14773271=50000055=EUR/USD110=100000279=1269=0270=1.14773271=100000055=EUR/USD110=50000010=003
20260120-14:04:43.033433000 : 8=FIX.4.49=028035=X49=NTPRO_IDBA_UAT56=SIRIUS_500007460_MD34=136552=20260120-14:04:43.511262=MD_EUR/USD_140109278614268=3279=1269=1270=1.19798271=10000055=EUR/USD110=0279=1269=1270=1.19798271=50000055=EUR/USD110=100000279=1269=1270=1.19798271=100000055=EUR/USD110=50000010=038
20260120-14:04:43.093107000 : 8=FIX.4.49=044735=X49=NTPRO_IDBA_UAT56=SIRIUS_500007460_MD34=136652=20260120-14:04:43.561262=MD_EUR/USD_140109278614268=6279=1269=0270=1.14774271=10000055=EUR/USD110=0279=1269=0270=1.14774271=50000055=EUR/USD110=100000279=1269=0270=1.14774271=100000055=EUR/USD110=500000279=1269=1270=1.19799271=10000055=EUR/USD110=0279=1269=1270=1.19799271=50000055=EUR/USD110=100000279=1269=1270=1.19799271=100000055=EUR/USD110=50000010=096
20260120-14:04:43.093906000 : 8=FIX.4.49=068435=X49=NTPRO_IDBA_UAT56=SIRIUS_500007460_MD34=136752=20260120-14:04:43.563262=MD_GBP/USD_140109778778268=10279=2269=0270=1.25447271=10000055=GBP/USD110=0279=2269=0270=1.25447271=50000055=GBP/USD110=100000279=2269=0270=1.25447271=100000055=GBP/USD110=500000279=2269=0270=1.25447271=300000055=GBP/USD110=1000000279=2269=0270=1.25447271=500000055=GBP/USD110=3000000279=2269=1270=1.43483271=10000055=GBP/USD110=0279=2269=1270=1.43483271=50000055=GBP/USD110=100000279=2269=1270=1.43483271=100000055=GBP/USD110=500000279=2269=1270=1.43483271=300000055=GBP/USD110=1000000279=2269=1270=1.43483271=500000055=GBP/USD110=300000010=022
20260120-14:04:43.301875000 : 8=FIX.4.49=044735=X49=NTPRO_IDBA_UAT56=SIRIUS_500007460_MD34=136852=20260120-14:04:43.791262=MD_EUR/USD_140109278614268=6279=1269=0270=1.14773271=10000055=EUR/USD110=0279=1269=0270=1.14773271=50000055=EUR/USD110=100000279=1269=0270=1.14773271=100000055=EUR/USD110=500000279=1269=1270=1.19798271=10000055=EUR/USD110=0279=1269=1270=1.19798271=50000055=EUR/USD110=100000279=1269=1270=1.19798271=100000055=EUR/USD110=50000010=097
20260120-14:04:43.939236000 : 8=FIX.4.49=068435=X49=NTPRO_IDBA_UAT56=SIRIUS_500007460_MD34=136952=20260120-14:04:44.464262=MD_GBP/USD_140109778778268=10279=0269=0270=1.25448271=10000055=GBP/USD110=0279=0269=0270=1.25448271=50000055=GBP/USD110=100000279=0269=0270=1.25448271=100000055=GBP/USD110=500000279=0269=0270=1.25448271=300000055=GBP/USD110=1000000279=0269=0270=1.25448271=500000055=GBP/USD110=3000000279=0269=1270=1.43483271=10000055=GBP/USD110=0279=0269=1270=1.43483271=50000055=GBP/USD110=100000279=0269=1270=1.43483271=100000055=GBP/USD110=500000279=0269=1270=1.43483271=300000055=GBP/USD110=1000000279=0269=1270=1.43483271=500000055=GBP/USD110=300000010=010
20260120-14:04:44.097854000 : 8=FIX.4.49=068435=X49=NTPRO_IDBA_UAT56=SIRIUS_500007460_MD34=137052=20260120-14:04:44.637262=MD_GBP/USD_140109778778268=10279=2269=0270=1.25448271=10000055=GBP/USD110=0279=2269=0270=1.25448271=50000055=GBP/USD110=100000279=2269=0270=1.25448271=100000055=GBP/USD110=500000279=2269=0270=1.25448271=300000055=GBP/USD110=1000000279=2269=0270=1.25448271=500000055=GBP/USD110=3000000279=2269=1270=1.43483271=10000055=GBP/USD110=0279=2269=1270=1.43483271=50000055=GBP/USD110=100000279=2269=1270=1.43483271=100000055=GBP/USD110=500000279=2269=1270=1.43483271=300000055=GBP/USD110=1000000279=2269=1270=1.43483271=500000055=GBP/USD110=300000010=024
20260120-14:04:44.180439000 : 8=FIX.4.49=044735=X49=NTPRO_IDBA_UAT56=SIRIUS_500007460_MD34=137152=20260120-14:04:44.722262=MD_EUR/USD_140109278614268=6279=1269=0270=1.14776271=10000055=EUR/USD110=0279=1269=0270=1.14776271=50000055=EUR/USD110=100000279=1269=0270=1.14776271=100000055=EUR/USD110=500000279=1269=1270=1.19801271=10000055=EUR/USD110=0279=1269=1270=1.19801271=50000055=EUR/USD110=100000279=1269=1270=1.19801271=100000055=EUR/USD110=50000010=050
20260120-14:04:44.232987000 : 8=FIX.4.49=028035=X49=NTPRO_IDBA_UAT56=SIRIUS_500007460_MD34=137252=20260120-14:04:44.780262=MD_EUR/USD_140109278614268=3279=1269=1270=1.19802271=10000055=EUR/USD110=0279=1269=1270=1.19802271=50000055=EUR/USD110=100000279=1269=1270=1.19802271=100000055=EUR/USD110=50000010=003
20260120-14:04:44.240156000 : 8=FIX.4.49=068435=X49=NTPRO_IDBA_UAT56=SIRIUS_500007460_MD34=137352=20260120-14:04:44.787262=MD_GBP/USD_140109778778268=10279=0269=0270=1.25451271=10000055=GBP/USD110=0279=0269=0270=1.25451271=50000055=GBP/USD110=100000279=0269=0270=1.25451271=100000055=GBP/USD110=500000279=0269=0270=1.25451271=300000055=GBP/USD110=1000000279=0269=0270=1.25451271=500000055=GBP/USD110=3000000279=0269=1270=1.43483271=10000055=GBP/USD110=0279=0269=1270=1.43483271=50000055=GBP/USD110=100000279=0269=1270=1.43483271=100000055=GBP/USD110=500000279=0269=1270=1.43483271=300000055=GBP/USD110=1000000279=0269=1270=1.43483271=500000055=GBP/USD110=300000010=239
20260120-14:04:44.288133000 : 8=FIX.4.49=068435=X49=NTPRO_IDBA_UAT56=SIRIUS_500007460_MD34=137452=20260120-14:04:44.838262=MD_GBP/USD_140109778778268=10279=1269=0270=1.25452271=10000055=GBP/USD110=0279=1269=0270=1.25452271=50000055=GBP/USD110=100000279=1269=0270=1.25452271=100000055=GBP/USD110=500000279=1269=0270=1.25452271=300000055=GBP/USD110=1000000279=1269=0270=1.25452271=500000055=GBP/USD110=3000000279=1269=1270=1.43488271=10000055=GBP/USD110=0279=1269=1270=1.43488271=50000055=GBP/USD110=100000279=1269=1270=1.43488271=100000055=GBP/USD110=500000279=1269=1270=1.43488271=300000055=GBP/USD110=1000000279=1269=1270=1.43488271=500000055=GBP/USD110=300000010=021
20260120-14:04:44.303083000 : 8=FIX.4.49=028035=X49=NTPRO_IDBA_UAT56=SIRIUS_500007460_MD34=137552=20260120-14:04:44.847262=MD_EUR/USD_140109278614268=3279=1269=0270=1.14777271=10000055=EUR/USD110=0279=1269=0270=1.14777271=50000055=EUR/USD110=100000279=1269=0270=1.14777271=100000055=EUR/USD110=50000010=025
20260120-14:04:44.364863000 : 8=FIX.4.49=068435=X49=NTPRO_IDBA_UAT56=SIRIUS_500007460_MD34=137652=20260120-14:04:44.919262=MD_GBP/USD_140109778778268=10279=1269=0270=1.25451271=10000055=GBP/USD110=0279=1269=0270=1.25451271=50000055=GBP/USD110=100000279=1269=0270=1.25451271=100000055=GBP/USD110=500000279=1269=0270=1.25451271=300000055=GBP/USD110=1000000279=1269=0270=1.25451271=500000055=GBP/USD110=3000000279=1269=1270=1.43487271=10000055=GBP/USD110=0279=1269=1270=1.43487271=50000055=GBP/USD110=100000279=1269=1270=1.43487271=100000055=GBP/USD110=500000279=1269=1270=1.43487271=300000055=GBP/USD110=1000000279=1269=1270=1.43487271=500000055=GBP/USD110=300000010=013
20260120-14:04:44.420904000 : 8=FIX.4.49=039835=X49=NTPRO_IDBA_UAT56=SIRIUS_500007460_MD34=137752=20260120-14:04:44.970262=MD_GBP/USD_140109778778268=5279=1269=0270=1.25452271=10000055=GBP/USD110=0279=1269=0270=1.25452271=50000055=GBP/USD110=100000279=1269=0270=1.25452271=100000055=GBP/USD110=500000279=1269=0270=1.25452271=300000055=GBP/USD110=1000000279=1269=0270=1.25452271=500000055=GBP/USD110=300000010=084
20260120-14:04:44.465844000 : 8=FIX.4.49=039835=X49=NTPRO_IDBA_UAT56=SIRIUS_500007460_MD34=137852=20260120-14:04:45.026262=MD_GBP/USD_140109778778268=5279=1269=0270=1.25453271=10000055=GBP/USD110=0279=1269=0270=1.25453271=50000055=GBP/USD110=100000279=1269=0270=1.25453271=100000055=GBP/USD110=500000279=1269=0270=1.25453271=300000055=GBP/USD110=1000000279=1269=0270=1.25453271=500000055=GBP/USD110=300000010=083
20260120-14:04:44.518717000 : 8=FIX.4.49=028035=X49=NTPRO_IDBA_UAT56=SIRIUS_500007460_MD34=137952=20260120-14:04:45.073262=MD_EUR/USD_140109278614268=3279=1269=0270=1.14778271=10000055=EUR/USD110=0279=1269=0270=1.14778271=50000055=EUR/USD110=100000279=1269=0270=1.14778271=100000055=EUR/USD110=50000010=024
20260120-14:04:44.519227000 : 8=FIX.4.49=068435=X49=NTPRO_IDBA_UAT56=SIRIUS_500007460_MD34=138052=20260120-14:04:45.077262=MD_GBP/USD_140109778778268=10279=2269=0270=1.25453271=10000055=GBP/USD110=0279=2269=0270=1.25453271=50000055=GBP/USD110=100000279=2269=0270=1.25453271=100000055=GBP/USD110=500000279=2269=0270=1.25453271=300000055=GBP/USD110=1000000279=2269=0270=1.25453271=500000055=GBP/USD110=3000000279=2269=1270=1.43487271=10000055=GBP/USD110=0279=2269=1270=1.43487271=50000055=GBP/USD110=100000279=2269=1270=1.43487271=100000055=GBP/USD110=500000279=2269=1270=1.43487271=300000055=GBP/USD110=1000000279=2269=1270=1.43487271=500000055=GBP/USD110=300000010=024
20260120-14:04:44.555238000 : 8=FIX.4.49=068435=X49=NTPRO_IDBA_UAT56=SIRIUS_500007460_MD34=138152=20260120-14:04:45.112262=MD_GBP/USD_140109778778268=10279=0269=0270=1.25453271=10000055=GBP/USD110=0279=0269=0270=1.25453271=50000055=GBP/USD110=100000279=0269=0270=1.25453271=100000055=GBP/USD110=500000279=0269=0270=1.25453271=300000055=GBP/USD110=1000000279=0269=0270=1.25453271=500000055=GBP/USD110=3000000279=0269=1270=1.43489271=10000055=GBP/USD110=0279=0269=1270=1.43489271=50000055=GBP/USD110=100000279=0269=1270=1.43489271=100000055=GBP/USD110=500000279=0269=1270=1.43489271=300000055=GBP/USD110=1000000279=0269=1270=1.43489271=500000055=GBP/USD110=300000010=005
20260120-14:04:44.573178000 : 8=FIX.4.49=044735=X49=NTPRO_IDBA_UAT56=SIRIUS_500007460_MD34=138252=20260120-14:04:45.140262=MD_EUR/USD_140109278614268=6279=1269=0270=1.14779271=10000055=EUR/USD110=0279=1269=0270=1.14779271=50000055=EUR/USD110=100000279=1269=0270=1.14779271=100000055=EUR/USD110=500000279=1269=1270=1.19804271=10000055=EUR/USD110=0279=1269=1270=1.19804271=50000055=EUR/USD110=100000279=1269=1270=1.19804271=100000055=EUR/USD110=50000010=065
20260120-14:04:44.640117000 : 8=FIX.4.49=067935=X49=NTPRO_IDBA_UAT56=SIRIUS_500007460_MD34=138352=20260120-14:04:45.209262=MD_GBP/USD_140109778778268=10279=1269=0270=1.25454271=10000055=GBP/USD110=0279=1269=0270=1.25454271=50000055=GBP/USD110=100000279=1269=0270=1.25454271=100000055=GBP/USD110=500000279=1269=0270=1.25454271=300000055=GBP/USD110=1000000279=1269=0270=1.25454271=500000055=GBP/USD110=3000000279=1269=1270=1.4349271=10000055=GBP/USD110=0279=1269=1270=1.4349271=50000055=GBP/USD110=100000279=1269=1270=1.4349271=100000055=GBP/USD110=500000279=1269=1270=1.4349271=300000055=GBP/USD110=1000000279=1269=1270=1.4349271=500000055=GBP/USD110=300000010=009
20260120-14:04:44.768035000 : 8=FIX.4.49=044735=X49=NTPRO_IDBA_UAT56=SIRIUS_500007460_MD34=138452=20260120-14:04:45.346262=MD_EUR/USD_140109278614268=6279=1269=0270=1.14782271=10000055=EUR/USD110=0279=1269=0270=1.14782271=50000055=EUR/USD110=100000279=1269=0270=1.14782271=100000055=EUR/USD110=500000279=1269=1270=1.19807271=10000055=EUR/USD110=0279=1269=1270=1.19807271=50000055=EUR/USD110=100000279=1269=1270=1.19807271=100000055=EUR/USD110=50000010=066
20260120-14:04:44.778197000 : 8=FIX.4.49=068435=X49=NTPRO_IDBA_UAT56=SIRIUS_500007460_MD34=138552=20260120-14:04:45.357262=MD_GBP/USD_140109778778268=10279=1269=0270=1.25457271=10000055=GBP/USD110=0279=1269=0270=1.25457271=50000055=GBP/USD110=100000279=1269=0270=1.25457271=100000055=GBP/USD110=500000279=1269=0270=1.25457271=300000055=GBP/USD110=1000000279=1269=0270=1.25457271=500000055=GBP/USD110=3000000279=1269=1270=1.43492271=10000055=GBP/USD110=0279=1269=1270=1.43492271=50000055=GBP/USD110=100000279=1269=1270=1.43492271=100000055=GBP/USD110=500000279=1269=1270=1.43492271=300000055=GBP/USD110=1000000279=1269=1270=1.43492271=500000055=GBP/USD110=300000010=020
20260120-14:04:44.842770000 : 8=FIX.4.49=039835=X49=NTPRO_IDBA_UAT56=SIRIUS_500007460_MD34=138652=20260120-14:04:45.425262=MD_GBP/USD_140109778778268=5279=1269=0270=1.25458271=10000055=GBP/USD110=0279=1269=0270=1.25458271=50000055=GBP/USD110=100000279=1269=0270=1.25458271=100000055=GBP/USD110=500000279=1269=0270=1.25458271=300000055=GBP/USD110=1000000279=1269=0270=1.25458271=500000055=GBP/USD110=300000010=110
20260120-14:04:44.864067000 : 8=FIX.4.49=044435=X49=NTPRO_IDBA_UAT56=SIRIUS_500007460_MD34=138752=20260120-14:04:45.448262=MD_EUR/USD_140109278614268=6279=1269=0270=1.14785271=10000055=EUR/USD110=0279=1269=0270=1.14785271=50000055=EUR/USD110=100000279=1269=0270=1.14785271=100000055=EUR/USD110=500000279=1269=1270=1.1981271=10000055=EUR/USD110=0279=1269=1270=1.1981271=50000055=EUR/USD110=100000279=1269=1270=1.1981271=100000055=EUR/USD110=50000010=172
20260120-14:04:44.905684000 : 8=FIX.4.49=068435=X49=NTPRO_IDBA_UAT56=SIRIUS_500007460_MD34=138852=20260120-14:04:45.477262=MD_GBP/USD_140109778778268=10279=2269=0270=1.25458271=10000055=GBP/USD110=0279=2269=0270=1.25458271=50000055=GBP/USD110=100000279=2269=0270=1.25458271=100000055=GBP/USD110=500000279=2269=0270=1.25458271=300000055=GBP/USD110=1000000279=2269=0270=1.25458271=500000055=GBP/USD110=3000000279=2269=1270=1.43492271=10000055=GBP/USD110=0279=2269=1270=1.43492271=50000055=GBP/USD110=100000279=2269=1270=1.43492271=100000055=GBP/USD110=500000279=2269=1270=1.43492271=300000055=GBP/USD110=1000000279=2269=1270=1.43492271=500000055=GBP/USD110=300000010=041
20260120-14:04:44.946538000 : 8=FIX.4.49=068435=X49=NTPRO_IDBA_UAT56=SIRIUS_500007460_MD34=138952=20260120-14:04:45.533262=MD_GBP/USD_140109778778268=10279=0269=0270=1.25458271=10000055=GBP/USD110=0279=0269=0270=1.25458271=50000055=GBP/USD110=100000279=0269=0270=1.25458271=100000055=GBP/USD110=500000279=0269=0270=1.25458271=300000055=GBP/USD110=1000000279=0269=0270=1.25458271=500000055=GBP/USD110=3000000279=0269=1270=1.43493271=10000055=GBP/USD110=0279=0269=1270=1.43493271=50000055=GBP/USD110=100000279=0269=1270=1.43493271=100000055=GBP/USD110=500000279=0269=1270=1.43493271=300000055=GBP/USD110=1000000279=0269=1270=1.43493271=500000055=GBP/USD110=300000010=020
20260120-14:04:44.979062000 : 8=FIX.4.49=039835=X49=NTPRO_IDBA_UAT56=SIRIUS_500007460_MD34=139052=20260120-14:04:45.570262=MD_GBP/USD_140109778778268=5279=1269=1270=1.43494271=10000055=GBP/USD110=0279=1269=1270=1.43494271=50000055=GBP/USD110=100000279=1269=1270=1.43494271=100000055=GBP/USD110=500000279=1269=1270=1.43494271=300000055=GBP/USD110=1000000279=1269=1270=1.43494271=500000055=GBP/USD110=300000010=111
20260120-14:04:44.984853000 : 8=FIX.4.49=044735=X49=NTPRO_IDBA_UAT56=SIRIUS_500007460_MD34=139152=20260120-14:04:45.574262=MD_EUR/USD_140109278614268=6279=1269=0270=1.14783271=10000055=EUR/USD110=0279=1269=0270=1.14783271=50000055=EUR/USD110=100000279=1269=0270=1.14783271=100000055=EUR/USD110=500000279=1269=1270=1.19808271=10000055=EUR/USD110=0279=1269=1270=1.19808271=50000055=EUR/USD110=100000279=1269=1270=1.19808271=100000055=EUR/USD110=50000010=073
20260120-14:04:45.077282000 : 8=FIX.4.49=039835=X49=NTPRO_IDBA_UAT56=SIRIUS_500007460_MD34=139252=20260120-14:04:45.671262=MD_GBP/USD_140109778778268=5279=1269=1270=1.43493271=10000055=GBP/USD110=0279=1269=1270=1.43493271=50000055=GBP/USD110=100000279=1269=1270=1.43493271=100000055=GBP/USD110=500000279=1269=1270=1.43493271=300000055=GBP/USD110=1000000279=1269=1270=1.43493271=500000055=GBP/USD110=300000010=110
20260120-14:04:45.078905000 : 8=FIX.4.49=7735=034=1449=SIRIUS_500007460_MD52=20260120-14:04:45.07756=NTPRO_IDBA_UAT10=074
20260120-14:04:45.371526000 : 8=FIX.4.49=068435=X49=NTPRO_IDBA_UAT56=SIRIUS_500007460_MD34=139352=20260120-14:04:45.970262=MD_GBP/USD_140109778778268=10279=2269=0270=1.25458271=10000055=GBP/USD110=0279=2269=0270=1.25458271=50000055=GBP/USD110=100000279=2269=0270=1.25458271=100000055=GBP/USD110=500000279=2269=0270=1.25458271=300000055=GBP/USD110=1000000279=2269=0270=1.25458271=500000055=GBP/USD110=3000000279=2269=1270=1.43493271=10000055=GBP/USD110=0279=2269=1270=1.43493271=50000055=GBP/USD110=100000279=2269=1270=1.43493271=100000055=GBP/USD110=500000279=2269=1270=1.43493271=300000055=GBP/USD110=1000000279=2269=1270=1.43493271=500000055=GBP/USD110=300000010=040
20260120-14:04:45.402487000 : 8=FIX.4.49=028035=X49=NTPRO_IDBA_UAT56=SIRIUS_500007460_MD34=139452=20260120-14:04:46.011262=MD_EUR/USD_140109278614268=3279=1269=0270=1.14782271=10000055=EUR/USD110=0279=1269=0270=1.14782271=50000055=EUR/USD110=100000279=1269=0270=1.14782271=100000055=EUR/USD110=50000010=255
20260120-14:04:45.434340000 : 8=FIX.4.49=028035=X49=NTPRO_IDBA_UAT56=SIRIUS_500007460_MD34=139552=20260120-14:04:46.052262=MD_EUR/USD_140109278614268=3279=1269=1270=1.19807271=10000055=EUR/USD110=0279=1269=1270=1.19807271=50000055=EUR/USD110=100000279=1269=1270=1.19807271=100000055=EUR/USD110=50000010=017
20260120-14:04:45.506947000 : 8=FIX.4.49=044435=X49=NTPRO_IDBA_UAT56=SIRIUS_500007460_MD34=139652=20260120-14:04:46.127262=MD_EUR/USD_140109278614268=6279=1269=0270=1.1478271=10000055=EUR/USD110=0279=1269=0270=1.1478271=50000055=EUR/USD110=100000279=1269=0270=1.1478271=100000055=EUR/USD110=500000279=1269=1270=1.19805271=10000055=EUR/USD110=0279=1269=1270=1.19805271=50000055=EUR/USD110=100000279=1269=1270=1.19805271=100000055=EUR/USD110=50000010=164
20260120-14:04:45.585553000 : 8=FIX.4.49=068435=X49=NTPRO_IDBA_UAT56=SIRIUS_500007460_MD34=139752=20260120-14:04:46.203262=MD_GBP/USD_140109778778268=10279=0269=0270=1.25457271=10000055=GBP/USD110=0279=0269=0270=1.25457271=50000055=GBP/USD110=100000279=0269=0270=1.25457271=100000055=GBP/USD110=500000279=0269=0270=1.25457271=300000055=GBP/USD110=1000000279=0269=0270=1.25457271=500000055=GBP/USD110=3000000279=0269=1270=1.43493271=10000055=GBP/USD110=0279=0269=1270=1.43493271=50000055=GBP/USD110=100000279=0269=1270=1.43493271=100000055=GBP/USD110=500000279=0269=1270=1.43493271=300000055=GBP/USD110=1000000279=0269=1270=1.43493271=500000055=GBP/USD110=300000010=009
20260120-14:04:45.690977000 : 8=FIX.4.49=044735=X49=NTPRO_IDBA_UAT56=SIRIUS_500007460_MD34=139852=20260120-14:04:46.323262=MD_EUR/USD_140109278614268=6279=1269=0270=1.14781271=10000055=EUR/USD110=0279=1269=0270=1.14781271=50000055=EUR/USD110=100000279=1269=0270=1.14781271=100000055=EUR/USD110=500000279=1269=1270=1.19806271=10000055=EUR/USD110=0279=1269=1270=1.19806271=50000055=EUR/USD110=100000279=1269=1270=1.19806271=100000055=EUR/USD110=50000010=061
20260120-14:04:45.696902000 : 8=FIX.4.49=039835=X49=NTPRO_IDBA_UAT56=SIRIUS_500007460_MD34=139952=20260120-14:04:46.329262=MD_GBP/USD_140109778778268=5279=1269=0270=1.25458271=10000055=GBP/USD110=0279=1269=0270=1.25458271=50000055=GBP/USD110=100000279=1269=0270=1.25458271=100000055=GBP/USD110=500000279=1269=0270=1.25458271=300000055=GBP/USD110=1000000279=1269=0270=1.25458271=500000055=GBP/USD110=300000010=118
20260120-14:04:45.756817000 : 8=FIX.4.49=044735=X49=NTPRO_IDBA_UAT56=SIRIUS_500007460_MD34=140052=20260120-14:04:46.392262=MD_EUR/USD_140109278614268=6279=1269=0270=1.14782271=10000055=EUR/USD110=0279=1269=0270=1.14782271=50000055=EUR/USD110=100000279=1269=0270=1.14782271=100000055=EUR/USD110=500000279=1269=1270=1.19807271=10000055=EUR/USD110=0279=1269=1270=1.19807271=50000055=EUR/USD110=100000279=1269=1270=1.19807271=100000055=EUR/USD110=50000010=057
20260120-14:04:46.009181000 : 8=FIX.4.49=068435=X49=NTPRO_IDBA_UAT56=SIRIUS_500007460_MD34=140152=20260120-14:04:46.659262=MD_GBP/USD_140109778778268=10279=2269=0270=1.25458271=10000055=GBP/USD110=0279=2269=0270=1.25458271=50000055=GBP/USD110=100000279=2269=0270=1.25458271=100000055=GBP/USD110=500000279=2269=0270=1.25458271=300000055=GBP/USD110=1000000279=2269=0270=1.25458271=500000055=GBP/USD110=3000000279=2269=1270=1.43493271=10000055=GBP/USD110=0279=2269=1270=1.43493271=50000055=GBP/USD110=100000279=2269=1270=1.43493271=100000055=GBP/USD110=500000279=2269=1270=1.43493271=300000055=GBP/USD110=1000000279=2269=1270=1.43493271=500000055=GBP/USD110=300000010=035
20260120-14:04:46.122861000 : 8=FIX.4.49=044735=X49=NTPRO_IDBA_UAT56=SIRIUS_500007460_MD34=140252=20260120-14:04:46.780262=MD_EUR/USD_140109278614268=6279=1269=0270=1.14784271=10000055=EUR/USD110=0279=1269=0270=1.14784271=50000055=EUR/USD110=100000279=1269=0270=1.14784271=100000055=EUR/USD110=500000279=1269=1270=1.19808271=10000055=EUR/USD110=0279=1269=1270=1.19808271=50000055=EUR/USD110=100000279=1269=1270=1.19808271=100000055=EUR/USD110=50000010=069
20260120-14:04:46.162700000 : 8=FIX.4.49=068435=X49=NTPRO_IDBA_UAT56=SIRIUS_500007460_MD34=140352=20260120-14:04:46.810262=MD_GBP/USD_140109778778268=10279=0269=0270=1.25458271=10000055=GBP/USD110=0279=0269=0270=1.25458271=50000055=GBP/USD110=100000279=0269=0270=1.25458271=100000055=GBP/USD110=500000279=0269=0270=1.25458271=300000055=GBP/USD110=1000000279=0269=0270=1.25458271=500000055=GBP/USD110=3000000279=0269=1270=1.43493271=10000055=GBP/USD110=0279=0269=1270=1.43493271=50000055=GBP/USD110=100000279=0269=1270=1.43493271=100000055=GBP/USD110=500000279=0269=1270=1.43493271=300000055=GBP/USD110=1000000279=0269=1270=1.43493271=500000055=GBP/USD110=300000010=006
20260120-14:04:46.219841000 : 8=FIX.4.49=044735=X49=NTPRO_IDBA_UAT56=SIRIUS_500007460_MD34=140452=20260120-14:04:46.883262=MD_EUR/USD_140109278614268=6279=1269=0270=1.14782271=10000055=EUR/USD110=0279=1269=0270=1.14782271=50000055=EUR/USD110=100000279=1269=0270=1.14782271=100000055=EUR/USD110=500000279=1269=1270=1.19807271=10000055=EUR/USD110=0279=1269=1270=1.19807271=50000055=EUR/USD110=100000279=1269=1270=1.19807271=100000055=EUR/USD110=50000010=066
20260120-14:04:46.720744000 : 8=FIX.4.49=039835=X49=NTPRO_IDBA_UAT56=SIRIUS_500007460_MD34=140552=20260120-14:04:47.400262=MD_GBP/USD_140109778778268=5279=1269=1270=1.43494271=10000055=GBP/USD110=0279=1269=1270=1.43494271=50000055=GBP/USD110=100000279=1269=1270=1.43494271=100000055=GBP/USD110=500000279=1269=1270=1.43494271=300000055=GBP/USD110=1000000279=1269=1270=1.43494271=500000055=GBP/USD110=300000010=102
20260120-14:04:47.425716000 : 8=FIX.4.49=044735=X49=NTPRO_IDBA_UAT56=SIRIUS_500007460_MD34=140652=20260120-14:04:48.137262=MD_EUR/USD_140109278614268=6279=1269=0270=1.14781271=10000055=EUR/USD110=0279=1269=0270=1.14781271=50000055=EUR/USD110=100000279=1269=0270=1.14781271=100000055=EUR/USD110=500000279=1269=1270=1.19806271=10000055=EUR/USD110=0279=1269=1270=1.19806271=50000055=EUR/USD110=100000279=1269=1270=1.19806271=100000055=EUR/USD110=50000010=056
20260120-14:04:47.431073000 : 8=FIX.4.49=068435=X49=NTPRO_IDBA_UAT56=SIRIUS_500007460_MD34=140752=20260120-14:04:48.159262=MD_GBP/USD_140109778778268=10279=1269=0270=1.25456271=10000055=GBP/USD110=0279=1269=0270=1.25456271=50000055=GBP/USD110=100000279=1269=0270=1.25456271=100000055=GBP/USD110=500000279=1269=0270=1.25456271=300000055=GBP/USD110=1000000279=1269=0270=1.25456271=500000055=GBP/USD110=3000000279=1269=1270=1.43492271=10000055=GBP/USD110=0279=1269=1270=1.43492271=50000055=GBP/USD110=100000279=1269=1270=1.43492271=100000055=GBP/USD110=500000279=1269=1270=1.43492271=300000055=GBP/USD110=1000000279=1269=1270=1.43492271=500000055=GBP/USD110=300000010=013
20260120-14:04:47.459038000 : 8=FIX.4.49=044735=X49=NTPRO_IDBA_UAT56=SIRIUS_500007460_MD34=140852=20260120-14:04:48.188262=MD_EUR/USD_140109278614268=6279=1269=0270=1.14779271=10000055=EUR/USD110=0279=1269=0270=1.14779271=50000055=EUR/USD110=100000279=1269=0270=1.14779271=100000055=EUR/USD110=500000279=1269=1270=1.19804271=10000055=EUR/USD110=0279=1269=1270=1.19804271=50000055=EUR/USD110=100000279=1269=1270=1.19804271=100000055=EUR/USD110=50000010=079
20260120-14:04:47.650233000 : 8=FIX.4.49=028035=X49=NTPRO_IDBA_UAT56=SIRIUS_500007460_MD34=140952=20260120-14:04:48.386262=MD_EUR/USD_140109278614268=3279=1269=1270=1.19803271=10000055=EUR/USD110=0279=1269=1270=1.19803271=50000055=EUR/USD110=100000279=1269=1270=1.19803271=100000055=EUR/USD110=50000010=013
20260120-14:04:48.278435000 : 8=FIX.4.49=028035=X49=NTPRO_IDBA_UAT56=SIRIUS_500007460_MD34=141052=20260120-14:04:49.037262=MD_EUR/USD_140109278614268=3279=1269=0270=1.14778271=10000055=EUR/USD110=0279=1269=0270=1.14778271=50000055=EUR/USD110=100000279=1269=0270=1.14778271=100000055=EUR/USD110=50000010=014
20260120-14:04:48.373286000 : 8=FIX.4.49=044735=X49=NTPRO_IDBA_UAT56=SIRIUS_500007460_MD34=141152=20260120-14:04:49.133262=MD_EUR/USD_140109278614268=6279=1269=0270=1.14779271=10000055=EUR/USD110=0279=1269=0270=1.14779271=50000055=EUR/USD110=100000279=1269=0270=1.14779271=100000055=EUR/USD110=500000279=1269=1270=1.19804271=10000055=EUR/USD110=0279=1269=1270=1.19804271=50000055=EUR/USD110=100000279=1269=1270=1.19804271=100000055=EUR/USD110=50000010=064
20260120-14:04:48.478798000 : 8=FIX.4.49=044735=X49=NTPRO_IDBA_UAT56=SIRIUS_500007460_MD34=141252=20260120-14:04:49.243262=MD_EUR/USD_140109278614268=6279=1269=0270=1.14782271=10000055=EUR/USD110=0279=1269=0270=1.14782271=50000055=EUR/USD110=100000279=1269=0270=1.14782271=100000055=EUR/USD110=500000279=1269=1270=1.19806271=10000055=EUR/USD110=0279=1269=1270=1.19806271=50000055=EUR/USD110=100000279=1269=1270=1.19806271=100000055=EUR/USD110=50000010=055
20260120-14:04:48.516996000 : 8=FIX.4.49=039835=X49=NTPRO_IDBA_UAT56=SIRIUS_500007460_MD34=141352=20260120-14:04:49.270262=MD_GBP/USD_140109778778268=5279=1269=0270=1.25458271=10000055=GBP/USD110=0279=1269=0270=1.25458271=50000055=GBP/USD110=100000279=1269=0270=1.25458271=100000055=GBP/USD110=500000279=1269=0270=1.25458271=300000055=GBP/USD110=1000000279=1269=0270=1.25458271=500000055=GBP/USD110=300000010=103
20260120-14:04:48.535369000 : 8=FIX.4.49=068435=X49=NTPRO_IDBA_UAT56=SIRIUS_500007460_MD34=141452=20260120-14:04:49.301262=MD_GBP/USD_140109778778268=10279=1269=0270=1.25459271=10000055=GBP/USD110=0279=1269=0270=1.25459271=50000055=GBP/USD110=100000279=1269=0270=1.25459271=100000055=GBP/USD110=500000279=1269=0270=1.25459271=300000055=GBP/USD110=1000000279=1269=0270=1.25459271=500000055=GBP/USD110=3000000279=1269=1270=1.43494271=10000055=GBP/USD110=0279=1269=1270=1.43494271=50000055=GBP/USD110=100000279=1269=1270=1.43494271=100000055=GBP/USD110=500000279=1269=1270=1.43494271=300000055=GBP/USD110=1000000279=1269=1270=1.43494271=500000055=GBP/USD110=300000010=026
20260120-14:04:48.564406000 : 8=FIX.4.49=068435=X49=NTPRO_IDBA_UAT56=SIRIUS_500007460_MD34=141552=20260120-14:04:49.333262=MD_GBP/USD_140109778778268=10279=2269=0270=1.25459271=10000055=GBP/USD110=0279=2269=0270=1.25459271=50000055=GBP/USD110=100000279=2269=0270=1.25459271=100000055=GBP/USD110=500000279=2269=0270=1.25459271=300000055=GBP/USD110=1000000279=2269=0270=1.25459271=500000055=GBP/USD110=3000000279=2269=1270=1.43494271=10000055=GBP/USD110=0279=2269=1270=1.43494271=50000055=GBP/USD110=100000279=2269=1270=1.43494271=100000055=GBP/USD110=500000279=2269=1270=1.43494271=300000055=GBP/USD110=1000000279=2269=1270=1.43494271=500000055=GBP/USD110=300000010=042
20260120-14:04:48.614736000 : 8=FIX.4.49=044735=X49=NTPRO_IDBA_UAT56=SIRIUS_500007460_MD34=141652=20260120-14:04:49.385262=MD_EUR/USD_140109278614268=6279=1269=0270=1.14783271=10000055=EUR/USD110=0279=1269=0270=1.14783271=50000055=EUR/USD110=100000279=1269=0270=1.14783271=100000055=EUR/USD110=500000279=1269=1270=1.19808271=10000055=EUR/USD110=0279=1269=1270=1.19808271=50000055=EUR/USD110=100000279=1269=1270=1.19808271=100000055=EUR/USD110=50000010=075
20260120-14:04:48.647730000 : 8=FIX.4.49=068435=X49=NTPRO_IDBA_UAT56=SIRIUS_500007460_MD34=141752=20260120-14:04:49.418262=MD_GBP/USD_140109778778268=10279=0269=0270=1.25459271=10000055=GBP/USD110=0279=0269=0270=1.25459271=50000055=GBP/USD110=100000279=0269=0270=1.25459271=100000055=GBP/USD110=500000279=0269=0270=1.25459271=300000055=GBP/USD110=1000000279=0269=0270=1.25459271=500000055=GBP/USD110=3000000279=0269=1270=1.43494271=10000055=GBP/USD110=0279=0269=1270=1.43494271=50000055=GBP/USD110=100000279=0269=1270=1.43494271=100000055=GBP/USD110=500000279=0269=1270=1.43494271=300000055=GBP/USD110=1000000279=0269=1270=1.43494271=500000055=GBP/USD110=300000010=028
20260120-14:04:48.779975000 : 8=FIX.4.49=039835=X49=NTPRO_IDBA_UAT56=SIRIUS_500007460_MD34=141852=20260120-14:04:49.555262=MD_GBP/USD_140109778778268=5279=1269=0270=1.25458271=10000055=GBP/USD110=0279=1269=0270=1.25458271=50000055=GBP/USD110=100000279=1269=0270=1.25458271=100000055=GBP/USD110=500000279=1269=0270=1.25458271=300000055=GBP/USD110=1000000279=1269=0270=1.25458271=500000055=GBP/USD110=300000010=114
20260120-14:04:48.844016000 : 8=FIX.4.49=068435=X49=NTPRO_IDBA_UAT56=SIRIUS_500007460_MD34=141952=20260120-14:04:49.622262=MD_GBP/USD_140109778778268=10279=1269=0270=1.25457271=10000055=GBP/USD110=0279=1269=0270=1.25457271=50000055=GBP/USD110=100000279=1269=0270=1.25457271=100000055=GBP/USD110=500000279=1269=0270=1.25457271=300000055=GBP/USD110=1000000279=1269=0270=1.25457271=500000055=GBP/USD110=3000000279=1269=1270=1.43493271=10000055=GBP/USD110=0279=1269=1270=1.43493271=50000055=GBP/USD110=100000279=1269=1270=1.43493271=100000055=GBP/USD110=500000279=1269=1270=1.43493271=300000055=GBP/USD110=1000000279=1269=1270=1.43493271=500000055=GBP/USD110=300000010=022
20260120-14:04:48.869565000 : 8=FIX.4.49=044735=X49=NTPRO_IDBA_UAT56=SIRIUS_500007460_MD34=142052=20260120-14:04:49.649262=MD_EUR/USD_140109278614268=6279=1269=0270=1.14779271=10000055=EUR/USD110=0279=1269=0270=1.14779271=50000055=EUR/USD110=100000279=1269=0270=1.14779271=100000055=EUR/USD110=500000279=1269=1270=1.19804271=10000055=EUR/USD110=0279=1269=1270=1.19804271=50000055=EUR/USD110=100000279=1269=1270=1.19804271=100000055=EUR/USD110=50000010=076
20260120-14:04:48.921525000 : 8=FIX.4.49=068435=X49=NTPRO_IDBA_UAT56=SIRIUS_500007460_MD34=142152=20260120-14:04:49.702262=MD_GBP/USD_140109778778268=10279=2269=0270=1.25457271=10000055=GBP/USD110=0279=2269=0270=1.25457271=50000055=GBP/USD110=100000279=2269=0270=1.25457271=100000055=GBP/USD110=500000279=2269=0270=1.25457271=300000055=GBP/USD110=1000000279=2269=0270=1.25457271=500000055=GBP/USD110=3000000279=2269=1270=1.43493271=10000055=GBP/USD110=0279=2269=1270=1.43493271=50000055=GBP/USD110=100000279=2269=1270=1.43493271=100000055=GBP/USD110=500000279=2269=1270=1.43493271=300000055=GBP/USD110=1000000279=2269=1270=1.43493271=500000055=GBP/USD110=300000010=024
20260120-14:04:49.110618000 : 8=FIX.4.49=044735=X49=NTPRO_IDBA_UAT56=SIRIUS_500007460_MD34=142252=20260120-14:04:49.898262=MD_EUR/USD_140109278614268=6279=1269=0270=1.14784271=10000055=EUR/USD110=0279=1269=0270=1.14784271=50000055=EUR/USD110=100000279=1269=0270=1.14784271=100000055=EUR/USD110=500000279=1269=1270=1.19808271=10000055=EUR/USD110=0279=1269=1270=1.19808271=50000055=EUR/USD110=100000279=1269=1270=1.19808271=100000055=EUR/USD110=50000010=084
20260120-14:04:49.301948000 : 8=FIX.4.49=044735=X49=NTPRO_IDBA_UAT56=SIRIUS_500007460_MD34=142352=20260120-14:04:50.089262=MD_EUR/USD_140109278614268=6279=1269=0270=1.14785271=10000055=EUR/USD110=0279=1269=0270=1.14785271=50000055=EUR/USD110=100000279=1269=0270=1.14785271=100000055=EUR/USD110=500000279=1269=1270=1.19809271=10000055=EUR/USD110=0279=1269=1270=1.19809271=50000055=EUR/USD110=100000279=1269=1270=1.19809271=100000055=EUR/USD110=50000010=075
20260120-14:04:49.604567000 : 8=FIX.4.49=027735=X49=NTPRO_IDBA_UAT56=SIRIUS_500007460_MD34=142452=20260120-14:04:50.410262=MD_EUR/USD_140109278614268=3279=1269=1270=1.1981271=10000055=EUR/USD110=0279=1269=1270=1.1981271=50000055=EUR/USD110=100000279=1269=1270=1.1981271=100000055=EUR/USD110=50000010=103
20260120-14:04:49.701142000 : 8=FIX.4.49=044735=X49=NTPRO_IDBA_UAT56=SIRIUS_500007460_MD34=142552=20260120-14:04:50.507262=MD_EUR/USD_140109278614268=6279=1269=0270=1.14784271=10000055=EUR/USD110=0279=1269=0270=1.14784271=50000055=EUR/USD110=100000279=1269=0270=1.14784271=100000055=EUR/USD110=500000279=1269=1270=1.19809271=10000055=EUR/USD110=0279=1269=1270=1.19809271=50000055=EUR/USD110=100000279=1269=1270=1.19809271=100000055=EUR/USD110=50000010=069
20260120-14:04:49.868376000 : 8=FIX.4.49=068435=X49=NTPRO_IDBA_UAT56=SIRIUS_500007460_MD34=142652=20260120-14:04:50.682262=MD_GBP/USD_140109778778268=10279=0269=0270=1.25459271=10000055=GBP/USD110=0279=0269=0270=1.25459271=50000055=GBP/USD110=100000279=0269=0270=1.25459271=100000055=GBP/USD110=500000279=0269=0270=1.25459271=300000055=GBP/USD110=1000000279=0269=0270=1.25459271=500000055=GBP/USD110=3000000279=0269=1270=1.43495271=10000055=GBP/USD110=0279=0269=1270=1.43495271=50000055=GBP/USD110=100000279=0269=1270=1.43495271=100000055=GBP/USD110=500000279=0269=1270=1.43495271=300000055=GBP/USD110=1000000279=0269=1270=1.43495271=500000055=GBP/USD110=300000010=028
20260120-14:04:50.101480000 : 8=FIX.4.49=028035=X49=NTPRO_IDBA_UAT56=SIRIUS_500007460_MD34=142752=20260120-14:04:50.893262=MD_EUR/USD_140109278614268=3279=1269=1270=1.19808271=10000055=EUR/USD110=0279=1269=1270=1.19808271=50000055=EUR/USD110=100000279=1269=1270=1.19808271=100000055=EUR/USD110=50000010=024
20260120-14:04:50.102509000 : 8=FIX.4.49=068435=X49=NTPRO_IDBA_UAT56=SIRIUS_500007460_MD34=142852=20260120-14:04:50.904262=MD_GBP/USD_140109778778268=10279=2269=0270=1.25459271=10000055=GBP/USD110=0279=2269=0270=1.25459271=50000055=GBP/USD110=100000279=2269=0270=1.25459271=100000055=GBP/USD110=500000279=2269=0270=1.25459271=300000055=GBP/USD110=1000000279=2269=0270=1.25459271=500000055=GBP/USD110=3000000279=2269=1270=1.43495271=10000055=GBP/USD110=0279=2269=1270=1.43495271=50000055=GBP/USD110=100000279=2269=1270=1.43495271=100000055=GBP/USD110=500000279=2269=1270=1.43495271=300000055=GBP/USD110=1000000279=2269=1270=1.43495271=500000055=GBP/USD110=300000010=047
20260120-14:04:50.195948000 : 8=FIX.4.49=028035=X49=NTPRO_IDBA_UAT56=SIRIUS_500007460_MD34=142952=20260120-14:04:51.009262=MD_EUR/USD_140109278614268=3279=1269=1270=1.19809271=10000055=EUR/USD110=0279=1269=1270=1.19809271=50000055=EUR/USD110=100000279=1269=1270=1.19809271=100000055=EUR/USD110=50000010=019
20260120-14:04:50.309571000 : 8=FIX.4.49=068435=X49=NTPRO_IDBA_UAT56=SIRIUS_500007460_MD34=143052=20260120-14:04:51.139262=MD_GBP/USD_140109778778268=10279=0269=0270=1.25458271=10000055=GBP/USD110=0279=0269=0270=1.25458271=50000055=GBP/USD110=100000279=0269=0270=1.25458271=100000055=GBP/USD110=500000279=0269=0270=1.25458271=300000055=GBP/USD110=1000000279=0269=0270=1.25458271=500000055=GBP/USD110=3000000279=0269=1270=1.43494271=10000055=GBP/USD110=0279=0269=1270=1.43494271=50000055=GBP/USD110=100000279=0269=1270=1.43494271=100000055=GBP/USD110=500000279=0269=1270=1.43494271=300000055=GBP/USD110=1000000279=0269=1270=1.43494271=500000055=GBP/USD110=300000010=011
20260120-14:04:50.402429000 : 8=FIX.4.49=068435=X49=NTPRO_IDBA_UAT56=SIRIUS_500007460_MD34=143152=20260120-14:04:51.236262=MD_GBP/USD_140109778778268=10279=2269=0270=1.25458271=10000055=GBP/USD110=0279=2269=0270=1.25458271=50000055=GBP/USD110=100000279=2269=0270=1.25458271=100000055=GBP/USD110=500000279=2269=0270=1.25458271=300000055=GBP/USD110=1000000279=2269=0270=1.25458271=500000055=GBP/USD110=3000000279=2269=1270=1.43494271=10000055=GBP/USD110=0279=2269=1270=1.43494271=50000055=GBP/USD110=100000279=2269=1270=1.43494271=100000055=GBP/USD110=500000279=2269=1270=1.43494271=300000055=GBP/USD110=1000000279=2269=1270=1.43494271=500000055=GBP/USD110=300000010=030
20260120-14:04:51.812218000 : 8=FIX.4.49=044735=X49=NTPRO_IDBA_UAT56=SIRIUS_500007460_MD34=143252=20260120-14:04:52.693262=MD_EUR/USD_140109278614268=6279=1269=0270=1.14786271=10000055=EUR/USD110=0279=1269=0270=1.14786271=50000055=EUR/USD110=100000279=1269=0270=1.14786271=100000055=EUR/USD110=500000279=1269=1270=1.19811271=10000055=EUR/USD110=0279=1269=1270=1.19811271=50000055=EUR/USD110=100000279=1269=1270=1.19811271=100000055=EUR/USD110=50000010=060
20260120-14:04:51.845807000 : 8=FIX.4.49=044435=X49=NTPRO_IDBA_UAT56=SIRIUS_500007460_MD34=143352=20260120-14:04:52.730262=MD_EUR/USD_140109278614268=6279=1269=0270=1.14785271=10000055=EUR/USD110=0279=1269=0270=1.14785271=50000055=EUR/USD110=100000279=1269=0270=1.14785271=100000055=EUR/USD110=500000279=1269=1270=1.1981271=10000055=EUR/USD110=0279=1269=1270=1.1981271=50000055=EUR/USD110=100000279=1269=1270=1.1981271=100000055=EUR/USD110=50000010=156
20260120-14:04:51.987828000 : 8=FIX.4.49=044735=X49=NTPRO_IDBA_UAT56=SIRIUS_500007460_MD34=143452=20260120-14:04:52.877262=MD_EUR/USD_140109278614268=6279=1269=0270=1.14786271=10000055=EUR/USD110=0279=1269=0270=1.14786271=50000055=EUR/USD110=100000279=1269=0270=1.14786271=100000055=EUR/USD110=500000279=1269=1270=1.19811271=10000055=EUR/USD110=0279=1269=1270=1.19811271=50000055=EUR/USD110=100000279=1269=1270=1.19811271=100000055=EUR/USD110=50000010=066
20260120-14:04:52.095586000 : 8=FIX.4.49=044435=X49=NTPRO_IDBA_UAT56=SIRIUS_500007460_MD34=143552=20260120-14:04:52.989262=MD_EUR/USD_140109278614268=6279=1269=0270=1.14785271=10000055=EUR/USD110=0279=1269=0270=1.14785271=50000055=EUR/USD110=100000279=1269=0270=1.14785271=100000055=EUR/USD110=500000279=1269=1270=1.1981271=10000055=EUR/USD110=0279=1269=1270=1.1981271=50000055=EUR/USD110=100000279=1269=1270=1.1981271=100000055=EUR/USD110=50000010=174
20260120-14:04:52.123212000 : 8=FIX.4.49=068435=X49=NTPRO_IDBA_UAT56=SIRIUS_500007460_MD34=143652=20260120-14:04:53.016262=MD_GBP/USD_140109778778268=10279=0269=0270=1.25458271=10000055=GBP/USD110=0279=0269=0270=1.25458271=50000055=GBP/USD110=100000279=0269=0270=1.25458271=100000055=GBP/USD110=500000279=0269=0270=1.25458271=300000055=GBP/USD110=1000000279=0269=0270=1.25458271=500000055=GBP/USD110=3000000279=0269=1270=1.43494271=10000055=GBP/USD110=0279=0269=1270=1.43494271=50000055=GBP/USD110=100000279=0269=1270=1.43494271=100000055=GBP/USD110=500000279=0269=1270=1.43494271=300000055=GBP/USD110=1000000279=0269=1270=1.43494271=500000055=GBP/USD110=300000010=013
20260120-14:04:52.205056000 : 8=FIX.4.49=068435=X49=NTPRO_IDBA_UAT56=SIRIUS_500007460_MD34=143752=20260120-14:04:53.102262=MD_GBP/USD_140109778778268=10279=1269=0270=1.25457271=10000055=GBP/USD110=0279=1269=0270=1.25457271=50000055=GBP/USD110=100000279=1269=0270=1.25457271=100000055=GBP/USD110=500000279=1269=0270=1.25457271=300000055=GBP/USD110=1000000279=1269=0270=1.25457271=500000055=GBP/USD110=3000000279=1269=1270=1.43493271=10000055=GBP/USD110=0279=1269=1270=1.43493271=50000055=GBP/USD110=100000279=1269=1270=1.43493271=100000055=GBP/USD110=500000279=1269=1270=1.43493271=300000055=GBP/USD110=1000000279=1269=1270=1.43493271=500000055=GBP/USD110=300000010=010
20260120-14:04:52.668765000 : 8=FIX.4.49=068435=X49=NTPRO_IDBA_UAT56=SIRIUS_500007460_MD34=143852=20260120-14:04:53.554262=MD_GBP/USD_140109778778268=10279=2269=0270=1.25457271=10000055=GBP/USD110=0279=2269=0270=1.25457271=50000055=GBP/USD110=100000279=2269=0270=1.25457271=100000055=GBP/USD110=500000279=2269=0270=1.25457271=300000055=GBP/USD110=1000000279=2269=0270=1.25457271=500000055=GBP/USD110=3000000279=2269=1270=1.43493271=10000055=GBP/USD110=0279=2269=1270=1.43493271=50000055=GBP/USD110=100000279=2269=1270=1.43493271=100000055=GBP/USD110=500000279=2269=1270=1.43493271=300000055=GBP/USD110=1000000279=2269=1270=1.43493271=500000055=GBP/USD110=300000010=032
20260120-14:04:52.688849000 : 8=FIX.4.49=044735=X49=NTPRO_IDBA_UAT56=SIRIUS_500007460_MD34=143952=20260120-14:04:53.602262=MD_EUR/USD_140109278614268=6279=1269=0270=1.14787271=10000055=EUR/USD110=0279=1269=0270=1.14787271=50000055=EUR/USD110=100000279=1269=0270=1.14787271=100000055=EUR/USD110=500000279=1269=1270=1.19812271=10000055=EUR/USD110=0279=1269=1270=1.19812271=50000055=EUR/USD110=100000279=1269=1270=1.19812271=100000055=EUR/USD110=50000010=064
20260120-14:04:52.718269000 : 8=FIX.4.49=044735=X49=NTPRO_IDBA_UAT56=SIRIUS_500007460_MD34=144052=20260120-14:04:53.633262=MD_EUR/USD_140109278614268=6279=1269=0270=1.14786271=10000055=EUR/USD110=0279=1269=0270=1.14786271=50000055=EUR/USD110=100000279=1269=0270=1.14786271=100000055=EUR/USD110=500000279=1269=1270=1.19811271=10000055=EUR/USD110=0279=1269=1270=1.19811271=50000055=EUR/USD110=100000279=1269=1270=1.19811271=100000055=EUR/USD110=50000010=054
20260120-14:04:52.840565000 : 8=FIX.4.49=068435=X49=NTPRO_IDBA_UAT56=SIRIUS_500007460_MD34=144152=20260120-14:04:53.758262=MD_GBP/USD_140109778778268=10279=0269=0270=1.25457271=10000055=GBP/USD110=0279=0269=0270=1.25457271=50000055=GBP/USD110=100000279=0269=0270=1.25457271=100000055=GBP/USD110=500000279=0269=0270=1.25457271=300000055=GBP/USD110=1000000279=0269=0270=1.25457271=500000055=GBP/USD110=3000000279=0269=1270=1.43493271=10000055=GBP/USD110=0279=0269=1270=1.43493271=50000055=GBP/USD110=100000279=0269=1270=1.43493271=100000055=GBP/USD110=500000279=0269=1270=1.43493271=300000055=GBP/USD110=1000000279=0269=1270=1.43493271=500000055=GBP/USD110=300000010=012
20260120-14:04:53.060735000 : 8=FIX.4.49=068435=X49=NTPRO_IDBA_UAT56=SIRIUS_500007460_MD34=144252=20260120-14:04:53.974262=MD_GBP/USD_140109778778268=10279=2269=0270=1.25457271=10000055=GBP/USD110=0279=2269=0270=1.25457271=50000055=GBP/USD110=100000279=2269=0270=1.25457271=100000055=GBP/USD110=500000279=2269=0270=1.25457271=300000055=GBP/USD110=1000000279=2269=0270=1.25457271=500000055=GBP/USD110=3000000279=2269=1270=1.43493271=10000055=GBP/USD110=0279=2269=1270=1.43493271=50000055=GBP/USD110=100000279=2269=1270=1.43493271=100000055=GBP/USD110=500000279=2269=1270=1.43493271=300000055=GBP/USD110=1000000279=2269=1270=1.43493271=500000055=GBP/USD110=300000010=033
20260120-14:04:53.061551000 : 8=FIX.4.49=027735=X49=NTPRO_IDBA_UAT56=SIRIUS_500007460_MD34=144352=20260120-14:04:53.985262=MD_EUR/USD_140109278614268=3279=1269=1270=1.1981271=10000055=EUR/USD110=0279=1269=1270=1.1981271=50000055=EUR/USD110=100000279=1269=1270=1.1981271=100000055=EUR/USD110=50000010=124
20260120-14:04:53.183636000 : 8=FIX.4.49=044735=X49=NTPRO_IDBA_UAT56=SIRIUS_500007460_MD34=144452=20260120-14:04:54.113262=MD_EUR/USD_140109278614268=6279=1269=0270=1.14785271=10000055=EUR/USD110=0279=1269=0270=1.14785271=50000055=EUR/USD110=100000279=1269=0270=1.14785271=100000055=EUR/USD110=500000279=1269=1270=1.19809271=10000055=EUR/USD110=0279=1269=1270=1.19809271=50000055=EUR/USD110=100000279=1269=1270=1.19809271=100000055=EUR/USD110=50000010=070
20260120-14:04:53.262042000 : 8=FIX.4.49=044435=X49=NTPRO_IDBA_UAT56=SIRIUS_500007460_MD34=144552=20260120-14:04:54.183262=MD_EUR/USD_140109278614268=6279=1269=0270=1.14786271=10000055=EUR/USD110=0279=1269=0270=1.14786271=50000055=EUR/USD110=100000279=1269=0270=1.14786271=100000055=EUR/USD110=500000279=1269=1270=1.1981271=10000055=EUR/USD110=0279=1269=1270=1.1981271=50000055=EUR/USD110=100000279=1269=1270=1.1981271=100000055=EUR/USD110=50000010=166
20260120-14:04:53.289649000 : 8=FIX.4.49=044735=X49=NTPRO_IDBA_UAT56=SIRIUS_500007460_MD34=144652=20260120-14:04:54.225262=MD_EUR/USD_140109278614268=6279=1269=0270=1.14785271=10000055=EUR/USD110=0279=1269=0270=1.14785271=50000055=EUR/USD110=100000279=1269=0270=1.14785271=100000055=EUR/USD110=500000279=1269=1270=1.19809271=10000055=EUR/USD110=0279=1269=1270=1.19809271=50000055=EUR/USD110=100000279=1269=1270=1.19809271=100000055=EUR/USD110=50000010=076
20260120-14:04:53.368934000 : 8=FIX.4.49=028035=X49=NTPRO_IDBA_UAT56=SIRIUS_500007460_MD34=144752=20260120-14:04:54.300262=MD_EUR/USD_140109278614268=3279=1269=0270=1.14784271=10000055=EUR/USD110=0279=1269=0270=1.14784271=50000055=EUR/USD110=100000279=1269=0270=1.14784271=100000055=EUR/USD110=50000010=004
20260120-14:04:53.471487000 : 8=FIX.4.49=044735=X49=NTPRO_IDBA_UAT56=SIRIUS_500007460_MD34=144852=20260120-14:04:54.413262=MD_EUR/USD_140109278614268=6279=1269=0270=1.14786271=10000055=EUR/USD110=0279=1269=0270=1.14786271=50000055=EUR/USD110=100000279=1269=0270=1.14786271=100000055=EUR/USD110=500000279=1269=1270=1.19811271=10000055=EUR/USD110=0279=1269=1270=1.19811271=50000055=EUR/USD110=100000279=1269=1270=1.19811271=100000055=EUR/USD110=50000010=059
20260120-14:04:53.700000000 : 8=FIX.4.49=044435=X49=NTPRO_IDBA_UAT56=SIRIUS_500007460_MD34=144952=20260120-14:04:54.649262=MD_EUR/USD_140109278614268=6279=1269=0270=1.14785271=10000055=EUR/USD110=0279=1269=0270=1.14785271=50000055=EUR/USD110=100000279=1269=0270=1.14785271=100000055=EUR/USD110=500000279=1269=1270=1.1981271=10000055=EUR/USD110=0279=1269=1270=1.1981271=50000055=EUR/USD110=100000279=1269=1270=1.1981271=100000055=EUR/USD110=50000010=174
20260120-14:04:53.774062000 : 8=FIX.4.49=068435=X49=NTPRO_IDBA_UAT56=SIRIUS_500007460_MD34=145052=20260120-14:04:54.727262=MD_GBP/USD_140109778778268=10279=0269=0270=1.25457271=10000055=GBP/USD110=0279=0269=0270=1.25457271=50000055=GBP/USD110=100000279=0269=0270=1.25457271=100000055=GBP/USD110=500000279=0269=0270=1.25457271=300000055=GBP/USD110=1000000279=0269=0270=1.25457271=500000055=GBP/USD110=3000000279=0269=1270=1.43492271=10000055=GBP/USD110=0279=0269=1270=1.43492271=50000055=GBP/USD110=100000279=0269=1270=1.43492271=100000055=GBP/USD110=500000279=0269=1270=1.43492271=300000055=GBP/USD110=1000000279=0269=1270=1.43492271=500000055=GBP/USD110=300000010=004
20260120-14:04:53.807690000 : 8=FIX.4.49=068435=X49=NTPRO_IDBA_UAT56=SIRIUS_500007460_MD34=145152=20260120-14:04:54.762262=MD_GBP/USD_140109778778268=10279=2269=0270=1.25457271=10000055=GBP/USD110=0279=2269=0270=1.25457271=50000055=GBP/USD110=100000279=2269=0270=1.25457271=100000055=GBP/USD110=500000279=2269=0270=1.25457271=300000055=GBP/USD110=1000000279=2269=0270=1.25457271=500000055=GBP/USD110=3000000279=2269=1270=1.43492271=10000055=GBP/USD110=0279=2269=1270=1.43492271=50000055=GBP/USD110=100000279=2269=1270=1.43492271=100000055=GBP/USD110=500000279=2269=1270=1.43492271=300000055=GBP/USD110=1000000279=2269=1270=1.43492271=500000055=GBP/USD110=300000010=024
20260120-14:04:53.854179000 : 8=FIX.4.49=068435=X49=NTPRO_IDBA_UAT56=SIRIUS_500007460_MD34=145252=20260120-14:04:54.789262=MD_GBP/USD_140109778778268=10279=0269=0270=1.25455271=10000055=GBP/USD110=0279=0269=0270=1.25455271=50000055=GBP/USD110=100000279=0269=0270=1.25455271=100000055=GBP/USD110=500000279=0269=0270=1.25455271=300000055=GBP/USD110=1000000279=0269=0270=1.25455271=500000055=GBP/USD110=3000000279=0269=1270=1.43491271=10000055=GBP/USD110=0279=0269=1270=1.43491271=50000055=GBP/USD110=100000279=0269=1270=1.43491271=100000055=GBP/USD110=500000279=0269=1270=1.43491271=300000055=GBP/USD110=1000000279=0269=1270=1.43491271=500000055=GBP/USD110=300000010=255
20260120-14:04:53.859892000 : 8=FIX.4.49=068435=X49=NTPRO_IDBA_UAT56=SIRIUS_500007460_MD34=145352=20260120-14:04:54.811262=MD_GBP/USD_140109778778268=10279=2269=0270=1.25455271=10000055=GBP/USD110=0279=2269=0270=1.25455271=50000055=GBP/USD110=100000279=2269=0270=1.25455271=100000055=GBP/USD110=500000279=2269=0270=1.25455271=300000055=GBP/USD110=1000000279=2269=0270=1.25455271=500000055=GBP/USD110=3000000279=2269=1270=1.43491271=10000055=GBP/USD110=0279=2269=1270=1.43491271=50000055=GBP/USD110=100000279=2269=1270=1.43491271=100000055=GBP/USD110=500000279=2269=1270=1.43491271=300000055=GBP/USD110=1000000279=2269=1270=1.43491271=500000055=GBP/USD110=300000010=006
20260120-14:04:53.969610000 : 8=FIX.4.49=028035=X49=NTPRO_IDBA_UAT56=SIRIUS_500007460_MD34=145452=20260120-14:04:54.928262=MD_EUR/USD_140109278614268=3279=1269=1270=1.19809271=10000055=EUR/USD110=0279=1269=1270=1.19809271=50000055=EUR/USD110=100000279=1269=1270=1.19809271=100000055=EUR/USD110=50000010=030
20260120-14:04:54.061615000 : 8=FIX.4.49=027735=X49=NTPRO_IDBA_UAT56=SIRIUS_500007460_MD34=145552=20260120-14:04:55.020262=MD_EUR/USD_140109278614268=3279=1269=1270=1.1981271=10000055=EUR/USD110=0279=1269=1270=1.1981271=50000055=EUR/USD110=100000279=1269=1270=1.1981271=100000055=EUR/USD110=50000010=109
20260120-14:04:54.076891000 : 8=FIX.4.49=067935=X49=NTPRO_IDBA_UAT56=SIRIUS_500007460_MD34=145652=20260120-14:04:55.040262=MD_GBP/USD_140109778778268=10279=0269=0270=1.25455271=10000055=GBP/USD110=0279=0269=0270=1.25455271=50000055=GBP/USD110=100000279=0269=0270=1.25455271=100000055=GBP/USD110=500000279=0269=0270=1.25455271=300000055=GBP/USD110=1000000279=0269=0270=1.25455271=500000055=GBP/USD110=3000000279=0269=1270=1.4349271=10000055=GBP/USD110=0279=0269=1270=1.4349271=50000055=GBP/USD110=100000279=0269=1270=1.4349271=100000055=GBP/USD110=500000279=0269=1270=1.4349271=300000055=GBP/USD110=1000000279=0269=1270=1.4349271=500000055=GBP/USD110=300000010=255
20260120-14:04:54.478914000 : 8=FIX.4.49=039835=X49=NTPRO_IDBA_UAT56=SIRIUS_500007460_MD34=145752=20260120-14:04:55.456262=MD_GBP/USD_140109778778268=5279=1269=0270=1.25454271=10000055=GBP/USD110=0279=1269=0270=1.25454271=50000055=GBP/USD110=100000279=1269=0270=1.25454271=100000055=GBP/USD110=500000279=1269=0270=1.25454271=300000055=GBP/USD110=1000000279=1269=0270=1.25454271=500000055=GBP/USD110=300000010=094
20260120-14:04:54.515667000 : 8=FIX.4.49=039835=X49=NTPRO_IDBA_UAT56=SIRIUS_500007460_MD34=145852=20260120-14:04:55.495262=MD_GBP/USD_140109778778268=5279=1269=0270=1.25455271=10000055=GBP/USD110=0279=1269=0270=1.25455271=50000055=GBP/USD110=100000279=1269=0270=1.25455271=100000055=GBP/USD110=500000279=1269=0270=1.25455271=300000055=GBP/USD110=1000000279=1269=0270=1.25455271=500000055=GBP/USD110=300000010=103
20260120-14:04:54.521860000 : 8=FIX.4.49=044735=X49=NTPRO_IDBA_UAT56=SIRIUS_500007460_MD34=145952=20260120-14:04:55.498262=MD_EUR/USD_140109278614268=6279=1269=0270=1.14783271=10000055=EUR/USD110=0279=1269=0270=1.14783271=50000055=EUR/USD110=100000279=1269=0270=1.14783271=100000055=EUR/USD110=500000279=1269=1270=1.19808271=10000055=EUR/USD110=0279=1269=1270=1.19808271=50000055=EUR/USD110=100000279=1269=1270=1.19808271=100000055=EUR/USD110=50000010=084
20260120-14:04:54.568080000 : 8=FIX.4.49=039835=X49=NTPRO_IDBA_UAT56=SIRIUS_500007460_MD34=146052=20260120-14:04:55.548262=MD_GBP/USD_140109778778268=5279=1269=0270=1.25454271=10000055=GBP/USD110=0279=1269=0270=1.25454271=50000055=GBP/USD110=100000279=1269=0270=1.25454271=100000055=GBP/USD110=500000279=1269=0270=1.25454271=300000055=GBP/USD110=1000000279=1269=0270=1.25454271=500000055=GBP/USD110=300000010=090
20260120-14:04:54.615790000 : 8=FIX.4.49=067935=X49=NTPRO_IDBA_UAT56=SIRIUS_500007460_MD34=146152=20260120-14:04:55.597262=MD_GBP/USD_140109778778268=10279=2269=0270=1.25454271=10000055=GBP/USD110=0279=2269=0270=1.25454271=50000055=GBP/USD110=100000279=2269=0270=1.25454271=100000055=GBP/USD110=500000279=2269=0270=1.25454271=300000055=GBP/USD110=1000000279=2269=0270=1.25454271=500000055=GBP/USD110=3000000279=2269=1270=1.4349271=10000055=GBP/USD110=0279=2269=1270=1.4349271=50000055=GBP/USD110=100000279=2269=1270=1.4349271=100000055=GBP/USD110=500000279=2269=1270=1.4349271=300000055=GBP/USD110=1000000279=2269=1270=1.4349271=500000055=GBP/USD110=300000010=027
20260120-14:04:54.647003000 : 8=FIX.4.49=044435=X49=NTPRO_IDBA_UAT56=SIRIUS_500007460_MD34=146252=20260120-14:04:55.613262=MD_EUR/USD_140109278614268=6279=1269=0270=1.14786271=10000055=EUR/USD110=0279=1269=0270=1.14786271=50000055=EUR/USD110=100000279=1269=0270=1.14786271=100000055=EUR/USD110=500000279=1269=1270=1.1981271=10000055=EUR/USD110=0279=1269=1270=1.1981271=50000055=EUR/USD110=100000279=1269=1270=1.1981271=100000055=EUR/USD110=50000010=164
20260120-14:04:54.715057000 : 8=FIX.4.49=068435=X49=NTPRO_IDBA_UAT56=SIRIUS_500007460_MD34=146352=20260120-14:04:55.699262=MD_GBP/USD_140109778778268=10279=0269=0270=1.25457271=10000055=GBP/USD110=0279=0269=0270=1.25457271=50000055=GBP/USD110=100000279=0269=0270=1.25457271=100000055=GBP/USD110=500000279=0269=0270=1.25457271=300000055=GBP/USD110=1000000279=0269=0270=1.25457271=500000055=GBP/USD110=3000000279=0269=1270=1.43493271=10000055=GBP/USD110=0279=0269=1270=1.43493271=50000055=GBP/USD110=100000279=0269=1270=1.43493271=100000055=GBP/USD110=500000279=0269=1270=1.43493271=300000055=GBP/USD110=1000000279=0269=1270=1.43493271=500000055=GBP/USD110=300000010=022
20260120-14:04:54.744068000 : 8=FIX.4.49=028035=X49=NTPRO_IDBA_UAT56=SIRIUS_500007460_MD34=146452=20260120-14:04:55.720262=MD_EUR/USD_140109278614268=3279=1269=1270=1.19811271=10000055=EUR/USD110=0279=1269=1270=1.19811271=50000055=EUR/USD110=100000279=1269=1270=1.19811271=100000055=EUR/USD110=50000010=001
20260120-14:04:54.759512000 : 8=FIX.4.49=068435=X49=NTPRO_IDBA_UAT56=SIRIUS_500007460_MD34=146552=20260120-14:04:55.743262=MD_GBP/USD_140109778778268=10279=2269=0270=1.25457271=10000055=GBP/USD110=0279=2269=0270=1.25457271=50000055=GBP/USD110=100000279=2269=0270=1.25457271=100000055=GBP/USD110=500000279=2269=0270=1.25457271=300000055=GBP/USD110=1000000279=2269=0270=1.25457271=500000055=GBP/USD110=3000000279=2269=1270=1.43493271=10000055=GBP/USD110=0279=2269=1270=1.43493271=50000055=GBP/USD110=100000279=2269=1270=1.43493271=100000055=GBP/USD110=500000279=2269=1270=1.43493271=300000055=GBP/USD110=1000000279=2269=1270=1.43493271=500000055=GBP/USD110=300000010=034
20260120-14:04:54.775909000 : 8=FIX.4.49=044435=X49=NTPRO_IDBA_UAT56=SIRIUS_500007460_MD34=146652=20260120-14:04:55.764262=MD_EUR/USD_140109278614268=6279=1269=0270=1.14785271=10000055=EUR/USD110=0279=1269=0270=1.14785271=50000055=EUR/USD110=100000279=1269=0270=1.14785271=100000055=EUR/USD110=500000279=1269=1270=1.1981271=10000055=EUR/USD110=0279=1269=1270=1.1981271=50000055=EUR/USD110=100000279=1269=1270=1.1981271=100000055=EUR/USD110=50000010=172
20260120-14:04:54.800849000 : 8=FIX.4.49=068435=X49=NTPRO_IDBA_UAT56=SIRIUS_500007460_MD34=146752=20260120-14:04:55.789262=MD_GBP/USD_140109778778268=10279=0269=0270=1.25456271=10000055=GBP/USD110=0279=0269=0270=1.25456271=50000055=GBP/USD110=100000279=0269=0270=1.25456271=100000055=GBP/USD110=500000279=0269=0270=1.25456271=300000055=GBP/USD110=1000000279=0269=0270=1.25456271=500000055=GBP/USD110=3000000279=0269=1270=1.43492271=10000055=GBP/USD110=0279=0269=1270=1.43492271=50000055=GBP/USD110=100000279=0269=1270=1.43492271=100000055=GBP/USD110=500000279=0269=1270=1.43492271=300000055=GBP/USD110=1000000279=0269=1270=1.43492271=500000055=GBP/USD110=300000010=016
20260120-14:04:54.858310000 : 8=FIX.4.49=028035=X49=NTPRO_IDBA_UAT56=SIRIUS_500007460_MD34=146852=20260120-14:04:55.849262=MD_EUR/USD_140109278614268=3279=1269=0270=1.14786271=10000055=EUR/USD110=0279=1269=0270=1.14786271=50000055=EUR/USD110=100000279=1269=0270=1.14786271=100000055=EUR/USD110=50000010=032
20260120-14:04:55.053776000 : 8=FIX.4.49=068435=X49=NTPRO_IDBA_UAT56=SIRIUS_500007460_MD34=146952=20260120-14:04:56.052262=MD_GBP/USD_140109778778268=10279=2269=0270=1.25456271=10000055=GBP/USD110=0279=2269=0270=1.25456271=50000055=GBP/USD110=100000279=2269=0270=1.25456271=100000055=GBP/USD110=500000279=2269=0270=1.25456271=300000055=GBP/USD110=1000000279=2269=0270=1.25456271=500000055=GBP/USD110=3000000279=2269=1270=1.43492271=10000055=GBP/USD110=0279=2269=1270=1.43492271=50000055=GBP/USD110=100000279=2269=1270=1.43492271=100000055=GBP/USD110=500000279=2269=1270=1.43492271=300000055=GBP/USD110=1000000279=2269=1270=1.43492271=500000055=GBP/USD110=300000010=022
20260120-14:04:55.082974000 : 8=FIX.4.49=028035=X49=NTPRO_IDBA_UAT56=SIRIUS_500007460_MD34=147052=20260120-14:04:56.082262=MD_EUR/USD_140109278614268=3279=1269=1270=1.19811271=10000055=EUR/USD110=0279=1269=1270=1.19811271=50000055=EUR/USD110=100000279=1269=1270=1.19811271=100000055=EUR/USD110=50000010=000
20260120-14:04:55.146450000 : 8=FIX.4.49=044435=X49=NTPRO_IDBA_UAT56=SIRIUS_500007460_MD34=147152=20260120-14:04:56.148262=MD_EUR/USD_140109278614268=6279=1269=0270=1.14785271=10000055=EUR/USD110=0279=1269=0270=1.14785271=50000055=EUR/USD110=100000279=1269=0270=1.14785271=100000055=EUR/USD110=500000279=1269=1270=1.1981271=10000055=EUR/USD110=0279=1269=1270=1.1981271=50000055=EUR/USD110=100000279=1269=1270=1.1981271=100000055=EUR/USD110=50000010=165
20260120-14:04:55.692465000 : 8=FIX.4.49=068435=X49=NTPRO_IDBA_UAT56=SIRIUS_500007460_MD34=147252=20260120-14:04:56.713262=MD_GBP/USD_140109778778268=10279=0269=0270=1.25454271=10000055=GBP/USD110=0279=0269=0270=1.25454271=50000055=GBP/USD110=100000279=0269=0270=1.25454271=100000055=GBP/USD110=500000279=0269=0270=1.25454271=300000055=GBP/USD110=1000000279=0269=0270=1.25454271=500000055=GBP/USD110=3000000279=0269=1270=1.43491271=10000055=GBP/USD110=0279=0269=1270=1.43491271=50000055=GBP/USD110=100000279=0269=1270=1.43491271=100000055=GBP/USD110=500000279=0269=1270=1.43491271=300000055=GBP/USD110=1000000279=0269=1270=1.43491271=500000055=GBP/USD110=300000010=241
20260120-14:04:55.998578000 : 8=FIX.4.49=068435=X49=NTPRO_IDBA_UAT56=SIRIUS_500007460_MD34=147352=20260120-14:04:57.027262=MD_GBP/USD_140109778778268=10279=2269=0270=1.25454271=10000055=GBP/USD110=0279=2269=0270=1.25454271=50000055=GBP/USD110=100000279=2269=0270=1.25454271=100000055=GBP/USD110=500000279=2269=0270=1.25454271=300000055=GBP/USD110=1000000279=2269=0270=1.25454271=500000055=GBP/USD110=3000000279=2269=1270=1.43491271=10000055=GBP/USD110=0279=2269=1270=1.43491271=50000055=GBP/USD110=100000279=2269=1270=1.43491271=100000055=GBP/USD110=500000279=2269=1270=1.43491271=300000055=GBP/USD110=1000000279=2269=1270=1.43491271=500000055=GBP/USD110=300000010=005
20260120-14:04:56.356547000 : 8=FIX.4.49=068435=X49=NTPRO_IDBA_UAT56=SIRIUS_500007460_MD34=147452=20260120-14:04:57.400262=MD_GBP/USD_140109778778268=10279=0269=0270=1.25454271=10000055=GBP/USD110=0279=0269=0270=1.25454271=50000055=GBP/USD110=100000279=0269=0270=1.25454271=100000055=GBP/USD110=500000279=0269=0270=1.25454271=300000055=GBP/USD110=1000000279=0269=0270=1.25454271=500000055=GBP/USD110=3000000279=0269=1270=1.43491271=10000055=GBP/USD110=0279=0269=1270=1.43491271=50000055=GBP/USD110=100000279=0269=1270=1.43491271=100000055=GBP/USD110=500000279=0269=1270=1.43491271=300000055=GBP/USD110=1000000279=0269=1270=1.43491271=500000055=GBP/USD110=300000010=237
20260120-14:04:56.477432000 : 8=FIX.4.49=068435=X49=NTPRO_IDBA_UAT56=SIRIUS_500007460_MD34=147552=20260120-14:04:57.525262=MD_GBP/USD_140109778778268=10279=2269=0270=1.25454271=10000055=GBP/USD110=0279=2269=0270=1.25454271=50000055=GBP/USD110=100000279=2269=0270=1.25454271=100000055=GBP/USD110=500000279=2269=0270=1.25454271=300000055=GBP/USD110=1000000279=2269=0270=1.25454271=500000055=GBP/USD110=3000000279=2269=1270=1.43491271=10000055=GBP/USD110=0279=2269=1270=1.43491271=50000055=GBP/USD110=100000279=2269=1270=1.43491271=100000055=GBP/USD110=500000279=2269=1270=1.43491271=300000055=GBP/USD110=1000000279=2269=1270=1.43491271=500000055=GBP/USD110=300000010=010
20260120-14:04:56.698149000 : 8=FIX.4.49=044735=X49=NTPRO_IDBA_UAT56=SIRIUS_500007460_MD34=147652=20260120-14:04:57.753262=MD_EUR/USD_140109278614268=6279=1269=0270=1.14784271=10000055=EUR/USD110=0279=1269=0270=1.14784271=50000055=EUR/USD110=100000279=1269=0270=1.14784271=100000055=EUR/USD110=500000279=1269=1270=1.19809271=10000055=EUR/USD110=0279=1269=1270=1.19809271=50000055=EUR/USD110=100000279=1269=1270=1.19809271=100000055=EUR/USD110=50000010=085
20260120-14:04:57.022269000 : 8=FIX.4.49=044435=X49=NTPRO_IDBA_UAT56=SIRIUS_500007460_MD34=147752=20260120-14:04:58.077262=MD_EUR/USD_140109278614268=6279=1269=0270=1.14785271=10000055=EUR/USD110=0279=1269=0270=1.14785271=50000055=EUR/USD110=100000279=1269=0270=1.14785271=100000055=EUR/USD110=500000279=1269=1270=1.1981271=10000055=EUR/USD110=0279=1269=1270=1.1981271=50000055=EUR/USD110=100000279=1269=1270=1.1981271=100000055=EUR/USD110=50000010=174
20260120-14:04:57.175841000 : 8=FIX.4.49=028035=X49=NTPRO_IDBA_UAT56=SIRIUS_500007460_MD34=147852=20260120-14:04:58.242262=MD_EUR/USD_140109278614268=3279=1269=1270=1.19809271=10000055=EUR/USD110=0279=1269=1270=1.19809271=50000055=EUR/USD110=100000279=1269=1270=1.19809271=100000055=EUR/USD110=50000010=029
20260120-14:04:57.261120000 : 8=FIX.4.49=068435=X49=NTPRO_IDBA_UAT56=SIRIUS_500007460_MD34=147952=20260120-14:04:58.329262=MD_GBP/USD_140109778778268=10279=0269=0270=1.25453271=10000055=GBP/USD110=0279=0269=0270=1.25453271=50000055=GBP/USD110=100000279=0269=0270=1.25453271=100000055=GBP/USD110=500000279=0269=0270=1.25453271=300000055=GBP/USD110=1000000279=0269=0270=1.25453271=500000055=GBP/USD110=3000000279=0269=1270=1.43488271=10000055=GBP/USD110=0279=0269=1270=1.43488271=50000055=GBP/USD110=100000279=0269=1270=1.43488271=100000055=GBP/USD110=500000279=0269=1270=1.43488271=300000055=GBP/USD110=1000000279=0269=1270=1.43488271=500000055=GBP/USD110=300000010=022
20260120-14:04:57.288778000 : 8=FIX.4.49=039835=X49=NTPRO_IDBA_UAT56=SIRIUS_500007460_MD34=148052=20260120-14:04:58.357262=MD_GBP/USD_140109778778268=5279=1269=0270=1.25452271=10000055=GBP/USD110=0279=1269=0270=1.25452271=50000055=GBP/USD110=100000279=1269=0270=1.25452271=100000055=GBP/USD110=500000279=1269=0270=1.25452271=300000055=GBP/USD110=1000000279=1269=0270=1.25452271=500000055=GBP/USD110=300000010=083
20260120-14:04:57.326019000 : 8=FIX.4.49=039835=X49=NTPRO_IDBA_UAT56=SIRIUS_500007460_MD34=148152=20260120-14:04:58.394262=MD_GBP/USD_140109778778268=5279=1269=1270=1.43487271=10000055=GBP/USD110=0279=1269=1270=1.43487271=50000055=GBP/USD110=100000279=1269=1270=1.43487271=100000055=GBP/USD110=500000279=1269=1270=1.43487271=300000055=GBP/USD110=1000000279=1269=1270=1.43487271=500000055=GBP/USD110=300000010=130
20260120-14:04:57.389770000 : 8=FIX.4.49=067935=X49=NTPRO_IDBA_UAT56=SIRIUS_500007460_MD34=148252=20260120-14:04:58.459262=MD_GBP/USD_140109778778268=10279=1269=0270=1.2545271=10000055=GBP/USD110=0279=1269=0270=1.2545271=50000055=GBP/USD110=100000279=1269=0270=1.2545271=100000055=GBP/USD110=500000279=1269=0270=1.2545271=300000055=GBP/USD110=1000000279=1269=0270=1.2545271=500000055=GBP/USD110=3000000279=1269=1270=1.43485271=10000055=GBP/USD110=0279=1269=1270=1.43485271=50000055=GBP/USD110=100000279=1269=1270=1.43485271=100000055=GBP/USD110=500000279=1269=1270=1.43485271=300000055=GBP/USD110=1000000279=1269=1270=1.43485271=500000055=GBP/USD110=300000010=020
20260120-14:04:57.407240000 : 8=FIX.4.49=044735=X49=NTPRO_IDBA_UAT56=SIRIUS_500007460_MD34=148352=20260120-14:04:58.476262=MD_EUR/USD_140109278614268=6279=1269=0270=1.14784271=10000055=EUR/USD110=0279=1269=0270=1.14784271=50000055=EUR/USD110=100000279=1269=0270=1.14784271=100000055=EUR/USD110=500000279=1269=1270=1.19808271=10000055=EUR/USD110=0279=1269=1270=1.19808271=50000055=EUR/USD110=100000279=1269=1270=1.19808271=100000055=EUR/USD110=50000010=083
20260120-14:04:57.478450000 : 8=FIX.4.49=028035=X49=NTPRO_IDBA_UAT56=SIRIUS_500007460_MD34=148452=20260120-14:04:58.549262=MD_EUR/USD_140109278614268=3279=1269=0270=1.14783271=10000055=EUR/USD110=0279=1269=0270=1.14783271=50000055=EUR/USD110=100000279=1269=0270=1.14783271=100000055=EUR/USD110=50000010=021
20260120-14:04:57.528073000 : 8=FIX.4.49=067935=X49=NTPRO_IDBA_UAT56=SIRIUS_500007460_MD34=148552=20260120-14:04:58.597262=MD_GBP/USD_140109778778268=10279=2269=0270=1.2545271=10000055=GBP/USD110=0279=2269=0270=1.2545271=50000055=GBP/USD110=100000279=2269=0270=1.2545271=100000055=GBP/USD110=500000279=2269=0270=1.2545271=300000055=GBP/USD110=1000000279=2269=0270=1.2545271=500000055=GBP/USD110=3000000279=2269=1270=1.43485271=10000055=GBP/USD110=0279=2269=1270=1.43485271=50000055=GBP/USD110=100000279=2269=1270=1.43485271=100000055=GBP/USD110=500000279=2269=1270=1.43485271=300000055=GBP/USD110=1000000279=2269=1270=1.43485271=500000055=GBP/USD110=300000010=036
20260120-14:04:58.031771000 : 8=FIX.4.49=068435=X49=NTPRO_IDBA_UAT56=SIRIUS_500007460_MD34=148652=20260120-14:04:59.091262=MD_GBP/USD_140109778778268=10279=0269=0270=1.25449271=10000055=GBP/USD110=0279=0269=0270=1.25449271=50000055=GBP/USD110=100000279=0269=0270=1.25449271=100000055=GBP/USD110=500000279=0269=0270=1.25449271=300000055=GBP/USD110=1000000279=0269=0270=1.25449271=500000055=GBP/USD110=3000000279=0269=1270=1.43484271=10000055=GBP/USD110=0279=0269=1270=1.43484271=50000055=GBP/USD110=100000279=0269=1270=1.43484271=100000055=GBP/USD110=500000279=0269=1270=1.43484271=300000055=GBP/USD110=1000000279=0269=1270=1.43484271=500000055=GBP/USD110=300000010=022
20260120-14:04:58.157173000 : 8=FIX.4.49=028035=X49=NTPRO_IDBA_UAT56=SIRIUS_500007460_MD34=148752=20260120-14:04:59.234262=MD_EUR/USD_140109278614268=3279=1269=0270=1.14784271=10000055=EUR/USD110=0279=1269=0270=1.14784271=50000055=EUR/USD110=100000279=1269=0270=1.14784271=100000055=EUR/USD110=50000010=019
20260120-14:04:58.185845000 : 8=FIX.4.49=044735=X49=NTPRO_IDBA_UAT56=SIRIUS_500007460_MD34=148852=20260120-14:04:59.265262=MD_EUR/USD_140109278614268=6279=1269=0270=1.14783271=10000055=EUR/USD110=0279=1269=0270=1.14783271=50000055=EUR/USD110=100000279=1269=0270=1.14783271=100000055=EUR/USD110=500000279=1269=1270=1.19807271=10000055=EUR/USD110=0279=1269=1270=1.19807271=50000055=EUR/USD110=100000279=1269=1270=1.19807271=100000055=EUR/USD110=50000010=079
20260120-14:04:58.186365000 : 8=FIX.4.49=039835=X49=NTPRO_IDBA_UAT56=SIRIUS_500007460_MD34=148952=20260120-14:04:59.265262=MD_GBP/USD_140109778778268=5279=1269=0270=1.25448271=10000055=GBP/USD110=0279=1269=0270=1.25448271=50000055=GBP/USD110=100000279=1269=0270=1.25448271=100000055=GBP/USD110=500000279=1269=0270=1.25448271=300000055=GBP/USD110=1000000279=1269=0270=1.25448271=500000055=GBP/USD110=300000010=116
20260120-14:04:58.236892000 : 8=FIX.4.49=044735=X49=NTPRO_IDBA_UAT56=SIRIUS_500007460_MD34=149052=20260120-14:04:59.304262=MD_EUR/USD_140109278614268=6279=1269=0270=1.14781271=10000055=EUR/USD110=0279=1269=0270=1.14781271=50000055=EUR/USD110=100000279=1269=0270=1.14781271=100000055=EUR/USD110=500000279=1269=1270=1.19806271=10000055=EUR/USD110=0279=1269=1270=1.19806271=50000055=EUR/USD110=100000279=1269=1270=1.19806271=100000055=EUR/USD110=50000010=057
20260120-14:04:58.295243000 : 8=FIX.4.49=044735=X49=NTPRO_IDBA_UAT56=SIRIUS_500007460_MD34=149152=20260120-14:04:59.376262=MD_EUR/USD_140109278614268=6279=1269=0270=1.14779271=10000055=EUR/USD110=0279=1269=0270=1.14779271=50000055=EUR/USD110=100000279=1269=0270=1.14779271=100000055=EUR/USD110=500000279=1269=1270=1.19805271=10000055=EUR/USD110=0279=1269=1270=1.19805271=50000055=EUR/USD110=100000279=1269=1270=1.19805271=100000055=EUR/USD110=50000010=085
20260120-14:04:58.314218000 : 8=FIX.4.49=068435=X49=NTPRO_IDBA_UAT56=SIRIUS_500007460_MD34=149252=20260120-14:04:59.393262=MD_GBP/USD_140109778778268=10279=1269=0270=1.25447271=10000055=GBP/USD110=0279=1269=0270=1.25447271=50000055=GBP/USD110=100000279=1269=0270=1.25447271=100000055=GBP/USD110=500000279=1269=0270=1.25447271=300000055=GBP/USD110=1000000279=1269=0270=1.25447271=500000055=GBP/USD110=3000000279=1269=1270=1.43481271=10000055=GBP/USD110=0279=1269=1270=1.43481271=50000055=GBP/USD110=100000279=1269=1270=1.43481271=100000055=GBP/USD110=500000279=1269=1270=1.43481271=300000055=GBP/USD110=1000000279=1269=1270=1.43481271=500000055=GBP/USD110=300000010=009
20260120-14:04:58.362130000 : 8=FIX.4.49=039835=X49=NTPRO_IDBA_UAT56=SIRIUS_500007460_MD34=149352=20260120-14:04:59.443262=MD_GBP/USD_140109778778268=5279=1269=0270=1.25446271=10000055=GBP/USD110=0279=1269=0270=1.25446271=50000055=GBP/USD110=100000279=1269=0270=1.25446271=100000055=GBP/USD110=500000279=1269=0270=1.25446271=300000055=GBP/USD110=1000000279=1269=0270=1.25446271=500000055=GBP/USD110=300000010=099
20260120-14:04:58.401550000 : 8=FIX.4.49=039835=X49=NTPRO_IDBA_UAT56=SIRIUS_500007460_MD34=149452=20260120-14:04:59.483262=MD_GBP/USD_140109778778268=5279=1269=0270=1.25447271=10000055=GBP/USD110=0279=1269=0270=1.25447271=50000055=GBP/USD110=100000279=1269=0270=1.25447271=100000055=GBP/USD110=500000279=1269=0270=1.25447271=300000055=GBP/USD110=1000000279=1269=0270=1.25447271=500000055=GBP/USD110=300000010=109
20260120-14:04:58.404595000 : 8=FIX.4.49=044735=X49=NTPRO_IDBA_UAT56=SIRIUS_500007460_MD34=149552=20260120-14:04:59.487262=MD_EUR/USD_140109278614268=6279=1269=0270=1.14778271=10000055=EUR/USD110=0279=1269=0270=1.14778271=50000055=EUR/USD110=100000279=1269=0270=1.14778271=100000055=EUR/USD110=500000279=1269=1270=1.19803271=10000055=EUR/USD110=0279=1269=1270=1.19803271=50000055=EUR/USD110=100000279=1269=1270=1.19803271=100000055=EUR/USD110=50000010=083
20260120-14:04:58.473300000 : 8=FIX.4.49=068435=X49=NTPRO_IDBA_UAT56=SIRIUS_500007460_MD34=149652=20260120-14:04:59.556262=MD_GBP/USD_140109778778268=10279=1269=0270=1.25446271=10000055=GBP/USD110=0279=1269=0270=1.25446271=50000055=GBP/USD110=100000279=1269=0270=1.25446271=100000055=GBP/USD110=500000279=1269=0270=1.25446271=300000055=GBP/USD110=1000000279=1269=0270=1.25446271=500000055=GBP/USD110=3000000279=1269=1270=1.43482271=10000055=GBP/USD110=0279=1269=1270=1.43482271=50000055=GBP/USD110=100000279=1269=1270=1.43482271=100000055=GBP/USD110=500000279=1269=1270=1.43482271=300000055=GBP/USD110=1000000279=1269=1270=1.43482271=500000055=GBP/USD110=300000010=014
20260120-14:04:58.793663000 : 8=FIX.4.49=068435=X49=NTPRO_IDBA_UAT56=SIRIUS_500007460_MD34=149752=20260120-14:04:59.880262=MD_GBP/USD_140109778778268=10279=2269=0270=1.25446271=10000055=GBP/USD110=0279=2269=0270=1.25446271=50000055=GBP/USD110=100000279=2269=0270=1.25446271=100000055=GBP/USD110=500000279=2269=0270=1.25446271=300000055=GBP/USD110=1000000279=2269=0270=1.25446271=500000055=GBP/USD110=3000000279=2269=1270=1.43482271=10000055=GBP/USD110=0279=2269=1270=1.43482271=50000055=GBP/USD110=100000279=2269=1270=1.43482271=100000055=GBP/USD110=500000279=2269=1270=1.43482271=300000055=GBP/USD110=1000000279=2269=1270=1.43482271=500000055=GBP/USD110=300000010=025
20260120-14:04:58.817038000 : 8=FIX.4.49=068435=X49=NTPRO_IDBA_UAT56=SIRIUS_500007460_MD34=149852=20260120-14:04:59.904262=MD_GBP/USD_140109778778268=10279=0269=0270=1.25445271=10000055=GBP/USD110=0279=0269=0270=1.25445271=50000055=GBP/USD110=100000279=0269=0270=1.25445271=100000055=GBP/USD110=500000279=0269=0270=1.25445271=300000055=GBP/USD110=1000000279=0269=0270=1.25445271=500000055=GBP/USD110=3000000279=0269=1270=1.43481271=10000055=GBP/USD110=0279=0269=1270=1.43481271=50000055=GBP/USD110=100000279=0269=1270=1.43481271=100000055=GBP/USD110=500000279=0269=1270=1.43481271=300000055=GBP/USD110=1000000279=0269=1270=1.43481271=500000055=GBP/USD110=300000010=249
20260120-14:04:58.906441000 : 8=FIX.4.49=068435=X49=NTPRO_IDBA_UAT56=SIRIUS_500007460_MD34=149952=20260120-14:04:59.992262=MD_GBP/USD_140109778778268=10279=2269=0270=1.25445271=10000055=GBP/USD110=0279=2269=0270=1.25445271=50000055=GBP/USD110=100000279=2269=0270=1.25445271=100000055=GBP/USD110=500000279=2269=0270=1.25445271=300000055=GBP/USD110=1000000279=2269=0270=1.25445271=500000055=GBP/USD110=3000000279=2269=1270=1.43481271=10000055=GBP/USD110=0279=2269=1270=1.43481271=50000055=GBP/USD110=100000279=2269=1270=1.43481271=100000055=GBP/USD110=500000279=2269=1270=1.43481271=300000055=GBP/USD110=1000000279=2269=1270=1.43481271=500000055=GBP/USD110=300000010=021
20260120-14:04:59.043282000 : 8=FIX.4.49=068435=X49=NTPRO_IDBA_UAT56=SIRIUS_500007460_MD34=150052=20260120-14:05:00.119262=MD_GBP/USD_140109778778268=10279=0269=0270=1.25446271=10000055=GBP/USD110=0279=0269=0270=1.25446271=50000055=GBP/USD110=100000279=0269=0270=1.25446271=100000055=GBP/USD110=500000279=0269=0270=1.25446271=300000055=GBP/USD110=1000000279=0269=0270=1.25446271=500000055=GBP/USD110=3000000279=0269=1270=1.43481271=10000055=GBP/USD110=0279=0269=1270=1.43481271=50000055=GBP/USD110=100000279=0269=1270=1.43481271=100000055=GBP/USD110=500000279=0269=1270=1.43481271=300000055=GBP/USD110=1000000279=0269=1270=1.43481271=500000055=GBP/USD110=300000010=223
20260120-14:04:59.067055000 : 8=FIX.4.49=028035=X49=NTPRO_IDBA_UAT56=SIRIUS_500007460_MD34=150152=20260120-14:05:00.156262=MD_EUR/USD_140109278614268=3279=1269=0270=1.14779271=10000055=EUR/USD110=0279=1269=0270=1.14779271=50000055=EUR/USD110=100000279=1269=0270=1.14779271=100000055=EUR/USD110=50000010=008
20260120-14:04:59.126786000 : 8=FIX.4.49=028035=X49=NTPRO_IDBA_UAT56=SIRIUS_500007460_MD34=150252=20260120-14:05:00.215262=MD_EUR/USD_140109278614268=3279=1269=0270=1.14778271=10000055=EUR/USD110=0279=1269=0270=1.14778271=50000055=EUR/USD110=100000279=1269=0270=1.14778271=100000055=EUR/USD110=50000010=002
20260120-14:04:59.252478000 : 8=FIX.4.49=039835=X49=NTPRO_IDBA_UAT56=SIRIUS_500007460_MD34=150352=20260120-14:05:00.345262=MD_GBP/USD_140109778778268=5279=1269=1270=1.43482271=10000055=GBP/USD110=0279=1269=1270=1.43482271=50000055=GBP/USD110=100000279=1269=1270=1.43482271=100000055=GBP/USD110=500000279=1269=1270=1.43482271=300000055=GBP/USD110=1000000279=1269=1270=1.43482271=500000055=GBP/USD110=300000010=084
20260120-14:04:59.358255000 : 8=FIX.4.49=044735=X49=NTPRO_IDBA_UAT56=SIRIUS_500007460_MD34=150452=20260120-14:05:00.450262=MD_EUR/USD_140109278614268=6279=1269=0270=1.14779271=10000055=EUR/USD110=0279=1269=0270=1.14779271=50000055=EUR/USD110=100000279=1269=0270=1.14779271=100000055=EUR/USD110=500000279=1269=1270=1.19804271=10000055=EUR/USD110=0279=1269=1270=1.19804271=50000055=EUR/USD110=100000279=1269=1270=1.19804271=100000055=EUR/USD110=50000010=057
20260120-14:04:59.676737000 : 8=FIX.4.49=007935=049=NTPRO_IDBA_UAT56=SIRIUS_500007460_MD34=150552=20260120-14:05:00.77210=012
20260120-14:05:00.830414000 : 8=FIX.4.49=068435=X49=NTPRO_IDBA_UAT56=SIRIUS_500007460_MD34=150652=20260120-14:05:01.357262=MD_GBP/USD_140109778778268=10279=2269=0270=1.25446271=10000055=GBP/USD110=0279=2269=0270=1.25446271=50000055=GBP/USD110=100000279=2269=0270=1.25446271=100000055=GBP/USD110=500000279=2269=0270=1.25446271=300000055=GBP/USD110=1000000279=2269=0270=1.25446271=500000055=GBP/USD110=3000000279=2269=1270=1.43482271=10000055=GBP/USD110=0279=2269=1270=1.43482271=50000055=GBP/USD110=100000279=2269=1270=1.43482271=100000055=GBP/USD110=500000279=2269=1270=1.43482271=300000055=GBP/USD110=1000000279=2269=1270=1.43482271=500000055=GBP/USD110=300000010=003
20260120-14:05:01.562133000 : 8=FIX.4.49=028035=X49=NTPRO_IDBA_UAT56=SIRIUS_500007460_MD34=150752=20260120-14:05:01.516262=MD_EUR/USD_140109278614268=3279=1269=1270=1.19803271=10000055=EUR/USD110=0279=1269=1270=1.19803271=50000055=EUR/USD110=100000279=1269=1270=1.19803271=100000055=EUR/USD110=50000010=253
20260120-14:05:01.580286000 : 8=FIX.4.49=067935=X49=NTPRO_IDBA_UAT56=SIRIUS_500007460_MD34=150852=20260120-14:05:01.535262=MD_GBP/USD_140109778778268=10279=0269=0270=1.25445271=10000055=GBP/USD110=0279=0269=0270=1.25445271=50000055=GBP/USD110=100000279=0269=0270=1.25445271=100000055=GBP/USD110=500000279=0269=0270=1.25445271=300000055=GBP/USD110=1000000279=0269=0270=1.25445271=500000055=GBP/USD110=3000000279=0269=1270=1.4348271=10000055=GBP/USD110=0279=0269=1270=1.4348271=50000055=GBP/USD110=100000279=0269=1270=1.4348271=100000055=GBP/USD110=500000279=0269=1270=1.4348271=300000055=GBP/USD110=1000000279=0269=1270=1.4348271=500000055=GBP/USD110=300000010=244
20260120-14:05:01.614835000 : 8=FIX.4.49=068435=X49=NTPRO_IDBA_UAT56=SIRIUS_500007460_MD34=150952=20260120-14:05:01.569262=MD_GBP/USD_140109778778268=10279=1269=0270=1.25444271=10000055=GBP/USD110=0279=1269=0270=1.25444271=50000055=GBP/USD110=100000279=1269=0270=1.25444271=100000055=GBP/USD110=500000279=1269=0270=1.25444271=300000055=GBP/USD110=1000000279=1269=0270=1.25444271=500000055=GBP/USD110=3000000279=1269=1270=1.43479271=10000055=GBP/USD110=0279=1269=1270=1.43479271=50000055=GBP/USD110=100000279=1269=1270=1.43479271=100000055=GBP/USD110=500000279=1269=1270=1.43479271=300000055=GBP/USD110=1000000279=1269=1270=1.43479271=500000055=GBP/USD110=300000010=021
20260120-14:05:01.712110000 : 8=FIX.4.49=039835=X49=NTPRO_IDBA_UAT56=SIRIUS_500007460_MD34=151052=20260120-14:05:01.659262=MD_GBP/USD_140109778778268=5279=1269=0270=1.25443271=10000055=GBP/USD110=0279=1269=0270=1.25443271=50000055=GBP/USD110=100000279=1269=0270=1.25443271=100000055=GBP/USD110=500000279=1269=0270=1.25443271=300000055=GBP/USD110=1000000279=1269=0270=1.25443271=500000055=GBP/USD110=300000010=071
20260120-14:05:01.746487000 : 8=FIX.4.49=039835=X49=NTPRO_IDBA_UAT56=SIRIUS_500007460_MD34=151152=20260120-14:05:01.702262=MD_GBP/USD_140109778778268=5279=1269=1270=1.43478271=10000055=GBP/USD110=0279=1269=1270=1.43478271=50000055=GBP/USD110=100000279=1269=1270=1.43478271=100000055=GBP/USD110=500000279=1269=1270=1.43478271=300000055=GBP/USD110=1000000279=1269=1270=1.43478271=500000055=GBP/USD110=300000010=106
20260120-14:05:01.810078000 : 8=FIX.4.49=039835=X49=NTPRO_IDBA_UAT56=SIRIUS_500007460_MD34=151252=20260120-14:05:01.761262=MD_GBP/USD_140109778778268=5279=1269=0270=1.25442271=10000055=GBP/USD110=0279=1269=0270=1.25442271=50000055=GBP/USD110=100000279=1269=0270=1.25442271=100000055=GBP/USD110=500000279=1269=0270=1.25442271=300000055=GBP/USD110=1000000279=1269=0270=1.25442271=500000055=GBP/USD110=300000010=062
20260120-14:05:01.823237000 : 8=FIX.4.49=044735=X49=NTPRO_IDBA_UAT56=SIRIUS_500007460_MD34=151352=20260120-14:05:01.779262=MD_EUR/USD_140109278614268=6279=1269=0270=1.14777271=10000055=EUR/USD110=0279=1269=0270=1.14777271=50000055=EUR/USD110=100000279=1269=0270=1.14777271=100000055=EUR/USD110=500000279=1269=1270=1.19801271=10000055=EUR/USD110=0279=1269=1270=1.19801271=50000055=EUR/USD110=100000279=1269=1270=1.19801271=100000055=EUR/USD110=50000010=057
20260120-14:05:01.841070000 : 8=FIX.4.49=068435=X49=NTPRO_IDBA_UAT56=SIRIUS_500007460_MD34=151452=20260120-14:05:01.799262=MD_GBP/USD_140109778778268=10279=1269=0270=1.25441271=10000055=GBP/USD110=0279=1269=0270=1.25441271=50000055=GBP/USD110=100000279=1269=0270=1.25441271=100000055=GBP/USD110=500000279=1269=0270=1.25441271=300000055=GBP/USD110=1000000279=1269=0270=1.25441271=500000055=GBP/USD110=3000000279=1269=1270=1.43477271=10000055=GBP/USD110=0279=1269=1270=1.43477271=50000055=GBP/USD110=100000279=1269=1270=1.43477271=100000055=GBP/USD110=500000279=1269=1270=1.43477271=300000055=GBP/USD110=1000000279=1269=1270=1.43477271=500000055=GBP/USD110=300000010=253
20260120-14:05:01.918009000 : 8=FIX.4.49=067935=X49=NTPRO_IDBA_UAT56=SIRIUS_500007460_MD34=151552=20260120-14:05:01.858262=MD_GBP/USD_140109778778268=10279=1269=0270=1.2544271=10000055=GBP/USD110=0279=1269=0270=1.2544271=50000055=GBP/USD110=100000279=1269=0270=1.2544271=100000055=GBP/USD110=500000279=1269=0270=1.2544271=300000055=GBP/USD110=1000000279=1269=0270=1.2544271=500000055=GBP/USD110=3000000279=1269=1270=1.43475271=10000055=GBP/USD110=0279=1269=1270=1.43475271=50000055=GBP/USD110=100000279=1269=1270=1.43475271=100000055=GBP/USD110=500000279=1269=1270=1.43475271=300000055=GBP/USD110=1000000279=1269=1270=1.43475271=500000055=GBP/USD110=300000010=255
20260120-14:05:01.918739000 : 8=FIX.4.49=044735=X49=NTPRO_IDBA_UAT56=SIRIUS_500007460_MD34=151652=20260120-14:05:01.870262=MD_EUR/USD_140109278614268=6279=1269=0270=1.14778271=10000055=EUR/USD110=0279=1269=0270=1.14778271=50000055=EUR/USD110=100000279=1269=0270=1.14778271=100000055=EUR/USD110=500000279=1269=1270=1.19803271=10000055=EUR/USD110=0279=1269=1270=1.19803271=50000055=EUR/USD110=100000279=1269=1270=1.19803271=100000055=EUR/USD110=50000010=061
20260120-14:05:01.956258000 : 8=FIX.4.49=039835=X49=NTPRO_IDBA_UAT56=SIRIUS_500007460_MD34=151752=20260120-14:05:01.915262=MD_GBP/USD_140109778778268=5279=1269=0270=1.25442271=10000055=GBP/USD110=0279=1269=0270=1.25442271=50000055=GBP/USD110=100000279=1269=0270=1.25442271=100000055=GBP/USD110=500000279=1269=0270=1.25442271=300000055=GBP/USD110=1000000279=1269=0270=1.25442271=500000055=GBP/USD110=300000010=068
20260120-14:05:01.966829000 : 8=FIX.4.49=028035=X49=NTPRO_IDBA_UAT56=SIRIUS_500007460_MD34=151852=20260120-14:05:01.926262=MD_EUR/USD_140109278614268=3279=1269=0270=1.14779271=10000055=EUR/USD110=0279=1269=0270=1.14779271=50000055=EUR/USD110=100000279=1269=0270=1.14779271=100000055=EUR/USD110=50000010=022
20260120-14:05:01.986775000 : 8=FIX.4.49=039835=X49=NTPRO_IDBA_UAT56=SIRIUS_500007460_MD34=151952=20260120-14:05:01.945262=MD_GBP/USD_140109778778268=5279=1269=1270=1.43476271=10000055=GBP/USD110=0279=1269=1270=1.43476271=50000055=GBP/USD110=100000279=1269=1270=1.43476271=100000055=GBP/USD110=500000279=1269=1270=1.43476271=300000055=GBP/USD110=1000000279=1269=1270=1.43476271=500000055=GBP/USD110=300000010=113
20260120-14:05:02.020077000 : 8=FIX.4.49=044435=X49=NTPRO_IDBA_UAT56=SIRIUS_500007460_MD34=152052=20260120-14:05:01.966262=MD_EUR/USD_140109278614268=6279=1269=0270=1.1478271=10000055=EUR/USD110=0279=1269=0270=1.1478271=50000055=EUR/USD110=100000279=1269=0270=1.1478271=100000055=EUR/USD110=500000279=1269=1270=1.19804271=10000055=EUR/USD110=0279=1269=1270=1.19804271=50000055=EUR/USD110=100000279=1269=1270=1.19804271=100000055=EUR/USD110=50000010=153
20260120-14:05:02.023648000 : 8=FIX.4.49=068435=X49=NTPRO_IDBA_UAT56=SIRIUS_500007460_MD34=152152=20260120-14:05:01.983262=MD_GBP/USD_140109778778268=10279=1269=0270=1.25443271=10000055=GBP/USD110=0279=1269=0270=1.25443271=50000055=GBP/USD110=100000279=1269=0270=1.25443271=100000055=GBP/USD110=500000279=1269=0270=1.25443271=300000055=GBP/USD110=1000000279=1269=0270=1.25443271=500000055=GBP/USD110=3000000279=1269=1270=1.43478271=10000055=GBP/USD110=0279=1269=1270=1.43478271=50000055=GBP/USD110=100000279=1269=1270=1.43478271=100000055=GBP/USD110=500000279=1269=1270=1.43478271=300000055=GBP/USD110=1000000279=1269=1270=1.43478271=500000055=GBP/USD110=300000010=005
20260120-14:05:02.172041000 : 8=FIX.4.49=028035=X49=NTPRO_IDBA_UAT56=SIRIUS_500007460_MD34=152252=20260120-14:05:02.133262=MD_EUR/USD_140109278614268=3279=1269=0270=1.14779271=10000055=EUR/USD110=0279=1269=0270=1.14779271=50000055=EUR/USD110=100000279=1269=0270=1.14779271=100000055=EUR/USD110=50000010=008
20260120-14:05:02.276100000 : 8=FIX.4.49=027735=X49=NTPRO_IDBA_UAT56=SIRIUS_500007460_MD34=152352=20260120-14:05:02.239262=MD_EUR/USD_140109278614268=3279=1269=0270=1.1478271=10000055=EUR/USD110=0279=1269=0270=1.1478271=50000055=EUR/USD110=100000279=1269=0270=1.1478271=100000055=EUR/USD110=50000010=110
20260120-14:05:02.619307000 : 8=FIX.4.49=044735=X49=NTPRO_IDBA_UAT56=SIRIUS_500007460_MD34=152452=20260120-14:05:02.560262=MD_EUR/USD_140109278614268=6279=1269=0270=1.14779271=10000055=EUR/USD110=0279=1269=0270=1.14779271=50000055=EUR/USD110=100000279=1269=0270=1.14779271=100000055=EUR/USD110=500000279=1269=1270=1.19803271=10000055=EUR/USD110=0279=1269=1270=1.19803271=50000055=EUR/USD110=100000279=1269=1270=1.19803271=100000055=EUR/USD110=50000010=060
20260120-14:05:02.647509000 : 8=FIX.4.49=044735=X49=NTPRO_IDBA_UAT56=SIRIUS_500007460_MD34=152552=20260120-14:05:02.608262=MD_EUR/USD_140109278614268=6279=1269=0270=1.14781271=10000055=EUR/USD110=0279=1269=0270=1.14781271=50000055=EUR/USD110=100000279=1269=0270=1.14781271=100000055=EUR/USD110=500000279=1269=1270=1.19805271=10000055=EUR/USD110=0279=1269=1270=1.19805271=50000055=EUR/USD110=100000279=1269=1270=1.19805271=100000055=EUR/USD110=50000010=049
20260120-14:05:03.089046000 : 8=FIX.4.49=039835=X49=NTPRO_IDBA_UAT56=SIRIUS_500007460_MD34=152652=20260120-14:05:03.063262=MD_GBP/USD_140109778778268=5279=1269=1270=1.43477271=10000055=GBP/USD110=0279=1269=1270=1.43477271=50000055=GBP/USD110=100000279=1269=1270=1.43477271=100000055=GBP/USD110=500000279=1269=1270=1.43477271=300000055=GBP/USD110=1000000279=1269=1270=1.43477271=500000055=GBP/USD110=300000010=109
20260120-14:05:03.172371000 : 8=FIX.4.49=028035=X49=NTPRO_IDBA_UAT56=SIRIUS_500007460_MD34=152752=20260120-14:05:03.148262=MD_EUR/USD_140109278614268=3279=1269=1270=1.19806271=10000055=EUR/USD110=0279=1269=1270=1.19806271=50000055=EUR/USD110=100000279=1269=1270=1.19806271=100000055=EUR/USD110=50000010=011
20260120-14:05:03.258140000 : 8=FIX.4.49=028035=X49=NTPRO_IDBA_UAT56=SIRIUS_500007460_MD34=152852=20260120-14:05:03.239262=MD_EUR/USD_140109278614268=3279=1269=1270=1.19805271=10000055=EUR/USD110=0279=1269=1270=1.19805271=50000055=EUR/USD110=100000279=1269=1270=1.19805271=100000055=EUR/USD110=50000010=010
20260120-14:05:03.446127000 : 8=FIX.4.49=039835=X49=NTPRO_IDBA_UAT56=SIRIUS_500007460_MD34=152952=20260120-14:05:03.432262=MD_GBP/USD_140109778778268=5279=1269=1270=1.43478271=10000055=GBP/USD110=0279=1269=1270=1.43478271=50000055=GBP/USD110=100000279=1269=1270=1.43478271=100000055=GBP/USD110=500000279=1269=1270=1.43478271=300000055=GBP/USD110=1000000279=1269=1270=1.43478271=500000055=GBP/USD110=300000010=117
20260120-14:05:03.820786000 : 8=FIX.4.49=068435=X49=NTPRO_IDBA_UAT56=SIRIUS_500007460_MD34=153052=20260120-14:05:03.821262=MD_GBP/USD_140109778778268=10279=2269=0270=1.25443271=10000055=GBP/USD110=0279=2269=0270=1.25443271=50000055=GBP/USD110=100000279=2269=0270=1.25443271=100000055=GBP/USD110=500000279=2269=0270=1.25443271=300000055=GBP/USD110=1000000279=2269=0270=1.25443271=500000055=GBP/USD110=3000000279=2269=1270=1.43478271=10000055=GBP/USD110=0279=2269=1270=1.43478271=50000055=GBP/USD110=100000279=2269=1270=1.43478271=100000055=GBP/USD110=500000279=2269=1270=1.43478271=300000055=GBP/USD110=1000000279=2269=1270=1.43478271=500000055=GBP/USD110=300000010=008
20260120-14:05:03.919301000 : 8=FIX.4.49=044735=X49=NTPRO_IDBA_UAT56=SIRIUS_500007460_MD34=153152=20260120-14:05:03.913262=MD_EUR/USD_140109278614268=6279=1269=0270=1.14782271=10000055=EUR/USD110=0279=1269=0270=1.14782271=50000055=EUR/USD110=100000279=1269=0270=1.14782271=100000055=EUR/USD110=500000279=1269=1270=1.19807271=10000055=EUR/USD110=0279=1269=1270=1.19807271=50000055=EUR/USD110=100000279=1269=1270=1.19807271=100000055=EUR/USD110=50000010=055
20260120-14:05:03.952467000 : 8=FIX.4.49=068435=X49=NTPRO_IDBA_UAT56=SIRIUS_500007460_MD34=153252=20260120-14:05:03.958262=MD_GBP/USD_140109778778268=10279=0269=0270=1.25443271=10000055=GBP/USD110=0279=0269=0270=1.25443271=50000055=GBP/USD110=100000279=0269=0270=1.25443271=100000055=GBP/USD110=500000279=0269=0270=1.25443271=300000055=GBP/USD110=1000000279=0269=0270=1.25443271=500000055=GBP/USD110=3000000279=0269=1270=1.43478271=10000055=GBP/USD110=0279=0269=1270=1.43478271=50000055=GBP/USD110=100000279=0269=1270=1.43478271=100000055=GBP/USD110=500000279=0269=1270=1.43478271=300000055=GBP/USD110=1000000279=0269=1270=1.43478271=500000055=GBP/USD110=300000010=001
20260120-14:05:04.022252000 : 8=FIX.4.49=028035=X49=NTPRO_IDBA_UAT56=SIRIUS_500007460_MD34=153352=20260120-14:05:04.018262=MD_EUR/USD_140109278614268=3279=1269=1270=1.19806271=10000055=EUR/USD110=0279=1269=1270=1.19806271=50000055=EUR/USD110=100000279=1269=1270=1.19806271=100000055=EUR/USD110=50000010=005
20260120-14:05:04.527849000 : 8=FIX.4.49=028035=X49=NTPRO_IDBA_UAT56=SIRIUS_500007460_MD34=153452=20260120-14:05:04.553262=MD_EUR/USD_140109278614268=3279=1269=0270=1.14781271=10000055=EUR/USD110=0279=1269=0270=1.14781271=50000055=EUR/USD110=100000279=1269=0270=1.14781271=100000055=EUR/USD110=50000010=254
20260120-14:05:04.908449000 : 8=FIX.4.49=039835=X49=NTPRO_IDBA_UAT56=SIRIUS_500007460_MD34=153552=20260120-14:05:04.938262=MD_GBP/USD_140109778778268=5279=1269=0270=1.25442271=10000055=GBP/USD110=0279=1269=0270=1.25442271=50000055=GBP/USD110=100000279=1269=0270=1.25442271=100000055=GBP/USD110=500000279=1269=0270=1.25442271=300000055=GBP/USD110=1000000279=1269=0270=1.25442271=500000055=GBP/USD110=300000010=076
20260120-14:05:04.926866000 : 8=FIX.4.49=039835=X49=NTPRO_IDBA_UAT56=SIRIUS_500007460_MD34=153652=20260120-14:05:04.966262=MD_GBP/USD_140109778778268=5279=1269=0270=1.25443271=10000055=GBP/USD110=0279=1269=0270=1.25443271=50000055=GBP/USD110=100000279=1269=0270=1.25443271=100000055=GBP/USD110=500000279=1269=0270=1.25443271=300000055=GBP/USD110=1000000279=1269=0270=1.25443271=500000055=GBP/USD110=300000010=083
20260120-14:05:05.249597000 : 8=FIX.4.49=068435=X49=NTPRO_IDBA_UAT56=SIRIUS_500007460_MD34=153752=20260120-14:05:05.300262=MD_GBP/USD_140109778778268=10279=1269=0270=1.25442271=10000055=GBP/USD110=0279=1269=0270=1.25442271=50000055=GBP/USD110=100000279=1269=0270=1.25442271=100000055=GBP/USD110=500000279=1269=0270=1.25442271=300000055=GBP/USD110=1000000279=1269=0270=1.25442271=500000055=GBP/USD110=3000000279=1269=1270=1.43476271=10000055=GBP/USD110=0279=1269=1270=1.43476271=50000055=GBP/USD110=100000279=1269=1270=1.43476271=100000055=GBP/USD110=500000279=1269=1270=1.43476271=300000055=GBP/USD110=1000000279=1269=1270=1.43476271=500000055=GBP/USD110=300000010=240
20260120-14:05:05.295742000 : 8=FIX.4.49=068435=X49=NTPRO_IDBA_UAT56=SIRIUS_500007460_MD34=153852=20260120-14:05:05.342262=MD_GBP/USD_140109778778268=10279=1269=0270=1.25439271=10000055=GBP/USD110=0279=1269=0270=1.25439271=50000055=GBP/USD110=100000279=1269=0270=1.25439271=100000055=GBP/USD110=500000279=1269=0270=1.25439271=300000055=GBP/USD110=1000000279=1269=0270=1.25439271=500000055=GBP/USD110=3000000279=1269=1270=1.43475271=10000055=GBP/USD110=0279=1269=1270=1.43475271=50000055=GBP/USD110=100000279=1269=1270=1.43475271=100000055=GBP/USD110=500000279=1269=1270=1.43475271=300000055=GBP/USD110=1000000279=1269=1270=1.43475271=500000055=GBP/USD110=300000010=016
20260120-14:05:05.296455000 : 8=FIX.4.49=044435=X49=NTPRO_IDBA_UAT56=SIRIUS_500007460_MD34=153952=20260120-14:05:05.348262=MD_EUR/USD_140109278614268=6279=1269=0270=1.1478271=10000055=EUR/USD110=0279=1269=0270=1.1478271=50000055=EUR/USD110=100000279=1269=0270=1.1478271=100000055=EUR/USD110=500000279=1269=1270=1.19804271=10000055=EUR/USD110=0279=1269=1270=1.19804271=50000055=EUR/USD110=100000279=1269=1270=1.19804271=100000055=EUR/USD110=50000010=161
20260120-14:05:05.343055000 : 8=FIX.4.49=068435=X49=NTPRO_IDBA_UAT56=SIRIUS_500007460_MD34=154052=20260120-14:05:05.398262=MD_GBP/USD_140109778778268=10279=1269=0270=1.25442271=10000055=GBP/USD110=0279=1269=0270=1.25442271=50000055=GBP/USD110=100000279=1269=0270=1.25442271=100000055=GBP/USD110=500000279=1269=0270=1.25442271=300000055=GBP/USD110=1000000279=1269=0270=1.25442271=500000055=GBP/USD110=3000000279=1269=1270=1.43476271=10000055=GBP/USD110=0279=1269=1270=1.43476271=50000055=GBP/USD110=100000279=1269=1270=1.43476271=100000055=GBP/USD110=500000279=1269=1270=1.43476271=300000055=GBP/USD110=1000000279=1269=1270=1.43476271=500000055=GBP/USD110=300000010=251
20260120-14:05:05.370016000 : 8=FIX.4.49=028035=X49=NTPRO_IDBA_UAT56=SIRIUS_500007460_MD34=154152=20260120-14:05:05.426262=MD_EUR/USD_140109278614268=3279=1269=1270=1.19805271=10000055=EUR/USD110=0279=1269=1270=1.19805271=50000055=EUR/USD110=100000279=1269=1270=1.19805271=100000055=EUR/USD110=50000010=005
20260120-14:05:05.417684000 : 8=FIX.4.49=039835=X49=NTPRO_IDBA_UAT56=SIRIUS_500007460_MD34=154252=20260120-14:05:05.473262=MD_GBP/USD_140109778778268=5279=1269=1270=1.43478271=10000055=GBP/USD110=0279=1269=1270=1.43478271=50000055=GBP/USD110=100000279=1269=1270=1.43478271=100000055=GBP/USD110=500000279=1269=1270=1.43478271=300000055=GBP/USD110=1000000279=1269=1270=1.43478271=500000055=GBP/USD110=300000010=119
20260120-14:05:05.478228000 : 8=FIX.4.49=039835=X49=NTPRO_IDBA_UAT56=SIRIUS_500007460_MD34=154352=20260120-14:05:05.532262=MD_GBP/USD_140109778778268=5279=1269=1270=1.43477271=10000055=GBP/USD110=0279=1269=1270=1.43477271=50000055=GBP/USD110=100000279=1269=1270=1.43477271=100000055=GBP/USD110=500000279=1269=1270=1.43477271=300000055=GBP/USD110=1000000279=1269=1270=1.43477271=500000055=GBP/USD110=300000010=111
20260120-14:05:05.628513000 : 8=FIX.4.49=039835=X49=NTPRO_IDBA_UAT56=SIRIUS_500007460_MD34=154452=20260120-14:05:05.693262=MD_GBP/USD_140109778778268=5279=1269=1270=1.43478271=10000055=GBP/USD110=0279=1269=1270=1.43478271=50000055=GBP/USD110=100000279=1269=1270=1.43478271=100000055=GBP/USD110=500000279=1269=1270=1.43478271=300000055=GBP/USD110=1000000279=1269=1270=1.43478271=500000055=GBP/USD110=300000010=125
20260120-14:05:05.766405000 : 8=FIX.4.49=039835=X49=NTPRO_IDBA_UAT56=SIRIUS_500007460_MD34=154552=20260120-14:05:05.836262=MD_GBP/USD_140109778778268=5279=1269=1270=1.43477271=10000055=GBP/USD110=0279=1269=1270=1.43477271=50000055=GBP/USD110=100000279=1269=1270=1.43477271=100000055=GBP/USD110=500000279=1269=1270=1.43477271=300000055=GBP/USD110=1000000279=1269=1270=1.43477271=500000055=GBP/USD110=300000010=120
20260120-14:05:05.820037000 : 8=FIX.4.49=028035=X49=NTPRO_IDBA_UAT56=SIRIUS_500007460_MD34=154652=20260120-14:05:05.886262=MD_EUR/USD_140109278614268=3279=1269=0270=1.14781271=10000055=EUR/USD110=0279=1269=0270=1.14781271=50000055=EUR/USD110=100000279=1269=0270=1.14781271=100000055=EUR/USD110=50000010=011
20260120-14:05:05.907255000 : 8=FIX.4.49=068435=X49=NTPRO_IDBA_UAT56=SIRIUS_500007460_MD34=154752=20260120-14:05:05.955262=MD_GBP/USD_140109778778268=10279=2269=0270=1.25442271=10000055=GBP/USD110=0279=2269=0270=1.25442271=50000055=GBP/USD110=100000279=2269=0270=1.25442271=100000055=GBP/USD110=500000279=2269=0270=1.25442271=300000055=GBP/USD110=1000000279=2269=0270=1.25442271=500000055=GBP/USD110=3000000279=2269=1270=1.43477271=10000055=GBP/USD110=0279=2269=1270=1.43477271=50000055=GBP/USD110=100000279=2269=1270=1.43477271=100000055=GBP/USD110=500000279=2269=1270=1.43477271=300000055=GBP/USD110=1000000279=2269=1270=1.43477271=500000055=GBP/USD110=300000010=016
20260120-14:05:06.226016000 : 8=FIX.4.49=028035=X49=NTPRO_IDBA_UAT56=SIRIUS_500007460_MD34=154852=20260120-14:05:06.313262=MD_EUR/USD_140109278614268=3279=1269=1270=1.19806271=10000055=EUR/USD110=0279=1269=1270=1.19806271=50000055=EUR/USD110=100000279=1269=1270=1.19806271=100000055=EUR/USD110=50000010=011
20260120-14:05:06.269044000 : 8=FIX.4.49=028035=X49=NTPRO_IDBA_UAT56=SIRIUS_500007460_MD34=154952=20260120-14:05:06.356262=MD_EUR/USD_140109278614268=3279=1269=1270=1.19805271=10000055=EUR/USD110=0279=1269=1270=1.19805271=50000055=EUR/USD110=100000279=1269=1270=1.19805271=100000055=EUR/USD110=50000010=016
20260120-14:05:06.339601000 : 8=FIX.4.49=068435=X49=NTPRO_IDBA_UAT56=SIRIUS_500007460_MD34=155052=20260120-14:05:06.431262=MD_GBP/USD_140109778778268=10279=0269=0270=1.25443271=10000055=GBP/USD110=0279=0269=0270=1.25443271=50000055=GBP/USD110=100000279=0269=0270=1.25443271=100000055=GBP/USD110=500000279=0269=0270=1.25443271=300000055=GBP/USD110=1000000279=0269=0270=1.25443271=500000055=GBP/USD110=3000000279=0269=1270=1.43477271=10000055=GBP/USD110=0279=0269=1270=1.43477271=50000055=GBP/USD110=100000279=0269=1270=1.43477271=100000055=GBP/USD110=500000279=0269=1270=1.43477271=300000055=GBP/USD110=1000000279=0269=1270=1.43477271=500000055=GBP/USD110=300000010=241
20260120-14:05:06.364847000 : 8=FIX.4.49=068435=X49=NTPRO_IDBA_UAT56=SIRIUS_500007460_MD34=155152=20260120-14:05:06.458262=MD_GBP/USD_140109778778268=10279=1269=0270=1.25441271=10000055=GBP/USD110=0279=1269=0270=1.25441271=50000055=GBP/USD110=100000279=1269=0270=1.25441271=100000055=GBP/USD110=500000279=1269=0270=1.25441271=300000055=GBP/USD110=1000000279=1269=0270=1.25441271=500000055=GBP/USD110=3000000279=1269=1270=1.43476271=10000055=GBP/USD110=0279=1269=1270=1.43476271=50000055=GBP/USD110=100000279=1269=1270=1.43476271=100000055=GBP/USD110=500000279=1269=1270=1.43476271=300000055=GBP/USD110=1000000279=1269=1270=1.43476271=500000055=GBP/USD110=300000010=246
20260120-14:05:06.394284000 : 8=FIX.4.49=039835=X49=NTPRO_IDBA_UAT56=SIRIUS_500007460_MD34=155252=20260120-14:05:06.487262=MD_GBP/USD_140109778778268=5279=1269=1270=1.43477271=10000055=GBP/USD110=0279=1269=1270=1.43477271=50000055=GBP/USD110=100000279=1269=1270=1.43477271=100000055=GBP/USD110=500000279=1269=1270=1.43477271=300000055=GBP/USD110=1000000279=1269=1270=1.43477271=500000055=GBP/USD110=300000010=121
20260120-14:05:06.396179000 : 8=FIX.4.49=027735=X49=NTPRO_IDBA_UAT56=SIRIUS_500007460_MD34=155352=20260120-14:05:06.491262=MD_EUR/USD_140109278614268=3279=1269=0270=1.1478271=10000055=EUR/USD110=0279=1269=0270=1.1478271=50000055=EUR/USD110=100000279=1269=0270=1.1478271=100000055=EUR/USD110=50000010=117
20260120-14:05:06.430917000 : 8=FIX.4.49=039835=X49=NTPRO_IDBA_UAT56=SIRIUS_500007460_MD34=155452=20260120-14:05:06.526262=MD_GBP/USD_140109778778268=5279=1269=0270=1.25442271=10000055=GBP/USD110=0279=1269=0270=1.25442271=50000055=GBP/USD110=100000279=1269=0270=1.25442271=100000055=GBP/USD110=500000279=1269=0270=1.25442271=300000055=GBP/USD110=1000000279=1269=0270=1.25442271=500000055=GBP/USD110=300000010=072
20260120-14:05:06.462938000 : 8=FIX.4.49=068435=X49=NTPRO_IDBA_UAT56=SIRIUS_500007460_MD34=155552=20260120-14:05:06.555262=MD_GBP/USD_140109778778268=10279=2269=0270=1.25442271=10000055=GBP/USD110=0279=2269=0270=1.25442271=50000055=GBP/USD110=100000279=2269=0270=1.25442271=100000055=GBP/USD110=500000279=2269=0270=1.25442271=300000055=GBP/USD110=1000000279=2269=0270=1.25442271=500000055=GBP/USD110=3000000279=2269=1270=1.43477271=10000055=GBP/USD110=0279=2269=1270=1.43477271=50000055=GBP/USD110=100000279=2269=1270=1.43477271=100000055=GBP/USD110=500000279=2269=1270=1.43477271=300000055=GBP/USD110=1000000279=2269=1270=1.43477271=500000055=GBP/USD110=300000010=012
20260120-14:05:06.493798000 : 8=FIX.4.49=068435=X49=NTPRO_IDBA_UAT56=SIRIUS_500007460_MD34=155652=20260120-14:05:06.591262=MD_GBP/USD_140109778778268=10279=0269=0270=1.25441271=10000055=GBP/USD110=0279=0269=0270=1.25441271=50000055=GBP/USD110=100000279=0269=0270=1.25441271=100000055=GBP/USD110=500000279=0269=0270=1.25441271=300000055=GBP/USD110=1000000279=0269=0270=1.25441271=500000055=GBP/USD110=3000000279=0269=1270=1.43477271=10000055=GBP/USD110=0279=0269=1270=1.43477271=50000055=GBP/USD110=100000279=0269=1270=1.43477271=100000055=GBP/USD110=500000279=0269=1270=1.43477271=300000055=GBP/USD110=1000000279=0269=1270=1.43477271=500000055=GBP/USD110=300000010=244
20260120-14:05:06.716921000 : 8=FIX.4.49=039835=X49=NTPRO_IDBA_UAT56=SIRIUS_500007460_MD34=155752=20260120-14:05:06.825262=MD_GBP/USD_140109778778268=5279=1269=0270=1.25442271=10000055=GBP/USD110=0279=1269=0270=1.25442271=50000055=GBP/USD110=100000279=1269=0270=1.25442271=100000055=GBP/USD110=500000279=1269=0270=1.25442271=300000055=GBP/USD110=1000000279=1269=0270=1.25442271=500000055=GBP/USD110=300000010=077
20260120-14:05:06.840096000 : 8=FIX.4.49=039835=X49=NTPRO_IDBA_UAT56=SIRIUS_500007460_MD34=155852=20260120-14:05:06.951262=MD_GBP/USD_140109778778268=5279=1269=1270=1.43476271=10000055=GBP/USD110=0279=1269=1270=1.43476271=50000055=GBP/USD110=100000279=1269=1270=1.43476271=100000055=GBP/USD110=500000279=1269=1270=1.43476271=300000055=GBP/USD110=1000000279=1269=1270=1.43476271=500000055=GBP/USD110=300000010=118
20260120-14:05:07.088872000 : 8=FIX.4.49=068435=X49=NTPRO_IDBA_UAT56=SIRIUS_500007460_MD34=155952=20260120-14:05:07.212262=MD_GBP/USD_140109778778268=10279=2269=0270=1.25442271=10000055=GBP/USD110=0279=2269=0270=1.25442271=50000055=GBP/USD110=100000279=2269=0270=1.25442271=100000055=GBP/USD110=500000279=2269=0270=1.25442271=300000055=GBP/USD110=1000000279=2269=0270=1.25442271=500000055=GBP/USD110=3000000279=2269=1270=1.43476271=10000055=GBP/USD110=0279=2269=1270=1.43476271=50000055=GBP/USD110=100000279=2269=1270=1.43476271=100000055=GBP/USD110=500000279=2269=1270=1.43476271=300000055=GBP/USD110=1000000279=2269=1270=1.43476271=500000055=GBP/USD110=300000010=002
20260120-14:05:07.212020000 : 8=FIX.4.49=068435=X49=NTPRO_IDBA_UAT56=SIRIUS_500007460_MD34=156052=20260120-14:05:07.341262=MD_GBP/USD_140109778778268=10279=0269=0270=1.25443271=10000055=GBP/USD110=0279=0269=0270=1.25443271=50000055=GBP/USD110=100000279=0269=0270=1.25443271=100000055=GBP/USD110=500000279=0269=0270=1.25443271=300000055=GBP/USD110=1000000279=0269=0270=1.25443271=500000055=GBP/USD110=3000000279=0269=1270=1.43477271=10000055=GBP/USD110=0279=0269=1270=1.43477271=50000055=GBP/USD110=100000279=0269=1270=1.43477271=100000055=GBP/USD110=500000279=0269=1270=1.43477271=300000055=GBP/USD110=1000000279=0269=1270=1.43477271=500000055=GBP/USD110=300000010=243
20260120-14:05:07.349332000 : 8=FIX.4.49=039835=X49=NTPRO_IDBA_UAT56=SIRIUS_500007460_MD34=156152=20260120-14:05:07.484262=MD_GBP/USD_140109778778268=5279=1269=0270=1.25442271=10000055=GBP/USD110=0279=1269=0270=1.25442271=50000055=GBP/USD110=100000279=1269=0270=1.25442271=100000055=GBP/USD110=500000279=1269=0270=1.25442271=300000055=GBP/USD110=1000000279=1269=0270=1.25442271=500000055=GBP/USD110=300000010=074
20260120-14:05:07.399943000 : 8=FIX.4.49=068435=X49=NTPRO_IDBA_UAT56=SIRIUS_500007460_MD34=156252=20260120-14:05:07.537262=MD_GBP/USD_140109778778268=10279=1269=0270=1.25441271=10000055=GBP/USD110=0279=1269=0270=1.25441271=50000055=GBP/USD110=100000279=1269=0270=1.25441271=100000055=GBP/USD110=500000279=1269=0270=1.25441271=300000055=GBP/USD110=1000000279=1269=0270=1.25441271=500000055=GBP/USD110=3000000279=1269=1270=1.43476271=10000055=GBP/USD110=0279=1269=1270=1.43476271=50000055=GBP/USD110=100000279=1269=1270=1.43476271=100000055=GBP/USD110=500000279=1269=1270=1.43476271=300000055=GBP/USD110=1000000279=1269=1270=1.43476271=500000055=GBP/USD110=300000010=247
20260120-14:05:07.405751000 : 8=FIX.4.49=044135=X49=NTPRO_IDBA_UAT56=SIRIUS_500007460_MD34=156352=20260120-14:05:07.544262=MD_EUR/USD_140109278614268=6279=1269=0270=1.14775271=10000055=EUR/USD110=0279=1269=0270=1.14775271=50000055=EUR/USD110=100000279=1269=0270=1.14775271=100000055=EUR/USD110=500000279=1269=1270=1.198271=10000055=EUR/USD110=0279=1269=1270=1.198271=50000055=EUR/USD110=100000279=1269=1270=1.198271=100000055=EUR/USD110=50000010=011
20260120-14:05:07.517228000 : 8=FIX.4.49=068435=X49=NTPRO_IDBA_UAT56=SIRIUS_500007460_MD34=156452=20260120-14:05:07.660262=MD_GBP/USD_140109778778268=10279=1269=0270=1.25439271=10000055=GBP/USD110=0279=1269=0270=1.25439271=50000055=GBP/USD110=100000279=1269=0270=1.25439271=100000055=GBP/USD110=500000279=1269=0270=1.25439271=300000055=GBP/USD110=1000000279=1269=0270=1.25439271=500000055=GBP/USD110=3000000279=1269=1270=1.43474271=10000055=GBP/USD110=0279=1269=1270=1.43474271=50000055=GBP/USD110=100000279=1269=1270=1.43474271=100000055=GBP/USD110=500000279=1269=1270=1.43474271=300000055=GBP/USD110=1000000279=1269=1270=1.43474271=500000055=GBP/USD110=300000010=015
20260120-14:05:07.595845000 : 8=FIX.4.49=044735=X49=NTPRO_IDBA_UAT56=SIRIUS_500007460_MD34=156552=20260120-14:05:07.742262=MD_EUR/USD_140109278614268=6279=1269=0270=1.14773271=10000055=EUR/USD110=0279=1269=0270=1.14773271=50000055=EUR/USD110=100000279=1269=0270=1.14773271=100000055=EUR/USD110=500000279=1269=1270=1.19798271=10000055=EUR/USD110=0279=1269=1270=1.19798271=50000055=EUR/USD110=100000279=1269=1270=1.19798271=100000055=EUR/USD110=50000010=093
20260120-14:05:07.596513000 : 8=FIX.4.49=068435=X49=NTPRO_IDBA_UAT56=SIRIUS_500007460_MD34=156652=20260120-14:05:07.742262=MD_GBP/USD_140109778778268=10279=1269=0270=1.25438271=10000055=GBP/USD110=0279=1269=0270=1.25438271=50000055=GBP/USD110=100000279=1269=0270=1.25438271=100000055=GBP/USD110=500000279=1269=0270=1.25438271=300000055=GBP/USD110=1000000279=1269=0270=1.25438271=500000055=GBP/USD110=3000000279=1269=1270=1.43473271=10000055=GBP/USD110=0279=1269=1270=1.43473271=50000055=GBP/USD110=100000279=1269=1270=1.43473271=100000055=GBP/USD110=500000279=1269=1270=1.43473271=300000055=GBP/USD110=1000000279=1269=1270=1.43473271=500000055=GBP/USD110=300000010=008
20260120-14:05:07.857043000 : 8=FIX.4.49=028035=X49=NTPRO_IDBA_UAT56=SIRIUS_500007460_MD34=156752=20260120-14:05:08.003262=MD_EUR/USD_140109278614268=3279=1269=1270=1.19797271=10000055=EUR/USD110=0279=1269=1270=1.19797271=50000055=EUR/USD110=100000279=1269=1270=1.19797271=100000055=EUR/USD110=50000010=037
20260120-14:05:07.957614000 : 8=FIX.4.49=028035=X49=NTPRO_IDBA_UAT56=SIRIUS_500007460_MD34=156852=20260120-14:05:08.108262=MD_EUR/USD_140109278614268=3279=1269=1270=1.19798271=10000055=EUR/USD110=0279=1269=1270=1.19798271=50000055=EUR/USD110=100000279=1269=1270=1.19798271=100000055=EUR/USD110=50000010=047
20260120-14:05:08.315053000 : 8=FIX.4.49=044735=X49=NTPRO_IDBA_UAT56=SIRIUS_500007460_MD34=156952=20260120-14:05:08.491262=MD_EUR/USD_140109278614268=6279=1269=0270=1.14772271=10000055=EUR/USD110=0279=1269=0270=1.14772271=50000055=EUR/USD110=100000279=1269=0270=1.14772271=100000055=EUR/USD110=500000279=1269=1270=1.19797271=10000055=EUR/USD110=0279=1269=1270=1.19797271=50000055=EUR/USD110=100000279=1269=1270=1.19797271=100000055=EUR/USD110=50000010=093
20260120-14:05:08.376837000 : 8=FIX.4.49=044435=X49=NTPRO_IDBA_UAT56=SIRIUS_500007460_MD34=157052=20260120-14:05:08.556262=MD_EUR/USD_140109278614268=6279=1269=0270=1.1477271=10000055=EUR/USD110=0279=1269=0270=1.1477271=50000055=EUR/USD110=100000279=1269=0270=1.1477271=100000055=EUR/USD110=500000279=1269=1270=1.19795271=10000055=EUR/USD110=0279=1269=1270=1.19795271=50000055=EUR/USD110=100000279=1269=1270=1.19795271=100000055=EUR/USD110=50000010=184
20260120-14:05:08.377892000 : 8=FIX.4.49=068435=X49=NTPRO_IDBA_UAT56=SIRIUS_500007460_MD34=157152=20260120-14:05:08.556262=MD_GBP/USD_140109778778268=10279=1269=0270=1.25435271=10000055=GBP/USD110=0279=1269=0270=1.25435271=50000055=GBP/USD110=100000279=1269=0270=1.25435271=100000055=GBP/USD110=500000279=1269=0270=1.25435271=300000055=GBP/USD110=1000000279=1269=0270=1.25435271=500000055=GBP/USD110=3000000279=1269=1270=1.43471271=10000055=GBP/USD110=0279=1269=1270=1.43471271=50000055=GBP/USD110=100000279=1269=1270=1.43471271=100000055=GBP/USD110=500000279=1269=1270=1.43471271=300000055=GBP/USD110=1000000279=1269=1270=1.43471271=500000055=GBP/USD110=300000010=239
20260120-14:05:08.430347000 : 8=FIX.4.49=068435=X49=NTPRO_IDBA_UAT56=SIRIUS_500007460_MD34=157252=20260120-14:05:08.612262=MD_GBP/USD_140109778778268=10279=1269=0270=1.25434271=10000055=GBP/USD110=0279=1269=0270=1.25434271=50000055=GBP/USD110=100000279=1269=0270=1.25434271=100000055=GBP/USD110=500000279=1269=0270=1.25434271=300000055=GBP/USD110=1000000279=1269=0270=1.25434271=500000055=GBP/USD110=3000000279=1269=1270=1.43468271=10000055=GBP/USD110=0279=1269=1270=1.43468271=50000055=GBP/USD110=100000279=1269=1270=1.43468271=100000055=GBP/USD110=500000279=1269=1270=1.43468271=300000055=GBP/USD110=1000000279=1269=1270=1.43468271=500000055=GBP/USD110=300000010=002
20260120-14:05:08.450913000 : 8=FIX.4.49=044735=X49=NTPRO_IDBA_UAT56=SIRIUS_500007460_MD34=157352=20260120-14:05:08.631262=MD_EUR/USD_140109278614268=6279=1269=0270=1.14768271=10000055=EUR/USD110=0279=1269=0270=1.14768271=50000055=EUR/USD110=100000279=1269=0270=1.14768271=100000055=EUR/USD110=500000279=1269=1270=1.19793271=10000055=EUR/USD110=0279=1269=1270=1.19793271=50000055=EUR/USD110=100000279=1269=1270=1.19793271=100000055=EUR/USD110=50000010=087
20260120-14:05:08.465471000 : 8=FIX.4.49=039835=X49=NTPRO_IDBA_UAT56=SIRIUS_500007460_MD34=157452=20260120-14:05:08.648262=MD_GBP/USD_140109778778268=5279=1269=1270=1.43469271=10000055=GBP/USD110=0279=1269=1270=1.43469271=50000055=GBP/USD110=100000279=1269=1270=1.43469271=100000055=GBP/USD110=500000279=1269=1270=1.43469271=300000055=GBP/USD110=1000000279=1269=1270=1.43469271=500000055=GBP/USD110=300000010=131
20260120-14:05:08.567880000 : 8=FIX.4.49=039835=X49=NTPRO_IDBA_UAT56=SIRIUS_500007460_MD34=157552=20260120-14:05:08.756262=MD_GBP/USD_140109778778268=5279=1269=0270=1.25435271=10000055=GBP/USD110=0279=1269=0270=1.25435271=50000055=GBP/USD110=100000279=1269=0270=1.25435271=100000055=GBP/USD110=500000279=1269=0270=1.25435271=300000055=GBP/USD110=1000000279=1269=0270=1.25435271=500000055=GBP/USD110=300000010=092
20260120-14:05:08.592270000 : 8=FIX.4.49=039335=X49=NTPRO_IDBA_UAT56=SIRIUS_500007460_MD34=157652=20260120-14:05:08.781262=MD_GBP/USD_140109778778268=5279=1269=1270=1.4347271=10000055=GBP/USD110=0279=1269=1270=1.4347271=50000055=GBP/USD110=100000279=1269=1270=1.4347271=100000055=GBP/USD110=500000279=1269=1270=1.4347271=300000055=GBP/USD110=1000000279=1269=1270=1.4347271=500000055=GBP/USD110=300000010=102
20260120-14:05:09.040603000 : 8=FIX.4.49=044735=X49=NTPRO_IDBA_UAT56=SIRIUS_500007460_MD34=157752=20260120-14:05:09.245262=MD_EUR/USD_140109278614268=6279=1269=0270=1.14767271=10000055=EUR/USD110=0279=1269=0270=1.14767271=50000055=EUR/USD110=100000279=1269=0270=1.14767271=100000055=EUR/USD110=500000279=1269=1270=1.19792271=10000055=EUR/USD110=0279=1269=1270=1.19792271=50000055=EUR/USD110=100000279=1269=1270=1.19792271=100000055=EUR/USD110=50000010=087
20260120-14:05:09.078570000 : 8=FIX.4.49=039835=X49=NTPRO_IDBA_UAT56=SIRIUS_500007460_MD34=157852=20260120-14:05:09.283262=MD_GBP/USD_140109778778268=5279=1269=1270=1.43469271=10000055=GBP/USD110=0279=1269=1270=1.43469271=50000055=GBP/USD110=100000279=1269=1270=1.43469271=100000055=GBP/USD110=500000279=1269=1270=1.43469271=300000055=GBP/USD110=1000000279=1269=1270=1.43469271=500000055=GBP/USD110=300000010=131
20260120-14:05:09.107386000 : 8=FIX.4.49=039335=X49=NTPRO_IDBA_UAT56=SIRIUS_500007460_MD34=157952=20260120-14:05:09.318262=MD_GBP/USD_140109778778268=5279=1269=1270=1.4347271=10000055=GBP/USD110=0279=1269=1270=1.4347271=50000055=GBP/USD110=100000279=1269=1270=1.4347271=100000055=GBP/USD110=500000279=1269=1270=1.4347271=300000055=GBP/USD110=1000000279=1269=1270=1.4347271=500000055=GBP/USD110=300000010=102
20260120-14:05:09.109291000 : 8=FIX.4.49=028035=X49=NTPRO_IDBA_UAT56=SIRIUS_500007460_MD34=158052=20260120-14:05:09.320262=MD_EUR/USD_140109278614268=3279=1269=0270=1.14768271=10000055=EUR/USD110=0279=1269=0270=1.14768271=50000055=EUR/USD110=100000279=1269=0270=1.14768271=100000055=EUR/USD110=50000010=011
20260120-14:05:09.206358000 : 8=FIX.4.49=028035=X49=NTPRO_IDBA_UAT56=SIRIUS_500007460_MD34=158152=20260120-14:05:09.420262=MD_EUR/USD_140109278614268=3279=1269=0270=1.14767271=10000055=EUR/USD110=0279=1269=0270=1.14767271=50000055=EUR/USD110=100000279=1269=0270=1.14767271=100000055=EUR/USD110=50000010=010
20260120-14:05:09.267869000 : 8=FIX.4.49=039835=X49=NTPRO_IDBA_UAT56=SIRIUS_500007460_MD34=158252=20260120-14:05:09.486262=MD_GBP/USD_140109778778268=5279=1269=0270=1.25434271=10000055=GBP/USD110=0279=1269=0270=1.25434271=50000055=GBP/USD110=100000279=1269=0270=1.25434271=100000055=GBP/USD110=500000279=1269=0270=1.25434271=300000055=GBP/USD110=1000000279=1269=0270=1.25434271=500000055=GBP/USD110=300000010=086
20260120-14:05:09.288758000 : 8=FIX.4.49=044735=X49=NTPRO_IDBA_UAT56=SIRIUS_500007460_MD34=158352=20260120-14:05:09.506262=MD_EUR/USD_140109278614268=6279=1269=0270=1.14766271=10000055=EUR/USD110=0279=1269=0270=1.14766271=50000055=EUR/USD110=100000279=1269=0270=1.14766271=100000055=EUR/USD110=500000279=1269=1270=1.19791271=10000055=EUR/USD110=0279=1269=1270=1.19791271=50000055=EUR/USD110=100000279=1269=1270=1.19791271=100000055=EUR/USD110=50000010=078
20260120-14:05:09.341767000 : 8=FIX.4.49=027735=X49=NTPRO_IDBA_UAT56=SIRIUS_500007460_MD34=158452=20260120-14:05:09.556262=MD_EUR/USD_140109278614268=3279=1269=1270=1.1979271=10000055=EUR/USD110=0279=1269=1270=1.1979271=50000055=EUR/USD110=100000279=1269=1270=1.1979271=100000055=EUR/USD110=50000010=147
20260120-14:05:09.438071000 : 8=FIX.4.49=067935=X49=NTPRO_IDBA_UAT56=SIRIUS_500007460_MD34=158552=20260120-14:05:09.658262=MD_GBP/USD_140109778778268=10279=2269=0270=1.25434271=10000055=GBP/USD110=0279=2269=0270=1.25434271=50000055=GBP/USD110=100000279=2269=0270=1.25434271=100000055=GBP/USD110=500000279=2269=0270=1.25434271=300000055=GBP/USD110=1000000279=2269=0270=1.25434271=500000055=GBP/USD110=3000000279=2269=1270=1.4347271=10000055=GBP/USD110=0279=2269=1270=1.4347271=50000055=GBP/USD110=100000279=2269=1270=1.4347271=100000055=GBP/USD110=500000279=2269=1270=1.4347271=300000055=GBP/USD110=1000000279=2269=1270=1.4347271=500000055=GBP/USD110=300000010=012
20260120-14:05:09.725890000 : 8=FIX.4.49=067935=X49=NTPRO_IDBA_UAT56=SIRIUS_500007460_MD34=158652=20260120-14:05:09.951262=MD_GBP/USD_140109778778268=10279=0269=0270=1.25435271=10000055=GBP/USD110=0279=0269=0270=1.25435271=50000055=GBP/USD110=100000279=0269=0270=1.25435271=100000055=GBP/USD110=500000279=0269=0270=1.25435271=300000055=GBP/USD110=1000000279=0269=0270=1.25435271=500000055=GBP/USD110=3000000279=0269=1270=1.4347271=10000055=GBP/USD110=0279=0269=1270=1.4347271=50000055=GBP/USD110=100000279=0269=1270=1.4347271=100000055=GBP/USD110=500000279=0269=1270=1.4347271=300000055=GBP/USD110=1000000279=0269=1270=1.4347271=500000055=GBP/USD110=300000010=250
20260120-14:05:09.726477000 : 8=FIX.4.49=028035=X49=NTPRO_IDBA_UAT56=SIRIUS_500007460_MD34=158752=20260120-14:05:09.956262=MD_EUR/USD_140109278614268=3279=1269=1270=1.19791271=10000055=EUR/USD110=0279=1269=1270=1.19791271=50000055=EUR/USD110=100000279=1269=1270=1.19791271=100000055=EUR/USD110=50000010=039
20260120-14:05:09.769652000 : 8=FIX.4.49=044735=X49=NTPRO_IDBA_UAT56=SIRIUS_500007460_MD34=158852=20260120-14:05:10.008262=MD_EUR/USD_140109278614268=6279=1269=0270=1.14767271=10000055=EUR/USD110=0279=1269=0270=1.14767271=50000055=EUR/USD110=100000279=1269=0270=1.14767271=100000055=EUR/USD110=500000279=1269=1270=1.19792271=10000055=EUR/USD110=0279=1269=1270=1.19792271=50000055=EUR/USD110=100000279=1269=1270=1.19792271=100000055=EUR/USD110=50000010=078
20260120-14:05:09.930666000 : 8=FIX.4.49=044735=X49=NTPRO_IDBA_UAT56=SIRIUS_500007460_MD34=158952=20260120-14:05:10.176262=MD_EUR/USD_140109278614268=6279=1269=0270=1.14768271=10000055=EUR/USD110=0279=1269=0270=1.14768271=50000055=EUR/USD110=100000279=1269=0270=1.14768271=100000055=EUR/USD110=500000279=1269=1270=1.19793271=10000055=EUR/USD110=0279=1269=1270=1.19793271=50000055=EUR/USD110=100000279=1269=1270=1.19793271=100000055=EUR/USD110=50000010=091
20260120-14:05:09.988332000 : 8=FIX.4.49=039835=X49=NTPRO_IDBA_UAT56=SIRIUS_500007460_MD34=159052=20260120-14:05:10.237262=MD_GBP/USD_140109778778268=5279=1269=0270=1.25436271=10000055=GBP/USD110=0279=1269=0270=1.25436271=50000055=GBP/USD110=100000279=1269=0270=1.25436271=100000055=GBP/USD110=500000279=1269=0270=1.25436271=300000055=GBP/USD110=1000000279=1269=0270=1.25436271=500000055=GBP/USD110=300000010=081
20260120-14:05:10.414773000 : 8=FIX.4.49=068435=X49=NTPRO_IDBA_UAT56=SIRIUS_500007460_MD34=159152=20260120-14:05:10.673262=MD_GBP/USD_140109778778268=10279=1269=0270=1.25437271=10000055=GBP/USD110=0279=1269=0270=1.25437271=50000055=GBP/USD110=100000279=1269=0270=1.25437271=100000055=GBP/USD110=500000279=1269=0270=1.25437271=300000055=GBP/USD110=1000000279=1269=0270=1.25437271=500000055=GBP/USD110=3000000279=1269=1270=1.43471271=10000055=GBP/USD110=0279=1269=1270=1.43471271=50000055=GBP/USD110=100000279=1269=1270=1.43471271=100000055=GBP/USD110=500000279=1269=1270=1.43471271=300000055=GBP/USD110=1000000279=1269=1270=1.43471271=500000055=GBP/USD110=300000010=244
20260120-14:05:10.415878000 : 8=FIX.4.49=028035=X49=NTPRO_IDBA_UAT56=SIRIUS_500007460_MD34=159252=20260120-14:05:10.677262=MD_EUR/USD_140109278614268=3279=1269=0270=1.14769271=10000055=EUR/USD110=0279=1269=0270=1.14769271=50000055=EUR/USD110=100000279=1269=0270=1.14769271=100000055=EUR/USD110=50000010=024
20260120-14:05:10.577095000 : 8=FIX.4.49=068435=X49=NTPRO_IDBA_UAT56=SIRIUS_500007460_MD34=159352=20260120-14:05:10.849262=MD_GBP/USD_140109778778268=10279=2269=0270=1.25437271=10000055=GBP/USD110=0279=2269=0270=1.25437271=50000055=GBP/USD110=100000279=2269=0270=1.25437271=100000055=GBP/USD110=500000279=2269=0270=1.25437271=300000055=GBP/USD110=1000000279=2269=0270=1.25437271=500000055=GBP/USD110=3000000279=2269=1270=1.43471271=10000055=GBP/USD110=0279=2269=1270=1.43471271=50000055=GBP/USD110=100000279=2269=1270=1.43471271=100000055=GBP/USD110=500000279=2269=1270=1.43471271=300000055=GBP/USD110=1000000279=2269=1270=1.43471271=500000055=GBP/USD110=300000010=005
20260120-14:05:10.908637000 : 8=FIX.4.49=028035=X49=NTPRO_IDBA_UAT56=SIRIUS_500007460_MD34=159452=20260120-14:05:11.177262=MD_EUR/USD_140109278614268=3279=1269=1270=1.19794271=10000055=EUR/USD110=0279=1269=1270=1.19794271=50000055=EUR/USD110=100000279=1269=1270=1.19794271=100000055=EUR/USD110=50000010=034
20260120-14:05:10.909513000 : 8=FIX.4.49=068435=X49=NTPRO_IDBA_UAT56=SIRIUS_500007460_MD34=159552=20260120-14:05:11.195262=MD_GBP/USD_140109778778268=10279=0269=0270=1.25437271=10000055=GBP/USD110=0279=0269=0270=1.25437271=50000055=GBP/USD110=100000279=0269=0270=1.25437271=100000055=GBP/USD110=500000279=0269=0270=1.25437271=300000055=GBP/USD110=1000000279=0269=0270=1.25437271=500000055=GBP/USD110=3000000279=0269=1270=1.43471271=10000055=GBP/USD110=0279=0269=1270=1.43471271=50000055=GBP/USD110=100000279=0269=1270=1.43471271=100000055=GBP/USD110=500000279=0269=1270=1.43471271=300000055=GBP/USD110=1000000279=0269=1270=1.43471271=500000055=GBP/USD110=300000010=238
20260120-14:05:10.947388000 : 8=FIX.4.49=044435=X49=NTPRO_IDBA_UAT56=SIRIUS_500007460_MD34=159652=20260120-14:05:11.233262=MD_EUR/USD_140109278614268=6279=1269=0270=1.1477271=10000055=EUR/USD110=0279=1269=0270=1.1477271=50000055=EUR/USD110=100000279=1269=0270=1.1477271=100000055=EUR/USD110=500000279=1269=1270=1.19795271=10000055=EUR/USD110=0279=1269=1270=1.19795271=50000055=EUR/USD110=100000279=1269=1270=1.19795271=100000055=EUR/USD110=50000010=178
20260120-14:05:10.954199000 : 8=FIX.4.49=068435=X49=NTPRO_IDBA_UAT56=SIRIUS_500007460_MD34=159752=20260120-14:05:11.240262=MD_GBP/USD_140109778778268=10279=1269=0270=1.25439271=10000055=GBP/USD110=0279=1269=0270=1.25439271=50000055=GBP/USD110=100000279=1269=0270=1.25439271=100000055=GBP/USD110=500000279=1269=0270=1.25439271=300000055=GBP/USD110=1000000279=1269=0270=1.25439271=500000055=GBP/USD110=3000000279=1269=1270=1.43472271=10000055=GBP/USD110=0279=1269=1270=1.43472271=50000055=GBP/USD110=100000279=1269=1270=1.43472271=100000055=GBP/USD110=500000279=1269=1270=1.43472271=300000055=GBP/USD110=1000000279=1269=1270=1.43472271=500000055=GBP/USD110=300000010=000
20260120-14:05:11.008402000 : 8=FIX.4.49=067935=X49=NTPRO_IDBA_UAT56=SIRIUS_500007460_MD34=159852=20260120-14:05:11.300262=MD_GBP/USD_140109778778268=10279=1269=0270=1.2544271=10000055=GBP/USD110=0279=1269=0270=1.2544271=50000055=GBP/USD110=100000279=1269=0270=1.2544271=100000055=GBP/USD110=500000279=1269=0270=1.2544271=300000055=GBP/USD110=1000000279=1269=0270=1.2544271=500000055=GBP/USD110=3000000279=1269=1270=1.43474271=10000055=GBP/USD110=0279=1269=1270=1.43474271=50000055=GBP/USD110=100000279=1269=1270=1.43474271=100000055=GBP/USD110=500000279=1269=1270=1.43474271=300000055=GBP/USD110=1000000279=1269=1270=1.43474271=500000055=GBP/USD110=300000010=244
20260120-14:05:11.026346000 : 8=FIX.4.49=044735=X49=NTPRO_IDBA_UAT56=SIRIUS_500007460_MD34=159952=20260120-14:05:11.318262=MD_EUR/USD_140109278614268=6279=1269=0270=1.14775271=10000055=EUR/USD110=0279=1269=0270=1.14775271=50000055=EUR/USD110=100000279=1269=0270=1.14775271=100000055=EUR/USD110=500000279=1269=1270=1.19799271=10000055=EUR/USD110=0279=1269=1270=1.19799271=50000055=EUR/USD110=100000279=1269=1270=1.19799271=100000055=EUR/USD110=50000010=103
20260120-14:05:11.123573000 : 8=FIX.4.49=068435=X49=NTPRO_IDBA_UAT56=SIRIUS_500007460_MD34=160052=20260120-14:05:11.418262=MD_GBP/USD_140109778778268=10279=1269=0270=1.25443271=10000055=GBP/USD110=0279=1269=0270=1.25443271=50000055=GBP/USD110=100000279=1269=0270=1.25443271=100000055=GBP/USD110=500000279=1269=0270=1.25443271=300000055=GBP/USD110=1000000279=1269=0270=1.25443271=500000055=GBP/USD110=3000000279=1269=1270=1.43475271=10000055=GBP/USD110=0279=1269=1270=1.43475271=50000055=GBP/USD110=100000279=1269=1270=1.43475271=100000055=GBP/USD110=500000279=1269=1270=1.43475271=300000055=GBP/USD110=1000000279=1269=1270=1.43475271=500000055=GBP/USD110=300000010=238
20260120-14:05:11.130743000 : 8=FIX.4.49=027435=X49=NTPRO_IDBA_UAT56=SIRIUS_500007460_MD34=160152=20260120-14:05:11.428262=MD_EUR/USD_140109278614268=3279=1269=1270=1.198271=10000055=EUR/USD110=0279=1269=1270=1.198271=50000055=EUR/USD110=100000279=1269=1270=1.198271=100000055=EUR/USD110=50000010=213
20260120-14:05:11.164333000 : 8=FIX.4.49=068435=X49=NTPRO_IDBA_UAT56=SIRIUS_500007460_MD34=160252=20260120-14:05:11.463262=MD_GBP/USD_140109778778268=10279=1269=0270=1.25444271=10000055=GBP/USD110=0279=1269=0270=1.25444271=50000055=GBP/USD110=100000279=1269=0270=1.25444271=100000055=GBP/USD110=500000279=1269=0270=1.25444271=300000055=GBP/USD110=1000000279=1269=0270=1.25444271=500000055=GBP/USD110=3000000279=1269=1270=1.43476271=10000055=GBP/USD110=0279=1269=1270=1.43476271=50000055=GBP/USD110=100000279=1269=1270=1.43476271=100000055=GBP/USD110=500000279=1269=1270=1.43476271=300000055=GBP/USD110=1000000279=1269=1270=1.43476271=500000055=GBP/USD110=300000010=250
