20260120-14:05:11.213644000 : 8=FIX.4.49=044435=X49=NTPRO_IDBA_UAT56=SIRIUS_500007460_MD34=160352=20260120-14:05:11.514262=MD_EUR/USD_140109278614268=6279=1269=0270=1.1478271=10000055=EUR/USD110=0279=1269=0270=1.1478271=50000055=EUR/USD110=100000279=1269=0270=1.1478271=100000055=EUR/USD110=500000279=1269=1270=1.19804271=10000055=EUR/USD110=0279=1269=1270=1.19804271=50000055=EUR/USD110=100000279=1269=1270=1.19804271=100000055=EUR/USD110=50000010=145
20260120-14:05:11.250717000 : 8=FIX.4.49=068435=X49=NTPRO_IDBA_UAT56=SIRIUS_500007460_MD34=160452=20260120-14:05:11.553262=MD_GBP/USD_140109778778268=10279=1269=0270=1.25447271=10000055=GBP/USD110=0279=1269=0270=1.25447271=50000055=GBP/USD110=100000279=1269=0270=1.25447271=100000055=GBP/USD110=500000279=1269=0270=1.25447271=300000055=GBP/USD110=1000000279=1269=0270=1.25447271=500000055=GBP/USD110=3000000279=1269=1270=1.43481271=10000055=GBP/USD110=0279=1269=1270=1.43481271=50000055=GBP/USD110=100000279=1269=1270=1.43481271=100000055=GBP/USD110=500000279=1269=1270=1.43481271=300000055=GBP/USD110=1000000279=1269=1270=1.43481271=500000055=GBP/USD110=300000010=247
20260120-14:05:11.300830000 : 8=FIX.4.49=028035=X49=NTPRO_IDBA_UAT56=SIRIUS_500007460_MD34=160552=20260120-14:05:11.605262=MD_EUR/USD_140109278614268=3279=1269=0270=1.14779271=10000055=EUR/USD110=0279=1269=0270=1.14779271=50000055=EUR/USD110=100000279=1269=0270=1.14779271=100000055=EUR/USD110=50000010=014
20260120-14:05:11.355207000 : 8=FIX.4.49=044735=X49=NTPRO_IDBA_UAT56=SIRIUS_500007460_MD34=160652=20260120-14:05:11.662262=MD_EUR/USD_140109278614268=6279=1269=0270=1.14778271=10000055=EUR/USD110=0279=1269=0270=1.14778271=50000055=EUR/USD110=100000279=1269=0270=1.14778271=100000055=EUR/USD110=500000279=1269=1270=1.19803271=10000055=EUR/USD110=0279=1269=1270=1.19803271=50000055=EUR/USD110=100000279=1269=1270=1.19803271=100000055=EUR/USD110=50000010=061
20260120-14:05:11.374873000 : 8=FIX.4.49=039835=X49=NTPRO_IDBA_UAT56=SIRIUS_500007460_MD34=160752=20260120-14:05:11.676262=MD_GBP/USD_140109778778268=5279=1269=0270=1.25446271=10000055=GBP/USD110=0279=1269=0270=1.25446271=50000055=GBP/USD110=100000279=1269=0270=1.25446271=100000055=GBP/USD110=500000279=1269=0270=1.25446271=300000055=GBP/USD110=1000000279=1269=0270=1.25446271=500000055=GBP/USD110=300000010=093
20260120-14:05:11.499477000 : 8=FIX.4.49=028035=X49=NTPRO_IDBA_UAT56=SIRIUS_500007460_MD34=160852=20260120-14:05:11.813262=MD_EUR/USD_140109278614268=3279=1269=0270=1.14779271=10000055=EUR/USD110=0279=1269=0270=1.14779271=50000055=EUR/USD110=100000279=1269=0270=1.14779271=100000055=EUR/USD110=50000010=018
20260120-14:05:11.796145000 : 8=FIX.4.49=068435=X49=NTPRO_IDBA_UAT56=SIRIUS_500007460_MD34=160952=20260120-14:05:12.122262=MD_GBP/USD_140109778778268=10279=2269=0270=1.25446271=10000055=GBP/USD110=0279=2269=0270=1.25446271=50000055=GBP/USD110=100000279=2269=0270=1.25446271=100000055=GBP/USD110=500000279=2269=0270=1.25446271=300000055=GBP/USD110=1000000279=2269=0270=1.25446271=500000055=GBP/USD110=3000000279=2269=1270=1.43481271=10000055=GBP/USD110=0279=2269=1270=1.43481271=50000055=GBP/USD110=100000279=2269=1270=1.43481271=100000055=GBP/USD110=500000279=2269=1270=1.43481271=300000055=GBP/USD110=1000000279=2269=1270=1.43481271=500000055=GBP/USD110=300000010=250
20260120-14:05:11.963387000 : 8=FIX.4.49=067935=X49=NTPRO_IDBA_UAT56=SIRIUS_500007460_MD34=161052=20260120-14:05:12.291262=MD_GBP/USD_140109778778268=10279=0269=0270=1.25445271=10000055=GBP/USD110=0279=0269=0270=1.25445271=50000055=GBP/USD110=100000279=0269=0270=1.25445271=100000055=GBP/USD110=500000279=0269=0270=1.25445271=300000055=GBP/USD110=1000000279=0269=0270=1.25445271=500000055=GBP/USD110=3000000279=0269=1270=1.4348271=10000055=GBP/USD110=0279=0269=1270=1.4348271=50000055=GBP/USD110=100000279=0269=1270=1.4348271=100000055=GBP/USD110=500000279=0269=1270=1.4348271=300000055=GBP/USD110=1000000279=0269=1270=1.4348271=500000055=GBP/USD110=300000010=239
20260120-14:05:13.228905000 : 8=FIX.4.49=044735=X49=NTPRO_IDBA_UAT56=SIRIUS_500007460_MD34=161152=20260120-14:05:13.616262=MD_EUR/USD_140109278614268=6279=1269=0270=1.14778271=10000055=EUR/USD110=0279=1269=0270=1.14778271=50000055=EUR/USD110=100000279=1269=0270=1.14778271=100000055=EUR/USD110=500000279=1269=1270=1.19802271=10000055=EUR/USD110=0279=1269=1270=1.19802271=50000055=EUR/USD110=100000279=1269=1270=1.19802271=100000055=EUR/USD110=50000010=055
20260120-14:05:13.273978000 : 8=FIX.4.49=067935=X49=NTPRO_IDBA_UAT56=SIRIUS_500007460_MD34=161252=20260120-14:05:13.663262=MD_GBP/USD_140109778778268=10279=2269=0270=1.25445271=10000055=GBP/USD110=0279=2269=0270=1.25445271=50000055=GBP/USD110=100000279=2269=0270=1.25445271=100000055=GBP/USD110=500000279=2269=0270=1.25445271=300000055=GBP/USD110=1000000279=2269=0270=1.25445271=500000055=GBP/USD110=3000000279=2269=1270=1.4348271=10000055=GBP/USD110=0279=2269=1270=1.4348271=50000055=GBP/USD110=100000279=2269=1270=1.4348271=100000055=GBP/USD110=500000279=2269=1270=1.4348271=300000055=GBP/USD110=1000000279=2269=1270=1.4348271=500000055=GBP/USD110=300000010=009
20260120-14:05:13.340164000 : 8=FIX.4.49=044735=X49=NTPRO_IDBA_UAT56=SIRIUS_500007460_MD34=161352=20260120-14:05:13.730262=MD_EUR/USD_140109278614268=6279=1269=0270=1.14777271=10000055=EUR/USD110=0279=1269=0270=1.14777271=50000055=EUR/USD110=100000279=1269=0270=1.14777271=100000055=EUR/USD110=500000279=1269=1270=1.19801271=10000055=EUR/USD110=0279=1269=1270=1.19801271=50000055=EUR/USD110=100000279=1269=1270=1.19801271=100000055=EUR/USD110=50000010=048
20260120-14:05:13.402809000 : 8=FIX.4.49=067935=X49=NTPRO_IDBA_UAT56=SIRIUS_500007460_MD34=161452=20260120-14:05:13.795262=MD_GBP/USD_140109778778268=10279=0269=0270=1.25445271=10000055=GBP/USD110=0279=0269=0270=1.25445271=50000055=GBP/USD110=100000279=0269=0270=1.25445271=100000055=GBP/USD110=500000279=0269=0270=1.25445271=300000055=GBP/USD110=1000000279=0269=0270=1.25445271=500000055=GBP/USD110=3000000279=0269=1270=1.4348271=10000055=GBP/USD110=0279=0269=1270=1.4348271=50000055=GBP/USD110=100000279=0269=1270=1.4348271=100000055=GBP/USD110=500000279=0269=1270=1.4348271=300000055=GBP/USD110=1000000279=0269=1270=1.4348271=500000055=GBP/USD110=300000010=253
20260120-14:05:13.458805000 : 8=FIX.4.49=028035=X49=NTPRO_IDBA_UAT56=SIRIUS_500007460_MD34=161552=20260120-14:05:13.848262=MD_EUR/USD_140109278614268=3279=1269=0270=1.14776271=10000055=EUR/USD110=0279=1269=0270=1.14776271=50000055=EUR/USD110=100000279=1269=0270=1.14776271=100000055=EUR/USD110=50000010=017
20260120-14:05:13.533690000 : 8=FIX.4.49=044735=X49=NTPRO_IDBA_UAT56=SIRIUS_500007460_MD34=161652=20260120-14:05:13.929262=MD_EUR/USD_140109278614268=6279=1269=0270=1.14774271=10000055=EUR/USD110=0279=1269=0270=1.14774271=50000055=EUR/USD110=100000279=1269=0270=1.14774271=100000055=EUR/USD110=500000279=1269=1270=1.19799271=10000055=EUR/USD110=0279=1269=1270=1.19799271=50000055=EUR/USD110=100000279=1269=1270=1.19799271=100000055=EUR/USD110=50000010=100
20260120-14:05:13.570226000 : 8=FIX.4.49=068435=X49=NTPRO_IDBA_UAT56=SIRIUS_500007460_MD34=161752=20260120-14:05:13.972262=MD_GBP/USD_140109778778268=10279=1269=0270=1.25444271=10000055=GBP/USD110=0279=1269=0270=1.25444271=50000055=GBP/USD110=100000279=1269=0270=1.25444271=100000055=GBP/USD110=500000279=1269=0270=1.25444271=300000055=GBP/USD110=1000000279=1269=0270=1.25444271=500000055=GBP/USD110=3000000279=1269=1270=1.43479271=10000055=GBP/USD110=0279=1269=1270=1.43479271=50000055=GBP/USD110=100000279=1269=1270=1.43479271=100000055=GBP/USD110=500000279=1269=1270=1.43479271=300000055=GBP/USD110=1000000279=1269=1270=1.43479271=500000055=GBP/USD110=300000010=022
20260120-14:05:13.620812000 : 8=FIX.4.49=044735=X49=NTPRO_IDBA_UAT56=SIRIUS_500007460_MD34=161852=20260120-14:05:14.025262=MD_EUR/USD_140109278614268=6279=1269=0270=1.14773271=10000055=EUR/USD110=0279=1269=0270=1.14773271=50000055=EUR/USD110=100000279=1269=0270=1.14773271=100000055=EUR/USD110=500000279=1269=1270=1.19798271=10000055=EUR/USD110=0279=1269=1270=1.19798271=50000055=EUR/USD110=100000279=1269=1270=1.19798271=100000055=EUR/USD110=50000010=084
20260120-14:05:13.622087000 : 8=FIX.4.49=068435=X49=NTPRO_IDBA_UAT56=SIRIUS_500007460_MD34=161952=20260120-14:05:14.027262=MD_GBP/USD_140109778778268=10279=1269=0270=1.25442271=10000055=GBP/USD110=0279=1269=0270=1.25442271=50000055=GBP/USD110=100000279=1269=0270=1.25442271=100000055=GBP/USD110=500000279=1269=0270=1.25442271=300000055=GBP/USD110=1000000279=1269=0270=1.25442271=500000055=GBP/USD110=3000000279=1269=1270=1.43476271=10000055=GBP/USD110=0279=1269=1270=1.43476271=50000055=GBP/USD110=100000279=1269=1270=1.43476271=100000055=GBP/USD110=500000279=1269=1270=1.43476271=300000055=GBP/USD110=1000000279=1269=1270=1.43476271=500000055=GBP/USD110=300000010=247
20260120-14:05:13.833732000 : 8=FIX.4.49=028035=X49=NTPRO_IDBA_UAT56=SIRIUS_500007460_MD34=162052=20260120-14:05:14.244262=MD_EUR/USD_140109278614268=3279=1269=1270=1.19797271=10000055=EUR/USD110=0279=1269=1270=1.19797271=50000055=EUR/USD110=100000279=1269=1270=1.19797271=100000055=EUR/USD110=50000010=031
20260120-14:05:13.893884000 : 8=FIX.4.49=028035=X49=NTPRO_IDBA_UAT56=SIRIUS_500007460_MD34=162152=20260120-14:05:14.310262=MD_EUR/USD_140109278614268=3279=1269=1270=1.19798271=10000055=EUR/USD110=0279=1269=1270=1.19798271=50000055=EUR/USD110=100000279=1269=1270=1.19798271=100000055=EUR/USD110=50000010=029
20260120-14:05:14.480098000 : 8=FIX.4.49=068435=X49=NTPRO_IDBA_UAT56=SIRIUS_500007460_MD34=162252=20260120-14:05:14.907262=MD_GBP/USD_140109778778268=10279=2269=0270=1.25442271=10000055=GBP/USD110=0279=2269=0270=1.25442271=50000055=GBP/USD110=100000279=2269=0270=1.25442271=100000055=GBP/USD110=500000279=2269=0270=1.25442271=300000055=GBP/USD110=1000000279=2269=0270=1.25442271=500000055=GBP/USD110=3000000279=2269=1270=1.43476271=10000055=GBP/USD110=0279=2269=1270=1.43476271=50000055=GBP/USD110=100000279=2269=1270=1.43476271=100000055=GBP/USD110=500000279=2269=1270=1.43476271=300000055=GBP/USD110=1000000279=2269=1270=1.43476271=500000055=GBP/USD110=300000010=002
20260120-14:05:14.655062000 : 8=FIX.4.49=044735=X49=NTPRO_IDBA_UAT56=SIRIUS_500007460_MD34=162352=20260120-14:05:15.106262=MD_EUR/USD_140109278614268=6279=1269=0270=1.14774271=10000055=EUR/USD110=0279=1269=0270=1.14774271=50000055=EUR/USD110=100000279=1269=0270=1.14774271=100000055=EUR/USD110=500000279=1269=1270=1.19799271=10000055=EUR/USD110=0279=1269=1270=1.19799271=50000055=EUR/USD110=100000279=1269=1270=1.19799271=100000055=EUR/USD110=50000010=087
20260120-14:05:14.731572000 : 8=FIX.4.49=067935=X49=NTPRO_IDBA_UAT56=SIRIUS_500007460_MD34=162452=20260120-14:05:15.160262=MD_GBP/USD_140109778778268=10279=0269=0270=1.25445271=10000055=GBP/USD110=0279=0269=0270=1.25445271=50000055=GBP/USD110=100000279=0269=0270=1.25445271=100000055=GBP/USD110=500000279=0269=0270=1.25445271=300000055=GBP/USD110=1000000279=0269=0270=1.25445271=500000055=GBP/USD110=3000000279=0269=1270=1.4348271=10000055=GBP/USD110=0279=0269=1270=1.4348271=50000055=GBP/USD110=100000279=0269=1270=1.4348271=100000055=GBP/USD110=500000279=0269=1270=1.4348271=300000055=GBP/USD110=1000000279=0269=1270=1.4348271=500000055=GBP/USD110=300000010=242
20260120-14:05:14.735855000 : 8=FIX.4.49=044735=X49=NTPRO_IDBA_UAT56=SIRIUS_500007460_MD34=162552=20260120-14:05:15.175262=MD_EUR/USD_140109278614268=6279=1269=0270=1.14777271=10000055=EUR/USD110=0279=1269=0270=1.14777271=50000055=EUR/USD110=100000279=1269=0270=1.14777271=100000055=EUR/USD110=500000279=1269=1270=1.19801271=10000055=EUR/USD110=0279=1269=1270=1.19801271=50000055=EUR/USD110=100000279=1269=1270=1.19801271=100000055=EUR/USD110=50000010=056
20260120-14:05:14.741883000 : 8=FIX.4.49=068435=X49=NTPRO_IDBA_UAT56=SIRIUS_500007460_MD34=162652=20260120-14:05:15.196262=MD_GBP/USD_140109778778268=10279=1269=0270=1.25446271=10000055=GBP/USD110=0279=1269=0270=1.25446271=50000055=GBP/USD110=100000279=1269=0270=1.25446271=100000055=GBP/USD110=500000279=1269=0270=1.25446271=300000055=GBP/USD110=1000000279=1269=0270=1.25446271=500000055=GBP/USD110=3000000279=1269=1270=1.43481271=10000055=GBP/USD110=0279=1269=1270=1.43481271=50000055=GBP/USD110=100000279=1269=1270=1.43481271=100000055=GBP/USD110=500000279=1269=1270=1.43481271=300000055=GBP/USD110=1000000279=1269=1270=1.43481271=500000055=GBP/USD110=300000010=253
20260120-14:05:14.789430000 : 8=FIX.4.49=039835=X49=NTPRO_IDBA_UAT56=SIRIUS_500007460_MD34=162752=20260120-14:05:15.249262=MD_GBP/USD_140109778778268=5279=1269=0270=1.25447271=10000055=GBP/USD110=0279=1269=0270=1.25447271=50000055=GBP/USD110=100000279=1269=0270=1.25447271=100000055=GBP/USD110=500000279=1269=0270=1.25447271=300000055=GBP/USD110=1000000279=1269=0270=1.25447271=500000055=GBP/USD110=300000010=100
20260120-14:05:14.828398000 : 8=FIX.4.49=044735=X49=NTPRO_IDBA_UAT56=SIRIUS_500007460_MD34=162852=20260120-14:05:15.284262=MD_EUR/USD_140109278614268=6279=1269=0270=1.14779271=10000055=EUR/USD110=0279=1269=0270=1.14779271=50000055=EUR/USD110=100000279=1269=0270=1.14779271=100000055=EUR/USD110=500000279=1269=1270=1.19804271=10000055=EUR/USD110=0279=1269=1270=1.19804271=50000055=EUR/USD110=100000279=1269=1270=1.19804271=100000055=EUR/USD110=50000010=075
20260120-14:05:14.834350000 : 8=FIX.4.49=039835=X49=NTPRO_IDBA_UAT56=SIRIUS_500007460_MD34=162952=20260120-14:05:15.296262=MD_GBP/USD_140109778778268=5279=1269=1270=1.43482271=10000055=GBP/USD110=0279=1269=1270=1.43482271=50000055=GBP/USD110=100000279=1269=1270=1.43482271=100000055=GBP/USD110=500000279=1269=1270=1.43482271=300000055=GBP/USD110=1000000279=1269=1270=1.43482271=500000055=GBP/USD110=300000010=104
20260120-14:05:14.888350000 : 8=FIX.4.49=068435=X49=NTPRO_IDBA_UAT56=SIRIUS_500007460_MD34=163052=20260120-14:05:15.353262=MD_GBP/USD_140109778778268=10279=1269=0270=1.25448271=10000055=GBP/USD110=0279=1269=0270=1.25448271=50000055=GBP/USD110=100000279=1269=0270=1.25448271=100000055=GBP/USD110=500000279=1269=0270=1.25448271=300000055=GBP/USD110=1000000279=1269=0270=1.25448271=500000055=GBP/USD110=3000000279=1269=1270=1.43483271=10000055=GBP/USD110=0279=1269=1270=1.43483271=50000055=GBP/USD110=100000279=1269=1270=1.43483271=100000055=GBP/USD110=500000279=1269=1270=1.43483271=300000055=GBP/USD110=1000000279=1269=1270=1.43483271=500000055=GBP/USD110=300000010=007
20260120-14:05:14.974396000 : 8=FIX.4.49=039835=X49=NTPRO_IDBA_UAT56=SIRIUS_500007460_MD34=163152=20260120-14:05:15.440262=MD_GBP/USD_140109778778268=5279=1269=0270=1.25449271=10000055=GBP/USD110=0279=1269=0270=1.25449271=50000055=GBP/USD110=100000279=1269=0270=1.25449271=100000055=GBP/USD110=500000279=1269=0270=1.25449271=300000055=GBP/USD110=1000000279=1269=0270=1.25449271=500000055=GBP/USD110=300000010=098
20260120-14:05:15.022388000 : 8=FIX.4.49=028035=X49=NTPRO_IDBA_UAT56=SIRIUS_500007460_MD34=163252=20260120-14:05:15.485262=MD_EUR/USD_140109278614268=3279=1269=1270=1.19803271=10000055=EUR/USD110=0279=1269=1270=1.19803271=50000055=EUR/USD110=100000279=1269=1270=1.19803271=100000055=EUR/USD110=50000010=006
20260120-14:05:15.024114000 : 8=FIX.4.49=7735=034=1549=SIRIUS_500007460_MD52=20260120-14:05:15.02356=NTPRO_IDBA_UAT10=064
20260120-14:05:15.040702000 : 8=FIX.4.49=068435=X49=NTPRO_IDBA_UAT56=SIRIUS_500007460_MD34=163352=20260120-14:05:15.513262=MD_GBP/USD_140109778778268=10279=2269=0270=1.25449271=10000055=GBP/USD110=0279=2269=0270=1.25449271=50000055=GBP/USD110=100000279=2269=0270=1.25449271=100000055=GBP/USD110=500000279=2269=0270=1.25449271=300000055=GBP/USD110=1000000279=2269=0270=1.25449271=500000055=GBP/USD110=3000000279=2269=1270=1.43483271=10000055=GBP/USD110=0279=2269=1270=1.43483271=50000055=GBP/USD110=100000279=2269=1270=1.43483271=100000055=GBP/USD110=500000279=2269=1270=1.43483271=300000055=GBP/USD110=1000000279=2269=1270=1.43483271=500000055=GBP/USD110=300000010=023
20260120-14:05:15.135768000 : 8=FIX.4.49=028035=X49=NTPRO_IDBA_UAT56=SIRIUS_500007460_MD34=163452=20260120-14:05:15.613262=MD_EUR/USD_140109278614268=3279=1269=1270=1.19804271=10000055=EUR/USD110=0279=1269=1270=1.19804271=50000055=EUR/USD110=100000279=1269=1270=1.19804271=100000055=EUR/USD110=50000010=004
20260120-14:05:15.609893000 : 8=FIX.4.49=028035=X49=NTPRO_IDBA_UAT56=SIRIUS_500007460_MD34=163552=20260120-14:05:16.111262=MD_EUR/USD_140109278614268=3279=1269=1270=1.19803271=10000055=EUR/USD110=0279=1269=1270=1.19803271=50000055=EUR/USD110=100000279=1269=1270=1.19803271=100000055=EUR/USD110=50000010=252
20260120-14:05:15.634228000 : 8=FIX.4.49=068435=X49=NTPRO_IDBA_UAT56=SIRIUS_500007460_MD34=163652=20260120-14:05:16.133262=MD_GBP/USD_140109778778268=10279=0269=0270=1.25447271=10000055=GBP/USD110=0279=0269=0270=1.25447271=50000055=GBP/USD110=100000279=0269=0270=1.25447271=100000055=GBP/USD110=500000279=0269=0270=1.25447271=300000055=GBP/USD110=1000000279=0269=0270=1.25447271=500000055=GBP/USD110=3000000279=0269=1270=1.43483271=10000055=GBP/USD110=0279=0269=1270=1.43483271=50000055=GBP/USD110=100000279=0269=1270=1.43483271=100000055=GBP/USD110=500000279=0269=1270=1.43483271=300000055=GBP/USD110=1000000279=0269=1270=1.43483271=500000055=GBP/USD110=300000010=251
20260120-14:05:15.666701000 : 8=FIX.4.49=028035=X49=NTPRO_IDBA_UAT56=SIRIUS_500007460_MD34=163752=20260120-14:05:16.171262=MD_EUR/USD_140109278614268=3279=1269=0270=1.14778271=10000055=EUR/USD110=0279=1269=0270=1.14778271=50000055=EUR/USD110=100000279=1269=0270=1.14778271=100000055=EUR/USD110=50000010=019
20260120-14:05:29.718942000 : 8=FIX.4.49=007935=049=NTPRO_IDBA_UAT56=SIRIUS_500007460_MD34=163852=20260120-14:05:30.78410=025
20260120-14:05:45.026844000 : 8=FIX.4.49=7735=034=1649=SIRIUS_500007460_MD52=20260120-14:05:45.02456=NTPRO_IDBA_UAT10=069
20260120-14:05:59.840031000 : 8=FIX.4.49=007935=049=NTPRO_IDBA_UAT56=SIRIUS_500007460_MD34=163952=20260120-14:06:00.79610=027
20260120-14:06:15.147726000 : 8=FIX.4.49=7735=034=1749=SIRIUS_500007460_MD52=20260120-14:06:15.14656=NTPRO_IDBA_UAT10=073
20260120-14:06:15.959690000 : 8=FIX.4.49=044435=X49=NTPRO_IDBA_UAT56=SIRIUS_500007460_MD34=164052=20260120-14:06:16.231262=MD_EUR/USD_140109278614268=6279=1269=0270=1.14795271=10000055=EUR/USD110=0279=1269=0270=1.14795271=50000055=EUR/USD110=100000279=1269=0270=1.14795271=100000055=EUR/USD110=500000279=1269=1270=1.1982271=10000055=EUR/USD110=0279=1269=1270=1.1982271=50000055=EUR/USD110=100000279=1269=1270=1.1982271=100000055=EUR/USD110=50000010=160
20260120-14:06:15.960199000 : 8=FIX.4.49=067935=X49=NTPRO_IDBA_UAT56=SIRIUS_500007460_MD34=164152=20260120-14:06:16.232262=MD_GBP/USD_140109778778268=10279=1269=0270=1.25476271=10000055=GBP/USD110=0279=1269=0270=1.25476271=50000055=GBP/USD110=100000279=1269=0270=1.25476271=100000055=GBP/USD110=500000279=1269=0270=1.25476271=300000055=GBP/USD110=1000000279=1269=0270=1.25476271=500000055=GBP/USD110=3000000279=1269=1270=1.4351271=10000055=GBP/USD110=0279=1269=1270=1.4351271=50000055=GBP/USD110=100000279=1269=1270=1.4351271=100000055=GBP/USD110=500000279=1269=1270=1.4351271=300000055=GBP/USD110=1000000279=1269=1270=1.4351271=500000055=GBP/USD110=300000010=243
20260120-14:06:16.673346000 : 8=FIX.4.49=028035=X49=NTPRO_IDBA_UAT56=SIRIUS_500007460_MD34=164252=20260120-14:06:16.975262=MD_EUR/USD_140109278614268=3279=1269=0270=1.14796271=10000055=EUR/USD110=0279=1269=0270=1.14796271=50000055=EUR/USD110=100000279=1269=0270=1.14796271=100000055=EUR/USD110=50000010=028
20260120-14:06:16.741389000 : 8=FIX.4.49=068435=X49=NTPRO_IDBA_UAT56=SIRIUS_500007460_MD34=164352=20260120-14:06:17.048262=MD_GBP/USD_140109778778268=10279=1269=0270=1.25475271=10000055=GBP/USD110=0279=1269=0270=1.25475271=50000055=GBP/USD110=100000279=1269=0270=1.25475271=100000055=GBP/USD110=500000279=1269=0270=1.25475271=300000055=GBP/USD110=1000000279=1269=0270=1.25475271=500000055=GBP/USD110=3000000279=1269=1270=1.43508271=10000055=GBP/USD110=0279=1269=1270=1.43508271=50000055=GBP/USD110=100000279=1269=1270=1.43508271=100000055=GBP/USD110=500000279=1269=1270=1.43508271=300000055=GBP/USD110=1000000279=1269=1270=1.43508271=500000055=GBP/USD110=300000010=005
20260120-14:06:16.745967000 : 8=FIX.4.49=044735=X49=NTPRO_IDBA_UAT56=SIRIUS_500007460_MD34=164452=20260120-14:06:17.054262=MD_EUR/USD_140109278614268=6279=1269=0270=1.14793271=10000055=EUR/USD110=0279=1269=0270=1.14793271=50000055=EUR/USD110=100000279=1269=0270=1.14793271=100000055=EUR/USD110=500000279=1269=1270=1.19817271=10000055=EUR/USD110=0279=1269=1270=1.19817271=50000055=EUR/USD110=100000279=1269=1270=1.19817271=100000055=EUR/USD110=50000010=071
20260120-14:06:16.825730000 : 8=FIX.4.49=039835=X49=NTPRO_IDBA_UAT56=SIRIUS_500007460_MD34=164552=20260120-14:06:17.123262=MD_GBP/USD_140109778778268=5279=1269=1270=1.43509271=10000055=GBP/USD110=0279=1269=1270=1.43509271=50000055=GBP/USD110=100000279=1269=1270=1.43509271=100000055=GBP/USD110=500000279=1269=1270=1.43509271=300000055=GBP/USD110=1000000279=1269=1270=1.43509271=500000055=GBP/USD110=300000010=094
20260120-14:06:16.826431000 : 8=FIX.4.49=028035=X49=NTPRO_IDBA_UAT56=SIRIUS_500007460_MD34=164652=20260120-14:06:17.133262=MD_EUR/USD_140109278614268=3279=1269=1270=1.19818271=10000055=EUR/USD110=0279=1269=1270=1.19818271=50000055=EUR/USD110=100000279=1269=1270=1.19818271=100000055=EUR/USD110=50000010=022
20260120-14:06:16.888286000 : 8=FIX.4.49=044735=X49=NTPRO_IDBA_UAT56=SIRIUS_500007460_MD34=164752=20260120-14:06:17.203262=MD_EUR/USD_140109278614268=6279=1269=0270=1.14792271=10000055=EUR/USD110=0279=1269=0270=1.14792271=50000055=EUR/USD110=100000279=1269=0270=1.14792271=100000055=EUR/USD110=500000279=1269=1270=1.19817271=10000055=EUR/USD110=0279=1269=1270=1.19817271=50000055=EUR/USD110=100000279=1269=1270=1.19817271=100000055=EUR/USD110=50000010=067
20260120-14:06:16.947358000 : 8=FIX.4.49=068435=X49=NTPRO_IDBA_UAT56=SIRIUS_500007460_MD34=164852=20260120-14:06:17.264262=MD_GBP/USD_140109778778268=10279=1269=0270=1.25474271=10000055=GBP/USD110=0279=1269=0270=1.25474271=50000055=GBP/USD110=100000279=1269=0270=1.25474271=100000055=GBP/USD110=500000279=1269=0270=1.25474271=300000055=GBP/USD110=1000000279=1269=0270=1.25474271=500000055=GBP/USD110=3000000279=1269=1270=1.43508271=10000055=GBP/USD110=0279=1269=1270=1.43508271=50000055=GBP/USD110=100000279=1269=1270=1.43508271=100000055=GBP/USD110=500000279=1269=1270=1.43508271=300000055=GBP/USD110=1000000279=1269=1270=1.43508271=500000055=GBP/USD110=300000010=005
20260120-14:06:16.988350000 : 8=FIX.4.49=039835=X49=NTPRO_IDBA_UAT56=SIRIUS_500007460_MD34=164952=20260120-14:06:17.308262=MD_GBP/USD_140109778778268=5279=1269=0270=1.25475271=10000055=GBP/USD110=0279=1269=0270=1.25475271=50000055=GBP/USD110=100000279=1269=0270=1.25475271=100000055=GBP/USD110=500000279=1269=0270=1.25475271=300000055=GBP/USD110=1000000279=1269=0270=1.25475271=500000055=GBP/USD110=300000010=108
20260120-14:06:17.026640000 : 8=FIX.4.49=044735=X49=NTPRO_IDBA_UAT56=SIRIUS_500007460_MD34=165052=20260120-14:06:17.348262=MD_EUR/USD_140109278614268=6279=1269=0270=1.14791271=10000055=EUR/USD110=0279=1269=0270=1.14791271=50000055=EUR/USD110=100000279=1269=0270=1.14791271=100000055=EUR/USD110=500000279=1269=1270=1.19816271=10000055=EUR/USD110=0279=1269=1270=1.19816271=50000055=EUR/USD110=100000279=1269=1270=1.19816271=100000055=EUR/USD110=50000010=065
20260120-14:06:17.045072000 : 8=FIX.4.49=039835=X49=NTPRO_IDBA_UAT56=SIRIUS_500007460_MD34=165152=20260120-14:06:17.365262=MD_GBP/USD_140109778778268=5279=1269=0270=1.25476271=10000055=GBP/USD110=0279=1269=0270=1.25476271=50000055=GBP/USD110=100000279=1269=0270=1.25476271=100000055=GBP/USD110=500000279=1269=0270=1.25476271=300000055=GBP/USD110=1000000279=1269=0270=1.25476271=500000055=GBP/USD110=300000010=109
20260120-14:06:17.065123000 : 8=FIX.4.49=068435=X49=NTPRO_IDBA_UAT56=SIRIUS_500007460_MD34=165252=20260120-14:06:17.388262=MD_GBP/USD_140109778778268=10279=1269=0270=1.25475271=10000055=GBP/USD110=0279=1269=0270=1.25475271=50000055=GBP/USD110=100000279=1269=0270=1.25475271=100000055=GBP/USD110=500000279=1269=0270=1.25475271=300000055=GBP/USD110=1000000279=1269=0270=1.25475271=500000055=GBP/USD110=3000000279=1269=1270=1.43509271=10000055=GBP/USD110=0279=1269=1270=1.43509271=50000055=GBP/USD110=100000279=1269=1270=1.43509271=100000055=GBP/USD110=500000279=1269=1270=1.43509271=300000055=GBP/USD110=1000000279=1269=1270=1.43509271=500000055=GBP/USD110=300000010=017
20260120-14:06:17.079411000 : 8=FIX.4.49=028035=X49=NTPRO_IDBA_UAT56=SIRIUS_500007460_MD34=165352=20260120-14:06:17.403262=MD_EUR/USD_140109278614268=3279=1269=0270=1.14792271=10000055=EUR/USD110=0279=1269=0270=1.14792271=50000055=EUR/USD110=100000279=1269=0270=1.14792271=100000055=EUR/USD110=50000010=005
20260120-14:06:17.090679000 : 8=FIX.4.49=039835=X49=NTPRO_IDBA_UAT56=SIRIUS_500007460_MD34=165452=20260120-14:06:17.415262=MD_GBP/USD_140109778778268=5279=1269=1270=1.43508271=10000055=GBP/USD110=0279=1269=1270=1.43508271=50000055=GBP/USD110=100000279=1269=1270=1.43508271=100000055=GBP/USD110=500000279=1269=1270=1.43508271=300000055=GBP/USD110=1000000279=1269=1270=1.43508271=500000055=GBP/USD110=300000010=093
20260120-14:06:17.116723000 : 8=FIX.4.49=039835=X49=NTPRO_IDBA_UAT56=SIRIUS_500007460_MD34=165552=20260120-14:06:17.442262=MD_GBP/USD_140109778778268=5279=1269=1270=1.43509271=10000055=GBP/USD110=0279=1269=1270=1.43509271=50000055=GBP/USD110=100000279=1269=1270=1.43509271=100000055=GBP/USD110=500000279=1269=1270=1.43509271=300000055=GBP/USD110=1000000279=1269=1270=1.43509271=500000055=GBP/USD110=300000010=099
20260120-14:06:17.148473000 : 8=FIX.4.49=039835=X49=NTPRO_IDBA_UAT56=SIRIUS_500007460_MD34=165652=20260120-14:06:17.475262=MD_GBP/USD_140109778778268=5279=1269=0270=1.25474271=10000055=GBP/USD110=0279=1269=0270=1.25474271=50000055=GBP/USD110=100000279=1269=0270=1.25474271=100000055=GBP/USD110=500000279=1269=0270=1.25474271=300000055=GBP/USD110=1000000279=1269=0270=1.25474271=500000055=GBP/USD110=300000010=106
20260120-14:06:17.168652000 : 8=FIX.4.49=039835=X49=NTPRO_IDBA_UAT56=SIRIUS_500007460_MD34=165752=20260120-14:06:17.495262=MD_GBP/USD_140109778778268=5279=1269=0270=1.25475271=10000055=GBP/USD110=0279=1269=0270=1.25475271=50000055=GBP/USD110=100000279=1269=0270=1.25475271=100000055=GBP/USD110=500000279=1269=0270=1.25475271=300000055=GBP/USD110=1000000279=1269=0270=1.25475271=500000055=GBP/USD110=300000010=114
20260120-14:06:17.217451000 : 8=FIX.4.49=028035=X49=NTPRO_IDBA_UAT56=SIRIUS_500007460_MD34=165852=20260120-14:06:17.534262=MD_EUR/USD_140109278614268=3279=1269=0270=1.14791271=10000055=EUR/USD110=0279=1269=0270=1.14791271=50000055=EUR/USD110=100000279=1269=0270=1.14791271=100000055=EUR/USD110=50000010=012
20260120-14:06:17.457289000 : 8=FIX.4.49=044735=X49=NTPRO_IDBA_UAT56=SIRIUS_500007460_MD34=165952=20260120-14:06:17.798262=MD_EUR/USD_140109278614268=6279=1269=0270=1.14792271=10000055=EUR/USD110=0279=1269=0270=1.14792271=50000055=EUR/USD110=100000279=1269=0270=1.14792271=100000055=EUR/USD110=500000279=1269=1270=1.19817271=10000055=EUR/USD110=0279=1269=1270=1.19817271=50000055=EUR/USD110=100000279=1269=1270=1.19817271=100000055=EUR/USD110=50000010=089
20260120-14:06:17.654808000 : 8=FIX.4.49=028035=X49=NTPRO_IDBA_UAT56=SIRIUS_500007460_MD34=166052=20260120-14:06:18.004262=MD_EUR/USD_140109278614268=3279=1269=1270=1.19816271=10000055=EUR/USD110=0279=1269=1270=1.19816271=50000055=EUR/USD110=100000279=1269=1270=1.19816271=100000055=EUR/USD110=50000010=010
20260120-14:06:17.876138000 : 8=FIX.4.49=039835=X49=NTPRO_IDBA_UAT56=SIRIUS_500007460_MD34=166152=20260120-14:06:18.236262=MD_GBP/USD_140109778778268=5279=1269=0270=1.25476271=10000055=GBP/USD110=0279=1269=0270=1.25476271=50000055=GBP/USD110=100000279=1269=0270=1.25476271=100000055=GBP/USD110=500000279=1269=0270=1.25476271=300000055=GBP/USD110=1000000279=1269=0270=1.25476271=500000055=GBP/USD110=300000010=108
20260120-14:06:17.922798000 : 8=FIX.4.49=028035=X49=NTPRO_IDBA_UAT56=SIRIUS_500007460_MD34=166252=20260120-14:06:18.285262=MD_EUR/USD_140109278614268=3279=1269=1270=1.19817271=10000055=EUR/USD110=0279=1269=1270=1.19817271=50000055=EUR/USD110=100000279=1269=1270=1.19817271=100000055=EUR/USD110=50000010=026
20260120-14:06:17.980813000 : 8=FIX.4.49=039335=X49=NTPRO_IDBA_UAT56=SIRIUS_500007460_MD34=166352=20260120-14:06:18.345262=MD_GBP/USD_140109778778268=5279=1269=1270=1.4351271=10000055=GBP/USD110=0279=1269=1270=1.4351271=50000055=GBP/USD110=100000279=1269=1270=1.4351271=100000055=GBP/USD110=500000279=1269=1270=1.4351271=300000055=GBP/USD110=1000000279=1269=1270=1.4351271=500000055=GBP/USD110=300000010=072
20260120-14:06:18.254865000 : 8=FIX.4.49=044735=X49=NTPRO_IDBA_UAT56=SIRIUS_500007460_MD34=166452=20260120-14:06:18.632262=MD_EUR/USD_140109278614268=6279=1269=0270=1.14794271=10000055=EUR/USD110=0279=1269=0270=1.14794271=50000055=EUR/USD110=100000279=1269=0270=1.14794271=100000055=EUR/USD110=500000279=1269=1270=1.19819271=10000055=EUR/USD110=0279=1269=1270=1.19819271=50000055=EUR/USD110=100000279=1269=1270=1.19819271=100000055=EUR/USD110=50000010=085
20260120-14:06:18.338119000 : 8=FIX.4.49=028035=X49=NTPRO_IDBA_UAT56=SIRIUS_500007460_MD34=166552=20260120-14:06:18.718262=MD_EUR/USD_140109278614268=3279=1269=1270=1.19818271=10000055=EUR/USD110=0279=1269=1270=1.19818271=50000055=EUR/USD110=100000279=1269=1270=1.19818271=100000055=EUR/USD110=50000010=033
20260120-14:06:18.400647000 : 8=FIX.4.49=039835=X49=NTPRO_IDBA_UAT56=SIRIUS_500007460_MD34=166652=20260120-14:06:18.784262=MD_GBP/USD_140109778778268=5279=1269=0270=1.25477271=10000055=GBP/USD110=0279=1269=0270=1.25477271=50000055=GBP/USD110=100000279=1269=0270=1.25477271=100000055=GBP/USD110=500000279=1269=0270=1.25477271=300000055=GBP/USD110=1000000279=1269=0270=1.25477271=500000055=GBP/USD110=300000010=126
20260120-14:06:18.453332000 : 8=FIX.4.49=044735=X49=NTPRO_IDBA_UAT56=SIRIUS_500007460_MD34=166752=20260120-14:06:18.838262=MD_EUR/USD_140109278614268=6279=1269=0270=1.14795271=10000055=EUR/USD110=0279=1269=0270=1.14795271=50000055=EUR/USD110=100000279=1269=0270=1.14795271=100000055=EUR/USD110=500000279=1269=1270=1.19819271=10000055=EUR/USD110=0279=1269=1270=1.19819271=50000055=EUR/USD110=100000279=1269=1270=1.19819271=100000055=EUR/USD110=50000010=099
20260120-14:06:18.686391000 : 8=FIX.4.49=039835=X49=NTPRO_IDBA_UAT56=SIRIUS_500007460_MD34=166852=20260120-14:06:19.080262=MD_GBP/USD_140109778778268=5279=1269=1270=1.43511271=10000055=GBP/USD110=0279=1269=1270=1.43511271=50000055=GBP/USD110=100000279=1269=1270=1.43511271=100000055=GBP/USD110=500000279=1269=1270=1.43511271=300000055=GBP/USD110=1000000279=1269=1270=1.43511271=500000055=GBP/USD110=300000010=068
20260120-14:06:18.737585000 : 8=FIX.4.49=039335=X49=NTPRO_IDBA_UAT56=SIRIUS_500007460_MD34=166952=20260120-14:06:19.135262=MD_GBP/USD_140109778778268=5279=1269=1270=1.4351271=10000055=GBP/USD110=0279=1269=1270=1.4351271=50000055=GBP/USD110=100000279=1269=1270=1.4351271=100000055=GBP/USD110=500000279=1269=1270=1.4351271=300000055=GBP/USD110=1000000279=1269=1270=1.4351271=500000055=GBP/USD110=300000010=076
20260120-14:06:18.789255000 : 8=FIX.4.49=039835=X49=NTPRO_IDBA_UAT56=SIRIUS_500007460_MD34=167052=20260120-14:06:19.188262=MD_GBP/USD_140109778778268=5279=1269=0270=1.25476271=10000055=GBP/USD110=0279=1269=0270=1.25476271=50000055=GBP/USD110=100000279=1269=0270=1.25476271=100000055=GBP/USD110=500000279=1269=0270=1.25476271=300000055=GBP/USD110=1000000279=1269=0270=1.25476271=500000055=GBP/USD110=300000010=115
20260120-14:06:18.819960000 : 8=FIX.4.49=028035=X49=NTPRO_IDBA_UAT56=SIRIUS_500007460_MD34=167152=20260120-14:06:19.223262=MD_EUR/USD_140109278614268=3279=1269=0270=1.14794271=10000055=EUR/USD110=0279=1269=0270=1.14794271=50000055=EUR/USD110=100000279=1269=0270=1.14794271=100000055=EUR/USD110=50000010=013
20260120-14:06:18.977191000 : 8=FIX.4.49=044735=X49=NTPRO_IDBA_UAT56=SIRIUS_500007460_MD34=167252=20260120-14:06:19.380262=MD_EUR/USD_140109278614268=6279=1269=0270=1.14792271=10000055=EUR/USD110=0279=1269=0270=1.14792271=50000055=EUR/USD110=100000279=1269=0270=1.14792271=100000055=EUR/USD110=500000279=1269=1270=1.19816271=10000055=EUR/USD110=0279=1269=1270=1.19816271=50000055=EUR/USD110=100000279=1269=1270=1.19816271=100000055=EUR/USD110=50000010=070
20260120-14:06:19.022800000 : 8=FIX.4.49=028035=X49=NTPRO_IDBA_UAT56=SIRIUS_500007460_MD34=167352=20260120-14:06:19.434262=MD_EUR/USD_140109278614268=3279=1269=1270=1.19817271=10000055=EUR/USD110=0279=1269=1270=1.19817271=50000055=EUR/USD110=100000279=1269=1270=1.19817271=100000055=EUR/USD110=50000010=025
20260120-14:06:19.160236000 : 8=FIX.4.49=039835=X49=NTPRO_IDBA_UAT56=SIRIUS_500007460_MD34=167452=20260120-14:06:19.577262=MD_GBP/USD_140109778778268=5279=1269=0270=1.25477271=10000055=GBP/USD110=0279=1269=0270=1.25477271=50000055=GBP/USD110=100000279=1269=0270=1.25477271=100000055=GBP/USD110=500000279=1269=0270=1.25477271=300000055=GBP/USD110=1000000279=1269=0270=1.25477271=500000055=GBP/USD110=300000010=126
20260120-14:06:19.242311000 : 8=FIX.4.49=039835=X49=NTPRO_IDBA_UAT56=SIRIUS_500007460_MD34=167552=20260120-14:06:19.663262=MD_GBP/USD_140109778778268=5279=1269=0270=1.25476271=10000055=GBP/USD110=0279=1269=0270=1.25476271=50000055=GBP/USD110=100000279=1269=0270=1.25476271=100000055=GBP/USD110=500000279=1269=0270=1.25476271=300000055=GBP/USD110=1000000279=1269=0270=1.25476271=500000055=GBP/USD110=300000010=118
20260120-14:06:19.253913000 : 8=FIX.4.49=028035=X49=NTPRO_IDBA_UAT56=SIRIUS_500007460_MD34=167652=20260120-14:06:19.674262=MD_EUR/USD_140109278614268=3279=1269=0270=1.14793271=10000055=EUR/USD110=0279=1269=0270=1.14793271=50000055=EUR/USD110=100000279=1269=0270=1.14793271=100000055=EUR/USD110=50000010=025
20260120-14:06:19.275367000 : 8=FIX.4.49=039835=X49=NTPRO_IDBA_UAT56=SIRIUS_500007460_MD34=167752=20260120-14:06:19.686262=MD_GBP/USD_140109778778268=5279=1269=0270=1.25477271=10000055=GBP/USD110=0279=1269=0270=1.25477271=50000055=GBP/USD110=100000279=1269=0270=1.25477271=100000055=GBP/USD110=500000279=1269=0270=1.25477271=300000055=GBP/USD110=1000000279=1269=0270=1.25477271=500000055=GBP/USD110=300000010=130
20260120-14:06:19.310159000 : 8=FIX.4.49=039835=X49=NTPRO_IDBA_UAT56=SIRIUS_500007460_MD34=167852=20260120-14:06:19.735262=MD_GBP/USD_140109778778268=5279=1269=1270=1.43511271=10000055=GBP/USD110=0279=1269=1270=1.43511271=50000055=GBP/USD110=100000279=1269=1270=1.43511271=100000055=GBP/USD110=500000279=1269=1270=1.43511271=300000055=GBP/USD110=1000000279=1269=1270=1.43511271=500000055=GBP/USD110=300000010=076
20260120-14:06:19.391228000 : 8=FIX.4.49=028035=X49=NTPRO_IDBA_UAT56=SIRIUS_500007460_MD34=167952=20260120-14:06:19.785262=MD_EUR/USD_140109278614268=3279=1269=0270=1.14792271=10000055=EUR/USD110=0279=1269=0270=1.14792271=50000055=EUR/USD110=100000279=1269=0270=1.14792271=100000055=EUR/USD110=50000010=028
20260120-14:06:19.437104000 : 8=FIX.4.49=028035=X49=NTPRO_IDBA_UAT56=SIRIUS_500007460_MD34=168052=20260120-14:06:19.868262=MD_EUR/USD_140109278614268=3279=1269=0270=1.14793271=10000055=EUR/USD110=0279=1269=0270=1.14793271=50000055=EUR/USD110=100000279=1269=0270=1.14793271=100000055=EUR/USD110=50000010=025
20260120-14:06:19.495066000 : 8=FIX.4.49=039835=X49=NTPRO_IDBA_UAT56=SIRIUS_500007460_MD34=168152=20260120-14:06:19.925262=MD_GBP/USD_140109778778268=5279=1269=0270=1.25476271=10000055=GBP/USD110=0279=1269=0270=1.25476271=50000055=GBP/USD110=100000279=1269=0270=1.25476271=100000055=GBP/USD110=500000279=1269=0270=1.25476271=300000055=GBP/USD110=1000000279=1269=0270=1.25476271=500000055=GBP/USD110=300000010=116
20260120-14:06:19.516947000 : 8=FIX.4.49=028035=X49=NTPRO_IDBA_UAT56=SIRIUS_500007460_MD34=168252=20260120-14:06:19.951262=MD_EUR/USD_140109278614268=3279=1269=1270=1.19818271=10000055=EUR/USD110=0279=1269=1270=1.19818271=50000055=EUR/USD110=100000279=1269=1270=1.19818271=100000055=EUR/USD110=50000010=032
20260120-14:06:19.819534000 : 8=FIX.4.49=028035=X49=NTPRO_IDBA_UAT56=SIRIUS_500007460_MD34=168352=20260120-14:06:20.268262=MD_EUR/USD_140109278614268=3279=1269=1270=1.19817271=10000055=EUR/USD110=0279=1269=1270=1.19817271=50000055=EUR/USD110=100000279=1269=1270=1.19817271=100000055=EUR/USD110=50000010=023
20260120-14:06:20.224787000 : 8=FIX.4.49=039835=X49=NTPRO_IDBA_UAT56=SIRIUS_500007460_MD34=168452=20260120-14:06:20.692262=MD_GBP/USD_140109778778268=5279=1269=0270=1.25477271=10000055=GBP/USD110=0279=1269=0270=1.25477271=50000055=GBP/USD110=100000279=1269=0270=1.25477271=100000055=GBP/USD110=500000279=1269=0270=1.25477271=300000055=GBP/USD110=1000000279=1269=0270=1.25477271=500000055=GBP/USD110=300000010=117
20260120-14:06:20.266256000 : 8=FIX.4.49=039335=X49=NTPRO_IDBA_UAT56=SIRIUS_500007460_MD34=168552=20260120-14:06:20.731262=MD_GBP/USD_140109778778268=5279=1269=1270=1.4351271=10000055=GBP/USD110=0279=1269=1270=1.4351271=50000055=GBP/USD110=100000279=1269=1270=1.4351271=100000055=GBP/USD110=500000279=1269=1270=1.4351271=300000055=GBP/USD110=1000000279=1269=1270=1.4351271=500000055=GBP/USD110=300000010=068
20260120-14:06:20.266872000 : 8=FIX.4.49=028035=X49=NTPRO_IDBA_UAT56=SIRIUS_500007460_MD34=168652=20260120-14:06:20.733262=MD_EUR/USD_140109278614268=3279=1269=0270=1.14792271=10000055=EUR/USD110=0279=1269=0270=1.14792271=50000055=EUR/USD110=100000279=1269=0270=1.14792271=100000055=EUR/USD110=50000010=011
20260120-14:06:20.356417000 : 8=FIX.4.49=039835=X49=NTPRO_IDBA_UAT56=SIRIUS_500007460_MD34=168752=20260120-14:06:20.826262=MD_GBP/USD_140109778778268=5279=1269=0270=1.25476271=10000055=GBP/USD110=0279=1269=0270=1.25476271=50000055=GBP/USD110=100000279=1269=0270=1.25476271=100000055=GBP/USD110=500000279=1269=0270=1.25476271=300000055=GBP/USD110=1000000279=1269=0270=1.25476271=500000055=GBP/USD110=300000010=114
20260120-14:06:20.379884000 : 8=FIX.4.49=044435=X49=NTPRO_IDBA_UAT56=SIRIUS_500007460_MD34=168852=20260120-14:06:20.853262=MD_EUR/USD_140109278614268=6279=1269=0270=1.1479271=10000055=EUR/USD110=0279=1269=0270=1.1479271=50000055=EUR/USD110=100000279=1269=0270=1.1479271=100000055=EUR/USD110=500000279=1269=1270=1.19815271=10000055=EUR/USD110=0279=1269=1270=1.19815271=50000055=EUR/USD110=100000279=1269=1270=1.19815271=100000055=EUR/USD110=50000010=174
20260120-14:06:20.400901000 : 8=FIX.4.49=068435=X49=NTPRO_IDBA_UAT56=SIRIUS_500007460_MD34=168952=20260120-14:06:20.876262=MD_GBP/USD_140109778778268=10279=1269=0270=1.25474271=10000055=GBP/USD110=0279=1269=0270=1.25474271=50000055=GBP/USD110=100000279=1269=0270=1.25474271=100000055=GBP/USD110=500000279=1269=0270=1.25474271=300000055=GBP/USD110=1000000279=1269=0270=1.25474271=500000055=GBP/USD110=3000000279=1269=1270=1.43507271=10000055=GBP/USD110=0279=1269=1270=1.43507271=50000055=GBP/USD110=100000279=1269=1270=1.43507271=100000055=GBP/USD110=500000279=1269=1270=1.43507271=300000055=GBP/USD110=1000000279=1269=1270=1.43507271=500000055=GBP/USD110=300000010=008
20260120-14:06:20.446408000 : 8=FIX.4.49=068435=X49=NTPRO_IDBA_UAT56=SIRIUS_500007460_MD34=169052=20260120-14:06:20.916262=MD_GBP/USD_140109778778268=10279=1269=0270=1.25473271=10000055=GBP/USD110=0279=1269=0270=1.25473271=50000055=GBP/USD110=100000279=1269=0270=1.25473271=100000055=GBP/USD110=500000279=1269=0270=1.25473271=300000055=GBP/USD110=1000000279=1269=0270=1.25473271=500000055=GBP/USD110=3000000279=1269=1270=1.43506271=10000055=GBP/USD110=0279=1269=1270=1.43506271=50000055=GBP/USD110=100000279=1269=1270=1.43506271=100000055=GBP/USD110=500000279=1269=1270=1.43506271=300000055=GBP/USD110=1000000279=1269=1270=1.43506271=500000055=GBP/USD110=300000010=241
20260120-14:06:20.463089000 : 8=FIX.4.49=068435=X49=NTPRO_IDBA_UAT56=SIRIUS_500007460_MD34=169152=20260120-14:06:20.940262=MD_GBP/USD_140109778778268=10279=1269=0270=1.25472271=10000055=GBP/USD110=0279=1269=0270=1.25472271=50000055=GBP/USD110=100000279=1269=0270=1.25472271=100000055=GBP/USD110=500000279=1269=0270=1.25472271=300000055=GBP/USD110=1000000279=1269=0270=1.25472271=500000055=GBP/USD110=3000000279=1269=1270=1.43505271=10000055=GBP/USD110=0279=1269=1270=1.43505271=50000055=GBP/USD110=100000279=1269=1270=1.43505271=100000055=GBP/USD110=500000279=1269=1270=1.43505271=300000055=GBP/USD110=1000000279=1269=1270=1.43505271=500000055=GBP/USD110=300000010=229
20260120-14:06:20.469303000 : 8=FIX.4.49=028035=X49=NTPRO_IDBA_UAT56=SIRIUS_500007460_MD34=169252=20260120-14:06:20.948262=MD_EUR/USD_140109278614268=3279=1269=1270=1.19814271=10000055=EUR/USD110=0279=1269=1270=1.19814271=50000055=EUR/USD110=100000279=1269=1270=1.19814271=100000055=EUR/USD110=50000010=019
20260120-14:06:20.493834000 : 8=FIX.4.49=039835=X49=NTPRO_IDBA_UAT56=SIRIUS_500007460_MD34=169352=20260120-14:06:20.971262=MD_GBP/USD_140109778778268=5279=1269=1270=1.43504271=10000055=GBP/USD110=0279=1269=1270=1.43504271=50000055=GBP/USD110=100000279=1269=1270=1.43504271=100000055=GBP/USD110=500000279=1269=1270=1.43504271=300000055=GBP/USD110=1000000279=1269=1270=1.43504271=500000055=GBP/USD110=300000010=077
20260120-14:06:20.525398000 : 8=FIX.4.49=039835=X49=NTPRO_IDBA_UAT56=SIRIUS_500007460_MD34=169452=20260120-14:06:21.006262=MD_GBP/USD_140109778778268=5279=1269=0270=1.25469271=10000055=GBP/USD110=0279=1269=0270=1.25469271=50000055=GBP/USD110=100000279=1269=0270=1.25469271=100000055=GBP/USD110=500000279=1269=0270=1.25469271=300000055=GBP/USD110=1000000279=1269=0270=1.25469271=500000055=GBP/USD110=300000010=113
20260120-14:06:20.557100000 : 8=FIX.4.49=039335=X49=NTPRO_IDBA_UAT56=SIRIUS_500007460_MD34=169552=20260120-14:06:21.039262=MD_GBP/USD_140109778778268=5279=1269=0270=1.2547271=10000055=GBP/USD110=0279=1269=0270=1.2547271=50000055=GBP/USD110=100000279=1269=0270=1.2547271=100000055=GBP/USD110=500000279=1269=0270=1.2547271=300000055=GBP/USD110=1000000279=1269=0270=1.2547271=500000055=GBP/USD110=300000010=091
20260120-14:06:20.590601000 : 8=FIX.4.49=039835=X49=NTPRO_IDBA_UAT56=SIRIUS_500007460_MD34=169652=20260120-14:06:21.074262=MD_GBP/USD_140109778778268=5279=1269=1270=1.43503271=10000055=GBP/USD110=0279=1269=1270=1.43503271=50000055=GBP/USD110=100000279=1269=1270=1.43503271=100000055=GBP/USD110=500000279=1269=1270=1.43503271=300000055=GBP/USD110=1000000279=1269=1270=1.43503271=500000055=GBP/USD110=300000010=070
20260120-14:06:20.648304000 : 8=FIX.4.49=028035=X49=NTPRO_IDBA_UAT56=SIRIUS_500007460_MD34=169752=20260120-14:06:21.134262=MD_EUR/USD_140109278614268=3279=1269=1270=1.19815271=10000055=EUR/USD110=0279=1269=1270=1.19815271=50000055=EUR/USD110=100000279=1269=1270=1.19815271=100000055=EUR/USD110=50000010=015
20260120-14:06:20.867491000 : 8=FIX.4.49=039835=X49=NTPRO_IDBA_UAT56=SIRIUS_500007460_MD34=169852=20260120-14:06:21.364262=MD_GBP/USD_140109778778268=5279=1269=0270=1.25469271=10000055=GBP/USD110=0279=1269=0270=1.25469271=50000055=GBP/USD110=100000279=1269=0270=1.25469271=100000055=GBP/USD110=500000279=1269=0270=1.25469271=300000055=GBP/USD110=1000000279=1269=0270=1.25469271=500000055=GBP/USD110=300000010=124
20260120-14:06:20.895461000 : 8=FIX.4.49=039335=X49=NTPRO_IDBA_UAT56=SIRIUS_500007460_MD34=169952=20260120-14:06:21.393262=MD_GBP/USD_140109778778268=5279=1269=0270=1.2547271=10000055=GBP/USD110=0279=1269=0270=1.2547271=50000055=GBP/USD110=100000279=1269=0270=1.2547271=100000055=GBP/USD110=500000279=1269=0270=1.2547271=300000055=GBP/USD110=1000000279=1269=0270=1.2547271=500000055=GBP/USD110=300000010=098
20260120-14:06:21.017827000 : 8=FIX.4.49=028035=X49=NTPRO_IDBA_UAT56=SIRIUS_500007460_MD34=170052=20260120-14:06:21.521262=MD_EUR/USD_140109278614268=3279=1269=1270=1.19814271=10000055=EUR/USD110=0279=1269=1270=1.19814271=50000055=EUR/USD110=100000279=1269=1270=1.19814271=100000055=EUR/USD110=50000010=253
20260120-14:06:21.880374000 : 8=FIX.4.49=039835=X49=NTPRO_IDBA_UAT56=SIRIUS_500007460_MD34=170152=20260120-14:06:22.423262=MD_GBP/USD_140109778778268=5279=1269=1270=1.43504271=10000055=GBP/USD110=0279=1269=1270=1.43504271=50000055=GBP/USD110=100000279=1269=1270=1.43504271=100000055=GBP/USD110=500000279=1269=1270=1.43504271=300000055=GBP/USD110=1000000279=1269=1270=1.43504271=500000055=GBP/USD110=300000010=061
20260120-14:06:22.167779000 : 8=FIX.4.49=039835=X49=NTPRO_IDBA_UAT56=SIRIUS_500007460_MD34=170252=20260120-14:06:22.713262=MD_GBP/USD_140109778778268=5279=1269=0270=1.25471271=10000055=GBP/USD110=0279=1269=0270=1.25471271=50000055=GBP/USD110=100000279=1269=0270=1.25471271=100000055=GBP/USD110=500000279=1269=0270=1.25471271=300000055=GBP/USD110=1000000279=1269=0270=1.25471271=500000055=GBP/USD110=300000010=074
20260120-14:06:22.275755000 : 8=FIX.4.49=044735=X49=NTPRO_IDBA_UAT56=SIRIUS_500007460_MD34=170352=20260120-14:06:22.757262=MD_EUR/USD_140109278614268=6279=1269=0270=1.14791271=10000055=EUR/USD110=0279=1269=0270=1.14791271=50000055=EUR/USD110=100000279=1269=0270=1.14791271=100000055=EUR/USD110=500000279=1269=1270=1.19815271=10000055=EUR/USD110=0279=1269=1270=1.19815271=50000055=EUR/USD110=100000279=1269=1270=1.19815271=100000055=EUR/USD110=50000010=061
20260120-14:06:22.276104000 : 8=FIX.4.49=039835=X49=NTPRO_IDBA_UAT56=SIRIUS_500007460_MD34=170452=20260120-14:06:22.768262=MD_GBP/USD_140109778778268=5279=1269=0270=1.25473271=10000055=GBP/USD110=0279=1269=0270=1.25473271=50000055=GBP/USD110=100000279=1269=0270=1.25473271=100000055=GBP/USD110=500000279=1269=0270=1.25473271=300000055=GBP/USD110=1000000279=1269=0270=1.25473271=500000055=GBP/USD110=300000010=096
20260120-14:06:22.276578000 : 8=FIX.4.49=068435=X49=NTPRO_IDBA_UAT56=SIRIUS_500007460_MD34=170552=20260120-14:06:22.829262=MD_GBP/USD_140109778778268=10279=1269=0270=1.25474271=10000055=GBP/USD110=0279=1269=0270=1.25474271=50000055=GBP/USD110=100000279=1269=0270=1.25474271=100000055=GBP/USD110=500000279=1269=0270=1.25474271=300000055=GBP/USD110=1000000279=1269=0270=1.25474271=500000055=GBP/USD110=3000000279=1269=1270=1.43507271=10000055=GBP/USD110=0279=1269=1270=1.43507271=50000055=GBP/USD110=100000279=1269=1270=1.43507271=100000055=GBP/USD110=500000279=1269=1270=1.43507271=300000055=GBP/USD110=1000000279=1269=1270=1.43507271=500000055=GBP/USD110=300000010=253
20260120-14:06:22.276816000 : 8=FIX.4.49=027735=X49=NTPRO_IDBA_UAT56=SIRIUS_500007460_MD34=170652=20260120-14:06:22.837262=MD_EUR/USD_140109278614268=3279=1269=0270=1.1479271=10000055=EUR/USD110=0279=1269=0270=1.1479271=50000055=EUR/USD110=100000279=1269=0270=1.1479271=100000055=EUR/USD110=50000010=123
20260120-14:06:22.373818000 : 8=FIX.4.49=039835=X49=NTPRO_IDBA_UAT56=SIRIUS_500007460_MD34=170752=20260120-14:06:22.904262=MD_GBP/USD_140109778778268=5279=1269=1270=1.43508271=10000055=GBP/USD110=0279=1269=1270=1.43508271=50000055=GBP/USD110=100000279=1269=1270=1.43508271=100000055=GBP/USD110=500000279=1269=1270=1.43508271=300000055=GBP/USD110=1000000279=1269=1270=1.43508271=500000055=GBP/USD110=300000010=091
20260120-14:06:22.465754000 : 8=FIX.4.49=039835=X49=NTPRO_IDBA_UAT56=SIRIUS_500007460_MD34=170852=20260120-14:06:22.982262=MD_GBP/USD_140109778778268=5279=1269=0270=1.25475271=10000055=GBP/USD110=0279=1269=0270=1.25475271=50000055=GBP/USD110=100000279=1269=0270=1.25475271=100000055=GBP/USD110=500000279=1269=0270=1.25475271=300000055=GBP/USD110=1000000279=1269=0270=1.25475271=500000055=GBP/USD110=300000010=108
20260120-14:06:22.466672000 : 8=FIX.4.49=028035=X49=NTPRO_IDBA_UAT56=SIRIUS_500007460_MD34=170952=20260120-14:06:23.025262=MD_EUR/USD_140109278614268=3279=1269=0270=1.14791271=10000055=EUR/USD110=0279=1269=0270=1.14791271=50000055=EUR/USD110=100000279=1269=0270=1.14791271=100000055=EUR/USD110=50000010=001
20260120-14:06:22.467646000 : 8=FIX.4.49=039835=X49=NTPRO_IDBA_UAT56=SIRIUS_500007460_MD34=171052=20260120-14:06:23.038262=MD_GBP/USD_140109778778268=5279=1269=0270=1.25476271=10000055=GBP/USD110=0279=1269=0270=1.25476271=50000055=GBP/USD110=100000279=1269=0270=1.25476271=100000055=GBP/USD110=500000279=1269=0270=1.25476271=300000055=GBP/USD110=1000000279=1269=0270=1.25476271=500000055=GBP/USD110=300000010=099
20260120-14:06:22.551254000 : 8=FIX.4.49=039835=X49=NTPRO_IDBA_UAT56=SIRIUS_500007460_MD34=171152=20260120-14:06:23.107262=MD_GBP/USD_140109778778268=5279=1269=0270=1.25475271=10000055=GBP/USD110=0279=1269=0270=1.25475271=50000055=GBP/USD110=100000279=1269=0270=1.25475271=100000055=GBP/USD110=500000279=1269=0270=1.25475271=300000055=GBP/USD110=1000000279=1269=0270=1.25475271=500000055=GBP/USD110=300000010=092
20260120-14:06:22.563622000 : 8=FIX.4.49=039835=X49=NTPRO_IDBA_UAT56=SIRIUS_500007460_MD34=171252=20260120-14:06:23.139262=MD_GBP/USD_140109778778268=5279=1269=1270=1.43509271=10000055=GBP/USD110=0279=1269=1270=1.43509271=50000055=GBP/USD110=100000279=1269=1270=1.43509271=100000055=GBP/USD110=500000279=1269=1270=1.43509271=300000055=GBP/USD110=1000000279=1269=1270=1.43509271=500000055=GBP/USD110=300000010=093
20260120-14:06:22.649970000 : 8=FIX.4.49=039835=X49=NTPRO_IDBA_UAT56=SIRIUS_500007460_MD34=171352=20260120-14:06:23.163262=MD_GBP/USD_140109778778268=5279=1269=0270=1.25476271=10000055=GBP/USD110=0279=1269=0270=1.25476271=50000055=GBP/USD110=100000279=1269=0270=1.25476271=100000055=GBP/USD110=500000279=1269=0270=1.25476271=300000055=GBP/USD110=1000000279=1269=0270=1.25476271=500000055=GBP/USD110=300000010=101
20260120-14:06:23.051261000 : 8=FIX.4.49=039335=X49=NTPRO_IDBA_UAT56=SIRIUS_500007460_MD34=171452=20260120-14:06:23.573262=MD_GBP/USD_140109778778268=5279=1269=1270=1.4351271=10000055=GBP/USD110=0279=1269=1270=1.4351271=50000055=GBP/USD110=100000279=1269=1270=1.4351271=100000055=GBP/USD110=500000279=1269=1270=1.4351271=300000055=GBP/USD110=1000000279=1269=1270=1.4351271=500000055=GBP/USD110=300000010=068
20260120-14:06:23.440148000 : 8=FIX.4.49=028035=X49=NTPRO_IDBA_UAT56=SIRIUS_500007460_MD34=171552=20260120-14:06:24.049262=MD_EUR/USD_140109278614268=3279=1269=1270=1.19816271=10000055=EUR/USD110=0279=1269=1270=1.19816271=50000055=EUR/USD110=100000279=1269=1270=1.19816271=100000055=EUR/USD110=50000010=017
20260120-14:06:23.531745000 : 8=FIX.4.49=044735=X49=NTPRO_IDBA_UAT56=SIRIUS_500007460_MD34=171652=20260120-14:06:24.137262=MD_EUR/USD_140109278614268=6279=1269=0270=1.14792271=10000055=EUR/USD110=0279=1269=0270=1.14792271=50000055=EUR/USD110=100000279=1269=0270=1.14792271=100000055=EUR/USD110=500000279=1269=1270=1.19817271=10000055=EUR/USD110=0279=1269=1270=1.19817271=50000055=EUR/USD110=100000279=1269=1270=1.19817271=100000055=EUR/USD110=50000010=068
20260120-14:06:24.135111000 : 8=FIX.4.49=028035=X49=NTPRO_IDBA_UAT56=SIRIUS_500007460_MD34=171752=20260120-14:06:24.730262=MD_EUR/USD_140109278614268=3279=1269=1270=1.19816271=10000055=EUR/USD110=0279=1269=1270=1.19816271=50000055=EUR/USD110=100000279=1269=1270=1.19816271=100000055=EUR/USD110=50000010=016
20260120-14:06:24.135881000 : 8=FIX.4.49=039835=X49=NTPRO_IDBA_UAT56=SIRIUS_500007460_MD34=171852=20260120-14:06:24.746262=MD_GBP/USD_140109778778268=5279=1269=1270=1.43509271=10000055=GBP/USD110=0279=1269=1270=1.43509271=50000055=GBP/USD110=100000279=1269=1270=1.43509271=100000055=GBP/USD110=500000279=1269=1270=1.43509271=300000055=GBP/USD110=1000000279=1269=1270=1.43509271=500000055=GBP/USD110=300000010=104
20260120-14:06:24.136283000 : 8=FIX.4.49=039835=X49=NTPRO_IDBA_UAT56=SIRIUS_500007460_MD34=171952=20260120-14:06:24.776262=MD_GBP/USD_140109778778268=5279=1269=1270=1.43508271=10000055=GBP/USD110=0279=1269=1270=1.43508271=50000055=GBP/USD110=100000279=1269=1270=1.43508271=100000055=GBP/USD110=500000279=1269=1270=1.43508271=300000055=GBP/USD110=1000000279=1269=1270=1.43508271=500000055=GBP/USD110=300000010=103
20260120-14:06:24.227690000 : 8=FIX.4.49=028035=X49=NTPRO_IDBA_UAT56=SIRIUS_500007460_MD34=172052=20260120-14:06:24.808262=MD_EUR/USD_140109278614268=3279=1269=0270=1.14791271=10000055=EUR/USD110=0279=1269=0270=1.14791271=50000055=EUR/USD110=100000279=1269=0270=1.14791271=100000055=EUR/USD110=50000010=004
20260120-14:06:24.228535000 : 8=FIX.4.49=067935=X49=NTPRO_IDBA_UAT56=SIRIUS_500007460_MD34=172152=20260120-14:06:24.832262=MD_GBP/USD_140109778778268=10279=1269=0270=1.2547271=10000055=GBP/USD110=0279=1269=0270=1.2547271=50000055=GBP/USD110=100000279=1269=0270=1.2547271=100000055=GBP/USD110=500000279=1269=0270=1.2547271=300000055=GBP/USD110=1000000279=1269=0270=1.2547271=500000055=GBP/USD110=3000000279=1269=1270=1.43502271=10000055=GBP/USD110=0279=1269=1270=1.43502271=50000055=GBP/USD110=100000279=1269=1270=1.43502271=100000055=GBP/USD110=500000279=1269=1270=1.43502271=300000055=GBP/USD110=1000000279=1269=1270=1.43502271=500000055=GBP/USD110=300000010=222
20260120-14:06:24.229473000 : 8=FIX.4.49=044735=X49=NTPRO_IDBA_UAT56=SIRIUS_500007460_MD34=172252=20260120-14:06:24.873262=MD_EUR/USD_140109278614268=6279=1269=0270=1.14789271=10000055=EUR/USD110=0279=1269=0270=1.14789271=50000055=EUR/USD110=100000279=1269=0270=1.14789271=100000055=EUR/USD110=500000279=1269=1270=1.19814271=10000055=EUR/USD110=0279=1269=1270=1.19814271=50000055=EUR/USD110=100000279=1269=1270=1.19814271=100000055=EUR/USD110=50000010=081
20260120-14:06:24.333036000 : 8=FIX.4.49=068435=X49=NTPRO_IDBA_UAT56=SIRIUS_500007460_MD34=172352=20260120-14:06:24.917262=MD_GBP/USD_140109778778268=10279=1269=0270=1.25467271=10000055=GBP/USD110=0279=1269=0270=1.25467271=50000055=GBP/USD110=100000279=1269=0270=1.25467271=100000055=GBP/USD110=500000279=1269=0270=1.25467271=300000055=GBP/USD110=1000000279=1269=0270=1.25467271=500000055=GBP/USD110=3000000279=1269=1270=1.43501271=10000055=GBP/USD110=0279=1269=1270=1.43501271=50000055=GBP/USD110=100000279=1269=1270=1.43501271=100000055=GBP/USD110=500000279=1269=1270=1.43501271=300000055=GBP/USD110=1000000279=1269=1270=1.43501271=500000055=GBP/USD110=300000010=233
20260120-14:06:24.426958000 : 8=FIX.4.49=044735=X49=NTPRO_IDBA_UAT56=SIRIUS_500007460_MD34=172452=20260120-14:06:25.009262=MD_EUR/USD_140109278614268=6279=1269=0270=1.14787271=10000055=EUR/USD110=0279=1269=0270=1.14787271=50000055=EUR/USD110=100000279=1269=0270=1.14787271=100000055=EUR/USD110=500000279=1269=1270=1.19812271=10000055=EUR/USD110=0279=1269=1270=1.19812271=50000055=EUR/USD110=100000279=1269=1270=1.19812271=100000055=EUR/USD110=50000010=063
20260120-14:06:24.427933000 : 8=FIX.4.49=039835=X49=NTPRO_IDBA_UAT56=SIRIUS_500007460_MD34=172552=20260120-14:06:25.039262=MD_GBP/USD_140109778778268=5279=1269=0270=1.25469271=10000055=GBP/USD110=0279=1269=0270=1.25469271=50000055=GBP/USD110=100000279=1269=0270=1.25469271=100000055=GBP/USD110=500000279=1269=0270=1.25469271=300000055=GBP/USD110=1000000279=1269=0270=1.25469271=500000055=GBP/USD110=300000010=118
20260120-14:06:24.520385000 : 8=FIX.4.49=044435=X49=NTPRO_IDBA_UAT56=SIRIUS_500007460_MD34=172652=20260120-14:06:25.102262=MD_EUR/USD_140109278614268=6279=1269=0270=1.1479271=10000055=EUR/USD110=0279=1269=0270=1.1479271=50000055=EUR/USD110=100000279=1269=0270=1.1479271=100000055=EUR/USD110=500000279=1269=1270=1.19814271=10000055=EUR/USD110=0279=1269=1270=1.19814271=50000055=EUR/USD110=100000279=1269=1270=1.19814271=100000055=EUR/USD110=50000010=156
20260120-14:06:24.521052000 : 8=FIX.4.49=039835=X49=NTPRO_IDBA_UAT56=SIRIUS_500007460_MD34=172752=20260120-14:06:25.108262=MD_GBP/USD_140109778778268=5279=1269=1270=1.43502271=10000055=GBP/USD110=0279=1269=1270=1.43502271=50000055=GBP/USD110=100000279=1269=1270=1.43502271=100000055=GBP/USD110=500000279=1269=1270=1.43502271=300000055=GBP/USD110=1000000279=1269=1270=1.43502271=500000055=GBP/USD110=300000010=062
20260120-14:06:24.720766000 : 8=FIX.4.49=039835=X49=NTPRO_IDBA_UAT56=SIRIUS_500007460_MD34=172852=20260120-14:06:25.303262=MD_GBP/USD_140109778778268=5279=1269=0270=1.25468271=10000055=GBP/USD110=0279=1269=0270=1.25468271=50000055=GBP/USD110=100000279=1269=0270=1.25468271=100000055=GBP/USD110=500000279=1269=0270=1.25468271=300000055=GBP/USD110=1000000279=1269=0270=1.25468271=500000055=GBP/USD110=300000010=110
20260120-14:06:24.721594000 : 8=FIX.4.49=039835=X49=NTPRO_IDBA_UAT56=SIRIUS_500007460_MD34=172952=20260120-14:06:25.337262=MD_GBP/USD_140109778778268=5279=1269=1270=1.43503271=10000055=GBP/USD110=0279=1269=1270=1.43503271=50000055=GBP/USD110=100000279=1269=1270=1.43503271=100000055=GBP/USD110=500000279=1269=1270=1.43503271=300000055=GBP/USD110=1000000279=1269=1270=1.43503271=500000055=GBP/USD110=300000010=073
20260120-14:06:24.722287000 : 8=FIX.4.49=039835=X49=NTPRO_IDBA_UAT56=SIRIUS_500007460_MD34=173052=20260120-14:06:25.363262=MD_GBP/USD_140109778778268=5279=1269=0270=1.25469271=10000055=GBP/USD110=0279=1269=0270=1.25469271=50000055=GBP/USD110=100000279=1269=0270=1.25469271=100000055=GBP/USD110=500000279=1269=0270=1.25469271=300000055=GBP/USD110=1000000279=1269=0270=1.25469271=500000055=GBP/USD110=300000010=114
20260120-14:06:24.722660000 : 8=FIX.4.49=039835=X49=NTPRO_IDBA_UAT56=SIRIUS_500007460_MD34=173152=20260120-14:06:25.388262=MD_GBP/USD_140109778778268=5279=1269=0270=1.25468271=10000055=GBP/USD110=0279=1269=0270=1.25468271=50000055=GBP/USD110=100000279=1269=0270=1.25468271=100000055=GBP/USD110=500000279=1269=0270=1.25468271=300000055=GBP/USD110=1000000279=1269=0270=1.25468271=500000055=GBP/USD110=300000010=117
20260120-14:06:24.806190000 : 8=FIX.4.49=044735=X49=NTPRO_IDBA_UAT56=SIRIUS_500007460_MD34=173252=20260120-14:06:25.448262=MD_EUR/USD_140109278614268=6279=1269=0270=1.14789271=10000055=EUR/USD110=0279=1269=0270=1.14789271=50000055=EUR/USD110=100000279=1269=0270=1.14789271=100000055=EUR/USD110=500000279=1269=1270=1.19813271=10000055=EUR/USD110=0279=1269=1270=1.19813271=50000055=EUR/USD110=100000279=1269=1270=1.19813271=100000055=EUR/USD110=50000010=078
20260120-14:06:24.907394000 : 8=FIX.4.49=039835=X49=NTPRO_IDBA_UAT56=SIRIUS_500007460_MD34=173352=20260120-14:06:25.509262=MD_GBP/USD_140109778778268=5279=1269=1270=1.43502271=10000055=GBP/USD110=0279=1269=1270=1.43502271=50000055=GBP/USD110=100000279=1269=1270=1.43502271=100000055=GBP/USD110=500000279=1269=1270=1.43502271=300000055=GBP/USD110=1000000279=1269=1270=1.43502271=500000055=GBP/USD110=300000010=064
20260120-14:06:24.909006000 : 8=FIX.4.49=044735=X49=NTPRO_IDBA_UAT56=SIRIUS_500007460_MD34=173452=20260120-14:06:25.539262=MD_EUR/USD_140109278614268=6279=1269=0270=1.14787271=10000055=EUR/USD110=0279=1269=0270=1.14787271=50000055=EUR/USD110=100000279=1269=0270=1.14787271=100000055=EUR/USD110=500000279=1269=1270=1.19812271=10000055=EUR/USD110=0279=1269=1270=1.19812271=50000055=EUR/USD110=100000279=1269=1270=1.19812271=100000055=EUR/USD110=50000010=072
20260120-14:06:24.910516000 : 8=FIX.4.49=067435=X49=NTPRO_IDBA_UAT56=SIRIUS_500007460_MD34=173552=20260120-14:06:25.561262=MD_GBP/USD_140109778778268=10279=1269=0270=1.25465271=10000055=GBP/USD110=0279=1269=0270=1.25465271=50000055=GBP/USD110=100000279=1269=0270=1.25465271=100000055=GBP/USD110=500000279=1269=0270=1.25465271=300000055=GBP/USD110=1000000279=1269=0270=1.25465271=500000055=GBP/USD110=3000000279=1269=1270=1.435271=10000055=GBP/USD110=0279=1269=1270=1.435271=50000055=GBP/USD110=100000279=1269=1270=1.435271=100000055=GBP/USD110=500000279=1269=1270=1.435271=300000055=GBP/USD110=1000000279=1269=1270=1.435271=500000055=GBP/USD110=300000010=248
20260120-14:06:24.916156000 : 8=FIX.4.49=044735=X49=NTPRO_IDBA_UAT56=SIRIUS_500007460_MD34=173652=20260120-14:06:25.600262=MD_EUR/USD_140109278614268=6279=1269=0270=1.14784271=10000055=EUR/USD110=0279=1269=0270=1.14784271=50000055=EUR/USD110=100000279=1269=0270=1.14784271=100000055=EUR/USD110=500000279=1269=1270=1.19809271=10000055=EUR/USD110=0279=1269=1270=1.19809271=50000055=EUR/USD110=100000279=1269=1270=1.19809271=100000055=EUR/USD110=50000010=072
20260120-14:06:25.009552000 : 8=FIX.4.49=068435=X49=NTPRO_IDBA_UAT56=SIRIUS_500007460_MD34=173752=20260120-14:06:25.613262=MD_GBP/USD_140109778778268=10279=1269=0270=1.25464271=10000055=GBP/USD110=0279=1269=0270=1.25464271=50000055=GBP/USD110=100000279=1269=0270=1.25464271=100000055=GBP/USD110=500000279=1269=0270=1.25464271=300000055=GBP/USD110=1000000279=1269=0270=1.25464271=500000055=GBP/USD110=3000000279=1269=1270=1.43499271=10000055=GBP/USD110=0279=1269=1270=1.43499271=50000055=GBP/USD110=100000279=1269=1270=1.43499271=100000055=GBP/USD110=500000279=1269=1270=1.43499271=300000055=GBP/USD110=1000000279=1269=1270=1.43499271=500000055=GBP/USD110=300000010=041
20260120-14:06:25.108727000 : 8=FIX.4.49=028035=X49=NTPRO_IDBA_UAT56=SIRIUS_500007460_MD34=173852=20260120-14:06:25.734262=MD_EUR/USD_140109278614268=3279=1269=0270=1.14785271=10000055=EUR/USD110=0279=1269=0270=1.14785271=50000055=EUR/USD110=100000279=1269=0270=1.14785271=100000055=EUR/USD110=50000010=021
20260120-14:06:25.109336000 : 8=FIX.4.49=039835=X49=NTPRO_IDBA_UAT56=SIRIUS_500007460_MD34=173952=20260120-14:06:25.741262=MD_GBP/USD_140109778778268=5279=1269=0270=1.25465271=10000055=GBP/USD110=0279=1269=0270=1.25465271=50000055=GBP/USD110=100000279=1269=0270=1.25465271=100000055=GBP/USD110=500000279=1269=0270=1.25465271=300000055=GBP/USD110=1000000279=1269=0270=1.25465271=500000055=GBP/USD110=300000010=103
20260120-14:06:25.206168000 : 8=FIX.4.49=028035=X49=NTPRO_IDBA_UAT56=SIRIUS_500007460_MD34=174052=20260120-14:06:25.807262=MD_EUR/USD_140109278614268=3279=1269=0270=1.14784271=10000055=EUR/USD110=0279=1269=0270=1.14784271=50000055=EUR/USD110=100000279=1269=0270=1.14784271=100000055=EUR/USD110=50000010=012
20260120-14:06:25.213254000 : 8=FIX.4.49=039835=X49=NTPRO_IDBA_UAT56=SIRIUS_500007460_MD34=174152=20260120-14:06:25.880262=MD_GBP/USD_140109778778268=5279=1269=0270=1.25464271=10000055=GBP/USD110=0279=1269=0270=1.25464271=50000055=GBP/USD110=100000279=1269=0270=1.25464271=100000055=GBP/USD110=500000279=1269=0270=1.25464271=300000055=GBP/USD110=1000000279=1269=0270=1.25464271=500000055=GBP/USD110=300000010=095
20260120-14:06:25.303410000 : 8=FIX.4.49=039835=X49=NTPRO_IDBA_UAT56=SIRIUS_500007460_MD34=174252=20260120-14:06:25.926262=MD_GBP/USD_140109778778268=5279=1269=0270=1.25465271=10000055=GBP/USD110=0279=1269=0270=1.25465271=50000055=GBP/USD110=100000279=1269=0270=1.25465271=100000055=GBP/USD110=500000279=1269=0270=1.25465271=300000055=GBP/USD110=1000000279=1269=0270=1.25465271=500000055=GBP/USD110=300000010=102
20260120-14:06:25.304129000 : 8=FIX.4.49=039835=X49=NTPRO_IDBA_UAT56=SIRIUS_500007460_MD34=174352=20260120-14:06:25.968262=MD_GBP/USD_140109778778268=5279=1269=0270=1.25464271=10000055=GBP/USD110=0279=1269=0270=1.25464271=50000055=GBP/USD110=100000279=1269=0270=1.25464271=100000055=GBP/USD110=500000279=1269=0270=1.25464271=300000055=GBP/USD110=1000000279=1269=0270=1.25464271=500000055=GBP/USD110=300000010=104
20260120-14:06:25.304768000 : 8=FIX.4.49=028035=X49=NTPRO_IDBA_UAT56=SIRIUS_500007460_MD34=174452=20260120-14:06:25.984262=MD_EUR/USD_140109278614268=3279=1269=1270=1.19808271=10000055=EUR/USD110=0279=1269=1270=1.19808271=50000055=EUR/USD110=100000279=1269=1270=1.19808271=100000055=EUR/USD110=50000010=031
20260120-14:06:25.395095000 : 8=FIX.4.49=039835=X49=NTPRO_IDBA_UAT56=SIRIUS_500007460_MD34=174552=20260120-14:06:26.049262=MD_GBP/USD_140109778778268=5279=1269=1270=1.43498271=10000055=GBP/USD110=0279=1269=1270=1.43498271=50000055=GBP/USD110=100000279=1269=1270=1.43498271=100000055=GBP/USD110=500000279=1269=1270=1.43498271=300000055=GBP/USD110=1000000279=1269=1270=1.43498271=500000055=GBP/USD110=300000010=137
20260120-14:06:25.400647000 : 8=FIX.4.49=028035=X49=NTPRO_IDBA_UAT56=SIRIUS_500007460_MD34=174652=20260120-14:06:26.105262=MD_EUR/USD_140109278614268=3279=1269=1270=1.19809271=10000055=EUR/USD110=0279=1269=1270=1.19809271=50000055=EUR/USD110=100000279=1269=1270=1.19809271=100000055=EUR/USD110=50000010=022
20260120-14:06:25.491834000 : 8=FIX.4.49=039835=X49=NTPRO_IDBA_UAT56=SIRIUS_500007460_MD34=174752=20260120-14:06:26.133262=MD_GBP/USD_140109778778268=5279=1269=0270=1.25463271=10000055=GBP/USD110=0279=1269=0270=1.25463271=50000055=GBP/USD110=100000279=1269=0270=1.25463271=100000055=GBP/USD110=500000279=1269=0270=1.25463271=300000055=GBP/USD110=1000000279=1269=0270=1.25463271=500000055=GBP/USD110=300000010=088
20260120-14:06:25.606197000 : 8=FIX.4.49=039835=X49=NTPRO_IDBA_UAT56=SIRIUS_500007460_MD34=174852=20260120-14:06:26.276262=MD_GBP/USD_140109778778268=5279=1269=1270=1.43497271=10000055=GBP/USD110=0279=1269=1270=1.43497271=50000055=GBP/USD110=100000279=1269=1270=1.43497271=100000055=GBP/USD110=500000279=1269=1270=1.43497271=300000055=GBP/USD110=1000000279=1269=1270=1.43497271=500000055=GBP/USD110=300000010=137
20260120-14:06:25.698127000 : 8=FIX.4.49=028035=X49=NTPRO_IDBA_UAT56=SIRIUS_500007460_MD34=174952=20260120-14:06:26.338262=MD_EUR/USD_140109278614268=3279=1269=1270=1.19808271=10000055=EUR/USD110=0279=1269=1270=1.19808271=50000055=EUR/USD110=100000279=1269=1270=1.19808271=100000055=EUR/USD110=50000010=030
20260120-14:06:25.698794000 : 8=FIX.4.49=039835=X49=NTPRO_IDBA_UAT56=SIRIUS_500007460_MD34=175052=20260120-14:06:26.356262=MD_GBP/USD_140109778778268=5279=1269=0270=1.25462271=10000055=GBP/USD110=0279=1269=0270=1.25462271=50000055=GBP/USD110=100000279=1269=0270=1.25462271=100000055=GBP/USD110=500000279=1269=0270=1.25462271=300000055=GBP/USD110=1000000279=1269=0270=1.25462271=500000055=GBP/USD110=300000010=084
20260120-14:06:25.797952000 : 8=FIX.4.49=028035=X49=NTPRO_IDBA_UAT56=SIRIUS_500007460_MD34=175152=20260120-14:06:26.501262=MD_EUR/USD_140109278614268=3279=1269=1270=1.19809271=10000055=EUR/USD110=0279=1269=1270=1.19809271=50000055=EUR/USD110=100000279=1269=1270=1.19809271=100000055=EUR/USD110=50000010=018
20260120-14:06:25.884044000 : 8=FIX.4.49=039835=X49=NTPRO_IDBA_UAT56=SIRIUS_500007460_MD34=175252=20260120-14:06:26.570262=MD_GBP/USD_140109778778268=5279=1269=0270=1.25461271=10000055=GBP/USD110=0279=1269=0270=1.25461271=50000055=GBP/USD110=100000279=1269=0270=1.25461271=100000055=GBP/USD110=500000279=1269=0270=1.25461271=300000055=GBP/USD110=1000000279=1269=0270=1.25461271=500000055=GBP/USD110=300000010=079
20260120-14:06:25.884829000 : 8=FIX.4.49=044735=X49=NTPRO_IDBA_UAT56=SIRIUS_500007460_MD34=175352=20260120-14:06:26.612262=MD_EUR/USD_140109278614268=6279=1269=0270=1.14782271=10000055=EUR/USD110=0279=1269=0270=1.14782271=50000055=EUR/USD110=100000279=1269=0270=1.14782271=100000055=EUR/USD110=500000279=1269=1270=1.19808271=10000055=EUR/USD110=0279=1269=1270=1.19808271=50000055=EUR/USD110=100000279=1269=1270=1.19808271=100000055=EUR/USD110=50000010=066
20260120-14:06:25.987720000 : 8=FIX.4.49=039835=X49=NTPRO_IDBA_UAT56=SIRIUS_500007460_MD34=175452=20260120-14:06:26.642262=MD_GBP/USD_140109778778268=5279=1269=0270=1.25462271=10000055=GBP/USD110=0279=1269=0270=1.25462271=50000055=GBP/USD110=100000279=1269=0270=1.25462271=100000055=GBP/USD110=500000279=1269=0270=1.25462271=300000055=GBP/USD110=1000000279=1269=0270=1.25462271=500000055=GBP/USD110=300000010=086
20260120-14:06:25.988425000 : 8=FIX.4.49=028035=X49=NTPRO_IDBA_UAT56=SIRIUS_500007460_MD34=175552=20260120-14:06:26.665262=MD_EUR/USD_140109278614268=3279=1269=1270=1.19806271=10000055=EUR/USD110=0279=1269=1270=1.19806271=50000055=EUR/USD110=100000279=1269=1270=1.19806271=100000055=EUR/USD110=50000010=024
20260120-14:06:26.186333000 : 8=FIX.4.49=068435=X49=NTPRO_IDBA_UAT56=SIRIUS_500007460_MD34=175652=20260120-14:06:26.928262=MD_GBP/USD_140109778778268=10279=1269=0270=1.25461271=10000055=GBP/USD110=0279=1269=0270=1.25461271=50000055=GBP/USD110=100000279=1269=0270=1.25461271=100000055=GBP/USD110=500000279=1269=0270=1.25461271=300000055=GBP/USD110=1000000279=1269=0270=1.25461271=500000055=GBP/USD110=3000000279=1269=1270=1.43496271=10000055=GBP/USD110=0279=1269=1270=1.43496271=50000055=GBP/USD110=100000279=1269=1270=1.43496271=100000055=GBP/USD110=500000279=1269=1270=1.43496271=300000055=GBP/USD110=1000000279=1269=1270=1.43496271=500000055=GBP/USD110=300000010=022
20260120-14:06:26.284796000 : 8=FIX.4.49=039335=X49=NTPRO_IDBA_UAT56=SIRIUS_500007460_MD34=175752=20260120-14:06:26.993262=MD_GBP/USD_140109778778268=5279=1269=0270=1.2546271=10000055=GBP/USD110=0279=1269=0270=1.2546271=50000055=GBP/USD110=100000279=1269=0270=1.2546271=100000055=GBP/USD110=500000279=1269=0270=1.2546271=300000055=GBP/USD110=1000000279=1269=0270=1.2546271=500000055=GBP/USD110=300000010=099
20260120-14:06:26.380816000 : 8=FIX.4.49=068435=X49=NTPRO_IDBA_UAT56=SIRIUS_500007460_MD34=175852=20260120-14:06:27.048262=MD_GBP/USD_140109778778268=10279=1269=0270=1.25459271=10000055=GBP/USD110=0279=1269=0270=1.25459271=50000055=GBP/USD110=100000279=1269=0270=1.25459271=100000055=GBP/USD110=500000279=1269=0270=1.25459271=300000055=GBP/USD110=1000000279=1269=0270=1.25459271=500000055=GBP/USD110=3000000279=1269=1270=1.43494271=10000055=GBP/USD110=0279=1269=1270=1.43494271=50000055=GBP/USD110=100000279=1269=1270=1.43494271=100000055=GBP/USD110=500000279=1269=1270=1.43494271=300000055=GBP/USD110=1000000279=1269=1270=1.43494271=500000055=GBP/USD110=300000010=043
20260120-14:06:26.381874000 : 8=FIX.4.49=044735=X49=NTPRO_IDBA_UAT56=SIRIUS_500007460_MD34=175952=20260120-14:06:27.079262=MD_EUR/USD_140109278614268=6279=1269=0270=1.14781271=10000055=EUR/USD110=0279=1269=0270=1.14781271=50000055=EUR/USD110=100000279=1269=0270=1.14781271=100000055=EUR/USD110=500000279=1269=1270=1.19805271=10000055=EUR/USD110=0279=1269=1270=1.19805271=50000055=EUR/USD110=100000279=1269=1270=1.19805271=100000055=EUR/USD110=50000010=068
20260120-14:06:26.772823000 : 8=FIX.4.49=039835=X49=NTPRO_IDBA_UAT56=SIRIUS_500007460_MD34=176052=20260120-14:06:27.542262=MD_GBP/USD_140109778778268=5279=1269=1270=1.43493271=10000055=GBP/USD110=0279=1269=1270=1.43493271=50000055=GBP/USD110=100000279=1269=1270=1.43493271=100000055=GBP/USD110=500000279=1269=1270=1.43493271=300000055=GBP/USD110=1000000279=1269=1270=1.43493271=500000055=GBP/USD110=300000010=108
20260120-14:06:26.864329000 : 8=FIX.4.49=027735=X49=NTPRO_IDBA_UAT56=SIRIUS_500007460_MD34=176152=20260120-14:06:27.570262=MD_EUR/USD_140109278614268=3279=1269=0270=1.1478271=10000055=EUR/USD110=0279=1269=0270=1.1478271=50000055=EUR/USD110=100000279=1269=0270=1.1478271=100000055=EUR/USD110=50000010=120
20260120-14:06:26.864990000 : 8=FIX.4.49=068435=X49=NTPRO_IDBA_UAT56=SIRIUS_500007460_MD34=176252=20260120-14:06:27.603262=MD_GBP/USD_140109778778268=10279=1269=0270=1.25458271=10000055=GBP/USD110=0279=1269=0270=1.25458271=50000055=GBP/USD110=100000279=1269=0270=1.25458271=100000055=GBP/USD110=500000279=1269=0270=1.25458271=300000055=GBP/USD110=1000000279=1269=0270=1.25458271=500000055=GBP/USD110=3000000279=1269=1270=1.43494271=10000055=GBP/USD110=0279=1269=1270=1.43494271=50000055=GBP/USD110=100000279=1269=1270=1.43494271=100000055=GBP/USD110=500000279=1269=1270=1.43494271=300000055=GBP/USD110=1000000279=1269=1270=1.43494271=500000055=GBP/USD110=300000010=030
20260120-14:06:26.974695000 : 8=FIX.4.49=044735=X49=NTPRO_IDBA_UAT56=SIRIUS_500007460_MD34=176352=20260120-14:06:27.753262=MD_EUR/USD_140109278614268=6279=1269=0270=1.14777271=10000055=EUR/USD110=0279=1269=0270=1.14777271=50000055=EUR/USD110=100000279=1269=0270=1.14777271=100000055=EUR/USD110=500000279=1269=1270=1.19802271=10000055=EUR/USD110=0279=1269=1270=1.19802271=50000055=EUR/USD110=100000279=1269=1270=1.19802271=100000055=EUR/USD110=50000010=068
20260120-14:06:26.979611000 : 8=FIX.4.49=068435=X49=NTPRO_IDBA_UAT56=SIRIUS_500007460_MD34=176452=20260120-14:06:27.759262=MD_GBP/USD_140109778778268=10279=2269=0270=1.25458271=10000055=GBP/USD110=0279=2269=0270=1.25458271=50000055=GBP/USD110=100000279=2269=0270=1.25458271=100000055=GBP/USD110=500000279=2269=0270=1.25458271=300000055=GBP/USD110=1000000279=2269=0270=1.25458271=500000055=GBP/USD110=3000000279=2269=1270=1.43494271=10000055=GBP/USD110=0279=2269=1270=1.43494271=50000055=GBP/USD110=100000279=2269=1270=1.43494271=100000055=GBP/USD110=500000279=2269=1270=1.43494271=300000055=GBP/USD110=1000000279=2269=1270=1.43494271=500000055=GBP/USD110=300000010=054
20260120-14:06:27.070817000 : 8=FIX.4.49=067935=X49=NTPRO_IDBA_UAT56=SIRIUS_500007460_MD34=176552=20260120-14:06:27.800262=MD_GBP/USD_140109778778268=10279=0269=0270=1.25455271=10000055=GBP/USD110=0279=0269=0270=1.25455271=50000055=GBP/USD110=100000279=0269=0270=1.25455271=100000055=GBP/USD110=500000279=0269=0270=1.25455271=300000055=GBP/USD110=1000000279=0269=0270=1.25455271=500000055=GBP/USD110=3000000279=0269=1270=1.4349271=10000055=GBP/USD110=0279=0269=1270=1.4349271=50000055=GBP/USD110=100000279=0269=1270=1.4349271=100000055=GBP/USD110=500000279=0269=1270=1.4349271=300000055=GBP/USD110=1000000279=0269=1270=1.4349271=500000055=GBP/USD110=300000010=007
20260120-14:06:27.071391000 : 8=FIX.4.49=044135=X49=NTPRO_IDBA_UAT56=SIRIUS_500007460_MD34=176652=20260120-14:06:27.823262=MD_EUR/USD_140109278614268=6279=1269=0270=1.14775271=10000055=EUR/USD110=0279=1269=0270=1.14775271=50000055=EUR/USD110=100000279=1269=0270=1.14775271=100000055=EUR/USD110=500000279=1269=1270=1.198271=10000055=EUR/USD110=0279=1269=1270=1.198271=50000055=EUR/USD110=100000279=1269=1270=1.198271=100000055=EUR/USD110=50000010=019
20260120-14:06:27.071849000 : 8=FIX.4.49=039835=X49=NTPRO_IDBA_UAT56=SIRIUS_500007460_MD34=176752=20260120-14:06:27.851262=MD_GBP/USD_140109778778268=5279=1269=0270=1.25454271=10000055=GBP/USD110=0279=1269=0270=1.25454271=50000055=GBP/USD110=100000279=1269=0270=1.25454271=100000055=GBP/USD110=500000279=1269=0270=1.25454271=300000055=GBP/USD110=1000000279=1269=0270=1.25454271=500000055=GBP/USD110=300000010=098
20260120-14:06:27.167864000 : 8=FIX.4.49=039835=X49=NTPRO_IDBA_UAT56=SIRIUS_500007460_MD34=176852=20260120-14:06:27.892262=MD_GBP/USD_140109778778268=5279=1269=0270=1.25455271=10000055=GBP/USD110=0279=1269=0270=1.25455271=50000055=GBP/USD110=100000279=1269=0270=1.25455271=100000055=GBP/USD110=500000279=1269=0270=1.25455271=300000055=GBP/USD110=1000000279=1269=0270=1.25455271=500000055=GBP/USD110=300000010=109
20260120-14:06:27.258247000 : 8=FIX.4.49=044735=X49=NTPRO_IDBA_UAT56=SIRIUS_500007460_MD34=176952=20260120-14:06:27.992262=MD_EUR/USD_140109278614268=6279=1269=0270=1.14774271=10000055=EUR/USD110=0279=1269=0270=1.14774271=50000055=EUR/USD110=100000279=1269=0270=1.14774271=100000055=EUR/USD110=500000279=1269=1270=1.19799271=10000055=EUR/USD110=0279=1269=1270=1.19799271=50000055=EUR/USD110=100000279=1269=1270=1.19799271=100000055=EUR/USD110=50000010=115
20260120-14:06:27.259576000 : 8=FIX.4.49=039835=X49=NTPRO_IDBA_UAT56=SIRIUS_500007460_MD34=177052=20260120-14:06:27.994262=MD_GBP/USD_140109778778268=5279=1269=1270=1.43489271=10000055=GBP/USD110=0279=1269=1270=1.43489271=50000055=GBP/USD110=100000279=1269=1270=1.43489271=100000055=GBP/USD110=500000279=1269=1270=1.43489271=300000055=GBP/USD110=1000000279=1269=1270=1.43489271=500000055=GBP/USD110=300000010=145
20260120-14:06:27.358178000 : 8=FIX.4.49=039335=X49=NTPRO_IDBA_UAT56=SIRIUS_500007460_MD34=177152=20260120-14:06:28.135262=MD_GBP/USD_140109778778268=5279=1269=1270=1.4349271=10000055=GBP/USD110=0279=1269=1270=1.4349271=50000055=GBP/USD110=100000279=1269=1270=1.4349271=100000055=GBP/USD110=500000279=1269=1270=1.4349271=300000055=GBP/USD110=1000000279=1269=1270=1.4349271=500000055=GBP/USD110=300000010=105
20260120-14:06:27.452772000 : 8=FIX.4.49=028035=X49=NTPRO_IDBA_UAT56=SIRIUS_500007460_MD34=177252=20260120-14:06:28.237262=MD_EUR/USD_140109278614268=3279=1269=1270=1.19798271=10000055=EUR/USD110=0279=1269=1270=1.19798271=50000055=EUR/USD110=100000279=1269=1270=1.19798271=100000055=EUR/USD110=50000010=050
20260120-14:06:27.461128000 : 8=FIX.4.49=044735=X49=NTPRO_IDBA_UAT56=SIRIUS_500007460_MD34=177352=20260120-14:06:28.263262=MD_EUR/USD_140109278614268=6279=1269=0270=1.14772271=10000055=EUR/USD110=0279=1269=0270=1.14772271=50000055=EUR/USD110=100000279=1269=0270=1.14772271=100000055=EUR/USD110=500000279=1269=1270=1.19797271=10000055=EUR/USD110=0279=1269=1270=1.19797271=50000055=EUR/USD110=100000279=1269=1270=1.19797271=100000055=EUR/USD110=50000010=090
20260120-14:06:27.557187000 : 8=FIX.4.49=068435=X49=NTPRO_IDBA_UAT56=SIRIUS_500007460_MD34=177452=20260120-14:06:28.308262=MD_GBP/USD_140109778778268=10279=1269=0270=1.25453271=10000055=GBP/USD110=0279=1269=0270=1.25453271=50000055=GBP/USD110=100000279=1269=0270=1.25453271=100000055=GBP/USD110=500000279=1269=0270=1.25453271=300000055=GBP/USD110=1000000279=1269=0270=1.25453271=500000055=GBP/USD110=3000000279=1269=1270=1.43488271=10000055=GBP/USD110=0279=1269=1270=1.43488271=50000055=GBP/USD110=100000279=1269=1270=1.43488271=100000055=GBP/USD110=500000279=1269=1270=1.43488271=300000055=GBP/USD110=1000000279=1269=1270=1.43488271=500000055=GBP/USD110=300000010=026
20260120-14:06:27.558239000 : 8=FIX.4.49=044735=X49=NTPRO_IDBA_UAT56=SIRIUS_500007460_MD34=177552=20260120-14:06:28.319262=MD_EUR/USD_140109278614268=6279=1269=0270=1.14769271=10000055=EUR/USD110=0279=1269=0270=1.14769271=50000055=EUR/USD110=100000279=1269=0270=1.14769271=100000055=EUR/USD110=500000279=1269=1270=1.19794271=10000055=EUR/USD110=0279=1269=1270=1.19794271=50000055=EUR/USD110=100000279=1269=1270=1.19794271=100000055=EUR/USD110=50000010=103
20260120-14:06:27.652482000 : 8=FIX.4.49=068435=X49=NTPRO_IDBA_UAT56=SIRIUS_500007460_MD34=177652=20260120-14:06:28.402262=MD_GBP/USD_140109778778268=10279=1269=0270=1.25455271=10000055=GBP/USD110=0279=1269=0270=1.25455271=50000055=GBP/USD110=100000279=1269=0270=1.25455271=100000055=GBP/USD110=500000279=1269=0270=1.25455271=300000055=GBP/USD110=1000000279=1269=0270=1.25455271=500000055=GBP/USD110=3000000279=1269=1270=1.43489271=10000055=GBP/USD110=0279=1269=1270=1.43489271=50000055=GBP/USD110=100000279=1269=1270=1.43489271=100000055=GBP/USD110=500000279=1269=1270=1.43489271=300000055=GBP/USD110=1000000279=1269=1270=1.43489271=500000055=GBP/USD110=300000010=038
20260120-14:06:27.653238000 : 8=FIX.4.49=044735=X49=NTPRO_IDBA_UAT56=SIRIUS_500007460_MD34=177752=20260120-14:06:28.420262=MD_EUR/USD_140109278614268=6279=1269=0270=1.14771271=10000055=EUR/USD110=0279=1269=0270=1.14771271=50000055=EUR/USD110=100000279=1269=0270=1.14771271=100000055=EUR/USD110=500000279=1269=1270=1.19796271=10000055=EUR/USD110=0279=1269=1270=1.19796271=50000055=EUR/USD110=100000279=1269=1270=1.19796271=100000055=EUR/USD110=50000010=083
20260120-14:06:27.653879000 : 8=FIX.4.49=039335=X49=NTPRO_IDBA_UAT56=SIRIUS_500007460_MD34=177852=20260120-14:06:28.439262=MD_GBP/USD_140109778778268=5279=1269=1270=1.4349271=10000055=GBP/USD110=0279=1269=1270=1.4349271=50000055=GBP/USD110=100000279=1269=1270=1.4349271=100000055=GBP/USD110=500000279=1269=1270=1.4349271=300000055=GBP/USD110=1000000279=1269=1270=1.4349271=500000055=GBP/USD110=300000010=119
20260120-14:06:27.849677000 : 8=FIX.4.49=028035=X49=NTPRO_IDBA_UAT56=SIRIUS_500007460_MD34=177952=20260120-14:06:28.586262=MD_EUR/USD_140109278614268=3279=1269=0270=1.14772271=10000055=EUR/USD110=0279=1269=0270=1.14772271=50000055=EUR/USD110=100000279=1269=0270=1.14772271=100000055=EUR/USD110=50000010=022
20260120-14:06:27.949106000 : 8=FIX.4.49=028035=X49=NTPRO_IDBA_UAT56=SIRIUS_500007460_MD34=178052=20260120-14:06:28.735262=MD_EUR/USD_140109278614268=3279=1269=0270=1.14771271=10000055=EUR/USD110=0279=1269=0270=1.14771271=50000055=EUR/USD110=100000279=1269=0270=1.14771271=100000055=EUR/USD110=50000010=007
20260120-14:06:28.044337000 : 8=FIX.4.49=028035=X49=NTPRO_IDBA_UAT56=SIRIUS_500007460_MD34=178152=20260120-14:06:28.818262=MD_EUR/USD_140109278614268=3279=1269=1270=1.19795271=10000055=EUR/USD110=0279=1269=1270=1.19795271=50000055=EUR/USD110=100000279=1269=1270=1.19795271=100000055=EUR/USD110=50000010=046
20260120-14:06:28.549542000 : 8=FIX.4.49=028035=X49=NTPRO_IDBA_UAT56=SIRIUS_500007460_MD34=178252=20260120-14:06:29.383262=MD_EUR/USD_140109278614268=3279=1269=1270=1.19796271=10000055=EUR/USD110=0279=1269=1270=1.19796271=50000055=EUR/USD110=100000279=1269=1270=1.19796271=100000055=EUR/USD110=50000010=048
20260120-14:06:28.638486000 : 8=FIX.4.49=028035=X49=NTPRO_IDBA_UAT56=SIRIUS_500007460_MD34=178352=20260120-14:06:29.463262=MD_EUR/USD_140109278614268=3279=1269=0270=1.14772271=10000055=EUR/USD110=0279=1269=0270=1.14772271=50000055=EUR/USD110=100000279=1269=0270=1.14772271=100000055=EUR/USD110=50000010=012
20260120-14:06:28.827606000 : 8=FIX.4.49=044735=X49=NTPRO_IDBA_UAT56=SIRIUS_500007460_MD34=178452=20260120-14:06:29.603262=MD_EUR/USD_140109278614268=6279=1269=0270=1.14771271=10000055=EUR/USD110=0279=1269=0270=1.14771271=50000055=EUR/USD110=100000279=1269=0270=1.14771271=100000055=EUR/USD110=500000279=1269=1270=1.19795271=10000055=EUR/USD110=0279=1269=1270=1.19795271=50000055=EUR/USD110=100000279=1269=1270=1.19795271=100000055=EUR/USD110=50000010=082
20260120-14:06:28.828288000 : 8=FIX.4.49=044735=X49=NTPRO_IDBA_UAT56=SIRIUS_500007460_MD34=178552=20260120-14:06:29.643262=MD_EUR/USD_140109278614268=6279=1269=0270=1.14772271=10000055=EUR/USD110=0279=1269=0270=1.14772271=50000055=EUR/USD110=100000279=1269=0270=1.14772271=100000055=EUR/USD110=500000279=1269=1270=1.19796271=10000055=EUR/USD110=0279=1269=1270=1.19796271=50000055=EUR/USD110=100000279=1269=1270=1.19796271=100000055=EUR/USD110=50000010=093
20260120-14:06:28.828739000 : 8=FIX.4.49=039835=X49=NTPRO_IDBA_UAT56=SIRIUS_500007460_MD34=178652=20260120-14:06:29.678262=MD_GBP/USD_140109778778268=5279=1269=0270=1.25457271=10000055=GBP/USD110=0279=1269=0270=1.25457271=50000055=GBP/USD110=100000279=1269=0270=1.25457271=100000055=GBP/USD110=500000279=1269=0270=1.25457271=300000055=GBP/USD110=1000000279=1269=0270=1.25457271=500000055=GBP/USD110=300000010=123
20260120-14:06:28.932041000 : 8=FIX.4.49=039835=X49=NTPRO_IDBA_UAT56=SIRIUS_500007460_MD34=178752=20260120-14:06:29.735262=MD_GBP/USD_140109778778268=5279=1269=1270=1.43491271=10000055=GBP/USD110=0279=1269=1270=1.43491271=50000055=GBP/USD110=100000279=1269=1270=1.43491271=100000055=GBP/USD110=500000279=1269=1270=1.43491271=300000055=GBP/USD110=1000000279=1269=1270=1.43491271=500000055=GBP/USD110=300000010=113
20260120-14:06:28.932801000 : 8=FIX.4.49=028035=X49=NTPRO_IDBA_UAT56=SIRIUS_500007460_MD34=178852=20260120-14:06:29.766262=MD_EUR/USD_140109278614268=3279=1269=1270=1.19797271=10000055=EUR/USD110=0279=1269=1270=1.19797271=50000055=EUR/USD110=100000279=1269=1270=1.19797271=100000055=EUR/USD110=50000010=062
20260120-14:06:28.952178000 : 8=FIX.4.49=068435=X49=NTPRO_IDBA_UAT56=SIRIUS_500007460_MD34=178952=20260120-14:06:29.806262=MD_GBP/USD_140109778778268=10279=2269=0270=1.25457271=10000055=GBP/USD110=0279=2269=0270=1.25457271=50000055=GBP/USD110=100000279=2269=0270=1.25457271=100000055=GBP/USD110=500000279=2269=0270=1.25457271=300000055=GBP/USD110=1000000279=2269=0270=1.25457271=500000055=GBP/USD110=3000000279=2269=1270=1.43491271=10000055=GBP/USD110=0279=2269=1270=1.43491271=50000055=GBP/USD110=100000279=2269=1270=1.43491271=100000055=GBP/USD110=500000279=2269=1270=1.43491271=300000055=GBP/USD110=1000000279=2269=1270=1.43491271=500000055=GBP/USD110=300000010=036
20260120-14:06:29.032277000 : 8=FIX.4.49=044735=X49=NTPRO_IDBA_UAT56=SIRIUS_500007460_MD34=179052=20260120-14:06:29.873262=MD_EUR/USD_140109278614268=6279=1269=0270=1.14774271=10000055=EUR/USD110=0279=1269=0270=1.14774271=50000055=EUR/USD110=100000279=1269=0270=1.14774271=100000055=EUR/USD110=500000279=1269=1270=1.19799271=10000055=EUR/USD110=0279=1269=1270=1.19799271=50000055=EUR/USD110=100000279=1269=1270=1.19799271=100000055=EUR/USD110=50000010=109
20260120-14:06:29.119576000 : 8=FIX.4.49=068435=X49=NTPRO_IDBA_UAT56=SIRIUS_500007460_MD34=179152=20260120-14:06:29.928262=MD_GBP/USD_140109778778268=10279=0269=0270=1.25464271=10000055=GBP/USD110=0279=0269=0270=1.25464271=50000055=GBP/USD110=100000279=0269=0270=1.25464271=100000055=GBP/USD110=500000279=0269=0270=1.25464271=300000055=GBP/USD110=1000000279=0269=0270=1.25464271=500000055=GBP/USD110=3000000279=0269=1270=1.43498271=10000055=GBP/USD110=0279=0269=1270=1.43498271=50000055=GBP/USD110=100000279=0269=1270=1.43498271=100000055=GBP/USD110=500000279=0269=1270=1.43498271=300000055=GBP/USD110=1000000279=0269=1270=1.43498271=500000055=GBP/USD110=300000010=039
20260120-14:06:29.120230000 : 8=FIX.4.49=044135=X49=NTPRO_IDBA_UAT56=SIRIUS_500007460_MD34=179252=20260120-14:06:29.949262=MD_EUR/USD_140109278614268=6279=1269=0270=1.14775271=10000055=EUR/USD110=0279=1269=0270=1.14775271=50000055=EUR/USD110=100000279=1269=0270=1.14775271=100000055=EUR/USD110=500000279=1269=1270=1.198271=10000055=EUR/USD110=0279=1269=1270=1.198271=50000055=EUR/USD110=100000279=1269=1270=1.198271=100000055=EUR/USD110=50000010=029
20260120-14:06:29.144706000 : 8=FIX.4.49=039835=X49=NTPRO_IDBA_UAT56=SIRIUS_500007460_MD34=179352=20260120-14:06:30.005262=MD_GBP/USD_140109778778268=5279=1269=1270=1.43499271=10000055=GBP/USD110=0279=1269=1270=1.43499271=50000055=GBP/USD110=100000279=1269=1270=1.43499271=100000055=GBP/USD110=500000279=1269=1270=1.43499271=300000055=GBP/USD110=1000000279=1269=1270=1.43499271=500000055=GBP/USD110=300000010=132
20260120-14:06:29.205262000 : 8=FIX.4.49=028035=X49=NTPRO_IDBA_UAT56=SIRIUS_500007460_MD34=179452=20260120-14:06:30.066262=MD_EUR/USD_140109278614268=3279=1269=1270=1.19799271=10000055=EUR/USD110=0279=1269=1270=1.19799271=50000055=EUR/USD110=100000279=1269=1270=1.19799271=100000055=EUR/USD110=50000010=050
20260120-14:06:29.296172000 : 8=FIX.4.49=044735=X49=NTPRO_IDBA_UAT56=SIRIUS_500007460_MD34=179552=20260120-14:06:30.118262=MD_EUR/USD_140109278614268=6279=1269=0270=1.14776271=10000055=EUR/USD110=0279=1269=0270=1.14776271=50000055=EUR/USD110=100000279=1269=0270=1.14776271=100000055=EUR/USD110=500000279=1269=1270=1.19801271=10000055=EUR/USD110=0279=1269=1270=1.19801271=50000055=EUR/USD110=100000279=1269=1270=1.19801271=100000055=EUR/USD110=50000010=056
20260120-14:06:29.336473000 : 8=FIX.4.49=044735=X49=NTPRO_IDBA_UAT56=SIRIUS_500007460_MD34=179652=20260120-14:06:30.193262=MD_EUR/USD_140109278614268=6279=1269=0270=1.14779271=10000055=EUR/USD110=0279=1269=0270=1.14779271=50000055=EUR/USD110=100000279=1269=0270=1.14779271=100000055=EUR/USD110=500000279=1269=1270=1.19803271=10000055=EUR/USD110=0279=1269=1270=1.19803271=50000055=EUR/USD110=100000279=1269=1270=1.19803271=100000055=EUR/USD110=50000010=075
20260120-14:06:29.337225000 : 8=FIX.4.49=039835=X49=NTPRO_IDBA_UAT56=SIRIUS_500007460_MD34=179752=20260120-14:06:30.196262=MD_GBP/USD_140109778778268=5279=1269=0270=1.25465271=10000055=GBP/USD110=0279=1269=0270=1.25465271=50000055=GBP/USD110=100000279=1269=0270=1.25465271=100000055=GBP/USD110=500000279=1269=0270=1.25465271=300000055=GBP/USD110=1000000279=1269=0270=1.25465271=500000055=GBP/USD110=300000010=107
20260120-14:06:29.389917000 : 8=FIX.4.49=044735=X49=NTPRO_IDBA_UAT56=SIRIUS_500007460_MD34=179852=20260120-14:06:30.246262=MD_EUR/USD_140109278614268=6279=1269=0270=1.14778271=10000055=EUR/USD110=0279=1269=0270=1.14778271=50000055=EUR/USD110=100000279=1269=0270=1.14778271=100000055=EUR/USD110=500000279=1269=1270=1.19802271=10000055=EUR/USD110=0279=1269=1270=1.19802271=50000055=EUR/USD110=100000279=1269=1270=1.19802271=100000055=EUR/USD110=50000010=070
20260120-14:06:29.426654000 : 8=FIX.4.49=044735=X49=NTPRO_IDBA_UAT56=SIRIUS_500007460_MD34=179952=20260120-14:06:30.288262=MD_EUR/USD_140109278614268=6279=1269=0270=1.14777271=10000055=EUR/USD110=0279=1269=0270=1.14777271=50000055=EUR/USD110=100000279=1269=0270=1.14777271=100000055=EUR/USD110=500000279=1269=1270=1.19801271=10000055=EUR/USD110=0279=1269=1270=1.19801271=50000055=EUR/USD110=100000279=1269=1270=1.19801271=100000055=EUR/USD110=50000010=071
20260120-14:06:29.638579000 : 8=FIX.4.49=039835=X49=NTPRO_IDBA_UAT56=SIRIUS_500007460_MD34=180052=20260120-14:06:30.506262=MD_GBP/USD_140109778778268=5279=1269=0270=1.25463271=10000055=GBP/USD110=0279=1269=0270=1.25463271=50000055=GBP/USD110=100000279=1269=0270=1.25463271=100000055=GBP/USD110=500000279=1269=0270=1.25463271=300000055=GBP/USD110=1000000279=1269=0270=1.25463271=500000055=GBP/USD110=300000010=077
20260120-14:06:29.721675000 : 8=FIX.4.49=044135=X49=NTPRO_IDBA_UAT56=SIRIUS_500007460_MD34=180152=20260120-14:06:30.597262=MD_EUR/USD_140109278614268=6279=1269=0270=1.14776271=10000055=EUR/USD110=0279=1269=0270=1.14776271=50000055=EUR/USD110=100000279=1269=0270=1.14776271=100000055=EUR/USD110=500000279=1269=1270=1.198271=10000055=EUR/USD110=0279=1269=1270=1.198271=50000055=EUR/USD110=100000279=1269=1270=1.198271=100000055=EUR/USD110=50000010=014
20260120-14:06:29.779048000 : 8=FIX.4.49=039835=X49=NTPRO_IDBA_UAT56=SIRIUS_500007460_MD34=180252=20260120-14:06:30.652262=MD_GBP/USD_140109778778268=5279=1269=1270=1.43498271=10000055=GBP/USD110=0279=1269=1270=1.43498271=50000055=GBP/USD110=100000279=1269=1270=1.43498271=100000055=GBP/USD110=500000279=1269=1270=1.43498271=300000055=GBP/USD110=1000000279=1269=1270=1.43498271=500000055=GBP/USD110=300000010=126
20260120-14:06:29.926514000 : 8=FIX.4.49=007935=049=NTPRO_IDBA_UAT56=SIRIUS_500007460_MD34=180352=20260120-14:06:30.80910=018
20260120-14:06:30.716137000 : 8=FIX.4.49=039835=X49=NTPRO_IDBA_UAT56=SIRIUS_500007460_MD34=180452=20260120-14:06:31.621262=MD_GBP/USD_140109778778268=5279=1269=1270=1.43497271=10000055=GBP/USD110=0279=1269=1270=1.43497271=50000055=GBP/USD110=100000279=1269=1270=1.43497271=100000055=GBP/USD110=500000279=1269=1270=1.43497271=300000055=GBP/USD110=1000000279=1269=1270=1.43497271=500000055=GBP/USD110=300000010=120
20260120-14:06:30.979841000 : 8=FIX.4.49=039835=X49=NTPRO_IDBA_UAT56=SIRIUS_500007460_MD34=180552=20260120-14:06:31.893262=MD_GBP/USD_140109778778268=5279=1269=1270=1.43498271=10000055=GBP/USD110=0279=1269=1270=1.43498271=50000055=GBP/USD110=100000279=1269=1270=1.43498271=100000055=GBP/USD110=500000279=1269=1270=1.43498271=300000055=GBP/USD110=1000000279=1269=1270=1.43498271=500000055=GBP/USD110=300000010=137
20260120-14:06:31.020509000 : 8=FIX.4.49=039835=X49=NTPRO_IDBA_UAT56=SIRIUS_500007460_MD34=180652=20260120-14:06:31.935262=MD_GBP/USD_140109778778268=5279=1269=0270=1.25464271=10000055=GBP/USD110=0279=1269=0270=1.25464271=50000055=GBP/USD110=100000279=1269=0270=1.25464271=100000055=GBP/USD110=500000279=1269=0270=1.25464271=300000055=GBP/USD110=1000000279=1269=0270=1.25464271=500000055=GBP/USD110=300000010=095
20260120-14:06:31.179755000 : 8=FIX.4.49=028035=X49=NTPRO_IDBA_UAT56=SIRIUS_500007460_MD34=180752=20260120-14:06:32.099262=MD_EUR/USD_140109278614268=3279=1269=0270=1.14775271=10000055=EUR/USD110=0279=1269=0270=1.14775271=50000055=EUR/USD110=100000279=1269=0270=1.14775271=100000055=EUR/USD110=50000010=017
20260120-14:06:31.224782000 : 8=FIX.4.49=044735=X49=NTPRO_IDBA_UAT56=SIRIUS_500007460_MD34=180852=20260120-14:06:32.145262=MD_EUR/USD_140109278614268=6279=1269=0270=1.14776271=10000055=EUR/USD110=0279=1269=0270=1.14776271=50000055=EUR/USD110=100000279=1269=0270=1.14776271=100000055=EUR/USD110=500000279=1269=1270=1.19801271=10000055=EUR/USD110=0279=1269=1270=1.19801271=50000055=EUR/USD110=100000279=1269=1270=1.19801271=100000055=EUR/USD110=50000010=053
20260120-14:06:31.247688000 : 8=FIX.4.49=067435=X49=NTPRO_IDBA_UAT56=SIRIUS_500007460_MD34=180952=20260120-14:06:32.169262=MD_GBP/USD_140109778778268=10279=1269=0270=1.25465271=10000055=GBP/USD110=0279=1269=0270=1.25465271=50000055=GBP/USD110=100000279=1269=0270=1.25465271=100000055=GBP/USD110=500000279=1269=0270=1.25465271=300000055=GBP/USD110=1000000279=1269=0270=1.25465271=500000055=GBP/USD110=3000000279=1269=1270=1.435271=10000055=GBP/USD110=0279=1269=1270=1.435271=50000055=GBP/USD110=100000279=1269=1270=1.435271=100000055=GBP/USD110=500000279=1269=1270=1.435271=300000055=GBP/USD110=1000000279=1269=1270=1.435271=500000055=GBP/USD110=300000010=252
20260120-14:06:31.317681000 : 8=FIX.4.49=067435=X49=NTPRO_IDBA_UAT56=SIRIUS_500007460_MD34=181052=20260120-14:06:32.241262=MD_GBP/USD_140109778778268=10279=2269=0270=1.25465271=10000055=GBP/USD110=0279=2269=0270=1.25465271=50000055=GBP/USD110=100000279=2269=0270=1.25465271=100000055=GBP/USD110=500000279=2269=0270=1.25465271=300000055=GBP/USD110=1000000279=2269=0270=1.25465271=500000055=GBP/USD110=3000000279=2269=1270=1.435271=10000055=GBP/USD110=0279=2269=1270=1.435271=50000055=GBP/USD110=100000279=2269=1270=1.435271=100000055=GBP/USD110=500000279=2269=1270=1.435271=300000055=GBP/USD110=1000000279=2269=1270=1.435271=500000055=GBP/USD110=300000010=245
20260120-14:06:31.372917000 : 8=FIX.4.49=044735=X49=NTPRO_IDBA_UAT56=SIRIUS_500007460_MD34=181152=20260120-14:06:32.292262=MD_EUR/USD_140109278614268=6279=1269=0270=1.14778271=10000055=EUR/USD110=0279=1269=0270=1.14778271=50000055=EUR/USD110=100000279=1269=0270=1.14778271=100000055=EUR/USD110=500000279=1269=1270=1.19802271=10000055=EUR/USD110=0279=1269=1270=1.19802271=50000055=EUR/USD110=100000279=1269=1270=1.19802271=100000055=EUR/USD110=50000010=059
20260120-14:06:31.389514000 : 8=FIX.4.49=068435=X49=NTPRO_IDBA_UAT56=SIRIUS_500007460_MD34=181252=20260120-14:06:32.315262=MD_GBP/USD_140109778778268=10279=0269=0270=1.25465271=10000055=GBP/USD110=0279=0269=0270=1.25465271=50000055=GBP/USD110=100000279=0269=0270=1.25465271=100000055=GBP/USD110=500000279=0269=0270=1.25465271=300000055=GBP/USD110=1000000279=0269=0270=1.25465271=500000055=GBP/USD110=3000000279=0269=1270=1.43499271=10000055=GBP/USD110=0279=0269=1270=1.43499271=50000055=GBP/USD110=100000279=0269=1270=1.43499271=100000055=GBP/USD110=500000279=0269=1270=1.43499271=300000055=GBP/USD110=1000000279=0269=1270=1.43499271=500000055=GBP/USD110=300000010=027
20260120-14:06:31.537964000 : 8=FIX.4.49=038835=X49=NTPRO_IDBA_UAT56=SIRIUS_500007460_MD34=181352=20260120-14:06:32.467262=MD_GBP/USD_140109778778268=5279=1269=1270=1.435271=10000055=GBP/USD110=0279=1269=1270=1.435271=50000055=GBP/USD110=100000279=1269=1270=1.435271=100000055=GBP/USD110=500000279=1269=1270=1.435271=300000055=GBP/USD110=1000000279=1269=1270=1.435271=500000055=GBP/USD110=300000010=085
20260120-14:06:31.692175000 : 8=FIX.4.49=039835=X49=NTPRO_IDBA_UAT56=SIRIUS_500007460_MD34=181452=20260120-14:06:32.626262=MD_GBP/USD_140109778778268=5279=1269=1270=1.43501271=10000055=GBP/USD110=0279=1269=1270=1.43501271=50000055=GBP/USD110=100000279=1269=1270=1.43501271=100000055=GBP/USD110=500000279=1269=1270=1.43501271=300000055=GBP/USD110=1000000279=1269=1270=1.43501271=500000055=GBP/USD110=300000010=057
20260120-14:06:31.831814000 : 8=FIX.4.49=028035=X49=NTPRO_IDBA_UAT56=SIRIUS_500007460_MD34=181552=20260120-14:06:32.770262=MD_EUR/USD_140109278614268=3279=1269=0270=1.14777271=10000055=EUR/USD110=0279=1269=0270=1.14777271=50000055=EUR/USD110=100000279=1269=0270=1.14777271=100000055=EUR/USD110=50000010=018
20260120-14:06:31.863138000 : 8=FIX.4.49=067435=X49=NTPRO_IDBA_UAT56=SIRIUS_500007460_MD34=181652=20260120-14:06:32.787262=MD_GBP/USD_140109778778268=10279=1269=0270=1.25466271=10000055=GBP/USD110=0279=1269=0270=1.25466271=50000055=GBP/USD110=100000279=1269=0270=1.25466271=100000055=GBP/USD110=500000279=1269=0270=1.25466271=300000055=GBP/USD110=1000000279=1269=0270=1.25466271=500000055=GBP/USD110=3000000279=1269=1270=1.435271=10000055=GBP/USD110=0279=1269=1270=1.435271=50000055=GBP/USD110=100000279=1269=1270=1.435271=100000055=GBP/USD110=500000279=1269=1270=1.435271=300000055=GBP/USD110=1000000279=1269=1270=1.435271=500000055=GBP/USD110=300000010=005
20260120-14:06:31.896164000 : 8=FIX.4.49=028035=X49=NTPRO_IDBA_UAT56=SIRIUS_500007460_MD34=181752=20260120-14:06:32.836262=MD_EUR/USD_140109278614268=3279=1269=0270=1.14778271=10000055=EUR/USD110=0279=1269=0270=1.14778271=50000055=EUR/USD110=100000279=1269=0270=1.14778271=100000055=EUR/USD110=50000010=026
20260120-14:06:31.973016000 : 8=FIX.4.49=068435=X49=NTPRO_IDBA_UAT56=SIRIUS_500007460_MD34=181852=20260120-14:06:32.915262=MD_GBP/USD_140109778778268=10279=1269=0270=1.25467271=10000055=GBP/USD110=0279=1269=0270=1.25467271=50000055=GBP/USD110=100000279=1269=0270=1.25467271=100000055=GBP/USD110=500000279=1269=0270=1.25467271=300000055=GBP/USD110=1000000279=1269=0270=1.25467271=500000055=GBP/USD110=3000000279=1269=1270=1.43502271=10000055=GBP/USD110=0279=1269=1270=1.43502271=50000055=GBP/USD110=100000279=1269=1270=1.43502271=100000055=GBP/USD110=500000279=1269=1270=1.43502271=300000055=GBP/USD110=1000000279=1269=1270=1.43502271=500000055=GBP/USD110=300000010=240
20260120-14:06:32.097844000 : 8=FIX.4.49=044735=X49=NTPRO_IDBA_UAT56=SIRIUS_500007460_MD34=181952=20260120-14:06:33.043262=MD_EUR/USD_140109278614268=6279=1269=0270=1.14779271=10000055=EUR/USD110=0279=1269=0270=1.14779271=50000055=EUR/USD110=100000279=1269=0270=1.14779271=100000055=EUR/USD110=500000279=1269=1270=1.19803271=10000055=EUR/USD110=0279=1269=1270=1.19803271=50000055=EUR/USD110=100000279=1269=1270=1.19803271=100000055=EUR/USD110=50000010=068
20260120-14:06:32.265863000 : 8=FIX.4.49=039835=X49=NTPRO_IDBA_UAT56=SIRIUS_500007460_MD34=182052=20260120-14:06:33.209262=MD_GBP/USD_140109778778268=5279=1269=1270=1.43501271=10000055=GBP/USD110=0279=1269=1270=1.43501271=50000055=GBP/USD110=100000279=1269=1270=1.43501271=100000055=GBP/USD110=500000279=1269=1270=1.43501271=300000055=GBP/USD110=1000000279=1269=1270=1.43501271=500000055=GBP/USD110=300000010=052
20260120-14:06:32.318170000 : 8=FIX.4.49=039835=X49=NTPRO_IDBA_UAT56=SIRIUS_500007460_MD34=182152=20260120-14:06:33.270262=MD_GBP/USD_140109778778268=5279=1269=0270=1.25469271=10000055=GBP/USD110=0279=1269=0270=1.25469271=50000055=GBP/USD110=100000279=1269=0270=1.25469271=100000055=GBP/USD110=500000279=1269=0270=1.25469271=300000055=GBP/USD110=1000000279=1269=0270=1.25469271=500000055=GBP/USD110=300000010=111
20260120-14:06:32.401607000 : 8=FIX.4.49=028035=X49=NTPRO_IDBA_UAT56=SIRIUS_500007460_MD34=182252=20260120-14:06:33.356262=MD_EUR/USD_140109278614268=3279=1269=1270=1.19805271=10000055=EUR/USD110=0279=1269=1270=1.19805271=50000055=EUR/USD110=100000279=1269=1270=1.19805271=100000055=EUR/USD110=50000010=011
20260120-14:06:32.402366000 : 8=FIX.4.49=068435=X49=NTPRO_IDBA_UAT56=SIRIUS_500007460_MD34=182352=20260120-14:06:33.357262=MD_GBP/USD_140109778778268=10279=1269=0270=1.25468271=10000055=GBP/USD110=0279=1269=0270=1.25468271=50000055=GBP/USD110=100000279=1269=0270=1.25468271=100000055=GBP/USD110=500000279=1269=0270=1.25468271=300000055=GBP/USD110=1000000279=1269=0270=1.25468271=500000055=GBP/USD110=3000000279=1269=1270=1.43503271=10000055=GBP/USD110=0279=1269=1270=1.43503271=50000055=GBP/USD110=100000279=1269=1270=1.43503271=100000055=GBP/USD110=500000279=1269=1270=1.43503271=300000055=GBP/USD110=1000000279=1269=1270=1.43503271=500000055=GBP/USD110=300000010=247
20260120-14:06:32.563872000 : 8=FIX.4.49=039835=X49=NTPRO_IDBA_UAT56=SIRIUS_500007460_MD34=182452=20260120-14:06:33.518262=MD_GBP/USD_140109778778268=5279=1269=0270=1.25469271=10000055=GBP/USD110=0279=1269=0270=1.25469271=50000055=GBP/USD110=100000279=1269=0270=1.25469271=100000055=GBP/USD110=500000279=1269=0270=1.25469271=300000055=GBP/USD110=1000000279=1269=0270=1.25469271=500000055=GBP/USD110=300000010=119
20260120-14:06:32.827480000 : 8=FIX.4.49=068435=X49=NTPRO_IDBA_UAT56=SIRIUS_500007460_MD34=182552=20260120-14:06:33.794262=MD_GBP/USD_140109778778268=10279=2269=0270=1.25469271=10000055=GBP/USD110=0279=2269=0270=1.25469271=50000055=GBP/USD110=100000279=2269=0270=1.25469271=100000055=GBP/USD110=500000279=2269=0270=1.25469271=300000055=GBP/USD110=1000000279=2269=0270=1.25469271=500000055=GBP/USD110=3000000279=2269=1270=1.43503271=10000055=GBP/USD110=0279=2269=1270=1.43503271=50000055=GBP/USD110=100000279=2269=1270=1.43503271=100000055=GBP/USD110=500000279=2269=1270=1.43503271=300000055=GBP/USD110=1000000279=2269=1270=1.43503271=500000055=GBP/USD110=300000010=013
20260120-14:06:32.966457000 : 8=FIX.4.49=044735=X49=NTPRO_IDBA_UAT56=SIRIUS_500007460_MD34=182652=20260120-14:06:33.937262=MD_EUR/USD_140109278614268=6279=1269=0270=1.14778271=10000055=EUR/USD110=0279=1269=0270=1.14778271=50000055=EUR/USD110=100000279=1269=0270=1.14778271=100000055=EUR/USD110=500000279=1269=1270=1.19804271=10000055=EUR/USD110=0279=1269=1270=1.19804271=50000055=EUR/USD110=100000279=1269=1270=1.19804271=100000055=EUR/USD110=50000010=078
20260120-14:06:32.995778000 : 8=FIX.4.49=068435=X49=NTPRO_IDBA_UAT56=SIRIUS_500007460_MD34=182752=20260120-14:06:33.966262=MD_GBP/USD_140109778778268=10279=0269=0270=1.25468271=10000055=GBP/USD110=0279=0269=0270=1.25468271=50000055=GBP/USD110=100000279=0269=0270=1.25468271=100000055=GBP/USD110=500000279=0269=0270=1.25468271=300000055=GBP/USD110=1000000279=0269=0270=1.25468271=500000055=GBP/USD110=3000000279=0269=1270=1.43503271=10000055=GBP/USD110=0279=0269=1270=1.43503271=50000055=GBP/USD110=100000279=0269=1270=1.43503271=100000055=GBP/USD110=500000279=0269=1270=1.43503271=300000055=GBP/USD110=1000000279=0269=1270=1.43503271=500000055=GBP/USD110=300000010=247
20260120-14:06:33.020530000 : 8=FIX.4.49=028035=X49=NTPRO_IDBA_UAT56=SIRIUS_500007460_MD34=182852=20260120-14:06:33.993262=MD_EUR/USD_140109278614268=3279=1269=0270=1.14779271=10000055=EUR/USD110=0279=1269=0270=1.14779271=50000055=EUR/USD110=100000279=1269=0270=1.14779271=100000055=EUR/USD110=50000010=036
20260120-14:06:33.066311000 : 8=FIX.4.49=028035=X49=NTPRO_IDBA_UAT56=SIRIUS_500007460_MD34=182952=20260120-14:06:34.040262=MD_EUR/USD_140109278614268=3279=1269=0270=1.14778271=10000055=EUR/USD110=0279=1269=0270=1.14778271=50000055=EUR/USD110=100000279=1269=0270=1.14778271=100000055=EUR/USD110=50000010=018
20260120-14:06:33.127851000 : 8=FIX.4.49=068435=X49=NTPRO_IDBA_UAT56=SIRIUS_500007460_MD34=183052=20260120-14:06:34.097262=MD_GBP/USD_140109778778268=10279=1269=0270=1.25467271=10000055=GBP/USD110=0279=1269=0270=1.25467271=50000055=GBP/USD110=100000279=1269=0270=1.25467271=100000055=GBP/USD110=500000279=1269=0270=1.25467271=300000055=GBP/USD110=1000000279=1269=0270=1.25467271=500000055=GBP/USD110=3000000279=1269=1270=1.43502271=10000055=GBP/USD110=0279=1269=1270=1.43502271=50000055=GBP/USD110=100000279=1269=1270=1.43502271=100000055=GBP/USD110=500000279=1269=1270=1.43502271=300000055=GBP/USD110=1000000279=1269=1270=1.43502271=500000055=GBP/USD110=300000010=237
20260120-14:06:33.172307000 : 8=FIX.4.49=044735=X49=NTPRO_IDBA_UAT56=SIRIUS_500007460_MD34=183152=20260120-14:06:34.122262=MD_EUR/USD_140109278614268=6279=1269=0270=1.14777271=10000055=EUR/USD110=0279=1269=0270=1.14777271=50000055=EUR/USD110=100000279=1269=0270=1.14777271=100000055=EUR/USD110=500000279=1269=1270=1.19802271=10000055=EUR/USD110=0279=1269=1270=1.19802271=50000055=EUR/USD110=100000279=1269=1270=1.19802271=100000055=EUR/USD110=50000010=052
20260120-14:06:33.213780000 : 8=FIX.4.49=068435=X49=NTPRO_IDBA_UAT56=SIRIUS_500007460_MD34=183252=20260120-14:06:34.192262=MD_GBP/USD_140109778778268=10279=1269=0270=1.25466271=10000055=GBP/USD110=0279=1269=0270=1.25466271=50000055=GBP/USD110=100000279=1269=0270=1.25466271=100000055=GBP/USD110=500000279=1269=0270=1.25466271=300000055=GBP/USD110=1000000279=1269=0270=1.25466271=500000055=GBP/USD110=3000000279=1269=1270=1.43501271=10000055=GBP/USD110=0279=1269=1270=1.43501271=50000055=GBP/USD110=100000279=1269=1270=1.43501271=100000055=GBP/USD110=500000279=1269=1270=1.43501271=300000055=GBP/USD110=1000000279=1269=1270=1.43501271=500000055=GBP/USD110=300000010=225
20260120-14:06:33.225210000 : 8=FIX.4.49=044735=X49=NTPRO_IDBA_UAT56=SIRIUS_500007460_MD34=183352=20260120-14:06:34.204262=MD_EUR/USD_140109278614268=6279=1269=0270=1.14776271=10000055=EUR/USD110=0279=1269=0270=1.14776271=50000055=EUR/USD110=100000279=1269=0270=1.14776271=100000055=EUR/USD110=500000279=1269=1270=1.19801271=10000055=EUR/USD110=0279=1269=1270=1.19801271=50000055=EUR/USD110=100000279=1269=1270=1.19801271=100000055=EUR/USD110=50000010=049
20260120-14:06:33.263710000 : 8=FIX.4.49=039835=X49=NTPRO_IDBA_UAT56=SIRIUS_500007460_MD34=183452=20260120-14:06:34.238262=MD_GBP/USD_140109778778268=5279=1269=0270=1.25467271=10000055=GBP/USD110=0279=1269=0270=1.25467271=50000055=GBP/USD110=100000279=1269=0270=1.25467271=100000055=GBP/USD110=500000279=1269=0270=1.25467271=300000055=GBP/USD110=1000000279=1269=0270=1.25467271=500000055=GBP/USD110=300000010=110
20260120-14:06:33.264222000 : 8=FIX.4.49=044435=X49=NTPRO_IDBA_UAT56=SIRIUS_500007460_MD34=183552=20260120-14:06:34.243262=MD_EUR/USD_140109278614268=6279=1269=0270=1.1478271=10000055=EUR/USD110=0279=1269=0270=1.1478271=50000055=EUR/USD110=100000279=1269=0270=1.1478271=100000055=EUR/USD110=500000279=1269=1270=1.19804271=10000055=EUR/USD110=0279=1269=1270=1.19804271=50000055=EUR/USD110=100000279=1269=1270=1.19804271=100000055=EUR/USD110=50000010=157
20260120-14:06:33.362689000 : 8=FIX.4.49=028035=X49=NTPRO_IDBA_UAT56=SIRIUS_500007460_MD34=183652=20260120-14:06:34.334262=MD_EUR/USD_140109278614268=3279=1269=1270=1.19805271=10000055=EUR/USD110=0279=1269=1270=1.19805271=50000055=EUR/USD110=100000279=1269=1270=1.19805271=100000055=EUR/USD110=50000010=013
20260120-14:06:33.466252000 : 8=FIX.4.49=068435=X49=NTPRO_IDBA_UAT56=SIRIUS_500007460_MD34=183752=20260120-14:06:34.451262=MD_GBP/USD_140109778778268=10279=1269=0270=1.25468271=10000055=GBP/USD110=0279=1269=0270=1.25468271=50000055=GBP/USD110=100000279=1269=0270=1.25468271=100000055=GBP/USD110=500000279=1269=0270=1.25468271=300000055=GBP/USD110=1000000279=1269=0270=1.25468271=500000055=GBP/USD110=3000000279=1269=1270=1.43502271=10000055=GBP/USD110=0279=1269=1270=1.43502271=50000055=GBP/USD110=100000279=1269=1270=1.43502271=100000055=GBP/USD110=500000279=1269=1270=1.43502271=300000055=GBP/USD110=1000000279=1269=1270=1.43502271=500000055=GBP/USD110=300000010=243
20260120-14:06:33.491914000 : 8=FIX.4.49=028035=X49=NTPRO_IDBA_UAT56=SIRIUS_500007460_MD34=183852=20260120-14:06:34.478262=MD_EUR/USD_140109278614268=3279=1269=0270=1.14781271=10000055=EUR/USD110=0279=1269=0270=1.14781271=50000055=EUR/USD110=100000279=1269=0270=1.14781271=100000055=EUR/USD110=50000010=015
20260120-14:06:33.586669000 : 8=FIX.4.49=027735=X49=NTPRO_IDBA_UAT56=SIRIUS_500007460_MD34=183952=20260120-14:06:34.575262=MD_EUR/USD_140109278614268=3279=1269=0270=1.1478271=10000055=EUR/USD110=0279=1269=0270=1.1478271=50000055=EUR/USD110=100000279=1269=0270=1.1478271=100000055=EUR/USD110=50000010=129
20260120-14:06:34.062754000 : 8=FIX.4.49=068435=X49=NTPRO_IDBA_UAT56=SIRIUS_500007460_MD34=184052=20260120-14:06:34.599262=MD_GBP/USD_140109778778268=10279=1269=0270=1.25469271=10000055=GBP/USD110=0279=1269=0270=1.25469271=50000055=GBP/USD110=100000279=1269=0270=1.25469271=100000055=GBP/USD110=500000279=1269=0270=1.25469271=300000055=GBP/USD110=1000000279=1269=0270=1.25469271=500000055=GBP/USD110=3000000279=1269=1270=1.43503271=10000055=GBP/USD110=0279=1269=1270=1.43503271=50000055=GBP/USD110=100000279=1269=1270=1.43503271=100000055=GBP/USD110=500000279=1269=1270=1.43503271=300000055=GBP/USD110=1000000279=1269=1270=1.43503271=500000055=GBP/USD110=300000010=004
20260120-14:06:34.076313000 : 8=FIX.4.49=028035=X49=NTPRO_IDBA_UAT56=SIRIUS_500007460_MD34=184152=20260120-14:06:34.612262=MD_EUR/USD_140109278614268=3279=1269=0270=1.14781271=10000055=EUR/USD110=0279=1269=0270=1.14781271=50000055=EUR/USD110=100000279=1269=0270=1.14781271=100000055=EUR/USD110=50000010=255
20260120-14:06:34.168852000 : 8=FIX.4.49=044735=X49=NTPRO_IDBA_UAT56=SIRIUS_500007460_MD34=184252=20260120-14:06:34.702262=MD_EUR/USD_140109278614268=6279=1269=0270=1.14782271=10000055=EUR/USD110=0279=1269=0270=1.14782271=50000055=EUR/USD110=100000279=1269=0270=1.14782271=100000055=EUR/USD110=500000279=1269=1270=1.19807271=10000055=EUR/USD110=0279=1269=1270=1.19807271=50000055=EUR/USD110=100000279=1269=1270=1.19807271=100000055=EUR/USD110=50000010=061
20260120-14:06:34.187780000 : 8=FIX.4.49=039835=X49=NTPRO_IDBA_UAT56=SIRIUS_500007460_MD34=184352=20260120-14:06:34.715262=MD_GBP/USD_140109778778268=5279=1269=1270=1.43504271=10000055=GBP/USD110=0279=1269=1270=1.43504271=50000055=GBP/USD110=100000279=1269=1270=1.43504271=100000055=GBP/USD110=500000279=1269=1270=1.43504271=300000055=GBP/USD110=1000000279=1269=1270=1.43504271=500000055=GBP/USD110=300000010=075
20260120-14:06:34.829554000 : 8=FIX.4.49=044735=X49=NTPRO_IDBA_UAT56=SIRIUS_500007460_MD34=184452=20260120-14:06:34.792262=MD_EUR/USD_140109278614268=6279=1269=0270=1.14781271=10000055=EUR/USD110=0279=1269=0270=1.14781271=50000055=EUR/USD110=100000279=1269=0270=1.14781271=100000055=EUR/USD110=500000279=1269=1270=1.19805271=10000055=EUR/USD110=0279=1269=1270=1.19805271=50000055=EUR/USD110=100000279=1269=1270=1.19805271=100000055=EUR/USD110=50000010=063
20260120-14:06:34.872745000 : 8=FIX.4.49=027735=X49=NTPRO_IDBA_UAT56=SIRIUS_500007460_MD34=184552=20260120-14:06:34.837262=MD_EUR/USD_140109278614268=3279=1269=0270=1.1478271=10000055=EUR/USD110=0279=1269=0270=1.1478271=50000055=EUR/USD110=100000279=1269=0270=1.1478271=100000055=EUR/USD110=50000010=127
20260120-14:06:34.891466000 : 8=FIX.4.49=068435=X49=NTPRO_IDBA_UAT56=SIRIUS_500007460_MD34=184652=20260120-14:06:34.842262=MD_GBP/USD_140109778778268=10279=1269=0270=1.25468271=10000055=GBP/USD110=0279=1269=0270=1.25468271=50000055=GBP/USD110=100000279=1269=0270=1.25468271=100000055=GBP/USD110=500000279=1269=0270=1.25468271=300000055=GBP/USD110=1000000279=1269=0270=1.25468271=500000055=GBP/USD110=3000000279=1269=1270=1.43503271=10000055=GBP/USD110=0279=1269=1270=1.43503271=50000055=GBP/USD110=100000279=1269=1270=1.43503271=100000055=GBP/USD110=500000279=1269=1270=1.43503271=300000055=GBP/USD110=1000000279=1269=1270=1.43503271=500000055=GBP/USD110=300000010=252
20260120-14:06:35.147020000 : 8=FIX.4.49=044735=X49=NTPRO_IDBA_UAT56=SIRIUS_500007460_MD34=184752=20260120-14:06:35.035262=MD_EUR/USD_140109278614268=6279=1269=0270=1.14782271=10000055=EUR/USD110=0279=1269=0270=1.14782271=50000055=EUR/USD110=100000279=1269=0270=1.14782271=100000055=EUR/USD110=500000279=1269=1270=1.19806271=10000055=EUR/USD110=0279=1269=1270=1.19806271=50000055=EUR/USD110=100000279=1269=1270=1.19806271=100000055=EUR/USD110=50000010=063
20260120-14:06:35.147503000 : 8=FIX.4.49=028035=X49=NTPRO_IDBA_UAT56=SIRIUS_500007460_MD34=184852=20260120-14:06:35.108262=MD_EUR/USD_140109278614268=3279=1269=0270=1.14781271=10000055=EUR/USD110=0279=1269=0270=1.14781271=50000055=EUR/USD110=100000279=1269=0270=1.14781271=100000055=EUR/USD110=50000010=007
20260120-14:06:35.245715000 : 8=FIX.4.49=039835=X49=NTPRO_IDBA_UAT56=SIRIUS_500007460_MD34=184952=20260120-14:06:35.190262=MD_GBP/USD_140109778778268=5279=1269=0270=1.25469271=10000055=GBP/USD110=0279=1269=0270=1.25469271=50000055=GBP/USD110=100000279=1269=0270=1.25469271=100000055=GBP/USD110=500000279=1269=0270=1.25469271=300000055=GBP/USD110=1000000279=1269=0270=1.25469271=500000055=GBP/USD110=300000010=124
20260120-14:06:35.295116000 : 8=FIX.4.49=068435=X49=NTPRO_IDBA_UAT56=SIRIUS_500007460_MD34=185052=20260120-14:06:35.237262=MD_GBP/USD_140109778778268=10279=2269=0270=1.25469271=10000055=GBP/USD110=0279=2269=0270=1.25469271=50000055=GBP/USD110=100000279=2269=0270=1.25469271=100000055=GBP/USD110=500000279=2269=0270=1.25469271=300000055=GBP/USD110=1000000279=2269=0270=1.25469271=500000055=GBP/USD110=3000000279=2269=1270=1.43503271=10000055=GBP/USD110=0279=2269=1270=1.43503271=50000055=GBP/USD110=100000279=2269=1270=1.43503271=100000055=GBP/USD110=500000279=2269=1270=1.43503271=300000055=GBP/USD110=1000000279=2269=1270=1.43503271=500000055=GBP/USD110=300000010=005
20260120-14:06:35.392087000 : 8=FIX.4.49=044735=X49=NTPRO_IDBA_UAT56=SIRIUS_500007460_MD34=185152=20260120-14:06:35.372262=MD_EUR/USD_140109278614268=6279=1269=0270=1.14782271=10000055=EUR/USD110=0279=1269=0270=1.14782271=50000055=EUR/USD110=100000279=1269=0270=1.14782271=100000055=EUR/USD110=500000279=1269=1270=1.19807271=10000055=EUR/USD110=0279=1269=1270=1.19807271=50000055=EUR/USD110=100000279=1269=1270=1.19807271=100000055=EUR/USD110=50000010=065
20260120-14:06:35.441717000 : 8=FIX.4.49=044735=X49=NTPRO_IDBA_UAT56=SIRIUS_500007460_MD34=185252=20260120-14:06:35.422262=MD_EUR/USD_140109278614268=6279=1269=0270=1.14783271=10000055=EUR/USD110=0279=1269=0270=1.14783271=50000055=EUR/USD110=100000279=1269=0270=1.14783271=100000055=EUR/USD110=500000279=1269=1270=1.19808271=10000055=EUR/USD110=0279=1269=1270=1.19808271=50000055=EUR/USD110=100000279=1269=1270=1.19808271=100000055=EUR/USD110=50000010=068
20260120-14:06:35.544273000 : 8=FIX.4.49=067935=X49=NTPRO_IDBA_UAT56=SIRIUS_500007460_MD34=185352=20260120-14:06:35.465262=MD_GBP/USD_140109778778268=10279=0269=0270=1.2547271=10000055=GBP/USD110=0279=0269=0270=1.2547271=50000055=GBP/USD110=100000279=0269=0270=1.2547271=100000055=GBP/USD110=500000279=0269=0270=1.2547271=300000055=GBP/USD110=1000000279=0269=0270=1.2547271=500000055=GBP/USD110=3000000279=0269=1270=1.43504271=10000055=GBP/USD110=0279=0269=1270=1.43504271=50000055=GBP/USD110=100000279=0269=1270=1.43504271=100000055=GBP/USD110=500000279=0269=1270=1.43504271=300000055=GBP/USD110=1000000279=0269=1270=1.43504271=500000055=GBP/USD110=300000010=232
20260120-14:06:35.747754000 : 8=FIX.4.49=028035=X49=NTPRO_IDBA_UAT56=SIRIUS_500007460_MD34=185452=20260120-14:06:35.737262=MD_EUR/USD_140109278614268=3279=1269=0270=1.14784271=10000055=EUR/USD110=0279=1269=0270=1.14784271=50000055=EUR/USD110=100000279=1269=0270=1.14784271=100000055=EUR/USD110=50000010=021
20260120-14:06:35.901583000 : 8=FIX.4.49=044735=X49=NTPRO_IDBA_UAT56=SIRIUS_500007460_MD34=185552=20260120-14:06:35.896262=MD_EUR/USD_140109278614268=6279=1269=0270=1.14785271=10000055=EUR/USD110=0279=1269=0270=1.14785271=50000055=EUR/USD110=100000279=1269=0270=1.14785271=100000055=EUR/USD110=500000279=1269=1270=1.19809271=10000055=EUR/USD110=0279=1269=1270=1.19809271=50000055=EUR/USD110=100000279=1269=1270=1.19809271=100000055=EUR/USD110=50000010=095
20260120-14:06:35.910002000 : 8=FIX.4.49=039835=X49=NTPRO_IDBA_UAT56=SIRIUS_500007460_MD34=185652=20260120-14:06:35.902262=MD_GBP/USD_140109778778268=5279=1269=1270=1.43505271=10000055=GBP/USD110=0279=1269=1270=1.43505271=50000055=GBP/USD110=100000279=1269=1270=1.43505271=100000055=GBP/USD110=500000279=1269=1270=1.43505271=300000055=GBP/USD110=1000000279=1269=1270=1.43505271=500000055=GBP/USD110=300000010=083
20260120-14:06:36.192581000 : 8=FIX.4.49=028035=X49=NTPRO_IDBA_UAT56=SIRIUS_500007460_MD34=185752=20260120-14:06:36.195262=MD_EUR/USD_140109278614268=3279=1269=0270=1.14784271=10000055=EUR/USD110=0279=1269=0270=1.14784271=50000055=EUR/USD110=100000279=1269=0270=1.14784271=100000055=EUR/USD110=50000010=023
20260120-14:06:36.296016000 : 8=FIX.4.49=044435=X49=NTPRO_IDBA_UAT56=SIRIUS_500007460_MD34=185852=20260120-14:06:36.247262=MD_EUR/USD_140109278614268=6279=1269=0270=1.14785271=10000055=EUR/USD110=0279=1269=0270=1.14785271=50000055=EUR/USD110=100000279=1269=0270=1.14785271=100000055=EUR/USD110=500000279=1269=1270=1.1981271=10000055=EUR/USD110=0279=1269=1270=1.1981271=50000055=EUR/USD110=100000279=1269=1270=1.1981271=100000055=EUR/USD110=50000010=174
20260120-14:06:36.296823000 : 8=FIX.4.49=039835=X49=NTPRO_IDBA_UAT56=SIRIUS_500007460_MD34=185952=20260120-14:06:36.273262=MD_GBP/USD_140109778778268=5279=1269=0270=1.25471271=10000055=GBP/USD110=0279=1269=0270=1.25471271=50000055=GBP/USD110=100000279=1269=0270=1.25471271=100000055=GBP/USD110=500000279=1269=0270=1.25471271=300000055=GBP/USD110=1000000279=1269=0270=1.25471271=500000055=GBP/USD110=300000010=093
20260120-14:06:36.297403000 : 8=FIX.4.49=028035=X49=NTPRO_IDBA_UAT56=SIRIUS_500007460_MD34=186052=20260120-14:06:36.292262=MD_EUR/USD_140109278614268=3279=1269=0270=1.14784271=10000055=EUR/USD110=0279=1269=0270=1.14784271=50000055=EUR/USD110=100000279=1269=0270=1.14784271=100000055=EUR/USD110=50000010=015
20260120-14:06:36.332554000 : 8=FIX.4.49=028035=X49=NTPRO_IDBA_UAT56=SIRIUS_500007460_MD34=186152=20260120-14:06:36.339262=MD_EUR/USD_140109278614268=3279=1269=0270=1.14785271=10000055=EUR/USD110=0279=1269=0270=1.14785271=50000055=EUR/USD110=100000279=1269=0270=1.14785271=100000055=EUR/USD110=50000010=021
20260120-14:06:36.387868000 : 8=FIX.4.49=044735=X49=NTPRO_IDBA_UAT56=SIRIUS_500007460_MD34=186252=20260120-14:06:36.380262=MD_EUR/USD_140109278614268=6279=1269=0270=1.14786271=10000055=EUR/USD110=0279=1269=0270=1.14786271=50000055=EUR/USD110=100000279=1269=0270=1.14786271=100000055=EUR/USD110=500000279=1269=1270=1.19811271=10000055=EUR/USD110=0279=1269=1270=1.19811271=50000055=EUR/USD110=100000279=1269=1270=1.19811271=100000055=EUR/USD110=50000010=064
20260120-14:06:36.438903000 : 8=FIX.4.49=028035=X49=NTPRO_IDBA_UAT56=SIRIUS_500007460_MD34=186352=20260120-14:06:36.449262=MD_EUR/USD_140109278614268=3279=1269=0270=1.14787271=10000055=EUR/USD110=0279=1269=0270=1.14787271=50000055=EUR/USD110=100000279=1269=0270=1.14787271=100000055=EUR/USD110=50000010=031
20260120-14:06:36.522730000 : 8=FIX.4.49=039335=X49=NTPRO_IDBA_UAT56=SIRIUS_500007460_MD34=186452=20260120-14:06:36.526262=MD_GBP/USD_140109778778268=5279=1269=0270=1.2547271=10000055=GBP/USD110=0279=1269=0270=1.2547271=50000055=GBP/USD110=100000279=1269=0270=1.2547271=100000055=GBP/USD110=500000279=1269=0270=1.2547271=300000055=GBP/USD110=1000000279=1269=0270=1.2547271=500000055=GBP/USD110=300000010=096
20260120-14:06:36.546887000 : 8=FIX.4.49=028035=X49=NTPRO_IDBA_UAT56=SIRIUS_500007460_MD34=186552=20260120-14:06:36.557262=MD_EUR/USD_140109278614268=3279=1269=0270=1.14786271=10000055=EUR/USD110=0279=1269=0270=1.14786271=50000055=EUR/USD110=100000279=1269=0270=1.14786271=100000055=EUR/USD110=50000010=030
20260120-14:06:36.603944000 : 8=FIX.4.49=044735=X49=NTPRO_IDBA_UAT56=SIRIUS_500007460_MD34=186652=20260120-14:06:36.610262=MD_EUR/USD_140109278614268=6279=1269=0270=1.14785271=10000055=EUR/USD110=0279=1269=0270=1.14785271=50000055=EUR/USD110=100000279=1269=0270=1.14785271=100000055=EUR/USD110=500000279=1269=1270=1.19809271=10000055=EUR/USD110=0279=1269=1270=1.19809271=50000055=EUR/USD110=100000279=1269=1270=1.19809271=100000055=EUR/USD110=50000010=082
20260120-14:06:36.681990000 : 8=FIX.4.49=068435=X49=NTPRO_IDBA_UAT56=SIRIUS_500007460_MD34=186752=20260120-14:06:36.687262=MD_GBP/USD_140109778778268=10279=1269=0270=1.25469271=10000055=GBP/USD110=0279=1269=0270=1.25469271=50000055=GBP/USD110=100000279=1269=0270=1.25469271=100000055=GBP/USD110=500000279=1269=0270=1.25469271=300000055=GBP/USD110=1000000279=1269=0270=1.25469271=500000055=GBP/USD110=3000000279=1269=1270=1.43504271=10000055=GBP/USD110=0279=1269=1270=1.43504271=50000055=GBP/USD110=100000279=1269=1270=1.43504271=100000055=GBP/USD110=500000279=1269=1270=1.43504271=300000055=GBP/USD110=1000000279=1269=1270=1.43504271=500000055=GBP/USD110=300000010=018
20260120-14:06:36.735549000 : 8=FIX.4.49=068435=X49=NTPRO_IDBA_UAT56=SIRIUS_500007460_MD34=186852=20260120-14:06:36.754262=MD_GBP/USD_140109778778268=10279=1269=0270=1.25468271=10000055=GBP/USD110=0279=1269=0270=1.25468271=50000055=GBP/USD110=100000279=1269=0270=1.25468271=100000055=GBP/USD110=500000279=1269=0270=1.25468271=300000055=GBP/USD110=1000000279=1269=0270=1.25468271=500000055=GBP/USD110=3000000279=1269=1270=1.43503271=10000055=GBP/USD110=0279=1269=1270=1.43503271=50000055=GBP/USD110=100000279=1269=1270=1.43503271=100000055=GBP/USD110=500000279=1269=1270=1.43503271=300000055=GBP/USD110=1000000279=1269=1270=1.43503271=500000055=GBP/USD110=300000010=004
20260120-14:06:36.780584000 : 8=FIX.4.49=039835=X49=NTPRO_IDBA_UAT56=SIRIUS_500007460_MD34=186952=20260120-14:06:36.794262=MD_GBP/USD_140109778778268=5279=1269=0270=1.25469271=10000055=GBP/USD110=0279=1269=0270=1.25469271=50000055=GBP/USD110=100000279=1269=0270=1.25469271=100000055=GBP/USD110=500000279=1269=0270=1.25469271=300000055=GBP/USD110=1000000279=1269=0270=1.25469271=500000055=GBP/USD110=300000010=137
20260120-14:06:36.841278000 : 8=FIX.4.49=067935=X49=NTPRO_IDBA_UAT56=SIRIUS_500007460_MD34=187052=20260120-14:06:36.862262=MD_GBP/USD_140109778778268=10279=1269=0270=1.2547271=10000055=GBP/USD110=0279=1269=0270=1.2547271=50000055=GBP/USD110=100000279=1269=0270=1.2547271=100000055=GBP/USD110=500000279=1269=0270=1.2547271=300000055=GBP/USD110=1000000279=1269=0270=1.2547271=500000055=GBP/USD110=3000000279=1269=1270=1.43505271=10000055=GBP/USD110=0279=1269=1270=1.43505271=50000055=GBP/USD110=100000279=1269=1270=1.43505271=100000055=GBP/USD110=500000279=1269=1270=1.43505271=300000055=GBP/USD110=1000000279=1269=1270=1.43505271=500000055=GBP/USD110=300000010=248
20260120-14:06:36.884457000 : 8=FIX.4.49=039835=X49=NTPRO_IDBA_UAT56=SIRIUS_500007460_MD34=187152=20260120-14:06:36.907262=MD_GBP/USD_140109778778268=5279=1269=0270=1.25471271=10000055=GBP/USD110=0279=1269=0270=1.25471271=50000055=GBP/USD110=100000279=1269=0270=1.25471271=100000055=GBP/USD110=500000279=1269=0270=1.25471271=300000055=GBP/USD110=1000000279=1269=0270=1.25471271=500000055=GBP/USD110=300000010=091
20260120-14:06:36.984454000 : 8=FIX.4.49=027735=X49=NTPRO_IDBA_UAT56=SIRIUS_500007460_MD34=187252=20260120-14:06:36.992262=MD_EUR/USD_140109278614268=3279=1269=1270=1.1981271=10000055=EUR/USD110=0279=1269=1270=1.1981271=50000055=EUR/USD110=100000279=1269=1270=1.1981271=100000055=EUR/USD110=50000010=131
20260120-14:06:37.034978000 : 8=FIX.4.49=028035=X49=NTPRO_IDBA_UAT56=SIRIUS_500007460_MD34=187352=20260120-14:06:37.061262=MD_EUR/USD_140109278614268=3279=1269=0270=1.14786271=10000055=EUR/USD110=0279=1269=0270=1.14786271=50000055=EUR/USD110=100000279=1269=0270=1.14786271=100000055=EUR/USD110=50000010=020
20260120-14:06:37.035735000 : 8=FIX.4.49=039335=X49=NTPRO_IDBA_UAT56=SIRIUS_500007460_MD34=187452=20260120-14:06:37.063262=MD_GBP/USD_140109778778268=5279=1269=0270=1.2547271=10000055=GBP/USD110=0279=1269=0270=1.2547271=50000055=GBP/USD110=100000279=1269=0270=1.2547271=100000055=GBP/USD110=500000279=1269=0270=1.2547271=300000055=GBP/USD110=1000000279=1269=0270=1.2547271=500000055=GBP/USD110=300000010=094
20260120-14:06:37.090353000 : 8=FIX.4.49=068435=X49=NTPRO_IDBA_UAT56=SIRIUS_500007460_MD34=187552=20260120-14:06:37.119262=MD_GBP/USD_140109778778268=10279=1269=0270=1.25472271=10000055=GBP/USD110=0279=1269=0270=1.25472271=50000055=GBP/USD110=100000279=1269=0270=1.25472271=100000055=GBP/USD110=500000279=1269=0270=1.25472271=300000055=GBP/USD110=1000000279=1269=0270=1.25472271=500000055=GBP/USD110=3000000279=1269=1270=1.43506271=10000055=GBP/USD110=0279=1269=1270=1.43506271=50000055=GBP/USD110=100000279=1269=1270=1.43506271=100000055=GBP/USD110=500000279=1269=1270=1.43506271=300000055=GBP/USD110=1000000279=1269=1270=1.43506271=500000055=GBP/USD110=300000010=244
20260120-14:06:37.095078000 : 8=FIX.4.49=028035=X49=NTPRO_IDBA_UAT56=SIRIUS_500007460_MD34=187652=20260120-14:06:37.124262=MD_EUR/USD_140109278614268=3279=1269=1270=1.19812271=10000055=EUR/USD110=0279=1269=1270=1.19812271=50000055=EUR/USD110=100000279=1269=1270=1.19812271=100000055=EUR/USD110=50000010=011
20260120-14:06:37.181202000 : 8=FIX.4.49=068435=X49=NTPRO_IDBA_UAT56=SIRIUS_500007460_MD34=187752=20260120-14:06:37.210262=MD_GBP/USD_140109778778268=10279=1269=0270=1.25474271=10000055=GBP/USD110=0279=1269=0270=1.25474271=50000055=GBP/USD110=100000279=1269=0270=1.25474271=100000055=GBP/USD110=500000279=1269=0270=1.25474271=300000055=GBP/USD110=1000000279=1269=0270=1.25474271=500000055=GBP/USD110=3000000279=1269=1270=1.43508271=10000055=GBP/USD110=0279=1269=1270=1.43508271=50000055=GBP/USD110=100000279=1269=1270=1.43508271=100000055=GBP/USD110=500000279=1269=1270=1.43508271=300000055=GBP/USD110=1000000279=1269=1270=1.43508271=500000055=GBP/USD110=300000010=002
20260120-14:06:37.201464000 : 8=FIX.4.49=028035=X49=NTPRO_IDBA_UAT56=SIRIUS_500007460_MD34=187852=20260120-14:06:37.232262=MD_EUR/USD_140109278614268=3279=1269=0270=1.14787271=10000055=EUR/USD110=0279=1269=0270=1.14787271=50000055=EUR/USD110=100000279=1269=0270=1.14787271=100000055=EUR/USD110=50000010=028
20260120-14:06:37.255849000 : 8=FIX.4.49=067935=X49=NTPRO_IDBA_UAT56=SIRIUS_500007460_MD34=187952=20260120-14:06:37.289262=MD_GBP/USD_140109778778268=10279=1269=0270=1.25475271=10000055=GBP/USD110=0279=1269=0270=1.25475271=50000055=GBP/USD110=100000279=1269=0270=1.25475271=100000055=GBP/USD110=500000279=1269=0270=1.25475271=300000055=GBP/USD110=1000000279=1269=0270=1.25475271=500000055=GBP/USD110=3000000279=1269=1270=1.4351271=10000055=GBP/USD110=0279=1269=1270=1.4351271=50000055=GBP/USD110=100000279=1269=1270=1.4351271=100000055=GBP/USD110=500000279=1269=1270=1.4351271=300000055=GBP/USD110=1000000279=1269=1270=1.4351271=500000055=GBP/USD110=300000010=010
20260120-14:06:37.380804000 : 8=FIX.4.49=028035=X49=NTPRO_IDBA_UAT56=SIRIUS_500007460_MD34=188052=20260120-14:06:37.415262=MD_EUR/USD_140109278614268=3279=1269=0270=1.14788271=10000055=EUR/USD110=0279=1269=0270=1.14788271=50000055=EUR/USD110=100000279=1269=0270=1.14788271=100000055=EUR/USD110=50000010=027
20260120-14:06:37.518444000 : 8=FIX.4.49=044735=X49=NTPRO_IDBA_UAT56=SIRIUS_500007460_MD34=188152=20260120-14:06:37.561262=MD_EUR/USD_140109278614268=6279=1269=0270=1.14789271=10000055=EUR/USD110=0279=1269=0270=1.14789271=50000055=EUR/USD110=100000279=1269=0270=1.14789271=100000055=EUR/USD110=500000279=1269=1270=1.19813271=10000055=EUR/USD110=0279=1269=1270=1.19813271=50000055=EUR/USD110=100000279=1269=1270=1.19813271=100000055=EUR/USD110=50000010=082
20260120-14:06:37.674764000 : 8=FIX.4.49=039835=X49=NTPRO_IDBA_UAT56=SIRIUS_500007460_MD34=188252=20260120-14:06:37.722262=MD_GBP/USD_140109778778268=5279=1269=1270=1.43509271=10000055=GBP/USD110=0279=1269=1270=1.43509271=50000055=GBP/USD110=100000279=1269=1270=1.43509271=100000055=GBP/USD110=500000279=1269=1270=1.43509271=300000055=GBP/USD110=1000000279=1269=1270=1.43509271=500000055=GBP/USD110=300000010=104
20260120-14:06:37.879202000 : 8=FIX.4.49=039835=X49=NTPRO_IDBA_UAT56=SIRIUS_500007460_MD34=188352=20260120-14:06:37.898262=MD_GBP/USD_140109778778268=5279=1269=0270=1.25474271=10000055=GBP/USD110=0279=1269=0270=1.25474271=50000055=GBP/USD110=100000279=1269=0270=1.25474271=100000055=GBP/USD110=500000279=1269=0270=1.25474271=300000055=GBP/USD110=1000000279=1269=0270=1.25474271=500000055=GBP/USD110=300000010=119
20260120-14:06:37.929187000 : 8=FIX.4.49=044735=X49=NTPRO_IDBA_UAT56=SIRIUS_500007460_MD34=188452=20260120-14:06:37.987262=MD_EUR/USD_140109278614268=6279=1269=0270=1.14788271=10000055=EUR/USD110=0279=1269=0270=1.14788271=50000055=EUR/USD110=100000279=1269=0270=1.14788271=100000055=EUR/USD110=500000279=1269=1270=1.19812271=10000055=EUR/USD110=0279=1269=1270=1.19812271=50000055=EUR/USD110=100000279=1269=1270=1.19812271=100000055=EUR/USD110=50000010=091
20260120-14:06:37.984917000 : 8=FIX.4.49=067935=X49=NTPRO_IDBA_UAT56=SIRIUS_500007460_MD34=188552=20260120-14:06:38.044262=MD_GBP/USD_140109778778268=10279=1269=0270=1.25475271=10000055=GBP/USD110=0279=1269=0270=1.25475271=50000055=GBP/USD110=100000279=1269=0270=1.25475271=100000055=GBP/USD110=500000279=1269=0270=1.25475271=300000055=GBP/USD110=1000000279=1269=0270=1.25475271=500000055=GBP/USD110=3000000279=1269=1270=1.4351271=10000055=GBP/USD110=0279=1269=1270=1.4351271=50000055=GBP/USD110=100000279=1269=1270=1.4351271=100000055=GBP/USD110=500000279=1269=1270=1.4351271=300000055=GBP/USD110=1000000279=1269=1270=1.4351271=500000055=GBP/USD110=300000010=253
20260120-14:06:38.126356000 : 8=FIX.4.49=028035=X49=NTPRO_IDBA_UAT56=SIRIUS_500007460_MD34=188652=20260120-14:06:38.191262=MD_EUR/USD_140109278614268=3279=1269=0270=1.14787271=10000055=EUR/USD110=0279=1269=0270=1.14787271=50000055=EUR/USD110=100000279=1269=0270=1.14787271=100000055=EUR/USD110=50000010=032
20260120-14:06:38.147872000 : 8=FIX.4.49=068435=X49=NTPRO_IDBA_UAT56=SIRIUS_500007460_MD34=188752=20260120-14:06:38.213262=MD_GBP/USD_140109778778268=10279=1269=0270=1.25474271=10000055=GBP/USD110=0279=1269=0270=1.25474271=50000055=GBP/USD110=100000279=1269=0270=1.25474271=100000055=GBP/USD110=500000279=1269=0270=1.25474271=300000055=GBP/USD110=1000000279=1269=0270=1.25474271=500000055=GBP/USD110=3000000279=1269=1270=1.43509271=10000055=GBP/USD110=0279=1269=1270=1.43509271=50000055=GBP/USD110=100000279=1269=1270=1.43509271=100000055=GBP/USD110=500000279=1269=1270=1.43509271=300000055=GBP/USD110=1000000279=1269=1270=1.43509271=500000055=GBP/USD110=300000010=012
20260120-14:06:38.245735000 : 8=FIX.4.49=044735=X49=NTPRO_IDBA_UAT56=SIRIUS_500007460_MD34=188852=20260120-14:06:38.313262=MD_EUR/USD_140109278614268=6279=1269=0270=1.14788271=10000055=EUR/USD110=0279=1269=0270=1.14788271=50000055=EUR/USD110=100000279=1269=0270=1.14788271=100000055=EUR/USD110=500000279=1269=1270=1.19813271=10000055=EUR/USD110=0279=1269=1270=1.19813271=50000055=EUR/USD110=100000279=1269=1270=1.19813271=100000055=EUR/USD110=50000010=082
20260120-14:06:38.311500000 : 8=FIX.4.49=039835=X49=NTPRO_IDBA_UAT56=SIRIUS_500007460_MD34=188952=20260120-14:06:38.382262=MD_GBP/USD_140109778778268=5279=1269=0270=1.25473271=10000055=GBP/USD110=0279=1269=0270=1.25473271=50000055=GBP/USD110=100000279=1269=0270=1.25473271=100000055=GBP/USD110=500000279=1269=0270=1.25473271=300000055=GBP/USD110=1000000279=1269=0270=1.25473271=500000055=GBP/USD110=300000010=109
20260120-14:06:38.404898000 : 8=FIX.4.49=028035=X49=NTPRO_IDBA_UAT56=SIRIUS_500007460_MD34=189052=20260120-14:06:38.479262=MD_EUR/USD_140109278614268=3279=1269=0270=1.14787271=10000055=EUR/USD110=0279=1269=0270=1.14787271=50000055=EUR/USD110=100000279=1269=0270=1.14787271=100000055=EUR/USD110=50000010=036
20260120-14:06:38.424524000 : 8=FIX.4.49=067935=X49=NTPRO_IDBA_UAT56=SIRIUS_500007460_MD34=189152=20260120-14:06:38.499262=MD_GBP/USD_140109778778268=10279=1269=0270=1.25474271=10000055=GBP/USD110=0279=1269=0270=1.25474271=50000055=GBP/USD110=100000279=1269=0270=1.25474271=100000055=GBP/USD110=500000279=1269=0270=1.25474271=300000055=GBP/USD110=1000000279=1269=0270=1.25474271=500000055=GBP/USD110=3000000279=1269=1270=1.4351271=10000055=GBP/USD110=0279=1269=1270=1.4351271=50000055=GBP/USD110=100000279=1269=1270=1.4351271=100000055=GBP/USD110=500000279=1269=1270=1.4351271=300000055=GBP/USD110=1000000279=1269=1270=1.4351271=500000055=GBP/USD110=300000010=003
20260120-14:06:38.512308000 : 8=FIX.4.49=028035=X49=NTPRO_IDBA_UAT56=SIRIUS_500007460_MD34=189252=20260120-14:06:38.588262=MD_EUR/USD_140109278614268=3279=1269=0270=1.14789271=10000055=EUR/USD110=0279=1269=0270=1.14789271=50000055=EUR/USD110=100000279=1269=0270=1.14789271=100000055=EUR/USD110=50000010=045
20260120-14:06:38.591258000 : 8=FIX.4.49=039835=X49=NTPRO_IDBA_UAT56=SIRIUS_500007460_MD34=189352=20260120-14:06:38.672262=MD_GBP/USD_140109778778268=5279=1269=0270=1.25475271=10000055=GBP/USD110=0279=1269=0270=1.25475271=50000055=GBP/USD110=100000279=1269=0270=1.25475271=100000055=GBP/USD110=500000279=1269=0270=1.25475271=300000055=GBP/USD110=1000000279=1269=0270=1.25475271=500000055=GBP/USD110=300000010=116
20260120-14:06:38.900981000 : 8=FIX.4.49=068435=X49=NTPRO_IDBA_UAT56=SIRIUS_500007460_MD34=189452=20260120-14:06:38.993262=MD_GBP/USD_140109778778268=10279=1269=0270=1.25469271=10000055=GBP/USD110=0279=1269=0270=1.25469271=50000055=GBP/USD110=100000279=1269=0270=1.25469271=100000055=GBP/USD110=500000279=1269=0270=1.25469271=300000055=GBP/USD110=1000000279=1269=0270=1.25469271=500000055=GBP/USD110=3000000279=1269=1270=1.43504271=10000055=GBP/USD110=0279=1269=1270=1.43504271=50000055=GBP/USD110=100000279=1269=1270=1.43504271=100000055=GBP/USD110=500000279=1269=1270=1.43504271=300000055=GBP/USD110=1000000279=1269=1270=1.43504271=500000055=GBP/USD110=300000010=020
20260120-14:06:38.930690000 : 8=FIX.4.49=044735=X49=NTPRO_IDBA_UAT56=SIRIUS_500007460_MD34=189552=20260120-14:06:39.023262=MD_EUR/USD_140109278614268=6279=1269=0270=1.14786271=10000055=EUR/USD110=0279=1269=0270=1.14786271=50000055=EUR/USD110=100000279=1269=0270=1.14786271=100000055=EUR/USD110=500000279=1269=1270=1.19811271=10000055=EUR/USD110=0279=1269=1270=1.19811271=50000055=EUR/USD110=100000279=1269=1270=1.19811271=100000055=EUR/USD110=50000010=067
20260120-14:06:39.065424000 : 8=FIX.4.49=044735=X49=NTPRO_IDBA_UAT56=SIRIUS_500007460_MD34=189652=20260120-14:06:39.163262=MD_EUR/USD_140109278614268=6279=1269=0270=1.14785271=10000055=EUR/USD110=0279=1269=0270=1.14785271=50000055=EUR/USD110=100000279=1269=0270=1.14785271=100000055=EUR/USD110=500000279=1269=1270=1.19809271=10000055=EUR/USD110=0279=1269=1270=1.19809271=50000055=EUR/USD110=100000279=1269=1270=1.19809271=100000055=EUR/USD110=50000010=091
20260120-14:06:39.077767000 : 8=FIX.4.49=039835=X49=NTPRO_IDBA_UAT56=SIRIUS_500007460_MD34=189752=20260120-14:06:39.169262=MD_GBP/USD_140109778778268=5279=1269=1270=1.43503271=10000055=GBP/USD110=0279=1269=1270=1.43503271=50000055=GBP/USD110=100000279=1269=1270=1.43503271=100000055=GBP/USD110=500000279=1269=1270=1.43503271=300000055=GBP/USD110=1000000279=1269=1270=1.43503271=500000055=GBP/USD110=300000010=087
20260120-14:06:39.411193000 : 8=FIX.4.49=028035=X49=NTPRO_IDBA_UAT56=SIRIUS_500007460_MD34=189852=20260120-14:06:39.521262=MD_EUR/USD_140109278614268=3279=1269=0270=1.14784271=10000055=EUR/USD110=0279=1269=0270=1.14784271=50000055=EUR/USD110=100000279=1269=0270=1.14784271=100000055=EUR/USD110=50000010=024
20260120-14:06:39.479658000 : 8=FIX.4.49=028035=X49=NTPRO_IDBA_UAT56=SIRIUS_500007460_MD34=189952=20260120-14:06:39.592262=MD_EUR/USD_140109278614268=3279=1269=0270=1.14785271=10000055=EUR/USD110=0279=1269=0270=1.14785271=50000055=EUR/USD110=100000279=1269=0270=1.14785271=100000055=EUR/USD110=50000010=036
20260120-14:06:39.674686000 : 8=FIX.4.49=039835=X49=NTPRO_IDBA_UAT56=SIRIUS_500007460_MD34=190052=20260120-14:06:39.789262=MD_GBP/USD_140109778778268=5279=1269=0270=1.25468271=10000055=GBP/USD110=0279=1269=0270=1.25468271=50000055=GBP/USD110=100000279=1269=0270=1.25468271=100000055=GBP/USD110=500000279=1269=0270=1.25468271=300000055=GBP/USD110=1000000279=1269=0270=1.25468271=500000055=GBP/USD110=300000010=125
20260120-14:06:39.695298000 : 8=FIX.4.49=028035=X49=NTPRO_IDBA_UAT56=SIRIUS_500007460_MD34=190152=20260120-14:06:39.816262=MD_EUR/USD_140109278614268=3279=1269=0270=1.14784271=10000055=EUR/USD110=0279=1269=0270=1.14784271=50000055=EUR/USD110=100000279=1269=0270=1.14784271=100000055=EUR/USD110=50000010=016
20260120-14:06:39.929105000 : 8=FIX.4.49=068435=X49=NTPRO_IDBA_UAT56=SIRIUS_500007460_MD34=190252=20260120-14:06:40.051262=MD_GBP/USD_140109778778268=10279=1269=0270=1.25469271=10000055=GBP/USD110=0279=1269=0270=1.25469271=50000055=GBP/USD110=100000279=1269=0270=1.25469271=100000055=GBP/USD110=500000279=1269=0270=1.25469271=300000055=GBP/USD110=1000000279=1269=0270=1.25469271=500000055=GBP/USD110=3000000279=1269=1270=1.43504271=10000055=GBP/USD110=0279=1269=1270=1.43504271=50000055=GBP/USD110=100000279=1269=1270=1.43504271=100000055=GBP/USD110=500000279=1269=1270=1.43504271=300000055=GBP/USD110=1000000279=1269=1270=1.43504271=500000055=GBP/USD110=300000010=244
20260120-14:06:39.951446000 : 8=FIX.4.49=039335=X49=NTPRO_IDBA_UAT56=SIRIUS_500007460_MD34=190352=20260120-14:06:40.080262=MD_GBP/USD_140109778778268=5279=1269=0270=1.2547271=10000055=GBP/USD110=0279=1269=0270=1.2547271=50000055=GBP/USD110=100000279=1269=0270=1.2547271=100000055=GBP/USD110=500000279=1269=0270=1.2547271=300000055=GBP/USD110=1000000279=1269=0270=1.2547271=500000055=GBP/USD110=300000010=080
20260120-14:06:40.048902000 : 8=FIX.4.49=028035=X49=NTPRO_IDBA_UAT56=SIRIUS_500007460_MD34=190452=20260120-14:06:40.153262=MD_EUR/USD_140109278614268=3279=1269=0270=1.14785271=10000055=EUR/USD110=0279=1269=0270=1.14785271=50000055=EUR/USD110=100000279=1269=0270=1.14785271=100000055=EUR/USD110=50000010=008
20260120-14:06:40.176904000 : 8=FIX.4.49=039835=X49=NTPRO_IDBA_UAT56=SIRIUS_500007460_MD34=190552=20260120-14:06:40.314262=MD_GBP/USD_140109778778268=5279=1269=1270=1.43505271=10000055=GBP/USD110=0279=1269=1270=1.43505271=50000055=GBP/USD110=100000279=1269=1270=1.43505271=100000055=GBP/USD110=500000279=1269=1270=1.43505271=300000055=GBP/USD110=1000000279=1269=1270=1.43505271=500000055=GBP/USD110=300000010=071
20260120-14:06:40.215099000 : 8=FIX.4.49=027735=X49=NTPRO_IDBA_UAT56=SIRIUS_500007460_MD34=190652=20260120-14:06:40.354262=MD_EUR/USD_140109278614268=3279=1269=1270=1.1981271=10000055=EUR/USD110=0279=1269=1270=1.1981271=50000055=EUR/USD110=100000279=1269=1270=1.1981271=100000055=EUR/USD110=50000010=116
20260120-14:06:40.259491000 : 8=FIX.4.49=028035=X49=NTPRO_IDBA_UAT56=SIRIUS_500007460_MD34=190752=20260120-14:06:40.398262=MD_EUR/USD_140109278614268=3279=1269=0270=1.14786271=10000055=EUR/USD110=0279=1269=0270=1.14786271=50000055=EUR/USD110=100000279=1269=0270=1.14786271=100000055=EUR/USD110=50000010=025
20260120-14:06:40.777356000 : 8=FIX.4.49=039835=X49=NTPRO_IDBA_UAT56=SIRIUS_500007460_MD34=190852=20260120-14:06:40.936262=MD_GBP/USD_140109778778268=5279=1269=1270=1.43504271=10000055=GBP/USD110=0279=1269=1270=1.43504271=50000055=GBP/USD110=100000279=1269=1270=1.43504271=100000055=GBP/USD110=500000279=1269=1270=1.43504271=300000055=GBP/USD110=1000000279=1269=1270=1.43504271=500000055=GBP/USD110=300000010=079
20260120-14:06:40.840078000 : 8=FIX.4.49=039835=X49=NTPRO_IDBA_UAT56=SIRIUS_500007460_MD34=190952=20260120-14:06:40.987262=MD_GBP/USD_140109778778268=5279=1269=0270=1.25472271=10000055=GBP/USD110=0279=1269=0270=1.25472271=50000055=GBP/USD110=100000279=1269=0270=1.25472271=100000055=GBP/USD110=500000279=1269=0270=1.25472271=300000055=GBP/USD110=1000000279=1269=0270=1.25472271=500000055=GBP/USD110=300000010=101
20260120-14:06:40.860946000 : 8=FIX.4.49=039835=X49=NTPRO_IDBA_UAT56=SIRIUS_500007460_MD34=191052=20260120-14:06:41.018262=MD_GBP/USD_140109778778268=5279=1269=1270=1.43505271=10000055=GBP/USD110=0279=1269=1270=1.43505271=50000055=GBP/USD110=100000279=1269=1270=1.43505271=100000055=GBP/USD110=500000279=1269=1270=1.43505271=300000055=GBP/USD110=1000000279=1269=1270=1.43505271=500000055=GBP/USD110=300000010=069
20260120-14:06:40.937918000 : 8=FIX.4.49=068435=X49=NTPRO_IDBA_UAT56=SIRIUS_500007460_MD34=191152=20260120-14:06:41.089262=MD_GBP/USD_140109778778268=10279=1269=0270=1.25473271=10000055=GBP/USD110=0279=1269=0270=1.25473271=50000055=GBP/USD110=100000279=1269=0270=1.25473271=100000055=GBP/USD110=500000279=1269=0270=1.25473271=300000055=GBP/USD110=1000000279=1269=0270=1.25473271=500000055=GBP/USD110=3000000279=1269=1270=1.43507271=10000055=GBP/USD110=0279=1269=1270=1.43507271=50000055=GBP/USD110=100000279=1269=1270=1.43507271=100000055=GBP/USD110=500000279=1269=1270=1.43507271=300000055=GBP/USD110=1000000279=1269=1270=1.43507271=500000055=GBP/USD110=300000010=246
20260120-14:06:40.953303000 : 8=FIX.4.49=028035=X49=NTPRO_IDBA_UAT56=SIRIUS_500007460_MD34=191252=20260120-14:06:41.118262=MD_EUR/USD_140109278614268=3279=1269=1270=1.19811271=10000055=EUR/USD110=0279=1269=1270=1.19811271=50000055=EUR/USD110=100000279=1269=1270=1.19811271=100000055=EUR/USD110=50000010=253
20260120-14:06:40.988632000 : 8=FIX.4.49=068435=X49=NTPRO_IDBA_UAT56=SIRIUS_500007460_MD34=191352=20260120-14:06:41.154262=MD_GBP/USD_140109778778268=10279=1269=0270=1.25474271=10000055=GBP/USD110=0279=1269=0270=1.25474271=50000055=GBP/USD110=100000279=1269=0270=1.25474271=100000055=GBP/USD110=500000279=1269=0270=1.25474271=300000055=GBP/USD110=1000000279=1269=0270=1.25474271=500000055=GBP/USD110=3000000279=1269=1270=1.43508271=10000055=GBP/USD110=0279=1269=1270=1.43508271=50000055=GBP/USD110=100000279=1269=1270=1.43508271=100000055=GBP/USD110=500000279=1269=1270=1.43508271=300000055=GBP/USD110=1000000279=1269=1270=1.43508271=500000055=GBP/USD110=300000010=251
20260120-14:06:41.070364000 : 8=FIX.4.49=044735=X49=NTPRO_IDBA_UAT56=SIRIUS_500007460_MD34=191452=20260120-14:06:41.239262=MD_EUR/USD_140109278614268=6279=1269=0270=1.14788271=10000055=EUR/USD110=0279=1269=0270=1.14788271=50000055=EUR/USD110=100000279=1269=0270=1.14788271=100000055=EUR/USD110=500000279=1269=1270=1.19812271=10000055=EUR/USD110=0279=1269=1270=1.19812271=50000055=EUR/USD110=100000279=1269=1270=1.19812271=100000055=EUR/USD110=50000010=070
20260120-14:06:41.089620000 : 8=FIX.4.49=067935=X49=NTPRO_IDBA_UAT56=SIRIUS_500007460_MD34=191552=20260120-14:06:41.259262=MD_GBP/USD_140109778778268=10279=1269=0270=1.25475271=10000055=GBP/USD110=0279=1269=0270=1.25475271=50000055=GBP/USD110=100000279=1269=0270=1.25475271=100000055=GBP/USD110=500000279=1269=0270=1.25475271=300000055=GBP/USD110=1000000279=1269=0270=1.25475271=500000055=GBP/USD110=3000000279=1269=1270=1.4351271=10000055=GBP/USD110=0279=1269=1270=1.4351271=50000055=GBP/USD110=100000279=1269=1270=1.4351271=100000055=GBP/USD110=500000279=1269=1270=1.4351271=300000055=GBP/USD110=1000000279=1269=1270=1.4351271=500000055=GBP/USD110=300000010=249
20260120-14:06:41.209279000 : 8=FIX.4.49=028035=X49=NTPRO_IDBA_UAT56=SIRIUS_500007460_MD34=191652=20260120-14:06:41.381262=MD_EUR/USD_140109278614268=3279=1269=1270=1.19813271=10000055=EUR/USD110=0279=1269=1270=1.19813271=50000055=EUR/USD110=100000279=1269=1270=1.19813271=100000055=EUR/USD110=50000010=009
20260120-14:06:41.570875000 : 8=FIX.4.49=039835=X49=NTPRO_IDBA_UAT56=SIRIUS_500007460_MD34=191752=20260120-14:06:41.756262=MD_GBP/USD_140109778778268=5279=1269=1270=1.43509271=10000055=GBP/USD110=0279=1269=1270=1.43509271=50000055=GBP/USD110=100000279=1269=1270=1.43509271=100000055=GBP/USD110=500000279=1269=1270=1.43509271=300000055=GBP/USD110=1000000279=1269=1270=1.43509271=500000055=GBP/USD110=300000010=105
20260120-14:06:41.659841000 : 8=FIX.4.49=044735=X49=NTPRO_IDBA_UAT56=SIRIUS_500007460_MD34=191852=20260120-14:06:41.836262=MD_EUR/USD_140109278614268=6279=1269=0270=1.14786271=10000055=EUR/USD110=0279=1269=0270=1.14786271=50000055=EUR/USD110=100000279=1269=0270=1.14786271=100000055=EUR/USD110=500000279=1269=1270=1.19811271=10000055=EUR/USD110=0279=1269=1270=1.19811271=50000055=EUR/USD110=100000279=1269=1270=1.19811271=100000055=EUR/USD110=50000010=068
20260120-14:06:41.660627000 : 8=FIX.4.49=068435=X49=NTPRO_IDBA_UAT56=SIRIUS_500007460_MD34=191952=20260120-14:06:41.848262=MD_GBP/USD_140109778778268=10279=1269=0270=1.25473271=10000055=GBP/USD110=0279=1269=0270=1.25473271=50000055=GBP/USD110=100000279=1269=0270=1.25473271=100000055=GBP/USD110=500000279=1269=0270=1.25473271=300000055=GBP/USD110=1000000279=1269=0270=1.25473271=500000055=GBP/USD110=3000000279=1269=1270=1.43508271=10000055=GBP/USD110=0279=1269=1270=1.43508271=50000055=GBP/USD110=100000279=1269=1270=1.43508271=100000055=GBP/USD110=500000279=1269=1270=1.43508271=300000055=GBP/USD110=1000000279=1269=1270=1.43508271=500000055=GBP/USD110=300000010=006
20260120-14:06:41.729029000 : 8=FIX.4.49=044435=X49=NTPRO_IDBA_UAT56=SIRIUS_500007460_MD34=192052=20260120-14:06:41.911262=MD_EUR/USD_140109278614268=6279=1269=0270=1.14785271=10000055=EUR/USD110=0279=1269=0270=1.14785271=50000055=EUR/USD110=100000279=1269=0270=1.14785271=100000055=EUR/USD110=500000279=1269=1270=1.1981271=10000055=EUR/USD110=0279=1269=1270=1.1981271=50000055=EUR/USD110=100000279=1269=1270=1.1981271=100000055=EUR/USD110=50000010=158
20260120-14:06:41.753376000 : 8=FIX.4.49=028035=X49=NTPRO_IDBA_UAT56=SIRIUS_500007460_MD34=192152=20260120-14:06:41.947262=MD_EUR/USD_140109278614268=3279=1269=0270=1.14786271=10000055=EUR/USD110=0279=1269=0270=1.14786271=50000055=EUR/USD110=100000279=1269=0270=1.14786271=100000055=EUR/USD110=50000010=022
20260120-14:06:41.849339000 : 8=FIX.4.49=039835=X49=NTPRO_IDBA_UAT56=SIRIUS_500007460_MD34=192252=20260120-14:06:42.042262=MD_GBP/USD_140109778778268=5279=1269=1270=1.43507271=10000055=GBP/USD110=0279=1269=1270=1.43507271=50000055=GBP/USD110=100000279=1269=1270=1.43507271=100000055=GBP/USD110=500000279=1269=1270=1.43507271=300000055=GBP/USD110=1000000279=1269=1270=1.43507271=500000055=GBP/USD110=300000010=080
20260120-14:06:42.124458000 : 8=FIX.4.49=039835=X49=NTPRO_IDBA_UAT56=SIRIUS_500007460_MD34=192352=20260120-14:06:42.328262=MD_GBP/USD_140109778778268=5279=1269=1270=1.43508271=10000055=GBP/USD110=0279=1269=1270=1.43508271=50000055=GBP/USD110=100000279=1269=1270=1.43508271=100000055=GBP/USD110=500000279=1269=1270=1.43508271=300000055=GBP/USD110=1000000279=1269=1270=1.43508271=500000055=GBP/USD110=300000010=093
20260120-14:06:42.150194000 : 8=FIX.4.49=068435=X49=NTPRO_IDBA_UAT56=SIRIUS_500007460_MD34=192452=20260120-14:06:42.357262=MD_GBP/USD_140109778778268=10279=1269=0270=1.25472271=10000055=GBP/USD110=0279=1269=0270=1.25472271=50000055=GBP/USD110=100000279=1269=0270=1.25472271=100000055=GBP/USD110=500000279=1269=0270=1.25472271=300000055=GBP/USD110=1000000279=1269=0270=1.25472271=500000055=GBP/USD110=3000000279=1269=1270=1.43507271=10000055=GBP/USD110=0279=1269=1270=1.43507271=50000055=GBP/USD110=100000279=1269=1270=1.43507271=100000055=GBP/USD110=500000279=1269=1270=1.43507271=300000055=GBP/USD110=1000000279=1269=1270=1.43507271=500000055=GBP/USD110=300000010=244
20260120-14:06:42.237769000 : 8=FIX.4.49=028035=X49=NTPRO_IDBA_UAT56=SIRIUS_500007460_MD34=192552=20260120-14:06:42.448262=MD_EUR/USD_140109278614268=3279=1269=0270=1.14785271=10000055=EUR/USD110=0279=1269=0270=1.14785271=50000055=EUR/USD110=100000279=1269=0270=1.14785271=100000055=EUR/USD110=50000010=020
20260120-14:06:42.244505000 : 8=FIX.4.49=068435=X49=NTPRO_IDBA_UAT56=SIRIUS_500007460_MD34=192652=20260120-14:06:42.455262=MD_GBP/USD_140109778778268=10279=1269=0270=1.25471271=10000055=GBP/USD110=0279=1269=0270=1.25471271=50000055=GBP/USD110=100000279=1269=0270=1.25471271=100000055=GBP/USD110=500000279=1269=0270=1.25471271=300000055=GBP/USD110=1000000279=1269=0270=1.25471271=500000055=GBP/USD110=3000000279=1269=1270=1.43506271=10000055=GBP/USD110=0279=1269=1270=1.43506271=50000055=GBP/USD110=100000279=1269=1270=1.43506271=100000055=GBP/USD110=500000279=1269=1270=1.43506271=300000055=GBP/USD110=1000000279=1269=1270=1.43506271=500000055=GBP/USD110=300000010=235
20260120-14:06:42.284754000 : 8=FIX.4.49=028035=X49=NTPRO_IDBA_UAT56=SIRIUS_500007460_MD34=192752=20260120-14:06:42.497262=MD_EUR/USD_140109278614268=3279=1269=1270=1.19809271=10000055=EUR/USD110=0279=1269=1270=1.19809271=50000055=EUR/USD110=100000279=1269=1270=1.19809271=100000055=EUR/USD110=50000010=035
20260120-14:06:42.370199000 : 8=FIX.4.49=027735=X49=NTPRO_IDBA_UAT56=SIRIUS_500007460_MD34=192852=20260120-14:06:42.585262=MD_EUR/USD_140109278614268=3279=1269=1270=1.1981271=10000055=EUR/USD110=0279=1269=1270=1.1981271=50000055=EUR/USD110=100000279=1269=1270=1.1981271=100000055=EUR/USD110=50000010=128
20260120-14:06:42.427442000 : 8=FIX.4.49=028035=X49=NTPRO_IDBA_UAT56=SIRIUS_500007460_MD34=192952=20260120-14:06:42.615262=MD_EUR/USD_140109278614268=3279=1269=0270=1.14786271=10000055=EUR/USD110=0279=1269=0270=1.14786271=50000055=EUR/USD110=100000279=1269=0270=1.14786271=100000055=EUR/USD110=50000010=023
20260120-14:06:42.520194000 : 8=FIX.4.49=044735=X49=NTPRO_IDBA_UAT56=SIRIUS_500007460_MD34=193052=20260120-14:06:42.722262=MD_EUR/USD_140109278614268=6279=1269=0270=1.14785271=10000055=EUR/USD110=0279=1269=0270=1.14785271=50000055=EUR/USD110=100000279=1269=0270=1.14785271=100000055=EUR/USD110=500000279=1269=1270=1.19809271=10000055=EUR/USD110=0279=1269=1270=1.19809271=50000055=EUR/USD110=100000279=1269=1270=1.19809271=100000055=EUR/USD110=50000010=075
20260120-14:06:42.687171000 : 8=FIX.4.49=044435=X49=NTPRO_IDBA_UAT56=SIRIUS_500007460_MD34=193152=20260120-14:06:42.913262=MD_EUR/USD_140109278614268=6279=1269=0270=1.14786271=10000055=EUR/USD110=0279=1269=0270=1.14786271=50000055=EUR/USD110=100000279=1269=0270=1.14786271=100000055=EUR/USD110=500000279=1269=1270=1.1981271=10000055=EUR/USD110=0279=1269=1270=1.1981271=50000055=EUR/USD110=100000279=1269=1270=1.1981271=100000055=EUR/USD110=50000010=166
20260120-14:06:42.976050000 : 8=FIX.4.49=039835=X49=NTPRO_IDBA_UAT56=SIRIUS_500007460_MD34=193252=20260120-14:06:43.193262=MD_GBP/USD_140109778778268=5279=1269=0270=1.25472271=10000055=GBP/USD110=0279=1269=0270=1.25472271=50000055=GBP/USD110=100000279=1269=0270=1.25472271=100000055=GBP/USD110=500000279=1269=0270=1.25472271=300000055=GBP/USD110=1000000279=1269=0270=1.25472271=500000055=GBP/USD110=300000010=089
20260120-14:06:43.292290000 : 8=FIX.4.49=044735=X49=NTPRO_IDBA_UAT56=SIRIUS_500007460_MD34=193352=20260120-14:06:43.540262=MD_EUR/USD_140109278614268=6279=1269=0270=1.14785271=10000055=EUR/USD110=0279=1269=0270=1.14785271=50000055=EUR/USD110=100000279=1269=0270=1.14785271=100000055=EUR/USD110=500000279=1269=1270=1.19811271=10000055=EUR/USD110=0279=1269=1270=1.19811271=50000055=EUR/USD110=100000279=1269=1270=1.19811271=100000055=EUR/USD110=50000010=056
20260120-14:06:43.319283000 : 8=FIX.4.49=068435=X49=NTPRO_IDBA_UAT56=SIRIUS_500007460_MD34=193452=20260120-14:06:43.568262=MD_GBP/USD_140109778778268=10279=2269=0270=1.25472271=10000055=GBP/USD110=0279=2269=0270=1.25472271=50000055=GBP/USD110=100000279=2269=0270=1.25472271=100000055=GBP/USD110=500000279=2269=0270=1.25472271=300000055=GBP/USD110=1000000279=2269=0270=1.25472271=500000055=GBP/USD110=3000000279=2269=1270=1.43506271=10000055=GBP/USD110=0279=2269=1270=1.43506271=50000055=GBP/USD110=100000279=2269=1270=1.43506271=100000055=GBP/USD110=500000279=2269=1270=1.43506271=300000055=GBP/USD110=1000000279=2269=1270=1.43506271=500000055=GBP/USD110=300000010=255
20260120-14:06:43.356956000 : 8=FIX.4.49=067935=X49=NTPRO_IDBA_UAT56=SIRIUS_500007460_MD34=193552=20260120-14:06:43.607262=MD_GBP/USD_140109778778268=10279=0269=0270=1.2547271=10000055=GBP/USD110=0279=0269=0270=1.2547271=50000055=GBP/USD110=100000279=0269=0270=1.2547271=100000055=GBP/USD110=500000279=0269=0270=1.2547271=300000055=GBP/USD110=1000000279=0269=0270=1.2547271=500000055=GBP/USD110=3000000279=0269=1270=1.43505271=10000055=GBP/USD110=0279=0269=1270=1.43505271=50000055=GBP/USD110=100000279=0269=1270=1.43505271=100000055=GBP/USD110=500000279=0269=1270=1.43505271=300000055=GBP/USD110=1000000279=0269=1270=1.43505271=500000055=GBP/USD110=300000010=235
20260120-14:06:43.408912000 : 8=FIX.4.49=028035=X49=NTPRO_IDBA_UAT56=SIRIUS_500007460_MD34=193652=20260120-14:06:43.660262=MD_EUR/USD_140109278614268=3279=1269=0270=1.14786271=10000055=EUR/USD110=0279=1269=0270=1.14786271=50000055=EUR/USD110=100000279=1269=0270=1.14786271=100000055=EUR/USD110=50000010=022
20260120-14:06:43.437474000 : 8=FIX.4.49=068435=X49=NTPRO_IDBA_UAT56=SIRIUS_500007460_MD34=193752=20260120-14:06:43.691262=MD_GBP/USD_140109778778268=10279=1269=0270=1.25469271=10000055=GBP/USD110=0279=1269=0270=1.25469271=50000055=GBP/USD110=100000279=1269=0270=1.25469271=100000055=GBP/USD110=500000279=1269=0270=1.25469271=300000055=GBP/USD110=1000000279=1269=0270=1.25469271=500000055=GBP/USD110=3000000279=1269=1270=1.43504271=10000055=GBP/USD110=0279=1269=1270=1.43504271=50000055=GBP/USD110=100000279=1269=1270=1.43504271=100000055=GBP/USD110=500000279=1269=1270=1.43504271=300000055=GBP/USD110=1000000279=1269=1270=1.43504271=500000055=GBP/USD110=300000010=009
20260120-14:06:43.734758000 : 8=FIX.4.49=039335=X49=NTPRO_IDBA_UAT56=SIRIUS_500007460_MD34=193852=20260120-14:06:43.999262=MD_GBP/USD_140109778778268=5279=1269=0270=1.2547271=10000055=GBP/USD110=0279=1269=0270=1.2547271=50000055=GBP/USD110=100000279=1269=0270=1.2547271=100000055=GBP/USD110=500000279=1269=0270=1.2547271=300000055=GBP/USD110=1000000279=1269=0270=1.2547271=500000055=GBP/USD110=300000010=110
20260120-14:06:43.786723000 : 8=FIX.4.49=027735=X49=NTPRO_IDBA_UAT56=SIRIUS_500007460_MD34=193952=20260120-14:06:44.051262=MD_EUR/USD_140109278614268=3279=1269=1270=1.1981271=10000055=EUR/USD110=0279=1269=1270=1.1981271=50000055=EUR/USD110=100000279=1269=1270=1.1981271=100000055=EUR/USD110=50000010=120
20260120-14:06:43.858266000 : 8=FIX.4.49=039835=X49=NTPRO_IDBA_UAT56=SIRIUS_500007460_MD34=194052=20260120-14:06:44.126262=MD_GBP/USD_140109778778268=5279=1269=0270=1.25469271=10000055=GBP/USD110=0279=1269=0270=1.25469271=50000055=GBP/USD110=100000279=1269=0270=1.25469271=100000055=GBP/USD110=500000279=1269=0270=1.25469271=300000055=GBP/USD110=1000000279=1269=0270=1.25469271=500000055=GBP/USD110=300000010=115
20260120-14:06:43.967076000 : 8=FIX.4.49=044735=X49=NTPRO_IDBA_UAT56=SIRIUS_500007460_MD34=194152=20260120-14:06:44.239262=MD_EUR/USD_140109278614268=6279=1269=0270=1.14785271=10000055=EUR/USD110=0279=1269=0270=1.14785271=50000055=EUR/USD110=100000279=1269=0270=1.14785271=100000055=EUR/USD110=500000279=1269=1270=1.19809271=10000055=EUR/USD110=0279=1269=1270=1.19809271=50000055=EUR/USD110=100000279=1269=1270=1.19809271=100000055=EUR/USD110=50000010=082
20260120-14:06:44.005344000 : 8=FIX.4.49=039835=X49=NTPRO_IDBA_UAT56=SIRIUS_500007460_MD34=194252=20260120-14:06:44.251262=MD_GBP/USD_140109778778268=5279=1269=1270=1.43503271=10000055=GBP/USD110=0279=1269=1270=1.43503271=50000055=GBP/USD110=100000279=1269=1270=1.43503271=100000055=GBP/USD110=500000279=1269=1270=1.43503271=300000055=GBP/USD110=1000000279=1269=1270=1.43503271=500000055=GBP/USD110=300000010=066
20260120-14:06:44.134629000 : 8=FIX.4.49=039835=X49=NTPRO_IDBA_UAT56=SIRIUS_500007460_MD34=194352=20260120-14:06:44.408262=MD_GBP/USD_140109778778268=5279=1269=0270=1.25468271=10000055=GBP/USD110=0279=1269=0270=1.25468271=50000055=GBP/USD110=100000279=1269=0270=1.25468271=100000055=GBP/USD110=500000279=1269=0270=1.25468271=300000055=GBP/USD110=1000000279=1269=0270=1.25468271=500000055=GBP/USD110=300000010=116
20260120-14:06:44.209463000 : 8=FIX.4.49=068435=X49=NTPRO_IDBA_UAT56=SIRIUS_500007460_MD34=194452=20260120-14:06:44.490262=MD_GBP/USD_140109778778268=10279=1269=0270=1.25467271=10000055=GBP/USD110=0279=1269=0270=1.25467271=50000055=GBP/USD110=100000279=1269=0270=1.25467271=100000055=GBP/USD110=500000279=1269=0270=1.25467271=300000055=GBP/USD110=1000000279=1269=0270=1.25467271=500000055=GBP/USD110=3000000279=1269=1270=1.43502271=10000055=GBP/USD110=0279=1269=1270=1.43502271=50000055=GBP/USD110=100000279=1269=1270=1.43502271=100000055=GBP/USD110=500000279=1269=1270=1.43502271=300000055=GBP/USD110=1000000279=1269=1270=1.43502271=500000055=GBP/USD110=300000010=241
20260120-14:06:44.233784000 : 8=FIX.4.49=028035=X49=NTPRO_IDBA_UAT56=SIRIUS_500007460_MD34=194552=20260120-14:06:44.516262=MD_EUR/USD_140109278614268=3279=1269=0270=1.14784271=10000055=EUR/USD110=0279=1269=0270=1.14784271=50000055=EUR/USD110=100000279=1269=0270=1.14784271=100000055=EUR/USD110=50000010=017
20260120-14:06:44.368381000 : 8=FIX.4.49=044735=X49=NTPRO_IDBA_UAT56=SIRIUS_500007460_MD34=194652=20260120-14:06:44.655262=MD_EUR/USD_140109278614268=6279=1269=0270=1.14783271=10000055=EUR/USD110=0279=1269=0270=1.14783271=50000055=EUR/USD110=100000279=1269=0270=1.14783271=100000055=EUR/USD110=500000279=1269=1270=1.19807271=10000055=EUR/USD110=0279=1269=1270=1.19807271=50000055=EUR/USD110=100000279=1269=1270=1.19807271=100000055=EUR/USD110=50000010=077
20260120-14:06:44.404494000 : 8=FIX.4.49=039835=X49=NTPRO_IDBA_UAT56=SIRIUS_500007460_MD34=194752=20260120-14:06:44.692262=MD_GBP/USD_140109778778268=5279=1269=0270=1.25466271=10000055=GBP/USD110=0279=1269=0270=1.25466271=50000055=GBP/USD110=100000279=1269=0270=1.25466271=100000055=GBP/USD110=500000279=1269=0270=1.25466271=300000055=GBP/USD110=1000000279=1269=0270=1.25466271=500000055=GBP/USD110=300000010=115
20260120-14:06:44.596607000 : 8=FIX.4.49=068435=X49=NTPRO_IDBA_UAT56=SIRIUS_500007460_MD34=194852=20260120-14:06:44.871262=MD_GBP/USD_140109778778268=10279=1269=0270=1.25467271=10000055=GBP/USD110=0279=1269=0270=1.25467271=50000055=GBP/USD110=100000279=1269=0270=1.25467271=100000055=GBP/USD110=500000279=1269=0270=1.25467271=300000055=GBP/USD110=1000000279=1269=0270=1.25467271=500000055=GBP/USD110=3000000279=1269=1270=1.43501271=10000055=GBP/USD110=0279=1269=1270=1.43501271=50000055=GBP/USD110=100000279=1269=1270=1.43501271=100000055=GBP/USD110=500000279=1269=1270=1.43501271=300000055=GBP/USD110=1000000279=1269=1270=1.43501271=500000055=GBP/USD110=300000010=243
20260120-14:06:44.995626000 : 8=FIX.4.49=039835=X49=NTPRO_IDBA_UAT56=SIRIUS_500007460_MD34=194952=20260120-14:06:45.302262=MD_GBP/USD_140109778778268=5279=1269=0270=1.25466271=10000055=GBP/USD110=0279=1269=0270=1.25466271=50000055=GBP/USD110=100000279=1269=0270=1.25466271=100000055=GBP/USD110=500000279=1269=0270=1.25466271=300000055=GBP/USD110=1000000279=1269=0270=1.25466271=500000055=GBP/USD110=300000010=106
20260120-14:06:45.030427000 : 8=FIX.4.49=7735=034=1849=SIRIUS_500007460_MD52=20260120-14:06:45.02956=NTPRO_IDBA_UAT10=077
20260120-14:06:45.037202000 : 8=FIX.4.49=068435=X49=NTPRO_IDBA_UAT56=SIRIUS_500007460_MD34=195052=20260120-14:06:45.347262=MD_GBP/USD_140109778778268=10279=1269=0270=1.25467271=10000055=GBP/USD110=0279=1269=0270=1.25467271=50000055=GBP/USD110=100000279=1269=0270=1.25467271=100000055=GBP/USD110=500000279=1269=0270=1.25467271=300000055=GBP/USD110=1000000279=1269=0270=1.25467271=500000055=GBP/USD110=3000000279=1269=1270=1.43502271=10000055=GBP/USD110=0279=1269=1270=1.43502271=50000055=GBP/USD110=100000279=1269=1270=1.43502271=100000055=GBP/USD110=500000279=1269=1270=1.43502271=300000055=GBP/USD110=1000000279=1269=1270=1.43502271=500000055=GBP/USD110=300000010=240
20260120-14:06:45.295464000 : 8=FIX.4.49=039835=X49=NTPRO_IDBA_UAT56=SIRIUS_500007460_MD34=195152=20260120-14:06:45.611262=MD_GBP/USD_140109778778268=5279=1269=1270=1.43501271=10000055=GBP/USD110=0279=1269=1270=1.43501271=50000055=GBP/USD110=100000279=1269=1270=1.43501271=100000055=GBP/USD110=500000279=1269=1270=1.43501271=300000055=GBP/USD110=1000000279=1269=1270=1.43501271=500000055=GBP/USD110=300000010=057
20260120-14:06:45.338127000 : 8=FIX.4.49=028035=X49=NTPRO_IDBA_UAT56=SIRIUS_500007460_MD34=195252=20260120-14:06:45.659262=MD_EUR/USD_140109278614268=3279=1269=0270=1.14782271=10000055=EUR/USD110=0279=1269=0270=1.14782271=50000055=EUR/USD110=100000279=1269=0270=1.14782271=100000055=EUR/USD110=50000010=018
20260120-14:06:45.387559000 : 8=FIX.4.49=067435=X49=NTPRO_IDBA_UAT56=SIRIUS_500007460_MD34=195352=20260120-14:06:45.701262=MD_GBP/USD_140109778778268=10279=1269=0270=1.25466271=10000055=GBP/USD110=0279=1269=0270=1.25466271=50000055=GBP/USD110=100000279=1269=0270=1.25466271=100000055=GBP/USD110=500000279=1269=0270=1.25466271=300000055=GBP/USD110=1000000279=1269=0270=1.25466271=500000055=GBP/USD110=3000000279=1269=1270=1.435271=10000055=GBP/USD110=0279=1269=1270=1.435271=50000055=GBP/USD110=100000279=1269=1270=1.435271=100000055=GBP/USD110=500000279=1269=1270=1.435271=300000055=GBP/USD110=1000000279=1269=1270=1.435271=500000055=GBP/USD110=300000010=253
20260120-14:06:45.493292000 : 8=FIX.4.49=068435=X49=NTPRO_IDBA_UAT56=SIRIUS_500007460_MD34=195452=20260120-14:06:45.819262=MD_GBP/USD_140109778778268=10279=1269=0270=1.25469271=10000055=GBP/USD110=0279=1269=0270=1.25469271=50000055=GBP/USD110=100000279=1269=0270=1.25469271=100000055=GBP/USD110=500000279=1269=0270=1.25469271=300000055=GBP/USD110=1000000279=1269=0270=1.25469271=500000055=GBP/USD110=3000000279=1269=1270=1.43501271=10000055=GBP/USD110=0279=1269=1270=1.43501271=50000055=GBP/USD110=100000279=1269=1270=1.43501271=100000055=GBP/USD110=500000279=1269=1270=1.43501271=300000055=GBP/USD110=1000000279=1269=1270=1.43501271=500000055=GBP/USD110=300000010=253
20260120-14:06:45.548040000 : 8=FIX.4.49=044735=X49=NTPRO_IDBA_UAT56=SIRIUS_500007460_MD34=195552=20260120-14:06:45.876262=MD_EUR/USD_140109278614268=6279=1269=0270=1.14786271=10000055=EUR/USD110=0279=1269=0270=1.14786271=50000055=EUR/USD110=100000279=1269=0270=1.14786271=100000055=EUR/USD110=500000279=1269=1270=1.19811271=10000055=EUR/USD110=0279=1269=1270=1.19811271=50000055=EUR/USD110=100000279=1269=1270=1.19811271=100000055=EUR/USD110=50000010=077
20260120-14:06:45.562037000 : 8=FIX.4.49=068435=X49=NTPRO_IDBA_UAT56=SIRIUS_500007460_MD34=195652=20260120-14:06:45.887262=MD_GBP/USD_140109778778268=10279=1269=0270=1.25473271=10000055=GBP/USD110=0279=1269=0270=1.25473271=50000055=GBP/USD110=100000279=1269=0270=1.25473271=100000055=GBP/USD110=500000279=1269=0270=1.25473271=300000055=GBP/USD110=1000000279=1269=0270=1.25473271=500000055=GBP/USD110=3000000279=1269=1270=1.43507271=10000055=GBP/USD110=0279=1269=1270=1.43507271=50000055=GBP/USD110=100000279=1269=1270=1.43507271=100000055=GBP/USD110=500000279=1269=1270=1.43507271=300000055=GBP/USD110=1000000279=1269=1270=1.43507271=500000055=GBP/USD110=300000010=009
20260120-14:06:45.602555000 : 8=FIX.4.49=068435=X49=NTPRO_IDBA_UAT56=SIRIUS_500007460_MD34=195752=20260120-14:06:45.933262=MD_GBP/USD_140109778778268=10279=1269=0270=1.25472271=10000055=GBP/USD110=0279=1269=0270=1.25472271=50000055=GBP/USD110=100000279=1269=0270=1.25472271=100000055=GBP/USD110=500000279=1269=0270=1.25472271=300000055=GBP/USD110=1000000279=1269=0270=1.25472271=500000055=GBP/USD110=3000000279=1269=1270=1.43506271=10000055=GBP/USD110=0279=1269=1270=1.43506271=50000055=GBP/USD110=100000279=1269=1270=1.43506271=100000055=GBP/USD110=500000279=1269=1270=1.43506271=300000055=GBP/USD110=1000000279=1269=1270=1.43506271=500000055=GBP/USD110=300000010=248
20260120-14:06:45.784743000 : 8=FIX.4.49=044735=X49=NTPRO_IDBA_UAT56=SIRIUS_500007460_MD34=195852=20260120-14:06:46.121262=MD_EUR/USD_140109278614268=6279=1269=0270=1.14788271=10000055=EUR/USD110=0279=1269=0270=1.14788271=50000055=EUR/USD110=100000279=1269=0270=1.14788271=100000055=EUR/USD110=500000279=1269=1270=1.19812271=10000055=EUR/USD110=0279=1269=1270=1.19812271=50000055=EUR/USD110=100000279=1269=1270=1.19812271=100000055=EUR/USD110=50000010=073
20260120-14:06:45.920868000 : 8=FIX.4.49=028035=X49=NTPRO_IDBA_UAT56=SIRIUS_500007460_MD34=195952=20260120-14:06:46.262262=MD_EUR/USD_140109278614268=3279=1269=0270=1.14787271=10000055=EUR/USD110=0279=1269=0270=1.14787271=50000055=EUR/USD110=100000279=1269=0270=1.14787271=100000055=EUR/USD110=50000010=031
20260120-14:06:46.018589000 : 8=FIX.4.49=028035=X49=NTPRO_IDBA_UAT56=SIRIUS_500007460_MD34=196052=20260120-14:06:46.364262=MD_EUR/USD_140109278614268=3279=1269=0270=1.14788271=10000055=EUR/USD110=0279=1269=0270=1.14788271=50000055=EUR/USD110=100000279=1269=0270=1.14788271=100000055=EUR/USD110=50000010=029
20260120-14:06:46.044527000 : 8=FIX.4.49=028035=X49=NTPRO_IDBA_UAT56=SIRIUS_500007460_MD34=196152=20260120-14:06:46.391262=MD_EUR/USD_140109278614268=3279=1269=0270=1.14786271=10000055=EUR/USD110=0279=1269=0270=1.14786271=50000055=EUR/USD110=100000279=1269=0270=1.14786271=100000055=EUR/USD110=50000010=024
20260120-14:06:46.087045000 : 8=FIX.4.49=068435=X49=NTPRO_IDBA_UAT56=SIRIUS_500007460_MD34=196252=20260120-14:06:46.434262=MD_GBP/USD_140109778778268=10279=1269=0270=1.25473271=10000055=GBP/USD110=0279=1269=0270=1.25473271=50000055=GBP/USD110=100000279=1269=0270=1.25473271=100000055=GBP/USD110=500000279=1269=0270=1.25473271=300000055=GBP/USD110=1000000279=1269=0270=1.25473271=500000055=GBP/USD110=3000000279=1269=1270=1.43507271=10000055=GBP/USD110=0279=1269=1270=1.43507271=50000055=GBP/USD110=100000279=1269=1270=1.43507271=100000055=GBP/USD110=500000279=1269=1270=1.43507271=300000055=GBP/USD110=1000000279=1269=1270=1.43507271=500000055=GBP/USD110=300000010=251
20260120-14:06:46.406103000 : 8=FIX.4.49=028035=X49=NTPRO_IDBA_UAT56=SIRIUS_500007460_MD34=196352=20260120-14:06:46.760262=MD_EUR/USD_140109278614268=3279=1269=0270=1.14787271=10000055=EUR/USD110=0279=1269=0270=1.14787271=50000055=EUR/USD110=100000279=1269=0270=1.14787271=100000055=EUR/USD110=50000010=029
20260120-14:06:46.487857000 : 8=FIX.4.49=028035=X49=NTPRO_IDBA_UAT56=SIRIUS_500007460_MD34=196452=20260120-14:06:46.841262=MD_EUR/USD_140109278614268=3279=1269=1270=1.19811271=10000055=EUR/USD110=0279=1269=1270=1.19811271=50000055=EUR/USD110=100000279=1269=1270=1.19811271=100000055=EUR/USD110=50000010=012
20260120-14:06:46.584069000 : 8=FIX.4.49=044735=X49=NTPRO_IDBA_UAT56=SIRIUS_500007460_MD34=196552=20260120-14:06:46.948262=MD_EUR/USD_140109278614268=6279=1269=0270=1.14788271=10000055=EUR/USD110=0279=1269=0270=1.14788271=50000055=EUR/USD110=100000279=1269=0270=1.14788271=100000055=EUR/USD110=500000279=1269=1270=1.19812271=10000055=EUR/USD110=0279=1269=1270=1.19812271=50000055=EUR/USD110=100000279=1269=1270=1.19812271=100000055=EUR/USD110=50000010=088
20260120-14:06:46.976545000 : 8=FIX.4.49=028035=X49=NTPRO_IDBA_UAT56=SIRIUS_500007460_MD34=196652=20260120-14:06:47.356262=MD_EUR/USD_140109278614268=3279=1269=0270=1.14787271=10000055=EUR/USD110=0279=1269=0270=1.14787271=50000055=EUR/USD110=100000279=1269=0270=1.14787271=100000055=EUR/USD110=50000010=034
20260120-14:06:47.015824000 : 8=FIX.4.49=028035=X49=NTPRO_IDBA_UAT56=SIRIUS_500007460_MD34=196752=20260120-14:06:47.397262=MD_EUR/USD_140109278614268=3279=1269=0270=1.14788271=10000055=EUR/USD110=0279=1269=0270=1.14788271=50000055=EUR/USD110=100000279=1269=0270=1.14788271=100000055=EUR/USD110=50000010=043
20260120-14:06:47.081250000 : 8=FIX.4.49=028035=X49=NTPRO_IDBA_UAT56=SIRIUS_500007460_MD34=196852=20260120-14:06:47.465262=MD_EUR/USD_140109278614268=3279=1269=1270=1.19813271=10000055=EUR/USD110=0279=1269=1270=1.19813271=50000055=EUR/USD110=100000279=1269=1270=1.19813271=100000055=EUR/USD110=50000010=025
20260120-14:06:47.120881000 : 8=FIX.4.49=028035=X49=NTPRO_IDBA_UAT56=SIRIUS_500007460_MD34=196952=20260120-14:06:47.505262=MD_EUR/USD_140109278614268=3279=1269=0270=1.14789271=10000055=EUR/USD110=0279=1269=0270=1.14789271=50000055=EUR/USD110=100000279=1269=0270=1.14789271=100000055=EUR/USD110=50000010=039
20260120-14:06:47.167231000 : 8=FIX.4.49=028035=X49=NTPRO_IDBA_UAT56=SIRIUS_500007460_MD34=197052=20260120-14:06:47.535262=MD_EUR/USD_140109278614268=3279=1269=0270=1.14788271=10000055=EUR/USD110=0279=1269=0270=1.14788271=50000055=EUR/USD110=100000279=1269=0270=1.14788271=100000055=EUR/USD110=50000010=031
20260120-14:06:47.276805000 : 8=FIX.4.49=028035=X49=NTPRO_IDBA_UAT56=SIRIUS_500007460_MD34=197152=20260120-14:06:47.667262=MD_EUR/USD_140109278614268=3279=1269=1270=1.19812271=10000055=EUR/USD110=0279=1269=1270=1.19812271=50000055=EUR/USD110=100000279=1269=1270=1.19812271=100000055=EUR/USD110=50000010=020
20260120-14:06:47.388436000 : 8=FIX.4.49=028035=X49=NTPRO_IDBA_UAT56=SIRIUS_500007460_MD34=197252=20260120-14:06:47.783262=MD_EUR/USD_140109278614268=3279=1269=1270=1.19813271=10000055=EUR/USD110=0279=1269=1270=1.19813271=50000055=EUR/USD110=100000279=1269=1270=1.19813271=100000055=EUR/USD110=50000010=023
20260120-14:06:47.443397000 : 8=FIX.4.49=028035=X49=NTPRO_IDBA_UAT56=SIRIUS_500007460_MD34=197352=20260120-14:06:47.839262=MD_EUR/USD_140109278614268=3279=1269=0270=1.14789271=10000055=EUR/USD110=0279=1269=0270=1.14789271=50000055=EUR/USD110=100000279=1269=0270=1.14789271=100000055=EUR/USD110=50000010=044
20260120-14:06:47.463654000 : 8=FIX.4.49=028035=X49=NTPRO_IDBA_UAT56=SIRIUS_500007460_MD34=197452=20260120-14:06:47.860262=MD_EUR/USD_140109278614268=3279=1269=0270=1.14788271=10000055=EUR/USD110=0279=1269=0270=1.14788271=50000055=EUR/USD110=100000279=1269=0270=1.14788271=100000055=EUR/USD110=50000010=036
20260120-14:06:47.708825000 : 8=FIX.4.49=028035=X49=NTPRO_IDBA_UAT56=SIRIUS_500007460_MD34=197552=20260120-14:06:48.108262=MD_EUR/USD_140109278614268=3279=1269=1270=1.19812271=10000055=EUR/USD110=0279=1269=1270=1.19812271=50000055=EUR/USD110=100000279=1269=1270=1.19812271=100000055=EUR/USD110=50000010=015
20260120-14:06:47.819979000 : 8=FIX.4.49=028035=X49=NTPRO_IDBA_UAT56=SIRIUS_500007460_MD34=197652=20260120-14:06:48.228262=MD_EUR/USD_140109278614268=3279=1269=0270=1.14787271=10000055=EUR/USD110=0279=1269=0270=1.14787271=50000055=EUR/USD110=100000279=1269=0270=1.14787271=100000055=EUR/USD110=50000010=034
20260120-14:06:47.880616000 : 8=FIX.4.49=068435=X49=NTPRO_IDBA_UAT56=SIRIUS_500007460_MD34=197752=20260120-14:06:48.290262=MD_GBP/USD_140109778778268=10279=1269=0270=1.25471271=10000055=GBP/USD110=0279=1269=0270=1.25471271=50000055=GBP/USD110=100000279=1269=0270=1.25471271=100000055=GBP/USD110=500000279=1269=0270=1.25471271=300000055=GBP/USD110=1000000279=1269=0270=1.25471271=500000055=GBP/USD110=3000000279=1269=1270=1.43506271=10000055=GBP/USD110=0279=1269=1270=1.43506271=50000055=GBP/USD110=100000279=1269=1270=1.43506271=100000055=GBP/USD110=500000279=1269=1270=1.43506271=300000055=GBP/USD110=1000000279=1269=1270=1.43506271=500000055=GBP/USD110=300000010=244
20260120-14:06:47.902828000 : 8=FIX.4.49=044435=X49=NTPRO_IDBA_UAT56=SIRIUS_500007460_MD34=197852=20260120-14:06:48.315262=MD_EUR/USD_140109278614268=6279=1269=0270=1.14786271=10000055=EUR/USD110=0279=1269=0270=1.14786271=50000055=EUR/USD110=100000279=1269=0270=1.14786271=100000055=EUR/USD110=500000279=1269=1270=1.1981271=10000055=EUR/USD110=0279=1269=1270=1.1981271=50000055=EUR/USD110=100000279=1269=1270=1.1981271=100000055=EUR/USD110=50000010=179
20260120-14:06:47.936314000 : 8=FIX.4.49=039835=X49=NTPRO_IDBA_UAT56=SIRIUS_500007460_MD34=197952=20260120-14:06:48.348262=MD_GBP/USD_140109778778268=5279=1269=1270=1.43505271=10000055=GBP/USD110=0279=1269=1270=1.43505271=50000055=GBP/USD110=100000279=1269=1270=1.43505271=100000055=GBP/USD110=500000279=1269=1270=1.43505271=300000055=GBP/USD110=1000000279=1269=1270=1.43505271=500000055=GBP/USD110=300000010=097
20260120-14:06:47.972363000 : 8=FIX.4.49=039335=X49=NTPRO_IDBA_UAT56=SIRIUS_500007460_MD34=198052=20260120-14:06:48.388262=MD_GBP/USD_140109778778268=5279=1269=0270=1.2547271=10000055=GBP/USD110=0279=1269=0270=1.2547271=50000055=GBP/USD110=100000279=1269=0270=1.2547271=100000055=GBP/USD110=500000279=1269=0270=1.2547271=300000055=GBP/USD110=1000000279=1269=0270=1.2547271=500000055=GBP/USD110=300000010=104
20260120-14:06:48.172120000 : 8=FIX.4.49=044735=X49=NTPRO_IDBA_UAT56=SIRIUS_500007460_MD34=198152=20260120-14:06:48.552262=MD_EUR/USD_140109278614268=6279=1269=0270=1.14785271=10000055=EUR/USD110=0279=1269=0270=1.14785271=50000055=EUR/USD110=100000279=1269=0270=1.14785271=100000055=EUR/USD110=500000279=1269=1270=1.19809271=10000055=EUR/USD110=0279=1269=1270=1.19809271=50000055=EUR/USD110=100000279=1269=1270=1.19809271=100000055=EUR/USD110=50000010=088
20260120-14:06:48.261289000 : 8=FIX.4.49=039835=X49=NTPRO_IDBA_UAT56=SIRIUS_500007460_MD34=198252=20260120-14:06:48.653262=MD_GBP/USD_140109778778268=5279=1269=1270=1.43504271=10000055=GBP/USD110=0279=1269=1270=1.43504271=50000055=GBP/USD110=100000279=1269=1270=1.43504271=100000055=GBP/USD110=500000279=1269=1270=1.43504271=300000055=GBP/USD110=1000000279=1269=1270=1.43504271=500000055=GBP/USD110=300000010=085
20260120-14:06:48.354500000 : 8=FIX.4.49=028035=X49=NTPRO_IDBA_UAT56=SIRIUS_500007460_MD34=198352=20260120-14:06:48.777262=MD_EUR/USD_140109278614268=3279=1269=0270=1.14784271=10000055=EUR/USD110=0279=1269=0270=1.14784271=50000055=EUR/USD110=100000279=1269=0270=1.14784271=100000055=EUR/USD110=50000010=032
20260120-14:06:48.404729000 : 8=FIX.4.49=039835=X49=NTPRO_IDBA_UAT56=SIRIUS_500007460_MD34=198452=20260120-14:06:48.835262=MD_GBP/USD_140109778778268=5279=1269=0270=1.25469271=10000055=GBP/USD110=0279=1269=0270=1.25469271=50000055=GBP/USD110=100000279=1269=0270=1.25469271=100000055=GBP/USD110=500000279=1269=0270=1.25469271=300000055=GBP/USD110=1000000279=1269=0270=1.25469271=500000055=GBP/USD110=300000010=134
20260120-14:06:48.479638000 : 8=FIX.4.49=028035=X49=NTPRO_IDBA_UAT56=SIRIUS_500007460_MD34=198552=20260120-14:06:48.912262=MD_EUR/USD_140109278614268=3279=1269=0270=1.14785271=10000055=EUR/USD110=0279=1269=0270=1.14785271=50000055=EUR/USD110=100000279=1269=0270=1.14785271=100000055=EUR/USD110=50000010=028
20260120-14:06:48.581555000 : 8=FIX.4.49=028035=X49=NTPRO_IDBA_UAT56=SIRIUS_500007460_MD34=198652=20260120-14:06:49.005262=MD_EUR/USD_140109278614268=3279=1269=0270=1.14784271=10000055=EUR/USD110=0279=1269=0270=1.14784271=50000055=EUR/USD110=100000279=1269=0270=1.14784271=100000055=EUR/USD110=50000010=020
20260120-14:06:48.606593000 : 8=FIX.4.49=039835=X49=NTPRO_IDBA_UAT56=SIRIUS_500007460_MD34=198752=20260120-14:06:49.044262=MD_GBP/USD_140109778778268=5279=1269=1270=1.43503271=10000055=GBP/USD110=0279=1269=1270=1.43503271=50000055=GBP/USD110=100000279=1269=1270=1.43503271=100000055=GBP/USD110=500000279=1269=1270=1.43503271=300000055=GBP/USD110=1000000279=1269=1270=1.43503271=500000055=GBP/USD110=300000010=080
20260120-14:06:48.650331000 : 8=FIX.4.49=028035=X49=NTPRO_IDBA_UAT56=SIRIUS_500007460_MD34=198852=20260120-14:06:49.085262=MD_EUR/USD_140109278614268=3279=1269=0270=1.14785271=10000055=EUR/USD110=0279=1269=0270=1.14785271=50000055=EUR/USD110=100000279=1269=0270=1.14785271=100000055=EUR/USD110=50000010=033
20260120-14:06:48.675163000 : 8=FIX.4.49=039835=X49=NTPRO_IDBA_UAT56=SIRIUS_500007460_MD34=198952=20260120-14:06:49.108262=MD_GBP/USD_140109778778268=5279=1269=0270=1.25468271=10000055=GBP/USD110=0279=1269=0270=1.25468271=50000055=GBP/USD110=100000279=1269=0270=1.25468271=100000055=GBP/USD110=500000279=1269=0270=1.25468271=300000055=GBP/USD110=1000000279=1269=0270=1.25468271=500000055=GBP/USD110=300000010=128
20260120-14:06:48.706013000 : 8=FIX.4.49=044735=X49=NTPRO_IDBA_UAT56=SIRIUS_500007460_MD34=199052=20260120-14:06:49.146262=MD_EUR/USD_140109278614268=6279=1269=0270=1.14783271=10000055=EUR/USD110=0279=1269=0270=1.14783271=50000055=EUR/USD110=100000279=1269=0270=1.14783271=100000055=EUR/USD110=500000279=1269=1270=1.19808271=10000055=EUR/USD110=0279=1269=1270=1.19808271=50000055=EUR/USD110=100000279=1269=1270=1.19808271=100000055=EUR/USD110=50000010=079
20260120-14:06:48.848323000 : 8=FIX.4.49=028035=X49=NTPRO_IDBA_UAT56=SIRIUS_500007460_MD34=199152=20260120-14:06:49.278262=MD_EUR/USD_140109278614268=3279=1269=0270=1.14784271=10000055=EUR/USD110=0279=1269=0270=1.14784271=50000055=EUR/USD110=100000279=1269=0270=1.14784271=100000055=EUR/USD110=50000010=028
20260120-14:06:48.877133000 : 8=FIX.4.49=028035=X49=NTPRO_IDBA_UAT56=SIRIUS_500007460_MD34=199252=20260120-14:06:49.324262=MD_EUR/USD_140109278614268=3279=1269=0270=1.14783271=10000055=EUR/USD110=0279=1269=0270=1.14783271=50000055=EUR/USD110=100000279=1269=0270=1.14783271=100000055=EUR/USD110=50000010=018
20260120-14:06:48.927255000 : 8=FIX.4.49=028035=X49=NTPRO_IDBA_UAT56=SIRIUS_500007460_MD34=199352=20260120-14:06:49.370262=MD_EUR/USD_140109278614268=3279=1269=0270=1.14784271=10000055=EUR/USD110=0279=1269=0270=1.14784271=50000055=EUR/USD110=100000279=1269=0270=1.14784271=100000055=EUR/USD110=50000010=023
20260120-14:06:48.949944000 : 8=FIX.4.49=028035=X49=NTPRO_IDBA_UAT56=SIRIUS_500007460_MD34=199452=20260120-14:06:49.400262=MD_EUR/USD_140109278614268=3279=1269=0270=1.14783271=10000055=EUR/USD110=0279=1269=0270=1.14783271=50000055=EUR/USD110=100000279=1269=0270=1.14783271=100000055=EUR/USD110=50000010=015
20260120-14:06:49.079110000 : 8=FIX.4.49=028035=X49=NTPRO_IDBA_UAT56=SIRIUS_500007460_MD34=199552=20260120-14:06:49.533262=MD_EUR/USD_140109278614268=3279=1269=0270=1.14784271=10000055=EUR/USD110=0279=1269=0270=1.14784271=50000055=EUR/USD110=100000279=1269=0270=1.14784271=100000055=EUR/USD110=50000010=026
20260120-14:06:50.243939000 : 8=FIX.4.49=028035=X49=NTPRO_IDBA_UAT56=SIRIUS_500007460_MD34=199652=20260120-14:06:50.740262=MD_EUR/USD_140109278614268=3279=1269=0270=1.14783271=10000055=EUR/USD110=0279=1269=0270=1.14783271=50000055=EUR/USD110=100000279=1269=0270=1.14783271=100000055=EUR/USD110=50000010=016
20260120-14:06:50.562119000 : 8=FIX.4.49=028035=X49=NTPRO_IDBA_UAT56=SIRIUS_500007460_MD34=199752=20260120-14:06:51.069262=MD_EUR/USD_140109278614268=3279=1269=1270=1.19807271=10000055=EUR/USD110=0279=1269=1270=1.19807271=50000055=EUR/USD110=100000279=1269=1270=1.19807271=100000055=EUR/USD110=50000010=031
20260120-14:06:50.595803000 : 8=FIX.4.49=028035=X49=NTPRO_IDBA_UAT56=SIRIUS_500007460_MD34=199852=20260120-14:06:51.104262=MD_EUR/USD_140109278614268=3279=1269=1270=1.19808271=10000055=EUR/USD110=0279=1269=1270=1.19808271=50000055=EUR/USD110=100000279=1269=1270=1.19808271=100000055=EUR/USD110=50000010=025
20260120-14:06:50.627499000 : 8=FIX.4.49=028035=X49=NTPRO_IDBA_UAT56=SIRIUS_500007460_MD34=199952=20260120-14:06:51.130262=MD_EUR/USD_140109278614268=3279=1269=0270=1.14784271=10000055=EUR/USD110=0279=1269=0270=1.14784271=50000055=EUR/USD110=100000279=1269=0270=1.14784271=100000055=EUR/USD110=50000010=016
20260120-14:06:51.295148000 : 8=FIX.4.49=028035=X49=NTPRO_IDBA_UAT56=SIRIUS_500007460_MD34=200052=20260120-14:06:51.822262=MD_EUR/USD_140109278614268=3279=1269=1270=1.19809271=10000055=EUR/USD110=0279=1269=1270=1.19809271=50000055=EUR/USD110=100000279=1269=1270=1.19809271=100000055=EUR/USD110=50000010=010
20260120-14:06:51.346169000 : 8=FIX.4.49=028035=X49=NTPRO_IDBA_UAT56=SIRIUS_500007460_MD34=200152=20260120-14:06:51.877262=MD_EUR/USD_140109278614268=3279=1269=0270=1.14785271=10000055=EUR/USD110=0279=1269=0270=1.14785271=50000055=EUR/USD110=100000279=1269=0270=1.14785271=100000055=EUR/USD110=50000010=012
20260120-14:06:51.418885000 : 8=FIX.4.49=039835=X49=NTPRO_IDBA_UAT56=SIRIUS_500007460_MD34=200252=20260120-14:06:51.956262=MD_GBP/USD_140109778778268=5279=1269=0270=1.25469271=10000055=GBP/USD110=0279=1269=0270=1.25469271=50000055=GBP/USD110=100000279=1269=0270=1.25469271=100000055=GBP/USD110=500000279=1269=0270=1.25469271=300000055=GBP/USD110=1000000279=1269=0270=1.25469271=500000055=GBP/USD110=300000010=114
20260120-14:06:51.519526000 : 8=FIX.4.49=039835=X49=NTPRO_IDBA_UAT56=SIRIUS_500007460_MD34=200352=20260120-14:06:52.048262=MD_GBP/USD_140109778778268=5279=1269=1270=1.43504271=10000055=GBP/USD110=0279=1269=1270=1.43504271=50000055=GBP/USD110=100000279=1269=1270=1.43504271=100000055=GBP/USD110=500000279=1269=1270=1.43504271=300000055=GBP/USD110=1000000279=1269=1270=1.43504271=500000055=GBP/USD110=300000010=063
20260120-14:06:51.563687000 : 8=FIX.4.49=044435=X49=NTPRO_IDBA_UAT56=SIRIUS_500007460_MD34=200452=20260120-14:06:52.106262=MD_EUR/USD_140109278614268=6279=1269=0270=1.14786271=10000055=EUR/USD110=0279=1269=0270=1.14786271=50000055=EUR/USD110=100000279=1269=0270=1.14786271=100000055=EUR/USD110=500000279=1269=1270=1.1981271=10000055=EUR/USD110=0279=1269=1270=1.1981271=50000055=EUR/USD110=100000279=1269=1270=1.1981271=100000055=EUR/USD110=50000010=153
20260120-14:06:51.660990000 : 8=FIX.4.49=028035=X49=NTPRO_IDBA_UAT56=SIRIUS_500007460_MD34=200552=20260120-14:06:52.203262=MD_EUR/USD_140109278614268=3279=1269=0270=1.14785271=10000055=EUR/USD110=0279=1269=0270=1.14785271=50000055=EUR/USD110=100000279=1269=0270=1.14785271=100000055=EUR/USD110=50000010=000
20260120-14:06:51.717222000 : 8=FIX.4.49=028035=X49=NTPRO_IDBA_UAT56=SIRIUS_500007460_MD34=200652=20260120-14:06:52.248262=MD_EUR/USD_140109278614268=3279=1269=0270=1.14786271=10000055=EUR/USD110=0279=1269=0270=1.14786271=50000055=EUR/USD110=100000279=1269=0270=1.14786271=100000055=EUR/USD110=50000010=013
20260120-14:06:51.773043000 : 8=FIX.4.49=044735=X49=NTPRO_IDBA_UAT56=SIRIUS_500007460_MD34=200752=20260120-14:06:52.319262=MD_EUR/USD_140109278614268=6279=1269=0270=1.14785271=10000055=EUR/USD110=0279=1269=0270=1.14785271=50000055=EUR/USD110=100000279=1269=0270=1.14785271=100000055=EUR/USD110=500000279=1269=1270=1.19809271=10000055=EUR/USD110=0279=1269=1270=1.19809271=50000055=EUR/USD110=100000279=1269=1270=1.19809271=100000055=EUR/USD110=50000010=074
20260120-14:06:52.111641000 : 8=FIX.4.49=039835=X49=NTPRO_IDBA_UAT56=SIRIUS_500007460_MD34=200852=20260120-14:06:52.665262=MD_GBP/USD_140109778778268=5279=1269=0270=1.25474271=10000055=GBP/USD110=0279=1269=0270=1.25474271=50000055=GBP/USD110=100000279=1269=0270=1.25474271=100000055=GBP/USD110=500000279=1269=0270=1.25474271=300000055=GBP/USD110=1000000279=1269=0270=1.25474271=500000055=GBP/USD110=300000010=098
20260120-14:06:52.139657000 : 8=FIX.4.49=044735=X49=NTPRO_IDBA_UAT56=SIRIUS_500007460_MD34=200952=20260120-14:06:52.703262=MD_EUR/USD_140109278614268=6279=1269=0270=1.14787271=10000055=EUR/USD110=0279=1269=0270=1.14787271=50000055=EUR/USD110=100000279=1269=0270=1.14787271=100000055=EUR/USD110=500000279=1269=1270=1.19812271=10000055=EUR/USD110=0279=1269=1270=1.19812271=50000055=EUR/USD110=100000279=1269=1270=1.19812271=100000055=EUR/USD110=50000010=061
20260120-14:06:52.187655000 : 8=FIX.4.49=068435=X49=NTPRO_IDBA_UAT56=SIRIUS_500007460_MD34=201052=20260120-14:06:52.752262=MD_GBP/USD_140109778778268=10279=2269=0270=1.25474271=10000055=GBP/USD110=0279=2269=0270=1.25474271=50000055=GBP/USD110=100000279=2269=0270=1.25474271=100000055=GBP/USD110=500000279=2269=0270=1.25474271=300000055=GBP/USD110=1000000279=2269=0270=1.25474271=500000055=GBP/USD110=3000000279=2269=1270=1.43504271=10000055=GBP/USD110=0279=2269=1270=1.43504271=50000055=GBP/USD110=100000279=2269=1270=1.43504271=100000055=GBP/USD110=500000279=2269=1270=1.43504271=300000055=GBP/USD110=1000000279=2269=1270=1.43504271=500000055=GBP/USD110=300000010=236
20260120-14:06:52.264763000 : 8=FIX.4.49=067935=X49=NTPRO_IDBA_UAT56=SIRIUS_500007460_MD34=201152=20260120-14:06:52.832262=MD_GBP/USD_140109778778268=10279=0269=0270=1.25475271=10000055=GBP/USD110=0279=0269=0270=1.25475271=50000055=GBP/USD110=100000279=0269=0270=1.25475271=100000055=GBP/USD110=500000279=0269=0270=1.25475271=300000055=GBP/USD110=1000000279=0269=0270=1.25475271=500000055=GBP/USD110=3000000279=0269=1270=1.4351271=10000055=GBP/USD110=0279=0269=1270=1.4351271=50000055=GBP/USD110=100000279=0269=1270=1.4351271=100000055=GBP/USD110=500000279=0269=1270=1.4351271=300000055=GBP/USD110=1000000279=0269=1270=1.4351271=500000055=GBP/USD110=300000010=226
20260120-14:06:52.332175000 : 8=FIX.4.49=044735=X49=NTPRO_IDBA_UAT56=SIRIUS_500007460_MD34=201252=20260120-14:06:52.902262=MD_EUR/USD_140109278614268=6279=1269=0270=1.14788271=10000055=EUR/USD110=0279=1269=0270=1.14788271=50000055=EUR/USD110=100000279=1269=0270=1.14788271=100000055=EUR/USD110=500000279=1269=1270=1.19813271=10000055=EUR/USD110=0279=1269=1270=1.19813271=50000055=EUR/USD110=100000279=1269=1270=1.19813271=100000055=EUR/USD110=50000010=062
20260120-14:06:52.335229000 : 8=FIX.4.49=039835=X49=NTPRO_IDBA_UAT56=SIRIUS_500007460_MD34=201352=20260120-14:06:52.906262=MD_GBP/USD_140109778778268=5279=1269=1270=1.43511271=10000055=GBP/USD110=0279=1269=1270=1.43511271=50000055=GBP/USD110=100000279=1269=1270=1.43511271=100000055=GBP/USD110=500000279=1269=1270=1.43511271=300000055=GBP/USD110=1000000279=1269=1270=1.43511271=500000055=GBP/USD110=300000010=057
20260120-14:06:52.438025000 : 8=FIX.4.49=044735=X49=NTPRO_IDBA_UAT56=SIRIUS_500007460_MD34=201452=20260120-14:06:53.002262=MD_EUR/USD_140109278614268=6279=1269=0270=1.14791271=10000055=EUR/USD110=0279=1269=0270=1.14791271=50000055=EUR/USD110=100000279=1269=0270=1.14791271=100000055=EUR/USD110=500000279=1269=1270=1.19816271=10000055=EUR/USD110=0279=1269=1270=1.19816271=50000055=EUR/USD110=100000279=1269=1270=1.19816271=100000055=EUR/USD110=50000010=047
20260120-14:06:52.439264000 : 8=FIX.4.49=068435=X49=NTPRO_IDBA_UAT56=SIRIUS_500007460_MD34=201552=20260120-14:06:53.010262=MD_GBP/USD_140109778778268=10279=2269=0270=1.25475271=10000055=GBP/USD110=0279=2269=0270=1.25475271=50000055=GBP/USD110=100000279=2269=0270=1.25475271=100000055=GBP/USD110=500000279=2269=0270=1.25475271=300000055=GBP/USD110=1000000279=2269=0270=1.25475271=500000055=GBP/USD110=3000000279=2269=1270=1.43511271=10000055=GBP/USD110=0279=2269=1270=1.43511271=50000055=GBP/USD110=100000279=2269=1270=1.43511271=100000055=GBP/USD110=500000279=2269=1270=1.43511271=300000055=GBP/USD110=1000000279=2269=1270=1.43511271=500000055=GBP/USD110=300000010=224
20260120-14:06:52.517641000 : 8=FIX.4.49=028035=X49=NTPRO_IDBA_UAT56=SIRIUS_500007460_MD34=201652=20260120-14:06:53.094262=MD_EUR/USD_140109278614268=3279=1269=1270=1.19817271=10000055=EUR/USD110=0279=1269=1270=1.19817271=50000055=EUR/USD110=100000279=1269=1270=1.19817271=100000055=EUR/USD110=50000010=017
